Workbook

Sheet 00_封面
B2: 聚氯乙烯 主要生产企业与产能分布
B3: 企业 → 集团 → 生产基地 → 装置 → 产品 五级可追溯数据包 · 统计口径：设计产能 · 数据年度 2025
B4: 地域范围：中国大陆 | 生成日期：2026-10-20 | 数据截止：2026-10-20（产能数据年度以 2025 年为主，部分为 2024/2026 年披露）
B6: 品种 | C6: 聚氯乙烯（9002-86-2）
B7: 统计基期 | C7: 2025
B8: 样本范围 | C8: 中国境内聚氯乙烯（PVC）树脂生产企业：覆盖主要集团全量基地 + 中型企业主要基地 + 已取得一手披露的独立厂；含电石法、乙烯法、煤制烯烃乙烯法。不含境外产能，不含 VCM/EDC 中间品贸易环节。
B9: 样本规模 | C9: 45 条装置记录 / 37 个生产基地 / 44 个法人主体 / 28 个集团
B10: 样本产能合计 | C10: 1,423.0 万吨/年（设计产能）
B11: 全国口径参考 | C11: 未取得
B12: 样本覆盖率 | C12: 无法计算
B13: 覆盖提醒 | C13: 本表为「样本口径」。全国约 71 家 PVC 生产企业中，本表仅覆盖主要集团与已取得可引用来源的企业；未覆盖企业的产能未计入，故样本合计 < 全国产能，不得称为全国总产能。
B14: 数据缺口 | C14: 12 项（见 16_数据缺口）
B15: 来源数量 | C15: 79 条（见 17_来源清单）
B17: 阅读顺序与口径纪律
B18: 1) 先读 01_口径与样本范围，确认本表统计的是「设计产能」还是其他口径；不同口径严禁相加。
B19: 2) 06_装置明细是唯一事实层（装置级一行）。03/04/05/07/08/09/10 的合计均由该表筛选+求和得出，可在 14_汇总公式与溯源 核对。
B20: 3) 集团合计已合并其全部下属法人产能，不得再把某子公司产能与集团合计相加。
B21: 4) 样本合计 ≠ 全国产能；覆盖率见封面与 01 表，样本外企业未计入。
B22: 5) 11_在建拟建项目是「增量」，不得与存量相加；置换退出产能已在 12_新增净额还原 中扣减。
B23: 6) 13_重复统计校验 列出全部自动校验结果；ERROR 项必须在引用前处理。
B24: 7) 所有产能记录附来源编号与可信等级（A/B/C/D），D 级不得单独作为结论依据。

Sheet 01_口径与样本范围
A1: 统计口径、样本范围与使用边界
A2: 同一指标多套公开口径并列展示，不取平均；样本合计不等于全国总产能
A4: 编号 | B4: 口径/口径项 | C4: 定义 | D4: 数值/说明 | E4: 单位 | F4: 数据年份 | G4: 来源编号 | H4: 可信度 | I4: 备注
A5: B01 | B5: 本表主口径 | C5: 所有汇总（03-10 表）默认使用的产能口径 | D5: 设计产能（铭牌/名义） | E5: 万吨/年 | F5: 2025 | H5: A | I5: 与各公司年报「设计产能/产能」栏目口径一致
A6: B02 | B6: 有效产能口径 | C6: 扣除长期停产、限产、检修后的可用能力 | D6: 仅部分基地可得，见 06 表 basis 字段 | E6: 万吨/年 | F6: 2025 | H6: B | I6: 未取得行业统一口径，故不做有效产能全口径合计
A7: B03 | B7: 实际产量口径 | C7: 年度实际产出，用于计算开工率 | D7: 见 15_口径对比 | E7: 万吨/年 | F7: 2025 | H7: A | I7: 产量≠产能，禁止混用
A8: BM01 | B8: 全国 PVC 产能（协会口径·氯碱网） | C8: 协会口径年末产能；净增 205 万吨 | D8: 2993 | E8: 万吨/年 | F8: 2025 | G8: S44 | H8: B | I8: ⚠ 修正：此前常被引作 3,088 万吨并冠以「中国氯碱网」。经复核，3,038 万吨系百川盈孚口径，2,993 万吨为中国氯碱工业协会口径，2,962 万吨为商务部口径。三者不可混用，本表并列保留。
A9: BM02 | B9: 产能净增（协会口径） | C9: 协会口径净增 | D9: 205 | E9: 万吨/年 | F9: 2025 | G9: S44 | H9: B | I9: ⚠ 与北元年报转引的「净增 137 万吨」矛盾。两者不是同年同口径，禁止混用。本报告并列呈现。
A10: BM03 | B10: 全国 PVC 产量 | C10: 年度实际产出 | D10: 2300 | E10: 万吨 | F10: 2025 | G10: S05 | H10: A | I10: 英力特年报口径 2,285 万吨；华经口径 2,394 万吨
A11: BM04 | B11: 行业开工率 | C11: 产量/产能 | D11: 74 | E11: % | F11: 2025 | G11: S05 | H11: A | I11: 较 2024 年降 1 个百分点；中盐口径为 81.45%（分母不同）
A12: BM05 | B12: 生产企业数 | C12: 年末在册 PVC 生产企业 | D12: 71 | E12: 家 | F12: 2025 | G12: S05 | H12: A | I12: 较上年减少 2 家
A13: BM06 | B13: 乙烯法产能占比 | C13: 乙烯法产能/总产能 | D13: 30 | E13: % | F13: 2025 | G13: S05 | H13: A | I13: 2024 年为 26%，预计 2030 年超 40%
A14: BM07 | B14: 2025 年新增产能中乙烯法占比（修正） | C14: 年报原文：乙烯法新增 172 万吨，占当年新增 204 万吨的 84.3% | D14: 84.3 | E14: % | F14: 2025 | G14: S05 | H14: A | I14: ⚠ 需与「实际投产装置」区分：2025 年实际投产的陕西金泰神木 60 万吨、甘肃耀望 30 万吨共 90 万吨为电石法（无汞示范装置）。年报的 84.3% 是「新增产能（含改扩建）」口径，不等于「2025 年新投产装置」。两个概念不可混用。
A15: BM08 | B15: 全国 PVC 产能（另一口径） | C15: 电石法 2,055 + 乙烯法 877；未特别说明糊树脂是否单列 | D15: 2932 | E15: 万吨/年 | F15: 2025 | G15: S11 | H15: A | I15: 低于 BM01，差额约 156 万吨，接近糊树脂 162 万吨
A16: BM09 | B16: 全国 PVC 产能（另一口径） | C16: 含聚氯乙烯糊状树脂 164.5 万吨；电石法 70% / 乙烯法 30% | D16: 3087.5 | E16: 万吨/年 | F16: 2025 | G16: S12 | H16: A | I16: 与 BM01 基本一致（差 0.5 万吨），可互为印证
A17: BM10 | B17: 全国 PVC 产能（第三方） | C17: 乙烯法 27.39%、电石法 72.61% | D17: 3017 | E17: 万吨/年 | F17: 2025 | G17: S42 | H17: C | I17: 第三方口径，与协会口径差异明显
A18: BM11 | B18: 全国 PVC 产能（券商口径） | C18: 2018-2025 由 2,490 增至 3,038 万吨，CAGR 约 2.9% | D18: 3038 | E18: 万吨/年 | F18: 2025 | G18: S43 | H18: B | I18: 产量 2,394 万吨
A19: BM12 | B19: 2025 年底产能（隆众预估） | C19: 预估 2025 年投产 250 万吨（电石法 60、乙烯法 190）后的年末产能 | D19: 2972 | E19: 万吨/年 | F19: 2025 | G19: S44 | H19: B | I19: 预估值，非年末实测
... A22: BM15 | B22: 长期停车装置 | C22: 2025 年约有超 100 万吨装置停车超一年 | D22: 100 | E22: 万吨/年 | F22: 2025 | G22: S05 | H22: A | I22: 「约」「超」为原文限定词，非精确值
A23: BM16 | B23: 中国占全球产能比重 | C23: 产能占全球约 48%、产量约 46% | D23: 48 | E23: % | F23: 2025 | G23: S05 | H23: A
A24: BM17 | B24: 表观消费量 | C24: 同比 -2.0% | D24: 1941 | E24: 万吨 | F24: 2025 | G24: S05 | H24: A
A25: BM18 | B25: PVC 出口量 | C25: 同比增长 46.09%，创历史新高 | D25: 382.32 | E25: 万吨 | F25: 2025 | G25: S17 | H25: A | I25: 进口 22.67 万吨
A26: BM19 | B26: 中国在建 PVC 项目（可核查清单口径） | C26: 万融 96 + 天业十户滩 50 + 广西华谊 30 + 嘉化 30 + 信发华兴二期 20 = 226 万吨 | D26: 226 | E26: 万吨/年 | F26: 2026 | G26: S61 | H26: B | I26: ⚠ 修正：广为流传的「在建 8 个项目 370 万吨」出自标普全球分析师会议表述，未公布项目名单。逐条落到书面来源仅 226 万吨，缺口 144 万吨无公开项目对应，不可当作项目清单使用。
A27: BM20 | B27: 2025 年 PVC 产量（第三方） | C27: 同比 +7.8% | D27: 2394 | E27: 万吨 | F27: 2025 | G27: S43 | H27: B | I27: 与 BM03 的 2,300 万吨差异约 4%
A28: BM21 | B28: 糊状树脂产能 | C28: 包含在 3,088 万吨口径内 | D28: 162 | E28: 万吨/年 | F28: 2025 | G28: S05 | H28: A | I28: 英力特口径为 164.5 万吨——不同来源差 2.5 万吨
A29: BM22 | B29: 西北地区产能占比 | C29: 2022 年数据（华东 24%、华北 13%） | D29: 49 | E29: % | F29: 2022 | G29: S41 | H29: C | I29: 年份较早，仅作趋势参考
A30: BM01b | B30: 全国 PVC 产能（北元年报转引氯碱网） | C30: 含聚氯乙烯糊状树脂 162 万吨；净增 137 万吨（新增 204 / 退出 67） | D30: 3088 | E30: 万吨/年 | F30: 2025 | G30: S05 | H30: A | I30: 上市公司年报原文口径。与协会 2,993 万吨差 95 万吨。原文如此，照录不调和。
A31: BM01c | B31: 全国 PVC 产能（商务部口径） | C31: 未公开完整定义 | D31: 2962 | E31: 万吨/年 | F31: 2025 | G31: S60 | H31: C | I31: 四套口径中的最低值。
A33: 口径判定规则（行业统计口径是否包含联产/副产/长期停车/不同等级）
A34: • 【联产/副产】PVC 装置与烧碱装置在氯碱平衡意义上是联产的（每吨 PVC 约联产 0.7 吨烧碱），但行业统计的「PVC 产能」只计 PVC 树脂本身，不把烧碱并入；因此本报告 PVC 产能与烧碱产能分列，不合并。
A35: • 【副产】电石法 PVC 副产电石渣，并配套电石渣制水泥，水泥产能不能计入 PVC。乙烯法 PVC 与乙烯装置深度耦合，乙烯产能按乙烯计，不重复计入 PVC。
A36: • 【不同产品等级】3,088 万吨的行业口径明确「包含聚氯乙烯糊状树脂 162 万吨」。糊树脂与通用悬浮树脂同属 PVC，故本报告将通用树脂、专用料、糊树脂一并计入总量，但在「产品等级」维度单列，便于与只统计纯粉的口径对比。
A37: • 【长期停产】行业产能口径按「在册产能」统计，通常包含长期停车装置——北元年报明确指出 2025 年约有超 100 万吨装置停车超一年。因此「产能」显著高于「有效产能」，两者不可混用。
A38: • 【已退出/注销】2020 年后退出产能全部为电石法。已注销法人（如石河子天域新实，2026-02 注销）若按旧资料录入会与吸收合并方重复，须以最新法人存续状态为准。
A39: • 【集团 vs 上市公司】集团口径与上市主体口径不同：天业集团含上市公司 134 万吨及在建 50 万吨；上市公司仅 134 万吨。引用时必须标明是「集团」还是「上市主体」。

Sheet 02_核心结论
A1: 核心结论与数据摘要
A2: 结论均由下方明细表计算，不含估算值
A4: 一、规模与集中度
A5: 样本产能合计 | B5: 1,423.0 万吨/年 | C5: 设计产能
A6: 样本企业（法人）数 | B6: 26 | C6: 个
A7: 样本集团数 | B7: 23 | C7: 个
A8: 样本基地数 | B8: 26 | C8: 个
A9: 全国总产能（参考） | B9: 未取得 | C9: 万吨/年
A10: 样本覆盖率 | B10: 无法计算 | C10: 样本合计/全国口径
A11: CR1（样本口径） | B11: 9.42% | C11: 最大集团份额
A12: CR3（样本口径） | B12: 24.81%
A13: CR5（样本口径） | B13: 38.37%
A14: CR10（样本口径） | B14: 64.23%
A15: HHI（样本口径） | B15: 541.2 | C15: 分散（HHI<1000）
A16: CR5（法人口径） | B16: 35.77% | C16: 以单一法人为单位
A17: HHI（法人口径） | B17: 483.5 | C17: 分散（HHI<1000）
A19: 二、前十大集团
A20: 排名 | B20: 集团 | C20: 样本产能(万吨/年) | D20: 占样本比 | E20: 折全国份额(参考) | F20: 主要省份/区域
A21: 1 | B21: 天业集团 | C21: 134 | D21: 0.094167252 | F21: 新疆维吾尔自治区
A22: 2 | B22: 北元集团 | C22: 110 | D22: 0.077301476 | F22: 陕西省
A23: 3 | B23: 中泰集团 | C23: 109 | D23: 0.076598735 | F23: 新疆维吾尔自治区
A24: 4 | B24: 海湾集团 | C24: 105 | D24: 0.073787772 | F24: 山东省
A25: 5 | B25: 华谊集团 | C25: 88 | D25: 0.061841181 | F25: 上海市、广西壮族自治区
A26: 6 | B26: 君正集团 | C26: 80 | D26: 0.056219255 | F26: 内蒙古自治区
A27: 7 | B27: 渤化集团 | C27: 80 | D27: 0.056219255 | F27: 天津市
A28: 8 | B28: 万华化学 | C28: 80 | D28: 0.056219255 | F28: 山东省、福建省
A29: 9 | B29: 中盐化工 | C29: 64 | D29: 0.044975404 | F29: 内蒙古自治区
A30: 10 | B30: 华塑股份 | C30: 64 | D30: 0.044975404 | F30: 安徽省
A32: 三、区域结构（省份 Top10）
A33: 排名 | B33: 省份 | C33: 样本产能(万吨/年) | D33: 占样本比
A34: 1 | B34: 新疆维吾尔自治区 | C34: 243 | D34: 0.17076599
A35: 2 | B35: 内蒙古自治区 | C35: 234 | D35: 0.16444132
A36: 3 | B36: 陕西省 | C36: 170 | D36: 0.11946592
A37: 4 | B37: 山东省 | C37: 145 | D37: 0.1018974
A38: 5 | B38: 天津市 | C38: 80 | D38: 0.056219255
A39: 6 | B39: 河南省 | C39: 70 | D39: 0.049191848
A40: 7 | B40: 安徽省 | C40: 64 | D40: 0.044975404
A41: 8 | B41: 四川省 | C41: 50 | D41: 0.035137034
A42: 9 | B42: 江苏省 | C42: 50 | D42: 0.035137034
A43: 10 | B43: 上海市 | C43: 48 | D43: 0.033731553
...

Sheet 03_集团汇总
A1: 集团级产能汇总（设计产能）
A2: 集团合计 = 其下全部法人全部基地全部装置之和；不得与子公司产能再相加
A4: 集团ID | B4: 集团简称 | C4: 集团全称 | D4: 实际控制人/性质 | E4: 产能合计(万吨/年) | F4: 法人数 | G4: 基地数 | H4: 覆盖省份 | I4: 占样本比 | J4: 工艺构成(万吨) | K4: 来源
A5: G02 | B5: 天业集团 | C5: 新疆天业（集团）有限公司 | D5: 新疆生产建设兵团第八师国有资产监督管理委员会（兵团国企） | E5: 134 | F5: 7 | G5: 2 | H5: 新疆维吾尔自治区 | I5: =IF($E$29=0,"",E5/$E$29) | J5: 电石法（乙炔法） 134 | K5: S02
A6: G03 | B6: 北元集团 | C6: 陕西北元化工集团股份有限公司（独立上市） | D6: 陕西省人民政府国有资产监督管理委员会（控股股东：陕西煤业化工集团有限责任公司）（省属国企） | E6: 110 | F6: 1 | G6: 1 | H6: 陕西省 | I6: =IF($E$29=0,"",E6/$E$29) | J6: 电石法（乙炔法） 110 | K6: S05
A7: G01 | B7: 中泰集团 | C7: 新疆中泰（集团）有限责任公司 | D7: 新疆维吾尔自治区人民政府国有资产监督管理委员会（省属国企） | E7: 109 | F7: 6 | G7: 4 | H7: 新疆维吾尔自治区 | I7: =IF($E$29=0,"",E7/$E$29) | J7: 电石法（乙炔法） 109 | K7: S01
A8: G12 | B8: 海湾集团 | C8: 青岛海湾集团有限公司 | D8: 青岛市国有资产监督管理委员会（地方国企） | E8: 105 | F8: 1 | G8: 1 | H8: 山东省 | I8: =IF($E$29=0,"",E8/$E$29) | J8: 乙烯法 105 | K8: S22
A9: G06 | B9: 华谊集团 | C9: 上海华谊控股集团有限公司 | D9: 上海市国有资产监督管理委员会（地方国企） | E9: 88 | F9: 2 | G9: 2 | H9: 上海市、广西壮族自治区 | I9: =IF($E$29=0,"",E9/$E$29) | J9: 乙烯法 88 | K9: S09
A10: G04 | B10: 君正集团 | C10: 内蒙古君正能源化工集团股份有限公司（含乌海市君正科技产业集团） | D10: 杜江涛（自然人，民营控股）（民营） | E10: 80 | F10: 1 | G10: 1 | H10: 内蒙古自治区 | I10: =IF($E$29=0,"",E10/$E$29) | J10: 电石法（乙炔法） 80 | K10: S06
A11: G11 | B11: 渤化集团 | C11: 天津渤海化工集团有限责任公司 | D11: 天津市国有资产监督管理委员会（地方国企） | E11: 80 | F11: 1 | G11: 1 | H11: 天津市 | I11: =IF($E$29=0,"",E11/$E$29) | J11: 乙烯法 80 | K11: S19
A12: G13 | B12: 万华化学 | C12: 万华化学集团股份有限公司（独立上市） | D12: 烟台市国资委（国有控股混合所有制）（混合所有制） | E12: 80 | F12: 3 | G12: 3 | H12: 山东省、福建省 | I12: =IF($E$29=0,"",E12/$E$29) | J12: 乙烯法 80 | K12: S25
A13: G07 | B13: 中盐化工 | C13: 中盐内蒙古化工股份有限公司（独立上市） | D13: 中国盐业集团有限公司（国务院国资委）（央企） | E13: 64 | F13: 1 | G13: 1 | H13: 内蒙古自治区 | I13: =IF($E$29=0,"",E13/$E$29) | J13: 电石法（乙炔法） 64 | K13: S11
A14: G10 | B14: 华塑股份 | C14: 安徽华塑股份有限公司（独立上市） | D14: 安徽省国资委（淮北矿业集团方向，具体持股以年报为准）（地方国企） | E14: 64 | F14: 1 | G14: 1 | H14: 安徽省 | I14: =IF($E$29=0,"",E14/$E$29) | J14: 电石法（乙炔法） 64 | K14: S18
A15: G24 | B15: 陕投集团 | C15: 陕西投资集团有限公司 | D15: 陕西省人民政府国有资产监督管理委员会（省属国企） | E15: 60 | F15: 1 | G15: 1 | H15: 陕西省 | I15: =IF($E$29=0,"",E15/$E$29) | J15: 电石法（乙炔法） 60 | K15: S72
A16: G15 | B16: 亿利集团 | C16: 亿利资源集团有限公司 | D16: 王文彪（自然人）/亿利资源集团（民营） | E16: 50 | F16: 1 | G16: 1 | H16: 内蒙古自治区 | I16: =IF($E$29=0,"",E16/$E$29) | J16: 电石法（乙炔法） 50 | K16: S38
... A27: G20 | B27: 东曹广州 | C27: 东曹株式会社（东曹（广州）化工有限公司） | D27: 东曹株式会社 Tosoh Corporation（日本）（外资） | E27: 22 | F27: 1 | G27: 1 | H27: 广东省 | I27: =IF($E$29=0,"",E27/$E$29) | J27: 乙烯法 22 | K27: S29
B29: 样本合计 | E29: =SUM(E5:E27)
A31: 说明：集团简称仅用于本报告可读性，法定主体见 04_法人汇总；同一集团内不同法人不得重复计入集团合计。
A32: 「占样本比」的分母是样本产能合计，不是全国产能；折全国份额请用 02 表的参考值自行换算并注明假设。

Sheet 04_法人汇总
A1: 法人（企业主体）级产能汇总（设计产能）
A2: 一个法人一行：法定全称、所属集团、统一社会信用代码、核验依据
A4: 法人ID | B4: 法定主体全称 | C4: 简称 | D4: 所属集团 | E4: 证券代码 | F4: 企业性质 | G4: 统一社会信用代码 | H4: 注册地址 | I4: 产能合计(万吨/年) | J4: 基地数 | K4: 工艺 | L4: 主体核验依据 | M4: 来源
A5: E010 | B5: 新疆天业股份有限公司 | C5: 新疆天业 | D5: 天业集团 | E5: 600075.SH | F5: 兵团国企（八师国资委） | H5: 新疆维吾尔自治区石河子市 | I5: 134 | J5: 1 | K5: 电石法（乙炔法） | L5: 2025 年报释义表（本公司=新疆天业股份有限公司，天业集团=控股股东） | M5: S02
A6: E020 | B6: 陕西北元化工集团股份有限公司 | C6: 北元集团 | D6: 北元集团 | E6: 601568.SH | F6: 陕西省国资委（控股股东陕煤集团） | H6: 陕西省榆林市神木市锦界工业园区 | I6: 110 | J6: 1 | K6: 电石法（乙炔法） | L6: 2025 年报 p9 主要业务 + p5 释义（化工分公司/热电分公司） | M6: S05
A7: E110 | B7: 青岛海湾化学股份有限公司 | C7: 海湾化学 | D7: 海湾集团 | F7: 青岛海湾集团 | H7: 山东省青岛市西海岸新区董家口经济区 | I7: 105 | J7: 1 | K7: 乙烯法 | L7: 证券时报：已建成投产 85 万吨/年乙烯法 PVC、55.5 万吨/年烧碱 | M7: S22
A8: E003 | B8: 新疆中泰化学阜康能源有限公司 | C8: 阜康能源 | D8: 中泰集团 | F8: 中泰化学控股子公司 | H8: 新疆昌吉州阜康市准噶尔路 3188 号（阜康工业园） | I8: 80 | J8: 1 | K8: 电石法（乙炔法） | L8: 中泰化学 2025 年报 p5 释义表 / 子公司表（阜康市准噶尔路 3188 号） | M8: S01
A9: E030 | B9: 内蒙古君正化工有限责任公司 | C9: 君正化工 | D9: 君正集团 | F9: 君正集团子公司 | H9: 内蒙古自治区乌海市乌达区工业园区 | I9: 80 | J9: 1 | K9: 电石法（乙炔法） | L9: 君正集团 2025 年报子公司表（内蒙古君正化工有限责任公司 乌海市乌达区工业园区） | M9: S06
A10: E100 | B10: 天津大沽化工股份有限公司 | C10: 大沽化工 | D10: 渤化集团 | F10: 天津渤海化工集团 | H10: 天津市滨海新区（临港经济区） | I10: 80 | J10: 1 | K10: 乙烯法 | L10: 渤化集团官网产品与服务页 / 评级报告（2021-12 烧碱、聚氯乙烯装置试车投产） | M10: S19
A11: E060 | B11: 中盐吉兰泰氯碱化工有限公司 | C11: 中盐吉兰泰 | D11: 中盐化工 | F11: 中盐内蒙古化工股份有限公司子公司 | H11: 内蒙古自治区阿拉善盟阿拉善左旗吉兰泰镇 | I11: 64 | J11: 1 | K11: 电石法（乙炔法） | L11: 中盐内蒙古化工 2025 年报（提及中盐吉兰泰氯碱化工与 PVC 板块） | M11: S11
A12: E090 | B12: 安徽华塑股份有限公司 | C12: 华塑股份 | D12: 华塑股份 | E12: 600935.SH | F12: 安徽省国资委体系 | H12: 安徽省滁州市定远县（盐化工业园） | I12: 64 | J12: 1 | K12: 电石法（乙炔法） | L12: 2026 半年报：现有 PVC 产能 64 万吨/年、烧碱 48 万吨/年 | M12: S18
A13: E305 | B13: 陕西金泰氯碱神木化工有限公司 | C13: 金泰神木 | D13: 陕投集团 | F13: 陕西投资集团（陕投集团） | H13: 陕西省榆林市神木市 | I13: 60 | J13: 1 | K13: 电石法（乙炔法） | L13: 项目试生产与交工验收公告 | M13: S72
A14: E140 | B14: 内蒙古亿利化学工业有限公司 | C14: 亿利化学 | D14: 亿利集团 | F14: 亿利资源集团系（亿利洁能/上海华谊/神华神东电力合资设立，现控股方待核） | H14: 内蒙古自治区鄂尔多斯市达拉特旗（达拉特化工园区） | I14: 50 | J14: 1 | K14: 电石法（乙炔法） | L14: 财联社：具备年产 50 万吨 PVC、40 万吨离子膜烧碱、64 万吨电石能力 | M14: S38
A15: E400 | B15: 宜宾天原集团股份有限公司 | C15: 天原集团 | D15: 天原集团 | E15: 002386.SZ | F15: 宜宾市国资委 | H15: 四川省宜宾市 | I15: 50 | J15: 1 | K15: 电石法（乙炔法） | L15: 2025 年报：PVC 设计产能 50 万吨、利用率 78.44%；原材料表显示电石全部外购 | M15: S76
A16: E307 | B16: 新浦化学（泰兴）有限公司 | C16: 新浦化学 | D16: 新浦化学 | F16: 新加坡新浦化学（SP Chemicals） | H16: 江苏省泰兴市泰兴经济开发区 | I16: 50 | J16: 1 | K16: 乙烯法 | L16: 项目中期与量产报道 | M16: S74
A17: E050 | B17: 上海氯碱化工股份有限公司 | C17: 氯碱化工 | D17: 华谊集团 | E17: 600618.SH | F17: 华谊集团控股 | H17: 上海市（上海化学工业区） | I17: 48 | J17: 1 | K17: 乙烯法 | L17: 2025 年报：烧碱 102 万吨、聚氯乙烯 48 万吨（40 + 特种 8） | M17: S09
A18: E080 | B18: 唐山三友氯碱有限责任公司 | C18: 三友氯碱 | D18: 三友化工 | F18: 唐山三友化工股份有限公司子公司 | H18: 河北省唐山市（南堡经济开发区） | I18: 47 | J18: 1 | K18: 电石法（乙炔法） | L18: 三友化工 2025 年报：子公司聚氯乙烯树脂、烧碱的生产与销售 | M18: S14
A19: E051 | B19: 广西华谊氯碱化工有限公司 | C19: 广西氯碱 | D19: 华谊集团 | F19: 氯碱化工 100% 持股（2024 年完成收购剩余 40%） | H19: 广西壮族自治区钦州市（华谊钦州一体化基地） | I19: 40 | J19: 1 | K19: 乙烯法 | L19: 证券时报 2024-05：广西钦州 30 万吨/年烧碱、40 万吨/年聚氯乙烯项目 | M19: S10
A20: E120 | B20: 万华化学集团股份有限公司 | C20: 万华化学 | D20: 万华化学 | E20: 600309.SH | F20: 国有控股混合所有制 | H20: 山东省烟台市（烟台工业园） | I20: 40 | J20: 1 | K20: 乙烯法 | L20: 证券时报：乙烯一期新建 100 万吨/年乙烯联合装置、40 万吨/年聚氯乙烯装置 | M20: S25
A21: E150 | B21: 内蒙古鄂尔多斯电力冶金集团股份有限公司氯碱化工分公司 | C21: 鄂尔多斯电冶氯碱 | D21: 鄂尔多斯电冶 | F21: 鄂尔多斯电冶集团 | H21: 内蒙古自治区鄂尔多斯市鄂托克旗棋盘井工业园区 | I21: 40 | J21: 1 | K21: 电石法（乙炔法） | L21: 新华网 2023-02：年产 40 万吨电石法 PVC 及烧碱项目已完全装填无汞催化剂 | M21: S35
A22: E180 | B22: 河南联创化工有限公司 | C22: 河南联创 | D22: 河南联创 | F22: 待核 | H22: 河南省（具体地址待核） | I22: 40 | J22: 1 | K22: 电石法（乙炔法） | L22: 行业盘点：聚氯乙烯树脂 40 万吨、离子膜烧碱 35 万吨等 | M22: S31
A23: E304 | B23: 万华化学（福建）有限公司 | C23: 万华福建 | D23: 万华化学 | F23: 万华化学集团股份有限公司 | H23: 福建省福州市福清市江阴港城经济区 | I23: 40 | J23: 1 | K23: 乙烯法 | L23: 项目开工与复产公告 | M23: S75
A24: E130 | B24: 阳煤化工股份有限公司 | C24: 阳煤化工 | D24: 阳煤化工 | E24: 600691.SH | F24: 山西省国资委（2024-12 潞安化工成为控股股东） | H24: 山西省阳泉市 | I24: 30 | J24: 1 | K24: 乙烯法 | L24: 2024 年报：聚氯乙烯 25.06 万吨；工艺为乙烯氧氯化平衡法/直接氯化法 | M24: S27
A25: E160 | B25: 青海盐湖镁业有限公司 | C25: 盐湖镁业 | D25: 盐湖镁业 | F25: 青海汇信资产管理有限责任公司 | H25: 青海省海西州格尔木市察尔汗（柴达木循环经济试验区） | I25: 30 | J25: 1 | K25: 乙烯法 | L25: 中控技术中标信息：PVC&钾碱厂 30 万吨乙烯法 PVC 装置，2016 年投产 | M25: S36
A26: E170 | B26: 河南神马氯碱发展有限责任公司 | C26: 神马氯碱 | D26: 神马氯碱 | F26: 平煤神马集团 | H26: 河南省平顶山市 | I26: 30 | J26: 1 | K26: 电石法（乙炔法） | L26: 南阳理工学院企业介绍：以离子膜烧碱（32%）及聚氯乙烯树脂（PVC）等基础化工原料为主（产能数字待一手核实） | M26: S30
A27: E306 | B27: 甘肃耀望化工有限公司 | C27: 耀望化工 | D27: 耀望化工 | F27: 待核 | H27: 甘肃省兰州新区 | I27: 30 | J27: 1 | K27: 电石法（乙炔法） | L27: 杭州新区投产公示 / 行业媒体 | M27: S73
A28: E302 | B28: 浙江嘉化能源化工股份有限公司 | C28: 嘉化能源 | D28: 嘉化能源 | E28: 600273.SH | F28: 民营控股 | H28: 浙江省嘉兴市嘉兴港区 | I28: 30 | J28: 1 | K28: 乙烯法 | L28: 公司定期报告与投资者关系表述 | M28: S66
A29: E004 | B29: 新疆中泰化学托克逊能化有限公司 | C29: 托克逊能化 | D29: 中泰集团 | F29: 中泰化学控股子公司（注册资本 48.03 亿元） | H29: 新疆吐鲁番市托克逊县工业园区第三辅道南侧 | I29: 29 | J29: 1 | K29: 电石法（乙炔法） | L29: 中泰化学 2025 年报 p5 释义表 / 子公司表（托克逊县） | M29: S01
A30: E190 | B30: 东曹（广州）化工有限公司 | C30: 东曹广州 | D30: 东曹广州 | F30: 东曹株式会社（日本）全资 | H30: 广东省广州市南沙区 | I30: 22 | J30: 1 | K30: 乙烯法 | L30: 东曹官网：2004 年成立，PVC 产能 22 万吨/年 | M30: S29
A32: 法定主体全称以年报释义表/工商登记为准；简称不等于法定名称，不可直接用于合同或诉讼。

Sheet 05_基地清单
A1: 生产基地清单（Plant-level）
A2: 一个厂区一行；集团→法人→基地→装置的四级归属在此显式列出
A4: 基地ID | B4: 基地简称 | C4: 基地全称 | D4: 省 | E4: 市 | F4: 区县 | G4: 园区/位置 | H4: 运营法人 | I4: 所属集团 | J4: 产能(万吨/年) | K4: 装置数 | L4: 工艺 | M4: 注册地址 | N4: 经纬度 | O4: 坐标精度
A5: P010 | B5: 石河子化工园区基地（综合） | C5: 新疆天业股份有限公司 石河子化工园区 PVC 生产基地（天伟/天能/天辰三厂合并口径） | D5: 新疆维吾尔自治区 | E5: 石河子市 | G5: 石河子经济技术开发区化工产业园 | H5: 新疆天业股份有限公司 | I5: 天业集团 | J5: 134 | K5: 3 | L5: 电石法（乙炔法） | M5: 新疆石河子市 | N5: 44.3100,86.0600 | O5: city
A6: P020 | B6: 锦界园区基地（北元） | C6: 陕西北元化工集团股份有限公司 锦界工业园区 PVC 生产基地 | D6: 陕西省 | E6: 神木市 | G6: 锦界工业园区 | H6: 陕西北元化工集团股份有限公司 | I6: 北元集团 | J6: 110 | K6: 1 | L6: 电石法（乙炔法） | M6: 陕西省榆林市神木市锦界工业园区 | N6: 38.8700,110.4300 | O6: city
A7: P110 | B7: 董家口基地（海湾化学） | C7: 青岛海湾化学股份有限公司 董家口经济区 PVC 生产基地 | D7: 山东省 | E7: 青岛市 | F7: 西海岸新区 | G7: 董家口经济区 | H7: 青岛海湾化学股份有限公司 | I7: 海湾集团 | J7: 105 | K7: 2 | L7: 乙烯法 | M7: 山东省青岛市西海岸新区 | N7: 35.9600,120.2000 | O7: city
A8: P002 | B8: 阜康基地（阜康能源） | C8: 新疆中泰化学阜康能源有限公司 阜康工业园 PVC 生产基地 | D8: 新疆维吾尔自治区 | E8: 阜康市 | G8: 阜康工业园（准噶尔路 3188 号） | H8: 新疆中泰化学阜康能源有限公司 | I8: 中泰集团 | J8: 80 | K8: 1 | L8: 电石法（乙炔法） | M8: 新疆昌吉州阜康市准噶尔路 3188 号 | N8: 44.1600,87.9900 | O8: city
A9: P030 | B9: 乌达工业园区基地（君正） | C9: 内蒙古君正化工有限责任公司 乌达工业园区 PVC 生产基地 | D9: 内蒙古自治区 | E9: 乌海市 | F9: 乌达区 | G9: 乌达区工业园区 | H9: 内蒙古君正化工有限责任公司 | I9: 君正集团 | J9: 80 | K9: 1 | L9: 电石法（乙炔法） | M9: 内蒙古乌海市乌达区工业园区 | N9: 39.5000,106.7200 | O9: city
A10: P100 | B10: 临港基地（大沽化工） | C10: 天津大沽化工股份有限公司 临港经济区 PVC 生产基地 | D10: 天津市 | E10: 天津市 | F10: 滨海新区 | G10: 临港经济区 | H10: 天津大沽化工股份有限公司 | I10: 渤化集团 | J10: 80 | K10: 2 | L10: 乙烯法 | M10: 天津市滨海新区临港经济区 | N10: 38.9500,117.7200 | O10: city
A11: P060 | B11: 吉兰泰基地（中盐吉兰泰） | C11: 中盐吉兰泰氯碱化工有限公司 PVC 生产基地 | D11: 内蒙古自治区 | E11: 阿拉善盟 | F11: 阿拉善左旗 | G11: 吉兰泰工业园区 | H11: 中盐吉兰泰氯碱化工有限公司 | I11: 中盐化工 | J11: 64 | K11: 2 | L11: 电石法（乙炔法） | M11: 内蒙古阿拉善盟阿拉善左旗吉兰泰镇 | N11: 38.8500,105.6700 | O11: city
A12: P090 | B12: 定远基地（华塑） | C12: 安徽华塑股份有限公司 定远盐化工业园 PVC 生产基地 | D12: 安徽省 | E12: 滁州市 | F12: 定远县 | G12: 定远盐化工业园 | H12: 安徽华塑股份有限公司 | I12: 华塑股份 | J12: 64 | K12: 1 | L12: 电石法（乙炔法） | M12: 安徽省滁州市定远县 | N12: 32.5300,117.6800 | O12: city
A13: P305 | B13: 神木基地（金泰氯碱） | C13: 陕西金泰氯碱神木化工有限公司 PVC 生产基地 | D13: 陕西省 | E13: 神木市 | G13: 神木市锦界工业园东区 | H13: 陕西金泰氯碱神木化工有限公司 | I13: 陕投集团 | J13: 60 | K13: 1 | L13: 电石法（乙炔法） | M13: 陕西省榆林市神木市 | N13: 38.8300,110.5000 | O13: city
A14: P140 | B14: 达拉特基地（亿利化学） | C14: 内蒙古亿利化学工业有限公司 达拉特化工园区 PVC 生产基地 | D14: 内蒙古自治区 | E14: 鄂尔多斯市 | F14: 达拉特旗 | G14: 达拉特化工园区 | H14: 内蒙古亿利化学工业有限公司 | I14: 亿利集团 | J14: 50 | K14: 1 | L14: 电石法（乙炔法） | M14: 内蒙古鄂尔多斯市达拉特旗 | N14: 40.4000,110.0300 | O14: city
A15: P400 | B15: 宜宾基地（天原集团） | C15: 宜宾天原集团股份有限公司 宜宾 PVC 生产基地 | D15: 四川省 | E15: 宜宾市 | G15: 宜宾临港经济技术开发区 | H15: 宜宾天原集团股份有限公司 | I15: 天原集团 | J15: 50 | K15: 1 | L15: 电石法（乙炔法） | M15: 四川省宜宾市 | N15: 28.7700,104.6200 | O15: city
A16: P307 | B16: 泰兴基地（新浦化学） | C16: 新浦化学（泰兴）有限公司 PVC 生产基地 | D16: 江苏省 | E16: 泰兴市 | G16: 泰兴经济开发区 | H16: 新浦化学（泰兴）有限公司 | I16: 新浦化学 | J16: 50 | K16: 1 | L16: 乙烯法 | M16: 江苏省泰兴市泰兴经济开发区 | N16: 32.1700,119.9500 | O16: city
A17: P050 | B17: 上海化工区基地（氯碱化工） | C17: 上海氯碱化工股份有限公司 上海化学工业区 PVC 生产基地 | D17: 上海市 | E17: 上海市 | G17: 上海化学工业区 | H17: 上海氯碱化工股份有限公司 | I17: 华谊集团 | J17: 48 | K17: 2 | L17: 乙烯法 | M17: 上海市 | N17: 31.2300,121.4700 | O17: city
A18: P080 | B18: 南堡基地（三友氯碱） | C18: 唐山三友氯碱有限责任公司 PVC 生产基地 | D18: 河北省 | E18: 唐山市 | F18: 曹妃甸区 | G18: 南堡经济开发区 | H18: 唐山三友氯碱有限责任公司 | I18: 三友化工 | J18: 47 | K18: 2 | L18: 电石法（乙炔法） | M18: 河北省唐山市南堡经济开发区 | N18: 39.2700,118.4600 | O18: city
A19: P051 | B19: 钦州基地（广西氯碱） | C19: 广西华谊氯碱化工有限公司 钦州一体化基地 PVC 生产基地 | D19: 广西壮族自治区 | E19: 钦州市 | F19: 钦州港区 | G19: 华谊钦州化工新材料一体化基地 | H19: 广西华谊氯碱化工有限公司 | I19: 华谊集团 | J19: 40 | K19: 1 | L19: 乙烯法 | M19: 广西钦州市 | N19: 21.7200,108.6000 | O19: city
A20: P120 | B20: 烟台工业园基地（万华） | C20: 万华化学集团股份有限公司 烟台工业园 PVC 生产基地 | D20: 山东省 | E20: 烟台市 | G20: 万华烟台工业园 | H20: 万华化学集团股份有限公司 | I20: 万华化学 | J20: 40 | K20: 1 | L20: 乙烯法 | M20: 山东省烟台市 | N20: 37.5500,121.0200 | O20: city
A21: P150 | B21: 棋盘井基地（鄂尔多斯电冶） | C21: 内蒙古鄂尔多斯电力冶金集团股份有限公司氯碱化工分公司 PVC 生产基地 | D21: 内蒙古自治区 | E21: 鄂尔多斯市 | F21: 鄂托克旗 | G21: 棋盘井工业园区 | H21: 内蒙古鄂尔多斯电力冶金集团股份有限公司氯碱化工分公司 | I21: 鄂尔多斯电冶 | J21: 40 | K21: 1 | L21: 电石法（乙炔法） | M21: 内蒙古鄂尔多斯市鄂托克旗棋盘井 | N21: 39.1000,107.9800 | O21: city
A22: P180 | B22: 河南联创基地 | C22: 河南联创化工有限公司 PVC 生产基地 | D22: 河南省 | E22: （待核） | G22: （待核） | H22: 河南联创化工有限公司 | I22: 河南联创 | J22: 40 | K22: 1 | L22: 电石法（乙炔法） | M22: 河南省 | N22: 34.7500,113.6300 | O22: province
A23: P304 | B23: 江阴港城基地（万华福建） | C23: 万华化学（福建）有限公司 江阴港城经济区 PVC 生产基地 | D23: 福建省 | E23: 福清市 | F23: 江阴港城经济区 | G23: 江阴港城经济区 | H23: 万华化学（福建）有限公司 | I23: 万华化学 | J23: 40 | K23: 1 | L23: 乙烯法 | M23: 福建省福州市福清市江阴港城经济区 | N23: 25.5000,119.3200 | O23: city
A24: P130 | B24: 阳泉基地（阳煤化工） | C24: 阳煤化工股份有限公司 阳泉 PVC 生产基地 | D24: 山西省 | E24: 阳泉市 | G24: （具体园区待核） | H24: 阳煤化工股份有限公司 | I24: 阳煤化工 | J24: 30 | K24: 1 | L24: 乙烯法 | M24: 山西省阳泉市 | N24: 37.8600,113.5800 | O24: city
A25: P160 | B25: 察尔汗基地（盐湖镁业） | C25: 青海盐湖镁业有限公司 察尔汗 PVC&钾碱厂 | D25: 青海省 | E25: 格尔木市 | F25: 察尔汗 | G25: 柴达木循环经济试验区察尔汗 | H25: 青海盐湖镁业有限公司 | I25: 盐湖镁业 | J25: 30 | K25: 1 | L25: 乙烯法 | M25: 青海省海西州格尔木市察尔汗 | N25: 36.7900,95.0900 | O25: city
A26: P170 | B26: 平顶山基地（神马氯碱） | C26: 河南神马氯碱发展有限责任公司 PVC 生产基地 | D26: 河南省 | E26: 平顶山市 | G26: （具体园区待核） | H26: 河南神马氯碱发展有限责任公司 | I26: 神马氯碱 | J26: 30 | K26: 1 | L26: 电石法（乙炔法） | M26: 河南省平顶山市 | N26: 33.7700,113.1900 | O26: city
A27: P302 | B27: 嘉兴港区基地（嘉化能源） | C27: 浙江嘉化能源化工股份有限公司 嘉兴港区 PVC 生产基地 | D27: 浙江省 | E27: 嘉兴市 | F27: 嘉兴港区 | G27: 嘉兴港区化工新材料园区 | H27: 浙江嘉化能源化工股份有限公司 | I27: 嘉化能源 | J27: 30 | K27: 1 | L27: 乙烯法 | M27: 浙江省嘉兴市嘉兴港区 | N27: 30.6100,121.1000 | O27: city
A28: P306 | B28: 兰州新区基地（耀望化工） | C28: 甘肃耀望化工有限公司 PVC 生产基地 | D28: 甘肃省 | E28: 兰州新区 | G28: 兰州新区化工园区 | H28: 甘肃耀望化工有限公司 | I28: 耀望化工 | J28: 30 | K28: 1 | L28: 电石法（乙炔法） | M28: 甘肃省兰州新区 | N28: 36.5500,103.7200 | O28: city
A29: P003 | B29: 托克逊基地（托克逊能化） | C29: 新疆中泰化学托克逊能化有限公司 托克逊工业园 PVC 生产基地 | D29: 新疆维吾尔自治区 | E29: 托克逊县 | G29: 托克逊能源重化工工业园 | H29: 新疆中泰化学托克逊能化有限公司 | I29: 中泰集团 | J29: 29 | K29: 3 | L29: 电石法（乙炔法） | M29: 新疆吐鲁番市托克逊县工业园区第三辅道南侧 | N29: 42.7900,88.6500 | O29: city
A30: P190 | B30: 广州南沙基地（东曹） | C30: 东曹（广州）化工有限公司 PVC 生产基地 | D30: 广东省 | E30: 广州市 | F30: 南沙区 | G30: 南沙经济技术开发区 | H30: 东曹（广州）化工有限公司 | I30: 东曹广州 | J30: 22 | K30: 1 | L30: 乙烯法 | M30: 广东省广州市南沙区 | N30: 22.8000,113.5300 | O30: city
A31: P001 | B31: 米东基地（华泰重化工） | C31: 新疆华泰重化工有限责任公司 米东工业园 PVC 生产基地 | D31: 新疆维吾尔自治区 | E31: 乌鲁木齐市 | F31: 米东区 | G31: 米东工业园 | H31: 新疆华泰重化工有限责任公司 | I31: 中泰集团 | J31: 0 | K31: 0 | L31: 电石法（乙炔法） | M31: 新疆乌鲁木齐市米东区 | N31: 43.9600,87.6500 | O31: city
A32: P004 | B32: 圣雄基地（圣雄能源） | C32: 新疆圣雄能源股份有限公司 PVC 生产基地 | D32: 新疆维吾尔自治区 | E32: 吐鲁番市 | G32: 圣雄工业园 | H32: 新疆圣雄能源股份有限公司 | I32: 中泰集团 | J32: 0 | K32: 0 | L32: 电石法（乙炔法） | M32: 新疆吐鲁番市 | N32: 42.9500,89.1900 | O32: city
A33: P040 | B33: 青海宜化基地 | C33: 青海宜化化工有限责任公司 PVC 生产基地 | D33: 青海省 | E33: 西宁市 | G33: （具体园区待核） | H33: 青海宜化化工有限责任公司 | I33: 宜化集团 | J33: 0 | K33: 0 | L33: 电石法（乙炔法） | M33: 青海省 | N33: 36.6200,101.7800 | O33: province
A34: P041 | B34: 准东五彩湾基地（新疆宜化） | C34: 新疆宜化化工有限公司 准东经济技术开发区 PVC 生产基地 | D34: 新疆维吾尔自治区 | E34: 准东经济开发区 | G34: 准东经济技术开发区（五彩湾） | H34: 新疆宜化化工有限公司 | I34: 宜化集团 | J34: 0 | K34: 0 | L34: 电石法（乙炔法） | M34: 新疆昌吉州准东经济技术开发区 | N34: 44.6800,89.1000 | O34: city
A35: P042 | B35: 内蒙古宜化基地 | C35: 内蒙古宜化化工有限公司 PVC 生产基地 | D35: 内蒙古自治区 | E35: 乌海市 | G35: （具体园区待核） | H35: 内蒙古宜化化工有限公司 | I35: 宜化集团 | J35: 0 | K35: 0 | L35: 工艺未核实 | M35: 内蒙古乌海市 | N35: 39.6600,106.7900 | O35: city
A36: P070 | B36: 惠农基地（英力特） | C36: 宁夏英力特化工股份有限公司 PVC 生产基地 | D36: 宁夏回族自治区 | E36: 石嘴山市 | F36: 惠农区 | G36: 惠农区钢电路 41 号 | H36: 宁夏英力特化工股份有限公司 | I36: 英力特 | J36: 0 | K36: 0 | L36: 电石法（乙炔法） | M36: 宁夏石嘴山市惠农区钢电路 41 号 | N36: 39.2400,106.7700 | O36: city
A37: P200 | B37: 海南区海化工业园基地（乌海化工，长期停车） | C37: 内蒙古乌海化工有限公司 PVC 生产基地（破产重整中） | D37: 内蒙古自治区 | E37: 乌海市 | F37: 海南区 | G37: 海化工业园区 | H37: 内蒙古乌海化工有限公司 | I37: 鸿达兴业 | J37: 0 | K37: 0 | L37: 电石法（乙炔法） | M37: 内蒙古乌海市海南区海化工业园区 | N37: 39.4500,106.8700 | O37: city
A38: P300 | B38: 江阴港城东部片区（万融） | C38: 万融新材料（福建）有限公司 江阴港城经济区东部片区 PVC 项目基地 | D38: 福建省 | E38: 福清市 | F38: 江阴港城经济区 | G38: 江阴港城经济区东部片区 | H38: 万融新材料（福建）有限公司 | I38: 万华化学 | J38: 0 | K38: 0 | M38: 福建省福州市福清市江阴港城经济区 | N38: 25.5200,119.3500 | O38: city
A39: P301 | B39: 十户滩新材料工业园（天业集团） | C39: 新疆天业（集团）有限公司 十户滩新材料工业园 PVC 项目基地 | D39: 新疆维吾尔自治区 | E39: 石河子市 | F39: 147 团 | G39: 十户滩新材料工业园 | H39: 新疆天业（集团）有限公司 | I39: 天业集团 | J39: 0 | K39: 0 | M39: 新疆石河子市 147 团 | N39: 44.4500,86.1500 | O39: city
A40: P303 | B40: 乐平铺基地（信发华兴） | C40: 茌平信发华兴化工有限公司 乐平铺 PVC 生产基地 | D40: 山东省 | E40: 聊城市 | F40: 茌平区乐平铺镇 | G40: 茌平信发工业园 | H40: 茌平信发华兴化工有限公司 | I40: 信发集团 | J40: 0 | K40: 0 | M40: 山东省聊城市茌平区乐平铺镇 | N40: 36.5200,116.1000 | O40: city
A41: P308 | B41: 宁波基地（镇洋发展） | C41: 浙江镇洋发展股份有限公司 PVC 生产基地 | D41: 浙江省 | E41: 宁波市 | F41: 镇海区 | G41: 宁波石化经济技术开发区 | H41: 浙江镇洋发展股份有限公司 | I41: 镇洋发展 | J41: 0 | K41: 0 | L41: 乙烯法 | M41: 浙江省宁波市镇海区 | N41: 29.9500,121.6500 | O41: city
...

Sheet 06_装置明细
A1: 装置级明细（唯一事实层 / Head of Truth）
A2: 一行 = 一个装置的一条产能事实；全部汇总表均引用本表
A4: 装置ID | B4: 省 | C4: 市 | D4: 基地 | E4: 运营法人 | F4: 集团 | G4: 产品/牌号 | H4: 产品等级 | I4: 工艺路线 | J4: 工艺备注 | K4: 产能口径 | L4: 产能(万吨/年) | M4: 原文表述 | N4: 数据年份 | O4: 投产年份 | P4: 运行状态 | Q4: 状态说明 | R4: 配套自产电石 | S4: 来源编号 | T4: 可信度 | U4: 来源标题 | V4: 来源URL | W4: 来源日期
A5: U-P001-01 | B5: 新疆维吾尔自治区 | C5: 乌鲁木齐市 | D5: 米东基地（华泰重化工） | E5: 新疆华泰重化工有限责任公司 | F5: 中泰集团 | G5: 聚氯乙烯树脂 | H5: 未细分 | I5: 电石法（乙炔法） | J5: 电石法 | K5: 设计产能 | M5: 中泰化学 2025 年报仅披露合并口径 260 万吨/年，未拆分至华泰/阜康/托克逊/圣雄各厂 | N5: 2025 | P5: 在产 | Q5: 生产中 | R5: 是 | S5: S01 | T5: A | U5: 新疆中泰化学股份有限公司 2025 年年度报告 | V5: https://static.cninfo.com.cn/finalpage/2026-03-26/1225033261.PDF | W5: 2026-03-26
A6: U-P002-01 | B6: 新疆维吾尔自治区 | C6: 阜康市 | D6: 阜康基地（阜康能源） | E6: 新疆中泰化学阜康能源有限公司 | F6: 中泰集团 | G6: 聚氯乙烯树脂（悬浮法通用型） | H6: 通用树脂（纯粉） | I6: 电石法（乙炔法） | J6: 以电石为原料 | K6: 设计产能 | L6: 80 | M6: 取 80 万吨（新疆国资委 2022-07 通稿：阜康能源年产 80 万吨聚氯乙烯树脂 + 60 万吨离子膜烧碱，2012 年 9 月一次开车成功，称「国内最大的氯碱单套装置产业基地」）。⚠ 口径冲突：新疆生态环境厅 2023-11 环评后评价公示载「设计规模 年产聚氯乙烯 40 万吨、离子膜烧碱 30 万吨」。两个数字差一倍，可能是「一期 40 万吨」与「一二期合计 80 万吨」之别，也可能环评仅覆盖单个厂区。本报告取 80 万吨并在 15_口径对比 中并列保留 40 万吨作为下行情景，不取平均。 | N6: 2022 | O6: 2012 | P6: 在产 | Q6: 2012-09 一次性开车成功 | R6: 是 | S6: S46 | T6: A | U6: 新疆国资委：中泰集团 科技创新为产业发展注入「绿色基因」 | V6: https://gzw.xinjiang.gov.cn/gzw/gzyw/202207/5984c184046d47bb82f3d3c0a883bf63.shtml | W6: 2022-07-27
A7: U-P003-02 | B7: 新疆维吾尔自治区 | C7: 托克逊县 | D7: 托克逊基地（托克逊能化） | E7: 新疆中泰化学托克逊能化有限公司 | F7: 中泰集团 | G7: 聚氯乙烯糊树脂（EPVC） | H7: 糊树脂 | I7: 电石法（乙炔法） | J7: 本体法/乳液法 | K7: 设计产能 | L7: 6 | M7: 同一项目：6 万吨糊树脂装置 + 3 万吨降粘树脂装置 | N7: 2020 | O7: 2020 | P7: 在产 | Q7: 2020-10 转固 | R7: 是 | S7: S48 | T7: B | U7: 中泰化学托克逊能化 30 万吨高性能树脂项目投产 | V7: http://www.cppia.com.cn/front/article/20895/500 | W7: 2020
A8: U-P003-01 | B8: 新疆维吾尔自治区 | C8: 托克逊县 | D8: 托克逊基地（托克逊能化） | E8: 新疆中泰化学托克逊能化有限公司 | F8: 中泰集团 | G8: 聚氯乙烯（本体法树脂） | H8: 专用料 | I8: 电石法（乙炔法） | J8: 配套 30 万吨高纯 VCM，电石法 | K8: 设计产能 | L8: 20 | M8: 托克逊能化 30 万吨高性能树脂项目：20 万吨本体法 PVC 树脂装置 | N8: 2020 | O8: 2020 | P8: 在产 | Q8: 2020-10 转固 | R8: 是 | S8: S48 | T8: B | U8: 中泰化学托克逊能化 30 万吨高性能树脂项目投产 | V8: http://www.cppia.com.cn/front/article/20895/500 | W8: 2020
A9: U-P003-03 | B9: 新疆维吾尔自治区 | C9: 托克逊县 | D9: 托克逊基地（托克逊能化） | E9: 新疆中泰化学托克逊能化有限公司 | F9: 中泰集团 | G9: 聚氯乙烯（降粘树脂） | H9: 特种树脂 | I9: 电石法（乙炔法） | J9: 配套本体法 | K9: 设计产能 | L9: 3 | M9: 同一项目：3 万吨降粘树脂装置 | N9: 2020 | O9: 2020 | P9: 在产 | R9: 是 | S9: S48 | T9: B | U9: 中泰化学托克逊能化 30 万吨高性能树脂项目投产 | V9: http://www.cppia.com.cn/front/article/20895/500 | W9: 2020
A10: U-P004-01 | B10: 新疆维吾尔自治区 | C10: 吐鲁番市 | D10: 圣雄基地（圣雄能源） | E10: 新疆圣雄能源股份有限公司 | F10: 中泰集团 | G10: 聚氯乙烯树脂 | H10: 未细分 | I10: 电石法（乙炔法） | J10: 电石法 | K10: 设计产能 | M10: 未拆分（圣雄能源并于中泰化学合并口径） | N10: 2025 | P10: 在产 | Q10: 生产中 | R10: 是 | S10: S01 | T10: A | U10: 新疆中泰化学股份有限公司 2025 年年度报告 | V10: https://static.cninfo.com.cn/finalpage/2026-03-26/1225033261.PDF | W10: 2026-03-26
A11: U-P010-03 | B11: 新疆维吾尔自治区 | C11: 石河子市 | D11: 石河子化工园区基地（综合） | E11: 新疆天业股份有限公司 | F11: 天业集团 | G11: 聚氯乙烯糊树脂（EPVC） | H11: 糊树脂 | I11: 电石法（乙炔法） | J11: 电石法 | K11: 设计产能 | L11: 10 | M11: 同上，年产 20 万吨特种 PVC 装置中的糊树脂部分 | N11: 2025 | P11: 在产 | R11: 是 | S11: S02 | T11: A | U11: 新疆天业股份有限公司 2025 年度报告 | V11: https://money.finance.sina.com.cn/corp/view/vCB_AllBulletinDetail.php?stockid=600075&id=12071824 | W11: 2026-04-10
A12: U-P010-02 | B12: 新疆维吾尔自治区 | C12: 石河子市 | D12: 石河子化工园区基地（综合） | E12: 新疆天业股份有限公司 | F12: 天业集团 | G12: 聚氯乙烯（特种树脂 SPVC） | H12: 特种树脂 | I12: 电石法（乙炔法） | J12: 电石法 | K12: 设计产能 | L12: 10 | M12: 年报：年产 20 万吨特种 PVC 装置 → 10 万吨特种树脂 + 10 万吨糊树脂；利用率 103.44% | N12: 2025 | P12: 在产 | Q12: 利用率 103.44% | R12: 是 | S12: S02 | T12: A | U12: 新疆天业股份有限公司 2025 年度报告 | V12: https://money.finance.sina.com.cn/corp/view/vCB_AllBulletinDetail.php?stockid=600075&id=12071824 | W12: 2026-04-10
A13: U-P010-01 | B13: 新疆维吾尔自治区 | C13: 石河子市 | D13: 石河子化工园区基地（综合） | E13: 新疆天业股份有限公司 | F13: 天业集团 | G13: 聚氯乙烯（通用 PVC 树脂） | H13: 通用树脂（纯粉） | I13: 电石法（乙炔法） | J13: 电石法 | K13: 设计产能 | L13: 114 | M13: 年报：年产 114 万吨 PVC 装置 → 114 万吨 PVC 树脂；产能利用率 95.33% | N13: 2025 | P13: 在产 | Q13: 利用率 95.33% | R13: 是 | S13: S02 | T13: A | U13: 新疆天业股份有限公司 2025 年度报告 | V13: https://money.finance.sina.com.cn/corp/view/vCB_AllBulletinDetail.php?stockid=600075&id=12071824 | W13: 2026-04-10
A14: U-P020-01 | B14: 陕西省 | C14: 神木市 | D14: 锦界园区基地（北元） | E14: 陕西北元化工集团股份有限公司 | F14: 北元集团 | G14: 聚氯乙烯树脂 | H14: 未细分 | I14: 电石法（乙炔法） | J14: 乙炔法（电石法） | K14: 设计产能 | L14: 110 | M14: 年报：公司现具有 110 万吨/年聚氯乙烯、80 万吨/年离子膜烧碱、220 万吨/年水泥、50 万吨/年电石；产能利用率 123.67%，无在建产能 | N14: 2025 | P14: 在产 | Q14: 利用率 123.67%（超产） | R14: 是 | S14: S05 | T14: A | U14: 陕西北元化工集团股份有限公司 2025 年年度报告 | V14: https://static.cninfo.com.cn/finalpage/2026-04-23/1225144565.PDF | W14: 2026-04-23
A15: U-P030-01 | B15: 内蒙古自治区 | C15: 乌海市 | D15: 乌达工业园区基地（君正） | E15: 内蒙古君正化工有限责任公司 | F15: 君正集团 | G15: 聚氯乙烯树脂 | H15: 未细分 | I15: 电石法（乙炔法） | J15: 年报称「乙炔法聚氯乙烯制备」 | K15: 设计产能 | L15: 80 | M15: 年报：树脂项目 80 万吨/年，产能利用率 110.74%；电石 238.3 万吨/年 | N15: 2025 | P15: 在产 | Q15: 利用率 110.74% | R15: 是 | S15: S06 | T15: A | U15: 内蒙古君正能源化工集团股份有限公司 2025 年年度报告 | V15: https://money.finance.sina.com.cn/corp/view/vCB_AllBulletinDetail.php?stockid=601216&id=12182384 | W15: 2026-04-25
A16: U-P040-01 | B16: 青海省 | C16: 西宁市 | D16: 青海宜化基地 | E16: 青海宜化化工有限责任公司 | F16: 宜化集团 | G16: 聚氯乙烯树脂 | H16: 未细分 | I16: 电石法（乙炔法） | J16: 电石法 | K16: 核定/批复产能 | L16: 30 | M16: 安全生产许可证许可产能：聚氯乙烯 30 万 t/a、氯乙烯 30 万 t/a | N16: 2025 | P16: 在产 | Q16: 许可在有效期内，推定在产 | R16: 未知 | S16: S08 | T16: A | U16: 湖北宜化化工股份有限公司 2025 年年度报告 | V16: https://money.finance.sina.com.cn/corp/view/vCB_AllBulletinDetail.php?stockid=000422&id=12190431 | W16: 2026-04-14
A17: U-P040-02 | B17: 青海省 | C17: 西宁市 | D17: 青海宜化基地 | E17: 青海宜化化工有限责任公司 | F17: 宜化集团 | G17: 聚氯乙烯树脂 | H17: 未细分 | I17: 电石法（乙炔法） | J17: 电石法 | K17: 设计产能 | M17: 湖北宜化合并 90 万吨中归属青海宜化的部分未单独披露（安全许可 30 万 t/a 见 U-P040-01） | N17: 2025 | P17: 状态未核实 | Q17: 2025 年报注：本年度存在部分 PVC 装置关停，具体厂址未披露 | R17: 未知 | S17: S08 | T17: A | U17: 湖北宜化化工股份有限公司 2025 年年度报告 | V17: https://money.finance.sina.com.cn/corp/view/vCB_AllBulletinDetail.php?stockid=000422&id=12190431 | W17: 2026-04-14
A18: U-P041-01 | B18: 新疆维吾尔自治区 | C18: 准东经济开发区 | D18: 准东五彩湾基地（新疆宜化） | E18: 新疆宜化化工有限公司 | F18: 宜化集团 | G18: 聚氯乙烯树脂 | H18: 未细分 | I18: 电石法（乙炔法） | J18: 电石法 | K18: 核定/批复产能 | L18: 30 | M18: 年报：新疆宜化新增主要产品年产能 PVC 30 万吨；安全许可另列 VCM 30 万吨、烧碱 25 万吨 | N18: 2025 | P18: 在产 | Q18: 氯碱分厂安全许可未单列「聚氯乙烯」条目，存疑 | R18: 是 | S18: S08 | T18: A | U18: 湖北宜化化工股份有限公司 2025 年年度报告 | V18: https://money.finance.sina.com.cn/corp/view/vCB_AllBulletinDetail.php?stockid=000422&id=12190431 | W18: 2026-04-14
A19: U-P042-01 | B19: 内蒙古自治区 | C19: 乌海市 | D19: 内蒙古宜化基地 | E19: 内蒙古宜化化工有限公司 | F19: 宜化集团 | G19: 聚氯乙烯树脂 | H19: 未细分 | I19: 工艺未核实 | J19: 未核实 | K19: 设计产能 | M19: 年报安全许可证未列聚氯乙烯条目（仅列碳化钙 66 万吨、氢氧化钠 30 万吨、氯 18 万吨）；旧资料「40 万吨 PVC」与之冲突，未采信 | N19: 2025 | P19: 状态未核实 | Q19: 待核（见数据缺口 G-03） | R19: 未知 | S19: S08 | T19: A | U19: 湖北宜化化工股份有限公司 2025 年年度报告 | V19: https://money.finance.sina.com.cn/corp/view/vCB_AllBulletinDetail.php?stockid=000422&id=12190431 | W19: 2026-04-14
A20: U-P050-02 | B20: 上海市 | C20: 上海市 | D20: 上海化工区基地（氯碱化工） | E20: 上海氯碱化工股份有限公司 | F20: 华谊集团 | G20: 特种聚氯乙烯树脂 | H20: 特种树脂 | I20: 乙烯法 | J20: 乙烯法 | K20: 设计产能 | L20: 8 | M20: 年报产能表：特种聚氯乙烯 8 万吨 | N20: 2025 | P20: 在产 | Q20: 利用率约 100% | R20: 否 | S20: S09 | T20: A | U20: 上海氯碱化工股份有限公司 2025 年年度报告 | V20: https://money.finance.sina.com.cn/corp/view/vCB_AllBulletinDetail.php?stockid=600618&id=12116978 | W20: 2026-04-14
A21: U-P050-01 | B21: 上海市 | C21: 上海市 | D21: 上海化工区基地（氯碱化工） | E21: 上海氯碱化工股份有限公司 | F21: 华谊集团 | G21: 聚氯乙烯树脂（悬浮法） | H21: 通用树脂（纯粉） | I21: 乙烯法 | J21: 乙烯法 | K21: 设计产能 | L21: 40 | M21: 年报产能表：聚氯乙烯 40 万吨 | N21: 2025 | P21: 在产 | Q21: 利用率约 100% | R21: 否 | S21: S09 | T21: A | U21: 上海氯碱化工股份有限公司 2025 年年度报告 | V21: https://money.finance.sina.com.cn/corp/view/vCB_AllBulletinDetail.php?stockid=600618&id=12116978 | W21: 2026-04-14
A22: U-P051-01 | B22: 广西壮族自治区 | C22: 钦州市 | D22: 钦州基地（广西氯碱） | E22: 广西华谊氯碱化工有限公司 | F22: 华谊集团 | G22: 聚氯乙烯树脂 | H22: 未细分 | I22: 乙烯法 | J22: 乙烯法，配 5 万 m³ 低温乙烯储罐 | K22: 设计产能 | L22: 40 | M22: 广西钦州 30 万吨/年烧碱、40 万吨/年聚氯乙烯项目，2019 年投资建设；2022-11-30 首批产品下线 | N22: 2024 | O22: 2022 | P22: 在产 | Q22: 已投产 | R22: 否 | S22: S10 | T22: B | U22: 氯碱化工拟 6.85 亿收购广西氯碱 40% 股权 | V22: https://www.stcn.com/article/detail/1213318.html | W22: 2024-05-23
A23: U-P060-01 | B23: 内蒙古自治区 | C23: 阿拉善盟 | D23: 吉兰泰基地（中盐吉兰泰） | E23: 中盐吉兰泰氯碱化工有限公司 | F23: 中盐化工 | G23: 聚氯乙烯树脂 | H23: 未细分 | I23: 电石法（乙炔法） | J23: 电石法 | K23: 设计产能 | L23: 40 | M23: 中盐内蒙古化工 2025 年报：树脂 40 万吨 + 糊树脂 24 万吨，产能利用率 106.08%（电石法，自备电石）。本行为树脂 40 万吨部分。 | N23: 2025 | O23: 2011 | P23: 在产 | Q23: 利用率 106.08% | R23: 是 | S23: S11 | T23: A | U23: 中盐内蒙古化工股份有限公司 2025 年年度报告摘要 | V23: http://xinpi.zqrb.cn/pdf/SH/600328/2026/0430/7f22920af9a2cf45f8a2b1b4f84933e7df.pdf | W23: 2026-04-30
A24: U-P060-02 | B24: 内蒙古自治区 | C24: 阿拉善盟 | D24: 吉兰泰基地（中盐吉兰泰） | E24: 中盐吉兰泰氯碱化工有限公司 | F24: 中盐化工 | G24: 聚氯乙烯糊树脂（EPVC） | H24: 糊树脂 | I24: 电石法（乙炔法） | J24: 电石法 | K24: 设计产能 | L24: 24 | M24: 中盐内蒙古化工 2025 年报：糊树脂 24 万吨（与树脂 40 万吨分列） | N24: 2025 | P24: 在产 | Q24: 利用率 106.08%（合并口径） | R24: 是 | S24: S11 | T24: A | U24: 中盐内蒙古化工股份有限公司 2025 年年度报告摘要 | V24: http://xinpi.zqrb.cn/pdf/SH/600328/2026/0430/7f22920af9a2cf45f8a2b1b4f84933e7df.pdf | W24: 2026-04-30
A25: U-P070-01 | B25: 宁夏回族自治区 | C25: 石嘴山市 | D25: 惠农基地（英力特） | E25: 宁夏英力特化工股份有限公司 | F25: 英力特 | G25: 聚氯乙烯树脂 | H25: 通用树脂（纯粉） | I25: 电石法（乙炔法） | J25: 电石法 | K25: 设计产能 | L25: 22 | M25: 官网：年产电石 40 万吨、聚氯乙烯 26 万吨（含糊树脂 4 万吨）、烧碱 19 万吨 ⇒ 纯粉 22 万吨 | N25: 2025 | P25: 长期停车 | Q25: 2026-09-22 公告：氯碱运行部生产线（PVC）+ 部分电石装置临时停产，理由为 PVC 价格不及预期；已连亏四年。年报口径仍为 22 万吨。 | R25: 是 | S25: S13 | T25: A | U25: 宁夏英力特化工股份有限公司 公司简介 | V25: http://ylthg.chnenergy.com.cn/nxyltww/gsjj/listcontent.shtml | W25: 2025
A26: U-P070-02 | B26: 宁夏回族自治区 | C26: 石嘴山市 | D26: 惠农基地（英力特） | E26: 宁夏英力特化工股份有限公司 | F26: 英力特 | G26: 聚氯乙烯糊树脂（EPVC） | H26: 糊树脂 | I26: 电石法（乙炔法） | J26: 电石法 | K26: 设计产能 | L26: 4 | M26: 同上，26 万吨中含糊树脂 4 万吨 | N26: 2025 | P26: 长期停车 | Q26: 同上 | R26: 是 | S26: S13 | T26: A | U26: 宁夏英力特化工股份有限公司 公司简介 | V26: http://ylthg.chnenergy.com.cn/nxyltww/gsjj/listcontent.shtml | W26: 2025
A27: U-P080-02 | B27: 河北省 | C27: 唐山市 | D27: 南堡基地（三友氯碱） | E27: 唐山三友氯碱有限责任公司 | F27: 三友化工 | G27: 聚氯乙烯专用树脂 | H27: 专用料 | I27: 电石法（乙炔法） | J27: 电石法 | K27: 设计产能 | L27: 7 | M27: 三友氯碱：7 万吨聚氯乙烯专用树脂生产线 | N27: 2026 | P27: 在产 | Q27: 产能利用率 80.00%（2025 年报，合并口径） | R27: 未知 | S27: S15 | T27: A | U27: 唐山三友化工股份有限公司主体长期信用评级报告 | V27: https://www.lhratings.com/uploads/file/20261016/g39fff68a7e.pdf | W27: 2026-10-16
A28: U-P080-01 | B28: 河北省 | C28: 唐山市 | D28: 南堡基地（三友氯碱） | E28: 唐山三友氯碱有限责任公司 | F28: 三友化工 | G28: 聚氯乙烯树脂 | H28: 通用树脂（纯粉） | I28: 电石法（乙炔法） | J28: 官网标「电石法」，品种 SG3/SG5/SG8/2500 | K28: 设计产能 | L28: 40 | M28: 三友氯碱：40 万吨聚氯乙烯树脂生产线；评级报告合计 52.5 万吨 PVC（含 7 万吨专用树脂及 5.5 万吨其他） | N28: 2026 | P28: 在产 | Q28: 产能利用率 80.00%（2025 年报） | R28: 未知 | S28: S15 | T28: A | U28: 唐山三友化工股份有限公司主体长期信用评级报告 | V28: https://www.lhratings.com/uploads/file/20261016/g39fff68a7e.pdf | W28: 2026-10-16
A29: U-P090-01 | B29: 安徽省 | C29: 滁州市 | D29: 定远基地（华塑） | E29: 安徽华塑股份有限公司 | F29: 华塑股份 | G29: 聚氯乙烯树脂 | H29: 未细分 | I29: 电石法（乙炔法） | J29: 电石法，一体化（原盐/灰岩—电石—PVC） | K29: 设计产能 | L29: 64 | M29: 2026 半年报：公司现有 PVC 产能 64 万吨/年、烧碱产能 48 万吨/年 | N29: 2026 | P29: 在产 | Q29: 产能利用率 90.63%（2025 年报） | R29: 是 | S29: S18 | T29: A | U29: 安徽华塑股份有限公司 2026 年半年度报告 | V29: https://stockmc.xueqiu.com/202608/600935_20260826_Q61P.pdf | W29: 2026-08-26
A30: U-P100-01 | B30: 天津市 | C30: 天津市 | D30: 临港基地（大沽化工） | E30: 天津大沽化工股份有限公司 | F30: 渤化集团 | G30: 聚氯乙烯树脂（悬浮法，一期） | H30: 未细分 | I30: 乙烯法 | J30: 由电石法改为乙烯法（两化搬迁 + 工艺革新） | K30: 设计产能 | L30: 40 | M30: 渤化集团官网：PVC 80 万吨（60 万吨/年离子膜烧碱 + 80 万吨/年 PVC 项目）。此处 40 万吨为一期口径（2021-12 试车投产）；二期 40 万吨见 U-P100-02（2025-09-28 全面投产）。两者合计 120 万吨 = 渤化集团 PVC 总产能。2022 年起不再采购电石 ⇒ 乙烯法。 | N30: 2021 | O30: 2021 | P30: 在产 | Q30: 2021-12 试车投产 ｜ 塘沽老厂区 2022 年关停，主体迁天津南港工业区 | R30: 否 | S30: S19 | T30: A | U30: 天津渤海化工集团 氯碱化工 产品与服务 | V30: https://www.bcig.cn/cpfw/6991255165038759936.html | W30: 2025
A31: U-P100-02 | B31: 天津市 | C31: 天津市 | D31: 临港基地（大沽化工） | E31: 天津大沽化工股份有限公司 | F31: 渤化集团 | G31: 聚氯乙烯树脂（悬浮法，二期） | H31: 未细分 | I31: 乙烯法 | J31: 乙烯法，替代原电石法产能 | K31: 设计产能 | L31: 40 | M31: PVC 二期 40 万吨，2025-09-28 全面投产，乙烯法替代原电石法；投产后渤化 PVC 总产能 120 万吨 | N31: 2025 | O31: 2025 | P31: 在产 | Q31: 2025-09-28 全面投产 ｜ 塘沽老厂区 2022 年关停，主体迁天津南港工业区 | R31: 否 | S31: S67 | T31: B | U31: 天津渤海化工集团 PVC 二期 40 万吨 2025-09-28 全面投产（PVC 总产能 120 万吨，乙烯法替代电石法） | W31: 2025-09-28
A32: U-P110-02 | B32: 山东省 | C32: 青岛市 | D32: 董家口基地（海湾化学） | E32: 青岛海湾化学股份有限公司 | F32: 海湾集团 | G32: 聚氯乙烯树脂（2025 年新增线） | H32: 未细分 | I32: 乙烯法 | J32: 乙烯法 | K32: 设计产能 | L32: 20 | M32: 青岛海湾化学 2025 年 8—9 月试车的 20 万吨新增产能；现有 85 万吨见 U-P110-01 | N32: 2025 | O32: 2025 | P32: 在产 | Q32: 2025-08 起试车 | R32: 否 | S32: S22 | T32: B | U32: 青岛海湾化学撤回沪主板 IPO 原计划募资 30 亿元 | V32: https://www.stcn.com/article/detail/2185695.html | W32: 2024
A33: U-P110-01 | B33: 山东省 | C33: 青岛市 | D33: 董家口基地（海湾化学） | E33: 青岛海湾化学股份有限公司 | F33: 海湾集团 | G33: 聚氯乙烯树脂（乙烯法） | H33: 未细分 | I33: 乙烯法 | J33: 英国英力士乙烯法技术 | K33: 设计产能 | L33: 85 | M33: 证券时报：已建成投产 85 万吨/年乙烯法 PVC、55.5 万吨/年烧碱；招股书口径 2021 年为 70 万吨/年 | N33: 2025 | O33: 2020 | P33: 在产 | Q33: PVC 二期与烧碱二期 2020 年底投产；2025 年 8—9 月新增 20 万吨试车 | R33: 否 | S33: S22 | T33: B | U33: 青岛海湾化学撤回沪主板 IPO 原计划募资 30 亿元 | V33: https://www.stcn.com/article/detail/2185695.html | W33: 2024
A34: U-P120-01 | B34: 山东省 | C34: 烟台市 | D34: 烟台工业园基地（万华） | E34: 万华化学集团股份有限公司 | F34: 万华化学 | G34: 聚氯乙烯树脂（高品质） | H34: 专用料 | I34: 乙烯法 | J34: 乙烯法（自有 100 万吨/年乙烯裂解） | K34: 设计产能 | L34: 40 | M34: 乙烯一期配套 40 万吨/年聚氯乙烯装置（2020-11 投产）；改造后 VCM 工序 48 万吨/年、PVC 工序产能不变 | N34: 2024 | O34: 2020 | P34: 在产 | Q34: 2020-11 投产 | R34: 否 | S34: S26 | T34: B | U34: 万华化学再上三个项目（VCM/PVC 改造） | V34: https://zh.echemi.com/cn-news-market/1041630.html | W34: 2024
A35: U-P130-01 | B35: 山西省 | C35: 阳泉市 | D35: 阳泉基地（阳煤化工） | E35: 阳煤化工股份有限公司 | F35: 阳煤化工 | G35: 聚氯乙烯树脂 | H35: 未细分 | I35: 乙烯法 | J35: 乙烯法（MTO+OCP 氧氯化） | K35: 设计产能 | L35: 30 | M35: 阳煤化工 2024 年报：PVC 设计产能 30 万吨/年，产能利用率 83.53%（对应产量约 25.06 万吨）。工艺为「以乙烯、氯气、氢气为原料，采用氧氯化平衡法和直接氯化法」，配套 UOP/Total MTO+OCP 烯烃装置 ⇒ 乙烯法。 | N35: 2024 | P35: 在产 | Q35: 利用率 83.53%；2025 年报巨潮不可得，运行状态以 2024 年报为准 | R35: 否 | S35: S27 | T35: A | U35: 阳煤化工股份有限公司 2024 年年度报告 | V35: https://stockn.xueqiu.com/SH600691/20250418271414.pdf | W35: 2025-04-18
A36: U-P140-01 | B36: 内蒙古自治区 | C36: 鄂尔多斯市 | D36: 达拉特基地（亿利化学） | E36: 内蒙古亿利化学工业有限公司 | F36: 亿利集团 | G36: 聚氯乙烯树脂 | H36: 未细分 | I36: 电石法（乙炔法） | J36: 电石法，配套 64 万吨电石 | K36: 设计产能 | L36: 50 | M36: 财联社：具备年产 50 万吨 PVC、40 万吨离子膜烧碱、64 万吨电石能力；至 2020 年连续六年突破设计产能 | N36: 2021 | P36: 状态未核实 | Q36: 亿利洁能 2022 年报口径（利用率 102.67%）；巨潮无 2023 年后年报，2023—2026 运行状态未知 | R36: 是 | S36: S38 | T36: B | U36: 亿利洁能：公司旗下亿利化学公司负责生产经营 PVC 业务 | V36: https://www.cls.cn/detail/537069 | W36: 2021
A37: U-P150-01 | B37: 内蒙古自治区 | C37: 鄂尔多斯市 | D37: 棋盘井基地（鄂尔多斯电冶） | E37: 内蒙古鄂尔多斯电力冶金集团股份有限公司氯碱化工分公司 | F37: 鄂尔多斯电冶 | G37: 聚氯乙烯树脂 | H37: 未细分 | I37: 电石法（乙炔法） | J37: 电石法，全球首套全装填无汞催化剂（2023-02） | K37: 设计产能 | L37: 40 | M37: 新华网：电冶集团氯碱化工分公司每年 40 万吨电石法聚氯乙烯及烧碱项目 | N37: 2023 | P37: 在产 | Q37: 全面无汞化生产 | R37: 是 | S37: S35 | T37: A | U37: 全球首家电石法聚氯乙烯（PVC）无汞化生产技术发布 | V37: http://www.news.cn/energy/20230220/468b29ee619b4f1094d1ef66d39f5efc/c.html | W37: 2023-02-20
A38: U-P160-01 | B38: 青海省 | C38: 格尔木市 | D38: 察尔汗基地（盐湖镁业） | E38: 青海盐湖镁业有限公司 | F38: 盐湖镁业 | G38: 聚氯乙烯树脂（乙烯法） | H38: 未细分 | I38: 乙烯法 | J38: 煤制烯烃/盐湖一体化耦合的乙烯法 | K38: 设计产能 | L38: 30 | M38: PVC&钾碱厂 30 万吨乙烯法 PVC 装置，2016 年投产；另有盐湖股份口径「高海拔地区年产 30 万吨乙烯法 PVC 产业化示范项目」 | N38: 2025 | O38: 2016 | P38: 在产 | Q38: 2016 年投产 | R38: 否 | S38: S36 | T38: B | U38: 中控技术中标青海盐湖镁业 PVC&钾碱厂 30 万吨乙烯法 PVC 装置智能化改造 | V38: https://www.stcn.com/article/kx-tag-detail.html?tag=7eDS25QMj9CV | W38: 2025-09
A39: U-P170-01 | B39: 河南省 | C39: 平顶山市 | D39: 平顶山基地（神马氯碱） | E39: 河南神马氯碱发展有限责任公司 | F39: 神马氯碱 | G39: 聚氯乙烯树脂 | H39: 未细分 | I39: 电石法（乙炔法） | J39: 电石法（待核） | K39: 设计产能 | L39: 30 | M39: 行业资料：河南神马氯碱产能 30 万吨（二手，未取得一手披露） | N39: 2022 | P39: 状态未核实 | Q39: 未核实 | R39: 未知 | S39: S30 | T39: C | U39: 国内外 39 家聚氯乙烯 PVC 树脂生产企业介绍 | V39: https://www.aibang.com/a/4566 | W39: 2022
A40: U-P180-01 | B40: 河南省 | C40: （待核） | D40: 河南联创基地 | E40: 河南联创化工有限公司 | F40: 河南联创 | G40: 聚氯乙烯树脂 | H40: 未细分 | I40: 电石法（乙炔法） | J40: 电石法（待核） | K40: 设计产能 | L40: 40 | M40: 行业盘点：河南联创主要产品年产能聚氯乙烯树脂 40 万吨、离子膜烧碱 35 万吨 | N40: 2024 | P40: 在产 | Q40: 行业盘点口径 | R40: 未知 | S40: S31 | T40: C | U40: 改色膜原料之聚氯乙烯 PVC 树脂厂商盘点 | V40: https://www.cmpe360.com/p/240686 | W40: 2024
A41: U-P190-01 | B41: 广东省 | C41: 广州市 | D41: 广州南沙基地（东曹） | E41: 东曹（广州）化工有限公司 | F41: 东曹广州 | G41: 聚氯乙烯树脂（悬浮法） | H41: 未细分 | I41: 乙烯法 | J41: 乙烯法（东曹 VCM 技术） | K41: 设计产能 | L41: 22 | M41: 东曹官网：东曹（广州）化工有限公司 2004 年成立，PVC 产能 22 万吨/年 | N41: 2025 | O41: 2004 | P41: 在产 | Q41: 生产中 | R41: 否 | S41: S29 | T41: A | U41: 东曹（广州）化工有限公司 公司介绍 | V41: https://www.tosoh.com/worldwide-cn/asia-cn | W41: 2025
...

Sheet 07_区域汇总(省)
A1: 省级产能汇总
A2: 按省加总；同时给出按工艺拆分与集团分布
A4: 省份 | B4: 产能合计(万吨/年) | C4: 占样本比 | D4: 电石法 | E4: 乙烯法 | F4: 混合 | G4: 未核实 | H4: 城市数 | I4: 集团数 | J4: 主要集团(万吨/年)
A5: 新疆维吾尔自治区 | B5: 243 | C5: 0.17076599 | D5: 243 | E5: 0 | F5: 0 | G5: 0 | H5: 3 | I5: 2 | J5: 天业集团(134)、中泰集团(109)
A6: 内蒙古自治区 | B6: 234 | C6: 0.16444132 | D6: 234 | E6: 0 | F6: 0 | G6: 0 | H6: 3 | I6: 4 | J6: 君正集团(80)、中盐化工(64)、亿利集团(50)、鄂尔多斯电冶(40)
A7: 陕西省 | B7: 170 | C7: 0.11946592 | D7: 170 | E7: 0 | F7: 0 | G7: 0 | H7: 1 | I7: 2 | J7: 北元集团(110)、陕投集团(60)
A8: 山东省 | B8: 145 | C8: 0.1018974 | D8: 0 | E8: 145 | F8: 0 | G8: 0 | H8: 2 | I8: 2 | J8: 海湾集团(105)、万华化学(40)
A9: 天津市 | B9: 80 | C9: 0.056219255 | D9: 0 | E9: 80 | F9: 0 | G9: 0 | H9: 1 | I9: 1 | J9: 渤化集团(80)
A10: 河南省 | B10: 70 | C10: 0.049191848 | D10: 70 | E10: 0 | F10: 0 | G10: 0 | H10: 2 | I10: 2 | J10: 河南联创(40)、神马氯碱(30)
A11: 安徽省 | B11: 64 | C11: 0.044975404 | D11: 64 | E11: 0 | F11: 0 | G11: 0 | H11: 1 | I11: 1 | J11: 华塑股份(64)
A12: 四川省 | B12: 50 | C12: 0.035137034 | D12: 50 | E12: 0 | F12: 0 | G12: 0 | H12: 1 | I12: 1 | J12: 天原集团(50)
A13: 江苏省 | B13: 50 | C13: 0.035137034 | D13: 0 | E13: 50 | F13: 0 | G13: 0 | H13: 1 | I13: 1 | J13: 新浦化学(50)
A14: 上海市 | B14: 48 | C14: 0.033731553 | D14: 0 | E14: 48 | F14: 0 | G14: 0 | H14: 1 | I14: 1 | J14: 华谊集团(48)
A15: 河北省 | B15: 47 | C15: 0.033028812 | D15: 47 | E15: 0 | F15: 0 | G15: 0 | H15: 1 | I15: 1 | J15: 三友化工(47)
A16: 广西壮族自治区 | B16: 40 | C16: 0.028109628 | D16: 0 | E16: 40 | F16: 0 | G16: 0 | H16: 1 | I16: 1 | J16: 华谊集团(40)
... A22: 广东省 | B22: 22 | C22: 0.015460295 | D22: 0 | E22: 22 | F22: 0 | G22: 0 | H22: 1 | I22: 1 | J22: 东曹广州(22)
A24: 合计 | B24: =SUM(B5:B22) | D24: =SUM(D5:D22) | E24: =SUM(E5:E22) | F24: =SUM(F5:F22) | G24: =SUM(G5:G22)
A26: 同一省份内「电石法+乙烯法+混合+未核实」= 该省合计；跨省合计 = 样本合计，不得另加全国口径。

Sheet 08_区域汇总(市)
A1: 市级产能汇总
A2: 按(省,市)加总，用于判断产业集聚的城市节点
A4: 省 | B4: 市 | C4: 产能合计(万吨/年) | D4: 占样本比 | E4: 基地数 | F4: 涉及集团 | G4: 工艺
A5: 陕西省 | B5: 神木市 | C5: 170 | D5: 0.11946592 | E5: 2 | F5: 北元集团、陕投集团 | G5: 电石法（乙炔法）
A6: 新疆维吾尔自治区 | B6: 石河子市 | C6: 134 | D6: 0.094167252 | E6: 2 | F6: 天业集团 | G6: 电石法（乙炔法）
A7: 山东省 | B7: 青岛市 | C7: 105 | D7: 0.073787772 | E7: 1 | F7: 海湾集团 | G7: 乙烯法
A8: 内蒙古自治区 | B8: 鄂尔多斯市 | C8: 90 | D8: 0.063246662 | E8: 2 | F8: 亿利集团、鄂尔多斯电冶 | G8: 电石法（乙炔法）
A9: 新疆维吾尔自治区 | B9: 阜康市 | C9: 80 | D9: 0.056219255 | E9: 1 | F9: 中泰集团 | G9: 电石法（乙炔法）
A10: 内蒙古自治区 | B10: 乌海市 | C10: 80 | D10: 0.056219255 | E10: 3 | F10: 君正集团、宜化集团、鸿达兴业 | G10: 工艺未核实 / 电石法（乙炔法）
A11: 天津市 | B11: 天津市 | C11: 80 | D11: 0.056219255 | E11: 1 | F11: 渤化集团 | G11: 乙烯法
A12: 内蒙古自治区 | B12: 阿拉善盟 | C12: 64 | D12: 0.044975404 | E12: 1 | F12: 中盐化工 | G12: 电石法（乙炔法）
A13: 安徽省 | B13: 滁州市 | C13: 64 | D13: 0.044975404 | E13: 1 | F13: 华塑股份 | G13: 电石法（乙炔法）
A14: 四川省 | B14: 宜宾市 | C14: 50 | D14: 0.035137034 | E14: 1 | F14: 天原集团 | G14: 电石法（乙炔法）
A15: 江苏省 | B15: 泰兴市 | C15: 50 | D15: 0.035137034 | E15: 1 | F15: 新浦化学 | G15: 乙烯法
A16: 上海市 | B16: 上海市 | C16: 48 | D16: 0.033731553 | E16: 1 | F16: 华谊集团 | G16: 乙烯法
... A28: 广东省 | B28: 广州市 | C28: 22 | D28: 0.015460295 | E28: 1 | F28: 东曹广州 | G28: 乙烯法

Sheet 09_工艺路线汇总
A1: 工艺路线产能汇总
A2: 路线定义见 01 表；「未核实」单列，不并入任何一条路线
A4: 工艺路线 | B4: 代码 | C4: 产能(万吨/年) | D4: 占样本比 | E4: 集团数 | F4: 主要集团(万吨/年) | G4: 主要省份(万吨/年)
A5: 电石法（乙炔法） | B5: carbide | C5: 908 | D5: 0.63808855 | E5: 14 | F5: 天业集团(134)、北元集团(110)、中泰集团(109)、君正集团(80)、中盐化工(64) | G5: 新疆维吾尔自治区(243)、内蒙古自治区(234)、陕西省(170)、河南省(70)、安徽省(64)
A6: 乙烯法 | B6: ethylene | C6: 515 | D6: 0.36191145 | E6: 9 | F6: 海湾集团(105)、华谊集团(88)、渤化集团(80)、万华化学(80)、新浦化学(50) | G6: 山东省(145)、天津市(80)、江苏省(50)、上海市(48)、广西壮族自治区(40)
A8: 电石法（乙炔法）：煤/石灰石→电石→乙炔→VCM→PVC。成本锚定煤价与电费，单装置规模通常 20–60 万吨/年。全球 98% 以上电石法 PVC 产能集中在中国。
A9: 乙烯法：石脑油/轻烃或煤制烯烃→乙烯→EDC/VCM→PVC。沿海装置多依托大型乙烯基地，单套规模 40–85 万吨/年。2025 年新增产能中 84.3% 为乙烯法。
A10: 煤制烯烃乙烯法：以煤制甲醇→烯烃→乙烯为原料再走乙烯法，典型如青海盐湖镁业（金属镁-PVC-钾肥耦合）与新疆天业汇祥（乙醇→乙烯→VCM）。
A11: 「煤→乙醇→乙烯→PVC」是新疆天业正在打通的新路线，其中 22.5 万吨/年乙烯法 VCM 装置 2025-07 打通流程，尚不构成 PVC 树脂产能。

Sheet 10_产品等级汇总
A1: 按产品/等级拆分
A2: 不同等级（通用树脂/专用料/糊树脂）是否计入总数，取决于行业统计口径，见 01 表说明
A4: 产品等级/类别 | B4: 产能(万吨/年) | C4: 占样本比 | D4: 装置条数 | E4: 涉及产品/牌号 | F4: 主要集团
A5: 未细分 | B5: 1021 | C5: 0.71749824 | D5: 22 | E5: 聚氯乙烯树脂、聚氯乙烯树脂（2025 年新增线）、聚氯乙烯树脂（一期）、聚氯乙烯树脂（乙烯法）、聚氯乙烯树脂（二期）、聚氯乙烯树脂（悬浮法）、聚氯乙烯树脂（悬浮法，一期）、聚氯乙烯树脂（悬浮法，二期）、聚氯乙烯树脂（电石法无汞） | F5: 北元集团(110)、海湾集团(105)、君正集团(80)、渤化集团(80)、华塑股份(64)
A6: 通用树脂（纯粉） | B6: 274 | C6: 0.19255095 | D6: 4 | E6: 聚氯乙烯树脂、聚氯乙烯树脂（悬浮法通用型）、聚氯乙烯树脂（悬浮法）、聚氯乙烯（通用 PVC 树脂） | F6: 天业集团(114)、中泰集团(80)、华谊集团(40)、三友化工(40)
A7: 专用料 | B7: 67 | C7: 0.047083626 | D7: 3 | E7: 聚氯乙烯专用树脂、聚氯乙烯树脂（高品质）、聚氯乙烯（本体法树脂） | F7: 万华化学(40)、中泰集团(20)、三友化工(7)
A8: 糊树脂 | B8: 40 | C8: 0.028109628 | D8: 3 | E8: 聚氯乙烯糊树脂（EPVC） | F8: 中盐化工(24)、天业集团(10)、中泰集团(6)
A9: 特种树脂 | B9: 21 | C9: 0.014757554 | D9: 3 | E9: 特种聚氯乙烯树脂、聚氯乙烯（特种树脂 SPVC）、聚氯乙烯（降粘树脂） | F9: 天业集团(10)、华谊集团(8)、中泰集团(3)
A11: 提示：若行业总产能口径「包含糊状树脂」，则通用树脂+糊树脂之和方可与全国口径对比；仅用通用树脂对比会低估。

Sheet 11_在建拟建项目
A1: 在建 / 拟建 / 扩建 / 试车 / 新投产项目
A2: 阶段判定以最新公开进展为准；不得把拟建当作存量
A4: 项目ID | B4: 项目名称 | C4: 建设单位(法人) | D4: 集团 | E4: 省 | F4: 市 | G4: 工艺 | H4: 规模(万吨/年) | I4: 原文表述 | J4: 建设阶段 | K4: 预计投产 | L4: 置换退出(万吨/年) | M4: 置换说明 | N4: 净增(万吨/年) | O4: 投资额 | P4: 来源 | Q4: 可信度 | R4: 进展时间线 | S4: 备注
A5: PR09 | B5: 广西华谊钦州 PVC 二期 40 万吨/年 | C5: 广西华谊氯碱化工有限公司 | D5: 华谊集团 | E5: 广西壮族自治区 | F5: 钦州市 | G5: 乙烯法 | H5: 40 | I5: PVC 40 万吨/年（二期） | J5: 已运行 | K5: 2022-11-30 首批产品下线 | M5: 无（净新增） | N5: 40 | P5: S10 | Q5: B | R5: 2019 项目投资建设；2022-11-30 首批产品下线；2024-05-23 氯碱化工公告收购广西氯碱剩余 40% 股权至 100% | S5: ⚠ 常见误引：多处资料把广西华谊写成「在建 30 万吨乙烯法」。事实上已投产的是二期 40 万吨（2022-11-30 首批产品下线），而 30 万吨是 2025-12 新备案的废盐综合利用配套项目（见 PR03）。两者是不同项目。
A6: PR06 | B6: 万华化学福建基地 PVC 一期 40 万吨/年 | C6: 万华化学（福建）有限公司 | D6: 万华化学 | E6: 福建省 | F6: 福清市 | G6: 乙烯法 | H6: 40 | I6: PVC 一期 40 万吨/年 | J6: 新投产爬坡 | K6: 2025 年 5—7 月试车投产 | M6: 净新增（无置换） | N6: 40 | P6: S75 | Q6: B | R6: 2022-02-07 项目开工；2025-05 进入试车；2025-06 与 MDI/TDI 装置一同检修；2025-07-30 发布复产公告 | S6: 万华化学集团股份有限公司（600309），福清江阴港城经济区。2022-02-07 开工。2025-06 与 MDI/TDI 装置一同检修，2025-07-30 发布复产公告。⚠ 二期 40 万吨状态未知（未查到投产公告），本表未将二期计入。
A7: PR07 | B7: 天津渤化 PVC 二期 40 万吨/年（乙烯法替代电石法） | C7: 天津大沽化工股份有限公司 | D7: 渤化集团 | E7: 天津市 | F7: 天津市 | G7: 乙烯法 | H7: 40 | I7: PVC 二期 40 万吨/年，悬浮法 | J7: 已运行 | K7: 2025-09-28 全面投产 | M7: 搬迁淘汰原电石法（吨数未披露） | N7: 40 | P7: S67 / S19 | Q7: B | R7: 2021-12 一期烧碱、聚氯乙烯装置试车投产；2022 起不再采购电石原料（改乙烯法）；2025-09-28 二期 40 万吨全面投产，PVC 总产能达 120 万吨 | S7: 投产后天津渤化 PVC 总产能 120 万吨（80 + 40），乙烯法替代原电石法。⚠ 这是本轮核查中置换逻辑最清晰的大型项目之一，但公开报道未给出淘汰吨数，因此 net 仍无法精确计算。
A8: PR08 | B8: 陕西金泰氯碱神木 60 万吨/年电石法 PVC（无汞示范） | C8: 陕西金泰氯碱神木化工有限公司 | D8: 陕投集团 | E8: 陕西省 | F8: 神木市 | G8: 电石法（乙炔法） | H8: 60 | I8: PVC 60 万吨/年，电石法无汞催化 | J8: 已运行 | K8: 2025-07-11 交工验收 | M8: 未查到 | N8: 60 | P8: S72 | Q8: B | R8: 2024-05-11 试生产；2025-07-11 交工验收 | S8: 陕西金泰氯碱（陕投集团），神木。2024-05-11 试生产，2025-07-11 交工验收。⚠ 重要：这是 2025 年实际投产的大型电石法装置（60 万吨），与「2025 年新增产能 84.3% 为乙烯法」的年报表述并不矛盾——后者是含改扩建的「新增产能」口径，前者是「新投产装置」口径，两者不可混用。
A9: PR10 | B9: 甘肃耀望化工 30 万吨/年无汞电石法 PVC | C9: 甘肃耀望化工有限公司 | D9: 耀望化工 | E9: 甘肃省 | F9: 兰州新区 | G9: 电石法（乙炔法） | H9: 30 | I9: PVC 30 万吨/年，电石法无汞催化 | J9: 新投产爬坡 | K9: 2025-11 投产 | M9: 未查到置换方案 | N9: 30 | P9: S73 | Q9: B | R9: 2025-11 投产（无汞催化电石法） | S9: 甘肃耀望化工，兰州新区。2025-11 投产。与陕西金泰 60 万吨合计 90 万吨电石法装置在 2025 年投产——这是「2025 年新投产装置电石法占比并不低」的关键证据。
A10: PR11 | B10: 新浦化学（泰兴）50 万吨/年 PVC | C10: 新浦化学（泰兴）有限公司 | D10: 新浦化学 | E10: 江苏省 | F10: 泰兴市 | G10: 乙烯法 | H10: 50 | I10: PVC 50 万吨/年 | J10: 新投产爬坡 | K10: 2025 年 1—2 月量产 | M10: 未查到置换方案 | N10: 50 | P10: S74 | Q10: B | R10: 2022-04 中交；2025-02 量产 | S10: 新浦化学（泰兴）有限公司，江苏泰兴经济开发区。2022-04 中交，2025 年 1—2 月量产。
A11: PR12 | B11: 青岛海湾化学 2025 年新增 20 万吨乙烯法 PVC | C11: 青岛海湾化学股份有限公司 | D11: 海湾集团 | E11: 山东省 | F11: 青岛市 | G11: 乙烯法 | H11: 20 | I11: PVC 新增 20 万吨/年（在 85 万吨基础上） | J11: 新投产爬坡 | K11: 2025 年 8—9 月试车 | M11: 净新增（无置换） | N11: 20 | P11: S22 / S24 | Q11: B | R11: 2020 年底 PVC 二期、烧碱二期投产；2025-08 新增 20 万吨试车 | S11: ⚠ 常见误引：多处把海湾化学写成「PVC 产能将达 100 万吨/年」。经核实：现有 85 万吨乙烯法 PVC 早已建成，2025 年新增仅 20 万吨；另有 40 万吨/年是 VCM（原料），不是 PVC 产能。「100 万吨」是媒体把不同口径加总后的说法，未采信。
A12: PR14 | B12: 湖北宜化旧 PVC 装置永久关停 | C12: 青海宜化化工有限责任公司 | D12: 宜化集团 | E12: 湖北省 | F12: （未披露） | G12: 电石法（乙炔法） | I12: 关停吨数未披露（年报仅注「本年度存在部分 PVC 装置关停」） | J12: 取消 | K12: 2025 年内 | M12: 不适用 | P12: S08 / S60 | Q12: B | R12: 2025 部分 PVC 装置永久关停（商务部口径） | S12: ⚠ 这是本报告最典型的一处「吨数未知」：退出方向明确（永久关停），但具体厂址与关停吨数均未公开。因此湖北宜化 90 万吨中究竟有多少仍在有效供给，无法精确计算，已列入数据缺口 G-04。
A13: PR04 | B13: 聚氯乙烯二期 30 万吨/年 | C13: 浙江嘉化能源化工股份有限公司 | D13: 嘉化能源 | E13: 浙江省 | F13: 嘉兴市 | G13: 乙烯法 | H13: 30 | I13: PVC 30 万吨/年（二期） | J13: 试车 | K13: 2026 年逐步放量 | M13: 净新增（无置换） | N13: 30 | P13: S66 | Q13: B | R13: 2025-08-28 VCM 二期装置开车；2026-02 公司表述「2026 年 PVC 二期产能陆续释放」 | S13: 浙江嘉化能源化工股份有限公司（600273），嘉兴港区。乙烯法（日本 JNC 悬浮法技术，外购乙烯）。VCM 二期已于 2025-08-28 开车，PVC 装置 2026 年逐步放量。⚠ 注意其成本结构：纯外购乙烯在乙烯价格高位时缺乏一体化缓冲。
A14: PR01 | B14: 年产 96 万吨聚氯乙烯项目 | C14: 万融新材料（福建）有限公司 | D14: 万华化学 | E14: 福建省 | F14: 福清市 | G14: 乙烯法 | H14: 96 | I14: PVC 96 万吨/年；配套 VCM 96 万吨/年；副产 25% 盐酸 8.6 万吨/年 | J14: 环评公示 | K14: 2027（环评载建设期 2 年，起算点未确认） | M14: 未查到置换方案 | N14: 96 | P14: S62 | Q14: B | R14: 2025-05-13 环境影响报告书 第一次公示；2025-06-13 环境影响报告书 第二次公示；未知 环评批复 / 开工 | S14: 万融新材料（福建）有限公司，万华化学持股 80%、员工持股平台 20%。位于福清江阴港城经济区东部片区。乙烯法，利用 MDI 80 万吨 + TDI 72 万吨装置的副产氯化氢制 VCM，是典型的「异氰酸酯—PVC」氯平衡耦合项目。2025-05-13 环评一次公示，2025-06-13 二次公示；环评批复文号与开工时间未公开。
A15: PR05 | B15: 茌平信发华兴 PVC 二期 20 万吨/年 | C15: 茌平信发华兴化工有限公司 | D15: 信发集团 | E15: 山东省 | F15: 聊城市 | G15: 工艺未核实 | H15: 20 | I15: PVC 20 万吨/年（二期） | J15: 在建 | K15: 2027Q4（建设期 2026Q4—2027Q4） | M15: 未查到置换方案 | N15: 20 | O15: 15 亿元 | P15: S64 | Q15: B | R15: 2026-07-04 仍在招标乙炔系统设备；2026-07-14 项目立项审批；2026-08-14 处于主体施工阶段 | S15: 茌平信发华兴化工有限公司（信发集团），山东聊城茌平区乐平铺镇。一期 40 万吨已于 2022-08 投产（无汞催化剂路线）。⚠ 合规风险：国家禁止新建＜20 万吨/年电石法 PVC，单体 20 万吨恰好踩线；是否合规取决于与一期合并计算，无公开文件，需向山东/聊城发改委核实。
A16: PR02 | B16: 智能生态光伏耦合绿色特种树脂低碳转型升级示范工程（一期）— PVC 50 万吨 | C16: 新疆天业（集团）有限公司 | D16: 天业集团 | E16: 新疆维吾尔自治区 | F16: 石河子市 | G16: 乙烯法 | H16: 50 | I16: PVC 50 万吨/年、烧碱 35 万吨/年、煤基乙醇 60 万吨/年 | J16: 在建 | K16: 未定（原计划受乙醇装置 EPC 废标影响，存在延后风险） | M16: 公开表述「部分产能置换」但方案未披露 | N16: 50 | O16: 139.67 亿元 | P16: S51 / S63 / S50 | Q16: B | R16: 2025-09-01 上市公司股东大会通过控股股东代建暨关联交易议案；2026-07 项目公司注册资本由 20 亿元增至 33.59 亿元；2026-07-31 气化装置 EPC 定标（航天长征 6.76 亿元）、全厂系统 EPC 定标（天辰 26.9 亿元）；2026-10-08 乙醇装置 EPC 三标段废标、重新招标 | S16: 建设单位为新疆天业（集团）有限公司——上市公司的控股股东，由集团「代为培育」，上市公司不投资、仅享优先购买权（2025-09-01 股东大会通过）。⚠ 该 50 万吨绝不能计入新疆天业股份的 134 万吨。位於石河子 147 团十户滩新材料工业园。2026-07 注册资本由 20 亿增至 33.59 亿元。
A17: PR03 | B17: 先进材料配套废盐综合利用项目 — PVC 30 万吨 | C17: 广西华谊氯碱化工有限公司 | D17: 华谊集团 | E17: 广西壮族自治区 | F17: 钦州市 | G17: 乙烯法 | H17: 30 | I17: PVC 30 万吨/年、烧碱 30 万吨/年、VCM 25 万吨/年 | J17: 已备案 | K17: 未定 | M17: 未查到置换方案 | N17: 30 | O17: 29.75 亿元（增资 8.93 亿元） | P17: S65 | Q17: A | R17: 2025-12-19 上市公司公告项目投资暨对广西氯碱增资 8.93 亿元、董事会决议；未知 环评公示 / 开工 | S17: 广西华谊氯碱化工有限公司，上海氯碱化工（600618）全资。位于钦州港经济技术开发区石化产业园。以园区废盐综合利用为配套的氯碱扩能，乙烯法。⚠ 注意：此 30 万吨为新增项目；已投产的二期 40 万吨见 PR09，两者不可混为一谈。
A18: PR13 | B18: 浙江镇洋发展 30 万吨/年 PVC 临时停产 | C18: 浙江镇洋发展股份有限公司 | D18: 镇洋发展 | E18: 浙江省 | F18: 宁波市 | G18: 乙烯法 | H18: 30 | I18: PVC 30 万吨/年（2023-05 投产，本次为减量事件） | J18: 暂停搁置 | K18: 预计不超过 4 个月（2026-09-19 起） | M18: 不适用（非退出，为临时停产） | N18: 30 | P18: S68 | Q18: A | R18: 2023-05 PVC 装置投产；2026-09-19 临时停产（原料乙烯涨价） | S18: 浙江镇洋发展股份有限公司（603213），宁波。因原料乙烯价格上涨，2026-09-19 起 PVC 装置临时停产，预计不超过 4 个月；2026H1 PVC 毛利率 -23.24%。⚠ 案例价值：这是「乙烯法=低成本」这一流行判断的反例——纯外购乙烯、无一体化配套的乙烯法装置，在乙烯高位时同样会停车。
A20: 净增 = 规模 − 置换退出。置换退出无法确认时留空（不估算），该行不计入净增合计。

Sheet 12_新增净额还原
A1: 新增产能的毛/净/加权还原
A2: 毛新增 ≠ 净新增 ≠ 实际可增量；加权仅供情景参考，不用于官方口径
A4: 建设阶段 | B4: 代码 | C4: 项目数 | D4: 毛新增(万吨/年) | E4: 置换退出(万吨/年) | F4: 净新增(万吨/年) | G4: 确定性权重 | H4: 加权可增量(情景) | I4: 项目ID
A5: 已备案 | B5: filed | C5: 1 | D5: 30 | F5: 30 | G5: 0.25 | H5: 7.5 | I5: PR03
A6: 环评公示 | B6: eia | C6: 1 | D6: 96 | F6: 96 | G6: 0.45 | H6: 43.2 | I6: PR01
A7: 在建 | B7: construction | C7: 2 | D7: 70 | F7: 70 | G7: 0.85 | H7: 59.5 | I7: PR02、PR05
A8: 试车 | B8: commissioning | C8: 1 | D8: 30 | F8: 30 | G8: 0.95 | H8: 28.5 | I8: PR04
A9: 新投产爬坡 | B9: rampup | C9: 4 | D9: 140 | F9: 140 | G9: 1 | H9: 140 | I9: PR06、PR10、PR11、PR12
A10: 已运行 | B10: operating | C10: 3 | D10: 140 | F10: 140 | I10: PR07、PR08、PR09
A11: 暂停搁置 | B11: suspended | C11: 1 | D11: 30 | F11: 30 | I11: PR13
A12: 取消 | B12: cancelled | C12: 1 | I12: PR14
A14: 说明
A15: ① 毛新增 = Σ项目规模，未扣减任何退出产能；不得直接称为「产能将增加 X 万吨」。
A16: ② 净新增 = 毛新增 − 置换/等量替代退出产能；仅当置换说明与退出产能均有来源时才可信。
A17: ③ 加权可增量 = 净新增 × 确定性权重，是情景值而非预测；权重按阶段设定（在建 0.85、试车 0.95、环评 0.45、备案 0.25、拟建 0.10）。
A18: ④ 存量与增量严禁相加；本表仅反映未来供给增量。

Sheet 13_重复统计校验
A1: 重复统计与口径一致性自动校验
A2: 规则 R1–R14；ERROR 必须在引用数据前处理，WARN 需在报告中说明
A4: 规则 | B4: 级别 | C4: 对象 | D4: 校验信息 | E4: 处理建议
A5: R10 | B5: WARN | C5: PR04 | D5: 项目 聚氯乙烯二期 30 万吨/年 与基地 P302 已有同工艺同产能装置；需确认是新增装置还是存量装置。 | E5: 核对装置数量；若为同一装置，删除项目记录
A6: R10 | B6: WARN | C6: PR06 | D6: 项目 万华化学福建基地 PVC 一期 40 万吨/年 与基地 P304 已有同工艺同产能装置；需确认是新增装置还是存量装置。 | E6: 核对装置数量；若为同一装置，删除项目记录
A7: R10 | B7: WARN | C7: PR07 | D7: 项目 天津渤化 PVC 二期 40 万吨/年（乙烯法替代电石法） 阶段为「已运行」，应已并入存量；请确认存量装置已录入，且不在增量中重复计。 | E7: 将 project.stage 改为 operating 并从增量汇总排除
A8: R10 | B8: WARN | C8: PR08 | D8: 项目 陕西金泰氯碱神木 60 万吨/年电石法 PVC（无汞示范） 阶段为「已运行」，应已并入存量；请确认存量装置已录入，且不在增量中重复计。 | E8: 将 project.stage 改为 operating 并从增量汇总排除
A9: R10 | B9: WARN | C9: PR09 | D9: 项目 广西华谊钦州 PVC 二期 40 万吨/年 阶段为「已运行」，应已并入存量；请确认存量装置已录入，且不在增量中重复计。 | E9: 将 project.stage 改为 operating 并从增量汇总排除
A10: R10 | B10: WARN | C10: PR10 | D10: 项目 甘肃耀望化工 30 万吨/年无汞电石法 PVC 与基地 P306 已有同工艺同产能装置；需确认是新增装置还是存量装置。 | E10: 核对装置数量；若为同一装置，删除项目记录
A11: R10 | B11: WARN | C11: PR11 | D11: 项目 新浦化学（泰兴）50 万吨/年 PVC 与基地 P307 已有同工艺同产能装置；需确认是新增装置还是存量装置。 | E11: 核对装置数量；若为同一装置，删除项目记录
A12: R10 | B12: WARN | C12: PR12 | D12: 项目 青岛海湾化学 2025 年新增 20 万吨乙烯法 PVC 与基地 P110 已有同工艺同产能装置；需确认是新增装置还是存量装置。 | E12: 核对装置数量；若为同一装置，删除项目记录
A13: R11 | B13: WARN | C13: PR01 | D13: 项目 年产 96 万吨聚氯乙烯项目 的置换情况为「未查到置换方案」，但未填写 retired_capacity，毛新增会被当作净新增，导致增量高估。 | E13: 补 retired_capacity；无法确认则净增记 null，不进基准预测
A14: R11 | B14: WARN | C14: PR02 | D14: 项目 智能生态光伏耦合绿色特种树脂低碳转型升级示范工程（一期）— PVC 50 万吨 的置换情况为「公开表述「部分产能置换」但方案未披露」，但未填写 retired_capacity，毛新增会被当作净新增，导致增量高估。 | E14: 补 retired_capacity；无法确认则净增记 null，不进基准预测
A15: R11 | B15: WARN | C15: PR03 | D15: 项目 先进材料配套废盐综合利用项目 — PVC 30 万吨 的置换情况为「未查到置换方案」，但未填写 retired_capacity，毛新增会被当作净新增，导致增量高估。 | E15: 补 retired_capacity；无法确认则净增记 null，不进基准预测
... A30: R13 | B30: INFO | C30: U-P080-02 | D30: 装置 U-P080-02 自评可信度 B 与来源 S15 等级 A 不一致 | E30: 以来源等级为准或说明理由
A31: R9 | B31: INFO | C31: 福建省福州市福清市江阴港城经济区 | D31: 多个基地共用同一注册地址 福建省福州市福清市江阴港城经济区：['P300', 'P304']；非错误，但需在报告中说明是否为同一厂区拆分。
A33: 校验结果：ERROR 0 项 / WARN 21 项 / INFO 6 项
A34: 规则定义见 references/去重校验规则.md；R4 重复装置、R6 来源缺失、R11 置换未扣减是最常见的三类翻车点。

Sheet 14_汇总公式与溯源
A1: 汇总公式与加成溯源
A2: 每一条产能最终被计入哪些汇总项，可逐行核对，避免重复计入
A4: 装置ID | B4: 基地 | C4: 省 | D4: 市 | E4: 法人 | F4: 集团 | G4: 工艺 | H4: 口径 | I4: 产能(万吨/年) | J4: 同基地合计(校验) | K4: 计入集团 | L4: 计入省份 | M4: 计入工艺
A5: U-P002-01 | B5: 阜康基地（阜康能源） | C5: 新疆维吾尔自治区 | D5: 阜康市 | E5: 新疆中泰化学阜康能源有限公司 | F5: 新疆中泰（集团）有限责任公司 | G5: 电石法（乙炔法） | H5: design | I5: 80 | J5: =SUMIFS('06_装置明细'!$L$5:$L$2000,'06_装置明细'!$D$5:$D$2000,"阜康基地（阜康能源）") | K5: 集团汇总 | L5: 省级汇总 | M5: 工艺汇总
A6: U-P003-01 | B6: 托克逊基地（托克逊能化） | C6: 新疆维吾尔自治区 | D6: 托克逊县 | E6: 新疆中泰化学托克逊能化有限公司 | F6: 新疆中泰（集团）有限责任公司 | G6: 电石法（乙炔法） | H6: design | I6: 20 | J6: =SUMIFS('06_装置明细'!$L$5:$L$2000,'06_装置明细'!$D$5:$D$2000,"托克逊基地（托克逊能化）") | K6: 集团汇总 | L6: 省级汇总 | M6: 工艺汇总
A7: U-P003-02 | B7: 托克逊基地（托克逊能化） | C7: 新疆维吾尔自治区 | D7: 托克逊县 | E7: 新疆中泰化学托克逊能化有限公司 | F7: 新疆中泰（集团）有限责任公司 | G7: 电石法（乙炔法） | H7: design | I7: 6 | J7: =SUMIFS('06_装置明细'!$L$5:$L$2000,'06_装置明细'!$D$5:$D$2000,"托克逊基地（托克逊能化）") | K7: 集团汇总 | L7: 省级汇总 | M7: 工艺汇总
A8: U-P003-03 | B8: 托克逊基地（托克逊能化） | C8: 新疆维吾尔自治区 | D8: 托克逊县 | E8: 新疆中泰化学托克逊能化有限公司 | F8: 新疆中泰（集团）有限责任公司 | G8: 电石法（乙炔法） | H8: design | I8: 3 | J8: =SUMIFS('06_装置明细'!$L$5:$L$2000,'06_装置明细'!$D$5:$D$2000,"托克逊基地（托克逊能化）") | K8: 集团汇总 | L8: 省级汇总 | M8: 工艺汇总
A9: U-P010-01 | B9: 石河子化工园区基地（综合） | C9: 新疆维吾尔自治区 | D9: 石河子市 | E9: 新疆天业股份有限公司 | F9: 新疆天业（集团）有限公司 | G9: 电石法（乙炔法） | H9: design | I9: 114 | J9: =SUMIFS('06_装置明细'!$L$5:$L$2000,'06_装置明细'!$D$5:$D$2000,"石河子化工园区基地（综合）") | K9: 集团汇总 | L9: 省级汇总 | M9: 工艺汇总
A10: U-P010-02 | B10: 石河子化工园区基地（综合） | C10: 新疆维吾尔自治区 | D10: 石河子市 | E10: 新疆天业股份有限公司 | F10: 新疆天业（集团）有限公司 | G10: 电石法（乙炔法） | H10: design | I10: 10 | J10: =SUMIFS('06_装置明细'!$L$5:$L$2000,'06_装置明细'!$D$5:$D$2000,"石河子化工园区基地（综合）") | K10: 集团汇总 | L10: 省级汇总 | M10: 工艺汇总
A11: U-P010-03 | B11: 石河子化工园区基地（综合） | C11: 新疆维吾尔自治区 | D11: 石河子市 | E11: 新疆天业股份有限公司 | F11: 新疆天业（集团）有限公司 | G11: 电石法（乙炔法） | H11: design | I11: 10 | J11: =SUMIFS('06_装置明细'!$L$5:$L$2000,'06_装置明细'!$D$5:$D$2000,"石河子化工园区基地（综合）") | K11: 集团汇总 | L11: 省级汇总 | M11: 工艺汇总
A12: U-P020-01 | B12: 锦界园区基地（北元） | C12: 陕西省 | D12: 神木市 | E12: 陕西北元化工集团股份有限公司 | F12: 陕西北元化工集团股份有限公司（独立上市） | G12: 电石法（乙炔法） | H12: design | I12: 110 | J12: =SUMIFS('06_装置明细'!$L$5:$L$2000,'06_装置明细'!$D$5:$D$2000,"锦界园区基地（北元）") | K12: 集团汇总 | L12: 省级汇总 | M12: 工艺汇总
A13: U-P030-01 | B13: 乌达工业园区基地（君正） | C13: 内蒙古自治区 | D13: 乌海市 | E13: 内蒙古君正化工有限责任公司 | F13: 内蒙古君正能源化工集团股份有限公司（含乌海市君正科技产业集团） | G13: 电石法（乙炔法） | H13: design | I13: 80 | J13: =SUMIFS('06_装置明细'!$L$5:$L$2000,'06_装置明细'!$D$5:$D$2000,"乌达工业园区基地（君正）") | K13: 集团汇总 | L13: 省级汇总 | M13: 工艺汇总
A14: U-P050-01 | B14: 上海化工区基地（氯碱化工） | C14: 上海市 | D14: 上海市 | E14: 上海氯碱化工股份有限公司 | F14: 上海华谊控股集团有限公司 | G14: 乙烯法 | H14: design | I14: 40 | J14: =SUMIFS('06_装置明细'!$L$5:$L$2000,'06_装置明细'!$D$5:$D$2000,"上海化工区基地（氯碱化工）") | K14: 集团汇总 | L14: 省级汇总 | M14: 工艺汇总
A15: U-P050-02 | B15: 上海化工区基地（氯碱化工） | C15: 上海市 | D15: 上海市 | E15: 上海氯碱化工股份有限公司 | F15: 上海华谊控股集团有限公司 | G15: 乙烯法 | H15: design | I15: 8 | J15: =SUMIFS('06_装置明细'!$L$5:$L$2000,'06_装置明细'!$D$5:$D$2000,"上海化工区基地（氯碱化工）") | K15: 集团汇总 | L15: 省级汇总 | M15: 工艺汇总
A16: U-P051-01 | B16: 钦州基地（广西氯碱） | C16: 广西壮族自治区 | D16: 钦州市 | E16: 广西华谊氯碱化工有限公司 | F16: 上海华谊控股集团有限公司 | G16: 乙烯法 | H16: design | I16: 40 | J16: =SUMIFS('06_装置明细'!$L$5:$L$2000,'06_装置明细'!$D$5:$D$2000,"钦州基地（广西氯碱）") | K16: 集团汇总 | L16: 省级汇总 | M16: 工艺汇总
A17: U-P060-01 | B17: 吉兰泰基地（中盐吉兰泰） | C17: 内蒙古自治区 | D17: 阿拉善盟 | E17: 中盐吉兰泰氯碱化工有限公司 | F17: 中盐内蒙古化工股份有限公司（独立上市） | G17: 电石法（乙炔法） | H17: design | I17: 40 | J17: =SUMIFS('06_装置明细'!$L$5:$L$2000,'06_装置明细'!$D$5:$D$2000,"吉兰泰基地（中盐吉兰泰）") | K17: 集团汇总 | L17: 省级汇总 | M17: 工艺汇总
A18: U-P080-01 | B18: 南堡基地（三友氯碱） | C18: 河北省 | D18: 唐山市 | E18: 唐山三友氯碱有限责任公司 | F18: 唐山三友集团有限公司 | G18: 电石法（乙炔法） | H18: design | I18: 40 | J18: =SUMIFS('06_装置明细'!$L$5:$L$2000,'06_装置明细'!$D$5:$D$2000,"南堡基地（三友氯碱）") | K18: 集团汇总 | L18: 省级汇总 | M18: 工艺汇总
A19: U-P080-02 | B19: 南堡基地（三友氯碱） | C19: 河北省 | D19: 唐山市 | E19: 唐山三友氯碱有限责任公司 | F19: 唐山三友集团有限公司 | G19: 电石法（乙炔法） | H19: design | I19: 7 | J19: =SUMIFS('06_装置明细'!$L$5:$L$2000,'06_装置明细'!$D$5:$D$2000,"南堡基地（三友氯碱）") | K19: 集团汇总 | L19: 省级汇总 | M19: 工艺汇总
A20: U-P090-01 | B20: 定远基地（华塑） | C20: 安徽省 | D20: 滁州市 | E20: 安徽华塑股份有限公司 | F20: 安徽华塑股份有限公司（独立上市） | G20: 电石法（乙炔法） | H20: design | I20: 64 | J20: =SUMIFS('06_装置明细'!$L$5:$L$2000,'06_装置明细'!$D$5:$D$2000,"定远基地（华塑）") | K20: 集团汇总 | L20: 省级汇总 | M20: 工艺汇总
A21: U-P100-01 | B21: 临港基地（大沽化工） | C21: 天津市 | D21: 天津市 | E21: 天津大沽化工股份有限公司 | F21: 天津渤海化工集团有限责任公司 | G21: 乙烯法 | H21: design | I21: 40 | J21: =SUMIFS('06_装置明细'!$L$5:$L$2000,'06_装置明细'!$D$5:$D$2000,"临港基地（大沽化工）") | K21: 集团汇总 | L21: 省级汇总 | M21: 工艺汇总
A22: U-P100-02 | B22: 临港基地（大沽化工） | C22: 天津市 | D22: 天津市 | E22: 天津大沽化工股份有限公司 | F22: 天津渤海化工集团有限责任公司 | G22: 乙烯法 | H22: design | I22: 40 | J22: =SUMIFS('06_装置明细'!$L$5:$L$2000,'06_装置明细'!$D$5:$D$2000,"临港基地（大沽化工）") | K22: 集团汇总 | L22: 省级汇总 | M22: 工艺汇总
A23: U-P110-01 | B23: 董家口基地（海湾化学） | C23: 山东省 | D23: 青岛市 | E23: 青岛海湾化学股份有限公司 | F23: 青岛海湾集团有限公司 | G23: 乙烯法 | H23: design | I23: 85 | J23: =SUMIFS('06_装置明细'!$L$5:$L$2000,'06_装置明细'!$D$5:$D$2000,"董家口基地（海湾化学）") | K23: 集团汇总 | L23: 省级汇总 | M23: 工艺汇总
A24: U-P120-01 | B24: 烟台工业园基地（万华） | C24: 山东省 | D24: 烟台市 | E24: 万华化学集团股份有限公司 | F24: 万华化学集团股份有限公司（独立上市） | G24: 乙烯法 | H24: design | I24: 40 | J24: =SUMIFS('06_装置明细'!$L$5:$L$2000,'06_装置明细'!$D$5:$D$2000,"烟台工业园基地（万华）") | K24: 集团汇总 | L24: 省级汇总 | M24: 工艺汇总
A25: U-P130-01 | B25: 阳泉基地（阳煤化工） | C25: 山西省 | D25: 阳泉市 | E25: 阳煤化工股份有限公司 | F25: 潞安化工集团（阳煤化工股份有限公司） | G25: 乙烯法 | H25: design | I25: 30 | J25: =SUMIFS('06_装置明细'!$L$5:$L$2000,'06_装置明细'!$D$5:$D$2000,"阳泉基地（阳煤化工）") | K25: 集团汇总 | L25: 省级汇总 | M25: 工艺汇总
