Workbook

Sheet 0.说明与口径
B1: 中国重质纯碱出口目标市场研究 — 工作簿
B2: 生成日期：2026-10-19（数据截止见各表）
B4: 产品 | C4: 重质纯碱（Sodium Carbonate, Dense / Heavy Soda Ash），CAS 497-19-8；Na2CO3 ≥99.2%，堆积密度约 0.9–1.1 g/cm³（重质），主要用于浮法玻璃、瓶罐玻璃、光伏玻璃
B5: HS 编码（统计口径） | C5: HS 2836.20 = Disodium carbonate（十位各国本地编码不同：EU 2836 20 00，US 2836.20.00.00）。本工作簿所有贸易数据均按 6 位 HS 2836.20 口径统计。
B6: 贸易数据来源 | C6: UN Comtrade 公开 API（comtradeapi.un.org/public/v1/preview），商品 HS 2836.20，flow=M（进口），报告国口径（as-reported），CIF 计值。
B7: 数据年份 | C7: 2019–2025。2025 年为部分国家初步数据；2024 年报告国 144 个、2025 年 119 个（2019 年 169 个），报告国覆盖下降会低估全球合计，不可与早期年份直接比较全球总额。
B8: 金额单位 | C8: 美元（USD），当期名义值，未做通胀或汇率调整。
B9: 数量单位 | C9: 净重（netWgt），千克（kg）。部分国家仅报送数量(qty)未报送净重，已在"数据缺口"页标注。
B10: 中国份额算法 | C10: 中国份额 = 报告国自中国进口金额 ÷ 报告国自全球进口金额（同一编码、同一年、同一报告国）。分子分母均取同一报告国口径，避免镜像误差。
B11: 增长率算法 | C11: CAGR = (末年值 ÷ 2019年值)^(1/年数) − 1。若基期缺失或为 0，则该国 CAGR 标记为 n/a，不得以其他年份替代。
B12: 关税来源 | C12: 美国：USITC HTS REST API（hts.usitc.gov）实时查询；欧盟：EU TARIC measures_details（SimDate 2025-01-01）实时查询；其他：trade.gov Country Commercial Guides，仅提供结构不提供行级税率 → 标记为缺口。
B13: 重要声明 | C13: 本工作簿区分三类信息：【贸易统计事实】= 可直接溯源的数字；【产业公开信息】= 官方/权威机构出版物；【初步判断】= 分析推论，需业务验证。“进口规模大 / 增长快”不等于存在可成交需求，更不构成客户采购意向。
B15: 页签导航
B16: 1.国家比较 | C16: 主表：各国进口额/量、增长、中国份额、来源集中度、关税状态（含实时公式）
B17: 2.历年明细 | C17: 各报告国 2019–2025 逐年进口额、净重、自中国进口额、自中国净重
B18: 3.竞争来源国 | C18: 按报告国×年份×来源国的进口额明细，用于竞争结构分析
B19: 4.全球趋势 | C19: 全球合计、中国合计、中国占全球比重
B20: 5.关税与限制 | C20: 各国本地编码、MFN/优惠税率、计征基础、贸易限制、核验状态
B21: 6.HS编码对照 | C21: HS 2836 项下细目及美国 8/10 位税率（USITC 实时）、欧盟 10 位（TARIC）
B22: 7.下游产业 | C22: 下游应用结构与公开产业信息（USGS 等），标注来源
B23: 8.数据缺口 | C23: 明确列出缺失年份/缺失字段/未核验关税
B24: 9.来源清单 | C24: 全部数据来源 URL 与取数时间

Sheet 1.国家比较
A1: 各国进口规模、增长、中国份额与关税比较（HS 2836.20，按最新年度进口额降序）
A2: 金额 USD；数量 kg；CAGR 为 2019→最新年度；中国份额分母为该国自全球进口额。关税列标注【已核验/待核验】。
A4: # | B4: 国家/地区 | C4: ISO3 | D4: 最新年度 | E4: 进口额 (USD) | F4: 进口净重 (kg) | G4: 均价 (USD/t) | H4: 2019 进口额 (USD) | I4: CAGR 2019→末 | J4: 中国供应额 (USD) | K4: 中国份额（金额） | L4: 中国份额（重量） | M4: 最大来源国 | N4: 最大来源国份额 | O4: 关税 MFN | P4: 关税核验状态 | Q4: 贸易限制/备注
A5: 1 | B5: Mexico | C5: MEX | D5: 2025 | E5: 325170396 | F5: 1148794754 | G5: =IFERROR(E5/(F5/1000),"") -> 0 | H5: 352353002 | I5: =IFERROR((E5/H5)^(1/(D5-2019))-1,"") -> 0 | J5: 52186 | K5: =IFERROR(J5/E5,"") -> 0 | L5: =IFERROR(K5*E5/F5,"") -> 0 | M5: USA | N5: 0.9997 | O5: 待核验 | P5: 待核验 | Q5: Mexico is a USMCA party; US-origin material enters duty-free, which is why US share is ~100%. Any China-origin entry faces the general (MFN) rate. Verify against current TIGIE.
A6: 2 | B6: Brazil | C6: BRA | D6: 2025 | E6: 310919639 | F6: 0 | G6: n/a | H6: 338853656 | I6: =IFERROR((E6/H6)^(1/(D6-2019))-1,"") -> 0 | J6: 954937 | K6: =IFERROR(J6/E6,"") -> 0 | L6: =n/a -> 0 | M6: USA | N6: 0.6512 | O6: 待核验 | P6: 待核验 | Q6: Mercosur Common External Tariff applies; cumulative federal+state taxes materially raise landed cost. Confirm NCM 2836.20.00 rate in Receita Federal / TEC.
A7: 3 | B7: Chile | C7: CHL | D7: 2025 | E7: 2.6159102e+08 | F7: 0 | G7: n/a | H7: 1.0738079e+08 | I7: =IFERROR((E7/H7)^(1/(D7-2019))-1,"") -> 0 | J7: 4759200.9 | K7: =IFERROR(J7/E7,"") -> 0 | L7: =n/a -> 0 | M7: USA | N7: 0.9732 | O7: 0.06 | P7: 已核验 | Q7: US-origin enters duty-free under US-Chile FTA, explaining ~97% US share. China has an FTA with Chile - preferential rate for Chinese origin must be verified in the Chile-China FTA schedule.
A8: 4 | B8: India | C8: IND | D8: 2025 | E8: 2.490782e+08 | F8: 0 | G8: n/a | H8: 2.2786392e+08 | I8: =IFERROR((E8/H8)^(1/(D8-2019))-1,"") -> 0 | J8: 13765644 | K8: =IFERROR(J8/E8,"") -> 0 | L8: =n/a -> 0 | M8: USA | N8: 0.3709 | O8: 待核验 | P8: 待核验 | Q8: India operates a trade remedy regime and has raised tariffs extensively 2021-2024 (trade.gov India Import Tariffs, pub. 2026-04-17). Confirm whether any AD/safeguard applies to soda ash.
A9: 5 | B9: Indonesia | C9: IDN | D9: 2025 | E9: 2.2556936e+08 | F9: 0 | G9: n/a | H9: 251935406 | I9: =IFERROR((E9/H9)^(1/(D9-2019))-1,"") -> 0 | J9: 60914157 | K9: =IFERROR(J9/E9,"") -> 0 | L9: =n/a -> 0 | M9: USA | N9: 0.6965 | O9: 待核验 | P9: 待核验 | Q9: Indonesia uses tariffs to protect domestic industry; chemicals specifically cited as higher-tariff or unbound. Also check SNI/import licensing (Permendag) and LS (full customs clearance) rules.
A10: 6 | B10: Netherlands | C10: NLD | D10: 2025 | E10: 1.8346749e+08 | F10: 611646031 | G10: =IFERROR(E10/(F10/1000),"") -> 0 | H10: 58816658 | I10: =IFERROR((E10/H10)^(1/(D10-2019))-1,"") -> 0 | J10: 1466.718 | K10: =IFERROR(J10/E10,"") -> 0 | L10: =IFERROR(K10*E10/F10,"") -> 0 | M10: Türkiye | N10: 0.556 | O10: 0.055 | P10: 已核验 | Q10: EU Waste Regulation (R1013/06) import/export control (CD572-CD577) applies to this code; EU CBAM/other measures to be re-checked at shipment date. No anti-dumping or countervailing duty found for China origin.
A11: 7 | B11: Malaysia | C11: MYS | D11: 2025 | E11: 1.7555514e+08 | F11: 0 | G11: n/a | H11: 1.1672449e+08 | I11: =IFERROR((E11/H11)^(1/(D11-2019))-1,"") -> 0 | J11: 41319051 | K11: =IFERROR(J11/E11,"") -> 0 | L11: =n/a -> 0 | M11: USA | N11: 0.5084 | O11: 待核验 | P11: 待核验 | Q11: Duties tend to be higher where there is significant local production - Malaysia has domestic soda ash-linked industry. Confirm line rate with Royal Malaysian Customs (JKDM).
A12: 8 | B12: Thailand | C12: THA | D12: 2025 | E12: 1.5571309e+08 | F12: 0 | G12: n/a | H12: 1.9075315e+08 | I12: =IFERROR((E12/H12)^(1/(D12-2019))-1,"") -> 0 | J12: 21399583 | K12: =IFERROR(J12/E12,"") -> 0 | L12: =n/a -> 0 | M12: USA | N12: 0.4362 | O12: 待核验 | P12: 待核验 | Q12: ACFTA/Form E may apply. Confirm.
A13: 9 | B13: United Kingdom | C13: GBR | D13: 2025 | E13: 1.3622969e+08 | F13: 0 | G13: n/a | H13: 83111320 | I13: =IFERROR((E13/H13)^(1/(D13-2019))-1,"") -> 0 | J13: 94000.492 | K13: =IFERROR(J13/E13,"") -> 0 | L13: =n/a -> 0 | M13: 来源明细缺失 | N13: n/a | O13: 待核验 | P13: 待核验 | Q13: UK Global Tariff (UKGT) since 2021 differs from EU CCT. No AD measure known; verify.
A14: 10 | B14: Germany | C14: DEU | D14: 2025 | E14: 1.3342216e+08 | F14: 3.8338768e+08 | G14: =IFERROR(E14/(F14/1000),"") -> 0 | H14: 85160804 | I14: =IFERROR((E14/H14)^(1/(D14-2019))-1,"") -> 0 | J14: 122995.97 | K14: =IFERROR(J14/E14,"") -> 0 | L14: =IFERROR(K14*E14/F14,"") -> 0 | M14: 来源明细缺失 | N14: n/a | O14: 0.055 | P14: 已核验 | Q14: Waste Regulation import control applies. No AD/CVD on China origin.
A15: 11 | B15: Italy | C15: ITA | D15: 2025 | E15: 1.3265813e+08 | F15: 524925185 | G15: =IFERROR(E15/(F15/1000),"") -> 0 | H15: 1.0357669e+08 | I15: =IFERROR((E15/H15)^(1/(D15-2019))-1,"") -> 0 | J15: 0 | K15: =IFERROR(J15/E15,"") -> 0 | L15: =IFERROR(K15*E15/F15,"") -> 0 | M15: Türkiye | N15: 0.7291 | O15: 0.055 | P15: 已核验 | Q15: Waste Regulation import control applies. No AD/CVD on China origin.
A16: 12 | B16: Argentina | C16: ARG | D16: 2025 | E16: 1.3219808e+08 | F16: 0 | G16: n/a | H16: 53433638 | I16: =IFERROR((E16/H16)^(1/(D16-2019))-1,"") -> 0 | J16: 4462220.5 | K16: =IFERROR(J16/E16,"") -> 0 | L16: =n/a -> 0 | M16: 来源明细缺失 | N16: n/a | O16: 待核验 | P16: 待核验 | Q16: Argentine import licensing/statistical system has been volatile - verify current rules.
A17: 13 | B17: Egypt | C17: EGY | D17: 2025 | E17: 1.2449454e+08 | F17: 3.7920169e+08 | G17: =IFERROR(E17/(F17/1000),"") -> 0 | H17: 1.2016678e+08 | I17: =IFERROR((E17/H17)^(1/(D17-2019))-1,"") -> 0 | J17: 284943.97 | K17: =IFERROR(J17/E17,"") -> 0 | L17: =IFERROR(K17*E17/F17,"") -> 0 | M17: 来源明细缺失 | N17: n/a | O17: 待核验 | P17: 待核验 | Q17: Egypt has domestic soda ash production; check import registration (GOEIC) and any local-content rules.
A18: 14 | B18: Spain | C18: ESP | D18: 2025 | E18: 1.2070851e+08 | F18: 0 | G18: n/a | H18: 94142374 | I18: =IFERROR((E18/H18)^(1/(D18-2019))-1,"") -> 0 | J18: 93777.418 | K18: =IFERROR(J18/E18,"") -> 0 | L18: =n/a -> 0 | M18: 来源明细缺失 | N18: n/a | O18: 0.055 | P18: 已核验 | Q18: Waste Regulation import control applies. No AD/CVD on China origin.
A19: 15 | B19: Kazakhstan | C19: KAZ | D19: 2025 | E19: 1.0530552e+08 | F19: 0 | G19: n/a | H19: 82280491 | I19: =IFERROR((E19/H19)^(1/(D19-2019))-1,"") -> 0 | J19: 10695262 | K19: =IFERROR(J19/E19,"") -> 0 | L19: =n/a -> 0 | M19: 来源明细缺失 | N19: n/a | O19: 待核验 | P19: 待核验 | Q19: EAEU (EEU) common external tariff applies; landlocked - rail logistics dominate.
A20: 16 | B20: South Africa | C20: ZAF | D20: 2025 | E20: 1.0020136e+08 | F20: 3.2591926e+08 | G20: =IFERROR(E20/(F20/1000),"") -> 0 | H20: 70630197 | I20: =IFERROR((E20/H20)^(1/(D20-2019))-1,"") -> 0 | J20: 17068386 | K20: =IFERROR(J20/E20,"") -> 0 | L20: =IFERROR(K20*E20/F20,"") -> 0 | M20: 来源明细缺失 | N20: n/a | O20: 待核验 | P20: 待核验 | Q20: SACU common external tariff; confirm.
A21: 17 | B21: Rep. of Korea | C21: KOR | D21: 2025 | E21: 96262699 | F21: 4.4863708e+08 | G21: =IFERROR(E21/(F21/1000),"") -> 0 | H21: 126830022 | I21: =IFERROR((E21/H21)^(1/(D21-2019))-1,"") -> 0 | J21: 34223849 | K21: =IFERROR(J21/E21,"") -> 0 | L21: =IFERROR(K21*E21/F21,"") -> 0 | M21: 来源明细缺失 | N21: n/a | O21: 待核验 | P21: 待核验 | Q21: Korea-China FTA in force since 2015 - preferential rate may apply with certificate of origin. Korea has its own producer base.
A22: 18 | B22: Poland | C22: POL | D22: 2025 | E22: 85819199 | F22: 2.9188111e+08 | G22: =IFERROR(E22/(F22/1000),"") -> 0 | H22: 7451442 | I22: =IFERROR((E22/H22)^(1/(D22-2019))-1,"") -> 0 | J22: 32974 | K22: =IFERROR(J22/E22,"") -> 0 | L22: =IFERROR(K22*E22/F22,"") -> 0 | M22: 来源明细缺失 | N22: n/a | O22: 0.055 | P22: 已核验 | Q22: Waste Regulation import control applies.
A23: 19 | B23: Saudi Arabia | C23: SAU | D23: 2025 | E23: 73069946 | F23: 298722364 | G23: =IFERROR(E23/(F23/1000),"") -> 0 | H23: 85941551 | I23: =IFERROR((E23/H23)^(1/(D23-2019))-1,"") -> 0 | J23: 8708710.5 | K23: =IFERROR(J23/E23,"") -> 0 | L23: =IFERROR(K23*E23/F23,"") -> 0 | M23: 来源明细缺失 | N23: n/a | O23: 待核验 | P23: 待核验 | Q23: GCC common tariff; SASO conformity required.
A24: 20 | B24: France | C24: FRA | D24: 2025 | E24: 64277960 | F24: 0 | G24: n/a | H24: 81798238 | I24: =IFERROR((E24/H24)^(1/(D24-2019))-1,"") -> 0 | J24: 130414.49 | K24: =IFERROR(J24/E24,"") -> 0 | L24: =n/a -> 0 | M24: 来源明细缺失 | N24: n/a | O24: 0.055 | P24: 已核验 | Q24: Waste Regulation import control applies.
A25: 21 | B25: Türkiye | C25: TUR | D25: 2025 | E25: 63744835 | F25: 0 | G25: n/a | H25: 46523294 | I25: =IFERROR((E25/H25)^(1/(D25-2019))-1,"") -> 0 | J25: 1043 | K25: =IFERROR(J25/E25,"") -> 0 | L25: =n/a -> 0 | M25: 来源明细缺失 | N25: n/a | O25: 待核验 | P25: 待核验 | Q25: Turkiye is itself a major global soda ash producer (source of ~92% of US imports per USGS MCS 2025) and an exporter - treat as competitor, not a target. Watch for domestic-injury trade actions.
A26: 22 | B26: Belgium | C26: BEL | D26: 2025 | E26: 63316346 | F26: 0 | G26: n/a | H26: 41056887 | I26: =IFERROR((E26/H26)^(1/(D26-2019))-1,"") -> 0 | J26: 110310.8 | K26: =IFERROR(J26/E26,"") -> 0 | L26: =n/a -> 0 | M26: 来源明细缺失 | N26: n/a | O26: 0.055 | P26: 已核验 | Q26: Waste Regulation import control applies.
A27: 23 | B27: Nigeria | C27: NGA | D27: 2025 | E27: 63062868 | F27: 0 | G27: n/a | H27: 64751676 | I27: =IFERROR((E27/H27)^(1/(D27-2019))-1,"") -> 0 | J27: 34814704 | K27: =IFERROR(J27/E27,"") -> 0 | L27: =n/a -> 0 | M27: 来源明细缺失 | N27: n/a | O27: 待核验 | P27: 待核验 | Q27: ECOWAS CET; FX controls and import procedures are material risks.
A28: 24 | B28: Ukraine | C28: UKR | D28: 2024 | E28: 60873489 | F28: 0 | G28: n/a | H28: 61776932 | I28: =IFERROR((E28/H28)^(1/(D28-2019))-1,"") -> 0 | J28: 62255.19 | K28: =IFERROR(J28/E28,"") -> 0 | L28: =n/a -> 0 | M28: 来源明细缺失 | N28: n/a | O28: 待核验 | P28: 待核验 | Q28: War-related logistics and insurance risk; partial-year data only.

Sheet 2.历年明细
A1: 各报告国 2019–2025 逐年：进口额 / 净重 / 自中国进口额 / 自中国净重（HS 2836.20，USD 与 kg）
A2: 空白 = 该国该年未向 UN Comtrade 报送该编码数据（缺口），不以 0 填充、不得插值。
A4: 国家 | B4: ISO3 | C4: 年份 | D4: 进口额 (USD) | E4: 进口净重 (kg) | F4: 自中国进口额 (USD) | G4: 自中国净重 (kg) | H4: 中国份额（金额） | I4: 中国份额（重量）
A5: Afghanistan | B5: AFG | C5: 2019 | D5: 690666.41 | E5: 1418816 | F5: 191652.34 | G5: 415806 | H5: =IFERROR(F5/D5,"") -> 0 | I5: =IFERROR(G5/E5,"") -> 0
A6: Albania | B6: ALB | C6: 2019 | D6: 9889.469 | E6: 8740 | F6: 0 | G6: 0 | H6: =IFERROR(F6/D6,"") -> 0 | I6: =IFERROR(G6/E6,"") -> 0
A7: Albania | B7: ALB | C7: 2020 | D7: 20809.504 | E7: 14940 | F7: 0 | G7: 0 | H7: =IFERROR(F7/D7,"") -> 0 | I7: =IFERROR(G7/E7,"") -> 0
A8: Albania | B8: ALB | C8: 2023 | D8: 109911.05 | E8: 186345 | F8: 0 | G8: 0 | H8: =IFERROR(F8/D8,"") -> 0 | I8: =IFERROR(G8/E8,"") -> 0
A9: Albania | B9: ALB | C9: 2024 | D9: 12122.138 | E9: 12936.39 | F9: 0 | G9: 0 | H9: =IFERROR(F9/D9,"") -> 0 | I9: =IFERROR(G9/E9,"") -> 0
A10: Algeria | B10: DZA | C10: 2024 | D10: 24308759 | E10: 72405436 | F10: 54196 | G10: 161426.79 | H10: =IFERROR(F10/D10,"") -> 0 | I10: =IFERROR(G10/E10,"") -> 0
A11: Andorra | B11: AND | C11: 2019 | D11: 303.816 | E11: 134.68 | F11: 0 | G11: 0 | H11: =IFERROR(F11/D11,"") -> 0 | I11: =IFERROR(G11/E11,"") -> 0
A12: Andorra | B12: AND | C12: 2020 | D12: 418.901 | E12: 258 | F12: 0 | G12: 0 | H12: =IFERROR(F12/D12,"") -> 0 | I12: =IFERROR(G12/E12,"") -> 0
A13: Andorra | B13: AND | C13: 2021 | D13: 667.083 | E13: 62.82 | F13: 0 | G13: 0 | H13: =IFERROR(F13/D13,"") -> 0 | I13: =IFERROR(G13/E13,"") -> 0
A14: Andorra | B14: AND | C14: 2022 | D14: 366.037 | E14: 139.4 | F14: 0 | G14: 0 | H14: =IFERROR(F14/D14,"") -> 0 | I14: =IFERROR(G14/E14,"") -> 0
A15: Andorra | B15: AND | C15: 2023 | D15: 532.189 | E15: 199.9 | F15: 0 | G15: 0 | H15: =IFERROR(F15/D15,"") -> 0 | I15: =IFERROR(G15/E15,"") -> 0
A16: Andorra | B16: AND | C16: 2024 | D16: 227.867 | E16: 80 | F16: 0 | G16: 0 | H16: =IFERROR(F16/D16,"") -> 0 | I16: =IFERROR(G16/E16,"") -> 0
A17: Andorra | B17: AND | C17: 2025 | D17: 197.942 | E17: 79 | F17: 0 | G17: 0 | H17: =IFERROR(F17/D17,"") -> 0 | I17: =IFERROR(G17/E17,"") -> 0
A18: Angola | B18: AGO | C18: 2019 | D18: 4251544.3 | E18: 0 | F18: 87989.12 | G18: 235416.2 | H18: =IFERROR(F18/D18,"") -> 0 | I18: ="n/a" -> 0
A19: Angola | B19: AGO | C19: 2020 | D19: 4711200.5 | E19: 12297960 | F19: 868989.03 | G19: 2430606 | H19: =IFERROR(F19/D19,"") -> 0 | I19: =IFERROR(G19/E19,"") -> 0
A20: Angola | B20: AGO | C20: 2021 | D20: 4583277 | E20: 0 | F20: 139741.43 | G20: 753111 | H20: =IFERROR(F20/D20,"") -> 0 | I20: ="n/a" -> 0
A21: Angola | B21: AGO | C21: 2022 | D21: 14051966 | E21: 22985817 | F21: 6119414 | G21: 11113885 | H21: =IFERROR(F21/D21,"") -> 0 | I21: =IFERROR(G21/E21,"") -> 0
A22: Angola | B22: AGO | C22: 2023 | D22: 7148225.4 | E22: 14664426 | F22: 2530334.3 | G22: 4631588.8 | H22: =IFERROR(F22/D22,"") -> 0 | I22: =IFERROR(G22/E22,"") -> 0
A23: Angola | B23: AGO | C23: 2024 | D23: 6176346.3 | E23: 0 | F23: 790854.13 | G23: 2301406.7 | H23: =IFERROR(F23/D23,"") -> 0 | I23: ="n/a" -> 0
A24: Angola | B24: AGO | C24: 2025 | D24: 6903117.8 | E24: 21357676 | F24: 2343072.6 | G24: 6767349.2 | H24: =IFERROR(F24/D24,"") -> 0 | I24: =IFERROR(G24/E24,"") -> 0
A25: Antigua and Barbuda | B25: ATG | C25: 2019 | D25: 23737.313 | E25: 4868.22 | F25: 0 | G25: 0 | H25: =IFERROR(F25/D25,"") -> 0 | I25: =IFERROR(G25/E25,"") -> 0
A26: Antigua and Barbuda | B26: ATG | C26: 2020 | D26: 5144.793 | E26: 2054.98 | F26: 0 | G26: 0 | H26: =IFERROR(F26/D26,"") -> 0 | I26: =IFERROR(G26/E26,"") -> 0
A27: Antigua and Barbuda | B27: ATG | C27: 2021 | D27: 5861.115 | E27: 2836.69 | F27: 0 | G27: 0 | H27: =IFERROR(F27/D27,"") -> 0 | I27: =IFERROR(G27/E27,"") -> 0
A28: Antigua and Barbuda | B28: ATG | C28: 2022 | D28: 5118.163 | E28: 2038.98 | F28: 0 | G28: 0 | H28: =IFERROR(F28/D28,"") -> 0 | I28: =IFERROR(G28/E28,"") -> 0
A29: Antigua and Barbuda | B29: ATG | C29: 2023 | D29: 12545.289 | E29: 5380.25 | F29: 0 | G29: 0 | H29: =IFERROR(F29/D29,"") -> 0 | I29: =IFERROR(G29/E29,"") -> 0
A30: Antigua and Barbuda | B30: ATG | C30: 2024 | D30: 10312.963 | E30: 23387.557 | F30: 0 | G30: 0 | H30: =IFERROR(F30/D30,"") -> 0 | I30: =IFERROR(G30/E30,"") -> 0
A31: Argentina | B31: ARG | C31: 2019 | D31: 53433638 | E31: 0 | F31: 543335.35 | G31: 1800515 | H31: =IFERROR(F31/D31,"") -> 0 | I31: ="n/a" -> 0
A32: Argentina | B32: ARG | C32: 2020 | D32: 49401721 | E32: 0 | F32: 469003.25 | G32: 1670250 | H32: =IFERROR(F32/D32,"") -> 0 | I32: ="n/a" -> 0
A33: Argentina | B33: ARG | C33: 2021 | D33: 52206456 | E33: 0 | F33: 386913.61 | G33: 1378500 | H33: =IFERROR(F33/D33,"") -> 0 | I33: ="n/a" -> 0
A34: Argentina | B34: ARG | C34: 2022 | D34: 1.1243973e+08 | E34: 0 | F34: 7381925.2 | G34: 11311750 | H34: =IFERROR(F34/D34,"") -> 0 | I34: ="n/a" -> 0
A35: Argentina | B35: ARG | C35: 2023 | D35: 1.6966647e+08 | E35: 0 | F35: 20047136 | G35: 34784603 | H35: =IFERROR(F35/D35,"") -> 0 | I35: ="n/a" -> 0
A36: Argentina | B36: ARG | C36: 2024 | D36: 1.0432361e+08 | E36: 0 | F36: 1260268.4 | G36: 2518500 | H36: =IFERROR(F36/D36,"") -> 0 | I36: ="n/a" -> 0
A37: Argentina | B37: ARG | C37: 2025 | D37: 1.3219808e+08 | E37: 0 | F37: 4462220.5 | G37: 0 | H37: =IFERROR(F37/D37,"") -> 0 | I37: ="n/a" -> 0
A38: Armenia | B38: ARM | C38: 2019 | D38: 5390200 | E38: 0 | F38: 0 | G38: 0 | H38: =IFERROR(F38/D38,"") -> 0 | I38: ="n/a" -> 0
A39: Armenia | B39: ARM | C39: 2020 | D39: 5819634.1 | E39: 0 | F39: 0 | G39: 0 | H39: =IFERROR(F39/D39,"") -> 0 | I39: ="n/a" -> 0
A40: Armenia | B40: ARM | C40: 2021 | D40: 4118132.1 | E40: 0 | F40: 0 | G40: 0 | H40: =IFERROR(F40/D40,"") -> 0 | I40: ="n/a" -> 0
A41: Armenia | B41: ARM | C41: 2022 | D41: 4743735.3 | E41: 0 | F41: 0 | G41: 0 | H41: =IFERROR(F41/D41,"") -> 0 | I41: ="n/a" -> 0
...

Sheet 3.竞争来源国
A1: 竞争来源国明细：报告国 × 年份 × 来源国 的进口额与净重（HS 2836.20）
A2: 仅覆盖本次成功取到 partner 明细的 12 个主要进口国；其余国家见"数据缺口"页。份额列 = 该国份额 ÷ 该国当年全部来源合计。
A4: 报告国 | B4: 报告国 ISO3 | C4: 年份 | D4: 来源国 | E4: 来源国 ISO3 | F4: 进口额 (USD) | G4: 净重 (kg)
A5: Brazil | B5: BRA | C5: 2020 | D5: USA | E5: 842 | F5: 141972657 | G5: 6.5584487e+08
A6: Brazil | B6: BRA | C6: 2020 | D6: Türkiye | E6: 792 | F6: 76487808 | G6: 351193540
A7: Brazil | B7: BRA | C7: 2020 | D7: Spain | E7: 724 | F7: 64095655 | G7: 260157673
A8: Brazil | B8: BRA | C8: 2020 | D8: Russian Federation | E8: 643 | F8: 3376914 | G8: 15677775
A9: Brazil | B9: BRA | C9: 2020 | D9: China | E9: 156 | F9: 819201 | G9: 3069703
A10: Brazil | B10: BRA | C10: 2020 | D10: Italy | E10: 380 | F10: 411539 | G10: 1498000
A11: Brazil | B11: BRA | C11: 2020 | D11: Poland | E11: 616 | F11: 146367 | G11: 567820
A12: Brazil | B12: BRA | C12: 2020 | D12: France | E12: 251 | F12: 104101 | G12: 45150
A13: Brazil | B13: BRA | C13: 2020 | D13: China, Hong Kong SAR | E13: 344 | F13: 60527 | G13: 299200
A14: Brazil | B14: BRA | C14: 2020 | D14: Bulgaria | E14: 100 | F14: 57710 | G14: 180000
A15: Brazil | B15: BRA | C15: 2020 | D15: Germany | E15: 276 | F15: 48640 | G15: 29142.715
A16: Brazil | B16: BRA | C16: 2020 | D16: United Kingdom | E16: 826 | F16: 40542 | G16: 157500
... A1285: Viet Nam | B1285: VNM | C1285: 2023 | D1285: Israel | E1285: 376 | F1285: 1691 | G1285: 3929.967

Sheet 4.全球趋势
A1: 全球进口合计与中国份额（对"已报送国家"求和，非真实世界总额）
A2: 注意：报告国数量逐年变化（2019:169 / 2024:144 / 2025:119），合计值受覆盖度影响，跨年比较需谨慎。
A4: 年份 | B4: 报告国数 | C4: 进口合计 (USD) | D4: 自中国合计 (USD) | E4: 中国占全球比重 | F4: 进口净重合计 (kg) | G4: 自中国净重 (kg) | H4: 中国重量占比
A5: 2019 | B5: 169 | C5: =SUMIF('2.历年明细'!$C$4:$C$2000,A5,'2.历年明细'!$D$4:$D$2000) -> 0 | D5: =SUMIF('2.历年明细'!$C$4:$C$2000,A5,'2.历年明细'!$F$4:$F$2000) -> 0 | E5: =IFERROR(D5/C5,"") -> 0 | F5: =SUMIF('2.历年明细'!$C$4:$C$2000,A5,'2.历年明细'!$E$4:$E$2000) -> 0 | G5: =SUMIF('2.历年明细'!$C$4:$C$2000,A5,'2.历年明细'!$G$4:$G$2000) -> 0 | H5: =IFERROR(G5/F5,"") -> 0
A6: 2020 | B6: 164 | C6: =SUMIF('2.历年明细'!$C$4:$C$2000,A6,'2.历年明细'!$D$4:$D$2000) -> 0 | D6: =SUMIF('2.历年明细'!$C$4:$C$2000,A6,'2.历年明细'!$F$4:$F$2000) -> 0 | E6: =IFERROR(D6/C6,"") -> 0 | F6: =SUMIF('2.历年明细'!$C$4:$C$2000,A6,'2.历年明细'!$E$4:$E$2000) -> 0 | G6: =SUMIF('2.历年明细'!$C$4:$C$2000,A6,'2.历年明细'!$G$4:$G$2000) -> 0 | H6: =IFERROR(G6/F6,"") -> 0
A7: 2021 | B7: 163 | C7: =SUMIF('2.历年明细'!$C$4:$C$2000,A7,'2.历年明细'!$D$4:$D$2000) -> 0 | D7: =SUMIF('2.历年明细'!$C$4:$C$2000,A7,'2.历年明细'!$F$4:$F$2000) -> 0 | E7: =IFERROR(D7/C7,"") -> 0 | F7: =SUMIF('2.历年明细'!$C$4:$C$2000,A7,'2.历年明细'!$E$4:$E$2000) -> 0 | G7: =SUMIF('2.历年明细'!$C$4:$C$2000,A7,'2.历年明细'!$G$4:$G$2000) -> 0 | H7: =IFERROR(G7/F7,"") -> 0
A8: 2022 | B8: 163 | C8: =SUMIF('2.历年明细'!$C$4:$C$2000,A8,'2.历年明细'!$D$4:$D$2000) -> 0 | D8: =SUMIF('2.历年明细'!$C$4:$C$2000,A8,'2.历年明细'!$F$4:$F$2000) -> 0 | E8: =IFERROR(D8/C8,"") -> 0 | F8: =SUMIF('2.历年明细'!$C$4:$C$2000,A8,'2.历年明细'!$E$4:$E$2000) -> 0 | G8: =SUMIF('2.历年明细'!$C$4:$C$2000,A8,'2.历年明细'!$G$4:$G$2000) -> 0 | H8: =IFERROR(G8/F8,"") -> 0
A9: 2023 | B9: 162 | C9: =SUMIF('2.历年明细'!$C$4:$C$2000,A9,'2.历年明细'!$D$4:$D$2000) -> 0 | D9: =SUMIF('2.历年明细'!$C$4:$C$2000,A9,'2.历年明细'!$F$4:$F$2000) -> 0 | E9: =IFERROR(D9/C9,"") -> 0 | F9: =SUMIF('2.历年明细'!$C$4:$C$2000,A9,'2.历年明细'!$E$4:$E$2000) -> 0 | G9: =SUMIF('2.历年明细'!$C$4:$C$2000,A9,'2.历年明细'!$G$4:$G$2000) -> 0 | H9: =IFERROR(G9/F9,"") -> 0
A10: 2024 | B10: 144 | C10: =SUMIF('2.历年明细'!$C$4:$C$2000,A10,'2.历年明细'!$D$4:$D$2000) -> 0 | D10: =SUMIF('2.历年明细'!$C$4:$C$2000,A10,'2.历年明细'!$F$4:$F$2000) -> 0 | E10: =IFERROR(D10/C10,"") -> 0 | F10: =SUMIF('2.历年明细'!$C$4:$C$2000,A10,'2.历年明细'!$E$4:$E$2000) -> 0 | G10: =SUMIF('2.历年明细'!$C$4:$C$2000,A10,'2.历年明细'!$G$4:$G$2000) -> 0 | H10: =IFERROR(G10/F10,"") -> 0
A11: 2025 | B11: 119 | C11: =SUMIF('2.历年明细'!$C$4:$C$2000,A11,'2.历年明细'!$D$4:$D$2000) -> 0 | D11: =SUMIF('2.历年明细'!$C$4:$C$2000,A11,'2.历年明细'!$F$4:$F$2000) -> 0 | E11: =IFERROR(D11/C11,"") -> 0 | F11: =SUMIF('2.历年明细'!$C$4:$C$2000,A11,'2.历年明细'!$E$4:$E$2000) -> 0 | G11: =SUMIF('2.历年明细'!$C$4:$C$2000,A11,'2.历年明细'!$G$4:$G$2000) -> 0 | H11: =IFERROR(G11/F11,"") -> 0

Sheet 5.关税与限制
A1: 目的国对中国产 HS 2836.20 的进口关税、优惠税率与主要贸易限制
A2: 【已核验】= 本次会话实时抓取官方系统；【待核验】= 未能取得行级税率，必须补齐后才可用于报价。绿色=已核验，黄色=缺口。
A4: ISO3 | B4: 国家/地区 | C4: 本地编码 | D4: MFN 税率 | E4: 优惠税率 | F4: 计征基础 | G4: 来源（URL/机构） | H4: 主要贸易限制 / 非关税措施 | I4: 核验状态
A5: MEX | B5: Mexico | C5: 2836.20.01 (TIGIE) | D5: 待核验 | E5: 见备注 | F5: CIF | G5: SAT / TIGIE schedule (dof.gob.mx) - not machine-accessible this session | H5: Mexico is a USMCA party; US-origin material enters duty-free, which is why US share is ~100%. Any China-origin entry faces the general (MFN) rate. Verify against current TIGIE. Need confirmation of specific TIGIE fraction for disodium carbonate before quoting. | I5: 待核验
A6: BRA | B6: Brazil | C6: 2836.20.00 (NCM) | D6: 待核验 | E6: 见备注 | F6: CIF (II) plus IPI, PIS/COFINS, ICMS cumulative | G6: trade.gov Brazil Import Tariffs (pub. 2025-08-21) - general structure only; NCM rate not published on that page | H6: Mercosur Common External Tariff applies; cumulative federal+state taxes materially raise landed cost. Confirm NCM 2836.20.00 rate in Receita Federal / TEC. II rate for NCM 2836.20.00 must be verified; total tax wedge is much larger than the II alone. | I6: 待核验
A7: CHL | B7: Chile | C7: HS 2836.20 | D7: 0.06 | E7: 一般税率适用 | F7: CIF | G7: trade.gov Chile Import Tariffs (pub. 2025-11-24): non-FTA origin pays a uniform 6% | H7: US-origin enters duty-free under US-Chile FTA, explaining ~97% US share. China has an FTA with Chile - preferential rate for Chinese origin must be verified in the Chile-China FTA schedule. 6% is the general rate for non-FTA origin; do NOT quote 6% for China origin without checking the China-Chile FTA rate. | I7: 已核验
A8: IND | B8: India | C8: 2836.20.00 (CTH) | D8: 待核验 | E8: 见备注 | F8: CIF + Basic Customs Duty + Social Welfare Surcharge + IGST | G8: CBIC Customs Tariff (cbic.gov.in) - JS-gated, not retrievable this session | H8: India operates a trade remedy regime and has raised tariffs extensively 2021-2024 (trade.gov India Import Tariffs, pub. 2026-04-17). Confirm whether any AD/safeguard applies to soda ash. CRITICAL GAP: India is the fastest-growing large market; its BCD+SWS+IGST stack must be verified before any quotation. | I8: 待核验
A9: IDN | B9: Indonesia | C9: HS 2836.20 | D9: 待核验 | E9: 见备注 | F9: CIF + import duty + VAT/PPN + income tax art.22 | G9: trade.gov Indonesia Import Tariffs (pub. 2025-11-17): average MFN 8.1%; chemicals flagged as facing higher or unbound rates | H9: Indonesia uses tariffs to protect domestic industry; chemicals specifically cited as higher-tariff or unbound. Also check SNI/import licensing (Permendag) and LS (full customs clearance) rules. Line-specific MFN rate unavailable - do not substitute the 8.1% national average for the product rate. | I9: 待核验
A10: MYS | B10: Malaysia | C10: HS 2836.20 | D10: 待核验 | E10: 见备注 | F10: CIF + SST (5-10%) | G10: trade.gov Malaysia Import Tariffs (pub. 2026-06-30): simple average 6.1% for industrial goods; line rate not published | H10: Duties tend to be higher where there is significant local production - Malaysia has domestic soda ash-linked industry. Confirm line rate with Royal Malaysian Customs (JKDM). ACFTA (ASEAN-China FTA) preferential treatment may apply - verify Form E eligibility. | I10: 待核验
A11: THA | B11: Thailand | C11: HS 2836.20 | D11: 待核验 | E11: 见备注 | F11: CIF | G11: Thai Customs tariff (customs.go.th) - not retrieved | H11: ACFTA/Form E may apply. Confirm. Line rate to be verified. | I11: 待核验
A12: NLD | B12: Netherlands | C12: 2836 20 00 | D12: 0.055 | E12: 一般税率适用 | F12: CIF | G12: EU TARIC, queried SimDate=2025-01-01, Area=CN, Taric=2836200000 (live pull this session) | H12: EU Waste Regulation (R1013/06) import/export control (CD572-CD577) applies to this code; EU CBAM/other measures to be re-checked at shipment date. No anti-dumping or countervailing duty found for China origin. NL is largely a port/entrepot market (Rotterdam) - import value overstates Dutch domestic consumption. | I12: 已核验
A13: DEU | B13: Germany | C13: 2836 20 00 | D13: 0.055 | E13: 一般税率适用 | F13: CIF | G13: EU TARIC (as Netherlands) | H13: Waste Regulation import control applies. No AD/CVD on China origin. Anchor market for EU flat/container glass and detergents. | I13: 已核验
A14: ITA | B14: Italy | C14: 2836 20 00 | D14: 0.055 | E14: 一般税率适用 | F14: CIF | G14: EU TARIC (as Netherlands) | H14: Waste Regulation import control applies. No AD/CVD on China origin. Italy is served mostly by Turkiye/Bulgaria - a competitive, short-sea-supplied market. | I14: 已核验
A15: ESP | B15: Spain | C15: 2836 20 00 | D15: 0.055 | E15: 一般税率适用 | F15: CIF | G15: EU TARIC (as Netherlands) | H15: Waste Regulation import control applies. No AD/CVD on China origin. | I15: 已核验
A16: FRA | B16: France | C16: 2836 20 00 | D16: 0.055 | E16: 一般税率适用 | F16: CIF | G16: EU TARIC (as Netherlands) | H16: Waste Regulation import control applies. | I16: 已核验
A17: POL | B17: Poland | C17: 2836 20 00 | D17: 0.055 | E17: 一般税率适用 | F17: CIF | G17: EU TARIC (as Netherlands) | H17: Waste Regulation import control applies. Poland 2019->2025 growth reflects enlargement-era supply chain build-out within the single market. | I17: 已核验
A18: BEL | B18: Belgium | C18: 2836 20 00 | D18: 0.055 | E18: 一般税率适用 | F18: CIF | G18: EU TARIC (as Netherlands) | H18: Waste Regulation import control applies. Antwerp port effect likely inflates value. | I18: 已核验
A19: GBR | B19: United Kingdom | C19: 2836 20 00 | D19: 待核验 | E19: 见备注 | F19: CIF | G19: UK Trade Tariff (trade-tariff.service.gov.uk) - not retrieved this session | H19: UK Global Tariff (UKGT) since 2021 differs from EU CCT. No AD measure known; verify. Post-Brexit UKGT rate to be verified; note the UK is not in the EU customs union. | I19: 待核验
A20: KOR | B20: Rep. of Korea | C20: 2836.20-0000 | D20: 待核验 | E20: 见备注 | F20: CIF | G20: Korea Customs Service (customs.go.kr) / KCS UNIPASS - not retrieved | H20: Korea-China FTA in force since 2015 - preferential rate may apply with certificate of origin. Korea has its own producer base. Verify both MFN and Korea-China FTA rate. | I20: 待核验
A21: TUR | B21: Turkiye | C21: 2836.20.00.00 | D21: 待核验 | E21: 见备注 | F21: CIF + VAT 20% | G21: trade.gov Turkiye Import Tariffs (pub. 2026-01-29): EU-aligned tariff structure + customs union; line rate not published | H21: Turkiye is itself a major global soda ash producer (source of ~92% of US imports per USGS MCS 2025) and an exporter - treat as competitor, not a target. Watch for domestic-injury trade actions. Turkiye listed as competitor; also note possible local-content / safeguard sensitivity. | I21: 待核验
A22: ZAF | B22: South Africa | C22: HS 2836.20 | D22: 待核验 | E22: 见备注 | F22: CIF | G22: SARS tariff (sars.gov.za) - not retrieved | H22: SACU common external tariff; confirm. | I22: 待核验
A23: EGY | B23: Egypt | C23: HS 2836.20 | D23: 待核验 | E23: 见备注 | F23: CIF | G23: Egyptian Customs (customs.gov.eg) - not retrieved | H23: Egypt has domestic soda ash production; check import registration (GOEIC) and any local-content rules. | I23: 待核验
A24: ARG | B24: Argentina | C24: 2836.20.00 (NCM) | D24: 待核验 | E24: 见备注 | F24: CIF | G24: Mercosur CET; not retrieved | H24: Argentine import licensing/statistical system has been volatile - verify current rules. | I24: 待核验
A25: SAU | B25: Saudi Arabia | C25: HS 2836.20 | D25: 待核验 | E25: 见备注 | F25: CIF | G25: ZATCA tariff - not retrieved | H25: GCC common tariff; SASO conformity required. | I25: 待核验
A26: KAZ | B26: Kazakhstan | C26: HS 2836.20 | D26: 待核验 | E26: 见备注 | F26: CIF | G26: EAEU common tariff - not retrieved | H26: EAEU (EEU) common external tariff applies; landlocked - rail logistics dominate. | I26: 待核验
A27: NGA | B27: Nigeria | C27: HS 2836.20 | D27: 待核验 | E27: 见备注 | F27: CIF | G27: Nigeria Customs Service CET - not retrieved | H27: ECOWAS CET; FX controls and import procedures are material risks. | I27: 待核验
A28: UKR | B28: Ukraine | C28: HS 2836.20 | D28: 待核验 | E28: 见备注 | F28: CIF | G28: not retrieved | H28: War-related logistics and insurance risk; partial-year data only. Latest full year 2024. | I28: 待核验

Sheet 6.HS编码对照
A1: HS 2836 项下细目与美国 10 位税率（来源：USITC HTS REST API 实时查询，2026-10-19）
A2: 重质纯碱归属 2836.20 各国一级细目。注意：部分国家（如印度）在 2836 下有本国细分监控码，但其 6 位层仍为 2836.20，贸易统计可比较。
A5: 2836 | B5: Carbonates; peroxocarbonates; commercial ammonium carbonate containing ammonium carbamate | C5: —
A6: 2836.20.00.00 | B6: Disodium carbonate ← 目标产品（重质纯碱） | C6: 1.2%
A7: 2836.30.00.00 | B7: Sodium hydrogencarbonate (sodium bicarbonate) | C7: Free
A8: 2836.40.10.00 | B8: Dipotassium carbonate | C8: 1.9%
A9: 2836.40.20.00 | B9: Potassium hydrogencarbonate (potassium bicarbonate) | C9: 1.3%
A10: 2836.50.00.00 | B10: Calcium carbonate | C10: Free
A11: 2836.60.00.00 | B11: Barium carbonate | C11: 2.3%
A12: 2836.91.00 | B12: Lithium carbonates | C12: 3.7%
A13: 2836.92.00.00 | B13: Strontium carbonate | C13: 4.2%
A14: 2836.99.10.00 | B14: Cobalt carbonates | C14: 4.2%
A15: 2836.99.20.00 | B15: Bismuth carbonate | C15: 5.5%
A16: 2836.99.30.00 | B16: Commercial ammonium carbonate and other ammonium carbonates | C16: 1.7%
... A18: 2836.99.50 | B18: Other carbonates | C18: 3.7%
A21: EU TARIC | B21: EU 10 位：2836 20 00 00 — 第三国关税 5.50%（SimDate 2025-01-01，Area=CN）；适用法规 R2658/87；另受 《废弃条例》R1013/06 进出口管制（CD572–CD577）。
A22: 口径提示 | B22: 6 位 HS 2836.20 仅含碳酸二钠（纯碱），不含碳酸氢钠(2836.30)、过碳酸钠(2836.99 视各国归类)。重质与轻质纯碱在 6 位层不区分，须用报告国 8/10 位细分或买方规格加以区分——这是本分析的核心口径局限。

Sheet 7.下游产业
A1: 下游应用结构与公开产业信息（【产业公开信息】不是销量预测）
A5: 纯碱终端用途结构 | B5: 美国（2024 估算） | C5: 玻璃 45%；化学品 29%；杂项 9%；经销商 7%；肥皂与洗涤剂 5%；烟气脱硫 3%；纸浆造纸 1%；水处理 1%。 | D5: USGS Mineral Commodity Summaries 2025, Soda Ash
A6: 全球生产 | B6: 美国 | C6: 2024 年国内产量约 1,200 万吨（12 Mt），同比 +10%；名义产能 1,390 万吨/年（5 家公司 6 厂）。 | D6: USGS MCS 2025
A7: 出口行为 | B7: 美国 | C7: 2024 年出口 740 万吨，超过产量一半；进口仅 1 万吨级 —— 美国是净出口国。 | D7: USGS MCS 2025
A8: 天然 vs 合成 | B8: 全球 | C8: 天然碱（trona）成本与碳排放低于合成碱；土耳其与美国天然碱对合成碱有优势。 | D8: USGS MCS 2025
A9: 浮法/瓶罐玻璃 | B9: 多国 | C9: 纯碱为玻璃配合料助熔剂，玻璃是最大单一出口消化方向；中国重质纯碱主要出口至东南亚、中东玻璃产业集中区。 | D9: 行业通识 + 贸易数据互证
A10: 竞争供给方 | B10: 土耳其 | C10: 土耳其为主要全球出口方之一；美国进口来源国别中土耳其占 92%（2020–23）。 | D10: USGS MCS 2025

Sheet 8.数据缺口
A1: 已识别数据缺口清单（必须补齐后方可对外报价/承诺）
A5: 2025 年数据不完整 | B5: 2025 年仅有 119 个报告国报送（2019 年为 169 个）。部分国家 2025 年为初步/部分年度数据，可能与最终值有差异。 | C5: 用 2023 或 2024 完整年度做决策，2025 仅作方向性参考
A6: 部分国家最新年度较旧 | B6: 越南(VNM) 最新仅到 2023；阿联酋(ARE) 最新 2023；乌克兰(UKR) 最新 2024。 | C6: 在表格中明确标注最新年度，不得当作 2025 数据
A7: 净重(qty)缺失 | B7: 部分报告国只报金额与数量(qty)不报净重(netWgt)，导致 USD/t 单价为空。 | C7: 用 qty 或改用 hsValue 加权；单价不得估算
A8: 竞争来源国明细不全 | B8: 仅 12 个主要进口国取得 partner 级明细（墨西哥/巴西/智利/印度/印尼/中国台湾/泰国/越南/马来西亚/荷兰/德国/意大利）。英国、法国、西班牙、波兰、韩国、土耳其等其他国家的来源国结构待补。 | C8: 补充拉取后更新"3.竞争来源国"页
A9: 行级关税税率 | B9: 除美国(USITC)、欧盟(TARIC)外，其余国家 MFN 行级税率本次未能从官方系统取得（CBIC/WITS/MacMap 均不可达或需账号）。 | C9: 用欧盟 TARIC 服务台 / WTO Tariff Download Facility / 各国海关官网逐条核验
A10: 优惠税率 | B10: 中智FTA、中国-东盟ACFTA(马来西亚/泰国/印尼)、中韩FTA 的具体优惠税率未逐条核验。 | C10: 按 FTA 原产地规则与原产地证书(Form E/FORM F等)核验
A11: 反倾销/反补贴 | B11: 本次仅对欧盟确认"未发现针对中国的 AD/CVD"。其他国家的贸易救济状态未系统核查。 | C11: 核查 WTO I-TIP、各国贸易救济主管机关公告
A12: 重质/轻质区分 | B12: HS 2836.20 不区分重质与轻质纯碱，全部合并统计。 | C12: 用报告国 8/10 位细分或买方采购规格区分；份额结论需口径说明
A13: 中国出口口径 | B13: 本表使用"报告国自中国进口"（镜像口径）。中国海关出口统计（自报口径）未交叉核对。 | C13: 交叉核对后做偏差说明；两者差异通常来自转运与香港/新加坡转口

Sheet 9.来源清单
A1: 数据来源清单（可溯源）
A5: UN Comtrade | B5: https://comtradeapi.un.org/public/v1/preview/C/A/HS?period=&cmdCode=283620&flowCode=M&partnerCode= | C5: 2026-10-19 | D5: HS 2836.20 双边进口额与净重，报告国口径
A6: Comtrade 参考表 | B6: https://comtradeapi.un.org/files/v1/app/reference/Reporters.json ; partnerAreas.json | C6: 2026-10-19 | D6: 国家代码与名称映射（M49）
A7: USITC HTS | B7: https://hts.usitc.gov/reststop/search?keyword=2836.20 | C7: 2026-10-19 | D7: 美国 10 位编码与税率（General/Special/Column 2）
A8: EU TARIC | B8: https://ec.europa.eu/taxation_customs/dds2/taric/measures.jsp (Area=CN, SimDate=20250101) | C8: 2026-10-19 | D8: 欧盟第三国关税 5.50%、废物管制措施
A9: trade.gov 国别指南 | B9: https://www.trade.gov/country-commercial-guides/<country>-import-tariffs | C9: 2026-10-19 | D9: 巴西/智利/印尼/马来西亚/土耳其/印度 关税结构与税种
A10: USGS MCS 2025 | B10: https://pubs.usgs.gov/periodicals/mcs2025/mcs2025-soda-ash.pdf | C10: 2026-10-19 | D10: 美国产量、产能、出口、终端用途结构、进口来源
