Workbook

Sheet 00_说明
A1: 中国电石法 PVC · 产业链利润模型（理论加工价差 / 理论制造利润）
A2: 数据冻结于 2026-10-20 | 区间 2025-10-20～2026-10-19 | 黄色单元格=可编辑输入，灰色=公式输出，请勿手改
A5: 一、这个模型算什么
A6: 理论加工价差 | B6: =产品含税价 − 原料成本（原料单耗已按综合收率修正）。只反映"原料→产品"的转换价差，不含任何加工费用。
A7: 理论制造利润 | B7: =加工价差 − 已核实的能源/辅料/制造费用。仍不是企业净利润。
A8: 企业实际利润 | B8: 本模型【不输出】。它需要财务费用、销售物流、税费、检修损失、区域价差等企业内部数据，缺少可核实来源时不编造。
A10: 二、三层指标为什么必须分开
A11: 常见错误 1 | B11: 把"加工价差"直接叫作"利润"。价差 1083 元/吨听起来很好，扣完成本后是 -431 元/吨，方向完全相反。
A12: 常见错误 2 | B12: 把不同工艺的单耗混用。外购电石口径的电石 1.45 t/t 与一体化口径的综合电耗 8500 kWh/t 放在一起，会重复计算近 5000 度电。
A13: 常见错误 3 | B13: 在缺价区间凭空外推。本模型对无电石报价的交易日直接留空，不做插值填充（除已披露锚点之间）。
A15: 三、怎么用
A16: 第 1 步 | B16: 打开 01_参数与单耗，把【单耗】【单价】改成你企业的真实值（黄色格）。有企业实测值就优先用实测值，行业典型值只作默认。
A17: 第 2 步 | B17: 在 01 表修改【综合收率】【制造费用】。
A18: 第 3 步 | B18: 02_成本构成 与 03_加工价差与利润 会自动重算（全部为活公式）。
A19: 第 4 步 | B19: 07_敏感性分析 的双因素矩阵同样会自动跟随 01 表的修改重算。
A20: 第 5 步 | B20: 任何数字要追溯来源 → 看 08_公式与来源。
A22: 四、重要口径提醒
A23: 税费 | B23: 产品价与原料价均为含 13% 增值税口径，因此价差本身含税，不做二次扣税。
A24: 收率 | B24: 只作用于原料与辅料单耗，不作用于能源（电、汽按实物量计量，与收率无关）。
A25: 区域 | B25: 本模型价格为全国基准，未体现区域价差（乌海 vs 山东可达 400–600 元/吨）。
A26: 时段 | B26: 电石日价仅近 93 天可得；更早区间使用已披露锚点线性插值，并在 04 表标注 interp。

Sheet 01_参数与单耗
A1: 01 参数与单耗（唯一输入源）
A2: 黄色格为可编辑输入；改这里，02/03/07 全部自动重算。单耗单位按"每吨 PVC"计。
A4: 产品与工艺
A5: 项目 | B5: 取值 | C5: 单位 | D5: 说明
A6: 产品名称 | B6: PVC 树脂粉 SG-5 | C6: — | D6: 电石乙炔法，悬浮聚合
A7: 产品含税售价 | B7: 4865 | C7: 元/吨 | D7: 生意社 2026-10-19 PVC(SG-5) 基准价 4865 元/吨
A8: 综合收率 | B8: 0.97 | C8: CaC₂→PVC | D8: 行业典型 96–98%；取 97%。收率只作用于原料与辅料，不作用于能源
A9: 增值税率 | B9: 0.13 | C9: — | D9: 产品与原料同为含税价，价差含税，不做二次扣税
A11: 逐项单耗与单价（单位换算系数：kg→0.001 吨；kWh 元/度=元；吨=1）
A12: 物料 | B12: 类别 | C12: 单耗 | D12: 单耗单位 | E12: 换算系数 | F12: 计费单耗(t/度) | G12: 单价 | H12: 单价单位 | I12: 成本 元/吨 | J12: 占原料
A13: 电石 (CaC2, 发气量≥300L/kg) | B13: 原料 | C13: 1.45 | D13: 吨/吨 | E13: 1 | F13: =IF(OR(C13=0,ISBLANK(C13)),0,C13*E13/$B$8) | G13: 2530 | H13: 元/吨 | I13: =ROUND(F13*G13,4)
A14: 石灰 (生石灰) | B14: 原料 | C14: 0 | D14: 吨/吨 | E14: 1 | F14: =IF(OR(C14=0,ISBLANK(C14)),0,C14*E14/$B$8) | G14: 0 | H14: 元/吨 | I14: =ROUND(F14*G14,4)
A15: 烧碱 (32% 液碱, 折百单价) | B15: 原料 | C15: 0 | D15: 吨(折百)/吨 | E15: 1 | F15: =IF(OR(C15=0,ISBLANK(C15)),0,C15*E15/$B$8) | G15: 1966 | H15: 元/吨 | I15: =ROUND(F15*G15,4)
A16: 原盐 | B16: 原料 | C16: 0 | D16: 吨/吨 | E16: 1 | F16: =IF(OR(C16=0,ISBLANK(C16)),0,C16*E16/$B$8) | G16: 0 | H16: 元/吨 | I16: =ROUND(F16*G16,4)
A17: 液氯 (外购) | B17: 原料 | C17: 0 | D17: 吨/吨 | E17: 1 | F17: =IF(OR(C17=0,ISBLANK(C17)),0,C17*E17/$B$8) | G17: 0 | H17: 元/吨 | I17: =ROUND(F17*G17,4)
A18: 氯化氢气体 (HCl) | B18: 辅料 | C18: 0.72 | D18: 吨/吨 | E18: 1 | F18: =IF(OR(C18=0,ISBLANK(C18)),0,C18*E18/$B$8) | G18: 380 | H18: 元/吨 | I18: =ROUND(F18*G18,4)
A19: 汞触媒(低汞/无汞) | B19: 辅料 | C19: 1.2 | D19: kg/吨 | E19: 0.001 | F19: =IF(OR(C19=0,ISBLANK(C19)),0,C19*E19/$B$8) | G19: 9500 | H19: 元/kg | I19: =ROUND(F19*G19,4)
A20: 引发剂/分散剂/助剂 | B20: 辅料 | C20: 1 | D20: kg/吨(综合) | E20: 0.001 | F20: =IF(OR(C20=0,ISBLANK(C20)),0,C20*E20/$B$8) | G20: 12000 | H20: 元/kg | I20: =ROUND(F20*G20,4)
A21: PVC 装置电耗 | B21: 能源 | C21: 450 | D21: kWh/吨 | E21: 1 | F21: =IF(OR(C21=0,ISBLANK(C21)),0,C21*E21) | G21: 0.55 | H21: 元/吨 | I21: =ROUND(F21*G21,4)
A22: 蒸汽 (1.0MPa) | B22: 能源 | C22: 1.2 | D22: 吨/吨 | E22: 1 | F22: =IF(OR(C22=0,ISBLANK(C22)),0,C22*E22) | G22: 150 | H22: 元/吨 | I22: =ROUND(F22*G22,4)
A23: 电石电耗(一体化口径) | B23: 能源 | C23: 0 | D23: kWh/吨 | E23: 1 | F23: =IF(OR(C23=0,ISBLANK(C23)),0,C23*E23) | G23: 0.42 | H23: 元/吨 | I23: =ROUND(F23*G23,4)
A24: 联产烧碱收益抵减 | B24: 副产 | C24: 0.75 | D24: 吨/吨 | E24: 1 | F24: =C24*E24 | G24: 629 | H24: 元/吨 | I24: =ROUND(F24*G24,4)
A25: 是否计入联产烧碱收益 | B25: 否 | D25: 填"是"则按氯碱一体化口径抵减；默认"否"=外购电石口径（与隆众周报样本一致）
A27: 制造费用（元/吨 PVC）
A28: 项目 | B28: 取值 | C28: 单位 | D28: 说明
A29: 人工成本 | B29: 260 | C29: 元/吨 | D29: 按 60 人/20 万吨·年、人均 14 万元折算
A30: 设备折旧 | B30: 320 | C30: 元/吨 | D30: 按投资强度与 10 年折旧折算
A31: 包装费用 | B31: 120 | C31: 元/吨 | D31: 25kg 编织袋 + 托盘，约 480 袋/吨
A32: 其他制造费用 | B32: 80 | C32: 元/吨 | D32: 维修、安全环保、检验等
A33: 制造费用合计 | B33: =SUM(B29:B32) | C33: 元/吨
A34: 是否计入制造费用 | B34: 是 | D34: 填"是"=理论制造利润口径；填"否"=只算加工价差

Sheet 02_成本构成
A1: 02 成本构成（公式联动 01 表）
A2: 本表所有数字均为公式；改 01 表即刻重算。计费单耗=名义单耗×换算系数÷收率（能源不除收率）。
A4: 物料 | B4: 类别 | C4: 单耗 | D4: 换算系数 | E4: 计费单耗 | F4: 单价 | G4: 单位成本 | H4: 占原料成本 | I4: 占总成本
A5: 电石 (CaC2, 发气量≥300L/kg) | B5: 原料 | C5: ='01_参数与单耗'!C13 | D5: ='01_参数与单耗'!E13 | E5: ='01_参数与单耗'!F13 | F5: ='01_参数与单耗'!G13 | G5: =ROUND(E5*F5,2) | H5: =IF(SUMIF($B$5:$B$15,"原料",$G$5:$G$15)=0,"—",G5/SUMIF($B$5:$B$15,"原料",$G$5:$G$15)) | I5: =IF($G$22=0,"—",G5/$G$22)
A6: 石灰 (生石灰) | B6: 原料 | C6: ='01_参数与单耗'!C14 | D6: ='01_参数与单耗'!E14 | E6: ='01_参数与单耗'!F14 | F6: ='01_参数与单耗'!G14 | G6: =ROUND(E6*F6,2) | H6: =IF(SUMIF($B$5:$B$15,"原料",$G$5:$G$15)=0,"—",G6/SUMIF($B$5:$B$15,"原料",$G$5:$G$15)) | I6: =IF($G$22=0,"—",G6/$G$22)
A7: 烧碱 (32% 液碱, 折百单价) | B7: 原料 | C7: ='01_参数与单耗'!C15 | D7: ='01_参数与单耗'!E15 | E7: ='01_参数与单耗'!F15 | F7: ='01_参数与单耗'!G15 | G7: =ROUND(E7*F7,2) | H7: =IF(SUMIF($B$5:$B$15,"原料",$G$5:$G$15)=0,"—",G7/SUMIF($B$5:$B$15,"原料",$G$5:$G$15)) | I7: =IF($G$22=0,"—",G7/$G$22)
A8: 原盐 | B8: 原料 | C8: ='01_参数与单耗'!C16 | D8: ='01_参数与单耗'!E16 | E8: ='01_参数与单耗'!F16 | F8: ='01_参数与单耗'!G16 | G8: =ROUND(E8*F8,2) | H8: =IF(SUMIF($B$5:$B$15,"原料",$G$5:$G$15)=0,"—",G8/SUMIF($B$5:$B$15,"原料",$G$5:$G$15)) | I8: =IF($G$22=0,"—",G8/$G$22)
A9: 液氯 (外购) | B9: 原料 | C9: ='01_参数与单耗'!C17 | D9: ='01_参数与单耗'!E17 | E9: ='01_参数与单耗'!F17 | F9: ='01_参数与单耗'!G17 | G9: =ROUND(E9*F9,2) | H9: =IF(SUMIF($B$5:$B$15,"原料",$G$5:$G$15)=0,"—",G9/SUMIF($B$5:$B$15,"原料",$G$5:$G$15)) | I9: =IF($G$22=0,"—",G9/$G$22)
A10: 氯化氢气体 (HCl) | B10: 辅料 | C10: ='01_参数与单耗'!C18 | D10: ='01_参数与单耗'!E18 | E10: ='01_参数与单耗'!F18 | F10: ='01_参数与单耗'!G18 | G10: =ROUND(E10*F10,2) | H10: =IF(SUMIF($B$5:$B$15,"原料",$G$5:$G$15)=0,"—",G10/SUMIF($B$5:$B$15,"原料",$G$5:$G$15)) | I10: =IF($G$22=0,"—",G10/$G$22)
A11: 汞触媒(低汞/无汞) | B11: 辅料 | C11: ='01_参数与单耗'!C19 | D11: ='01_参数与单耗'!E19 | E11: ='01_参数与单耗'!F19 | F11: ='01_参数与单耗'!G19 | G11: =ROUND(E11*F11,2) | H11: =IF(SUMIF($B$5:$B$15,"原料",$G$5:$G$15)=0,"—",G11/SUMIF($B$5:$B$15,"原料",$G$5:$G$15)) | I11: =IF($G$22=0,"—",G11/$G$22)
A12: 引发剂/分散剂/助剂 | B12: 辅料 | C12: ='01_参数与单耗'!C20 | D12: ='01_参数与单耗'!E20 | E12: ='01_参数与单耗'!F20 | F12: ='01_参数与单耗'!G20 | G12: =ROUND(E12*F12,2) | H12: =IF(SUMIF($B$5:$B$15,"原料",$G$5:$G$15)=0,"—",G12/SUMIF($B$5:$B$15,"原料",$G$5:$G$15)) | I12: =IF($G$22=0,"—",G12/$G$22)
A13: PVC 装置电耗 | B13: 能源 | C13: ='01_参数与单耗'!C21 | D13: ='01_参数与单耗'!E21 | E13: ='01_参数与单耗'!F21 | F13: ='01_参数与单耗'!G21 | G13: =ROUND(E13*F13,2) | H13: =IF(SUMIF($B$5:$B$15,"原料",$G$5:$G$15)=0,"—",G13/SUMIF($B$5:$B$15,"原料",$G$5:$G$15)) | I13: =IF($G$22=0,"—",G13/$G$22)
A14: 蒸汽 (1.0MPa) | B14: 能源 | C14: ='01_参数与单耗'!C22 | D14: ='01_参数与单耗'!E22 | E14: ='01_参数与单耗'!F22 | F14: ='01_参数与单耗'!G22 | G14: =ROUND(E14*F14,2) | H14: =IF(SUMIF($B$5:$B$15,"原料",$G$5:$G$15)=0,"—",G14/SUMIF($B$5:$B$15,"原料",$G$5:$G$15)) | I14: =IF($G$22=0,"—",G14/$G$22)
A15: 电石电耗(一体化口径) | B15: 能源 | C15: ='01_参数与单耗'!C23 | D15: ='01_参数与单耗'!E23 | E15: ='01_参数与单耗'!F23 | F15: ='01_参数与单耗'!G23 | G15: =ROUND(E15*F15,2) | H15: =IF(SUMIF($B$5:$B$15,"原料",$G$5:$G$15)=0,"—",G15/SUMIF($B$5:$B$15,"原料",$G$5:$G$15)) | I15: =IF($G$22=0,"—",G15/$G$22)
A16: 联产烧碱收益 | B16: 副产 | G16: =IF('01_参数与单耗'!$B$25="是",'01_参数与单耗'!I24,0) | H16: 抵减
A18: 原料成本小计（已按收率修正） | G18: =SUMIF($B$5:$B$15,"原料",$G$5:$G$15)
A19: 能源成本小计 | G19: =SUMIF($B$5:$B$15,"能源",$G$5:$G$15)
A20: 辅料成本小计 | G20: =SUMIF($B$5:$B$15,"辅料",$G$5:$G$15)
A21: 制造费用合计 | G21: =IF('01_参数与单耗'!$B$34="是",'01_参数与单耗'!$B$33,0)
A22: 总制成成本 | G22: =G18-G16+G19+G20+G21

Sheet 03_加工价差与利润
A1: 03 三层指标：加工价差 / 制造利润 / 企业实际利润（不输出）
A2: 严格分离。① 价差只扣原料；② 利润再扣能源辅料制造；③ 企业实际利润需内部数据，本表留空并说明原因。
A4: 指标 | B4: 数值 | C4: 单位 | D4: 口径说明
A5: 产品含税售价 P | B5: ='01_参数与单耗'!$B$7 | C5: 元/吨 | D5: 生意社 PVC(SG-5) 现货基准价
A6: ① 原料成本（含收率修正） | B6: ='02_成本构成'!$G$18 | C6: 元/吨 | D6: 逐项见 02 表
A7: ①b 联产烧碱抵减 | B7: =-'02_成本构成'!$G$16 | C7: 元/吨 | D7: 仅在"是否计入"填是时生效
A8: ② 理论加工价差 = P − ① (+①b) | B8: =B5-B6-B7 | C8: 元/吨 | D8: ★ 本指标只反映原料→产品的转换价差
A9: ③ 能源成本 | B9: ='02_成本构成'!$G$19 | C9: 元/吨 | D9: 电 + 汽
A10: ④ 辅料成本 | B10: ='02_成本构成'!$G$20 | C10: 元/吨 | D10: HCl + 触媒 + 助剂
A11: ⑤ 制造费用 | B11: ='02_成本构成'!$G$21 | C11: 元/吨 | D11: 折旧+人工+包装+其他
A12: ⑥ 理论制造利润 = ② − ③④⑤ | B12: =B8-B9-B10-B11 | C12: 元/吨 | D12: ★ 仍不是企业净利润
A13: 理论总制成成本（不含产品价） | B13: ='02_成本构成'!$G$22 | C13: 元/吨 | D13: =①+①b+③+④+⑤
A14: 理论销售利润率 | B14: =IF(B5=0,0,B12/B5) | C14: % | D14: =⑥ ÷ P
A16: 为什么不能把②或⑥叫“企业净利润”
A17: · ② 加工价差 不扣除电价、汽价、催化剂、人工、折旧、包装——它只是"买原料、卖产品"的价格差。
A18: · ⑥ 理论制造利润 扣的是"能核实的制造环节费用"，仍未扣财务费用（利息）、销售费用与物流、增值税进销差、检修与开停车损失、环保处置、所得税。
A19: · ⑦ 企业实际利润 只有拿到该企业的成本表、费用表与销售价格才能算；用行业均价反推"某企业赚了多少"是最常见的错误用法。
A20: · 本模型对 ⑦ 的态度是：明确留空 + 说明缺什么数据，而不是给一个看起来精确的数字。

Sheet 04_历史价格
A1: 04 近 1 年价格序列（2025-10-20 ～ 2026-10-19，242 个交易日）
A2: PVC 价格：有现货用现货(spot)，否则用期货主力收盘+平均基差(proxy)。电石：有现货用现货，否则锚点插值(interp)。空白=无可靠价格。
A4: 日期 | B4: PVC 现货 | C4: PVC 期货收盘 | D4: PVC 期货结算 | E4: PVC 采用价 | F4: 价格类型 | G4: 电石到厂价 | H4: 电石类型 | I4: 电石锚点说明 | J4: 理论加工价差 | K4: 理论制造利润 | L4: 烧碱价格
A5: 2025-10-20 | E5: 4582.3 | F5: 期货代理
A6: 2025-10-21 | E6: 4579.3 | F6: 期货代理
A7: 2025-10-22 | E7: 4599.3 | F7: 期货代理
A8: 2025-10-23 | E8: 4610.3 | F8: 期货代理
A9: 2025-10-24 | E9: 4588.3 | F9: 期货代理
A10: 2025-10-27 | E10: 4626.3 | F10: 期货代理
A11: 2025-10-28 | E11: 4596.3 | F11: 期货代理
A12: 2025-10-29 | E12: 4655.3 | F12: 期货代理
A13: 2025-10-30 | E13: 4646.3 | F13: 期货代理
A14: 2025-10-31 | E14: 4581.3 | F14: 期货代理
A15: 2025-11-03 | E15: 4560.3 | F15: 期货代理
A16: 2025-11-04 | E16: 4550.3 | F16: 期货代理
... A57: 2025-12-31 | E57: 4685.3 | F57: 期货代理
A58: 2026-01-05 | E58: 4644.3 | F58: 期货代理 | G58: 2743.2 | H58: 插值 | I58: 插值 2026-01-01 2750 → 2026-05-28 2500 (w=0.03) | J58: 543.64 | K58: -970.05
A59: 2026-01-06 | E59: 4799.3 | F59: 期货代理 | G59: 2741.5 | H59: 插值 | I59: 插值 2026-01-01 2750 → 2026-05-28 2500 (w=0.03) | J59: 701.18 | K59: -812.5
A60: 2026-01-07 | E60: 4852.3 | F60: 期货代理 | G60: 2739.8 | H60: 插值 | I60: 插值 2026-01-01 2750 → 2026-05-28 2500 (w=0.04) | J60: 756.72 | K60: -756.96
A61: 2026-01-08 | E61: 4785.3 | F61: 期货代理 | G61: 2738.1 | H61: 插值 | I61: 插值 2026-01-01 2750 → 2026-05-28 2500 (w=0.05) | J61: 692.26 | K61: -821.42
A62: 2026-01-09 | E62: 4777.3 | F62: 期货代理 | G62: 2736.4 | H62: 插值 | I62: 插值 2026-01-01 2750 → 2026-05-28 2500 (w=0.05) | J62: 686.81 | K62: -826.88
A63: 2026-01-12 | E63: 4820.3 | F63: 期货代理 | G63: 2731.3 | H63: 插值 | I63: 插值 2026-01-01 2750 → 2026-05-28 2500 (w=0.07) | J63: 737.43 | K63: -776.26
A64: 2026-01-13 | E64: 4768.3 | F64: 期货代理 | G64: 2729.6 | H64: 插值 | I64: 插值 2026-01-01 2750 → 2026-05-28 2500 (w=0.08) | J64: 687.97 | K64: -825.72
A65: 2026-01-14 | E65: 4758.3 | F65: 期货代理 | G65: 2727.9 | H65: 插值 | I65: 插值 2026-01-01 2750 → 2026-05-28 2500 (w=0.09) | J65: 680.51 | K65: -833.17
A66: 2026-01-15 | E66: 4748.3 | F66: 期货代理 | G66: 2726.2 | H66: 插值 | I66: 插值 2026-01-01 2750 → 2026-05-28 2500 (w=0.10) | J66: 673.05 | K66: -840.63
A67: 2026-01-16 | E67: 4683.3 | F67: 期货代理 | G67: 2724.5 | H67: 插值 | I67: 插值 2026-01-01 2750 → 2026-05-28 2500 (w=0.10) | J67: 610.59 | K67: -903.09
A68: 2026-01-19 | E68: 4681.3 | F68: 期货代理 | G68: 2719.4 | H68: 插值 | I68: 插值 2026-01-01 2750 → 2026-05-28 2500 (w=0.12) | J68: 616.22 | K68: -897.47
A69: 2026-01-20 | E69: 4687.3 | F69: 期货代理 | G69: 2717.7 | H69: 插值 | I69: 插值 2026-01-01 2750 → 2026-05-28 2500 (w=0.13) | J69: 624.76 | K69: -888.93
... A186: 2026-07-17 | E186: 4320.3 | F186: 期货代理 | G186: 2426.6 | H186: 插值 | I186: 插值 2026-05-31 2500 → 2026-08-03 2400 (w=0.73) | J186: 692.91 | K186: -820.78
A187: 2026-07-20 | E187: 4585 | F187: 现货 | G187: 2480 | H187: 现货 | J187: 877.78 | K187: -635.9 | L187: 643
A188: 2026-07-21 | E188: 4484 | F188: 现货 | G188: 2480 | H188: 现货 | J188: 776.78 | K188: -736.9 | L188: 643
A189: 2026-07-22 | E189: 4449 | F189: 现货 | G189: 2480 | H189: 现货 | J189: 741.78 | K189: -771.9 | L189: 643
A190: 2026-07-23 | E190: 4483 | F190: 现货 | G190: 2480 | H190: 现货 | J190: 775.78 | K190: -737.9 | L190: 643
A191: 2026-07-24 | E191: 4520 | F191: 现货 | G191: 2440 | H191: 现货 | J191: 872.58 | K191: -641.11 | L191: 643
A192: 2026-07-27 | E192: 4430 | F192: 现货 | G192: 2440 | H192: 现货 | J192: 782.58 | K192: -731.11 | L192: 643
A193: 2026-07-28 | E193: 4428 | F193: 现货 | G193: 2350 | H193: 现货 | J193: 915.11 | K193: -598.57 | L193: 643
A194: 2026-07-29 | E194: 4445 | F194: 现货 | G194: 2360 | H194: 现货 | J194: 917.16 | K194: -596.52 | L194: 643
A195: 2026-07-30 | E195: 4375 | F195: 现货 | G195: 2360 | H195: 现货 | J195: 847.16 | K195: -666.52 | L195: 643
A196: 2026-07-31 | E196: 4382 | F196: 现货 | G196: 2360 | H196: 现货 | J196: 854.16 | K196: -659.52 | L196: 643
A197: 2026-08-03 | E197: 4392 | F197: 现货 | G197: 2360 | H197: 现货 | J197: 864.16 | K197: -649.52 | L197: 641
...

Sheet 05_月度台账
A1: 05 月度台账：理论结果 vs 隆众资讯（第三方）
A2: 第三列为第三方口径（含全部制造成本），不是同一指标；差值用于校验方向与量级，不能直接相减当误差。
A4: 月份 | B4: 交易日数 | C4: PVC 采用均价 | D4: 电石均价 | E4: 理论原料成本 | F4: 理论加工价差 | G4: 理论制造利润 | H4: 隆众成本(全国) | I4: 隆众毛利(全国) | J4: 偏差(理论利润−隆众毛利) | K4: 价格来源 | L4: 方向是否一致
A5: 2025-10 | B5: 10 | J5: =IF(OR(G5="",I5=""),"",G5-I5) | K5: 无电石价 | L5: =IF(OR(G5="",I5=""),"—",IF(SIGN(G5)=SIGN(I5),"一致","背离"))
A6: 2025-11 | B6: 20 | J6: =IF(OR(G6="",I6=""),"",G6-I6) | K6: 无电石价 | L6: =IF(OR(G6="",I6=""),"—",IF(SIGN(G6)=SIGN(I6),"一致","背离"))
A7: 2025-12 | B7: 23 | J7: =IF(OR(G7="",I7=""),"",G7-I7) | K7: 无电石价 | L7: =IF(OR(G7="",I7=""),"—",IF(SIGN(G7)=SIGN(I7),"一致","背离"))
A8: 2026-01 | B8: 20 | C8: 4765.1 | D8: 2721.9 | E8: 4068.9 | F8: 696.2 | G8: -817.5 | H8: 5131 | I8: -710 | J8: =IF(OR(G8="",I8=""),"",G8-I8) | K8: 期货代理+锚点 | L8: =IF(OR(G8="",I8=""),"—",IF(SIGN(G8)=SIGN(I8),"一致","背离"))
A9: 2026-02 | B9: 14 | C9: 4853.7 | D9: 2677.5 | E9: 4002.5 | F9: 851.2 | G9: -662.5 | H9: 5180 | I9: -598.7 | J9: =IF(OR(G9="",I9=""),"",G9-I9) | K9: 期货代理+锚点 | L9: =IF(OR(G9="",I9=""),"—",IF(SIGN(G9)=SIGN(I9),"一致","背离"))
A10: 2026-03 | B10: 22 | C10: 5421.2 | D10: 2624.2 | E10: 3922.8 | F10: 1498.4 | G10: -15.3 | H10: 5210.5 | I10: 66.5 | J10: =IF(OR(G10="",I10=""),"",G10-I10) | K10: 期货代理+锚点 | L10: =IF(OR(G10="",I10=""),"—",IF(SIGN(G10)=SIGN(I10),"一致","背离"))
A11: 2026-04 | B11: 21 | C11: 5081.3 | D11: 2571.2 | E11: 3843.5 | F11: 1237.8 | G11: -275.9 | H11: 5061.8 | I11: -105.8 | J11: =IF(OR(G11="",I11=""),"",G11-I11) | K11: 期货代理+锚点 | L11: =IF(OR(G11="",I11=""),"—",IF(SIGN(G11)=SIGN(I11),"一致","背离"))
A12: 2026-05 | B12: 18 | C12: 4908 | D12: 2517.4 | E12: 3763.1 | F12: 1144.9 | G12: -368.8 | H12: 5028.2 | I12: -262.8 | J12: =IF(OR(G12="",I12=""),"",G12-I12) | K12: 期货代理+锚点 | L12: =IF(OR(G12="",I12=""),"—",IF(SIGN(G12)=SIGN(I12),"一致","背离"))
A13: 2026-06 | B13: 21 | C13: 4540.6 | D13: 2476.9 | E13: 3702.6 | F13: 838 | G13: -675.7 | H13: 4888.2 | I13: -386 | J13: =IF(OR(G13="",I13=""),"",G13-I13) | K13: 期货代理+锚点 | L13: =IF(OR(G13="",I13=""),"—",IF(SIGN(G13)=SIGN(I13),"一致","背离"))
A14: 2026-07 | B14: 23 | C14: 4406.4 | D14: 2431.8 | E14: 3635.2 | F14: 771.3 | G14: -742.4 | H14: 4936.2 | I14: -602.2 | J14: =IF(OR(G14="",I14=""),"",G14-I14) | K14: 混合 | L14: =IF(OR(G14="",I14=""),"—",IF(SIGN(G14)=SIGN(I14),"一致","背离"))
A15: 2026-08 | B15: 21 | C15: 4441.2 | D15: 2447.6 | E15: 3658.8 | F15: 782.4 | G15: -731.3 | H15: 5113.7 | I15: -738.7 | J15: =IF(OR(G15="",I15=""),"",G15-I15) | K15: 现货 | L15: =IF(OR(G15="",I15=""),"—",IF(SIGN(G15)=SIGN(I15),"一致","背离"))
A16: 2026-09 | B16: 21 | C16: 4768.6 | D16: 2649.5 | E16: 3960.6 | F16: 807.9 | G16: -705.7 | H16: 5397.8 | I16: -750.8 | J16: =IF(OR(G16="",I16=""),"",G16-I16) | K16: 现货 | L16: =IF(OR(G16="",I16=""),"—",IF(SIGN(G16)=SIGN(I16),"一致","背离"))
A17: 2026-10 | B17: 8 | C17: 4826.9 | D17: 2556.2 | E17: 3821.2 | F17: 1005.7 | G17: -508 | H17: 5287 | I17: -619 | J17: =IF(OR(G17="",I17=""),"",G17-I17) | K17: 现货 | L17: =IF(OR(G17="",I17=""),"—",IF(SIGN(G17)=SIGN(I17),"一致","背离"))
A19: 汇总 | B19: =COUNT(J5:J17) | F19: 平均偏差 | G19: =IFERROR(AVERAGE(J5:J17),"") | H19: 平均绝对偏差 | I19: =IFERROR(AVERAGE(ABS(J5:J17)),"") | K19: 方向一致月数 | L19: =COUNTIF(L5:L17,"一致")

Sheet 06_周度校验
A1: 06 周度校验：理论制造利润 vs 隆众全国电石法 PVC 毛利（40 周）
A2: 核心可用性指标是"方向一致率"，不是绝对误差——两者口径不同（第三方含全部制造成本、样本为特定期企业）。
A4: 周报日期 | B4: 对应交易日数 | C4: 理论制造利润 | D4: 隆众毛利 | E4: 偏差 | F4: 绝对偏差 | G4: 方向一致 | H4: 备注
A5: 20260109 | B5: 5 | C5: -837.6 | D5: -634 | E5: =C5-D5 | F5: =ABS(E5) | G5: =IF(SIGN(C5)=SIGN(D5),"一致","背离")
A6: 20260116 | B6: 5 | C6: -835.8 | D6: -662 | E6: =C6-D6 | F6: =ABS(E6) | G6: =IF(SIGN(C6)=SIGN(D6),"一致","背离")
A7: 20260123 | B7: 5 | C7: -869.2 | D7: -800 | E7: =C7-D7 | F7: =ABS(E7) | G7: =IF(SIGN(C7)=SIGN(D7),"一致","背离")
A8: 20260130 | B8: 5 | C8: -727.4 | D8: -744 | E8: =C8-D8 | F8: =ABS(E8) | G8: =IF(SIGN(C8)=SIGN(D8),"一致","背离")
A9: 20260206 | B9: 5 | C9: -603.2 | D9: -659 | E9: =C9-D9 | F9: =ABS(E9) | G9: =IF(SIGN(C9)=SIGN(D9),"一致","背离")
A10: 20260213 | B10: 5 | C10: -680.8 | D10: -698 | E10: =C10-D10 | F10: =ABS(E10) | G10: =IF(SIGN(C10)=SIGN(D10),"一致","背离")
A11: 20260227 | B11: 4 | C11: -713.7 | D11: -439 | E11: =C11-D11 | F11: =ABS(E11) | G11: =IF(SIGN(C11)=SIGN(D11),"一致","背离")
A12: 20260306 | B12: 5 | C12: -567.9 | D12: -159 | E12: =C12-D12 | F12: =ABS(E12) | G12: =IF(SIGN(C12)=SIGN(D12),"一致","背离")
A13: 20260313 | B13: 5 | C13: -46.9 | D13: 267 | E13: =C13-D13 | F13: =ABS(E13) | G13: =IF(SIGN(C13)=SIGN(D13),"一致","背离")
A14: 20260320 | B14: 5 | C14: 293.1 | D14: 193 | E14: =C14-D14 | F14: =ABS(E14) | G14: =IF(SIGN(C14)=SIGN(D14),"一致","背离")
A15: 20260327 | B15: 5 | C15: 281.3 | D15: -35 | E15: =C15-D15 | F15: =ABS(E15) | G15: =IF(SIGN(C15)=SIGN(D15),"一致","背离")
A16: 20260403 | B16: 5 | C16: -99 | D16: -307 | E16: =C16-D16 | F16: =ABS(E16) | G16: =IF(SIGN(C16)=SIGN(D16),"一致","背离")
... A44: 20261016 | B44: 5 | C44: -514.5 | D44: -472 | E44: =C44-D44 | F44: =ABS(E44) | G44: =IF(SIGN(C44)=SIGN(D44),"一致","背离")
A46: 统计口径 | B46: 数值 | C46: 说明
A47: 样本周数 | B47: =COUNT(E5:E44) | C47: 理论利润与第三方毛利方向是否一致
A48: 偏差均值 | B48: =AVERAGE(E5:E44)
A49: 平均绝对偏差 | B49: =AVERAGE(F5:F44)
A50: 偏差标准差 | B50: =STDEV(E5:E44)
A51: 最大正偏差 | B51: =MAX(E5:E44)
A52: 最大负偏差 | B52: =MIN(E5:E44)
A53: 方向一致周数 | B53: =COUNTIF(G5:G44,"一致")
A54: 方向一致率 | B54: =G53/B46 | C54: ≥85% 可认为模型可用于方向判断（当前 37/40=92.5%）

Sheet 07_敏感性分析
A1: 07 敏感性分析（双因素矩阵为活公式，随 01 表联动）
A2: 行=电石价格变动，列=产品价格变动。变动比例写在 B4:F4 / A6:A10，改这里重算全部矩阵。
A4: 电石＼产品 | B4: -0.1 | C4: -0.05 | D4: 0 | E4: 0.05 | F4: 0.1
A5: -0.1
A6: -0.05
A7: 0
A8: 0.05
A9: 0.1
A11: 矩阵①：理论加工价差（元/吨）
A12: 电石＼产品 | B12: -10% | C12: -5% | D12: +0% | E12: +5% | F12: +10%
A13: =$A$5 | B13: ='01_参数与单耗'!$B$7*(1+B$4)-('01_参数与单耗'!$C$13*'01_参数与单耗'!$E$13*'01_参数与单耗'!$G$13*(1+$A13)/'01_参数与单耗'!$B$8)-('02_成本构成'!$G$18-'02_成本构成'!$G$5) | C13: ='01_参数与单耗'!$B$7*(1+C$4)-('01_参数与单耗'!$C$13*'01_参数与单耗'!$E$13*'01_参数与单耗'!$G$13*(1+$A13)/'01_参数与单耗'!$B$8)-('02_成本构成'!$G$18-'02_成本构成'!$G$5) | D13: ='01_参数与单耗'!$B$7*(1+D$4)-('01_参数与单耗'!$C$13*'01_参数与单耗'!$E$13*'01_参数与单耗'!$G$13*(1+$A13)/'01_参数与单耗'!$B$8)-('02_成本构成'!$G$18-'02_成本构成'!$G$5) | E13: ='01_参数与单耗'!$B$7*(1+E$4)-('01_参数与单耗'!$C$13*'01_参数与单耗'!$E$13*'01_参数与单耗'!$G$13*(1+$A13)/'01_参数与单耗'!$B$8)-('02_成本构成'!$G$18-'02_成本构成'!$G$5) | F13: ='01_参数与单耗'!$B$7*(1+F$4)-('01_参数与单耗'!$C$13*'01_参数与单耗'!$E$13*'01_参数与单耗'!$G$13*(1+$A13)/'01_参数与单耗'!$B$8)-('02_成本构成'!$G$18-'02_成本构成'!$G$5)
A14: =$A$6 | B14: ='01_参数与单耗'!$B$7*(1+B$4)-('01_参数与单耗'!$C$13*'01_参数与单耗'!$E$13*'01_参数与单耗'!$G$13*(1+$A14)/'01_参数与单耗'!$B$8)-('02_成本构成'!$G$18-'02_成本构成'!$G$5) | C14: ='01_参数与单耗'!$B$7*(1+C$4)-('01_参数与单耗'!$C$13*'01_参数与单耗'!$E$13*'01_参数与单耗'!$G$13*(1+$A14)/'01_参数与单耗'!$B$8)-('02_成本构成'!$G$18-'02_成本构成'!$G$5) | D14: ='01_参数与单耗'!$B$7*(1+D$4)-('01_参数与单耗'!$C$13*'01_参数与单耗'!$E$13*'01_参数与单耗'!$G$13*(1+$A14)/'01_参数与单耗'!$B$8)-('02_成本构成'!$G$18-'02_成本构成'!$G$5) | E14: ='01_参数与单耗'!$B$7*(1+E$4)-('01_参数与单耗'!$C$13*'01_参数与单耗'!$E$13*'01_参数与单耗'!$G$13*(1+$A14)/'01_参数与单耗'!$B$8)-('02_成本构成'!$G$18-'02_成本构成'!$G$5) | F14: ='01_参数与单耗'!$B$7*(1+F$4)-('01_参数与单耗'!$C$13*'01_参数与单耗'!$E$13*'01_参数与单耗'!$G$13*(1+$A14)/'01_参数与单耗'!$B$8)-('02_成本构成'!$G$18-'02_成本构成'!$G$5)
A15: =$A$7 | B15: ='01_参数与单耗'!$B$7*(1+B$4)-('01_参数与单耗'!$C$13*'01_参数与单耗'!$E$13*'01_参数与单耗'!$G$13*(1+$A15)/'01_参数与单耗'!$B$8)-('02_成本构成'!$G$18-'02_成本构成'!$G$5) | C15: ='01_参数与单耗'!$B$7*(1+C$4)-('01_参数与单耗'!$C$13*'01_参数与单耗'!$E$13*'01_参数与单耗'!$G$13*(1+$A15)/'01_参数与单耗'!$B$8)-('02_成本构成'!$G$18-'02_成本构成'!$G$5) | D15: ='01_参数与单耗'!$B$7*(1+D$4)-('01_参数与单耗'!$C$13*'01_参数与单耗'!$E$13*'01_参数与单耗'!$G$13*(1+$A15)/'01_参数与单耗'!$B$8)-('02_成本构成'!$G$18-'02_成本构成'!$G$5) | E15: ='01_参数与单耗'!$B$7*(1+E$4)-('01_参数与单耗'!$C$13*'01_参数与单耗'!$E$13*'01_参数与单耗'!$G$13*(1+$A15)/'01_参数与单耗'!$B$8)-('02_成本构成'!$G$18-'02_成本构成'!$G$5) | F15: ='01_参数与单耗'!$B$7*(1+F$4)-('01_参数与单耗'!$C$13*'01_参数与单耗'!$E$13*'01_参数与单耗'!$G$13*(1+$A15)/'01_参数与单耗'!$B$8)-('02_成本构成'!$G$18-'02_成本构成'!$G$5)
A16: =$A$8 | B16: ='01_参数与单耗'!$B$7*(1+B$4)-('01_参数与单耗'!$C$13*'01_参数与单耗'!$E$13*'01_参数与单耗'!$G$13*(1+$A16)/'01_参数与单耗'!$B$8)-('02_成本构成'!$G$18-'02_成本构成'!$G$5) | C16: ='01_参数与单耗'!$B$7*(1+C$4)-('01_参数与单耗'!$C$13*'01_参数与单耗'!$E$13*'01_参数与单耗'!$G$13*(1+$A16)/'01_参数与单耗'!$B$8)-('02_成本构成'!$G$18-'02_成本构成'!$G$5) | D16: ='01_参数与单耗'!$B$7*(1+D$4)-('01_参数与单耗'!$C$13*'01_参数与单耗'!$E$13*'01_参数与单耗'!$G$13*(1+$A16)/'01_参数与单耗'!$B$8)-('02_成本构成'!$G$18-'02_成本构成'!$G$5) | E16: ='01_参数与单耗'!$B$7*(1+E$4)-('01_参数与单耗'!$C$13*'01_参数与单耗'!$E$13*'01_参数与单耗'!$G$13*(1+$A16)/'01_参数与单耗'!$B$8)-('02_成本构成'!$G$18-'02_成本构成'!$G$5) | F16: ='01_参数与单耗'!$B$7*(1+F$4)-('01_参数与单耗'!$C$13*'01_参数与单耗'!$E$13*'01_参数与单耗'!$G$13*(1+$A16)/'01_参数与单耗'!$B$8)-('02_成本构成'!$G$18-'02_成本构成'!$G$5)
A17: =$A$9 | B17: ='01_参数与单耗'!$B$7*(1+B$4)-('01_参数与单耗'!$C$13*'01_参数与单耗'!$E$13*'01_参数与单耗'!$G$13*(1+$A17)/'01_参数与单耗'!$B$8)-('02_成本构成'!$G$18-'02_成本构成'!$G$5) | C17: ='01_参数与单耗'!$B$7*(1+C$4)-('01_参数与单耗'!$C$13*'01_参数与单耗'!$E$13*'01_参数与单耗'!$G$13*(1+$A17)/'01_参数与单耗'!$B$8)-('02_成本构成'!$G$18-'02_成本构成'!$G$5) | D17: ='01_参数与单耗'!$B$7*(1+D$4)-('01_参数与单耗'!$C$13*'01_参数与单耗'!$E$13*'01_参数与单耗'!$G$13*(1+$A17)/'01_参数与单耗'!$B$8)-('02_成本构成'!$G$18-'02_成本构成'!$G$5) | E17: ='01_参数与单耗'!$B$7*(1+E$4)-('01_参数与单耗'!$C$13*'01_参数与单耗'!$E$13*'01_参数与单耗'!$G$13*(1+$A17)/'01_参数与单耗'!$B$8)-('02_成本构成'!$G$18-'02_成本构成'!$G$5) | F17: ='01_参数与单耗'!$B$7*(1+F$4)-('01_参数与单耗'!$C$13*'01_参数与单耗'!$E$13*'01_参数与单耗'!$G$13*(1+$A17)/'01_参数与单耗'!$B$8)-('02_成本构成'!$G$18-'02_成本构成'!$G$5)
A19: 矩阵②：理论制造利润（元/吨）= 矩阵① − 能源 − 辅料 − 制造费用
A20: 电石＼产品 | B20: -10% | C20: -5% | D20: +0% | E20: +5% | F20: +10%
A21: =$A$5 | B21: =B13-('02_成本构成'!$G$19+'02_成本构成'!$G$20+'02_成本构成'!$G$21) | C21: =C13-('02_成本构成'!$G$19+'02_成本构成'!$G$20+'02_成本构成'!$G$21) | D21: =D13-('02_成本构成'!$G$19+'02_成本构成'!$G$20+'02_成本构成'!$G$21) | E21: =E13-('02_成本构成'!$G$19+'02_成本构成'!$G$20+'02_成本构成'!$G$21) | F21: =F13-('02_成本构成'!$G$19+'02_成本构成'!$G$20+'02_成本构成'!$G$21)
A22: =$A$6 | B22: =B14-('02_成本构成'!$G$19+'02_成本构成'!$G$20+'02_成本构成'!$G$21) | C22: =C14-('02_成本构成'!$G$19+'02_成本构成'!$G$20+'02_成本构成'!$G$21) | D22: =D14-('02_成本构成'!$G$19+'02_成本构成'!$G$20+'02_成本构成'!$G$21) | E22: =E14-('02_成本构成'!$G$19+'02_成本构成'!$G$20+'02_成本构成'!$G$21) | F22: =F14-('02_成本构成'!$G$19+'02_成本构成'!$G$20+'02_成本构成'!$G$21)
A23: =$A$7 | B23: =B15-('02_成本构成'!$G$19+'02_成本构成'!$G$20+'02_成本构成'!$G$21) | C23: =C15-('02_成本构成'!$G$19+'02_成本构成'!$G$20+'02_成本构成'!$G$21) | D23: =D15-('02_成本构成'!$G$19+'02_成本构成'!$G$20+'02_成本构成'!$G$21) | E23: =E15-('02_成本构成'!$G$19+'02_成本构成'!$G$20+'02_成本构成'!$G$21) | F23: =F15-('02_成本构成'!$G$19+'02_成本构成'!$G$20+'02_成本构成'!$G$21)
A24: =$A$8 | B24: =B16-('02_成本构成'!$G$19+'02_成本构成'!$G$20+'02_成本构成'!$G$21) | C24: =C16-('02_成本构成'!$G$19+'02_成本构成'!$G$20+'02_成本构成'!$G$21) | D24: =D16-('02_成本构成'!$G$19+'02_成本构成'!$G$20+'02_成本构成'!$G$21) | E24: =E16-('02_成本构成'!$G$19+'02_成本构成'!$G$20+'02_成本构成'!$G$21) | F24: =F16-('02_成本构成'!$G$19+'02_成本构成'!$G$20+'02_成本构成'!$G$21)
A25: =$A$9 | B25: =B17-('02_成本构成'!$G$19+'02_成本构成'!$G$20+'02_成本构成'!$G$21) | C25: =C17-('02_成本构成'!$G$19+'02_成本构成'!$G$20+'02_成本构成'!$G$21) | D25: =D17-('02_成本构成'!$G$19+'02_成本构成'!$G$20+'02_成本构成'!$G$21) | E25: =E17-('02_成本构成'!$G$19+'02_成本构成'!$G$20+'02_成本构成'!$G$21) | F25: =F17-('02_成本构成'!$G$19+'02_成本构成'!$G$20+'02_成本构成'!$G$21)
A28: 单因素敏感性：各物料价格 ±5% / ±10% 对利润的影响（元/吨）
A29: 物料 | B29: -10% | C29: -5% | D29: +5% | E29: +10% | F29: 弹性(±10%均价) | G29: 当前成本
A30: 电石 (CaC2, 发气量≥300L/kg) | B30: =ROUND(-$G$13*0.9,2) | C30: =ROUND(-$G$13*0.95,2) | D30: =ROUND(-$G$13*1.05,2) | E30: =ROUND(-$G$13*1.1,2) | G30: =ROUND(((E30-D30)/2),1) | H30: =$C$13*$E$13*$G$13
A31: 氯化氢气体 (HCl) | B31: =ROUND(-$G$18*0.9,2) | C31: =ROUND(-$G$18*0.95,2) | D31: =ROUND(-$G$18*1.05,2) | E31: =ROUND(-$G$18*1.1,2) | G31: =ROUND(((E31-D31)/2),1) | H31: =$C$18*$E$18*$G$18
A32: 汞触媒(低汞/无汞) | B32: =ROUND(-$G$19*0.9,2) | C32: =ROUND(-$G$19*0.95,2) | D32: =ROUND(-$G$19*1.05,2) | E32: =ROUND(-$G$19*1.1,2) | G32: =ROUND(((E32-D32)/2),1) | H32: =$C$19*$E$19*$G$19
A33: 引发剂/分散剂/助剂 | B33: =ROUND(-$G$20*0.9,2) | C33: =ROUND(-$G$20*0.95,2) | D33: =ROUND(-$G$20*1.05,2) | E33: =ROUND(-$G$20*1.1,2) | G33: =ROUND(((E33-D33)/2),1) | H33: =$C$20*$E$20*$G$20
A34: PVC 装置电耗 | B34: =ROUND(-$G$21*0.9,2) | C34: =ROUND(-$G$21*0.95,2) | D34: =ROUND(-$G$21*1.05,2) | E34: =ROUND(-$G$21*1.1,2) | G34: =ROUND(((E34-D34)/2),1) | H34: =$C$21*$E$21*$G$21
A35: 蒸汽 (1.0MPa) | B35: =ROUND(-$G$22*0.9,2) | C35: =ROUND(-$G$22*0.95,2) | D35: =ROUND(-$G$22*1.05,2) | E35: =ROUND(-$G$22*1.1,2) | G35: =ROUND(((E35-D35)/2),1) | H35: =$C$22*$E$22*$G$22
A37: 盈亏平衡：使理论制造利润 = 0 所需的 PVC 售价（元/吨）
A38: 电石价格变动 | B38: -10% | C38: -5% | D38: 基准 | E38: +5% | F38: +10%
A39: PVC 需售价 | B39: =ROUND(('01_参数与单耗'!$C$13*'01_参数与单耗'!$E$13*'01_参数与单耗'!$G$13*(1+-0.10)/'01_参数与单耗'!$B$8)+('02_成本构成'!$G$19+'02_成本构成'!$G$20+'02_成本构成'!$G$21),0) | C39: =ROUND(('01_参数与单耗'!$C$13*'01_参数与单耗'!$E$13*'01_参数与单耗'!$G$13*(1+-0.05)/'01_参数与单耗'!$B$8)+('02_成本构成'!$G$19+'02_成本构成'!$G$20+'02_成本构成'!$G$21),0) | D39: =ROUND(('01_参数与单耗'!$C$13*'01_参数与单耗'!$E$13*'01_参数与单耗'!$G$13*(1+0.00)/'01_参数与单耗'!$B$8)+('02_成本构成'!$G$19+'02_成本构成'!$G$20+'02_成本构成'!$G$21),0) | E39: =ROUND(('01_参数与单耗'!$C$13*'01_参数与单耗'!$E$13*'01_参数与单耗'!$G$13*(1+0.05)/'01_参数与单耗'!$B$8)+('02_成本构成'!$G$19+'02_成本构成'!$G$20+'02_成本构成'!$G$21),0) | F39: =ROUND(('01_参数与单耗'!$C$13*'01_参数与单耗'!$E$13*'01_参数与单耗'!$G$13*(1+0.10)/'01_参数与单耗'!$B$8)+('02_成本构成'!$G$19+'02_成本构成'!$G$20+'02_成本构成'!$G$21),0)

Sheet 08_公式与来源
A1: 08 公式与来源（每个数字都可追溯）
A2: 左：公式文字化展开；右：数据来源与口径。审阅他人模型时，先看这一页。
A4: A. 公式展开（与 Excel 单元格公式一一对应）
A5: 指标 | B5: 公式 | C5: 单位 | D5: Excel 位置
A6: 计费单耗 | B6: 名义单耗 × 换算系数 ÷ 综合收率（能源不除收率） | C6: t 或 kWh | D6: 02!E 列
A7: 单位成本 | B7: 计费单耗 × 单价 | C7: 元/吨 | D7: 02!G 列
A8: 原料成本 | B8: Σ 电石与原料项单位成本 | C8: 元/吨 | D8: 02!原料小计
A9: 能源成本 | B9: 电耗 × 电价 + 汽耗 × 汽价 | C9: 元/吨 | D9: 02!能源小计
A10: 辅料成本 | B10: Σ (辅料单耗 ÷ 收率 × 单价) | C10: 元/吨 | D10: 02!辅料小计
A11: 制造费用 | B11: 折旧 + 人工 + 包装 + 其他 | C11: 元/吨 | D11: 01!B 合计
A12: 理论加工价差 | B12: 产品含税价 − 原料成本 − 联产抵减 | C12: 元/吨 | D12: 03!②
A13: 理论制造利润 | B13: 加工价差 − 能源 − 辅料 − 制造费用 | C13: 元/吨 | D13: 03!⑥
A14: 弹性（电石） | B14: 单耗 ÷ 收率 × 单价 × 变动幅度 | C14: 元/吨 | D14: 07!单因素
A15: 盈亏平衡价 | B15: 电石成本(受冲击后) + 能源 + 辅料 + 制造费用 | C15: 元/吨 | D15: 07!平衡价
A17: B. 单耗与工艺来源（多源并列，注明适用工艺，绝不混用）
A18: 指标 | B18: 取值 | C18: 来源 | D18: 适用工艺口径 | E18: 文献链接/出处
A19: 电石 CaC₂ | B19: 1.45 t/t | C19: 国标口径（前瞻产业研究院 / 新浪财经引国家标准） | D19: 外购电石，PVC 装置本级 | E19: https://finance.sina.com.cn/ 2022-01-17
A20: 电石 CaC₂ | B20: 1.35–1.42 t/t | C20: 隆众资讯 行业统计标准 | D20: 外购电石，行业统计 | E20: https://www.mysteel.com/oilchem/ 2024-12-17
A21: 电石 CaC₂ | B21: 1.40–1.60 t/t | C21: 中国化工网 | D21: 外购电石，较宽区间 | E21: https://www.chemnet.com/
A22: 氯化氢 HCl | B22: 0.72 t/t（630–850 kg 区间） | C22: 国标 750–850 kg；隆众 630–650 kg | D22: 气体计价，氯碱配套 | E22: —
A23: PVC 装置电耗 | B23: 450–500 kWh/t | C23: 国标口径 | D23: 外购电石企业，装置本级 | E23: —
A24: 综合电耗（全链） | B24: ≈8500 kWh/t | C24: 中国化工报 2025-11-05 | D24: 一体化全链，含电石环节 | E24: https://www.ccin.com.cn/
A25: 电石电耗 | B25: 3400–3600 kWh/t 电石 | C25: 联成化学（台塑）公开资料 | D25: 电石厂 | E25: —
A26: 汞触媒 | B26: 1.2 kg/t PVC | C26: 专利 CN103408392A | D26: 低汞触媒 | E26: —
A27: 综合收率 | B27: 97% | C27: 行业 96–98% | D27: 悬浮聚合 | E27: —
A29: C. 价格来源（品种 / 地区 / 规格 / 税费 / 频率）
A30: 序列 | B30: 来源 | C30: 地区与规格 | D30: 单位与税费 | E30: 区间 | F30: 链接
A31: PVC 现货 | B31: 生意社基准价 | C31: 中国综合，SG-5 型 | D31: 元/吨，含税 | E31: 近 93 天 | F31: https://www.100ppi.com/
A32: 电石 | B32: 生意社基准价 | C32: 宁夏/内蒙古，出厂折算 | D32: 元/吨，含税 | E32: 近 93 天 | F32: https://www.100ppi.com/
A33: 液碱 32% | B33: 生意社基准价 | C33: 华东 | D33: 元/吨，含税 | E33: 近 93 天 | F33: https://www.100ppi.com/
A34: PVC 期货 | B34: 新浪财经 主力连续 V0 | C34: 大连商品交易所 | D34: 元/吨，含税 | E34: 2025-10-20～2026-10-19 | F34: https://finance.sina.com.cn/futures/quotes/V0.shtml
A35: 电石（早期） | B35: 文章披露锚点+线性插值 | C35: 乌海主流贸易价 | D35: 元/吨 | E35: 2026-01～2026-09 | F35: 见 04 表锚点清单
A36: 成本与毛利 | B36: 隆众资讯 周报（40 期） | C36: 全国/西北/山东 电石法 | D36: 元/吨 | E36: 2026-01-09～2026-10-16 | F36: https://www.mysteel.com/oilchem/article/3yb4pa/
A38: D. 已知局限（写清楚，比装作没有更好）
A39: · 电石日价历史仅约 93 天，更早区间用 6 个已披露锚点线性插值，不能当成真实日价。
A40: · PVC 现货早于 93 天用"期货主力收盘 + 平均基差 −119.7 元/吨"代理，属推断值，已在 04 表标注。
A41: · 电价、汽价、触媒/助剂单价为截面典型值，未随时间变动；企业应替换为自身结算价。
A42: · 本模型为全国基准，未体现区域价差（乌海 vs 山东电石到厂价差可达 400–600 元/吨）。
A43: · HCl 按"自产氯成本"估值 380 元/吨；若改按液氯市价折入（≈1000 元/吨 HCl），HCl 占比升至约 13%（与文献 14–15% 吻合），但理论利润将再降约 390 元/吨。
