Workbook

Sheet 1 封面与口径
A1: 乙二醇 CFR 中国到岸价 vs 华东（张家港）现货：内外价差四层口径测算
A2: 品种 / 规格 | B2: 乙二醇（MEG） · 聚酯级（纤维级）乙二醇，纯度≥99.9%，散装船货
A3: HS 编码 | B3: 2905310000 1,2-乙二醇（HS 2905.31）
A4: 海外口径 | B4: 中国主港（货源以中东/东北亚为主，具体产地未在报价中披露） · CIF · USD · CFR/CIF 中国主港（卖方口径为中国到岸价，含海运与保险）
A5: 国内口径 | B5: 华东（张家港/太仓/江阴） · 送到主港、含税、现汇；聚酯级散水
A6: 基准日 | B6: 2026-08-18
A7: 观察窗口 | B7: 2025-09-04 ~ 2026-08-18（27 个可对齐观测点）
A8: 金额单位 | B8: 元/吨（除标注 USD 的报价）
A9: 生成时间 / 工具 | B9: 2026-10-20 · windows-spread-calc v1.0.0
A11: 贸易术语包含关系（防止重复计费）
A12: 费用层 | B12: 当前术语是否已包含 | C12: 当前术语 | D12: 说明
A13: 货值 | B13: 报价已含 | C13: CIF | D13: F 组及之后均含货值
A14: 出口国内陆运费 | B14: 报价已含 | C14: CIF | D14: 工厂仓库 → 装运港
A15: 出口报关杂费 | B15: 报价已含 | C15: CIF | D15: 出口报关、单证
A16: 国际海运费 | B16: 报价已含 | C16: CIF | D16: 主运费至目的港
A17: 保险费 | B17: 报价已含 | C17: CIF | D17: 海上运输保险
A18: 目的港卸货/港杂 | B18: 报价不含，需单列 | C18: CIF | D18: THC、港杂
A19: 进口国内陆运 | B19: 报价不含，需单列 | C19: CIF | D19: 目的港 → 收货地
A21: 必读声明
A22: 1. 本报告是成本与价差的对照测算，不是交易建议。文中 G1~G4 只是两个口径的价格之差，不等于可实现的利润，也不构成任何采购、销售、点价、套保或进口交易的指令与时机判断。
A23: 2. 所有海外报价均为二手引用（生意社转述的外盘报价），未取得原始报盘单、船期确认与供货商名称；商业决策前应索取原始报价单。
A24: 3. 历史曲线上每一行都标注了报价、汇率、运费的取得方式；凡标注假设的行，其成本侧数字只能作为条件性结果，不能当作历史实际发生成本。
A25: 4. 本报告不含任何价格预测。所有外生参数（汇率、运费、税率、国内价）均在交互面板显式给出，读者可自行替换并观察结论如何变化。
A26: 5. 所有数据缺口均在第 8 节逐条列出并标明对结论的影响方向；未列出的缺口不代表不存在。
A28: 口径要点
A29: • 本报告只做三件事：把海外报价折成四层可比成本、把国内价折算到同一口径、把两者的差及其变动说清楚。它不判断该不该买，不给出任何下单、建仓、点价或套利操作，也不把价差称作可实现的利润。
A30: • 基准时点取 2026-08-18：该日是海外 CFR 到岸价、同日国内基准价、同日汇率三项同时齐全的最后一个时点。更近的时点缺海外公开报价，故不作为基准，只在第 3 节与缺口清单中说明。
A31: • 四层成本必须分开：CIF 折人民币 / 含税到岸（landed_cash）/ 可抵扣进口增值税 / 可比经济成本（net_cash）。把 CIF 折人民币直接与国内含税价相减，会把 13% 增值税误算成价差。
A32: • 贸易术语是 CFR/CIF（中国到岸价），海运费与保险已在报价内。任何再填一次运费、再加一次保险的算法都是重复计费，本模型由代码强制置零。
A33: • 历史曲线上的运费列全部按 0 计，是因为术语已含运费，不是因为历史运费取不到却拿今天的运费顶替。真正取不到的是逐周运价指数，已在缺口清单第 3 条写明。

Sheet 2 参数与输入
A1: 参数与输入（蓝底格为唯一可修改区，改完所有计算表自动重算）
A2: # | B2: 参数 | C2: 取值 | D2: 单位 | E2: 含义 / 来源 | F2: Excel 名称
A3: 1 | B3: 海外报价 | C3: 685 | D3: USD/吨 | E3: 卖方报价；文本口径见「10 缺口与来源」 | F3: 报价
A4: 2 | B4: 汇率 | C4: 6.7423 | D4: CNY/USD | E4: 基准日 ECB 参考汇率 | F4: 汇率
A5: 3 | B5: 国际海运费 | C5: 0 | D5: USD/吨 | E5: 术语已含则为 0（本表已置 0） | F5: 海运费
A6: 4 | B6: 保险费率 | C6: 0 | D6: 小数 | E6: CIF 已含则不计 | F6: 保险费率
A7: 5 | B7: 保险加成率 | C7: 1.1 | D7: 倍 | E7: 惯例 110% | F7: 加成率
A8: 6 | B8: 目的港卸货 | C8: 0 | D8: USD/吨 | E8: CIF 不含卸货；未取证按 0 | F8: 卸货费
A9: 7 | B9: 进口国内陆运 | C9: 0 | D9: 元/吨 | E9: 港口→工厂 | F9: 国内运费
A10: 8 | B10: 出口国内陆运 | C10: 0 | D10: USD/吨 | E10: 仅 EXW 需要 | F10: 出口运费
A11: 9 | B11: 出口报关杂费 | C11: 0 | D11: USD/吨 | E11: 仅 EXW 需要 | F11: 出口报关
A12: 10 | B12: 装卸/损耗附加 | C12: 0 | D12: 元/吨 | E12: 显式附加项 | F12: 损耗附加
A13: 11 | B13: 进口关税率 | C13: 0 | D13: 小数 | E13: 见缺口第 1 条（5.5% vs 0%） | F13: 关税率
A14: 12 | B14: 其他税率 | C14: 0 | D14: 小数 | E14: 反倾销等 | F14: 其他税率
... A18: 16 | B18: 毛净比 | C18: 1 | D18: 倍 | E18: 包装/皮重修正 | F18: 毛净比
A20: # | B20: 国内可比价输入 | C20: 取值 | D20: 单位 | E20: 含义 | F20: Excel 名称
A21: D1 | B21: 国内现货价 | C21: 5116.67 | D21: 元/吨 | E21: 含税 · 送到基准地 · 现汇 | F21: 国内报价
A22: D2 | B22: 国内价税基 | C22: 含税 | D22: 文本 | E22: 含税 / 不含税 | F22: 税基
A23: D3 | B23: 送到运费（未含时补） | C23: 0 | D23: 元/吨 | E23: 若国内报价非送到价则填 | F23: 国内补运费
A24: D4 | B24: 规格/地区调整 | C24: 0 | D24: 元/吨 | E24: 升贴水（品质、区域） | F24: 调整项
A26: # | B26: 贸易术语 | C26: 取值 | D26: 单位 | E26: 说明 | F26: Excel 名称
A27: T1 | B27: 术语 | C27: CIF | D27: EXW/FCA/FOB/CFR/CIF/DAP | E27: 改术语后需手动把已含项填 0（或看「3 成本折算」的自动屏蔽结果） | F27: 术语
B29: 注：本表所有蓝色单元格都可改；其余工作表全部引用这里的单元格。

Sheet 3 成本折算
A1: 成本折算：从美元报价到四层成本（全部为活公式）
A2: # | B2: 项目 | C2: 金额（元/吨） | D2: 单位 | E2: 公式说明
A3: 1 | B3: 海外报价（原币） | C3: ='2 参数与输入'!$C$3 | D3: USD/吨 | E3: 来自「2 参数与输入」
A4: 2 | B4: 汇率 | C4: ='2 参数与输入'!$C$4 | D4: CNY/USD | E4: ECB 参考汇率
A5: 3 | B5: 货值折人民币 | C5: =C3*C4 | D5: 元/吨 | E5: 货值 = 报价 × 汇率
A6: 4 | B6: 出口国内陆运费 | C6: ='2 参数与输入'!$C$10*C4 | D6: 元/吨 | E6: EXW 才需要
A7: 5 | B7: 出口报关杂费 | C7: ='2 参数与输入'!$C$11*C4 | D7: 元/吨 | E7: EXW 才需要
A8: 6 | B8: 国际海运费 | C8: ='2 参数与输入'!$C$5*C4 | D8: 元/吨 | E8: CFR/CIF/DAP 已含，必须填 0
A9: 7 | B9: 保险费 | C9: =(C5+C6+C7+C8)*'2 参数与输入'!$C$7*'2 参数与输入'!$C$6 | D9: 元/吨 | E9: (货值+出口端费用+运费) × 加成率 × 费率；CIF 已含则填 0
A10: 8 | B10: =CIF 折人民币 | C10: =SUM(C5:C9) | D10: 元/吨 | E10: CIF = 货值 + 出口端 + 运费 + 保险
A11: 9 | B11: 目的港卸货/港杂 | C11: ='2 参数与输入'!$C$8*C4 | D11: 元/吨 | E11: CIF 不含
A12: 10 | B12: 进口关税 | C12: =(C10+C11)*'2 参数与输入'!$C$13 | D12: 元/吨 | E12: 关税 = (CIF+卸货) × 关税率
A13: 11 | B13: 其他税 | C13: =(C10+C11)*'2 参数与输入'!$C$14 | D13: 元/吨 | E13: (CIF+卸货) × 其他税率
A14: 12 | B14: 进口增值税 | C14: =(C10+C11+C12)*'2 参数与输入'!$C$15 | D14: 元/吨 | E14: (CIF+卸货+关税) × 增值税率
A15: 13 | B15: 进口国内陆运费 | C15: ='2 参数与输入'!$C$9 | D15: 元/吨 | E15: 港口→工厂
A16: 14 | B16: 装卸/损耗附加 | C16: ='2 参数与输入'!$C$12 | D16: 元/吨 | E16: 显式附加
A17: 15 | B17: =含税到岸 landed_cash | C17: =C10+C11+C12+C13+C14+C15+C16 | D17: 元/吨 | E17: 现金口径：全部税费与费用都付出去的总额
A18: 16 | B18: 可抵扣进口增值税 | C18: =C14*'2 参数与输入'!$C$16 | D18: 元/吨 | E18: VAT × 可抵扣比例
A19: 17 | B19: =可比经济成本 net_cash | C19: =C17-C18 | D19: 元/吨 | E19: landed_cash − 可抵扣 VAT（经济口径）
A20: 18 | B20: 税费现金支出 cash_out | C20: =C12+C13+(C14-C18) | D20: 元/吨 | E20: 关税 + 其他税 + 不可抵扣 VAT
A21: 19 | B21: 折纯成本 unit_net | C21: =C19/'2 参数与输入'!$C$17*'2 参数与输入'!$C$18 | D21: 元/纯吨 | E21: net_cash ÷ 纯度 × 毛净比
A23: # | B23: 自检 | C23: 结果 | D23: 单位 | E23: 判定规则
A24: K1 | B24: landed_cash 分项闭合 | C24: =ABS(C17-(C10+C11+C12+C13+C14+C15+C16)) | D24: 元/吨 | E24: 必须 = 0
A25: K2 | B25: net_cash = landed − credit | C25: =ABS(C19-(C17-C18)) | D25: 元/吨 | E25: 必须 = 0
A26: K3 | B26: 术语重复计费检查 | C26: =IF(AND('2 参数与输入'!$C$27="CFR",'2 参数与输入'!$C$5>0),"冲突","通过") | D26: — | E26: CFR 报价下海运费必须为 0

Sheet 4 价差四口径
A1: 价差四口径：先把国内价折到可比口径，再做减法
A2: # | B2: 项目 | C2: 金额（元/吨） | D2: 口径 | E2: 说明
A3: D1 | B3: 国内现货价（原样） | C3: ='2 参数与输入'!$C$21 | D3: 元/吨 | E3: 含税/不含税见「2 参数与输入」D2
A4: D2 | B4: 送到+税基调整 | C4: =IF('2 参数与输入'!$C$22="含税",C3,C3*(1+'2 参数与输入'!$C$15))+'2 参数与输入'!$C$23+'2 参数与输入'!$C$24 | D4: 元/吨 | E4: 统一折算到含税送到口径
A5: D3 | B5: 国内未税送到 | C5: =C5/(1+'2 参数与输入'!$C$15) | D5: 元/吨 | E5: 含税价 ÷ (1+增值税率)
A7: # | B7: 价差口径 | C7: 数值（元/吨） | D7: 符号 | E7: 含义（只描述口径差异，不是利润）
A8: G1 | B8: CIF 折人民币 vs 国内未税 | C8: =C5-C10 | D8: =IF(C8>0,"国内更强",IF(C8<0,"进口更便宜","持平")) | E8: 纯价格口径：两边都不含增值税，反映国际与国内价格本身的高低
A9: G2 | B9: 含税到岸 vs 国内含税送到 | C9: =C4-C17 | D9: =IF(C9>0,"国内更强",IF(C9<0,"进口更便宜","持平")) | E9: 现金口径：两边都含税，反映全部现金付出之差
A10: G3 | B10: 经济成本 vs 国内含税送到 | C10: =C4-C19 | D10: =IF(C10>0,"国内更强",IF(C10<0,"进口更便宜","持平")) | E10: 经济口径：进口增值税按可抵扣处理后的真实可比成本
A11: G4 | B11: 进项税抵扣调整后 | C11: =C5-C19 | D11: =IF(C11>0,"国内更强",IF(C11<0,"进口更便宜","持平")) | E11: 税制口径：价格差里有多少来自增值税抵扣权的估值差异
B13: 提示：G1 与 G3 的差 ≈ 进口环节增值税净额；若两者符号相反，说明价格差被税制掩盖，不能只用 CIF 与含税现货相减下结论。

Sheet 5 历史序列
A1: 历史序列（逐时点取值，运费/汇率来源已标注；运费为 0 表示术语已含，不是缺失）
A2: 日期 | B2: 海外报价 USD/吨 | C2: 报价区间 | D2: 汇率 CNY/USD | E2: 汇率日期 | F2: 海运费 USD/吨 | G2: 运费来源 | H2: CIF 元/吨 | I2: 含税到岸 元/吨 | J2: 经济成本 元/吨 | K2: 国内可比 元/吨 | L2: G3 价差 元/吨 | M2: G2 价差 元/吨 | N2: G1 价差 元/吨 | O2: 市场隐含其余成本 | P2: 报价来源 | Q2: 国内来源
A3: 2025-09-04 | B3: 523 | D3: 7.1407 | E3: 2025-09-04 | F3: 0 | G3: 假设(术语已含) | H3: 3734.5861 | I3: 4220.0823 | J3: 3734.5861 | K3: 4478.33 | L3: 743.7439 | M3: 258.24771 | N3: 228.53779 | O3: 743.7439 | P3: https://www.100ppi.com/news/detail-20250905-4735672.html | Q3: https://www.100ppi.com/news/detail-20250904-4731336.html
A4: 2025-09-09 | B4: 521 | D4: 7.1215 | E4: 2025-09-09 | F4: 0 | G4: 假设(术语已含) | H4: 3710.3015 | I4: 4192.6407 | J4: 3710.3015 | K4: 4486.67 | L4: 776.3685 | M4: 294.02931 | N4: 260.20292 | O4: 776.3685 | P4: https://www.100ppi.com/news/detail-20250910-4754833.html | Q4: https://www.100ppi.com/news/detail-20250909-4746332.html
A5: 2025-09-17 | B5: 517 | D5: 7.1042 | E5: 2025-09-17 | F5: 0 | G5: 假设(术语已含) | H5: 3672.8714 | I5: 4150.3447 | J5: 3672.8714 | K5: 4458.33 | L5: 785.4586 | M5: 307.98532 | N5: 272.55338 | O5: 785.4586 | P5: https://www.100ppi.com/news/detail-20250918-4782147.html | Q5: https://www.100ppi.com/news/detail-20250917-4773983.html
A6: 2025-09-18 | B6: 516 | D6: 7.1055 | E6: 2025-09-18 | F6: 0 | G6: 假设(术语已含) | H6: 3666.438 | I6: 4143.0749 | J6: 3666.438 | K6: 4458.33 | L6: 791.892 | M6: 315.25506 | N6: 278.98678 | O6: 791.892 | P6: https://www.100ppi.com/news/detail-20250919-4782782.html | Q6: https://www.100ppi.com/news/detail-20250918-4778121.html
A7: 2025-10-08 | B7: 503 | D7: 7.1195 | E7: 2025-10-08 | F7: 0 | G7: 假设(术语已含) | H7: 3581.1085 | I7: 4046.6526 | J7: 3581.1085 | K7: 4385 | L7: 803.8915 | M7: 338.3474 | N7: 299.42247 | O7: 803.8915 | P7: https://www.100ppi.com/news/detail-20251009-4836040.html | Q7: https://www.100ppi.com/news/detail-20251008-4833357.html
A8: 2025-10-10 | B8: 492 | D8: 7.1228 | E8: 2025-10-10 | F8: 0 | G8: 假设(术语已含) | H8: 3504.4176 | I8: 3959.9919 | J8: 3504.4176 | K8: 4346.67 | L8: 842.2524 | M8: 386.67811 | N8: 342.19302 | O8: 842.2524 | P8: https://www.100ppi.com/news/detail-20251011-4844274.html | Q8: https://www.100ppi.com/news/detail-20251010-4839959.html
A9: 2025-10-14 | B9: 485 | D9: 7.14 | E9: 2025-10-14 | F9: 0 | G9: 假设(术语已含) | H9: 3462.9 | I9: 3913.077 | J9: 3462.9 | K9: 4346.67 | L9: 883.77 | M9: 433.593 | N9: 383.71062 | O9: 883.77 | P9: https://www.100ppi.com/news/detail-20251015-4862578.html | Q9: https://www.100ppi.com/news/detail-20251014-4854341.html
A10: 2025-10-16 | B10: 488 | D10: 7.1258 | E10: 2025-10-16 | F10: 0 | G10: 假设(术语已含) | H10: 3477.3904 | I10: 3929.4512 | J10: 3477.3904 | K10: 4305 | L10: 827.6096 | M10: 375.54885 | N10: 332.34411 | O10: 827.6096 | P10: https://www.100ppi.com/news/detail-20251020-4878158.html | Q10: https://www.100ppi.com/news/detail-20251016-4863012.html
A11: 2025-10-23 | B11: 489 | D11: 7.1244 | E11: 2025-10-23 | F11: 0 | G11: 假设(术语已含) | H11: 3483.8316 | I11: 3936.7297 | J11: 3483.8316 | K11: 4260 | L11: 776.1684 | M11: 323.27029 | N11: 286.0799 | O11: 776.1684 | P11: https://www.100ppi.com/news/detail-20251024-4895542.html | Q11: https://www.100ppi.com/news/detail-20251023-4887441.html
A12: 2025-10-27 | B12: 490 | D12: 7.1075 | E12: 2025-10-27 | F12: 0 | G12: 假设(术语已含) | H12: 3482.675 | I12: 3935.4228 | J12: 3482.675 | K12: 4276.67 | L12: 793.995 | M12: 341.24725 | N12: 301.98872 | O12: 793.995 | P12: https://www.100ppi.com/news/detail-20251028-4906560.html | Q12: https://www.100ppi.com/news/detail-20251027-4898170.html
A13: 2025-11-17 | B13: 468 | D13: 7.1076 | E13: 2025-11-17 | F13: 0 | G13: 假设(术语已含) | H13: 3326.3568 | I13: 3758.7832 | J13: 3326.3568 | K13: 4133.33 | L13: 806.9732 | M13: 374.54682 | N13: 331.45736 | O13: 806.9732 | P13: https://www.100ppi.com/news/detail-20251118-4979572.html | Q13: https://www.100ppi.com/news/detail-20251117-4970455.html
A14: 2025-11-18 | B14: 463 | D14: 7.1104 | E14: 2025-11-18 | F14: 0 | G14: 假设(术语已含) | H14: 3292.1152 | I14: 3720.0902 | J14: 3292.1152 | K14: 4133.33 | L14: 841.2148 | M14: 413.23982 | N14: 365.69896 | O14: 841.2148 | P14: https://www.100ppi.com/news/detail-20251119-4983767.html | Q14: https://www.100ppi.com/news/detail-20251118-4975528.html
... A29: 2026-08-18 | B29: 685 | D29: 6.7423 | E29: 2026-08-18 | F29: 0 | G29: 假设(术语已含) | H29: 4618.4755 | I29: 5218.8773 | J29: 4618.4755 | K29: 5116.67 | L29: 498.1945 | M29: -102.20731 | N29: -90.448951 | O29: 498.1945 | P29: https://www.100ppi.com/news/detail-20260819-6095157.html | Q29: https://www.100ppi.com/news/detail-20260818-6083083.html
A31: 统计
A32: 样本数 | B32: =COUNTA(A3:A29)
A33: G3 最新 | B33: =IFERROR(LOOKUP(9E+307,L3:L29),"")
A34: G3 区间均值 | B34: =IFERROR(AVERAGE(L3:L29),"")
A35: G3 区间最高 | B35: =IFERROR(MAX(L3:L29),"")
A36: G3 区间最低 | B36: =IFERROR(MIN(L3:L29),"")
A37: G3 区间变化 | B37: =IFERROR(B33-B32,"")

Sheet 6 价差曲线数据
A1: 图表数据区（「5 历史序列」的镜像，供 Excel 折线图引用）
A2: 日期 | B2: G3 经济口径 | C2: G2 现金口径 | D2: G1 纯价格口径 | E2: CIF | F2: 经济成本 | G2: 国内可比
A3: ='5 历史序列'!A3 | B3: ='5 历史序列'!L3 | C3: ='5 历史序列'!M3 | D3: ='5 历史序列'!N3 | E3: ='5 历史序列'!H3 | F3: ='5 历史序列'!J3 | G3: ='5 历史序列'!K3
A4: ='5 历史序列'!A4 | B4: ='5 历史序列'!L4 | C4: ='5 历史序列'!M4 | D4: ='5 历史序列'!N4 | E4: ='5 历史序列'!H4 | F4: ='5 历史序列'!J4 | G4: ='5 历史序列'!K4
A5: ='5 历史序列'!A5 | B5: ='5 历史序列'!L5 | C5: ='5 历史序列'!M5 | D5: ='5 历史序列'!N5 | E5: ='5 历史序列'!H5 | F5: ='5 历史序列'!J5 | G5: ='5 历史序列'!K5
A6: ='5 历史序列'!A6 | B6: ='5 历史序列'!L6 | C6: ='5 历史序列'!M6 | D6: ='5 历史序列'!N6 | E6: ='5 历史序列'!H6 | F6: ='5 历史序列'!J6 | G6: ='5 历史序列'!K6
A7: ='5 历史序列'!A7 | B7: ='5 历史序列'!L7 | C7: ='5 历史序列'!M7 | D7: ='5 历史序列'!N7 | E7: ='5 历史序列'!H7 | F7: ='5 历史序列'!J7 | G7: ='5 历史序列'!K7
A8: ='5 历史序列'!A8 | B8: ='5 历史序列'!L8 | C8: ='5 历史序列'!M8 | D8: ='5 历史序列'!N8 | E8: ='5 历史序列'!H8 | F8: ='5 历史序列'!J8 | G8: ='5 历史序列'!K8
A9: ='5 历史序列'!A9 | B9: ='5 历史序列'!L9 | C9: ='5 历史序列'!M9 | D9: ='5 历史序列'!N9 | E9: ='5 历史序列'!H9 | F9: ='5 历史序列'!J9 | G9: ='5 历史序列'!K9
A10: ='5 历史序列'!A10 | B10: ='5 历史序列'!L10 | C10: ='5 历史序列'!M10 | D10: ='5 历史序列'!N10 | E10: ='5 历史序列'!H10 | F10: ='5 历史序列'!J10 | G10: ='5 历史序列'!K10
A11: ='5 历史序列'!A11 | B11: ='5 历史序列'!L11 | C11: ='5 历史序列'!M11 | D11: ='5 历史序列'!N11 | E11: ='5 历史序列'!H11 | F11: ='5 历史序列'!J11 | G11: ='5 历史序列'!K11
A12: ='5 历史序列'!A12 | B12: ='5 历史序列'!L12 | C12: ='5 历史序列'!M12 | D12: ='5 历史序列'!N12 | E12: ='5 历史序列'!H12 | F12: ='5 历史序列'!J12 | G12: ='5 历史序列'!K12
A13: ='5 历史序列'!A13 | B13: ='5 历史序列'!L13 | C13: ='5 历史序列'!M13 | D13: ='5 历史序列'!N13 | E13: ='5 历史序列'!H13 | F13: ='5 历史序列'!J13 | G13: ='5 历史序列'!K13
A14: ='5 历史序列'!A14 | B14: ='5 历史序列'!L14 | C14: ='5 历史序列'!M14 | D14: ='5 历史序列'!N14 | E14: ='5 历史序列'!H14 | F14: ='5 历史序列'!J14 | G14: ='5 历史序列'!K14
... A29: ='5 历史序列'!A29 | B29: ='5 历史序列'!L29 | C29: ='5 历史序列'!M29 | D29: ='5 历史序列'!N29 | E29: ='5 历史序列'!H29 | F29: ='5 历史序列'!J29 | G29: ='5 历史序列'!K29

Sheet 7 敏感性
A1: 敏感性：单参数（各参数独立变动，其余保持输入表值）
A2: 参数 | B2: 取值 | C2: CIF | D2: 含税到岸 | E2: 经济成本 | F2: 相对基准变化 | G2: G3 价差
A3: 海外报价（USD/t）
B4: 500 | C4: 3371.15 | D4: 3809.3995 | E4: 3371.15 | F4: =E4-'3 成本折算'!C19 | G4: ='4 价差四口径'!$C$10-E4
B5: 600 | C5: 4045.38 | D5: 4571.2794 | E5: 4045.38 | F5: =E5-'3 成本折算'!C19 | G5: ='4 价差四口径'!$C$10-E5
B6: 650 | C6: 4382.495 | D6: 4952.2194 | E6: 4382.495 | F6: =E6-'3 成本折算'!C19 | G6: ='4 价差四口径'!$C$10-E6
B7: 685 | C7: 4618.4755 | D7: 5218.8773 | E7: 4618.4755 | F7: =E7-'3 成本折算'!C19 | G7: ='4 价差四口径'!$C$10-E7
B8: 720 | C8: 4854.456 | D8: 5485.5353 | E8: 4854.456 | F8: =E8-'3 成本折算'!C19 | G8: ='4 价差四口径'!$C$10-E8
B9: 800 | C9: 5393.84 | D9: 6095.0392 | E9: 5393.84 | F9: =E9-'3 成本折算'!C19 | G9: ='4 价差四口径'!$C$10-E9
B10: 900 | C10: 6068.07 | D10: 6856.9191 | E10: 6068.07 | F10: =E10-'3 成本折算'!C19 | G10: ='4 价差四口径'!$C$10-E10
A12: 海运费（USD/t）
B13: 0 | C13: 4618.4755 | D13: 5218.8773 | E13: 4618.4755 | F13: =E13-'3 成本折算'!C19 | G13: ='4 价差四口径'!$C$10-E13
B14: 10 | C14: 4618.4755 | D14: 5218.8773 | E14: 4618.4755 | F14: =E14-'3 成本折算'!C19 | G14: ='4 价差四口径'!$C$10-E14
B15: 20 | C15: 4618.4755 | D15: 5218.8773 | E15: 4618.4755 | F15: =E15-'3 成本折算'!C19 | G15: ='4 价差四口径'!$C$10-E15
B16: 40 | C16: 4618.4755 | D16: 5218.8773 | E16: 4618.4755 | F16: =E16-'3 成本折算'!C19 | G16: ='4 价差四口径'!$C$10-E16
B17: 60 | C17: 4618.4755 | D17: 5218.8773 | E17: 4618.4755 | F17: =E17-'3 成本折算'!C19 | G17: ='4 价差四口径'!$C$10-E17
B18: 80 | C18: 4618.4755 | D18: 5218.8773 | E18: 4618.4755 | F18: =E18-'3 成本折算'!C19 | G18: ='4 价差四口径'!$C$10-E18
B19: 120 | C19: 4618.4755 | D19: 5218.8773 | E19: 4618.4755 | F19: =E19-'3 成本折算'!C19 | G19: ='4 价差四口径'!$C$10-E19
A21: USD/CNY
B22: 6.3 | C22: 4315.5 | D22: 4876.515 | E22: 4315.5 | F22: =E22-'3 成本折算'!C19 | G22: ='4 价差四口径'!$C$10-E22
B23: 6.5 | C23: 4452.5 | D23: 5031.325 | E23: 4452.5 | F23: =E23-'3 成本折算'!C19 | G23: ='4 价差四口径'!$C$10-E23
B24: 6.7423 | C24: 4618.4755 | D24: 5218.8773 | E24: 4618.4755 | F24: =E24-'3 成本折算'!C19 | G24: ='4 价差四口径'!$C$10-E24
B25: 6.9 | C25: 4726.5 | D25: 5340.945 | E25: 4726.5 | F25: =E25-'3 成本折算'!C19 | G25: ='4 价差四口径'!$C$10-E25
B26: 7.1 | C26: 4863.5 | D26: 5495.755 | E26: 4863.5 | F26: =E26-'3 成本折算'!C19 | G26: ='4 价差四口径'!$C$10-E26
B27: 7.3 | C27: 5000.5 | D27: 5650.565 | E27: 5000.5 | F27: =E27-'3 成本折算'!C19 | G27: ='4 价差四口径'!$C$10-E27
B28: 7.5 | C28: 5137.5 | D28: 5805.375 | E28: 5137.5 | F28: =E28-'3 成本折算'!C19 | G28: ='4 价差四口径'!$C$10-E28
A30: 关税率
B31: 0 | C31: 4618.4755 | D31: 5218.8773 | E31: 4618.4755 | F31: =E31-'3 成本折算'!C19 | G31: ='4 价差四口径'!$C$10-E31
B32: 0.02 | C32: 4618.4755 | D32: 5323.2549 | E32: 4710.845 | F32: =E32-'3 成本折算'!C19 | G32: ='4 价差四口径'!$C$10-E32
B33: 0.055 | C33: 4618.4755 | D33: 5505.9156 | E33: 4872.4917 | F33: =E33-'3 成本折算'!C19 | G33: ='4 价差四口径'!$C$10-E33
B34: 0.1 | C34: 4618.4755 | D34: 5740.765 | E34: 5080.323 | F34: =E34-'3 成本折算'!C19 | G34: ='4 价差四口径'!$C$10-E34
B35: 0.2 | C35: 4618.4755 | D35: 6262.6528 | E35: 5542.1706 | F35: =E35-'3 成本折算'!C19 | G35: ='4 价差四口径'!$C$10-E35
A37: 保险费率
B38: 0 | C38: 4618.4755 | D38: 5218.8773 | E38: 4618.4755 | F38: =E38-'3 成本折算'!C19 | G38: ='4 价差四口径'!$C$10-E38
B39: 0.001 | C39: 4618.4755 | D39: 5218.8773 | E39: 4618.4755 | F39: =E39-'3 成本折算'!C19 | G39: ='4 价差四口径'!$C$10-E39
B40: 0.0015 | C40: 4618.4755 | D40: 5218.8773 | E40: 4618.4755 | F40: =E40-'3 成本折算'!C19 | G40: ='4 价差四口径'!$C$10-E40
B41: 0.003 | C41: 4618.4755 | D41: 5218.8773 | E41: 4618.4755 | F41: =E41-'3 成本折算'!C19 | G41: ='4 价差四口径'!$C$10-E41
B42: 0.005 | C42: 4618.4755 | D42: 5218.8773 | E42: 4618.4755 | F42: =E42-'3 成本折算'!C19 | G42: ='4 价差四口径'!$C$10-E42
A44: 目的港卸货费（USD/t）
B45: 0 | C45: 4618.4755 | D45: 5218.8773 | E45: 4618.4755 | F45: =E45-'3 成本折算'!C19 | G45: ='4 价差四口径'!$C$10-E45
...

Sheet 8 归因分解
A1: 归因分解：2025-12-09 → 2026-08-18（逐项一次替换，单位 元/吨；正 = 该项使价差变大）
A2: 驱动因子 | B2: 变化描述 | C2: 对价差贡献 | D2: 读法
A3: 海外报价（美元） | B3: 436.0 → 685.0 USD/t | C3: -1759.0107 | D3: 价差因该项上升而收窄
A4: 汇率 USD/CNY | B4: 7.0643 → 6.7423 | C4: 220.57 | D4: 价差因该项上升而扩大
A5: 海运费 USD/t | B5: 0.0 → 0.0（assumed_base） | C5: 0 | D5: 价差因该项上升而收窄
A6: 关税/其他税率 | B6: 0.0 → 0.0 | C6: 0 | D6: 价差因该项上升而收窄
A7: 增值税可抵扣比例 | B7: 1.0 → 1.0 | C7: 0 | D7: 价差因该项上升而收窄
A8: 保险费率 | B8: 0.0 → 0.0 | C8: 0 | D8: 价差因该项上升而收窄
A9: 国内现货价 | B9: 3970.0 → 5116.67 CNY/t | C9: 1146.67 | D9: 价差因该项上升而扩大
A10: 合计 | B10: 889.97 → 498.19 | C10: =SUM(C5:C9) | D10: 与 Python 内核结果对照：-391.77
A12: 闭合残差（应 <1e-6） | C12: 0
A13: 对比期输入 | B13: 报价 436 USD / 汇率 7.06 / 国内 3,970 元 / 运费 0

Sheet 9 情景对比
A1: 情景对比：换术语 / 加费用 / 改税率后，成本与价差如何变化
A2: 情景 | B2: 说明 | C2: CIF | D2: 含税到岸 | E2: 经济成本 | F2: 相对基准变化 | G2: G3 价差
A3: 口径 A：报价原样（CIF 中国） | B3: 完全按卖方口径，不追加任何费用；只计关税与增值税 | C3: 4618.4755 | D3: 5218.8773 | E3: 4618.4755 | F3: 0 | G3: 498.1945
A4: 口径 B：CIF 补卸货/港杂 20 USD/t | B4: CIF 通常不含目的港卸货费，按假设值补入以观察影响 | C4: 4618.4755 | D4: 5371.2533 | E4: 4753.3215 | F4: 134.846 | G4: 363.3485
A5: 口径 C：视作 FOB，自付海运 40 USD/t | B5: 对照组：若拿到的是 FOB 价而非到岸价，成本抬高多少 | C5: 4896.233 | D5: 5532.7433 | E5: 4896.233 | F5: 277.75748 | G5: 220.43702
A6: 口径 D：可抵扣比例降为 80% | B6: 部分进项税无法及时抵扣的折价情形 | C6: 4618.4755 | D6: 5218.8773 | E6: 4738.5559 | F6: 120.08036 | G6: 378.11414
A7: 口径 E：按最惠国税率 5.5% 计关税 | B7: 对照组：若适用税率不是 0，成本抬升多少 | C7: 4618.4755 | D7: 5505.9156 | E7: 4872.4917 | F7: 254.01615 | G7: 244.17835
A9: 注：情景值由同一内核按 override 参数复算；口径 C（FOB+40 USD/t 运费）仅为对照，不代表真实运价。

Sheet 10 缺口与来源
A1: 数据缺口：这次结论哪里还不牢（按严重度处理，不是免责声明）
A2: # | B2: 缺口 | C2: 对结论的影响 | D2: 补齐办法 | E2: 严重度
A3: 1 | B3: 乙二醇最惠国进口税率 5.5%，但实际执行是否为暂定税率 0%，未取得现行税则原文 | C3: 若按 5.5% 计征，到岸成本上升约 (CIF+卸货)×5.5% ≈ 250 元/吨（按 CIF 4618 估），足以改变 G2/G3 的符号。本报告默认 0%，因此所有国内更强的结论都建立在该前提上。 | D3: 查海关总署《进出口税则》当年版 2905.31 条目与年度暂定税率表，或向报关行索取实际执行税率留档。 | E3: 高
A4: 2 | B4: 海外报价只有中国到岸价一个数，未拆分 CFR 与保险，也未披露产地、船期、装运港与供货商 | C4: 无法核对报价是否真含保险（若实为 CFR，本模型少计约 7 元/吨保险费，可忽略）；也无法判断该报价对应哪条产线、是否含地缘因素下的绕行附加。 | D4: 取得隆众/CCF/Platts 的 MEG 中国 CFR 日报或船货报盘，逐笔记录产地、装运期、付款方式。 | E4: 中
A5: 3 | B5: 逐周或逐月散化船运价指数、中东至华东实际运价未取得 | C5: 本品种报价为到岸价、运费已含，故对当前四层成本无直接影响；但若改用 FOB 口径（口径 C 情景），运费 40 USD/t 只是假设值，误差 ±20 USD/t 会让成本变动约 ±135 元/吨。 | D5: 接入上海航交所或波罗的海交易所相关航线运价，或按船司季度报盘留档；模型中运费须标注为假设而非实测。 | E5: 中
A6: 4 | B6: 目的港卸货费（THC、港建费、罐租与短驳）没有公开报价 | C6: 按 0 计入，成本可能低估约 10~30 USD/t（约 70~200 元/吨），足以吞掉当前价差的一半。 | D6: 向张家港/太仓码头或货代索取 MEG 散水接卸、罐租、短驳报价单。 | E6: 高
A7: 5 | B7: 增值税抵扣的实际实现程度未核实（模型默认 100% 可抵扣） | C7: 若实际只能抵扣 80%，经济成本上升约 120 元/吨（口径 D 已量化）。 | D7: 按报关主体（一般纳税人/小规模）与实际留抵情况确认；有留抵挂账时应改用现金口径 G2。 | E7: 中
A8: 6 | B8: 基准时点为 2026-08-18，距生成日 2026-10-20 已两个月，期间国内价由 5116.67 涨至 5808.33 | C8: 基准时点的结论不能直接当作今天的窗口；当期国内价上行约 691 元/吨，若海外报价未同步上行，价差会明显扩大。 | D8: 补齐 2026-09-01 之后的海外 CFR 公开报价（本报告检索范围内最后一条为 2026-08-18），即可把曲线延伸到当日。 | E8: 高
A9: 7 | B9: 海外报价为离散发布（27 个点，平均间隔约 13 天），不是连续日行情 | C9: 曲线只能读作观测到的价差水平，不能读作逐日路径；极值与转折日可能落在两次发布之间。 | D9: 改用日频 CFR 中间价序列（付费源），或按周固定日期采样。 | E9: 中
A10: 8 | B10: 国内价采用生意社基准价（采样加权参考价），与隆众张家港买卖盘、期货结算价存在系统性差异 | C10: 2026-10-19：生意社 5966.67、隆众张家港买盘 5630/卖盘 5640、EG0 收盘 4976，最大相差约 990 元/吨。基准价偏高会高估价差。 | D10: 固定使用单一权威口径并在首页声明；建议以隆众张家港 15:00 收盘买卖中值为准，生意社基准价作参照。 | E10: 高
A11: 9 | B11: 规格与品质升贴水未量化（进口聚酯级 vs 国内煤制聚酯级，纯度与水含量差异） | C11: 同为聚酯级，煤制与乙烯法在 UV 透过率、色度上有差异，下游结算价可差 50~150 元/吨。 | D11: 取得两家以上下游聚酯厂的到货验收标准与结算价，量化升贴水。 | E11: 低
A12: 10 | B12: 历史运费没有逐时点的实际值，全部按月度均价或基准日假设处理 | C12: 价差曲线中的成本部分含假设误差，方向可由运费假设解释 | D12: 接入逐周运价指数（SCFI 相关航线 / 波罗的海指数 / 船司报价） | E12: 高
A14: 数据来源：每个数字都带六要素（数值·规格·地区·含税·日期·来源）
A15: # | B15: 角色 / 名称 | C15: 说明与备注 | D15: 链接 | E15: 可信度
A16: 1 | B16: overseas · 生意社《外盘乙二醇价格一览》系列（二手引用，转述外盘报价） | C16: 2025-09-04 ~ 2026-08-18｜原文表述为中国到岸价为 N 美元/吨，本报告按 CIF 口径处理；未披露产地、船期与供货商。 | D16: https://www.100ppi.com/news/detail-20260819-6095157.html https://www.100ppi.com/news/detail-20250905-4735672.html https://www.100ppi.com/news/detail-20250910-4754833.html | E16: 中
A17: 2 | B17: domestic · 生意社乙二醇基准价（每日 08:30 发布，经销商/厂采样） | C17: 2025-04-28 ~ 2026-10-20（本次采集 388 个日值）｜基准价为采样加权含税参考价，不是交易所结算价，也不是某一家贸易商的成交价。 | D17: https://www.100ppi.com/news/detail-20260818-6083083.html https://www.100ppi.com/news/detail-20261020-6368369.html | E17: 中
A18: 3 | B18: fx · Frankfurter API / 欧洲央行 ECB 每日参考汇率 | C18: 2025-09-01 ~ 2026-10-19（290 个工作日）｜ECB 参考汇率非银行间即期成交价，通常存在 <0.5% 偏差。 | D18: https://api.frankfurter.app/2024-10-01..2026-10-20?from=USD&to=CNY | E18: 高
A19: 4 | B19: tax · 海关 HS 编码查询（2905310000 1,2-乙二醇） | C19: 2026-10-20 查询｜页面载明最惠国进口税率 5.5%、普通税率 30%、消费税 0%、增值税 13%、出口退税 13%。本模型采用 0% 关税（见缺口第 1 条）、13% 增值税。 | D19: https://www.i5a6.com/hscode/detail/2905310000 | E19: 中
A20: 5 | B20: cross · 期货日线 EG0 主连（新浪财经） | C20: 2025-09-01 ~ 2026-10-20｜仅作交叉验证：2026-10-19 EG0 收盘 4976，同期生意社国内价 5966.67、隆众张家港买盘 5630/卖盘 5640，三者关系可用于校验国内价口径的合理性。 | D20: https://stock2.finance.sina.com.cn/futures/api/jsonp.php/var%20_x=/InnerFuturesNewService.getDailyKLine?symbol=EG0 | E20: 高
A21: 6 | B21: cross · 隆众资讯张家港乙二醇市场行情（经同花顺/我的钢铁网转述） | C21: 2026-10-19 09:28｜原文：本周买盘 5630、卖盘 5640，现货基差 11+400 至 410（元/吨）。作为国内价的独立交叉验证。 | D21: http://news.10jqka.com.cn/20261019/c680817512.shtml | E21: 中
A22: 7 | B22: cross · 生意社：山西潞安化工聚酯级乙二醇起拍价（含税出厂、现汇） | C22: 2026-10-19 / 2026-10-20｜10-19 起拍价 5580 元/吨（现汇，承兑加 50），10-20 起拍价 5550 元/吨；用于判断内地出厂价与港口价的关系。 | D22: https://www.100ppi.com/news/detail-20261019-6367811.html https://www.100ppi.com/news/detail-20261020-6368784.html | E22: 高

Sheet 11 公式表
A1: 公式表：与 scripts/core.py、assets/core.js、HTML 报告完全同源
A2: # | B2: 项目 | C2: 公式 | D2: 基准值 | E2: 单位
A3: 1 | B3: 货值折人民币 | C3: 货值_CNY = 报价 × 汇率（USD 报价）或 报价（CNY 报价） | D3: 4618.4755 | E3: 元/吨
A4: 2 | B4: 保险费 | C4: 保险 = (货值 + 出口端费用 + 运费) × 加成率 × 费率 | D4: 0 | E4: 元/吨
A5: 3 | B5: CIF 到岸价 | C5: CIF = 货值 + 出口内陆 + 出口报关 + 运费 + 保险 | D5: 4618.4755 | E5: 元/吨
A6: 4 | B6: 进口关税 | C6: 关税 = (CIF + 卸货费) × 关税率 | D6: 0 | E6: 元/吨
A7: 5 | B7: 进口增值税 | C7: VAT = (CIF + 卸货费 + 关税) × 增值税率 | D7: 600.40182 | E7: 元/吨
A8: 6 | B8: 可抵扣增值税 | C8: 可抵扣 VAT = VAT × 可抵扣比例 | D8: 600.40182 | E8: 元/吨
A9: 7 | B9: 含税到岸成本（现金口径） | C9: landed_cash = CIF + 卸货 + 关税 + 其他税 + VAT + 进口内陆 + 损耗 | D9: 5218.8773 | E9: 元/吨
A10: 8 | B10: 可比经济成本 | C10: net_cash = landed_cash − 可抵扣 VAT | D10: 4618.4755 | E10: 元/吨
A11: 9 | B11: 折纯/毛净口径 | C11: unit_net = net_cash ÷ 纯度 × 毛净比 | D11: 4618.4755 | E11: 元/纯吨
A12: 10 | B12: 四口径价差 | C12: G1 = 国内未税 − CIF；G2 = 国内含税 − landed_cash；G3 = 国内含税 − net_cash；G4 = 国内未税 − net_cash | E12: 元/吨
A13: 11 | B13: 市场隐含其余成本 | C13: 残差 = 国内价 − CIF − 运费 − 保险 − 卸货（不含税口径） | E13: 元/吨
A14: 12 | B14: 归因分解 | C14: Δ价差 = Σ(−Δ成本项) + Δ国内价；闭合残差须 < 1e-6 | E14: 元/吨
