Workbook

Sheet 使用说明
B1: 进口到厂成本计算器 · Excel 版
B2: FOB / CFR / CIF 三口径 · 全公式 · 改参数自动重算
B4: 【30 秒上手】
B5: 只改黄色单元格：C6 单价、C7 数量、C10 市场汇率、C11 海关计征汇率、C14 海运费（仅 FOB）、C46~C51 境内费用。
B6: 看三个数：C61 最终经济成本 元/吨（★到厂成本）；C58 整票现金支出；C42 进口环节增值税现金。
B7: C64 状态若为「待补全」，说明有关键项没填——先补数据，不要用 C65 已知小计冒充完整到厂价。
B9: 【三口径怎么防重复计费】
B10: CFR 页：C29 海运费自动为 0（报价已含）；CIF 页：C29 与 C30 都为 0（海运+保险均已含）。
B11: 由此，CFR/CIF 报价里已经付过的运费/保费不会被再加一次。
B13: 【关税与增值税】
B14: 关税税率 C33 必须按税则查询后录入；可享优惠时先核验 4 道闸门：协定生效 / 降税清单 / 原产地规则 / 有效证书。
B15: 增值税分两栏：C42 现金支出 / C43 可抵扣进项；C60 = 现金支出 − 可抵扣。
... B26: 运费/保险/港杂/仓储为模拟情景；税率须按核验日期重新确认；最终金额以海关核定与实际单据为准。

Sheet FOB
B1: ① 商品与交易信息
B2: 产品 | C2: 工业级乙二醇 MEG | D2: 规格 | E2: ≥99.9% 工业级
B3: HS编码 | C3: 29053100 | D3: 原产国 | E3: SA 沙特阿拉伯
B4: 目的地 | C4: 宁波港 → 江苏苏州 | D4: 指定地点 | E4: 沙特朱拜勒 Al Jubail
B5: ② 报价与费用参数（黄色=可改，白色=公式；未填=待确认，绝不当作 0）
B6: 供应商单价（原币/计价单位） | C6: 640 | F6: 黄色单元格可修改
B7: 数量（吨） | C7: 62.5 | F7: 25×40' ISO 罐 × 25.0 吨
B8: 单价计价单位（MT / CONTAINER） | C8: MT | F8: MT=每吨价；CONTAINER=每柜价
B9: 包装是否已含于单价（TRUE/FALSE） | C9: TRUE | F9: 《关税法》第25条：包装费计入计税价格
B10: 市场参考汇率 USD/CNY | C10: 6.6807 | F10: ECB 2026-10-19；exchangerate-api 2026-10-20=6.69
B11: 海关计征汇率 USD/CNY（演示占位值，须替换） | C11: 6.72 | F11: 演示占位 6.7200（非2026-09-16官方值）；请替换为申报日对应上月第三个星期三亚行中间价；留空=待补全
B12: 出口侧费用 USD（EXW/FCA 填） | F12: 其余术语自动置 0
B13: 起运港费用 USD（EXW/FCA 填） | F13: FOB 及以上已含，自动置 0
B14: 海运费 USD/MT（报价未含时填） | C14: 45 | F14: 仅 FOB/EXW/FCA/FAS 需要
B15: 整票海运费 USD（可选） | F15: 货代按整票报价时填，优先于单价
B16: 保险费率 ‰ | C16: 0.55 | F16: 保费=(货值+运费)×费率×110%（模拟）
B17: 实际保险费 USD（可选） | F17: 有保单时填，优先于费率
B18: 保险是否已含于报价（TRUE/FALSE） | C18: FALSE | F18: CIF 默认 TRUE
B19: 包装费另计 USD | C19: 0 | F19: PI 另计包装时填；已含填 0
B20: 报价已含海运费（按术语判定） | C20: =OR("FOB"="CFR","FOB"="CIF","FOB"="CPT","FOB"="CIP","FOB"="DAP","FOB"="DPU","FOB"="DDP") | F20: Incoterms 2020
B21: 报价已含保险费（按术语判定） | C21: =OR("FOB"="CIF","FOB"="CIP","FOB"="DDP") | F21: Incoterms 2020
B22: 报价已含起运港费用（按术语判定） | C22: =NOT(OR("FOB"="EXW","FOB"="FCA")) | F22: EXW/FCA 不含装运港费用
B23: ③ 第一层：货值 → 到岸（C=原币；D=人民币，按市场参考汇率）
B24: 货值（单价×数量） | C24: =IF(AND(ISNUMBER(C6),ISNUMBER(C7)),C6*C7,"") | D24: =IF(ISNUMBER(C24),C24*$C$10,"") | E24: 人民币 | F24: 整票货值（原币）
B25: 单吨货值 | C25: =IF(AND(ISNUMBER(C24),C7>0),C24/C7,"") | D25: =IF(ISNUMBER(C25),C25*$C$10,"") | E25: 人民币 | F25: 原币/吨
B26: 包装费（另计） | C26: =IF(C9=TRUE,0,IF(ISNUMBER(C19),C19,"")) | D26: =IF(ISNUMBER(C26),C26*$C$10,"") | E26: 人民币 | F26: 单价已含包装 → 0
B27: 起运港费用 | C27: =IF(C22,0,IF(ISNUMBER(C13),C13,"")) | D27: =IF(ISNUMBER(C27),C27*$C$10,"") | E27: 人民币 | F27: 报价已含 → 0
B28: 出口侧费用 | C28: =IF(C22,0,IF(ISNUMBER(C12),C12,"")) | D28: =IF(ISNUMBER(C28),C28*$C$10,"") | E28: 人民币 | F28: 报价已含 → 0
B29: 海运费（整票） | C29: =IF(C20,0,IF(ISNUMBER(C15),C15,IF(AND(ISNUMBER(C14),ISNUMBER(C7)),C14*C7,""))) | D29: =IF(ISNUMBER(C29),C29*$C$10,"") | E29: 人民币 | F29: CFR/CIF 已含 → 0（不重复计费）
B30: 保险费（实际） | C30: =IF(C18,0,IF(ISNUMBER(C17),C17,IF(AND(ISNUMBER(C16),ISNUMBER(C24),ISNUMBER(C29)),(C24+C29)*C16/100*1.1,""))) | D30: =IF(ISNUMBER(C30),C30*$C$10,"") | E30: 人民币 | F30: CIF 已含 → 0；费率按 110% 投保额
B31: 到岸成本合计（CIF 等值） | C31: =IF(COUNT(C24,C26,C27,C28,C29,C30)=6,SUM(C24,C26,C27,C28,C29,C30),"") | D31: =IF(ISNUMBER(C31),C31*$C$10,"") | E31: 人民币 | F31: 货值+包装+起运港+出口侧+海运+保险（原币与人民币两列）
B32: ④ 第二层：进口税费（关税不可抵扣；增值税分现金/可抵扣两栏）
B33: 关税税率（实征，从税则查询录入） | C33: 0.055 | F33: 来源与核验日期见【数据来源】页
B34: 反倾销/反补贴税率 | C34: 0 | F34: 核验后填写；未查到填 0 并注明（≠不存在）
B35: 进口环节增值税率 | C35: 0.13 | F35: 一般货物 13%
B36: 增值税是否可抵扣（是/否） | C36: 是 | F36: 一般纳税人且用于应税项目=是
B37: 其中：计入计税价格的保险费 | C37: =IF(C18=TRUE,0,IF(ISNUMBER(C30),C30,IF(AND(ISNUMBER(C24),ISNUMBER(C29)),((C24)+IF(C9=TRUE,0,IF(ISNUMBER(C19),C19,0))+IF(C22,0,IF(ISNUMBER(C13),C13,0))+IF(C22,0,IF(ISNUMBER(C12),C12,0))+C29)*0.003/0.997,""))) | F37: 未投保时按（货价+运费）×0.3‰（第36条）
B38: 关税计税价格（人民币，完税价格） | C38: =IF(AND(ISNUMBER(C24),ISNUMBER(C11),ISNUMBER(C26),ISNUMBER(C28),ISNUMBER(C29),ISNUMBER(C30),ISNUMBER(C37)),(C24+C26+IF(ISNUMBER(C27),C27,0)+C28+C29+IF(C18,0,C37))*C11,"") | F38: ＝(货值+包装+起运港+出口侧+海运+实际保险+应计保险)×海关计征汇率
B39: 应纳关税 | C39: =IF(AND(ISNUMBER(C38),ISNUMBER(C33)),C38*C33,"") | F39: ＝计税价格×实征税率（不可抵扣，一定进成本）
B40: 反倾销/反补贴税 | C40: =IF(AND(ISNUMBER(C38),ISNUMBER(C34)),C38*C34,"") | F40: ＝计税价格×措施税率
...

Sheet CFR
B1: ① 商品与交易信息
B2: 产品 | C2: 工业级乙二醇 MEG | D2: 规格 | E2: ≥99.9% 工业级
B3: HS编码 | C3: 29053100 | D3: 原产国 | E3: SA 沙特阿拉伯
B4: 目的地 | C4: 宁波港 → 江苏苏州 | D4: 指定地点 | E4: 中国宁波
B5: ② 报价与费用参数（黄色=可改，白色=公式；未填=待确认，绝不当作 0）
B6: 供应商单价（原币/计价单位） | C6: 685 | F6: 黄色单元格可修改
B7: 数量（吨） | C7: 62.5 | F7: 25×40' ISO 罐 × 25.0 吨
B8: 单价计价单位（MT / CONTAINER） | C8: MT | F8: MT=每吨价；CONTAINER=每柜价
B9: 包装是否已含于单价（TRUE/FALSE） | C9: TRUE | F9: 《关税法》第25条：包装费计入计税价格
B10: 市场参考汇率 USD/CNY | C10: 6.6807 | F10: ECB 2026-10-19；exchangerate-api 2026-10-20=6.69
B11: 海关计征汇率 USD/CNY（演示占位值，须替换） | C11: 6.72 | F11: 演示占位 6.7200（非2026-09-16官方值）；请替换为申报日对应上月第三个星期三亚行中间价；留空=待补全
B12: 出口侧费用 USD（EXW/FCA 填） | F12: 其余术语自动置 0
B13: 起运港费用 USD（EXW/FCA 填） | F13: FOB 及以上已含，自动置 0
B14: 海运费 USD/MT（报价未含时填） | F14: 仅 FOB/EXW/FCA/FAS 需要
B15: 整票海运费 USD（可选） | F15: 货代按整票报价时填，优先于单价
B16: 保险费率 ‰ | C16: 0.55 | F16: 保费=(货值+运费)×费率×110%（模拟）
B17: 实际保险费 USD（可选） | F17: 有保单时填，优先于费率
B18: 保险是否已含于报价（TRUE/FALSE） | C18: FALSE | F18: CIF 默认 TRUE
B19: 包装费另计 USD | C19: 0 | F19: PI 另计包装时填；已含填 0
B20: 报价已含海运费（按术语判定） | C20: =OR("CFR"="CFR","CFR"="CIF","CFR"="CPT","CFR"="CIP","CFR"="DAP","CFR"="DPU","CFR"="DDP") | F20: Incoterms 2020
B21: 报价已含保险费（按术语判定） | C21: =OR("CFR"="CIF","CFR"="CIP","CFR"="DDP") | F21: Incoterms 2020
B22: 报价已含起运港费用（按术语判定） | C22: =NOT(OR("CFR"="EXW","CFR"="FCA")) | F22: EXW/FCA 不含装运港费用
B23: ③ 第一层：货值 → 到岸（C=原币；D=人民币，按市场参考汇率）
B24: 货值（单价×数量） | C24: =IF(AND(ISNUMBER(C6),ISNUMBER(C7)),C6*C7,"") | D24: =IF(ISNUMBER(C24),C24*$C$10,"") | E24: 人民币 | F24: 整票货值（原币）
B25: 单吨货值 | C25: =IF(AND(ISNUMBER(C24),C7>0),C24/C7,"") | D25: =IF(ISNUMBER(C25),C25*$C$10,"") | E25: 人民币 | F25: 原币/吨
B26: 包装费（另计） | C26: =IF(C9=TRUE,0,IF(ISNUMBER(C19),C19,"")) | D26: =IF(ISNUMBER(C26),C26*$C$10,"") | E26: 人民币 | F26: 单价已含包装 → 0
B27: 起运港费用 | C27: =IF(C22,0,IF(ISNUMBER(C13),C13,"")) | D27: =IF(ISNUMBER(C27),C27*$C$10,"") | E27: 人民币 | F27: 报价已含 → 0
B28: 出口侧费用 | C28: =IF(C22,0,IF(ISNUMBER(C12),C12,"")) | D28: =IF(ISNUMBER(C28),C28*$C$10,"") | E28: 人民币 | F28: 报价已含 → 0
B29: 海运费（整票） | C29: =IF(C20,0,IF(ISNUMBER(C15),C15,IF(AND(ISNUMBER(C14),ISNUMBER(C7)),C14*C7,""))) | D29: =IF(ISNUMBER(C29),C29*$C$10,"") | E29: 人民币 | F29: CFR/CIF 已含 → 0（不重复计费）
B30: 保险费（实际） | C30: =IF(C18,0,IF(ISNUMBER(C17),C17,IF(AND(ISNUMBER(C16),ISNUMBER(C24),ISNUMBER(C29)),(C24+C29)*C16/100*1.1,""))) | D30: =IF(ISNUMBER(C30),C30*$C$10,"") | E30: 人民币 | F30: CIF 已含 → 0；费率按 110% 投保额
B31: 到岸成本合计（CIF 等值） | C31: =IF(COUNT(C24,C26,C27,C28,C29,C30)=6,SUM(C24,C26,C27,C28,C29,C30),"") | D31: =IF(ISNUMBER(C31),C31*$C$10,"") | E31: 人民币 | F31: 货值+包装+起运港+出口侧+海运+保险（原币与人民币两列）
B32: ④ 第二层：进口税费（关税不可抵扣；增值税分现金/可抵扣两栏）
B33: 关税税率（实征，从税则查询录入） | C33: 0.055 | F33: 来源与核验日期见【数据来源】页
B34: 反倾销/反补贴税率 | C34: 0 | F34: 核验后填写；未查到填 0 并注明（≠不存在）
B35: 进口环节增值税率 | C35: 0.13 | F35: 一般货物 13%
B36: 增值税是否可抵扣（是/否） | C36: 是 | F36: 一般纳税人且用于应税项目=是
B37: 其中：计入计税价格的保险费 | C37: =IF(C18=TRUE,0,IF(ISNUMBER(C30),C30,IF(AND(ISNUMBER(C24),ISNUMBER(C29)),((C24)+IF(C9=TRUE,0,IF(ISNUMBER(C19),C19,0))+IF(C22,0,IF(ISNUMBER(C13),C13,0))+IF(C22,0,IF(ISNUMBER(C12),C12,0))+C29)*0.003/0.997,""))) | F37: 未投保时按（货价+运费）×0.3‰（第36条）
B38: 关税计税价格（人民币，完税价格） | C38: =IF(AND(ISNUMBER(C24),ISNUMBER(C11),ISNUMBER(C26),ISNUMBER(C28),ISNUMBER(C29),ISNUMBER(C30),ISNUMBER(C37)),(C24+C26+IF(ISNUMBER(C27),C27,0)+C28+C29+IF(C18,0,C37))*C11,"") | F38: ＝(货值+包装+起运港+出口侧+海运+实际保险+应计保险)×海关计征汇率
B39: 应纳关税 | C39: =IF(AND(ISNUMBER(C38),ISNUMBER(C33)),C38*C33,"") | F39: ＝计税价格×实征税率（不可抵扣，一定进成本）
B40: 反倾销/反补贴税 | C40: =IF(AND(ISNUMBER(C38),ISNUMBER(C34)),C38*C34,"") | F40: ＝计税价格×措施税率
...

Sheet CIF
B1: ① 商品与交易信息
B2: 产品 | C2: 工业级乙二醇 MEG | D2: 规格 | E2: ≥99.9% 工业级
B3: HS编码 | C3: 29053100 | D3: 原产国 | E3: SA 沙特阿拉伯
B4: 目的地 | C4: 宁波港 → 江苏苏州 | D4: 指定地点 | E4: 中国宁波
B5: ② 报价与费用参数（黄色=可改，白色=公式；未填=待确认，绝不当作 0）
B6: 供应商单价（原币/计价单位） | C6: 685.05 | F6: 黄色单元格可修改
B7: 数量（吨） | C7: 62.5 | F7: 25×40' ISO 罐 × 25.0 吨
B8: 单价计价单位（MT / CONTAINER） | C8: MT | F8: MT=每吨价；CONTAINER=每柜价
B9: 包装是否已含于单价（TRUE/FALSE） | C9: TRUE | F9: 《关税法》第25条：包装费计入计税价格
B10: 市场参考汇率 USD/CNY | C10: 6.6807 | F10: ECB 2026-10-19；exchangerate-api 2026-10-20=6.69
B11: 海关计征汇率 USD/CNY（演示占位值，须替换） | C11: 6.72 | F11: 演示占位 6.7200（非2026-09-16官方值）；请替换为申报日对应上月第三个星期三亚行中间价；留空=待补全
B12: 出口侧费用 USD（EXW/FCA 填） | F12: 其余术语自动置 0
B13: 起运港费用 USD（EXW/FCA 填） | F13: FOB 及以上已含，自动置 0
B14: 海运费 USD/MT（报价未含时填） | F14: 仅 FOB/EXW/FCA/FAS 需要
B15: 整票海运费 USD（可选） | F15: 货代按整票报价时填，优先于单价
B16: 保险费率 ‰ | C16: 0.55 | F16: 保费=(货值+运费)×费率×110%（模拟）
B17: 实际保险费 USD（可选） | F17: 有保单时填，优先于费率
B18: 保险是否已含于报价（TRUE/FALSE） | C18: TRUE | F18: CIF 默认 TRUE
B19: 包装费另计 USD | C19: 0 | F19: PI 另计包装时填；已含填 0
B20: 报价已含海运费（按术语判定） | C20: =OR("CIF"="CFR","CIF"="CIF","CIF"="CPT","CIF"="CIP","CIF"="DAP","CIF"="DPU","CIF"="DDP") | F20: Incoterms 2020
B21: 报价已含保险费（按术语判定） | C21: =OR("CIF"="CIF","CIF"="CIP","CIF"="DDP") | F21: Incoterms 2020
B22: 报价已含起运港费用（按术语判定） | C22: =NOT(OR("CIF"="EXW","CIF"="FCA")) | F22: EXW/FCA 不含装运港费用
B23: ③ 第一层：货值 → 到岸（C=原币；D=人民币，按市场参考汇率）
B24: 货值（单价×数量） | C24: =IF(AND(ISNUMBER(C6),ISNUMBER(C7)),C6*C7,"") | D24: =IF(ISNUMBER(C24),C24*$C$10,"") | E24: 人民币 | F24: 整票货值（原币）
B25: 单吨货值 | C25: =IF(AND(ISNUMBER(C24),C7>0),C24/C7,"") | D25: =IF(ISNUMBER(C25),C25*$C$10,"") | E25: 人民币 | F25: 原币/吨
B26: 包装费（另计） | C26: =IF(C9=TRUE,0,IF(ISNUMBER(C19),C19,"")) | D26: =IF(ISNUMBER(C26),C26*$C$10,"") | E26: 人民币 | F26: 单价已含包装 → 0
B27: 起运港费用 | C27: =IF(C22,0,IF(ISNUMBER(C13),C13,"")) | D27: =IF(ISNUMBER(C27),C27*$C$10,"") | E27: 人民币 | F27: 报价已含 → 0
B28: 出口侧费用 | C28: =IF(C22,0,IF(ISNUMBER(C12),C12,"")) | D28: =IF(ISNUMBER(C28),C28*$C$10,"") | E28: 人民币 | F28: 报价已含 → 0
B29: 海运费（整票） | C29: =IF(C20,0,IF(ISNUMBER(C15),C15,IF(AND(ISNUMBER(C14),ISNUMBER(C7)),C14*C7,""))) | D29: =IF(ISNUMBER(C29),C29*$C$10,"") | E29: 人民币 | F29: CFR/CIF 已含 → 0（不重复计费）
B30: 保险费（实际） | C30: =IF(C18,0,IF(ISNUMBER(C17),C17,IF(AND(ISNUMBER(C16),ISNUMBER(C24),ISNUMBER(C29)),(C24+C29)*C16/100*1.1,""))) | D30: =IF(ISNUMBER(C30),C30*$C$10,"") | E30: 人民币 | F30: CIF 已含 → 0；费率按 110% 投保额
B31: 到岸成本合计（CIF 等值） | C31: =IF(COUNT(C24,C26,C27,C28,C29,C30)=6,SUM(C24,C26,C27,C28,C29,C30),"") | D31: =IF(ISNUMBER(C31),C31*$C$10,"") | E31: 人民币 | F31: 货值+包装+起运港+出口侧+海运+保险（原币与人民币两列）
B32: ④ 第二层：进口税费（关税不可抵扣；增值税分现金/可抵扣两栏）
B33: 关税税率（实征，从税则查询录入） | C33: 0.055 | F33: 来源与核验日期见【数据来源】页
B34: 反倾销/反补贴税率 | C34: 0 | F34: 核验后填写；未查到填 0 并注明（≠不存在）
B35: 进口环节增值税率 | C35: 0.13 | F35: 一般货物 13%
B36: 增值税是否可抵扣（是/否） | C36: 是 | F36: 一般纳税人且用于应税项目=是
B37: 其中：计入计税价格的保险费 | C37: =IF(C18=TRUE,0,IF(ISNUMBER(C30),C30,IF(AND(ISNUMBER(C24),ISNUMBER(C29)),((C24)+IF(C9=TRUE,0,IF(ISNUMBER(C19),C19,0))+IF(C22,0,IF(ISNUMBER(C13),C13,0))+IF(C22,0,IF(ISNUMBER(C12),C12,0))+C29)*0.003/0.997,""))) | F37: 未投保时按（货价+运费）×0.3‰（第36条）
B38: 关税计税价格（人民币，完税价格） | C38: =IF(AND(ISNUMBER(C24),ISNUMBER(C11),ISNUMBER(C26),ISNUMBER(C28),ISNUMBER(C29),ISNUMBER(C30),ISNUMBER(C37)),(C24+C26+IF(ISNUMBER(C27),C27,0)+C28+C29+IF(C18,0,C37))*C11,"") | F38: ＝(货值+包装+起运港+出口侧+海运+实际保险+应计保险)×海关计征汇率
B39: 应纳关税 | C39: =IF(AND(ISNUMBER(C38),ISNUMBER(C33)),C38*C33,"") | F39: ＝计税价格×实征税率（不可抵扣，一定进成本）
B40: 反倾销/反补贴税 | C40: =IF(AND(ISNUMBER(C38),ISNUMBER(C34)),C38*C34,"") | F40: ＝计税价格×措施税率
...

Sheet 口径对照
B1: FOB / CFR / CIF 三口径对照
B2: 经济实质相同时（FOB 640 + 运费 45 + 保费），三口径到厂成本应基本一致；差异只来自卖方对运费/保险的加价。
B4: 指标 | C4: FOB 朱拜勒 | D4: CFR 宁波 | E4: CIF 宁波 | F4: CFR−FOB | G4: CIF−FOB
B5: 报价（原币/吨） | C5: ='FOB'!C6 | D5: ='CFR'!C6 | E5: ='CIF'!C6 | F5: =IF(AND(ISNUMBER(C5),ISNUMBER(D5)),D5-C5,"") | G5: =IF(AND(ISNUMBER(C5),ISNUMBER(E5)),E5-C5,"")
B6: 到岸成本 元/吨 | C6: ='FOB'!C63 | D6: ='CFR'!C63 | E6: ='CIF'!C63 | F6: =IF(AND(ISNUMBER(C6),ISNUMBER(D6)),D6-C6,"") | G6: =IF(AND(ISNUMBER(C6),ISNUMBER(E6)),E6-C6,"")
B7: 关税计税价格（元） | C7: ='FOB'!C38 | D7: ='CFR'!C38 | E7: ='CIF'!C38 | F7: =IF(AND(ISNUMBER(C7),ISNUMBER(D7)),D7-C7,"") | G7: =IF(AND(ISNUMBER(C7),ISNUMBER(E7)),E7-C7,"")
B8: 应纳关税（元） | C8: ='FOB'!C39 | D8: ='CFR'!C39 | E8: ='CIF'!C39 | F8: =IF(AND(ISNUMBER(C8),ISNUMBER(D8)),D8-C8,"") | G8: =IF(AND(ISNUMBER(C8),ISNUMBER(E8)),E8-C8,"")
B9: 增值税（元，现金） | C9: ='FOB'!C42 | D9: ='CFR'!C42 | E9: ='CIF'!C42 | F9: =IF(AND(ISNUMBER(C9),ISNUMBER(D9)),D9-C9,"") | G9: =IF(AND(ISNUMBER(C9),ISNUMBER(E9)),E9-C9,"")
B10: 可抵扣进项（元） | C10: ='FOB'!C43 | D10: ='CFR'!C43 | E10: ='CIF'!C43 | F10: =IF(AND(ISNUMBER(C10),ISNUMBER(D10)),D10-C10,"") | G10: =IF(AND(ISNUMBER(C10),ISNUMBER(E10)),E10-C10,"")
B11: 整票现金支出（元） | C11: ='FOB'!C58 | D11: ='CFR'!C58 | E11: ='CIF'!C58 | F11: =IF(AND(ISNUMBER(C11),ISNUMBER(D11)),D11-C11,"") | G11: =IF(AND(ISNUMBER(C11),ISNUMBER(E11)),E11-C11,"")
B12: 最终经济成本（元） | C12: ='FOB'!C60 | D12: ='CFR'!C60 | E12: ='CIF'!C60 | F12: =IF(AND(ISNUMBER(C12),ISNUMBER(D12)),D12-C12,"") | G12: =IF(AND(ISNUMBER(C12),ISNUMBER(E12)),E12-C12,"")
B13: 最终经济成本 元/吨 | C13: ='FOB'!C61 | D13: ='CFR'!C61 | E13: ='CIF'!C61 | F13: =IF(AND(ISNUMBER(C13),ISNUMBER(D13)),D13-C13,"") | G13: =IF(AND(ISNUMBER(C13),ISNUMBER(E13)),E13-C13,"")
B14: 完整状态 | C14: ='FOB'!C64 | D14: ='CFR'!C64 | E14: ='CIF'!C64 | F14: =IF(AND(ISNUMBER(C14),ISNUMBER(D14)),D14-C14,"") | G14: =IF(AND(ISNUMBER(C14),ISNUMBER(E14)),E14-C14,"")
B16: 结论要点
B17: ① FOB 报价不含海运与保险，测算必须另加；CFR/CIF 已含海运费，绝不能再加一次。
B18: ② CIF 已含保险；买方另行加保的费用单列，不得与报价内保费重复。
B19: ③ 三口径到厂成本差异 = 卖方对运费/保险的加价 → 这是议价抓手。
B20: ④ 关税与增值税的计税价格都以 CIF 等值为基础：FOB 报价看着低，税费基数并不低。
B21: ⑤ 状态为「待补全」时，该口径的到厂价不可对外使用，只能用「已知成本小计」。

Sheet 敏感性分析
B1: 敏感性分析（基准 = FOB 页，全部由公式驱动）
B2: 每个情景独立复刻计算链：货值→CIF→关税计税价格→关税→增值税→现金支出→可抵扣→元/吨。未做线性近似。
B4: 基准（FOB 页） | C4: ='FOB'!C6 | D4: ='FOB'!C61 | E4: ='FOB'!C60 | G4: C=单价 / D=到厂 元吨 / E=整票
B6: ① 汇率 ±3%（市场汇率与海关计征汇率同向变动）
B7: 情景 | C7: 情景参数 | D7: 到厂成本 元/吨 | E7: Δ 元/吨 | F7: Δ % | G7: 说明
B9: 汇率 -3% | C9: -0.03 | D9: =IF(AND(ISNUMBER('FOB'!C6),ISNUMBER('FOB'!C7),ISNUMBER('FOB'!C10*(1+-0.03)),ISNUMBER(IF(ISNUMBER('FOB'!C11),'FOB'!C11*(1+-0.03),"")),ISNUMBER('FOB'!C33)),((IF(AND(ISNUMBER('FOB'!C6),ISNUMBER('FOB'!C7)),'FOB'!C6*'FOB'!C7,0)+IF('FOB'!C9=TRUE,0,IF(ISNUMBER('FOB'!C19),'FOB'!C19,0))+IF(ISNUMBER('FOB'!C13),IF('FOB'!C22,0,'FOB'!C13),0)+IF(ISNUMBER('FOB'!C12),IF('FOB'!C22,0,'FOB'!C12),0)+IF('FOB'!C20,0,IF(ISNUMBER('FOB'!C14),'FOB'!C14*'FOB'!C7,0))+IF('FOB'!C18,0,IF(ISNUMBER('FOB'!C17),'FOB'!C17,IF(ISNUMBER('FOB'!C16),(IF(AND(ISNUMBER('FOB'!C6),ISNUMBER('FOB'!C7)),'FOB'!C6*'FOB'!C7,0)+IF('FOB'!C20,0,IF(ISNUMBER('FOB'!C14),'FOB'!C14*'FOB'!C7,0)))*'FOB'!C16/100*1.1,(IF(AND(ISNUMBER('FOB'!C6),ISNUMBER('FOB'!C7)),'FOB'!C6*'FOB'!C7,0)+IF('FOB'!C9=TRUE,0,IF(ISNUMBER('FOB'!C19),'FOB'!C19,0))+IF(ISNUMBER('FOB'!C13),IF('FOB'!C22,0,'FOB'!C13),0)+IF(ISNUMBER('FOB'!C12),IF('FOB'!C22,0,'FOB'!C12),0)+IF('FOB'!C20,0,IF(ISNUMBER('FOB'!C14),'FOB'!C14*'FOB'!C7,0)))*0.003/0.997))))*IF(ISNUMBER('FOB'!C10*(1+-0.03)),'FOB'!C10*(1+-0.03),0)+IF(ISNUMBER(IF(ISNUMBER('FOB'!C11),'FOB'!C11*(1+-0.03),"")),(IF(AND(ISNUMBER('FOB'!C6),ISNUMBER('FOB'!C7)),'FOB'!C6*'FOB'!C7,0)+IF('FOB'!C9=TRUE,0,IF(ISNUMBER('FOB'!C19),'FOB'!C19,0))+IF(ISNUMBER('FOB'!C13),IF('FOB'!C22,0,'FOB'!C13),0)+IF(ISNUMBER('FOB'!C12),IF('FOB'!C22,0,'FOB'!C12),0)+IF('FOB'!C20,0,IF(ISNUMBER('FOB'!C14),'FOB'!C14*'FOB'!C7,0))+IF('FOB'!C18,0,IF(ISNUMBER('FOB'!C17),'FOB'!C17,IF(ISNUMBER('FOB'!C16),(IF(AND(ISNUMBER('FOB'!C6),ISNUMBER('FOB'!C7)),'FOB'!C6*'FOB'!C7,0)+IF('FOB'!C20,0,IF(ISNUMBER('FOB'!C14),'FOB'!C14*'FOB'!C7,0)))*'FOB'!C16/100*1.1,(IF(AND(ISNUMBER('FOB'!C6),ISNUMBER('FOB'!C7)),'FOB'!C6*'FOB'!C7,0)+IF('FOB'!C9=TRUE,0,IF(ISNUMBER('FOB'!C19),'FOB'!C19,0))+IF(ISNUMBER('FOB'!C13),IF('FOB'!C22,0,'FOB'!C13),0)+IF(ISNUMBER('FOB'!C12),IF('FOB'!C22,0,'FOB'!C12),0)+IF('FOB'!C20,0,IF(ISNUMBER('FOB'!C14),'FOB'!C14*'FOB'!C7,0)))*0.003/0.997))))*IF(ISNUMBER('FOB'!C11),'FOB'!C11*(1+-0.03),""),0)*IF(ISNUMBER('FOB'!C33),'FOB'!C33,0)*(1+IF(ISNUMBER('FOB'!C34),'FOB'!C34,0))+(IF(ISNUMBER(IF(ISNUMBER('FOB'!C11),'FOB'!C11*(1+-0.03),"")),(IF(AND(ISNUMBER('FOB'!C6),ISNUMBER('FOB'!C7)),'FOB'!C6*'FOB'!C7,0)+IF('FOB'!C9=TRUE,0,IF(ISNUMBER('FOB'!C19),'FOB'!C19,0))+IF(ISNUMBER('FOB'!C13),IF('FOB'!C22,0,'FOB'!C13),0)+IF(ISNUMBER('FOB'!C12),IF('FOB'!C22,0,'FOB'!C12),0)+IF('FOB'!C20,0,IF(ISNUMBER('FOB'!C14),'FOB'!C14*'FOB'!C7,0))+IF('FOB'!C18,0,IF(ISNUMBER('FOB'!C17),'FOB'!C17,IF(ISNUMBER('FOB'!C16),(IF(AND(ISNUMBER('FOB'!C6),ISNUMBER('FOB'!C7)),'FOB'!C6*'FOB'!C7,0)+IF('FOB'!C20,0,IF(ISNUMBER('FOB'!C14),'FOB'!C14*'FOB'!C7,0)))*'FOB'!C16/100*1.1,(IF(AND(ISNUMBER('FOB'!C6),ISNUMBER('FOB'!C7)),'FOB'!C6*'FOB'!C7,0)+IF('FOB'!C9=TRUE,0,IF(ISNUMBER('FOB'!C19),'FOB'!C19,0))+IF(ISNUMBER('FOB'!C13),IF('FOB'!C22,0,'FOB'!C13),0)+IF(ISNUMBER('FOB'!C12),IF('FOB'!C22,0,'FOB'!C12),0)+IF('FOB'!C20,0,IF(ISNUMBER('FOB'!C14),'FOB'!C14*'FOB'!C7,0)))*0.003/0.997))))*IF(ISNUMBER('FOB'!C11),'FOB'!C11*(1+-0.03),""),0)+IF(ISNUMBER(IF(ISNUMBER('FOB'!C11),'FOB'!C11*(1+-0.03),"")),(IF(AND(ISNUMBER('FOB'!C6),ISNUMBER('FOB'!C7)),'FOB'!C6*'FOB'!C7,0)+IF('FOB'!C9=TRUE,0,IF(ISNUMBER('FOB'!C19),'FOB'!C19,0))+IF(ISNUMBER('FOB'!C13),IF('FOB'!C22,0,'FOB'!C13),0)+IF(ISNUMBER('FOB'!C12),IF('FOB'!C22,0,'FOB'!C12),0)+IF('FOB'!C20,0,IF(ISNUMBER('FOB'!C14),'FOB'!C14*'FOB'!C7,0))+IF('FOB'!C18,0,IF(ISNUMBER('FOB'!C17),'FOB'!C17,IF(ISNUMBER('FOB'!C16),(IF(AND(ISNUMBER('FOB'!C6),ISNUMBER('FOB'!C7)),'FOB'!C6*'FOB'!C7,0)+IF('FOB'!C20,0,IF(ISNUMBER('FOB'!C14),'FOB'!C14*'FOB'!C7,0)))*'FOB'!C16/100*1.1,(IF(AND(ISNUMBER('FOB'!C6),ISNUMBER('FOB'!C7)),'FOB'!C6*'FOB'!C7,0)+IF('FOB'!C9=TRUE,0,IF(ISNUMBER('FOB'!C19),'FOB'!C19,0))+IF(ISNUMBER('FOB'!C13),IF('FOB'!C22,0,'FOB'!C13),0)+IF(ISNUMBER('FOB'!C12),IF('FOB'!C22,0,'FOB'!C12),0)+IF('FOB'!C20,0,IF(ISNUMBER('FOB'!C14),'FOB'!C14*'FOB'!C7,0)))*0.003/0.997))))*IF(ISNUMBER('FOB'!C11),'FOB'!C11*(1+-0.03),""),0)*IF(ISNUMBER('FOB'!C33),'FOB'!C33,0)*(1+IF(ISNUMBER('FOB'!C34),'FOB'!C34,0)))*IF(ISNUMBER('FOB'!C35),'FOB'!C35,0)+(IF(ISNUMBER('FOB'!C46),'FOB'!C46,0)+IF(ISNUMBER('FOB'!C47),'FOB'!C47,0)+IF(ISNUMBER('FOB'!C48),'FOB'!C48,0)+IF(ISNUMBER('FOB'!C49),'FOB'!C49,0)+IF(ISNUMBER('FOB'!C50),'FOB'!C50,0)+IF(ISNUMBER('FOB'!C51),'FOB'!C51,0))-IF(LEFT('FOB'!C36,1)="是",(IF(ISNUMBER(IF(ISNUMBER('FOB'!C11),'FOB'!C11*(1+-0.03),"")),(IF(AND(ISNUMBER('FOB'!C6),ISNUMBER('FOB'!C7)),'FOB'!C6*'FOB'!C7,0)+IF('FOB'!C9=TRUE,0,IF(ISNUMBER('FOB'!C19),'FOB'!C19,0))+IF(ISNUMBER('FOB'!C13),IF('FOB'!C22,0,'FOB'!C13),0)+IF(ISNUMBER('FOB'!C12),IF('FOB'!C22,0,'FOB'!C12),0)+IF('FOB'!C20,0,IF(ISNUMBER('FOB'!C14),'FOB'!C14*'FOB'!C7,0))+IF('FOB'!C18,0,IF(ISNUMBER('FOB'!C17),'FOB'!C17,IF(ISNUMBER('FOB'!C16),(IF(AND(ISNUMBER('FOB'!C6),ISNUMBER('FOB'!C7)),'FOB'!C6*'FOB'!C7,0)+IF('FOB'!C20,0,IF(ISNUMBER('FOB'!C14),'FOB'!C14*'FOB'!C7,0)))*'FOB'!C16/100*1.1,(IF(AND(ISNUMBER('FOB'!C6),ISNUMBER('FOB'!C7)),'FOB'!C6*'FOB'!C7,0)+IF('FOB'!C9=TRUE,0,IF(ISNUMBER('FOB'!C19),'FOB'!C19,0))+IF(ISNUMBER('FOB'!C13),IF('FOB'!C22,0,'FOB'!C13),0)+IF(ISNUMBER('FOB'!C12),IF('FOB'!C22,0,'FOB'!C12),0)+IF('FOB'!C20,0,IF(ISNUMBER('FOB'!C14),'FOB'!C14*'FOB'!C7,0)))*0.003/0.997))))*IF(ISNUMBER('FOB'!C11),'FOB'!C11*(1+-0.03),""),0)+IF(ISNUMBER(IF(ISNUMBER('FOB'!C11),'FOB'!C11*(1+-0.03),"")),(IF(AND(ISNUMBER('FOB'!C6),ISNUMBER('FOB'!C7)),'FOB'!C6*'FOB'!C7,0)+IF('FOB'!C9=TRUE,0,IF(ISNUMBER('FOB'!C19),'FOB'!C19,0))+IF(ISNUMBER('FOB'!C13),IF('FOB'!C22,0,'FOB'!C13),0)+IF(ISNUMBER('FOB'!C12),IF('FOB'!C22,0,'FOB'!C12),0)+IF('FOB'!C20,0,IF(ISNUMBER('FOB'!C14),'FOB'!C14*'FOB'!C7,0))+IF('FOB'!C18,0,IF(ISNUMBER('FOB'!C17),'FOB'!C17,IF(ISNUMBER('FOB'!C16),(IF(AND(ISNUMBER('FOB'!C6),ISNUMBER('FOB'!C7)),'FOB'!C6*'FOB'!C7,0)+IF('FOB'!C20,0,IF(ISNUMBER('FOB'!C14),'FOB'!C14*'FOB'!C7,0)))*'FOB'!C16/100*1.1,(IF(AND(ISNUMBER('FOB'!C6),ISNUMBER('FOB'!C7)),'FOB'!C6*'FOB'!C7,0)+IF('FOB'!C9=TRUE,0,IF(ISNUMBER('FOB'!C19),'FOB'!C19,0))+IF(ISNUMBER('FOB'!C13),IF('FOB'!C22,0,'FOB'!C13),0)+IF(ISNUMBER('FOB'!C12),IF('FOB'!C22,0,'FOB'!C12),0)+IF('FOB'!C20,0,IF(ISNUMBER('FOB'!C14),'FOB'!C14*'FOB'!C7,0)))*0.003/0.997))))*IF(ISNUMBER('FOB'!C11),'FOB'!C11*(1+-0.03),""),0)*IF(ISNUMBER('FOB'!C33),'FOB'!C33,0)*(1+IF(ISNUMBER('FOB'!C34),'FOB'!C34,0)))*IF(ISNUMBER('FOB'!C35),'FOB'!C35,0),0))/('FOB'!C7),"") | E9: =IF(AND(ISNUMBER(D9),ISNUMBER(D4)),D9-D4,"") | F9: =IF(AND(ISNUMBER(E9),ISNUMBER(D4)),E9/D4,"") | G9: 市场汇率影响现金，海关计征汇率影响税费基数
B10: 汇率 +0% | C10: 0 | D10: =IF(AND(ISNUMBER('FOB'!C6),ISNUMBER('FOB'!C7),ISNUMBER('FOB'!C10*(1+0.0)),ISNUMBER(IF(ISNUMBER('FOB'!C11),'FOB'!C11*(1+0.0),"")),ISNUMBER('FOB'!C33)),((IF(AND(ISNUMBER('FOB'!C6),ISNUMBER('FOB'!C7)),'FOB'!C6*'FOB'!C7,0)+IF('FOB'!C9=TRUE,0,IF(ISNUMBER('FOB'!C19),'FOB'!C19,0))+IF(ISNUMBER('FOB'!C13),IF('FOB'!C22,0,'FOB'!C13),0)+IF(ISNUMBER('FOB'!C12),IF('FOB'!C22,0,'FOB'!C12),0)+IF('FOB'!C20,0,IF(ISNUMBER('FOB'!C14),'FOB'!C14*'FOB'!C7,0))+IF('FOB'!C18,0,IF(ISNUMBER('FOB'!C17),'FOB'!C17,IF(ISNUMBER('FOB'!C16),(IF(AND(ISNUMBER('FOB'!C6),ISNUMBER('FOB'!C7)),'FOB'!C6*'FOB'!C7,0)+IF('FOB'!C20,0,IF(ISNUMBER('FOB'!C14),'FOB'!C14*'FOB'!C7,0)))*'FOB'!C16/100*1.1,(IF(AND(ISNUMBER('FOB'!C6),ISNUMBER('FOB'!C7)),'FOB'!C6*'FOB'!C7,0)+IF('FOB'!C9=TRUE,0,IF(ISNUMBER('FOB'!C19),'FOB'!C19,0))+IF(ISNUMBER('FOB'!C13),IF('FOB'!C22,0,'FOB'!C13),0)+IF(ISNUMBER('FOB'!C12),IF('FOB'!C22,0,'FOB'!C12),0)+IF('FOB'!C20,0,IF(ISNUMBER('FOB'!C14),'FOB'!C14*'FOB'!C7,0)))*0.003/0.997))))*IF(ISNUMBER('FOB'!C10*(1+0.0)),'FOB'!C10*(1+0.0),0)+IF(ISNUMBER(IF(ISNUMBER('FOB'!C11),'FOB'!C11*(1+0.0),"")),(IF(AND(ISNUMBER('FOB'!C6),ISNUMBER('FOB'!C7)),'FOB'!C6*'FOB'!C7,0)+IF('FOB'!C9=TRUE,0,IF(ISNUMBER('FOB'!C19),'FOB'!C19,0))+IF(ISNUMBER('FOB'!C13),IF('FOB'!C22,0,'FOB'!C13),0)+IF(ISNUMBER('FOB'!C12),IF('FOB'!C22,0,'FOB'!C12),0)+IF('FOB'!C20,0,IF(ISNUMBER('FOB'!C14),'FOB'!C14*'FOB'!C7,0))+IF('FOB'!C18,0,IF(ISNUMBER('FOB'!C17),'FOB'!C17,IF(ISNUMBER('FOB'!C16),(IF(AND(ISNUMBER('FOB'!C6),ISNUMBER('FOB'!C7)),'FOB'!C6*'FOB'!C7,0)+IF('FOB'!C20,0,IF(ISNUMBER('FOB'!C14),'FOB'!C14*'FOB'!C7,0)))*'FOB'!C16/100*1.1,(IF(AND(ISNUMBER('FOB'!C6),ISNUMBER('FOB'!C7)),'FOB'!C6*'FOB'!C7,0)+IF('FOB'!C9=TRUE,0,IF(ISNUMBER('FOB'!C19),'FOB'!C19,0))+IF(ISNUMBER('FOB'!C13),IF('FOB'!C22,0,'FOB'!C13),0)+IF(ISNUMBER('FOB'!C12),IF('FOB'!C22,0,'FOB'!C12),0)+IF('FOB'!C20,0,IF(ISNUMBER('FOB'!C14),'FOB'!C14*'FOB'!C7,0)))*0.003/0.997))))*IF(ISNUMBER('FOB'!C11),'FOB'!C11*(1+0.0),""),0)*IF(ISNUMBER('FOB'!C33),'FOB'!C33,0)*(1+IF(ISNUMBER('FOB'!C34),'FOB'!C34,0))+(IF(ISNUMBER(IF(ISNUMBER('FOB'!C11),'FOB'!C11*(1+0.0),"")),(IF(AND(ISNUMBER('FOB'!C6),ISNUMBER('FOB'!C7)),'FOB'!C6*'FOB'!C7,0)+IF('FOB'!C9=TRUE,0,IF(ISNUMBER('FOB'!C19),'FOB'!C19,0))+IF(ISNUMBER('FOB'!C13),IF('FOB'!C22,0,'FOB'!C13),0)+IF(ISNUMBER('FOB'!C12),IF('FOB'!C22,0,'FOB'!C12),0)+IF('FOB'!C20,0,IF(ISNUMBER('FOB'!C14),'FOB'!C14*'FOB'!C7,0))+IF('FOB'!C18,0,IF(ISNUMBER('FOB'!C17),'FOB'!C17,IF(ISNUMBER('FOB'!C16),(IF(AND(ISNUMBER('FOB'!C6),ISNUMBER('FOB'!C7)),'FOB'!C6*'FOB'!C7,0)+IF('FOB'!C20,0,IF(ISNUMBER('FOB'!C14),'FOB'!C14*'FOB'!C7,0)))*'FOB'!C16/100*1.1,(IF(AND(ISNUMBER('FOB'!C6),ISNUMBER('FOB'!C7)),'FOB'!C6*'FOB'!C7,0)+IF('FOB'!C9=TRUE,0,IF(ISNUMBER('FOB'!C19),'FOB'!C19,0))+IF(ISNUMBER('FOB'!C13),IF('FOB'!C22,0,'FOB'!C13),0)+IF(ISNUMBER('FOB'!C12),IF('FOB'!C22,0,'FOB'!C12),0)+IF('FOB'!C20,0,IF(ISNUMBER('FOB'!C14),'FOB'!C14*'FOB'!C7,0)))*0.003/0.997))))*IF(ISNUMBER('FOB'!C11),'FOB'!C11*(1+0.0),""),0)+IF(ISNUMBER(IF(ISNUMBER('FOB'!C11),'FOB'!C11*(1+0.0),"")),(IF(AND(ISNUMBER('FOB'!C6),ISNUMBER('FOB'!C7)),'FOB'!C6*'FOB'!C7,0)+IF('FOB'!C9=TRUE,0,IF(ISNUMBER('FOB'!C19),'FOB'!C19,0))+IF(ISNUMBER('FOB'!C13),IF('FOB'!C22,0,'FOB'!C13),0)+IF(ISNUMBER('FOB'!C12),IF('FOB'!C22,0,'FOB'!C12),0)+IF('FOB'!C20,0,IF(ISNUMBER('FOB'!C14),'FOB'!C14*'FOB'!C7,0))+IF('FOB'!C18,0,IF(ISNUMBER('FOB'!C17),'FOB'!C17,IF(ISNUMBER('FOB'!C16),(IF(AND(ISNUMBER('FOB'!C6),ISNUMBER('FOB'!C7)),'FOB'!C6*'FOB'!C7,0)+IF('FOB'!C20,0,IF(ISNUMBER('FOB'!C14),'FOB'!C14*'FOB'!C7,0)))*'FOB'!C16/100*1.1,(IF(AND(ISNUMBER('FOB'!C6),ISNUMBER('FOB'!C7)),'FOB'!C6*'FOB'!C7,0)+IF('FOB'!C9=TRUE,0,IF(ISNUMBER('FOB'!C19),'FOB'!C19,0))+IF(ISNUMBER('FOB'!C13),IF('FOB'!C22,0,'FOB'!C13),0)+IF(ISNUMBER('FOB'!C12),IF('FOB'!C22,0,'FOB'!C12),0)+IF('FOB'!C20,0,IF(ISNUMBER('FOB'!C14),'FOB'!C14*'FOB'!C7,0)))*0.003/0.997))))*IF(ISNUMBER('FOB'!C11),'FOB'!C11*(1+0.0),""),0)*IF(ISNUMBER('FOB'!C33),'FOB'!C33,0)*(1+IF(ISNUMBER('FOB'!C34),'FOB'!C34,0)))*IF(ISNUMBER('FOB'!C35),'FOB'!C35,0)+(IF(ISNUMBER('FOB'!C46),'FOB'!C46,0)+IF(ISNUMBER('FOB'!C47),'FOB'!C47,0)+IF(ISNUMBER('FOB'!C48),'FOB'!C48,0)+IF(ISNUMBER('FOB'!C49),'FOB'!C49,0)+IF(ISNUMBER('FOB'!C50),'FOB'!C50,0)+IF(ISNUMBER('FOB'!C51),'FOB'!C51,0))-IF(LEFT('FOB'!C36,1)="是",(IF(ISNUMBER(IF(ISNUMBER('FOB'!C11),'FOB'!C11*(1+0.0),"")),(IF(AND(ISNUMBER('FOB'!C6),ISNUMBER('FOB'!C7)),'FOB'!C6*'FOB'!C7,0)+IF('FOB'!C9=TRUE,0,IF(ISNUMBER('FOB'!C19),'FOB'!C19,0))+IF(ISNUMBER('FOB'!C13),IF('FOB'!C22,0,'FOB'!C13),0)+IF(ISNUMBER('FOB'!C12),IF('FOB'!C22,0,'FOB'!C12),0)+IF('FOB'!C20,0,IF(ISNUMBER('FOB'!C14),'FOB'!C14*'FOB'!C7,0))+IF('FOB'!C18,0,IF(ISNUMBER('FOB'!C17),'FOB'!C17,IF(ISNUMBER('FOB'!C16),(IF(AND(ISNUMBER('FOB'!C6),ISNUMBER('FOB'!C7)),'FOB'!C6*'FOB'!C7,0)+IF('FOB'!C20,0,IF(ISNUMBER('FOB'!C14),'FOB'!C14*'FOB'!C7,0)))*'FOB'!C16/100*1.1,(IF(AND(ISNUMBER('FOB'!C6),ISNUMBER('FOB'!C7)),'FOB'!C6*'FOB'!C7,0)+IF('FOB'!C9=TRUE,0,IF(ISNUMBER('FOB'!C19),'FOB'!C19,0))+IF(ISNUMBER('FOB'!C13),IF('FOB'!C22,0,'FOB'!C13),0)+IF(ISNUMBER('FOB'!C12),IF('FOB'!C22,0,'FOB'!C12),0)+IF('FOB'!C20,0,IF(ISNUMBER('FOB'!C14),'FOB'!C14*'FOB'!C7,0)))*0.003/0.997))))*IF(ISNUMBER('FOB'!C11),'FOB'!C11*(1+0.0),""),0)+IF(ISNUMBER(IF(ISNUMBER('FOB'!C11),'FOB'!C11*(1+0.0),"")),(IF(AND(ISNUMBER('FOB'!C6),ISNUMBER('FOB'!C7)),'FOB'!C6*'FOB'!C7,0)+IF('FOB'!C9=TRUE,0,IF(ISNUMBER('FOB'!C19),'FOB'!C19,0))+IF(ISNUMBER('FOB'!C13),IF('FOB'!C22,0,'FOB'!C13),0)+IF(ISNUMBER('FOB'!C12),IF('FOB'!C22,0,'FOB'!C12),0)+IF('FOB'!C20,0,IF(ISNUMBER('FOB'!C14),'FOB'!C14*'FOB'!C7,0))+IF('FOB'!C18,0,IF(ISNUMBER('FOB'!C17),'FOB'!C17,IF(ISNUMBER('FOB'!C16),(IF(AND(ISNUMBER('FOB'!C6),ISNUMBER('FOB'!C7)),'FOB'!C6*'FOB'!C7,0)+IF('FOB'!C20,0,IF(ISNUMBER('FOB'!C14),'FOB'!C14*'FOB'!C7,0)))*'FOB'!C16/100*1.1,(IF(AND(ISNUMBER('FOB'!C6),ISNUMBER('FOB'!C7)),'FOB'!C6*'FOB'!C7,0)+IF('FOB'!C9=TRUE,0,IF(ISNUMBER('FOB'!C19),'FOB'!C19,0))+IF(ISNUMBER('FOB'!C13),IF('FOB'!C22,0,'FOB'!C13),0)+IF(ISNUMBER('FOB'!C12),IF('FOB'!C22,0,'FOB'!C12),0)+IF('FOB'!C20,0,IF(ISNUMBER('FOB'!C14),'FOB'!C14*'FOB'!C7,0)))*0.003/0.997))))*IF(ISNUMBER('FOB'!C11),'FOB'!C11*(1+0.0),""),0)*IF(ISNUMBER('FOB'!C33),'FOB'!C33,0)*(1+IF(ISNUMBER('FOB'!C34),'FOB'!C34,0)))*IF(ISNUMBER('FOB'!C35),'FOB'!C35,0),0))/('FOB'!C7),"") | E10: =IF(AND(ISNUMBER(D10),ISNUMBER(D4)),D10-D4,"") | F10: =IF(AND(ISNUMBER(E10),ISNUMBER(D4)),E10/D4,"")
B11: 汇率 +3% | C11: 0.03 | D11: =IF(AND(ISNUMBER('FOB'!C6),ISNUMBER('FOB'!C7),ISNUMBER('FOB'!C10*(1+0.03)),ISNUMBER(IF(ISNUMBER('FOB'!C11),'FOB'!C11*(1+0.03),"")),ISNUMBER('FOB'!C33)),((IF(AND(ISNUMBER('FOB'!C6),ISNUMBER('FOB'!C7)),'FOB'!C6*'FOB'!C7,0)+IF('FOB'!C9=TRUE,0,IF(ISNUMBER('FOB'!C19),'FOB'!C19,0))+IF(ISNUMBER('FOB'!C13),IF('FOB'!C22,0,'FOB'!C13),0)+IF(ISNUMBER('FOB'!C12),IF('FOB'!C22,0,'FOB'!C12),0)+IF('FOB'!C20,0,IF(ISNUMBER('FOB'!C14),'FOB'!C14*'FOB'!C7,0))+IF('FOB'!C18,0,IF(ISNUMBER('FOB'!C17),'FOB'!C17,IF(ISNUMBER('FOB'!C16),(IF(AND(ISNUMBER('FOB'!C6),ISNUMBER('FOB'!C7)),'FOB'!C6*'FOB'!C7,0)+IF('FOB'!C20,0,IF(ISNUMBER('FOB'!C14),'FOB'!C14*'FOB'!C7,0)))*'FOB'!C16/100*1.1,(IF(AND(ISNUMBER('FOB'!C6),ISNUMBER('FOB'!C7)),'FOB'!C6*'FOB'!C7,0)+IF('FOB'!C9=TRUE,0,IF(ISNUMBER('FOB'!C19),'FOB'!C19,0))+IF(ISNUMBER('FOB'!C13),IF('FOB'!C22,0,'FOB'!C13),0)+IF(ISNUMBER('FOB'!C12),IF('FOB'!C22,0,'FOB'!C12),0)+IF('FOB'!C20,0,IF(ISNUMBER('FOB'!C14),'FOB'!C14*'FOB'!C7,0)))*0.003/0.997))))*IF(ISNUMBER('FOB'!C10*(1+0.03)),'FOB'!C10*(1+0.03),0)+IF(ISNUMBER(IF(ISNUMBER('FOB'!C11),'FOB'!C11*(1+0.03),"")),(IF(AND(ISNUMBER('FOB'!C6),ISNUMBER('FOB'!C7)),'FOB'!C6*'FOB'!C7,0)+IF('FOB'!C9=TRUE,0,IF(ISNUMBER('FOB'!C19),'FOB'!C19,0))+IF(ISNUMBER('FOB'!C13),IF('FOB'!C22,0,'FOB'!C13),0)+IF(ISNUMBER('FOB'!C12),IF('FOB'!C22,0,'FOB'!C12),0)+IF('FOB'!C20,0,IF(ISNUMBER('FOB'!C14),'FOB'!C14*'FOB'!C7,0))+IF('FOB'!C18,0,IF(ISNUMBER('FOB'!C17),'FOB'!C17,IF(ISNUMBER('FOB'!C16),(IF(AND(ISNUMBER('FOB'!C6),ISNUMBER('FOB'!C7)),'FOB'!C6*'FOB'!C7,0)+IF('FOB'!C20,0,IF(ISNUMBER('FOB'!C14),'FOB'!C14*'FOB'!C7,0)))*'FOB'!C16/100*1.1,(IF(AND(ISNUMBER('FOB'!C6),ISNUMBER('FOB'!C7)),'FOB'!C6*'FOB'!C7,0)+IF('FOB'!C9=TRUE,0,IF(ISNUMBER('FOB'!C19),'FOB'!C19,0))+IF(ISNUMBER('FOB'!C13),IF('FOB'!C22,0,'FOB'!C13),0)+IF(ISNUMBER('FOB'!C12),IF('FOB'!C22,0,'FOB'!C12),0)+IF('FOB'!C20,0,IF(ISNUMBER('FOB'!C14),'FOB'!C14*'FOB'!C7,0)))*0.003/0.997))))*IF(ISNUMBER('FOB'!C11),'FOB'!C11*(1+0.03),""),0)*IF(ISNUMBER('FOB'!C33),'FOB'!C33,0)*(1+IF(ISNUMBER('FOB'!C34),'FOB'!C34,0))+(IF(ISNUMBER(IF(ISNUMBER('FOB'!C11),'FOB'!C11*(1+0.03),"")),(IF(AND(ISNUMBER('FOB'!C6),ISNUMBER('FOB'!C7)),'FOB'!C6*'FOB'!C7,0)+IF('FOB'!C9=TRUE,0,IF(ISNUMBER('FOB'!C19),'FOB'!C19,0))+IF(ISNUMBER('FOB'!C13),IF('FOB'!C22,0,'FOB'!C13),0)+IF(ISNUMBER('FOB'!C12),IF('FOB'!C22,0,'FOB'!C12),0)+IF('FOB'!C20,0,IF(ISNUMBER('FOB'!C14),'FOB'!C14*'FOB'!C7,0))+IF('FOB'!C18,0,IF(ISNUMBER('FOB'!C17),'FOB'!C17,IF(ISNUMBER('FOB'!C16),(IF(AND(ISNUMBER('FOB'!C6),ISNUMBER('FOB'!C7)),'FOB'!C6*'FOB'!C7,0)+IF('FOB'!C20,0,IF(ISNUMBER('FOB'!C14),'FOB'!C14*'FOB'!C7,0)))*'FOB'!C16/100*1.1,(IF(AND(ISNUMBER('FOB'!C6),ISNUMBER('FOB'!C7)),'FOB'!C6*'FOB'!C7,0)+IF('FOB'!C9=TRUE,0,IF(ISNUMBER('FOB'!C19),'FOB'!C19,0))+IF(ISNUMBER('FOB'!C13),IF('FOB'!C22,0,'FOB'!C13),0)+IF(ISNUMBER('FOB'!C12),IF('FOB'!C22,0,'FOB'!C12),0)+IF('FOB'!C20,0,IF(ISNUMBER('FOB'!C14),'FOB'!C14*'FOB'!C7,0)))*0.003/0.997))))*IF(ISNUMBER('FOB'!C11),'FOB'!C11*(1+0.03),""),0)+IF(ISNUMBER(IF(ISNUMBER('FOB'!C11),'FOB'!C11*(1+0.03),"")),(IF(AND(ISNUMBER('FOB'!C6),ISNUMBER('FOB'!C7)),'FOB'!C6*'FOB'!C7,0)+IF('FOB'!C9=TRUE,0,IF(ISNUMBER('FOB'!C19),'FOB'!C19,0))+IF(ISNUMBER('FOB'!C13),IF('FOB'!C22,0,'FOB'!C13),0)+IF(ISNUMBER('FOB'!C12),IF('FOB'!C22,0,'FOB'!C12),0)+IF('FOB'!C20,0,IF(ISNUMBER('FOB'!C14),'FOB'!C14*'FOB'!C7,0))+IF('FOB'!C18,0,IF(ISNUMBER('FOB'!C17),'FOB'!C17,IF(ISNUMBER('FOB'!C16),(IF(AND(ISNUMBER('FOB'!C6),ISNUMBER('FOB'!C7)),'FOB'!C6*'FOB'!C7,0)+IF('FOB'!C20,0,IF(ISNUMBER('FOB'!C14),'FOB'!C14*'FOB'!C7,0)))*'FOB'!C16/100*1.1,(IF(AND(ISNUMBER('FOB'!C6),ISNUMBER('FOB'!C7)),'FOB'!C6*'FOB'!C7,0)+IF('FOB'!C9=TRUE,0,IF(ISNUMBER('FOB'!C19),'FOB'!C19,0))+IF(ISNUMBER('FOB'!C13),IF('FOB'!C22,0,'FOB'!C13),0)+IF(ISNUMBER('FOB'!C12),IF('FOB'!C22,0,'FOB'!C12),0)+IF('FOB'!C20,0,IF(ISNUMBER('FOB'!C14),'FOB'!C14*'FOB'!C7,0)))*0.003/0.997))))*IF(ISNUMBER('FOB'!C11),'FOB'!C11*(1+0.03),""),0)*IF(ISNUMBER('FOB'!C33),'FOB'!C33,0)*(1+IF(ISNUMBER('FOB'!C34),'FOB'!C34,0)))*IF(ISNUMBER('FOB'!C35),'FOB'!C35,0)+(IF(ISNUMBER('FOB'!C46),'FOB'!C46,0)+IF(ISNUMBER('FOB'!C47),'FOB'!C47,0)+IF(ISNUMBER('FOB'!C48),'FOB'!C48,0)+IF(ISNUMBER('FOB'!C49),'FOB'!C49,0)+IF(ISNUMBER('FOB'!C50),'FOB'!C50,0)+IF(ISNUMBER('FOB'!C51),'FOB'!C51,0))-IF(LEFT('FOB'!C36,1)="是",(IF(ISNUMBER(IF(ISNUMBER('FOB'!C11),'FOB'!C11*(1+0.03),"")),(IF(AND(ISNUMBER('FOB'!C6),ISNUMBER('FOB'!C7)),'FOB'!C6*'FOB'!C7,0)+IF('FOB'!C9=TRUE,0,IF(ISNUMBER('FOB'!C19),'FOB'!C19,0))+IF(ISNUMBER('FOB'!C13),IF('FOB'!C22,0,'FOB'!C13),0)+IF(ISNUMBER('FOB'!C12),IF('FOB'!C22,0,'FOB'!C12),0)+IF('FOB'!C20,0,IF(ISNUMBER('FOB'!C14),'FOB'!C14*'FOB'!C7,0))+IF('FOB'!C18,0,IF(ISNUMBER('FOB'!C17),'FOB'!C17,IF(ISNUMBER('FOB'!C16),(IF(AND(ISNUMBER('FOB'!C6),ISNUMBER('FOB'!C7)),'FOB'!C6*'FOB'!C7,0)+IF('FOB'!C20,0,IF(ISNUMBER('FOB'!C14),'FOB'!C14*'FOB'!C7,0)))*'FOB'!C16/100*1.1,(IF(AND(ISNUMBER('FOB'!C6),ISNUMBER('FOB'!C7)),'FOB'!C6*'FOB'!C7,0)+IF('FOB'!C9=TRUE,0,IF(ISNUMBER('FOB'!C19),'FOB'!C19,0))+IF(ISNUMBER('FOB'!C13),IF('FOB'!C22,0,'FOB'!C13),0)+IF(ISNUMBER('FOB'!C12),IF('FOB'!C22,0,'FOB'!C12),0)+IF('FOB'!C20,0,IF(ISNUMBER('FOB'!C14),'FOB'!C14*'FOB'!C7,0)))*0.003/0.997))))*IF(ISNUMBER('FOB'!C11),'FOB'!C11*(1+0.03),""),0)+IF(ISNUMBER(IF(ISNUMBER('FOB'!C11),'FOB'!C11*(1+0.03),"")),(IF(AND(ISNUMBER('FOB'!C6),ISNUMBER('FOB'!C7)),'FOB'!C6*'FOB'!C7,0)+IF('FOB'!C9=TRUE,0,IF(ISNUMBER('FOB'!C19),'FOB'!C19,0))+IF(ISNUMBER('FOB'!C13),IF('FOB'!C22,0,'FOB'!C13),0)+IF(ISNUMBER('FOB'!C12),IF('FOB'!C22,0,'FOB'!C12),0)+IF('FOB'!C20,0,IF(ISNUMBER('FOB'!C14),'FOB'!C14*'FOB'!C7,0))+IF('FOB'!C18,0,IF(ISNUMBER('FOB'!C17),'FOB'!C17,IF(ISNUMBER('FOB'!C16),(IF(AND(ISNUMBER('FOB'!C6),ISNUMBER('FOB'!C7)),'FOB'!C6*'FOB'!C7,0)+IF('FOB'!C20,0,IF(ISNUMBER('FOB'!C14),'FOB'!C14*'FOB'!C7,0)))*'FOB'!C16/100*1.1,(IF(AND(ISNUMBER('FOB'!C6),ISNUMBER('FOB'!C7)),'FOB'!C6*'FOB'!C7,0)+IF('FOB'!C9=TRUE,0,IF(ISNUMBER('FOB'!C19),'FOB'!C19,0))+IF(ISNUMBER('FOB'!C13),IF('FOB'!C22,0,'FOB'!C13),0)+IF(ISNUMBER('FOB'!C12),IF('FOB'!C22,0,'FOB'!C12),0)+IF('FOB'!C20,0,IF(ISNUMBER('FOB'!C14),'FOB'!C14*'FOB'!C7,0)))*0.003/0.997))))*IF(ISNUMBER('FOB'!C11),'FOB'!C11*(1+0.03),""),0)*IF(ISNUMBER('FOB'!C33),'FOB'!C33,0)*(1+IF(ISNUMBER('FOB'!C34),'FOB'!C34,0)))*IF(ISNUMBER('FOB'!C35),'FOB'!C35,0),0))/('FOB'!C7),"") | E11: =IF(AND(ISNUMBER(D11),ISNUMBER(D4)),D11-D4,"") | F11: =IF(AND(ISNUMBER(E11),ISNUMBER(D4)),E11/D4,"")
B12: ② 海运费变化（运费会被关税放大）
B13: 情景 | C13: 情景参数 | D13: 到厂成本 元/吨 | E13: Δ 元/吨 | F13: Δ % | G13: 说明
B15: 海运费 -20% | C15: 'FOB'!C14*(1+-0.2) | D15: =IF(AND(ISNUMBER('FOB'!C6),ISNUMBER('FOB'!C7),ISNUMBER('FOB'!C10),ISNUMBER('FOB'!C11),ISNUMBER('FOB'!C33)),((IF(AND(ISNUMBER('FOB'!C6),ISNUMBER('FOB'!C7)),'FOB'!C6*'FOB'!C7,0)+IF('FOB'!C9=TRUE,0,IF(ISNUMBER('FOB'!C19),'FOB'!C19,0))+IF(ISNUMBER('FOB'!C13),IF('FOB'!C22,0,'FOB'!C13),0)+IF(ISNUMBER('FOB'!C12),IF('FOB'!C22,0,'FOB'!C12),0)+IF('FOB'!C20,0,IF(ISNUMBER('FOB'!C14*(1+-0.2)),'FOB'!C14*(1+-0.2)*'FOB'!C7,0))+IF('FOB'!C18,0,IF(ISNUMBER('FOB'!C17),'FOB'!C17,IF(ISNUMBER('FOB'!C16),(IF(AND(ISNUMBER('FOB'!C6),ISNUMBER('FOB'!C7)),'FOB'!C6*'FOB'!C7,0)+IF('FOB'!C20,0,IF(ISNUMBER('FOB'!C14*(1+-0.2)),'FOB'!C14*(1+-0.2)*'FOB'!C7,0)))*'FOB'!C16/100*1.1,(IF(AND(ISNUMBER('FOB'!C6),ISNUMBER('FOB'!C7)),'FOB'!C6*'FOB'!C7,0)+IF('FOB'!C9=TRUE,0,IF(ISNUMBER('FOB'!C19),'FOB'!C19,0))+IF(ISNUMBER('FOB'!C13),IF('FOB'!C22,0,'FOB'!C13),0)+IF(ISNUMBER('FOB'!C12),IF('FOB'!C22,0,'FOB'!C12),0)+IF('FOB'!C20,0,IF(ISNUMBER('FOB'!C14*(1+-0.2)),'FOB'!C14*(1+-0.2)*'FOB'!C7,0)))*0.003/0.997))))*IF(ISNUMBER('FOB'!C10),'FOB'!C10,0)+IF(ISNUMBER('FOB'!C11),(IF(AND(ISNUMBER('FOB'!C6),ISNUMBER('FOB'!C7)),'FOB'!C6*'FOB'!C7,0)+IF('FOB'!C9=TRUE,0,IF(ISNUMBER('FOB'!C19),'FOB'!C19,0))+IF(ISNUMBER('FOB'!C13),IF('FOB'!C22,0,'FOB'!C13),0)+IF(ISNUMBER('FOB'!C12),IF('FOB'!C22,0,'FOB'!C12),0)+IF('FOB'!C20,0,IF(ISNUMBER('FOB'!C14*(1+-0.2)),'FOB'!C14*(1+-0.2)*'FOB'!C7,0))+IF('FOB'!C18,0,IF(ISNUMBER('FOB'!C17),'FOB'!C17,IF(ISNUMBER('FOB'!C16),(IF(AND(ISNUMBER('FOB'!C6),ISNUMBER('FOB'!C7)),'FOB'!C6*'FOB'!C7,0)+IF('FOB'!C20,0,IF(ISNUMBER('FOB'!C14*(1+-0.2)),'FOB'!C14*(1+-0.2)*'FOB'!C7,0)))*'FOB'!C16/100*1.1,(IF(AND(ISNUMBER('FOB'!C6),ISNUMBER('FOB'!C7)),'FOB'!C6*'FOB'!C7,0)+IF('FOB'!C9=TRUE,0,IF(ISNUMBER('FOB'!C19),'FOB'!C19,0))+IF(ISNUMBER('FOB'!C13),IF('FOB'!C22,0,'FOB'!C13),0)+IF(ISNUMBER('FOB'!C12),IF('FOB'!C22,0,'FOB'!C12),0)+IF('FOB'!C20,0,IF(ISNUMBER('FOB'!C14*(1+-0.2)),'FOB'!C14*(1+-0.2)*'FOB'!C7,0)))*0.003/0.997))))*'FOB'!C11,0)*IF(ISNUMBER('FOB'!C33),'FOB'!C33,0)*(1+IF(ISNUMBER('FOB'!C34),'FOB'!C34,0))+(IF(ISNUMBER('FOB'!C11),(IF(AND(ISNUMBER('FOB'!C6),ISNUMBER('FOB'!C7)),'FOB'!C6*'FOB'!C7,0)+IF('FOB'!C9=TRUE,0,IF(ISNUMBER('FOB'!C19),'FOB'!C19,0))+IF(ISNUMBER('FOB'!C13),IF('FOB'!C22,0,'FOB'!C13),0)+IF(ISNUMBER('FOB'!C12),IF('FOB'!C22,0,'FOB'!C12),0)+IF('FOB'!C20,0,IF(ISNUMBER('FOB'!C14*(1+-0.2)),'FOB'!C14*(1+-0.2)*'FOB'!C7,0))+IF('FOB'!C18,0,IF(ISNUMBER('FOB'!C17),'FOB'!C17,IF(ISNUMBER('FOB'!C16),(IF(AND(ISNUMBER('FOB'!C6),ISNUMBER('FOB'!C7)),'FOB'!C6*'FOB'!C7,0)+IF('FOB'!C20,0,IF(ISNUMBER('FOB'!C14*(1+-0.2)),'FOB'!C14*(1+-0.2)*'FOB'!C7,0)))*'FOB'!C16/100*1.1,(IF(AND(ISNUMBER('FOB'!C6),ISNUMBER('FOB'!C7)),'FOB'!C6*'FOB'!C7,0)+IF('FOB'!C9=TRUE,0,IF(ISNUMBER('FOB'!C19),'FOB'!C19,0))+IF(ISNUMBER('FOB'!C13),IF('FOB'!C22,0,'FOB'!C13),0)+IF(ISNUMBER('FOB'!C12),IF('FOB'!C22,0,'FOB'!C12),0)+IF('FOB'!C20,0,IF(ISNUMBER('FOB'!C14*(1+-0.2)),'FOB'!C14*(1+-0.2)*'FOB'!C7,0)))*0.003/0.997))))*'FOB'!C11,0)+IF(ISNUMBER('FOB'!C11),(IF(AND(ISNUMBER('FOB'!C6),ISNUMBER('FOB'!C7)),'FOB'!C6*'FOB'!C7,0)+IF('FOB'!C9=TRUE,0,IF(ISNUMBER('FOB'!C19),'FOB'!C19,0))+IF(ISNUMBER('FOB'!C13),IF('FOB'!C22,0,'FOB'!C13),0)+IF(ISNUMBER('FOB'!C12),IF('FOB'!C22,0,'FOB'!C12),0)+IF('FOB'!C20,0,IF(ISNUMBER('FOB'!C14*(1+-0.2)),'FOB'!C14*(1+-0.2)*'FOB'!C7,0))+IF('FOB'!C18,0,IF(ISNUMBER('FOB'!C17),'FOB'!C17,IF(ISNUMBER('FOB'!C16),(IF(AND(ISNUMBER('FOB'!C6),ISNUMBER('FOB'!C7)),'FOB'!C6*'FOB'!C7,0)+IF('FOB'!C20,0,IF(ISNUMBER('FOB'!C14*(1+-0.2)),'FOB'!C14*(1+-0.2)*'FOB'!C7,0)))*'FOB'!C16/100*1.1,(IF(AND(ISNUMBER('FOB'!C6),ISNUMBER('FOB'!C7)),'FOB'!C6*'FOB'!C7,0)+IF('FOB'!C9=TRUE,0,IF(ISNUMBER('FOB'!C19),'FOB'!C19,0))+IF(ISNUMBER('FOB'!C13),IF('FOB'!C22,0,'FOB'!C13),0)+IF(ISNUMBER('FOB'!C12),IF('FOB'!C22,0,'FOB'!C12),0)+IF('FOB'!C20,0,IF(ISNUMBER('FOB'!C14*(1+-0.2)),'FOB'!C14*(1+-0.2)*'FOB'!C7,0)))*0.003/0.997))))*'FOB'!C11,0)*IF(ISNUMBER('FOB'!C33),'FOB'!C33,0)*(1+IF(ISNUMBER('FOB'!C34),'FOB'!C34,0)))*IF(ISNUMBER('FOB'!C35),'FOB'!C35,0)+(IF(ISNUMBER('FOB'!C46),'FOB'!C46,0)+IF(ISNUMBER('FOB'!C47),'FOB'!C47,0)+IF(ISNUMBER('FOB'!C48),'FOB'!C48,0)+IF(ISNUMBER('FOB'!C49),'FOB'!C49,0)+IF(ISNUMBER('FOB'!C50),'FOB'!C50,0)+IF(ISNUMBER('FOB'!C51),'FOB'!C51,0))-IF(LEFT('FOB'!C36,1)="是",(IF(ISNUMBER('FOB'!C11),(IF(AND(ISNUMBER('FOB'!C6),ISNUMBER('FOB'!C7)),'FOB'!C6*'FOB'!C7,0)+IF('FOB'!C9=TRUE,0,IF(ISNUMBER('FOB'!C19),'FOB'!C19,0))+IF(ISNUMBER('FOB'!C13),IF('FOB'!C22,0,'FOB'!C13),0)+IF(ISNUMBER('FOB'!C12),IF('FOB'!C22,0,'FOB'!C12),0)+IF('FOB'!C20,0,IF(ISNUMBER('FOB'!C14*(1+-0.2)),'FOB'!C14*(1+-0.2)*'FOB'!C7,0))+IF('FOB'!C18,0,IF(ISNUMBER('FOB'!C17),'FOB'!C17,IF(ISNUMBER('FOB'!C16),(IF(AND(ISNUMBER('FOB'!C6),ISNUMBER('FOB'!C7)),'FOB'!C6*'FOB'!C7,0)+IF('FOB'!C20,0,IF(ISNUMBER('FOB'!C14*(1+-0.2)),'FOB'!C14*(1+-0.2)*'FOB'!C7,0)))*'FOB'!C16/100*1.1,(IF(AND(ISNUMBER('FOB'!C6),ISNUMBER('FOB'!C7)),'FOB'!C6*'FOB'!C7,0)+IF('FOB'!C9=TRUE,0,IF(ISNUMBER('FOB'!C19),'FOB'!C19,0))+IF(ISNUMBER('FOB'!C13),IF('FOB'!C22,0,'FOB'!C13),0)+IF(ISNUMBER('FOB'!C12),IF('FOB'!C22,0,'FOB'!C12),0)+IF('FOB'!C20,0,IF(ISNUMBER('FOB'!C14*(1+-0.2)),'FOB'!C14*(1+-0.2)*'FOB'!C7,0)))*0.003/0.997))))*'FOB'!C11,0)+IF(ISNUMBER('FOB'!C11),(IF(AND(ISNUMBER('FOB'!C6),ISNUMBER('FOB'!C7)),'FOB'!C6*'FOB'!C7,0)+IF('FOB'!C9=TRUE,0,IF(ISNUMBER('FOB'!C19),'FOB'!C19,0))+IF(ISNUMBER('FOB'!C13),IF('FOB'!C22,0,'FOB'!C13),0)+IF(ISNUMBER('FOB'!C12),IF('FOB'!C22,0,'FOB'!C12),0)+IF('FOB'!C20,0,IF(ISNUMBER('FOB'!C14*(1+-0.2)),'FOB'!C14*(1+-0.2)*'FOB'!C7,0))+IF('FOB'!C18,0,IF(ISNUMBER('FOB'!C17),'FOB'!C17,IF(ISNUMBER('FOB'!C16),(IF(AND(ISNUMBER('FOB'!C6),ISNUMBER('FOB'!C7)),'FOB'!C6*'FOB'!C7,0)+IF('FOB'!C20,0,IF(ISNUMBER('FOB'!C14*(1+-0.2)),'FOB'!C14*(1+-0.2)*'FOB'!C7,0)))*'FOB'!C16/100*1.1,(IF(AND(ISNUMBER('FOB'!C6),ISNUMBER('FOB'!C7)),'FOB'!C6*'FOB'!C7,0)+IF('FOB'!C9=TRUE,0,IF(ISNUMBER('FOB'!C19),'FOB'!C19,0))+IF(ISNUMBER('FOB'!C13),IF('FOB'!C22,0,'FOB'!C13),0)+IF(ISNUMBER('FOB'!C12),IF('FOB'!C22,0,'FOB'!C12),0)+IF('FOB'!C20,0,IF(ISNUMBER('FOB'!C14*(1+-0.2)),'FOB'!C14*(1+-0.2)*'FOB'!C7,0)))*0.003/0.997))))*'FOB'!C11,0)*IF(ISNUMBER('FOB'!C33),'FOB'!C33,0)*(1+IF(ISNUMBER('FOB'!C34),'FOB'!C34,0)))*IF(ISNUMBER('FOB'!C35),'FOB'!C35,0),0))/('FOB'!C7),"") | E15: =IF(AND(ISNUMBER(D15),ISNUMBER(D4)),D15-D4,"") | F15: =IF(AND(ISNUMBER(E15),ISNUMBER(D4)),E15/D4,"") | G15: 运费 +1 USD/MT ≈ +(1+关税率)×汇率 元/吨
B16: 海运费 -10% | C16: 'FOB'!C14*(1+-0.1) | D16: =IF(AND(ISNUMBER('FOB'!C6),ISNUMBER('FOB'!C7),ISNUMBER('FOB'!C10),ISNUMBER('FOB'!C11),ISNUMBER('FOB'!C33)),((IF(AND(ISNUMBER('FOB'!C6),ISNUMBER('FOB'!C7)),'FOB'!C6*'FOB'!C7,0)+IF('FOB'!C9=TRUE,0,IF(ISNUMBER('FOB'!C19),'FOB'!C19,0))+IF(ISNUMBER('FOB'!C13),IF('FOB'!C22,0,'FOB'!C13),0)+IF(ISNUMBER('FOB'!C12),IF('FOB'!C22,0,'FOB'!C12),0)+IF('FOB'!C20,0,IF(ISNUMBER('FOB'!C14*(1+-0.1)),'FOB'!C14*(1+-0.1)*'FOB'!C7,0))+IF('FOB'!C18,0,IF(ISNUMBER('FOB'!C17),'FOB'!C17,IF(ISNUMBER('FOB'!C16),(IF(AND(ISNUMBER('FOB'!C6),ISNUMBER('FOB'!C7)),'FOB'!C6*'FOB'!C7,0)+IF('FOB'!C20,0,IF(ISNUMBER('FOB'!C14*(1+-0.1)),'FOB'!C14*(1+-0.1)*'FOB'!C7,0)))*'FOB'!C16/100*1.1,(IF(AND(ISNUMBER('FOB'!C6),ISNUMBER('FOB'!C7)),'FOB'!C6*'FOB'!C7,0)+IF('FOB'!C9=TRUE,0,IF(ISNUMBER('FOB'!C19),'FOB'!C19,0))+IF(ISNUMBER('FOB'!C13),IF('FOB'!C22,0,'FOB'!C13),0)+IF(ISNUMBER('FOB'!C12),IF('FOB'!C22,0,'FOB'!C12),0)+IF('FOB'!C20,0,IF(ISNUMBER('FOB'!C14*(1+-0.1)),'FOB'!C14*(1+-0.1)*'FOB'!C7,0)))*0.003/0.997))))*IF(ISNUMBER('FOB'!C10),'FOB'!C10,0)+IF(ISNUMBER('FOB'!C11),(IF(AND(ISNUMBER('FOB'!C6),ISNUMBER('FOB'!C7)),'FOB'!C6*'FOB'!C7,0)+IF('FOB'!C9=TRUE,0,IF(ISNUMBER('FOB'!C19),'FOB'!C19,0))+IF(ISNUMBER('FOB'!C13),IF('FOB'!C22,0,'FOB'!C13),0)+IF(ISNUMBER('FOB'!C12),IF('FOB'!C22,0,'FOB'!C12),0)+IF('FOB'!C20,0,IF(ISNUMBER('FOB'!C14*(1+-0.1)),'FOB'!C14*(1+-0.1)*'FOB'!C7,0))+IF('FOB'!C18,0,IF(ISNUMBER('FOB'!C17),'FOB'!C17,IF(ISNUMBER('FOB'!C16),(IF(AND(ISNUMBER('FOB'!C6),ISNUMBER('FOB'!C7)),'FOB'!C6*'FOB'!C7,0)+IF('FOB'!C20,0,IF(ISNUMBER('FOB'!C14*(1+-0.1)),'FOB'!C14*(1+-0.1)*'FOB'!C7,0)))*'FOB'!C16/100*1.1,(IF(AND(ISNUMBER('FOB'!C6),ISNUMBER('FOB'!C7)),'FOB'!C6*'FOB'!C7,0)+IF('FOB'!C9=TRUE,0,IF(ISNUMBER('FOB'!C19),'FOB'!C19,0))+IF(ISNUMBER('FOB'!C13),IF('FOB'!C22,0,'FOB'!C13),0)+IF(ISNUMBER('FOB'!C12),IF('FOB'!C22,0,'FOB'!C12),0)+IF('FOB'!C20,0,IF(ISNUMBER('FOB'!C14*(1+-0.1)),'FOB'!C14*(1+-0.1)*'FOB'!C7,0)))*0.003/0.997))))*'FOB'!C11,0)*IF(ISNUMBER('FOB'!C33),'FOB'!C33,0)*(1+IF(ISNUMBER('FOB'!C34),'FOB'!C34,0))+(IF(ISNUMBER('FOB'!C11),(IF(AND(ISNUMBER('FOB'!C6),ISNUMBER('FOB'!C7)),'FOB'!C6*'FOB'!C7,0)+IF('FOB'!C9=TRUE,0,IF(ISNUMBER('FOB'!C19),'FOB'!C19,0))+IF(ISNUMBER('FOB'!C13),IF('FOB'!C22,0,'FOB'!C13),0)+IF(ISNUMBER('FOB'!C12),IF('FOB'!C22,0,'FOB'!C12),0)+IF('FOB'!C20,0,IF(ISNUMBER('FOB'!C14*(1+-0.1)),'FOB'!C14*(1+-0.1)*'FOB'!C7,0))+IF('FOB'!C18,0,IF(ISNUMBER('FOB'!C17),'FOB'!C17,IF(ISNUMBER('FOB'!C16),(IF(AND(ISNUMBER('FOB'!C6),ISNUMBER('FOB'!C7)),'FOB'!C6*'FOB'!C7,0)+IF('FOB'!C20,0,IF(ISNUMBER('FOB'!C14*(1+-0.1)),'FOB'!C14*(1+-0.1)*'FOB'!C7,0)))*'FOB'!C16/100*1.1,(IF(AND(ISNUMBER('FOB'!C6),ISNUMBER('FOB'!C7)),'FOB'!C6*'FOB'!C7,0)+IF('FOB'!C9=TRUE,0,IF(ISNUMBER('FOB'!C19),'FOB'!C19,0))+IF(ISNUMBER('FOB'!C13),IF('FOB'!C22,0,'FOB'!C13),0)+IF(ISNUMBER('FOB'!C12),IF('FOB'!C22,0,'FOB'!C12),0)+IF('FOB'!C20,0,IF(ISNUMBER('FOB'!C14*(1+-0.1)),'FOB'!C14*(1+-0.1)*'FOB'!C7,0)))*0.003/0.997))))*'FOB'!C11,0)+IF(ISNUMBER('FOB'!C11),(IF(AND(ISNUMBER('FOB'!C6),ISNUMBER('FOB'!C7)),'FOB'!C6*'FOB'!C7,0)+IF('FOB'!C9=TRUE,0,IF(ISNUMBER('FOB'!C19),'FOB'!C19,0))+IF(ISNUMBER('FOB'!C13),IF('FOB'!C22,0,'FOB'!C13),0)+IF(ISNUMBER('FOB'!C12),IF('FOB'!C22,0,'FOB'!C12),0)+IF('FOB'!C20,0,IF(ISNUMBER('FOB'!C14*(1+-0.1)),'FOB'!C14*(1+-0.1)*'FOB'!C7,0))+IF('FOB'!C18,0,IF(ISNUMBER('FOB'!C17),'FOB'!C17,IF(ISNUMBER('FOB'!C16),(IF(AND(ISNUMBER('FOB'!C6),ISNUMBER('FOB'!C7)),'FOB'!C6*'FOB'!C7,0)+IF('FOB'!C20,0,IF(ISNUMBER('FOB'!C14*(1+-0.1)),'FOB'!C14*(1+-0.1)*'FOB'!C7,0)))*'FOB'!C16/100*1.1,(IF(AND(ISNUMBER('FOB'!C6),ISNUMBER('FOB'!C7)),'FOB'!C6*'FOB'!C7,0)+IF('FOB'!C9=TRUE,0,IF(ISNUMBER('FOB'!C19),'FOB'!C19,0))+IF(ISNUMBER('FOB'!C13),IF('FOB'!C22,0,'FOB'!C13),0)+IF(ISNUMBER('FOB'!C12),IF('FOB'!C22,0,'FOB'!C12),0)+IF('FOB'!C20,0,IF(ISNUMBER('FOB'!C14*(1+-0.1)),'FOB'!C14*(1+-0.1)*'FOB'!C7,0)))*0.003/0.997))))*'FOB'!C11,0)*IF(ISNUMBER('FOB'!C33),'FOB'!C33,0)*(1+IF(ISNUMBER('FOB'!C34),'FOB'!C34,0)))*IF(ISNUMBER('FOB'!C35),'FOB'!C35,0)+(IF(ISNUMBER('FOB'!C46),'FOB'!C46,0)+IF(ISNUMBER('FOB'!C47),'FOB'!C47,0)+IF(ISNUMBER('FOB'!C48),'FOB'!C48,0)+IF(ISNUMBER('FOB'!C49),'FOB'!C49,0)+IF(ISNUMBER('FOB'!C50),'FOB'!C50,0)+IF(ISNUMBER('FOB'!C51),'FOB'!C51,0))-IF(LEFT('FOB'!C36,1)="是",(IF(ISNUMBER('FOB'!C11),(IF(AND(ISNUMBER('FOB'!C6),ISNUMBER('FOB'!C7)),'FOB'!C6*'FOB'!C7,0)+IF('FOB'!C9=TRUE,0,IF(ISNUMBER('FOB'!C19),'FOB'!C19,0))+IF(ISNUMBER('FOB'!C13),IF('FOB'!C22,0,'FOB'!C13),0)+IF(ISNUMBER('FOB'!C12),IF('FOB'!C22,0,'FOB'!C12),0)+IF('FOB'!C20,0,IF(ISNUMBER('FOB'!C14*(1+-0.1)),'FOB'!C14*(1+-0.1)*'FOB'!C7,0))+IF('FOB'!C18,0,IF(ISNUMBER('FOB'!C17),'FOB'!C17,IF(ISNUMBER('FOB'!C16),(IF(AND(ISNUMBER('FOB'!C6),ISNUMBER('FOB'!C7)),'FOB'!C6*'FOB'!C7,0)+IF('FOB'!C20,0,IF(ISNUMBER('FOB'!C14*(1+-0.1)),'FOB'!C14*(1+-0.1)*'FOB'!C7,0)))*'FOB'!C16/100*1.1,(IF(AND(ISNUMBER('FOB'!C6),ISNUMBER('FOB'!C7)),'FOB'!C6*'FOB'!C7,0)+IF('FOB'!C9=TRUE,0,IF(ISNUMBER('FOB'!C19),'FOB'!C19,0))+IF(ISNUMBER('FOB'!C13),IF('FOB'!C22,0,'FOB'!C13),0)+IF(ISNUMBER('FOB'!C12),IF('FOB'!C22,0,'FOB'!C12),0)+IF('FOB'!C20,0,IF(ISNUMBER('FOB'!C14*(1+-0.1)),'FOB'!C14*(1+-0.1)*'FOB'!C7,0)))*0.003/0.997))))*'FOB'!C11,0)+IF(ISNUMBER('FOB'!C11),(IF(AND(ISNUMBER('FOB'!C6),ISNUMBER('FOB'!C7)),'FOB'!C6*'FOB'!C7,0)+IF('FOB'!C9=TRUE,0,IF(ISNUMBER('FOB'!C19),'FOB'!C19,0))+IF(ISNUMBER('FOB'!C13),IF('FOB'!C22,0,'FOB'!C13),0)+IF(ISNUMBER('FOB'!C12),IF('FOB'!C22,0,'FOB'!C12),0)+IF('FOB'!C20,0,IF(ISNUMBER('FOB'!C14*(1+-0.1)),'FOB'!C14*(1+-0.1)*'FOB'!C7,0))+IF('FOB'!C18,0,IF(ISNUMBER('FOB'!C17),'FOB'!C17,IF(ISNUMBER('FOB'!C16),(IF(AND(ISNUMBER('FOB'!C6),ISNUMBER('FOB'!C7)),'FOB'!C6*'FOB'!C7,0)+IF('FOB'!C20,0,IF(ISNUMBER('FOB'!C14*(1+-0.1)),'FOB'!C14*(1+-0.1)*'FOB'!C7,0)))*'FOB'!C16/100*1.1,(IF(AND(ISNUMBER('FOB'!C6),ISNUMBER('FOB'!C7)),'FOB'!C6*'FOB'!C7,0)+IF('FOB'!C9=TRUE,0,IF(ISNUMBER('FOB'!C19),'FOB'!C19,0))+IF(ISNUMBER('FOB'!C13),IF('FOB'!C22,0,'FOB'!C13),0)+IF(ISNUMBER('FOB'!C12),IF('FOB'!C22,0,'FOB'!C12),0)+IF('FOB'!C20,0,IF(ISNUMBER('FOB'!C14*(1+-0.1)),'FOB'!C14*(1+-0.1)*'FOB'!C7,0)))*0.003/0.997))))*'FOB'!C11,0)*IF(ISNUMBER('FOB'!C33),'FOB'!C33,0)*(1+IF(ISNUMBER('FOB'!C34),'FOB'!C34,0)))*IF(ISNUMBER('FOB'!C35),'FOB'!C35,0),0))/('FOB'!C7),"") | E16: =IF(AND(ISNUMBER(D16),ISNUMBER(D4)),D16-D4,"") | F16: =IF(AND(ISNUMBER(E16),ISNUMBER(D4)),E16/D4,"")
B17: 海运费 +0% | C17: 'FOB'!C14*(1+0.0) | D17: =IF(AND(ISNUMBER('FOB'!C6),ISNUMBER('FOB'!C7),ISNUMBER('FOB'!C10),ISNUMBER('FOB'!C11),ISNUMBER('FOB'!C33)),((IF(AND(ISNUMBER('FOB'!C6),ISNUMBER('FOB'!C7)),'FOB'!C6*'FOB'!C7,0)+IF('FOB'!C9=TRUE,0,IF(ISNUMBER('FOB'!C19),'FOB'!C19,0))+IF(ISNUMBER('FOB'!C13),IF('FOB'!C22,0,'FOB'!C13),0)+IF(ISNUMBER('FOB'!C12),IF('FOB'!C22,0,'FOB'!C12),0)+IF('FOB'!C20,0,IF(ISNUMBER('FOB'!C14*(1+0.0)),'FOB'!C14*(1+0.0)*'FOB'!C7,0))+IF('FOB'!C18,0,IF(ISNUMBER('FOB'!C17),'FOB'!C17,IF(ISNUMBER('FOB'!C16),(IF(AND(ISNUMBER('FOB'!C6),ISNUMBER('FOB'!C7)),'FOB'!C6*'FOB'!C7,0)+IF('FOB'!C20,0,IF(ISNUMBER('FOB'!C14*(1+0.0)),'FOB'!C14*(1+0.0)*'FOB'!C7,0)))*'FOB'!C16/100*1.1,(IF(AND(ISNUMBER('FOB'!C6),ISNUMBER('FOB'!C7)),'FOB'!C6*'FOB'!C7,0)+IF('FOB'!C9=TRUE,0,IF(ISNUMBER('FOB'!C19),'FOB'!C19,0))+IF(ISNUMBER('FOB'!C13),IF('FOB'!C22,0,'FOB'!C13),0)+IF(ISNUMBER('FOB'!C12),IF('FOB'!C22,0,'FOB'!C12),0)+IF('FOB'!C20,0,IF(ISNUMBER('FOB'!C14*(1+0.0)),'FOB'!C14*(1+0.0)*'FOB'!C7,0)))*0.003/0.997))))*IF(ISNUMBER('FOB'!C10),'FOB'!C10,0)+IF(ISNUMBER('FOB'!C11),(IF(AND(ISNUMBER('FOB'!C6),ISNUMBER('FOB'!C7)),'FOB'!C6*'FOB'!C7,0)+IF('FOB'!C9=TRUE,0,IF(ISNUMBER('FOB'!C19),'FOB'!C19,0))+IF(ISNUMBER('FOB'!C13),IF('FOB'!C22,0,'FOB'!C13),0)+IF(ISNUMBER('FOB'!C12),IF('FOB'!C22,0,'FOB'!C12),0)+IF('FOB'!C20,0,IF(ISNUMBER('FOB'!C14*(1+0.0)),'FOB'!C14*(1+0.0)*'FOB'!C7,0))+IF('FOB'!C18,0,IF(ISNUMBER('FOB'!C17),'FOB'!C17,IF(ISNUMBER('FOB'!C16),(IF(AND(ISNUMBER('FOB'!C6),ISNUMBER('FOB'!C7)),'FOB'!C6*'FOB'!C7,0)+IF('FOB'!C20,0,IF(ISNUMBER('FOB'!C14*(1+0.0)),'FOB'!C14*(1+0.0)*'FOB'!C7,0)))*'FOB'!C16/100*1.1,(IF(AND(ISNUMBER('FOB'!C6),ISNUMBER('FOB'!C7)),'FOB'!C6*'FOB'!C7,0)+IF('FOB'!C9=TRUE,0,IF(ISNUMBER('FOB'!C19),'FOB'!C19,0))+IF(ISNUMBER('FOB'!C13),IF('FOB'!C22,0,'FOB'!C13),0)+IF(ISNUMBER('FOB'!C12),IF('FOB'!C22,0,'FOB'!C12),0)+IF('FOB'!C20,0,IF(ISNUMBER('FOB'!C14*(1+0.0)),'FOB'!C14*(1+0.0)*'FOB'!C7,0)))*0.003/0.997))))*'FOB'!C11,0)*IF(ISNUMBER('FOB'!C33),'FOB'!C33,0)*(1+IF(ISNUMBER('FOB'!C34),'FOB'!C34,0))+(IF(ISNUMBER('FOB'!C11),(IF(AND(ISNUMBER('FOB'!C6),ISNUMBER('FOB'!C7)),'FOB'!C6*'FOB'!C7,0)+IF('FOB'!C9=TRUE,0,IF(ISNUMBER('FOB'!C19),'FOB'!C19,0))+IF(ISNUMBER('FOB'!C13),IF('FOB'!C22,0,'FOB'!C13),0)+IF(ISNUMBER('FOB'!C12),IF('FOB'!C22,0,'FOB'!C12),0)+IF('FOB'!C20,0,IF(ISNUMBER('FOB'!C14*(1+0.0)),'FOB'!C14*(1+0.0)*'FOB'!C7,0))+IF('FOB'!C18,0,IF(ISNUMBER('FOB'!C17),'FOB'!C17,IF(ISNUMBER('FOB'!C16),(IF(AND(ISNUMBER('FOB'!C6),ISNUMBER('FOB'!C7)),'FOB'!C6*'FOB'!C7,0)+IF('FOB'!C20,0,IF(ISNUMBER('FOB'!C14*(1+0.0)),'FOB'!C14*(1+0.0)*'FOB'!C7,0)))*'FOB'!C16/100*1.1,(IF(AND(ISNUMBER('FOB'!C6),ISNUMBER('FOB'!C7)),'FOB'!C6*'FOB'!C7,0)+IF('FOB'!C9=TRUE,0,IF(ISNUMBER('FOB'!C19),'FOB'!C19,0))+IF(ISNUMBER('FOB'!C13),IF('FOB'!C22,0,'FOB'!C13),0)+IF(ISNUMBER('FOB'!C12),IF('FOB'!C22,0,'FOB'!C12),0)+IF('FOB'!C20,0,IF(ISNUMBER('FOB'!C14*(1+0.0)),'FOB'!C14*(1+0.0)*'FOB'!C7,0)))*0.003/0.997))))*'FOB'!C11,0)+IF(ISNUMBER('FOB'!C11),(IF(AND(ISNUMBER('FOB'!C6),ISNUMBER('FOB'!C7)),'FOB'!C6*'FOB'!C7,0)+IF('FOB'!C9=TRUE,0,IF(ISNUMBER('FOB'!C19),'FOB'!C19,0))+IF(ISNUMBER('FOB'!C13),IF('FOB'!C22,0,'FOB'!C13),0)+IF(ISNUMBER('FOB'!C12),IF('FOB'!C22,0,'FOB'!C12),0)+IF('FOB'!C20,0,IF(ISNUMBER('FOB'!C14*(1+0.0)),'FOB'!C14*(1+0.0)*'FOB'!C7,0))+IF('FOB'!C18,0,IF(ISNUMBER('FOB'!C17),'FOB'!C17,IF(ISNUMBER('FOB'!C16),(IF(AND(ISNUMBER('FOB'!C6),ISNUMBER('FOB'!C7)),'FOB'!C6*'FOB'!C7,0)+IF('FOB'!C20,0,IF(ISNUMBER('FOB'!C14*(1+0.0)),'FOB'!C14*(1+0.0)*'FOB'!C7,0)))*'FOB'!C16/100*1.1,(IF(AND(ISNUMBER('FOB'!C6),ISNUMBER('FOB'!C7)),'FOB'!C6*'FOB'!C7,0)+IF('FOB'!C9=TRUE,0,IF(ISNUMBER('FOB'!C19),'FOB'!C19,0))+IF(ISNUMBER('FOB'!C13),IF('FOB'!C22,0,'FOB'!C13),0)+IF(ISNUMBER('FOB'!C12),IF('FOB'!C22,0,'FOB'!C12),0)+IF('FOB'!C20,0,IF(ISNUMBER('FOB'!C14*(1+0.0)),'FOB'!C14*(1+0.0)*'FOB'!C7,0)))*0.003/0.997))))*'FOB'!C11,0)*IF(ISNUMBER('FOB'!C33),'FOB'!C33,0)*(1+IF(ISNUMBER('FOB'!C34),'FOB'!C34,0)))*IF(ISNUMBER('FOB'!C35),'FOB'!C35,0)+(IF(ISNUMBER('FOB'!C46),'FOB'!C46,0)+IF(ISNUMBER('FOB'!C47),'FOB'!C47,0)+IF(ISNUMBER('FOB'!C48),'FOB'!C48,0)+IF(ISNUMBER('FOB'!C49),'FOB'!C49,0)+IF(ISNUMBER('FOB'!C50),'FOB'!C50,0)+IF(ISNUMBER('FOB'!C51),'FOB'!C51,0))-IF(LEFT('FOB'!C36,1)="是",(IF(ISNUMBER('FOB'!C11),(IF(AND(ISNUMBER('FOB'!C6),ISNUMBER('FOB'!C7)),'FOB'!C6*'FOB'!C7,0)+IF('FOB'!C9=TRUE,0,IF(ISNUMBER('FOB'!C19),'FOB'!C19,0))+IF(ISNUMBER('FOB'!C13),IF('FOB'!C22,0,'FOB'!C13),0)+IF(ISNUMBER('FOB'!C12),IF('FOB'!C22,0,'FOB'!C12),0)+IF('FOB'!C20,0,IF(ISNUMBER('FOB'!C14*(1+0.0)),'FOB'!C14*(1+0.0)*'FOB'!C7,0))+IF('FOB'!C18,0,IF(ISNUMBER('FOB'!C17),'FOB'!C17,IF(ISNUMBER('FOB'!C16),(IF(AND(ISNUMBER('FOB'!C6),ISNUMBER('FOB'!C7)),'FOB'!C6*'FOB'!C7,0)+IF('FOB'!C20,0,IF(ISNUMBER('FOB'!C14*(1+0.0)),'FOB'!C14*(1+0.0)*'FOB'!C7,0)))*'FOB'!C16/100*1.1,(IF(AND(ISNUMBER('FOB'!C6),ISNUMBER('FOB'!C7)),'FOB'!C6*'FOB'!C7,0)+IF('FOB'!C9=TRUE,0,IF(ISNUMBER('FOB'!C19),'FOB'!C19,0))+IF(ISNUMBER('FOB'!C13),IF('FOB'!C22,0,'FOB'!C13),0)+IF(ISNUMBER('FOB'!C12),IF('FOB'!C22,0,'FOB'!C12),0)+IF('FOB'!C20,0,IF(ISNUMBER('FOB'!C14*(1+0.0)),'FOB'!C14*(1+0.0)*'FOB'!C7,0)))*0.003/0.997))))*'FOB'!C11,0)+IF(ISNUMBER('FOB'!C11),(IF(AND(ISNUMBER('FOB'!C6),ISNUMBER('FOB'!C7)),'FOB'!C6*'FOB'!C7,0)+IF('FOB'!C9=TRUE,0,IF(ISNUMBER('FOB'!C19),'FOB'!C19,0))+IF(ISNUMBER('FOB'!C13),IF('FOB'!C22,0,'FOB'!C13),0)+IF(ISNUMBER('FOB'!C12),IF('FOB'!C22,0,'FOB'!C12),0)+IF('FOB'!C20,0,IF(ISNUMBER('FOB'!C14*(1+0.0)),'FOB'!C14*(1+0.0)*'FOB'!C7,0))+IF('FOB'!C18,0,IF(ISNUMBER('FOB'!C17),'FOB'!C17,IF(ISNUMBER('FOB'!C16),(IF(AND(ISNUMBER('FOB'!C6),ISNUMBER('FOB'!C7)),'FOB'!C6*'FOB'!C7,0)+IF('FOB'!C20,0,IF(ISNUMBER('FOB'!C14*(1+0.0)),'FOB'!C14*(1+0.0)*'FOB'!C7,0)))*'FOB'!C16/100*1.1,(IF(AND(ISNUMBER('FOB'!C6),ISNUMBER('FOB'!C7)),'FOB'!C6*'FOB'!C7,0)+IF('FOB'!C9=TRUE,0,IF(ISNUMBER('FOB'!C19),'FOB'!C19,0))+IF(ISNUMBER('FOB'!C13),IF('FOB'!C22,0,'FOB'!C13),0)+IF(ISNUMBER('FOB'!C12),IF('FOB'!C22,0,'FOB'!C12),0)+IF('FOB'!C20,0,IF(ISNUMBER('FOB'!C14*(1+0.0)),'FOB'!C14*(1+0.0)*'FOB'!C7,0)))*0.003/0.997))))*'FOB'!C11,0)*IF(ISNUMBER('FOB'!C33),'FOB'!C33,0)*(1+IF(ISNUMBER('FOB'!C34),'FOB'!C34,0)))*IF(ISNUMBER('FOB'!C35),'FOB'!C35,0),0))/('FOB'!C7),"") | E17: =IF(AND(ISNUMBER(D17),ISNUMBER(D4)),D17-D4,"") | F17: =IF(AND(ISNUMBER(E17),ISNUMBER(D4)),E17/D4,"")
B18: 海运费 +10% | C18: 'FOB'!C14*(1+0.1) | D18: =IF(AND(ISNUMBER('FOB'!C6),ISNUMBER('FOB'!C7),ISNUMBER('FOB'!C10),ISNUMBER('FOB'!C11),ISNUMBER('FOB'!C33)),((IF(AND(ISNUMBER('FOB'!C6),ISNUMBER('FOB'!C7)),'FOB'!C6*'FOB'!C7,0)+IF('FOB'!C9=TRUE,0,IF(ISNUMBER('FOB'!C19),'FOB'!C19,0))+IF(ISNUMBER('FOB'!C13),IF('FOB'!C22,0,'FOB'!C13),0)+IF(ISNUMBER('FOB'!C12),IF('FOB'!C22,0,'FOB'!C12),0)+IF('FOB'!C20,0,IF(ISNUMBER('FOB'!C14*(1+0.1)),'FOB'!C14*(1+0.1)*'FOB'!C7,0))+IF('FOB'!C18,0,IF(ISNUMBER('FOB'!C17),'FOB'!C17,IF(ISNUMBER('FOB'!C16),(IF(AND(ISNUMBER('FOB'!C6),ISNUMBER('FOB'!C7)),'FOB'!C6*'FOB'!C7,0)+IF('FOB'!C20,0,IF(ISNUMBER('FOB'!C14*(1+0.1)),'FOB'!C14*(1+0.1)*'FOB'!C7,0)))*'FOB'!C16/100*1.1,(IF(AND(ISNUMBER('FOB'!C6),ISNUMBER('FOB'!C7)),'FOB'!C6*'FOB'!C7,0)+IF('FOB'!C9=TRUE,0,IF(ISNUMBER('FOB'!C19),'FOB'!C19,0))+IF(ISNUMBER('FOB'!C13),IF('FOB'!C22,0,'FOB'!C13),0)+IF(ISNUMBER('FOB'!C12),IF('FOB'!C22,0,'FOB'!C12),0)+IF('FOB'!C20,0,IF(ISNUMBER('FOB'!C14*(1+0.1)),'FOB'!C14*(1+0.1)*'FOB'!C7,0)))*0.003/0.997))))*IF(ISNUMBER('FOB'!C10),'FOB'!C10,0)+IF(ISNUMBER('FOB'!C11),(IF(AND(ISNUMBER('FOB'!C6),ISNUMBER('FOB'!C7)),'FOB'!C6*'FOB'!C7,0)+IF('FOB'!C9=TRUE,0,IF(ISNUMBER('FOB'!C19),'FOB'!C19,0))+IF(ISNUMBER('FOB'!C13),IF('FOB'!C22,0,'FOB'!C13),0)+IF(ISNUMBER('FOB'!C12),IF('FOB'!C22,0,'FOB'!C12),0)+IF('FOB'!C20,0,IF(ISNUMBER('FOB'!C14*(1+0.1)),'FOB'!C14*(1+0.1)*'FOB'!C7,0))+IF('FOB'!C18,0,IF(ISNUMBER('FOB'!C17),'FOB'!C17,IF(ISNUMBER('FOB'!C16),(IF(AND(ISNUMBER('FOB'!C6),ISNUMBER('FOB'!C7)),'FOB'!C6*'FOB'!C7,0)+IF('FOB'!C20,0,IF(ISNUMBER('FOB'!C14*(1+0.1)),'FOB'!C14*(1+0.1)*'FOB'!C7,0)))*'FOB'!C16/100*1.1,(IF(AND(ISNUMBER('FOB'!C6),ISNUMBER('FOB'!C7)),'FOB'!C6*'FOB'!C7,0)+IF('FOB'!C9=TRUE,0,IF(ISNUMBER('FOB'!C19),'FOB'!C19,0))+IF(ISNUMBER('FOB'!C13),IF('FOB'!C22,0,'FOB'!C13),0)+IF(ISNUMBER('FOB'!C12),IF('FOB'!C22,0,'FOB'!C12),0)+IF('FOB'!C20,0,IF(ISNUMBER('FOB'!C14*(1+0.1)),'FOB'!C14*(1+0.1)*'FOB'!C7,0)))*0.003/0.997))))*'FOB'!C11,0)*IF(ISNUMBER('FOB'!C33),'FOB'!C33,0)*(1+IF(ISNUMBER('FOB'!C34),'FOB'!C34,0))+(IF(ISNUMBER('FOB'!C11),(IF(AND(ISNUMBER('FOB'!C6),ISNUMBER('FOB'!C7)),'FOB'!C6*'FOB'!C7,0)+IF('FOB'!C9=TRUE,0,IF(ISNUMBER('FOB'!C19),'FOB'!C19,0))+IF(ISNUMBER('FOB'!C13),IF('FOB'!C22,0,'FOB'!C13),0)+IF(ISNUMBER('FOB'!C12),IF('FOB'!C22,0,'FOB'!C12),0)+IF('FOB'!C20,0,IF(ISNUMBER('FOB'!C14*(1+0.1)),'FOB'!C14*(1+0.1)*'FOB'!C7,0))+IF('FOB'!C18,0,IF(ISNUMBER('FOB'!C17),'FOB'!C17,IF(ISNUMBER('FOB'!C16),(IF(AND(ISNUMBER('FOB'!C6),ISNUMBER('FOB'!C7)),'FOB'!C6*'FOB'!C7,0)+IF('FOB'!C20,0,IF(ISNUMBER('FOB'!C14*(1+0.1)),'FOB'!C14*(1+0.1)*'FOB'!C7,0)))*'FOB'!C16/100*1.1,(IF(AND(ISNUMBER('FOB'!C6),ISNUMBER('FOB'!C7)),'FOB'!C6*'FOB'!C7,0)+IF('FOB'!C9=TRUE,0,IF(ISNUMBER('FOB'!C19),'FOB'!C19,0))+IF(ISNUMBER('FOB'!C13),IF('FOB'!C22,0,'FOB'!C13),0)+IF(ISNUMBER('FOB'!C12),IF('FOB'!C22,0,'FOB'!C12),0)+IF('FOB'!C20,0,IF(ISNUMBER('FOB'!C14*(1+0.1)),'FOB'!C14*(1+0.1)*'FOB'!C7,0)))*0.003/0.997))))*'FOB'!C11,0)+IF(ISNUMBER('FOB'!C11),(IF(AND(ISNUMBER('FOB'!C6),ISNUMBER('FOB'!C7)),'FOB'!C6*'FOB'!C7,0)+IF('FOB'!C9=TRUE,0,IF(ISNUMBER('FOB'!C19),'FOB'!C19,0))+IF(ISNUMBER('FOB'!C13),IF('FOB'!C22,0,'FOB'!C13),0)+IF(ISNUMBER('FOB'!C12),IF('FOB'!C22,0,'FOB'!C12),0)+IF('FOB'!C20,0,IF(ISNUMBER('FOB'!C14*(1+0.1)),'FOB'!C14*(1+0.1)*'FOB'!C7,0))+IF('FOB'!C18,0,IF(ISNUMBER('FOB'!C17),'FOB'!C17,IF(ISNUMBER('FOB'!C16),(IF(AND(ISNUMBER('FOB'!C6),ISNUMBER('FOB'!C7)),'FOB'!C6*'FOB'!C7,0)+IF('FOB'!C20,0,IF(ISNUMBER('FOB'!C14*(1+0.1)),'FOB'!C14*(1+0.1)*'FOB'!C7,0)))*'FOB'!C16/100*1.1,(IF(AND(ISNUMBER('FOB'!C6),ISNUMBER('FOB'!C7)),'FOB'!C6*'FOB'!C7,0)+IF('FOB'!C9=TRUE,0,IF(ISNUMBER('FOB'!C19),'FOB'!C19,0))+IF(ISNUMBER('FOB'!C13),IF('FOB'!C22,0,'FOB'!C13),0)+IF(ISNUMBER('FOB'!C12),IF('FOB'!C22,0,'FOB'!C12),0)+IF('FOB'!C20,0,IF(ISNUMBER('FOB'!C14*(1+0.1)),'FOB'!C14*(1+0.1)*'FOB'!C7,0)))*0.003/0.997))))*'FOB'!C11,0)*IF(ISNUMBER('FOB'!C33),'FOB'!C33,0)*(1+IF(ISNUMBER('FOB'!C34),'FOB'!C34,0)))*IF(ISNUMBER('FOB'!C35),'FOB'!C35,0)+(IF(ISNUMBER('FOB'!C46),'FOB'!C46,0)+IF(ISNUMBER('FOB'!C47),'FOB'!C47,0)+IF(ISNUMBER('FOB'!C48),'FOB'!C48,0)+IF(ISNUMBER('FOB'!C49),'FOB'!C49,0)+IF(ISNUMBER('FOB'!C50),'FOB'!C50,0)+IF(ISNUMBER('FOB'!C51),'FOB'!C51,0))-IF(LEFT('FOB'!C36,1)="是",(IF(ISNUMBER('FOB'!C11),(IF(AND(ISNUMBER('FOB'!C6),ISNUMBER('FOB'!C7)),'FOB'!C6*'FOB'!C7,0)+IF('FOB'!C9=TRUE,0,IF(ISNUMBER('FOB'!C19),'FOB'!C19,0))+IF(ISNUMBER('FOB'!C13),IF('FOB'!C22,0,'FOB'!C13),0)+IF(ISNUMBER('FOB'!C12),IF('FOB'!C22,0,'FOB'!C12),0)+IF('FOB'!C20,0,IF(ISNUMBER('FOB'!C14*(1+0.1)),'FOB'!C14*(1+0.1)*'FOB'!C7,0))+IF('FOB'!C18,0,IF(ISNUMBER('FOB'!C17),'FOB'!C17,IF(ISNUMBER('FOB'!C16),(IF(AND(ISNUMBER('FOB'!C6),ISNUMBER('FOB'!C7)),'FOB'!C6*'FOB'!C7,0)+IF('FOB'!C20,0,IF(ISNUMBER('FOB'!C14*(1+0.1)),'FOB'!C14*(1+0.1)*'FOB'!C7,0)))*'FOB'!C16/100*1.1,(IF(AND(ISNUMBER('FOB'!C6),ISNUMBER('FOB'!C7)),'FOB'!C6*'FOB'!C7,0)+IF('FOB'!C9=TRUE,0,IF(ISNUMBER('FOB'!C19),'FOB'!C19,0))+IF(ISNUMBER('FOB'!C13),IF('FOB'!C22,0,'FOB'!C13),0)+IF(ISNUMBER('FOB'!C12),IF('FOB'!C22,0,'FOB'!C12),0)+IF('FOB'!C20,0,IF(ISNUMBER('FOB'!C14*(1+0.1)),'FOB'!C14*(1+0.1)*'FOB'!C7,0)))*0.003/0.997))))*'FOB'!C11,0)+IF(ISNUMBER('FOB'!C11),(IF(AND(ISNUMBER('FOB'!C6),ISNUMBER('FOB'!C7)),'FOB'!C6*'FOB'!C7,0)+IF('FOB'!C9=TRUE,0,IF(ISNUMBER('FOB'!C19),'FOB'!C19,0))+IF(ISNUMBER('FOB'!C13),IF('FOB'!C22,0,'FOB'!C13),0)+IF(ISNUMBER('FOB'!C12),IF('FOB'!C22,0,'FOB'!C12),0)+IF('FOB'!C20,0,IF(ISNUMBER('FOB'!C14*(1+0.1)),'FOB'!C14*(1+0.1)*'FOB'!C7,0))+IF('FOB'!C18,0,IF(ISNUMBER('FOB'!C17),'FOB'!C17,IF(ISNUMBER('FOB'!C16),(IF(AND(ISNUMBER('FOB'!C6),ISNUMBER('FOB'!C7)),'FOB'!C6*'FOB'!C7,0)+IF('FOB'!C20,0,IF(ISNUMBER('FOB'!C14*(1+0.1)),'FOB'!C14*(1+0.1)*'FOB'!C7,0)))*'FOB'!C16/100*1.1,(IF(AND(ISNUMBER('FOB'!C6),ISNUMBER('FOB'!C7)),'FOB'!C6*'FOB'!C7,0)+IF('FOB'!C9=TRUE,0,IF(ISNUMBER('FOB'!C19),'FOB'!C19,0))+IF(ISNUMBER('FOB'!C13),IF('FOB'!C22,0,'FOB'!C13),0)+IF(ISNUMBER('FOB'!C12),IF('FOB'!C22,0,'FOB'!C12),0)+IF('FOB'!C20,0,IF(ISNUMBER('FOB'!C14*(1+0.1)),'FOB'!C14*(1+0.1)*'FOB'!C7,0)))*0.003/0.997))))*'FOB'!C11,0)*IF(ISNUMBER('FOB'!C33),'FOB'!C33,0)*(1+IF(ISNUMBER('FOB'!C34),'FOB'!C34,0)))*IF(ISNUMBER('FOB'!C35),'FOB'!C35,0),0))/('FOB'!C7),"") | E18: =IF(AND(ISNUMBER(D18),ISNUMBER(D4)),D18-D4,"") | F18: =IF(AND(ISNUMBER(E18),ISNUMBER(D4)),E18/D4,"")
