Workbook

Sheet 00-说明
A1: 两个相关品种比价分析 · 工作簿说明
A2: 所有统计列均为 Excel 原生公式，可直接复算；不插值、不回填、不外推缺失数据。
A4: 一、本工作簿回答什么
B5: 两个品种是否存在替代/上下游/共同原料等产业关系；同一口径下的比价水平；
B6: 该水平在过去 1/3/5 年与全样本中的真实分位；比价变化由哪一边主导；
B7: 历史极端阶段的产业背景；比价分布是否因产业结构变化而长期移动。
A9: 二、不回答什么（红线）
B10: 不判断方向、不给目标价、不给交易建议；
B11: 不因为比价处于极端位置就认定必然回归；
B12: 不把相关性说成因果；产业事件只用于解释，不用于证明因果；
B13: 不混用现货与期货口径，不插值填补缺失。
A15: 三、口径（全簿统一）
A16: 品种 A | B16: PP
A17: 品种 B | B17: L
A18: 比价方向 | B18: PP/L（逐日收盘价相除）
A19: 价格类型 | B19: 期货主力连续收盘价，元/吨，含增值税、仓库交割基准
A20: 样本区间 | B20: 2014-02-28 → 2026-10-20
A21: 有效样本量 N | B21: 3069
A22: 交易日对齐 | B22: 按日期交集逐日对齐；任一侧当日缺失则该日整体剔除
A23: 换月处理 | B23: 主连日线，不做事后复权；换月跳空在 07-换月台账 单列，异常点中标注
A24: 分位算法 | B24: 经验分布分位 ECDF = 样本中 ≤ 当前值的观测占比；非最高/最低价线性反推
A25: 前序样本分位 | B25: 剔除最近 20 个交易日后重新打分，用于消除当前值自评分偏差
A26: 异常点算法 | B26: 稳健 z 分数（滚动 120 日中位数/MAD），|z| > 3.5
A28: 四、数据血缘
A29: 原始来源 | B29: 新浪财经 期货主力连续日线接口 InnerFuturesNewService.getDailyKLine
A30: 字段 | B30: 日期 / 开 / 高 / 低 / 收 / 成交量 / 持仓量
A31: 已做校验 | B31: 日期重复、收盘空值、OHLC 内部矛盾、单日异常涨跌、零成交、合约覆盖
A32: 校验结果 | B32: 见 10-数据来源 与 qc_report.json；ERROR 必须为 0 才进入统计
A34: 五、已知局限（写在结论里）
A35: 规格差异 | B35: PP 标准品为均聚拉丝级，LLDPE 标准品为薄膜料，比价含牌号价差，非同物比价
A36: 换月污染 | B36: 主连不连续；换月日新旧合约价差可达数个百分点，当日比价变动不可当产业信号
A37: 近月混合报价 | B37: 数据末端连续序列可能来自临近换月的混合报价路径，与单一挂牌合约不一致（见 10-数据来源）
A38: 结构漂移 | B38: 比价中枢在 13 年内至少移动过两次，全样本分位的分母并不稳定

Sheet 01-原始价格
A1: 原始价格：两侧逐日收盘（元/吨）
A2: A = PP，B = L。缺失保持空白，不插值。比价日期取两侧交集。
A4: 日期 | B4: PP 收盘 | C4: PP 开盘 | D4: PP 最高 | E4: PP 最低 | F4: PP 成交量 | G4: PP 持仓 | H4: L 收盘 | I4: L 开盘 | J4: L 最高 | K4: L 最低 | L4: L 成交量 | M4: L 持仓 | N4: 是否两侧齐全 | O4: 备注
A5: 2007-07-31 | H5: 12580 | I5: 12780 | J5: 12625 | K5: 12450 | L5: 21556 | M5: 2428 | N5: 否 | O5: 缺 PP
A6: 2007-08-01 | H6: 12450 | I6: 12650 | J6: 12650 | K6: 12390 | L6: 4728 | M6: 2294 | N6: 否 | O6: 缺 PP
A7: 2007-08-02 | H7: 12460 | I7: 12410 | J7: 12490 | K7: 12300 | L7: 5116 | M7: 2740 | N7: 否 | O7: 缺 PP
A8: 2007-08-03 | H8: 12495 | I8: 12440 | J8: 12560 | K8: 12410 | L8: 4810 | M8: 3026 | N8: 否 | O8: 缺 PP
A9: 2007-08-06 | H9: 12550 | I9: 12420 | J9: 12670 | K9: 12420 | L9: 6480 | M9: 3696 | N9: 否 | O9: 缺 PP
A10: 2007-08-07 | H10: 12540 | I10: 12455 | J10: 12570 | K10: 12440 | L10: 2600 | M10: 3106 | N10: 否 | O10: 缺 PP
A11: 2007-08-08 | H11: 12580 | I11: 12540 | J11: 12640 | K11: 12540 | L11: 2124 | M11: 3024 | N11: 否 | O11: 缺 PP
A12: 2007-08-09 | H12: 12770 | I12: 12575 | J12: 12795 | K12: 12560 | L12: 4630 | M12: 4452 | N12: 否 | O12: 缺 PP
A13: 2007-08-10 | H13: 12700 | I13: 12710 | J13: 12850 | K13: 12620 | L13: 8224 | M13: 4708 | N13: 否 | O13: 缺 PP
A14: 2007-08-13 | H14: 12685 | I14: 12745 | J14: 12780 | K14: 12660 | L14: 2740 | M14: 4122 | N14: 否 | O14: 缺 PP
A15: 2007-08-14 | H15: 12530 | I15: 12665 | J15: 12680 | K15: 12525 | L15: 3116 | M15: 3854 | N15: 否 | O15: 缺 PP
A16: 2007-08-15 | H16: 12565 | I16: 12530 | J16: 12600 | K16: 12520 | L16: 2166 | M16: 3908 | N16: 否 | O16: 缺 PP
... A1607: 2014-02-27 | H1607: 10825 | I1607: 10785 | J1607: 10825 | K1607: 10720 | L1607: 276716 | M1607: 372322 | N1607: 否 | O1607: 缺 PP
A1608: 2014-02-28 | B1608: 10657 | C1608: 10680 | D1608: 10720 | E1608: 10604 | F1608: 97582 | G1608: 21256 | H1608: 10765 | I1608: 10835 | J1608: 10840 | K1608: 10745 | L1608: 253700 | M1608: 346354 | N1608: 是
A1609: 2014-03-03 | B1609: 10298 | C1609: 10400 | D1609: 10403 | E1609: 10263 | F1609: 41518 | G1609: 20662 | H1609: 10670 | I1609: 10820 | J1609: 10835 | K1609: 10665 | L1609: 322598 | M1609: 315010 | N1609: 是
A1610: 2014-03-04 | B1610: 10306 | C1610: 10310 | D1610: 10330 | E1610: 10256 | F1610: 39938 | G1610: 25034 | H1610: 10705 | I1610: 10680 | J1610: 10715 | K1610: 10635 | L1610: 207590 | M1610: 306576 | N1610: 是
A1611: 2014-03-05 | B1611: 10710 | C1611: 10710 | D1611: 10732 | E1611: 10676 | F1611: 23616 | G1611: 27896 | H1611: 10620 | I1611: 10710 | J1611: 10745 | K1611: 10610 | L1611: 313710 | M1611: 310676 | N1611: 是
A1612: 2014-03-06 | B1612: 10166 | C1612: 10270 | D1612: 10290 | E1612: 10071 | F1612: 71074 | G1612: 32288 | H1612: 10265 | I1612: 10400 | J1612: 10400 | K1612: 10230 | L1612: 240760 | M1612: 295556 | N1612: 是
A1613: 2014-03-10 | B1613: 10077 | C1613: 10025 | D1613: 10150 | E1613: 10000 | F1613: 79360 | G1613: 46536 | H1613: 10145 | I1613: 10155 | J1613: 10240 | K1613: 9995 | L1613: 647936 | M1613: 387488 | N1613: 是
A1614: 2014-03-11 | B1614: 10180 | C1614: 10096 | D1614: 10350 | E1614: 10050 | F1614: 69412 | G1614: 39284 | H1614: 10235 | I1614: 10130 | J1614: 10345 | K1614: 10075 | L1614: 542938 | M1614: 361396 | N1614: 是
A1615: 2014-03-12 | B1615: 10191 | C1615: 10090 | D1615: 10193 | E1615: 10061 | F1615: 46214 | G1615: 49316 | H1615: 10270 | I1615: 10130 | J1615: 10285 | K1615: 10100 | L1615: 518080 | M1615: 396044 | N1615: 是
A1616: 2014-03-14 | B1616: 10171 | C1616: 10200 | D1616: 10210 | E1616: 10120 | F1616: 45528 | G1616: 52024 | H1616: 10295 | I1616: 10250 | J1616: 10320 | K1616: 10170 | L1616: 727380 | M1616: 394786 | N1616: 是
A1617: 2014-03-17 | B1617: 10171 | C1617: 10165 | D1617: 10290 | E1617: 10140 | F1617: 26120 | G1617: 52644 | H1617: 10325 | I1617: 10310 | J1617: 10345 | K1617: 10245 | L1617: 391802 | M1617: 418680 | N1617: 是
A1618: 2014-03-18 | B1618: 10284 | C1618: 10125 | D1618: 10290 | E1618: 10125 | F1618: 56886 | G1618: 51812 | H1618: 10485 | I1618: 10305 | J1618: 10490 | K1618: 10290 | L1618: 516632 | M1618: 405226 | N1618: 是
A1619: 2014-03-19 | B1619: 10214 | C1619: 10300 | D1619: 10348 | E1619: 10214 | F1619: 36210 | G1619: 48670 | H1619: 10305 | I1619: 10490 | J1619: 10500 | K1619: 10305 | L1619: 440130 | M1619: 368440 | N1619: 是
... A1648: 2014-04-30 | B1648: 10747 | C1648: 10762 | D1648: 10775 | E1648: 10713 | F1648: 79484 | G1648: 125832 | H1648: 10915 | I1648: 10920 | J1648: 10950 | K1648: 10870 | L1648: 314582 | M1648: 402554 | N1648: 是
A1649: 2014-05-01 | H1649: 10915 | I1649: 10915 | J1649: 10915 | K1649: 10915 | L1649: 20 | M1649: 12 | N1649: 否 | O1649: 缺 PP
A1650: 2014-05-05 | B1650: 10847 | C1650: 10750 | D1650: 10848 | E1650: 10675 | F1650: 125622 | G1650: 125364 | H1650: 11075 | I1650: 10915 | J1650: 11085 | K1650: 10885 | L1650: 452940 | M1650: 444228 | N1650: 是
A1651: 2014-05-06 | B1651: 10850 | C1651: 10832 | D1651: 10890 | E1651: 10808 | F1651: 133100 | G1651: 124310 | H1651: 11145 | I1651: 11070 | J1651: 11150 | K1651: 11040 | L1651: 416608 | M1651: 441456 | N1651: 是
A1652: 2014-05-07 | B1652: 10932 | C1652: 10850 | D1652: 10965 | E1652: 10823 | F1652: 171048 | G1652: 112828 | H1652: 11300 | I1652: 11145 | J1652: 11320 | K1652: 11130 | L1652: 562844 | M1652: 469510 | N1652: 是
A1653: 2014-05-08 | B1653: 10872 | C1653: 10955 | D1653: 10955 | E1653: 10843 | F1653: 91622 | G1653: 106412 | H1653: 11250 | I1653: 11300 | J1653: 11340 | K1653: 11210 | L1653: 390540 | M1653: 434270 | N1653: 是
A1654: 2014-05-09 | B1654: 10771 | C1654: 10884 | D1654: 10884 | E1654: 10750 | F1654: 102862 | G1654: 108646 | H1654: 11230 | I1654: 11260 | J1654: 11280 | K1654: 11190 | L1654: 325654 | M1654: 449318 | N1654: 是
A1655: 2014-05-12 | B1655: 10751 | C1655: 10790 | D1655: 10830 | E1655: 10714 | F1655: 125740 | G1655: 104282 | H1655: 11140 | I1655: 11205 | J1655: 11275 | K1655: 11110 | L1655: 425242 | M1655: 423224 | N1655: 是
A1656: 2014-05-13 | B1656: 10780 | C1656: 10773 | D1656: 10786 | E1656: 10725 | F1656: 82388 | G1656: 100942 | H1656: 11180 | I1656: 11140 | J1656: 11215 | K1656: 11120 | L1656: 279196 | M1656: 436962 | N1656: 是
A1657: 2014-05-14 | B1657: 10752 | C1657: 10810 | D1657: 10815 | E1657: 10718 | F1657: 91380 | G1657: 103418 | H1657: 11180 | I1657: 11210 | J1657: 11240 | K1657: 11130 | L1657: 266768 | M1657: 438694 | N1657: 是
A1658: 2014-05-15 | B1658: 10676 | C1658: 10740 | D1658: 10740 | E1658: 10667 | F1658: 111384 | G1658: 109596 | H1658: 11100 | I1658: 11180 | J1658: 11205 | K1658: 11090 | L1658: 324448 | M1658: 442570 | N1658: 是
A1659: 2014-05-16 | B1659: 10691 | C1659: 10665 | D1659: 10692 | E1659: 10600 | F1659: 113124 | G1659: 119902 | H1659: 11030 | I1659: 11090 | J1659: 11090 | K1659: 10975 | L1659: 377104 | M1659: 466210 | N1659: 是
...

Sheet 02-比价序列
A1: 比价序列与滚动统计（公式可复算）
A2: 比价 = A收盘/B收盘（原生除法公式）；滚动252日分位与均值用公式从本表历史自动计算；异常点用全样本稳健 z（中位数/MAD），因需整列统计，取值为计算结果。
A4: 日期 | B4: A 收盘 | C4: B 收盘 | D4: 比价 A/B | E4: A/B 取倒数(=B/A) | F4: 日变化 % | G4: 252日滚动分位 % | H4: 252日滚动均值 | I4: 稳健 z | J4: 是否异常 | K4: 是否换月日 | L4: 备注 | M4: 来源行
A5: 2014-02-28 | B5: =IFERROR(VLOOKUP($A5,'01-原始价格'!$A:$M,2,FALSE),"") | C5: =IFERROR(VLOOKUP($A5,'01-原始价格'!$A:$M,8,FALSE),"") | D5: =IFERROR(B5/C5,"") | E5: =IFERROR(C5/B5,"")
A6: 2014-03-03 | B6: =IFERROR(VLOOKUP($A6,'01-原始价格'!$A:$M,2,FALSE),"") | C6: =IFERROR(VLOOKUP($A6,'01-原始价格'!$A:$M,8,FALSE),"") | D6: =IFERROR(B6/C6,"") | E6: =IFERROR(C6/B6,"") | F6: =IFERROR((D6/D5-1)*100,"")
A7: 2014-03-04 | B7: =IFERROR(VLOOKUP($A7,'01-原始价格'!$A:$M,2,FALSE),"") | C7: =IFERROR(VLOOKUP($A7,'01-原始价格'!$A:$M,8,FALSE),"") | D7: =IFERROR(B7/C7,"") | E7: =IFERROR(C7/B7,"") | F7: =IFERROR((D7/D6-1)*100,"")
A8: 2014-03-05 | B8: =IFERROR(VLOOKUP($A8,'01-原始价格'!$A:$M,2,FALSE),"") | C8: =IFERROR(VLOOKUP($A8,'01-原始价格'!$A:$M,8,FALSE),"") | D8: =IFERROR(B8/C8,"") | E8: =IFERROR(C8/B8,"") | F8: =IFERROR((D8/D7-1)*100,"")
A9: 2014-03-06 | B9: =IFERROR(VLOOKUP($A9,'01-原始价格'!$A:$M,2,FALSE),"") | C9: =IFERROR(VLOOKUP($A9,'01-原始价格'!$A:$M,8,FALSE),"") | D9: =IFERROR(B9/C9,"") | E9: =IFERROR(C9/B9,"") | F9: =IFERROR((D9/D8-1)*100,"")
A10: 2014-03-10 | B10: =IFERROR(VLOOKUP($A10,'01-原始价格'!$A:$M,2,FALSE),"") | C10: =IFERROR(VLOOKUP($A10,'01-原始价格'!$A:$M,8,FALSE),"") | D10: =IFERROR(B10/C10,"") | E10: =IFERROR(C10/B10,"") | F10: =IFERROR((D10/D9-1)*100,"")
A11: 2014-03-11 | B11: =IFERROR(VLOOKUP($A11,'01-原始价格'!$A:$M,2,FALSE),"") | C11: =IFERROR(VLOOKUP($A11,'01-原始价格'!$A:$M,8,FALSE),"") | D11: =IFERROR(B11/C11,"") | E11: =IFERROR(C11/B11,"") | F11: =IFERROR((D11/D10-1)*100,"")
A12: 2014-03-12 | B12: =IFERROR(VLOOKUP($A12,'01-原始价格'!$A:$M,2,FALSE),"") | C12: =IFERROR(VLOOKUP($A12,'01-原始价格'!$A:$M,8,FALSE),"") | D12: =IFERROR(B12/C12,"") | E12: =IFERROR(C12/B12,"") | F12: =IFERROR((D12/D11-1)*100,"")
A13: 2014-03-14 | B13: =IFERROR(VLOOKUP($A13,'01-原始价格'!$A:$M,2,FALSE),"") | C13: =IFERROR(VLOOKUP($A13,'01-原始价格'!$A:$M,8,FALSE),"") | D13: =IFERROR(B13/C13,"") | E13: =IFERROR(C13/B13,"") | F13: =IFERROR((D13/D12-1)*100,"")
A14: 2014-03-17 | B14: =IFERROR(VLOOKUP($A14,'01-原始价格'!$A:$M,2,FALSE),"") | C14: =IFERROR(VLOOKUP($A14,'01-原始价格'!$A:$M,8,FALSE),"") | D14: =IFERROR(B14/C14,"") | E14: =IFERROR(C14/B14,"") | F14: =IFERROR((D14/D13-1)*100,"")
A15: 2014-03-18 | B15: =IFERROR(VLOOKUP($A15,'01-原始价格'!$A:$M,2,FALSE),"") | C15: =IFERROR(VLOOKUP($A15,'01-原始价格'!$A:$M,8,FALSE),"") | D15: =IFERROR(B15/C15,"") | E15: =IFERROR(C15/B15,"") | F15: =IFERROR((D15/D14-1)*100,"")
A16: 2014-03-19 | B16: =IFERROR(VLOOKUP($A16,'01-原始价格'!$A:$M,2,FALSE),"") | C16: =IFERROR(VLOOKUP($A16,'01-原始价格'!$A:$M,8,FALSE),"") | D16: =IFERROR(B16/C16,"") | E16: =IFERROR(C16/B16,"") | F16: =IFERROR((D16/D15-1)*100,"")
A17: 2014-03-20 | B17: =IFERROR(VLOOKUP($A17,'01-原始价格'!$A:$M,2,FALSE),"") | C17: =IFERROR(VLOOKUP($A17,'01-原始价格'!$A:$M,8,FALSE),"") | D17: =IFERROR(B17/C17,"") | E17: =IFERROR(C17/B17,"") | F17: =IFERROR((D17/D16-1)*100,"")
... A124: 2014-08-22 | B124: =IFERROR(VLOOKUP($A124,'01-原始价格'!$A:$M,2,FALSE),"") | C124: =IFERROR(VLOOKUP($A124,'01-原始价格'!$A:$M,8,FALSE),"") | D124: =IFERROR(B124/C124,"") | E124: =IFERROR(C124/B124,"") | F124: =IFERROR((D124/D123-1)*100,"")
A125: 2014-08-25 | B125: =IFERROR(VLOOKUP($A125,'01-原始价格'!$A:$M,2,FALSE),"") | C125: =IFERROR(VLOOKUP($A125,'01-原始价格'!$A:$M,8,FALSE),"") | D125: =IFERROR(B125/C125,"") | E125: =IFERROR(C125/B125,"") | F125: =IFERROR((D125/D124-1)*100,"") | I125: 0.31238163
A126: 2014-08-26 | B126: =IFERROR(VLOOKUP($A126,'01-原始价格'!$A:$M,2,FALSE),"") | C126: =IFERROR(VLOOKUP($A126,'01-原始价格'!$A:$M,8,FALSE),"") | D126: =IFERROR(B126/C126,"") | E126: =IFERROR(C126/B126,"") | F126: =IFERROR((D126/D125-1)*100,"") | I126: 0.44898287
A127: 2014-08-27 | B127: =IFERROR(VLOOKUP($A127,'01-原始价格'!$A:$M,2,FALSE),"") | C127: =IFERROR(VLOOKUP($A127,'01-原始价格'!$A:$M,8,FALSE),"") | D127: =IFERROR(B127/C127,"") | E127: =IFERROR(C127/B127,"") | F127: =IFERROR((D127/D126-1)*100,"") | I127: 0.543813
A128: 2014-08-28 | B128: =IFERROR(VLOOKUP($A128,'01-原始价格'!$A:$M,2,FALSE),"") | C128: =IFERROR(VLOOKUP($A128,'01-原始价格'!$A:$M,8,FALSE),"") | D128: =IFERROR(B128/C128,"") | E128: =IFERROR(C128/B128,"") | F128: =IFERROR((D128/D127-1)*100,"") | I128: 0.46060664
A129: 2014-08-29 | B129: =IFERROR(VLOOKUP($A129,'01-原始价格'!$A:$M,2,FALSE),"") | C129: =IFERROR(VLOOKUP($A129,'01-原始价格'!$A:$M,8,FALSE),"") | D129: =IFERROR(B129/C129,"") | E129: =IFERROR(C129/B129,"") | F129: =IFERROR((D129/D128-1)*100,"") | I129: 0.55284936
A130: 2014-09-01 | B130: =IFERROR(VLOOKUP($A130,'01-原始价格'!$A:$M,2,FALSE),"") | C130: =IFERROR(VLOOKUP($A130,'01-原始价格'!$A:$M,8,FALSE),"") | D130: =IFERROR(B130/C130,"") | E130: =IFERROR(C130/B130,"") | F130: =IFERROR((D130/D129-1)*100,"") | I130: 0.34907893
A131: 2014-09-02 | B131: =IFERROR(VLOOKUP($A131,'01-原始价格'!$A:$M,2,FALSE),"") | C131: =IFERROR(VLOOKUP($A131,'01-原始价格'!$A:$M,8,FALSE),"") | D131: =IFERROR(B131/C131,"") | E131: =IFERROR(C131/B131,"") | F131: =IFERROR((D131/D130-1)*100,"") | I131: 0.24333754
A132: 2014-09-03 | B132: =IFERROR(VLOOKUP($A132,'01-原始价格'!$A:$M,2,FALSE),"") | C132: =IFERROR(VLOOKUP($A132,'01-原始价格'!$A:$M,8,FALSE),"") | D132: =IFERROR(B132/C132,"") | E132: =IFERROR(C132/B132,"") | F132: =IFERROR((D132/D131-1)*100,"") | I132: 0.51727918
A133: 2014-09-04 | B133: =IFERROR(VLOOKUP($A133,'01-原始价格'!$A:$M,2,FALSE),"") | C133: =IFERROR(VLOOKUP($A133,'01-原始价格'!$A:$M,8,FALSE),"") | D133: =IFERROR(B133/C133,"") | E133: =IFERROR(C133/B133,"") | F133: =IFERROR((D133/D132-1)*100,"") | I133: 0.44131837
A134: 2014-09-05 | B134: =IFERROR(VLOOKUP($A134,'01-原始价格'!$A:$M,2,FALSE),"") | C134: =IFERROR(VLOOKUP($A134,'01-原始价格'!$A:$M,8,FALSE),"") | D134: =IFERROR(B134/C134,"") | E134: =IFERROR(C134/B134,"") | F134: =IFERROR((D134/D133-1)*100,"") | I134: 0.40046977
A135: 2014-09-09 | B135: =IFERROR(VLOOKUP($A135,'01-原始价格'!$A:$M,2,FALSE),"") | C135: =IFERROR(VLOOKUP($A135,'01-原始价格'!$A:$M,8,FALSE),"") | D135: =IFERROR(B135/C135,"") | E135: =IFERROR(C135/B135,"") | F135: =IFERROR((D135/D134-1)*100,"") | I135: 0.795687
A136: 2014-09-10 | B136: =IFERROR(VLOOKUP($A136,'01-原始价格'!$A:$M,2,FALSE),"") | C136: =IFERROR(VLOOKUP($A136,'01-原始价格'!$A:$M,8,FALSE),"") | D136: =IFERROR(B136/C136,"") | E136: =IFERROR(C136/B136,"") | F136: =IFERROR((D136/D135-1)*100,"") | I136: 0.83593025
... A183: 2014-11-24 | B183: =IFERROR(VLOOKUP($A183,'01-原始价格'!$A:$M,2,FALSE),"") | C183: =IFERROR(VLOOKUP($A183,'01-原始价格'!$A:$M,8,FALSE),"") | D183: =IFERROR(B183/C183,"") | E183: =IFERROR(C183/B183,"") | F183: =IFERROR((D183/D182-1)*100,"") | I183: 0.66334903
A184: 2014-11-25 | B184: =IFERROR(VLOOKUP($A184,'01-原始价格'!$A:$M,2,FALSE),"") | C184: =IFERROR(VLOOKUP($A184,'01-原始价格'!$A:$M,8,FALSE),"") | D184: =IFERROR(B184/C184,"") | E184: =IFERROR(C184/B184,"") | F184: =IFERROR((D184/D183-1)*100,"") | I184: -4.0090332 | J184: 是 | L184: 统计异常
A185: 2014-11-26 | B185: =IFERROR(VLOOKUP($A185,'01-原始价格'!$A:$M,2,FALSE),"") | C185: =IFERROR(VLOOKUP($A185,'01-原始价格'!$A:$M,8,FALSE),"") | D185: =IFERROR(B185/C185,"") | E185: =IFERROR(C185/B185,"") | F185: =IFERROR((D185/D184-1)*100,"") | I185: -4.3847836 | J185: 是 | L185: 统计异常
A186: 2014-11-27 | B186: =IFERROR(VLOOKUP($A186,'01-原始价格'!$A:$M,2,FALSE),"") | C186: =IFERROR(VLOOKUP($A186,'01-原始价格'!$A:$M,8,FALSE),"") | D186: =IFERROR(B186/C186,"") | E186: =IFERROR(C186/B186,"") | F186: =IFERROR((D186/D185-1)*100,"") | I186: -4.2840424 | J186: 是 | L186: 统计异常
A187: 2014-11-28 | B187: =IFERROR(VLOOKUP($A187,'01-原始价格'!$A:$M,2,FALSE),"") | C187: =IFERROR(VLOOKUP($A187,'01-原始价格'!$A:$M,8,FALSE),"") | D187: =IFERROR(B187/C187,"") | E187: =IFERROR(C187/B187,"") | F187: =IFERROR((D187/D186-1)*100,"") | I187: -4.2209543 | J187: 是 | L187: 统计异常
A188: 2014-12-01 | B188: =IFERROR(VLOOKUP($A188,'01-原始价格'!$A:$M,2,FALSE),"") | C188: =IFERROR(VLOOKUP($A188,'01-原始价格'!$A:$M,8,FALSE),"") | D188: =IFERROR(B188/C188,"") | E188: =IFERROR(C188/B188,"") | F188: =IFERROR((D188/D187-1)*100,"") | I188: -0.088680829
A189: 2014-12-02 | B189: =IFERROR(VLOOKUP($A189,'01-原始价格'!$A:$M,2,FALSE),"") | C189: =IFERROR(VLOOKUP($A189,'01-原始价格'!$A:$M,8,FALSE),"") | D189: =IFERROR(B189/C189,"") | E189: =IFERROR(C189/B189,"") | F189: =IFERROR((D189/D188-1)*100,"") | I189: -0.14403374
A190: 2014-12-03 | B190: =IFERROR(VLOOKUP($A190,'01-原始价格'!$A:$M,2,FALSE),"") | C190: =IFERROR(VLOOKUP($A190,'01-原始价格'!$A:$M,8,FALSE),"") | D190: =IFERROR(B190/C190,"") | E190: =IFERROR(C190/B190,"") | F190: =IFERROR((D190/D189-1)*100,"") | I190: -0.39390433
A191: 2014-12-04 | B191: =IFERROR(VLOOKUP($A191,'01-原始价格'!$A:$M,2,FALSE),"") | C191: =IFERROR(VLOOKUP($A191,'01-原始价格'!$A:$M,8,FALSE),"") | D191: =IFERROR(B191/C191,"") | E191: =IFERROR(C191/B191,"") | F191: =IFERROR((D191/D190-1)*100,"") | I191: -0.36669365
A192: 2014-12-05 | B192: =IFERROR(VLOOKUP($A192,'01-原始价格'!$A:$M,2,FALSE),"") | C192: =IFERROR(VLOOKUP($A192,'01-原始价格'!$A:$M,8,FALSE),"") | D192: =IFERROR(B192/C192,"") | E192: =IFERROR(C192/B192,"") | F192: =IFERROR((D192/D191-1)*100,"") | I192: -0.63225538
A193: 2014-12-08 | B193: =IFERROR(VLOOKUP($A193,'01-原始价格'!$A:$M,2,FALSE),"") | C193: =IFERROR(VLOOKUP($A193,'01-原始价格'!$A:$M,8,FALSE),"") | D193: =IFERROR(B193/C193,"") | E193: =IFERROR(C193/B193,"") | F193: =IFERROR((D193/D192-1)*100,"") | I193: -0.49898545
...

Sheet 03-窗口统计
A1: 窗口统计：1年 / 3年 / 5年 / 全样本
A2: 分位与统计量均以 02-比价序列 的比价列为输入，用 Excel 原生公式按窗口区间计算；N 为该窗口内有效交易日数。
A4: 窗口 | B4: 起始日 | C4: 结束日 | D4: N | E4: 均值 | F4: 中位数 | G4: 最低 | H4: 最低日期 | I4: 最高 | J4: 最高日期 | K4: 当前值分位 % | L4: 当前值
A5: 近1年 | B5: 2025-10-20 | C5: 2026-10-20 | D5: =COUNT('02-比价序列'!$D$2831:$D$3073) | E5: =IFERROR(AVERAGE('02-比价序列'!$D$2831:$D$3073),"") | F5: =IFERROR(MEDIAN('02-比价序列'!$D$2831:$D$3073),"") | G5: =IFERROR(MIN('02-比价序列'!$D$2831:$D$3073),"") | H5: 2025-12-10 | I5: =IFERROR(MAX('02-比价序列'!$D$2831:$D$3073),"") | J5: 2026-05-19 | K5: =IFERROR((COUNTIF('02-比价序列'!$D$2831:$D$3073,"<"&$L5)+0.5*COUNTIF('02-比价序列'!$D$2831:$D$3073,$L5))/COUNT('02-比价序列'!$D$2831:$D$3073)*100,"") | L5: 1.07449
A6: 近3年 | B6: 2023-10-20 | C6: 2026-10-20 | D6: =COUNT('02-比价序列'!$D$2348:$D$3073) | E6: =IFERROR(AVERAGE('02-比价序列'!$D$2348:$D$3073),"") | F6: =IFERROR(MEDIAN('02-比价序列'!$D$2348:$D$3073),"") | G6: =IFERROR(MIN('02-比价序列'!$D$2348:$D$3073),"") | H6: 2024-12-02 | I6: =IFERROR(MAX('02-比价序列'!$D$2348:$D$3073),"") | J6: 2026-05-19 | K6: =IFERROR((COUNTIF('02-比价序列'!$D$2348:$D$3073,"<"&$L6)+0.5*COUNTIF('02-比价序列'!$D$2348:$D$3073,$L6))/COUNT('02-比价序列'!$D$2348:$D$3073)*100,"") | L6: 1.07449
A7: 近5年 | B7: 2021-10-20 | C7: 2026-10-20 | D7: =COUNT('02-比价序列'!$D$1862:$D$3073) | E7: =IFERROR(AVERAGE('02-比价序列'!$D$1862:$D$3073),"") | F7: =IFERROR(MEDIAN('02-比价序列'!$D$1862:$D$3073),"") | G7: =IFERROR(MIN('02-比价序列'!$D$1862:$D$3073),"") | H7: 2024-12-02 | I7: =IFERROR(MAX('02-比价序列'!$D$1862:$D$3073),"") | J7: 2026-05-19 | K7: =IFERROR((COUNTIF('02-比价序列'!$D$1862:$D$3073,"<"&$L7)+0.5*COUNTIF('02-比价序列'!$D$1862:$D$3073,$L7))/COUNT('02-比价序列'!$D$1862:$D$3073)*100,"") | L7: 1.07449
A8: 全样本 | B8: 2014-02-28 | C8: 2026-10-20 | D8: =COUNT('02-比价序列'!$D$5:$D$3073) | E8: =IFERROR(AVERAGE('02-比价序列'!$D$5:$D$3073),"") | F8: =IFERROR(MEDIAN('02-比价序列'!$D$5:$D$3073),"") | G8: =IFERROR(MIN('02-比价序列'!$D$5:$D$3073),"") | H8: 2015-11-25 | I8: =IFERROR(MAX('02-比价序列'!$D$5:$D$3073),"") | J8: 2019-08-06 | K8: =IFERROR((COUNTIF('02-比价序列'!$D$5:$D$3073,"<"&$L8)+0.5*COUNTIF('02-比价序列'!$D$5:$D$3073,$L8))/COUNT('02-比价序列'!$D$5:$D$3073)*100,"") | L8: 1.07449
A9: 当前值（唯一）
A11: 说明：分位 = 窗口内比价 ≤ 当前值的交易日数 / 窗口内有效交易日数（ECDF）。不采用 (当前-最低)/(最高-最低) 的线性反推，因为那会把分布形状全部丢掉。

Sheet 04-分位口径对照
A1: 同一个当前值，在不同样本定义下的分位
A2: 这张表是本分析最重要的风险提示：分位不是比价的固有属性，而是样本选择的函数。
A4: 样本定义 | B4: N | C4: 当前值分位 % | D4: 解读
A5: 近1年 | B5: 243 | C5: 89.09465 | D5: 偏高
A6: 近3年 | B6: 726 | C6: 96.349862 | D6: 偏高
A7: 近5年 | B7: 1212 | C7: 97.813531 | D7: 偏高
A8: 全样本 | B8: 3069 | C8: 90.990551 | D8: 偏高
A9: 全样本剔除近120个交易日 | B9: 2950 | C9: 91.525424 | D9: 偏高
A10: 2014-2017 区间内 | B10: 938 | C10: 100 | D10: 样本内几乎最高：该样本区间与当前结构不同
A11: 2018-2022 区间内 | B11: 1214 | C11: 79.406919 | D11: 居中
A12: 2023-2025 区间内 | B12: 727 | C12: 100 | D12: 样本内几乎最高：该样本区间与当前结构不同
A14: 分位区间 | C14: 79.4% ~ 100.0%
A16: 结论用法：报告必须写明所用样本口径；若不同口径给出的分位差异超过 15 个百分点，就不能用「历史高位」作为单一论据。

Sheet 05-贡献分解
A1: 贡献分解：比价变化来自哪一边
A2: 恒等式：Δln(A/B) = ΔlnA − ΔlnB。份额 = |ΔlnA| / (|ΔlnA|+|ΔlnB|)，回答谁主导；方向看涨跌正负。份额列与比价列均为 Excel 公式。
A4: 区间 | B4: 起始日 | C4: 结束日 | D4: A 起 | E4: A 止 | F4: A 涨跌 % | G4: B 起 | H4: B 止 | I4: B 涨跌 % | J4: 比价变化 % | K4: 主导方
A5: 近1月 | B5: 2026-09-14 | C5: 2026-10-20 | D5: 8876 | E5: 9376 | F5: =(E5/D5-1)*100 | G5: 8579 | H5: 8726 | I5: =(H5/G5-1)*100 | J5: =((E5/D5)/(H5/G5)-1)*100 | K5: A
A6: 近3月 | B6: 2026-07-20 | C6: 2026-10-20 | D6: 8462 | E6: 9376 | F6: =(E6/D6-1)*100 | G6: 7940 | H6: 8726 | I6: =(H6/G6-1)*100 | J6: =((E6/D6)/(H6/G6)-1)*100 | K6: A
A7: 近6月 | B7: 2026-04-21 | C7: 2026-10-20 | D7: 8220 | E7: 9376 | F7: =(E7/D7-1)*100 | G7: 7981 | H7: 8726 | I7: =(H7/G7-1)*100 | J7: =((E7/D7)/(H7/G7)-1)*100 | K7: A
A8: 近1年 | B8: 2025-10-20 | C8: 2026-10-20 | D8: 6565 | E8: 9376 | F8: =(E8/D8-1)*100 | G8: 6879 | H8: 8726 | I8: =(H8/G8-1)*100 | J8: =((E8/D8)/(H8/G8)-1)*100 | K8: A
A9: 近3年 | B9: 2023-10-20 | C9: 2026-10-20 | D9: 7441 | E9: 9376 | F9: =(E9/D9-1)*100 | G9: 7954 | H9: 8726 | I9: =(H9/G9-1)*100 | J9: =((E9/D9)/(H9/G9)-1)*100 | K9: A
A10: 近5年 | B10: 2021-10-20 | C10: 2026-10-20 | D10: 9202 | E10: 9376 | F10: =(E10/D10-1)*100 | G10: 9210 | H10: 8726 | I10: =(H10/G10-1)*100 | J10: =((E10/D10)/(H10/G10)-1)*100 | K10: B
A11: 全样本 | B11: 2014-02-28 | C11: 2026-10-20 | D11: 10657 | E11: 9376 | F11: =(E11/D11-1)*100 | G11: 10765 | H11: 8726 | I11: =(H11/G11-1)*100 | J11: =((E11/D11)/(H11/G11)-1)*100 | K11: B
A13: 对数贡献份额（|ΔlnA| 与 |ΔlnB| 各自占比）
A14: 区间 | B14: ΔlnA | C14: ΔlnB | D14: A 份额 % | E14: B 份额 % | F14: 主导方 | G14: 主导份额 %
A15: 近1月 | B15: =LN(E5/D5) | C15: =LN(H5/G5) | D15: =ABS(B15)/(ABS(B15)+ABS(C15))*100 | E15: =ABS(C15)/(ABS(B15)+ABS(C15))*100 | F15: =IF(ABS(B15)>=ABS(C15),"PP","L") | G15: =MAX(D15:E15)
A16: 近3月 | B16: =LN(E6/D6) | C16: =LN(H6/G6) | D16: =ABS(B16)/(ABS(B16)+ABS(C16))*100 | E16: =ABS(C16)/(ABS(B16)+ABS(C16))*100 | F16: =IF(ABS(B16)>=ABS(C16),"PP","L") | G16: =MAX(D16:E16)
A17: 近6月 | B17: =LN(E7/D7) | C17: =LN(H7/G7) | D17: =ABS(B17)/(ABS(B17)+ABS(C17))*100 | E17: =ABS(C17)/(ABS(B17)+ABS(C17))*100 | F17: =IF(ABS(B17)>=ABS(C17),"PP","L") | G17: =MAX(D17:E17)
A18: 近1年 | B18: =LN(E8/D8) | C18: =LN(H8/G8) | D18: =ABS(B18)/(ABS(B18)+ABS(C18))*100 | E18: =ABS(C18)/(ABS(B18)+ABS(C18))*100 | F18: =IF(ABS(B18)>=ABS(C18),"PP","L") | G18: =MAX(D18:E18)
A19: 近3年 | B19: =LN(E9/D9) | C19: =LN(H9/G9) | D19: =ABS(B19)/(ABS(B19)+ABS(C19))*100 | E19: =ABS(C19)/(ABS(B19)+ABS(C19))*100 | F19: =IF(ABS(B19)>=ABS(C19),"PP","L") | G19: =MAX(D19:E19)
A20: 近5年 | B20: =LN(E10/D10) | C20: =LN(H10/G10) | D20: =ABS(B20)/(ABS(B20)+ABS(C20))*100 | E20: =ABS(C20)/(ABS(B20)+ABS(C20))*100 | F20: =IF(ABS(B20)>=ABS(C20),"PP","L") | G20: =MAX(D20:E20)
A21: 全样本 | B21: =LN(E11/D11) | C21: =LN(H11/G11) | D21: =ABS(B21)/(ABS(B21)+ABS(C21))*100 | E21: =ABS(C21)/(ABS(B21)+ABS(C21))*100 | F21: =IF(ABS(B21)>=ABS(C21),"PP","L") | G21: =MAX(D21:E21)
A23: 读法：份额接近 50/50 说明两边力度相当，比价几乎不动——这仍然是「两边都在动」，不能说成「比价没反应所以无关」。份额悬殊则说明是单边主导。

Sheet 06-异常点
A1: 比价异常点（稳健 z 分数）
A2: 稳健 z 分数（滚动 120 日中位数/MAD），|z| > 3.5；共 100 个 / 评估 3069 个交易日（3.3%）。
A4: 日期 | B4: 比价 | C4: 稳健 z | D4: 是否换月日 | E4: 性质判断 | F4: 处理建议
A5: 2014-11-25 | B5: 0.89616162 | C5: -4.0090332 | D5: 否 | E5: 价格真实异动 | F5: 需回到当日两侧产业信息解释
A6: 2014-11-26 | B6: 0.88748739 | C6: -4.3847836 | D6: 否 | E6: 价格真实异动 | F6: 需回到当日两侧产业信息解释
A7: 2014-11-27 | B7: 0.88719758 | C7: -4.2840424 | D7: 否 | E7: 价格真实异动 | F7: 需回到当日两侧产业信息解释
A8: 2014-11-28 | B8: 0.88563996 | C8: -4.2209543 | D8: 否 | E8: 价格真实异动 | F8: 需回到当日两侧产业信息解释
A9: 2015-01-06 | B9: 0.89082297 | C9: -4.2105958 | D9: 否 | E9: 价格真实异动 | F9: 需回到当日两侧产业信息解释
A10: 2015-01-07 | B10: 0.88687351 | C10: -4.41096 | D10: 否 | E10: 价格真实异动 | F10: 需回到当日两侧产业信息解释
A11: 2015-01-08 | B11: 0.89131484 | C11: -4.1856425 | D11: 否 | E11: 价格真实异动 | F11: 需回到当日两侧产业信息解释
A12: 2015-01-09 | B12: 0.88326127 | C12: -4.5942158 | D12: 否 | E12: 价格真实异动 | F12: 需回到当日两侧产业信息解释
A13: 2015-01-12 | B13: 0.89701121 | C13: -3.8966543 | D13: 否 | E13: 价格真实异动 | F13: 需回到当日两侧产业信息解释
A14: 2015-01-13 | B14: 0.89793879 | C14: -3.8495964 | D14: 否 | E14: 价格真实异动 | F14: 需回到当日两侧产业信息解释
A15: 2015-01-14 | B15: 0.88603077 | C15: -4.4537138 | D15: 否 | E15: 价格真实异动 | F15: 需回到当日两侧产业信息解释
A16: 2015-01-15 | B16: 0.87488038 | C16: -5.019395 | D16: 否 | E16: 价格真实异动 | F16: 需回到当日两侧产业信息解释
... A104: 2026-04-03 | B104: 1.0683032 | C104: 3.5174065 | D104: 否 | E104: 价格真实异动 | F104: 需回到当日两侧产业信息解释

Sheet 07-换月台账
A1: 换月台账：主连切换日与新旧合约价差
A2: 共 45 次换月。价差 =（旧合约收盘 − 新合约收盘）/ 新合约收盘；该价差就是换月当天比价被污染的近似幅度。
A4: 换月日 | B4: 旧合约 | C4: 新合约 | D4: 新旧价差 % | E4: 对当日比价的影响
A5: 2019-04-01 | B5: L1905 | C5: L1909 | D5: 1.9903498 | E5: 影响有限
A6: 2019-04-04 | B6: PP1905 | C6: PP1909 | D6: 3.0997778 | E6: 跳空较大，当日比价变动需剔除
A7: 2019-08-08 | B7: PP1909 | C7: PP2001 | D7: 5.1769088 | E7: 跳空较大，当日比价变动需剔除
A8: 2019-08-12 | B8: L1909 | C8: L2001 | D8: -0.3298153 | E8: 影响有限
A9: 2019-12-09 | B9: L2001 | C9: L2005 | D9: -0.20618557 | E9: 影响有限
A10: 2019-12-12 | B10: PP2001 | C10: PP2005 | D10: 4.3938592 | E10: 跳空较大，当日比价变动需剔除
A11: 2020-04-01 | B11: L2005 | C11: L2009 | D11: 0.8984726 | E11: 影响有限
A12: 2020-04-03 | B12: PP2005 | C12: PP2009 | D12: 1.5491622 | E12: 影响有限
A13: 2020-08-19 | B13: L2009 | C13: L2101 | D13: -0.28011204 | E13: 影响有限
A14: 2020-08-20 | B14: PP2009 | C14: PP2101 | D14: 0.46692607 | E14: 影响有限
A15: 2020-12-16 | B15: L2101 | C15: L2105 | D15: -0.63897764 | E15: 影响有限
A16: 2021-04-14 | B16: L2105 | C16: L2109 | D16: 0 | E16: 影响有限
... A49: 2026-08-18 | B49: L2609 | C49: L2701 | D49: 5.0198999 | E49: 跳空较大，当日比价变动需剔除

Sheet 08-分年统计
A1: 逐年统计：中枢在哪里移动
A2: 看中枢是否有台阶式迁移，而不是只看单年高低。
A4: 年份 | B4: N | C4: 均值 | D4: 中位数 | E4: 最低 | F4: 最高 | G4: 年内末值 | H4: 末值在年内分位 %
A5: 2014 | B5: 206 | C5: 0.96871286 | D5: 0.97362194 | E5: 0.88563996 | F5: 1.0152886 | G5: 0.92859639 | H5: 5.5825243
A6: 2015 | B6: 245 | C6: 0.8584895 | D6: 0.87659574 | E6: 0.69125 | F6: 0.94317578 | G6: 0.72450249 | H6: 0.6122449
A7: 2016 | B7: 243 | C7: 0.82987875 | D7: 0.82752294 | E7: 0.70907937 | F7: 0.95347181 | G7: 0.89068826 | H7: 80.452675
A8: 2017 | B8: 244 | C8: 0.89897175 | D8: 0.89499965 | E8: 0.84994325 | F8: 0.96098843 | G8: 0.94744898 | H8: 91.598361
A9: 2018 | B9: 243 | C9: 1.0055964 | D9: 0.99935414 | E9: 0.93016912 | F9: 1.0971631 | G9: 1.0004651 | H9: 50.823045
A10: 2019 | B10: 243 | C10: 1.0654476 | D10: 1.0646154 | E10: 0.99776207 | F10: 1.1405369 | G10: 1.0372093 | H10: 32.716049
A11: 2020 | B11: 243 | C11: 1.0667405 | D11: 1.0703039 | E11: 1.0011722 | F11: 1.1402844 | G11: 1.0436528 | H11: 25.720165
A12: 2021 | B12: 243 | C12: 1.0218629 | D12: 1.0323671 | E12: 0.93149916 | F12: 1.0891414 | G12: 0.95552687 | H12: 9.6707819
A13: 2022 | B13: 242 | C13: 0.98211639 | D13: 0.98275867 | E13: 0.94428938 | F13: 1.0451208 | G13: 0.95906361 | H13: 17.14876
A14: 2023 | B14: 242 | C14: 0.92888462 | D14: 0.93170614 | E14: 0.89287057 | F14: 0.97081249 | G14: 0.91304348 | H14: 26.239669
A15: 2024 | B15: 242 | C15: 0.91056296 | D15: 0.90933613 | E15: 0.88652898 | F15: 0.9381532 | G15: 0.91428222 | H15: 65.495868
A16: 2025 | B16: 243 | C16: 0.96078778 | D16: 0.960392 | E16: 0.91805488 | F16: 1.001145 | G16: 0.98084054 | H16: 87.037037
A17: 2026 | B17: 190 | C17: 1.0391499 | D17: 1.0435238 | E17: 0.96627566 | F17: 1.1109179 | G17: 1.07449 | H17: 86.052632

Sheet 09-产业事件台账
A1: 产业事件台账（用于解释，不用于证明因果）
A2: 核对级别：A=有原始报道标题/正文可直接核对；B=有标题但细节需二次确认；C=行业背景/常识，未逐条核实，不得单独支撑结论。方向列是对比价的预期影响方向，不是幅度预测。
A4: 日期 | B4: 影响侧 | C4: 对比价方向 | D4: 核对级别 | E4: 事件 | F4: 来源
A5: 2014-06-30 | B5: BOTH | C5: 压低比价 | D5: C | E5: 2014 年下半年原油自 110 美元/桶区间回落，聚烯烃成本中枢整体下移 | F5: 行业背景（布伦特原油 2014H2 大幅下跌，公开行情可核对）
A6: 2015-11-25 | B6: PP | C6: 压低比价 | D6: C | E6: 比价触及全样本最低 0.6913：PP 端新增产能（煤制烯烃/PDH）集中释放，PP 相对 PE 明显走弱 | F6: 比价数据（本研究报告 result.json）
A7: 2016-12-31 | B7: BOTH | C7: 中性 | D7: C | E7: OPEC 减产协议生效，原油自低位回升，聚烯烃成本端重新抬升 | F7: 行业背景（2016-11-30 OPEC 达成减产，公开新闻可核对）
A8: 2017-11-30 | B8: PE | C8: 推高比价 | D8: B | E8: 结构断点：比价中枢由约 0.88 抬升到约 0.99（Welch t≈42），PP 相对 PE 进入强势期 | F8: 本报告结构扫描（analyze.py structure_scan）
A9: 2018-12-31 | B9: PE | C9: 推高比价 | D9: C | E9: 国内 PE 新增产能集中投放，PE 供应压力大于 PP，比价向 1.0 以上抬升 | F9: 行业背景（PE 扩能周期，需以产能数据二次核对）
A10: 2019-08-06 | B10: PP | C10: 推高比价 | D10: A | E10: 比价触及全样本最高 1.1405（收盘口径）：PP 相对 PE 达历史最贵 | F10: 比价数据（本报告 result.json，PP/L=1.1405）
A11: 2020-02-03 | B11: BOTH | C11: 方向不定 | D11: A | E11: 春节后首个交易日，PP 与 L 双双跳空下跌约 6%（疫情冲击需求预期） | F11: 期货行情（PP/L 主连当日跌幅约 -5.9%/-6.0%，可复核）
A12: 2020-04-23 | B12: BOTH | C12: 方向不定 | D12: A | E12: 原油负价格后反弹，聚烯烃日内暴涨，比价日内高点 1.1448（盘中口径） | F12: 期货行情（当日 PP/L 涨幅约 +6%）
A13: 2021-02-18 | B13: BOTH | C13: 方向不定 | D13: A | E13: 节后聚烯烃集体大涨（PP +6.7%、L +7.6%） | F13: 期货行情（可复核）
A14: 2021-09-15 | B14: BOTH | C14: 方向不定 | D14: A | E14: 能耗双控/限电期间，聚烯烃同步大涨（两者均约 +5%） | F14: 期货行情（可复核）
A15: 2021-09-30 | B15: BOTH | C15: 中性 | D15: A | E15: 2021 年三季末 PP 与 L 同时冲到 9900-10150 元/吨区间，比价仍在 1.02 附近——同涨不改变比价 | F15: 本报告贡献分解（2019-10 → 2021-09：PP +27.8%、L +35.9%）
... A38: 2026-10-16 | B38: PE | C38: 压低比价 | D38: A | E38: 聚乙烯：供需格局转松，价格承压下行；PP 端为供应收缩、库存低位 | F38: 隆众资讯《聚乙烯》栏目（2026-10-16）；《隆众聚焦·供应收缩产业链库存低位》

Sheet 10-数据来源
A1: 数据来源与可得性
A2: 每个字段的来源、口径与已知问题；缺什么、为什么缺，都写在这里。
A4: 项目 | B4: 内容 | C4: 状态 | D4: 备注
A5: 接口地址 | B5: https://stock2.finance.sina.com.cn/futures/api/jsonp.php/var%20_{SYM}=/InnerFuturesNewService.getDailyKLine?symbol={SYM} | C5: 可用 | D5: SYM 取 PP0 / L0 为主连
A6: 实时快照 | B6: https://hq.sinajs.cn/list=nf_L0,nf_PP0 | C6: 可用 | D6: 需 Referer: finance.sina.com.cn，GBK 解码
A7: 价格类型 | B7: 期货主力连续日线（未复权） | C7: 可用 | D7: 非结算价；收盘价口径
A8: 单位 | B8: 元/吨 | C8: 可用 | D8: 两侧一致
A9: 成交量/持仓量 | B9: 接口返回 | C9: 可用 | D9: 用于判定主力合约
A10: 合约面板 | B10: 单合约日线（L/PP 各月份） | C10: 可用 | D10: 用于换月识别与交叉校验
A11: A 侧覆盖 | B11: 2014-02-28 → 2026-10-20 | C11: 可用 | D11: 3071 个交易日
A12: B 侧覆盖 | B12: 2007-07-31 → 2026-10-20 | C12: 可用 | D12: 4674 个交易日
A13: 共同样本 | B13: 2014-02-28 → 2026-10-20 | C13: 可用 | D13: N=3069；A 独有 2 天、B 独有 1605 天
A14: OHLC 矛盾 | B14: A: 1 处；B: 0 处 | C14: 已标注 | D14: 收盘价仍在高低区间内，不影响比价
A15: 单日涨跌 >15% | B15: A: 0 处；B: 1 处 | C15: 已标注 | D15: 集中在 2008/2015 极端行情
... A19: 末端混合报价 | B19: 数据末端连续序列可能来自临近换月的混合路径 | C19: 已披露 | D19: 当日连续序列持仓/成交高于任一挂牌合约，说明其为多合约混合报价；比价水平不受影响（约 1.07），但不宜用末端单日做精细判断
