Workbook

Sheet 00 说明与红线
A1: 化工期货｜异常月差（近远月价差）扫描工作簿
A2: 数据日 2026-10-20 品种池：甲醇 MA / 纯碱 SA / 聚丙烯 PP / PTA TA
A5: 本工作簿回答的问题 | B5: 1) 各品种主要合约月份与交易所规则；2) 当日全部挂牌合约价格与期限结构；3) 按"近月减远月"口径的月差；4) 同组合同剩余期限的可比历史样本；5) 当前月差、历史分位、近1月变化与极端程度；6) 极端分位排序；7) 异常组合的库存/仓单/交割/供需事件；8) 样本不足与不可比说明。
A6: 月差定义 | B6: 月差 = 近月结算价 − 远月结算价（元/吨）。正值＝近月升水（正向市场 contango）；负值＝近月贴水（反向市场 backwardation）。远月必须晚于近月。
A7: 历史分位 | B7: 在"同一品种 × 同一(近月,远月)月份组合 × 同一剩余期限整周数"的历史样本中，当前月差所处的位置。分位越接近 100% 表示近月相对远月比历史更贵；越接近 0% 表示更便宜。
A8: 可比样本 | B8: 每年取 1 个样本（2022–2026 各年度合约）。剩余期限 = 近月交割月结束日 − 观测日，取整周数 floor(days/7)。不同月份组合分别统计，绝不合并为一个分布。
A9: 数据源 | B9: ① 郑商所每日行情 FutureDataDaily.txt（结算价，官方）；② 郑商所仓单日报 FutureDataWhsheet.txt（仓单，官方）；③ 东方财富 futsseapi list/114（大商所 PP 当日最新价，官网对脚本返回 412）；④ 新浪财经 InnerFuturesNewService.getDailyKLine（逐合约历史日线，276 个合约）。
A10: ⚠ 价格口径差异 | B10: MA/SA/TA 使用交易所结算价；PP 因大商所官网拦截，当日行情为最新价口径。两套口径已在"02 挂牌合约行情"的 price_basis 列分列，不混算。
A11: ⚠ 红线 | B11: ① 不把异常月差直接当作跨期套利/交易建议；② 不合并不同月份组合的分布；③ 样本不足不给分位；④ 不插值、不向前填充、不使用主力连续合约；⑤ 未扣除仓储费、资金成本、交割成本、品级与地区升贴水。
A12: 公式说明 | B12: 黄色底纹单元格为 Excel 原生公式，改动源数据即重算，无宏无加载项。详见「09 公式说明」。
A14: 工作表索引 | B14: 01 合约规则 02 挂牌合约行情 03 期限结构 04 月差计算 05 历史可比样本 06 分位统计 07 产业面 08 供需事件 09 公式说明 10 数据质量与限制

Sheet 01 合约规则
A1: 01 合约规则匹配（交易所规则 + 实测验证）
A2: 规则来源：交易所合约全文（双源交叉）；挂牌月份经 276 个逐合约日线实测验证
A4: 品种 | B4: 名称 | C4: 交易所 | D4: 交易所(英) | E4: 合约月份 | F4: 交易单位 (吨/手) | G4: 最小变动 (元/吨) | H4: 最低保证金 (%) | I4: 涨跌停板 (%) | J4: 最后交易日 | K4: 最后交割日 | L4: 主力锚点 | M4: 特别说明
A5: MA | B5: 甲醇 | C5: 郑州商品交易所 | D5: CZCE | E5: 1–12 月（全年） | F5: 10 | G5: 1 | H5: 5 | I5: 4 | J5: 合约交割月份的第10个交易日 | K5: 合约交割月份的第13个交易日 | L5: 1月/5月/9月 | M5: 危化品交割资质要求（生产/储存/使用/经营/运输）
A6: SA | B6: 纯碱 | C6: 郑州商品交易所 | D6: CZCE | E6: 1–12 月（全年） | F6: 20 | G6: 1 | H6: 5 | I6: 4 | J6: 合约交割月份的第10个交易日 | K6: 合约交割月份的第13个交易日 | L6: 1月/5月/9月 | M6: 基准品为 GB/T 210-2022 II类优等品重质纯碱（NaCl≤0.6%），自 SA2406 起施行
A7: PP | B7: 聚丙烯 | C7: 大连商品交易所 | D7: DCE | E7: 1–12 月（全年） | F7: 5 | G7: 1 | H7: 5 | I7: 4 | J7: 合约月份的第10个交易日 | K7: 最后交易日后第3个交易日 | L7: 1月/5月/9月 | M7: 拉丝/注塑/纤维等交割品级差异，地区升贴水；包装25±0.2kg/袋
A8: TA | B8: PTA | C8: 郑州商品交易所 | D8: CZCE | E8: 1–12 月（全年） | F8: 5 | G8: 2 | H8: 5 | I8: 4 | J8: 合约交割月份的第10个交易日 | K8: 仓库/厂库仓单为交割月第13个交易日；出口型车船板为交割月次月10日 | L8: 1月/5月/9月 | M8: 四条交割路径；品牌制免检；最小变动价位为 2 元/吨（与 MA/SA/PP 的 1 元不同）
A10: 实测验证 | B10: 四个品种均为 1–12 月全月连续挂牌，无跳月设计。各合约上市首日距交割月恒为 12 个月（PP 为 11–12 个月，大商所挂牌略晚）。因此"主力只在 1/5/9"属过度简化：01/05/09 是生命周期锚点，但换月逐月滚动，其余月份同样有可观流动性。

Sheet 02 挂牌合约行情
A1: 02 当日全部挂牌合约行情（含主力标记）
A2: 数据日 2026-10-20 黄色列为公式：距交割月数 / 是否主力 / 合约市值
A4: 合约 | B4: 品种 | C4: 交割年 | D4: 交割月 | E4: 结算价 | F4: 收盘价 | G4: 昨结算 | H4: 涨跌 | I4: 成交量 | J4: 持仓量 | K4: 距交割(月) | L4: 是否主力 | M4: 价格口径
A5: MA2611 | B5: MA | C5: 2026 | D5: 11 | E5: 3347 | F5: 3384 | G5: 3363 | H5: =IF(N("x")="x",E5-G5) -> -16 | I5: 382266 | J5: 155303 | K5: =(C5-YEAR(DATEVALUE("2026-10-20")))*12+(D5-MONTH(DATEVALUE("2026-10-20"))) -> 1 | M5: settle
A6: MA2612 | B6: MA | C6: 2026 | D6: 12 | E6: 3204 | F6: 3231 | G6: 3248 | H6: =IF(N("x")="x",E6-G6) -> -44 | I6: 455161 | J6: 293034 | K6: =(C6-YEAR(DATEVALUE("2026-10-20")))*12+(D6-MONTH(DATEVALUE("2026-10-20"))) -> 2 | M6: settle
A7: MA2701 | B7: MA | C7: 2027 | D7: 1 | E7: 3137 | F7: 3157 | G7: 3179 | H7: =IF(N("x")="x",E7-G7) -> -42 | I7: 2146072 | J7: 860774 | K7: =(C7-YEAR(DATEVALUE("2026-10-20")))*12+(D7-MONTH(DATEVALUE("2026-10-20"))) -> 3 | L7: YES | M7: settle
A8: MA2702 | B8: MA | C8: 2027 | D8: 2 | E8: 3080 | F8: 3093 | G8: 3100 | H8: =IF(N("x")="x",E8-G8) -> -20 | I8: 224848 | J8: 134219 | K8: =(C8-YEAR(DATEVALUE("2026-10-20")))*12+(D8-MONTH(DATEVALUE("2026-10-20"))) -> 4 | M8: settle
A9: MA2703 | B9: MA | C9: 2027 | D9: 3 | E9: 3028 | F9: 3040 | G9: 3050 | H9: =IF(N("x")="x",E9-G9) -> -22 | I9: 197246 | J9: 229089 | K9: =(C9-YEAR(DATEVALUE("2026-10-20")))*12+(D9-MONTH(DATEVALUE("2026-10-20"))) -> 5 | M9: settle
A10: MA2704 | B10: MA | C10: 2027 | D10: 4 | E10: 2976 | F10: 2992 | G10: 3008 | H10: =IF(N("x")="x",E10-G10) -> -32 | I10: 1813 | J10: 2086 | K10: =(C10-YEAR(DATEVALUE("2026-10-20")))*12+(D10-MONTH(DATEVALUE("2026-10-20"))) -> 6 | M10: settle
A11: MA2705 | B11: MA | C11: 2027 | D11: 5 | E11: 2931 | F11: 2941 | G11: 2960 | H11: =IF(N("x")="x",E11-G11) -> -29 | I11: 64668 | J11: 149821 | K11: =(C11-YEAR(DATEVALUE("2026-10-20")))*12+(D11-MONTH(DATEVALUE("2026-10-20"))) -> 7 | M11: settle
A12: MA2706 | B12: MA | C12: 2027 | D12: 6 | E12: 2907 | F12: 2923 | G12: 2937 | H12: =IF(N("x")="x",E12-G12) -> -30 | I12: 394 | J12: 860 | K12: =(C12-YEAR(DATEVALUE("2026-10-20")))*12+(D12-MONTH(DATEVALUE("2026-10-20"))) -> 8 | M12: settle
A13: MA2707 | B13: MA | C13: 2027 | D13: 7 | E13: 2883 | F13: 2895 | G13: 2907 | H13: =IF(N("x")="x",E13-G13) -> -24 | I13: 375 | J13: 1202 | K13: =(C13-YEAR(DATEVALUE("2026-10-20")))*12+(D13-MONTH(DATEVALUE("2026-10-20"))) -> 9 | M13: settle
A14: MA2708 | B14: MA | C14: 2027 | D14: 8 | E14: 2863 | F14: 2876 | G14: 2884 | H14: =IF(N("x")="x",E14-G14) -> -21 | I14: 143 | J14: 828 | K14: =(C14-YEAR(DATEVALUE("2026-10-20")))*12+(D14-MONTH(DATEVALUE("2026-10-20"))) -> 10 | M14: settle
A15: MA2709 | B15: MA | C15: 2027 | D15: 9 | E15: 2844 | F15: 2853 | G15: 2861 | H15: =IF(N("x")="x",E15-G15) -> -17 | I15: 1924 | J15: 3759 | K15: =(C15-YEAR(DATEVALUE("2026-10-20")))*12+(D15-MONTH(DATEVALUE("2026-10-20"))) -> 11 | M15: settle
A16: PP2610 | B16: PP | C16: 2026 | D16: 10 | E16: 10401 | F16: 10450 | G16: 10436 | H16: =IF(N("x")="x",E16-G16) -> -35 | I16: 71 | J16: 5504 | K16: =(C16-YEAR(DATEVALUE("2026-10-20")))*12+(D16-MONTH(DATEVALUE("2026-10-20"))) -> 0 | M16: last
A17: PP2611 | B17: PP | C17: 2026 | D17: 11 | E17: 10144 | F17: 10184 | G17: 10203 | H17: =IF(N("x")="x",E17-G17) -> -59 | I17: 51316 | J17: 99417 | K17: =(C17-YEAR(DATEVALUE("2026-10-20")))*12+(D17-MONTH(DATEVALUE("2026-10-20"))) -> 1 | M17: last
A18: PP2612 | B18: PP | C18: 2026 | D18: 12 | E18: 9685 | F18: 9734 | G18: 9769 | H18: =IF(N("x")="x",E18-G18) -> -84 | I18: 61771 | J18: 133078 | K18: =(C18-YEAR(DATEVALUE("2026-10-20")))*12+(D18-MONTH(DATEVALUE("2026-10-20"))) -> 2 | M18: last
A19: PP2701 | B19: PP | C19: 2027 | D19: 1 | E19: 9331 | F19: 9376 | G19: 9405 | H19: =IF(N("x")="x",E19-G19) -> -74 | I19: 869012 | J19: 672680 | K19: =(C19-YEAR(DATEVALUE("2026-10-20")))*12+(D19-MONTH(DATEVALUE("2026-10-20"))) -> 3 | L19: YES | M19: last
A20: PP2702 | B20: PP | C20: 2027 | D20: 2 | E20: 9028 | F20: 9068 | G20: 9088 | H20: =IF(N("x")="x",E20-G20) -> -60 | I20: 7508 | J20: 57974 | K20: =(C20-YEAR(DATEVALUE("2026-10-20")))*12+(D20-MONTH(DATEVALUE("2026-10-20"))) -> 4 | M20: last
A21: PP2703 | B21: PP | C21: 2027 | D21: 3 | E21: 8819 | F21: 8864 | G21: 8880 | H21: =IF(N("x")="x",E21-G21) -> -61 | I21: 3986 | J21: 17823 | K21: =(C21-YEAR(DATEVALUE("2026-10-20")))*12+(D21-MONTH(DATEVALUE("2026-10-20"))) -> 5 | M21: last
A22: PP2704 | B22: PP | C22: 2027 | D22: 4 | E22: 8800 | F22: 8814 | G22: 8854 | H22: =IF(N("x")="x",E22-G22) -> -54 | I22: 297 | J22: 560 | K22: =(C22-YEAR(DATEVALUE("2026-10-20")))*12+(D22-MONTH(DATEVALUE("2026-10-20"))) -> 6 | M22: last
A23: PP2705 | B23: PP | C23: 2027 | D23: 5 | E23: 8690 | F23: 8695 | G23: 8769 | H23: =IF(N("x")="x",E23-G23) -> -79 | I23: 31910 | J23: 84791 | K23: =(C23-YEAR(DATEVALUE("2026-10-20")))*12+(D23-MONTH(DATEVALUE("2026-10-20"))) -> 7 | M23: last
A24: PP2706 | B24: PP | C24: 2027 | D24: 6 | E24: 8511 | F24: 8586 | G24: 8619 | H24: =IF(N("x")="x",E24-G24) -> -108 | I24: 14 | J24: 247 | K24: =(C24-YEAR(DATEVALUE("2026-10-20")))*12+(D24-MONTH(DATEVALUE("2026-10-20"))) -> 8 | M24: last
A25: PP2707 | B25: PP | C25: 2027 | D25: 7 | E25: 8456 | F25: 8400 | G25: 8550 | H25: =IF(N("x")="x",E25-G25) -> -94 | I25: 9 | J25: 656 | K25: =(C25-YEAR(DATEVALUE("2026-10-20")))*12+(D25-MONTH(DATEVALUE("2026-10-20"))) -> 9 | M25: last
A26: PP2708 | B26: PP | C26: 2027 | D26: 8 | E26: 8440 | F26: 8500 | G26: 8478 | H26: =IF(N("x")="x",E26-G26) -> -38 | I26: 26 | J26: 399 | K26: =(C26-YEAR(DATEVALUE("2026-10-20")))*12+(D26-MONTH(DATEVALUE("2026-10-20"))) -> 10 | M26: last
A27: PP2709 | B27: PP | C27: 2027 | D27: 9 | E27: 8400 | F27: 8384 | G27: 8421 | H27: =IF(N("x")="x",E27-G27) -> -21 | I27: 246 | J27: 904 | K27: =(C27-YEAR(DATEVALUE("2026-10-20")))*12+(D27-MONTH(DATEVALUE("2026-10-20"))) -> 11 | M27: last
A28: SA2611 | B28: SA | C28: 2026 | D28: 11 | E28: 918 | F28: 910 | G28: 924 | H28: =IF(N("x")="x",E28-G28) -> -6 | I28: 10663 | J28: 36399 | K28: =(C28-YEAR(DATEVALUE("2026-10-20")))*12+(D28-MONTH(DATEVALUE("2026-10-20"))) -> 1 | M28: settle
A29: SA2612 | B29: SA | C29: 2026 | D29: 12 | E29: 941 | F29: 934 | G29: 949 | H29: =IF(N("x")="x",E29-G29) -> -8 | I29: 92520 | J29: 142710 | K29: =(C29-YEAR(DATEVALUE("2026-10-20")))*12+(D29-MONTH(DATEVALUE("2026-10-20"))) -> 2 | M29: settle
A30: SA2701 | B30: SA | C30: 2027 | D30: 1 | E30: 946 | F30: 938 | G30: 953 | H30: =IF(N("x")="x",E30-G30) -> -7 | I30: 868888 | J30: 1317795 | K30: =(C30-YEAR(DATEVALUE("2026-10-20")))*12+(D30-MONTH(DATEVALUE("2026-10-20"))) -> 3 | L30: YES | M30: settle
A31: SA2702 | B31: SA | C31: 2027 | D31: 2 | E31: 981 | F31: 974 | G31: 987 | H31: =IF(N("x")="x",E31-G31) -> -6 | I31: 42417 | J31: 136429 | K31: =(C31-YEAR(DATEVALUE("2026-10-20")))*12+(D31-MONTH(DATEVALUE("2026-10-20"))) -> 4 | M31: settle
A32: SA2703 | B32: SA | C32: 2027 | D32: 3 | E32: 979 | F32: 972 | G32: 987 | H32: =IF(N("x")="x",E32-G32) -> -8 | I32: 137913 | J32: 251446 | K32: =(C32-YEAR(DATEVALUE("2026-10-20")))*12+(D32-MONTH(DATEVALUE("2026-10-20"))) -> 5 | M32: settle
A33: SA2704 | B33: SA | C33: 2027 | D33: 4 | E33: 1010 | F33: 1001 | G33: 1019 | H33: =IF(N("x")="x",E33-G33) -> -9 | I33: 966 | J33: 5097 | K33: =(C33-YEAR(DATEVALUE("2026-10-20")))*12+(D33-MONTH(DATEVALUE("2026-10-20"))) -> 6 | M33: settle
A34: SA2705 | B34: SA | C34: 2027 | D34: 5 | E34: 1008 | F34: 1002 | G34: 1017 | H34: =IF(N("x")="x",E34-G34) -> -9 | I34: 29659 | J34: 156478 | K34: =(C34-YEAR(DATEVALUE("2026-10-20")))*12+(D34-MONTH(DATEVALUE("2026-10-20"))) -> 7 | M34: settle
A35: SA2706 | B35: SA | C35: 2027 | D35: 6 | E35: 1033 | F35: 1026 | G35: 1042 | H35: =IF(N("x")="x",E35-G35) -> -9 | I35: 294 | J35: 3769 | K35: =(C35-YEAR(DATEVALUE("2026-10-20")))*12+(D35-MONTH(DATEVALUE("2026-10-20"))) -> 8 | M35: settle
A36: SA2707 | B36: SA | C36: 2027 | D36: 7 | E36: 1031 | F36: 1025 | G36: 1043 | H36: =IF(N("x")="x",E36-G36) -> -12 | I36: 627 | J36: 8887 | K36: =(C36-YEAR(DATEVALUE("2026-10-20")))*12+(D36-MONTH(DATEVALUE("2026-10-20"))) -> 9 | M36: settle
A37: SA2708 | B37: SA | C37: 2027 | D37: 8 | E37: 1061 | F37: 1053 | G37: 1068 | H37: =IF(N("x")="x",E37-G37) -> -7 | I37: 282 | J37: 2201 | K37: =(C37-YEAR(DATEVALUE("2026-10-20")))*12+(D37-MONTH(DATEVALUE("2026-10-20"))) -> 10 | M37: settle
A38: SA2709 | B38: SA | C38: 2027 | D38: 9 | E38: 1060 | F38: 1054 | G38: 1068 | H38: =IF(N("x")="x",E38-G38) -> -8 | I38: 1529 | J38: 5714 | K38: =(C38-YEAR(DATEVALUE("2026-10-20")))*12+(D38-MONTH(DATEVALUE("2026-10-20"))) -> 11 | M38: settle
A39: TA2610 | B39: TA | C39: 2026 | D39: 10 | E39: 6928 | F39: 6994 | G39: 6820 | H39: =IF(N("x")="x",E39-G39) -> 108 | I39: 869 | J39: 33756 | K39: =(C39-YEAR(DATEVALUE("2026-10-20")))*12+(D39-MONTH(DATEVALUE("2026-10-20"))) -> 0 | M39: settle
A40: TA2611 | B40: TA | C40: 2026 | D40: 11 | E40: 6696 | F40: 6758 | G40: 6712 | H40: =IF(N("x")="x",E40-G40) -> -16 | I40: 81306 | J40: 147051 | K40: =(C40-YEAR(DATEVALUE("2026-10-20")))*12+(D40-MONTH(DATEVALUE("2026-10-20"))) -> 1 | M40: settle
A41: TA2612 | B41: TA | C41: 2026 | D41: 12 | E41: 6604 | F41: 6644 | G41: 6614 | H41: =IF(N("x")="x",E41-G41) -> -10 | I41: 170689 | J41: 220816 | K41: =(C41-YEAR(DATEVALUE("2026-10-20")))*12+(D41-MONTH(DATEVALUE("2026-10-20"))) -> 2 | M41: settle
...

Sheet 03 期限结构
A1: 03 各品种当日期限结构（曲线形态与单步跳变）
A2: 黄色列为公式：相邻月价差、曲线斜率(OLS)、形态判定
A4: MA 甲醇 形态：正向市场(contango) 斜率 -46.22 元/月 单调性 r=-0.96
A5: 合约 | B5: 交割月 | C5: 结算价 | D5: 收盘价 | E5: 持仓量 | F5: 距交割(月) | G5: 相邻价差 | H5: 环比 | I5: 累计 vs 首月 | J5: 备注
A6: MA2611 | B6: 2026-11 | C6: 3347 | D6: 3384 | E6: 155303 | F6: 1 | I6: =C6-C6 -> 0
A7: MA2612 | B7: 2026-12 | C7: 3204 | D7: 3231 | E7: 293034 | F7: 2 | G7: =C7-C6 -> -143 | H7: =IF(C6=0,"",F7) -> -143 | I7: =C7-$C$6 -> -143
A8: MA2701 | B8: 2027-01 | C8: 3137 | D8: 3157 | E8: 860774 | F8: 3 | G8: =C8-C7 -> -67 | H8: =IF(C7=0,"",F8) -> -67 | I8: =C8-$C$6 -> -210 | J8: 主力合约
A9: MA2702 | B9: 2027-02 | C9: 3080 | D9: 3093 | E9: 134219 | F9: 4 | G9: =C9-C8 -> -57 | H9: =IF(C8=0,"",F9) -> -57 | I9: =C9-$C$6 -> -267
A10: MA2703 | B10: 2027-03 | C10: 3028 | D10: 3040 | E10: 229089 | F10: 5 | G10: =C10-C9 -> -52 | H10: =IF(C9=0,"",F10) -> -52 | I10: =C10-$C$6 -> -319
A11: MA2704 | B11: 2027-04 | C11: 2976 | D11: 2992 | E11: 2086 | F11: 6 | G11: =C11-C10 -> -52 | H11: =IF(C10=0,"",F11) -> -52 | I11: =C11-$C$6 -> -371
A12: MA2705 | B12: 2027-05 | C12: 2931 | D12: 2941 | E12: 149821 | F12: 7 | G12: =C12-C11 -> -45 | H12: =IF(C11=0,"",F12) -> -45 | I12: =C12-$C$6 -> -416
A13: MA2706 | B13: 2027-06 | C13: 2907 | D13: 2923 | E13: 860 | F13: 8 | G13: =C13-C12 -> -24 | H13: =IF(C12=0,"",F13) -> -24 | I13: =C13-$C$6 -> -440
A14: MA2707 | B14: 2027-07 | C14: 2883 | D14: 2895 | E14: 1202 | F14: 9 | G14: =C14-C13 -> -24 | H14: =IF(C13=0,"",F14) -> -24 | I14: =C14-$C$6 -> -464
A15: MA2708 | B15: 2027-08 | C15: 2863 | D15: 2876 | E15: 828 | F15: 10 | G15: =C15-C14 -> -20 | H15: =IF(C14=0,"",F15) -> -20 | I15: =C15-$C$6 -> -484
A16: MA2709 | B16: 2027-09 | C16: 2844 | D16: 2853 | E16: 3759 | F16: 11 | G16: =C16-C15 -> -19 | H16: =IF(C15=0,"",F16) -> -19 | I16: =C16-$C$6 -> -503
A17: 斜率(元/月, OLS) | B17: =SLOPE(C6:C16,F6:F16) -> -46.22 | C17: 形态 | D17: 正向市场(contango)
A20: SA 纯碱 形态：反向市场(backwardation) 斜率 14.35 元/月 单调性 r=0.984
A21: 合约 | B21: 交割月 | C21: 结算价 | D21: 收盘价 | E21: 持仓量 | F21: 距交割(月) | G21: 相邻价差 | H21: 环比 | I21: 累计 vs 首月 | J21: 备注
A22: SA2611 | B22: 2026-11 | C22: 918 | D22: 910 | E22: 36399 | F22: 1 | I22: =C22-C22 -> 0
A23: SA2612 | B23: 2026-12 | C23: 941 | D23: 934 | E23: 142710 | F23: 2 | G23: =C23-C22 -> 23 | H23: =IF(C22=0,"",F23) -> 23 | I23: =C23-$C$22 -> 23
A24: SA2701 | B24: 2027-01 | C24: 946 | D24: 938 | E24: 1317795 | F24: 3 | G24: =C24-C23 -> 5 | H24: =IF(C23=0,"",F24) -> 5 | I24: =C24-$C$22 -> 28 | J24: 主力合约
A25: SA2702 | B25: 2027-02 | C25: 981 | D25: 974 | E25: 136429 | F25: 4 | G25: =C25-C24 -> 35 | H25: =IF(C24=0,"",F25) -> 35 | I25: =C25-$C$22 -> 63
A26: SA2703 | B26: 2027-03 | C26: 979 | D26: 972 | E26: 251446 | F26: 5 | G26: =C26-C25 -> -2 | H26: =IF(C25=0,"",F26) -> -2 | I26: =C26-$C$22 -> 61
A27: SA2704 | B27: 2027-04 | C27: 1010 | D27: 1001 | E27: 5097 | F27: 6 | G27: =C27-C26 -> 31 | H27: =IF(C26=0,"",F27) -> 31 | I27: =C27-$C$22 -> 92
A28: SA2705 | B28: 2027-05 | C28: 1008 | D28: 1002 | E28: 156478 | F28: 7 | G28: =C28-C27 -> -2 | H28: =IF(C27=0,"",F28) -> -2 | I28: =C28-$C$22 -> 90
A29: SA2706 | B29: 2027-06 | C29: 1033 | D29: 1026 | E29: 3769 | F29: 8 | G29: =C29-C28 -> 25 | H29: =IF(C28=0,"",F29) -> 25 | I29: =C29-$C$22 -> 115
A30: SA2707 | B30: 2027-07 | C30: 1031 | D30: 1025 | E30: 8887 | F30: 9 | G30: =C30-C29 -> -2 | H30: =IF(C29=0,"",F30) -> -2 | I30: =C30-$C$22 -> 113
A31: SA2708 | B31: 2027-08 | C31: 1061 | D31: 1053 | E31: 2201 | F31: 10 | G31: =C31-C30 -> 30 | H31: =IF(C30=0,"",F31) -> 30 | I31: =C31-$C$22 -> 143
A32: SA2709 | B32: 2027-09 | C32: 1060 | D32: 1054 | E32: 5714 | F32: 11 | G32: =C32-C31 -> -1 | H32: =IF(C31=0,"",F32) -> -1 | I32: =C32-$C$22 -> 142
A33: 斜率(元/月, OLS) | B33: =SLOPE(C22:C32,F22:F32) -> 14.35 | C33: 形态 | D33: 反向市场(backwardation)
A36: PP 聚丙烯 形态：正向市场(contango) 斜率 -178.61 元/月 单调性 r=-0.938
A37: 合约 | B37: 交割月 | C37: 结算价 | D37: 收盘价 | E37: 持仓量 | F37: 距交割(月) | G37: 相邻价差 | H37: 环比 | I37: 累计 vs 首月 | J37: 备注
A38: PP2610 | B38: 2026-10 | C38: 10401 | D38: 10450 | E38: 5504 | F38: 0 | I38: =C38-C38 -> 0
A39: PP2611 | B39: 2026-11 | C39: 10144 | D39: 10184 | E39: 99417 | F39: 1 | G39: =C39-C38 -> -257 | H39: =IF(C38=0,"",F39) -> -257 | I39: =C39-$C$38 -> -257
A40: PP2612 | B40: 2026-12 | C40: 9685 | D40: 9734 | E40: 133078 | F40: 2 | G40: =C40-C39 -> -459 | H40: =IF(C39=0,"",F40) -> -459 | I40: =C40-$C$38 -> -716
A41: PP2701 | B41: 2027-01 | C41: 9331 | D41: 9376 | E41: 672680 | F41: 3 | G41: =C41-C40 -> -354 | H41: =IF(C40=0,"",F41) -> -354 | I41: =C41-$C$38 -> -1070 | J41: 主力合约
A42: PP2702 | B42: 2027-02 | C42: 9028 | D42: 9068 | E42: 57974 | F42: 4 | G42: =C42-C41 -> -303 | H42: =IF(C41=0,"",F42) -> -303 | I42: =C42-$C$38 -> -1373
A43: PP2703 | B43: 2027-03 | C43: 8819 | D43: 8864 | E43: 17823 | F43: 5 | G43: =C43-C42 -> -209 | H43: =IF(C42=0,"",F43) -> -209 | I43: =C43-$C$38 -> -1582
A44: PP2704 | B44: 2027-04 | C44: 8800 | D44: 8814 | E44: 560 | F44: 6 | G44: =C44-C43 -> -19 | H44: =IF(C43=0,"",F44) -> -19 | I44: =C44-$C$38 -> -1601
A45: PP2705 | B45: 2027-05 | C45: 8690 | D45: 8695 | E45: 84791 | F45: 7 | G45: =C45-C44 -> -110 | H45: =IF(C44=0,"",F45) -> -110 | I45: =C45-$C$38 -> -1711
...

Sheet 04 月差计算
A1: 04 月差计算与异常排序（主表）
A2: 月差 = 近月结算价 − 远月结算价；分位基于「05 历史可比样本」逐组合统计
A4: # | B4: 品种 | C4: 名称 | D4: 近月 − 远月 | E4: 近月价 | F4: 远月价 | G4: 当前月差 | H4: 历史均值 | I4: 历史分位 | J4: Z分数 | K4: 近1月前 | L4: 近1月变化 | M4: 极端度 | N4: N(年) | O4: 评级 | P4: 可交易性 | Q4: 备注
A5: 1 | B5: PP | C5: 聚丙烯 | D5: PP2701-PP2704 | E5: 9331 | F5: 8800 | G5: =E5-F5 -> 531 | H5: 22.8 | I5: 100 | J5: 7.73 | K5: 517 | L5: =G5-K5 -> 14 | M5: 100 | N5: 5 | O5: 极端(近月升水) | P5: 可交易
A6: 2 | B6: TA | C6: PTA | D6: TA2701-TA2704 | E6: 6450 | F6: 6192 | G6: =E6-F6 -> 258 | H6: 13.6 | I6: 100 | J6: 3.36 | K6: 286 | L6: =G6-K6 -> -28 | M6: 100 | N6: 5 | O6: 极端(近月升水) | P6: 受限 | Q6: 流动性不足
A7: 3 | B7: MA | C7: 甲醇 | D7: MA2701-MA2704 | E7: 3137 | F7: 2976 | G7: =E7-F7 -> 161 | H7: 92 | I7: 80 | J7: 0.47 | K7: 265 | L7: =G7-K7 -> -104 | M7: 60 | N7: 5 | O7: 偏高(近月升水) | P7: 可交易
A8: 4 | B8: SA | C8: 纯碱 | D8: SA2701-SA2704 | E8: 946 | F8: 1010 | G8: =E8-F8 -> -64 | H8: 43 | I8: 40 | J8: -0.81 | K8: -57 | L8: =G8-K8 -> -7 | M8: 20 | N8: 5 | O8: 正常 | P8: 可交易
A10: 口径说明 | B10: Z 分数 = (当前月差 − 历史均值) / 历史标准差(样本)。极端度 = |分位 − 50| × 2，0＝处于历史中位，100＝处于历史极限。可交易性受限的原因码见「10 数据质量与限制」。

Sheet 05 历史可比样本
A1: 05 历史可比样本明细（同品种 × 同月份组合 × 同剩余期限）
A2: 每行 = 某一历史年度合约在"同剩余期限周数"下的月差观测值
A4: # | B4: 品种 | C4: 月份组合 | D4: 年度 | E4: 历史合约 | F4: 观测日 | G4: 月差 | H4: 近月价 | I4: 远月价 | J4: 剩余期限(周) | K4: 对齐方式
A5: 1 | B5: PP | C5: PP2701-PP2704 | D5: 2022 | E5: PP2201/PP2204 | F5: 44489 | G5: 118 | H5: 9332 | I5: 9214 | J5: 13.14 | K5: 整周精确
A6: 2 | B6: PP | C6: PP2701-PP2704 | D6: 2023 | E6: PP2301/PP2304 | F6: 44854 | G6: 52 | H6: 7622 | I6: 7570 | J6: 13.14 | K6: 整周精确
A7: 3 | B7: PP | C7: PP2701-PP2704 | D7: 2024 | E7: PP2401/PP2404 | F7: 45219 | G7: 19 | H7: 7466 | I7: 7447 | J7: 13.14 | K7: 整周精确
A8: 4 | B8: PP | C8: PP2701-PP2704 | D8: 2025 | E8: PP2501/PP2504 | F8: 45586 | G8: -44 | H8: 7456 | I8: 7500 | J8: 13 | K8: 整周精确
A9: 5 | B9: PP | C9: PP2701-PP2704 | D9: 2026 | E9: PP2601/PP2604 | F9: 45950 | G9: -31 | H9: 6594 | I9: 6625 | J9: 13.14 | K9: 整周精确
A10: 6 | B10: TA | C10: TA2701-TA2704 | D10: 2022 | E10: TA2201/TA2204 | F10: 44489 | G10: 2 | H10: 5410 | I10: 5408 | J10: 13.14 | K10: 整周精确
A11: 7 | B11: TA | C11: TA2701-TA2704 | D11: 2023 | E11: TA2301/TA2304 | F11: 44854 | G11: 116 | H11: 5400 | I11: 5284 | J11: 13.14 | K11: 整周精确
A12: 8 | B12: TA | C12: TA2701-TA2704 | D12: 2024 | E12: TA2401/TA2404 | F12: 45219 | G12: 52 | H12: 5794 | I12: 5742 | J12: 13.14 | K12: 整周精确
A13: 9 | B13: TA | C13: TA2701-TA2704 | D13: 2025 | E13: TA2501/TA2504 | F13: 45586 | G13: -70 | H13: 4944 | I13: 5014 | J13: 13 | K13: 整周精确
A14: 10 | B14: TA | C14: TA2701-TA2704 | D14: 2026 | E14: TA2601/TA2604 | F14: 45950 | G14: -32 | H14: 4414 | I14: 4446 | J14: 13.14 | K14: 整周精确
A15: 11 | B15: MA | C15: MA2701-MA2704 | D15: 2022 | E15: MA2201/MA2204 | F15: 44489 | G15: 325 | H15: 3563 | I15: 3238 | J15: 13.14 | K15: 整周精确
A16: 12 | B16: MA | C16: MA2701-MA2704 | D16: 2023 | E16: MA2301/MA2304 | F16: 44854 | G16: 141 | H16: 2693 | I16: 2552 | J16: 13.14 | K16: 整周精确
... A24: 20 | B24: SA | C24: SA2701-SA2704 | D24: 2026 | E24: SA2601/SA2604 | F24: 45950 | G24: -82 | H24: 1228 | I24: 1310 | J24: 13.14 | K24: 整周精确
A26: 注意 | B26: 不同月份组合的样本分别统计，不在本表内合并。若某组合在某年度无同剩余期限的双边有效报价，该年度即为空缺，不补数。

Sheet 06 分位统计
A1: 06 分位统计（Excel 原生公式，改「05」数据即重算）
A2: 统计口径：AVEARGE/STDEV/MIN/MAX/PERCENTILE/COUNTIF，样本取自「05 历史可比样本」对应组合
A4: 品种 | B4: 月份组合 | C4: 样本数N | D4: 均值 | E4: 标准差 | F4: 最小值 | G4: P05 | H4: P25 | I4: 中位数P50 | J4: P75 | K4: P95 | L4: 最大值 | M4: 当前分位(%) | N4: 评级(公式)
A5: PP | B5: PP2701-PP2704 | C5: =COUNT('05 历史可比样本'!$G$5:$G$9) -> 5 | D5: =AVERAGE('05 历史可比样本'!$G$5:$G$9) -> 22.8 | E5: =STDEV('05 历史可比样本'!$G$5:$G$9) -> 44.43769 | F5: =MIN('05 历史可比样本'!$G$5:$G$9) -> -44 | G5: =PERCENTILE('05 历史可比样本'!$G$5:$G$9,0.05) -> -41.4 | H5: =PERCENTILE('05 历史可比样本'!$G$5:$G$9,0.25) -> -31 | I5: =PERCENTILE('05 历史可比样本'!$G$5:$G$9,0.5) -> 19 | J5: =PERCENTILE('05 历史可比样本'!$G$5:$G$9,0.75) -> 52 | K5: =PERCENTILE('05 历史可比样本'!$G$5:$G$9,0.95) -> 104.8 | L5: =MAX('05 历史可比样本'!$G$5:$G$9) -> 118 | M5: =IF(C5<3,"",(COUNTIF('05 历史可比样本'!$G$5:$G$9,"<"&531.0)+0.5*COUNTIF('05 历史可比样本'!$G$5:$G$9,531.0))/C5*100) -> 100 | N5: =IF(C5<3,"样本不足",IF(L5="","",IF(OR(M5<=5,M5>=95),"极端","正常"))) -> 极端(近月升水)
A6: TA | B6: TA2701-TA2704 | C6: =COUNT('05 历史可比样本'!$G$10:$G$14) -> 5 | D6: =AVERAGE('05 历史可比样本'!$G$10:$G$14) -> 13.6 | E6: =STDEV('05 历史可比样本'!$G$10:$G$14) -> 50.334347 | F6: =MIN('05 历史可比样本'!$G$10:$G$14) -> -70 | G6: =PERCENTILE('05 历史可比样本'!$G$10:$G$14,0.05) -> -62.4 | H6: =PERCENTILE('05 历史可比样本'!$G$10:$G$14,0.25) -> -32 | I6: =PERCENTILE('05 历史可比样本'!$G$10:$G$14,0.5) -> 2 | J6: =PERCENTILE('05 历史可比样本'!$G$10:$G$14,0.75) -> 52 | K6: =PERCENTILE('05 历史可比样本'!$G$10:$G$14,0.95) -> 103.2 | L6: =MAX('05 历史可比样本'!$G$10:$G$14) -> 116 | M6: =IF(C6<3,"",(COUNTIF('05 历史可比样本'!$G$10:$G$14,"<"&258.0)+0.5*COUNTIF('05 历史可比样本'!$G$10:$G$14,258.0))/C6*100) -> 100 | N6: =IF(C6<3,"样本不足",IF(L6="","",IF(OR(M6<=5,M6>=95),"极端","正常"))) -> 极端(近月升水)
A7: MA | B7: MA2701-MA2704 | C7: =COUNT('05 历史可比样本'!$G$15:$G$19) -> 5 | D7: =AVERAGE('05 历史可比样本'!$G$15:$G$19) -> 92 | E7: =STDEV('05 历史可比样本'!$G$15:$G$19) -> 96.960486 | F7: =MIN('05 历史可比样本'!$G$15:$G$19) -> -34 | G7: =PERCENTILE('05 历史可比样本'!$G$15:$G$19,0.05) -> -30.8 | H7: =PERCENTILE('05 历史可比样本'!$G$15:$G$19,0.25) -> -18 | I7: =PERCENTILE('05 历史可比样本'!$G$15:$G$19,0.5) -> 46 | J7: =PERCENTILE('05 历史可比样本'!$G$15:$G$19,0.75) -> 141 | K7: =PERCENTILE('05 历史可比样本'!$G$15:$G$19,0.95) -> 288.2 | L7: =MAX('05 历史可比样本'!$G$15:$G$19) -> 325 | M7: =IF(C7<3,"",(COUNTIF('05 历史可比样本'!$G$15:$G$19,"<"&161.0)+0.5*COUNTIF('05 历史可比样本'!$G$15:$G$19,161.0))/C7*100) -> 80 | N7: =IF(C7<3,"样本不足",IF(L7="","",IF(OR(M7<=5,M7>=95),"极端","正常"))) -> 偏高(近月升水)
A8: SA | B8: SA2701-SA2704 | C8: =COUNT('05 历史可比样本'!$G$20:$G$24) -> 5 | D8: =AVERAGE('05 历史可比样本'!$G$20:$G$24) -> 43 | E8: =STDEV('05 历史可比样本'!$G$20:$G$24) -> 85.531915 | F8: =MIN('05 历史可比样本'!$G$20:$G$24) -> -103 | G8: =PERCENTILE('05 历史可比样本'!$G$20:$G$24,0.05) -> -98.8 | H8: =PERCENTILE('05 历史可比样本'!$G$20:$G$24,0.25) -> -82 | I8: =PERCENTILE('05 历史可比样本'!$G$20:$G$24,0.5) -> 69 | J8: =PERCENTILE('05 历史可比样本'!$G$20:$G$24,0.75) -> 137 | K8: =PERCENTILE('05 历史可比样本'!$G$20:$G$24,0.95) -> 182.6 | L8: =MAX('05 历史可比样本'!$G$20:$G$24) -> 194 | M8: =IF(C8<3,"",(COUNTIF('05 历史可比样本'!$G$20:$G$24,"<"&-64.0)+0.5*COUNTIF('05 历史可比样本'!$G$20:$G$24,-64.0))/C8*100) -> 40 | N8: =IF(C8<3,"样本不足",IF(L8="","",IF(OR(M8<=5,M8>=95),"极端","正常"))) -> 正常

Sheet 07 产业面
A1: 07 产业面：库存 / 仓单 / 现货 / 基差
A2: 可信度：A=抓取正文+明确日期；B=研报/媒体转述；C=口径不明；D=未获取。缺数据一律留空，不估算。
A4: 品种 | B4: 类别 | C4: 指标 | D4: 数值 | E4: 单位 | F4: 变化 | G4: 变化% | H4: 日期 | I4: 来源 | J4: 可信度
A5: MA | B5: 仓单 | C5: 注册仓单 | D5: 6633 | E5: 张 | F5: 0 | H5: 2026-10-20 | I5: 郑商所仓单日报 FutureDataWhsheet.txt | J5: A
A6: MA | B6: 库存 | C6: 中国沿海港口库存(隆众口径) | D6: 30.51 | E6: 万吨 | F6: -8.84 | G6: -22.47 | H6: 2026-10-08 | I6: 新浪财经转隆众 https://finance.sina.com.cn/money/bond/2026-10-12/doc-iniuxrzr8524973.shtml | J6: B
A7: MA | B7: 库存 | C7: 港口社会库存(金联创口径) | D7: 30.44 | E7: 万吨 | F7: 5.62 | G7: 0 | H7: 2026-10-15 | I7: 东方财富转金联创 https://finance.eastmoney.com/a/202610193899284051.html | J7: B
A8: MA | B8: 现货 | C8: 太仓 | D8: 3965 | E8: 元/吨 | H8: 2026-10-19 | I8: 新浪财经期货晨报 | J8: A
A9: MA | B9: 现货 | C9: 内蒙北线 | D9: 3085 | E9: 元/吨 | H9: 2026-10-19 | J9: A
A10: SA | B10: 仓单 | C10: 注册仓单 | D10: 3214 | E10: 张 | F10: 297 | H10: 2026-10-20 | I10: 郑商所仓单日报 FutureDataWhsheet.txt | J10: A
A11: SA | B11: 库存 | C11: 纯碱厂家总库存 | D11: 153.96 | E11: 万吨 | F11: -8.93 | G11: -5.48 | H11: 2026-10-19 | I11: 新浪财经转期货日报 https://finance.sina.com.cn/money/future/fmnews/2026-10-20/doc-inivvxcp7623329.shtml | J11: A
A12: SA | B12: 库存 | C12: 轻碱 | D12: 82.23 | E12: 万吨 | F12: -3.15 | G12: 0 | H12: 2026-10-19 | J12: A
A13: SA | B13: 库存 | C13: 重碱 | D13: 71.73 | E13: 万吨 | F13: -5.78 | G13: 0 | H13: 2026-10-19 | J13: A
A14: SA | B14: 库存 | C14: 上一期厂家库存 | D14: 162.89 | E14: 万吨 | F14: -8.13 | G14: 0 | H14: 2026-10-15 | I14: 金十数据 https://xnews.jin10.com/details/232607 | J14: A
A15: SA | B15: 库存 | C15: 节后库存 | D15: 177.87 | E15: 万吨 | F15: 1.94 | G15: 0 | H15: 2026-10-08 | J15: B
A16: SA | B16: 现货 | C16: 沙河重碱自提 | D16: 951 | E16: 元/吨 | H16: 2026-10-19 | I16: 新浪财经期货晨报 | J16: A
A17: SA | B17: 现货 | C17: 华东重碱(区间1130-1230中值) | D17: 1180 | E17: 元/吨 | H17: 2026-10-19 | J17: B
A18: PP | B18: 仓单 | C18: 注册仓单 | D18: 26390 | E18: 手 | F18: 0 | H18: 2026-10-19 | I18: 新浪财经转DCE日度仓单（DCE官网对脚本返回412，未取得原始文件） | J18: B
A19: PP | B19: 库存 | C19: PP商业库存(隆众) | D19: 62.08 | E19: 万吨 | F19: -6.69 | G19: -9.73 | H19: 2026-10-14 | I19: 新浪财经转隆众 https://finance.sina.com.cn/money/future/roll/2026-10-17/doc-inivnvku1480435.shtml | J19: B
A20: PP | B20: 库存 | C20: 两油石化库存 | D20: 79 | E20: 万吨 | F20: 0 | G20: 0 | H20: 2026-10-15 | I20: 新浪财经 https://finance.sina.com.cn/money/future/fmnews/2026-10-15/doc-inivhiew1357592.shtml | J20: B
A21: PP | B21: 现货 | C21: 华东拉丝 | D21: 10775 | E21: 元/吨 | H21: 2026-10-19 | I21: 光大期货日报(东方财富转) | J21: B
A22: PP | B22: 基差 | C22: 现货10,756.67 − 期货9,320 = +1,436 (13.35%) | D22: 1436 | E22: 元/吨 | H22: 2026-10-19 | I22: 金投网 | J22: C
A23: TA | B23: 仓单 | C23: 注册仓单 | D23: 34728 | E23: 张(完税) | F23: 168 | H23: 2026-10-20 | I23: 郑商所仓单日报 FutureDataWhsheet.txt | J23: A
A24: TA | B24: 库存 | C24: PTA社会库存 | D24: 140 | E24: 万吨 | F24: 0 | G24: 0 | H24: 2026-10中旬 | I24: 期货日报(新浪转) https://finance.sina.com.cn/money/bond/2026-10-20/doc-inivvnps0829573.shtml | J24: B
A25: TA | B25: 库存 | C25: PTA社会库存(09-30) | D25: 122.75 | E25: 万吨 | F25: 11.2 | G25: 9.12 | H25: 2026-09-30 | I25: 新浪财经 https://finance.sina.com.cn/money/bond/2026-10-09/doc-iniuquqf7191797.shtml | J25: B
A26: TA | B26: 现货 | C26: 华东 | D26: 7054.5 | E26: 元/吨 | H26: 2026-10-19 | I26: 金投网 | J26: C
A27: TA | B27: 基差 | C27: 升水TA01约450（另一口径），现货10,756.67口径参见PP | D27: 670 | E27: 元/吨 | H27: 2026-10-19 | J27: C

Sheet 08 供需事件
A1: 08 供需事件时间线
A2: 事件仅用于解释期限结构为什么处在当前位置，不构成方向判断或交易建议
A4: 品种 | B4: 日期 | C4: 事件 | D4: 影响 | E4: 方向标签
A5: MA | B5: 2026-06底 | C5: 伊朗封锁霍尔木兹海峡，甲醇进口通道受阻 | D5: 供应中断预期 | E5: bullish
A6: MA | B6: 2026-09-22 | C6: 多数伊朗装置重启，仅约660万吨仍停车；9月伊朗装港15.4万吨，9月进口降至约40万吨（8月约70万吨） | D6: 进口量腰斩，沿海可流通货源紧张 | E6: bullish
A7: MA | B7: 2026-10-07 | C7: 伊朗革命卫队称海峡已关闭 | D7: 10-08 MA2611 封涨停（+9.02%） | E7: bullish
A8: MA | B8: 2026-10-09 | C8: 主力盘中最高3,959；当周外采MTO利润恶化至−4,000元/吨以上，江浙外采MTO开工降至20.06% | D8: 需求端负反馈启动 | E8: bearish
A9: MA | B9: 2026-10-10前后 | C9: 天津渤化、联泓、南京诚志、宁波富德、山东恒通MTO停车或降负；诚志二期10-18停车 | D9: 沿海MTO基本全停，甲醇需求塌陷 | E9: bearish_near
A10: MA | B10: 2026-10-10 | C10: 产区降价200元起拍仍流拍，太仓小单最低成交4,400（较前一日最高价−550） | D10: 现货强转弱 | E10: bearish_near
A11: MA | B11: 2026-10底(计划) | C11: 宁夏宝丰4期280万吨甲醇投产 | D11: 国内新增产能 | E11: bearish
A12: MA | B12: 2026-10下旬 | C12: 南京MTO计划停车；塞拉尼斯冰醋酸检修 | D12: 沿海需求继续走弱 | E12: bearish
A13: SA | B13: 2026-10-08 | C13: 节后产量回升至约70.32万吨(+3.4)，库存177.87万吨累库 | D13: 供应压力 | E13: bearish
A14: SA | B14: 2026-10-12 | C14: 秦皇岛5500大卡动力煤1,008元/吨，创近2年新高 | D14: 氨碱成本抬升，碱厂亏损加剧 | E14: bullish_cost
A15: SA | B15: 2026-10-15至19 | C15: 内蒙/河南/青海大厂集中检修，开工降至63.76%，周产60.56万吨(环比−15.17%) | D15: 供应收缩，两周去库24万吨 | E15: bullish_near
... A34: TA | B34: 产能 | C34: 据券商研究，PTA 至2026年无新增产能投放 | D34: 供给端约束 | E34: bullish

Sheet 09 公式说明
A1: 09 指标定义与 Excel 公式实现
A3: 指标 | B3: 定义 | C3: Excel 实现 / 说明
A4: 月差 Spread | B4: 近月结算价 − 远月结算价（元/吨） | C4: =E-F（04 表 G 列） -> 0
A5: 距交割月数 | B5: (交割年 − 数据年) × 12 + (交割月 − 数据月) | C5: =(C-YEAR(DATEVALUE("2026-10-20")))*12+(D-MONTH(DATEVALUE("2026-10-20"))) -> 0
A6: 相邻月价差 | B6: 后一交割月结算价 − 前一交割月结算价 | C6: =C(n)-C(n-1)（03 表） -> 0
A7: 曲线斜率 OLS | B7: 价格对距交割月数的最小二乘斜率 | C7: =SLOPE(结算价区, 距交割月数区)；<-3 判正向市场，>3 判反向市场 -> 0
A8: 可比历史样本 | B8: 同品种 × 同(近月,远月)组合 × 同剩余期限整周数 | C8: 剩余期限 = floor((近月交割月结束日 − 观测日)/7天)；每年取 1 个
A9: 历史分位 | B9: 当前月差在可比样本中的位置 | C9: =(COUNTIF(区间,"<"&当前)+0.5*COUNTIF(区间,当前))/N*100 -> 0
A10: 历史均值 | B10: 可比样本算术平均 | C10: =AVERAGE(区间) -> 0
A11: 标准差 | B11: 可比样本样本标准差 | C11: =STDEV(区间)（n−1 分母） -> 0
A12: Z 分数 | B12: (当前 − 均值) / 标准差 | C12: =(当前-AVERAGE(区间))/STDEV(区间) -> 0
A13: 近1月变化 | B13: 当前月差 − 30 个自然日前最近交易日月差 | C13: =G-K（04 表） -> 0
A14: 极端度 | B14: |分位 − 50| × 2 | C14: 0＝历史中位，100＝历史极限
A15: 评级阈值 | B15: ≥95% 或 ≤5% 为极端；≥80% 或 ≤20% 为偏高 | C15: 可改「06」表公式中的 5/95 阈值
A16: 样本不足 | B16: 可比历史年份 < 3（或 < 设定阈值） | C16: 不给分位，写"样本不足"

Sheet 10 数据质量与限制
A1: 10 数据质量、样本不足与不可比说明
A3: 品种 | B3: 组合/项目 | C3: 问题 | D3: 说明与处理
A4: MA | B4: — | C4: 价格口径 | D4: 交易所结算价；与其他品种口径不同，不混算
A5: SA | B5: — | C5: 价格口径 | D5: 交易所结算价；与其他品种口径不同，不混算
A6: PP | B6: — | C6: 价格口径 | D6: 最新价(东财)；与其他品种口径不同，不混算
A7: TA | B7: — | C7: 价格口径 | D7: 交易所结算价；与其他品种口径不同，不混算
A8: TA | B8: TA2701-TA2704 | C8: 可交易性受限 | D8: 流动性不足
A9: — | B9: 大商所仓单 | C9: 数据未取得原始文件 | D9: DCE 官网对脚本返回 HTTP 412；PP 仓单采用媒体转述的 2026-10-19 数值（可信度 B）
A10: — | B10: PTA 仓单跳升 | C10: 异常未解释 | D10: 10-08 约1,002张 → 10-09 约36,187张，抓取页面均未说明原因，仅记录事实，不作累库结论
A11: — | B11: 甲醇港口库存 | C11: 多口径并存 | D11: 隆众30.51(10-08) / 卓创37.41(10-08) / 金联创30.44(10-15)，不可混算环比
A12: — | B12: 历史区间 | C12: 仅覆盖 2022–2026 年度合约 | D12: 更早年度合约在新浪接口不可取；样本 N 上限为 5（含当期）
A13: — | B13: 成本项 | C13: 未扣除 | D13: 仓储费、资金成本、交割成本、品级/地区升贴水均未计入月差
