Workbook

Sheet 00封面与口径
A1: 华东甲醇现货价格季节性 · 价格季节性分析
A2: 历史已实现季节性 · 不是对未来价格的预测 · 生成于 2026-10-21 09:20
A4: 用途 | B4: 看清某品种/地区/合约在一年中同一周/月的历史价格分布位置，服务于价差与量化研究
A5: 需求口径 | B5: 华东地区 甲醇现货价格
A6: 实际口径 | B6: 生意社甲醇基准价 —— 全国口径·含税·交易指导价（元/吨）
A7: 口径是否降级 | B7: 是（已在全篇声明，不得把实际口径改写为需求口径）
A8: 降级原因/说明 | B8: 华东/太仓区域现货 10 年历史在免费公开渠道不可得（隆众、卓创接口需付费订阅）；本次取得的是生意社基准价的全国口径。该口径适用于全国价格水平的季节性判断，但不能用于区域价差、交割地贴水等区域特征推断。
A9: 单位 / 税基 | B9: 元/吨 / 含税
A10: 样本区间 | B10: 2022-08-17 → 2026-10-20
A11: 自然日报价点数 | B11: 1083
A12: 申请样本年数 | B12: 10
A13: 实际覆盖年数 | B13: 5
A14: 覆盖年份 | B14: 2022, 2023, 2024, 2025, 2026
A15: 月度完整年份(12个月都有数据) | B15: 2023, 2024, 2025, 2026
A16: 周度对齐规则 | B16: ISO 8601 周(周一为首日)；周值 = 该周最后一个有报价日；ISO 第53周折叠入第52周
A17: 月度对齐规则 | B17: 自然月；月值 = 该月最后一个有报价日
A18: 缺失处理 | B18: 不插值、不前值填充、不删除样本；缺口逐条列于「11数据缺口」
A19: 分位算法 | B19: 经验分位线性插值 = Excel PERCENTILE.INC (等价 numpy default / R type 7)
A20: 统计样本门槛 | B20: 同一位置有效年数 < 3 年 → 标记样本不足，不参与形态判断
A21: 季节性强度 R² | B21: 周度 13.8% · 月度 12.3%（季节性弱，年份间价格水平漂移主导）
A22: 使用边界 | B22: 仅描述历史分布；季节形态弱时不可作为价位判断依据；各位置样本仅数年，分位不确定性大
A23: 异常年处理 | B23: 自动识别并给出证据，但**不删除**任何年份；是否剔除由研究者决定并记录

Sheet 01日度价格
A1: 01 日度原始报价（逐行可追溯）
A2: 每条记录保留原文链接；缺失日期不出现（不补造）。共 1083 条
A3: 序号 | B3: 日期 | C3: 星期 | D3: 价格 | E3: ISO年 | F3: ISO周 | G3: 发布日 | H3: 来源链接 | I3: 标题
A4: 1 | B4: 2022-08-17 | C4: 三 | D4: 2425 | E4: 2022 | F4: 33 | G4: 2022-08-17 | H4: https://www.100ppi.com/news/detail-20220817-2246847.html | I4: 8月17日生意社甲醇基准价为2425.00元/吨
A5: 2 | B5: 2022-08-18 | C5: 四 | D5: 2432.5 | E5: 2022 | F5: 33 | G5: 2022-08-18 | H5: https://www.100ppi.com/news/detail-20220818-2248551.html | I5: 8月18日生意社甲醇基准价为2432.50元/吨
A6: 3 | B6: 2022-08-19 | C6: 五 | D6: 2438.75 | E6: 2022 | F6: 33 | G6: 2022-08-19 | H6: https://www.100ppi.com/news/detail-20220819-2250235.html | I6: 8月19日生意社甲醇基准价为2438.75元/吨
A7: 4 | B7: 2022-08-22 | C7: 一 | D7: 2458.75 | E7: 2022 | F7: 34 | G7: 2022-08-22 | H7: https://www.100ppi.com/news/detail-20220822-2253307.html | I7: 8月22日生意社甲醇基准价为2458.75元/吨
A8: 5 | B8: 2022-08-23 | C8: 二 | D8: 2475 | E8: 2022 | F8: 34 | G8: 2022-08-23 | H8: https://www.100ppi.com/news/detail-20220823-2255137.html | I8: 8月23日生意社甲醇基准价为2475.00元/吨
A9: 6 | B9: 2022-08-24 | C9: 三 | D9: 2483.33 | E9: 2022 | F9: 34 | G9: 2022-08-24 | H9: https://www.100ppi.com/news/detail-20220824-2256779.html | I9: 8月24日生意社甲醇基准价为2483.33元/吨
A10: 7 | B10: 2022-08-25 | C10: 四 | D10: 2512.5 | E10: 2022 | F10: 34 | G10: 2022-08-25 | H10: https://www.100ppi.com/news/detail-20220825-2258482.html | I10: 8月25日生意社甲醇基准价为2512.50元/吨
A11: 8 | B11: 2022-08-26 | C11: 五 | D11: 2568.75 | E11: 2022 | F11: 34 | G11: 2022-08-26 | H11: https://www.100ppi.com/news/detail-20220826-2260191.html | I11: 8月26日生意社甲醇基准价为2568.75元/吨
A12: 9 | B12: 2022-08-29 | C12: 一 | D12: 2539 | E12: 2022 | F12: 35 | G12: 2022-08-29 | H12: https://www.100ppi.com/news/detail-20220829-2263271.html | I12: 8月29日生意社甲醇基准价为2539.00元/吨
A13: 10 | B13: 2022-08-30 | C13: 二 | D13: 2550 | E13: 2022 | F13: 35 | G13: 2022-08-30 | H13: https://www.100ppi.com/news/detail-20220830-2265052.html | I13: 8月30日生意社甲醇基准价为2550.00元/吨
A14: 11 | B14: 2022-08-31 | C14: 三 | D14: 2540 | E14: 2022 | F14: 35 | G14: 2022-08-31 | H14: https://www.100ppi.com/news/detail-20220831-2266741.html | I14: 8月31日生意社甲醇基准价为2540.00元/吨
A15: 12 | B15: 2022-09-01 | C15: 四 | D15: 2528 | E15: 2022 | F15: 35 | G15: 2022-09-01 | H15: https://www.100ppi.com/news/detail-20220901-2268454.html | I15: 9月1日生意社甲醇基准价为2528.00元/吨
... A1086: 1083 | B1086: 2026-10-20 | C1086: 二 | D1086: 3966.67 | E1086: 2026 | F1086: 43 | G1086: 2026-10-20 | H1086: https://www.100ppi.com/news/detail-20261020-6368678.html | I1086: 10月20日生意社甲醇基准价为3966.67元/吨

Sheet 02周度面板
A1: 02 周度面板：年份 × ISO 周（每年一条独立轨迹）
A2: 每格 = 该 ISO 周最后一个有报价日的价格；空白 = 该年该周无数据（未补造）
A3: 年份 | B3: W01 | C3: W02 | D3: W03 | E3: W04 | F3: W05 | G3: W06 | H3: W07 | I3: W08 | J3: W09 | K3: W10 | L3: W11 | M3: W12 | N3: W13 | O3: W14 | P3: W15 | Q3: W16 | R3: W17 | S3: W18 | T3: W19 | U3: W20 | V3: W21 | W3: W22 | X3: W23 | Y3: W24 | Z3: W25 | AA3: W26 | AB3: W27 | AC3: W28 | AD3: W29 | AE3: W30 | AF3: W31 | AG3: W32 | AH3: W33 | AI3: W34 | AJ3: W35 | AK3: W36 | AL3: W37 | AM3: W38 | AN3: W39 | AO3: W40 | AP3: W41 | AQ3: W42 | AR3: W43 | AS3: W44 | AT3: W45 | AU3: W46 | AV3: W47 | AW3: W48 | AX3: W49 | AY3: W50 | AZ3: W51 | BA3: W52 | BB3: 报价天数 | BC3: 首个位置 | BD3: 末个位置 | BE3: 覆盖说明
A4: 2022 | AH4: 2438.75 | AI4: 2568.75 | AJ4: 2553.75 | AK4: 2712.5 | AL4: 2770 | AM4: 2766 | AN4: 3012.5 | AO4: 3105 | AP4: 2862.5 | AQ4: 2894 | AR4: 2800 | AS4: 2851 | AT4: 2691.67 | AU4: 2800 | AV4: 2785.83 | AW4: 2681.67 | AX4: 2631.67 | AY4: 2678.33 | AZ4: 2600 | BA4: 2631.67 | BB4: 93 | BC4: 33 | BD4: 52 | BE4: 部分年份（缺前段/后段）
A5: 2023 | B5: 2671.67 | C5: 2635.83 | D5: 2690 | E5: 2690 | F5: 2723.33 | G5: 2711.43 | H5: 2711.43 | I5: 2762.5 | J5: 2701.67 | K5: 2638.33 | L5: 2575.83 | M5: 2610 | N5: 2543.33 | O5: 2473.33 | P5: 2471.67 | Q5: 2550 | R5: 2488.33 | S5: 2411.67 | T5: 2360 | U5: 2343.33 | V5: 2135.83 | W5: 2161.67 | X5: 2085.83 | Y5: 2060 | Z5: 2091.67 | AA5: 2161.67 | AB5: 2155.83 | AC5: 2250 | AD5: 2245.83 | AE5: 2250.83 | AF5: 2330.83 | AG5: 2366.67 | AH5: 2355.83 | AI5: 2455.83 | AJ5: 2525 | AK5: 2499.17 | AL5: 2527.5 | AM5: 2539.17 | AN5: 2478.33 | AO5: 2478.33 | AP5: 2480 | AQ5: 2450 | AR5: 2430 | AS5: 2410 | AT5: 2505.83 | AU5: 2495.83 | AV5: 2365.83 | AW5: 2510.83 | AX5: 2455 | AY5: 2420.83 | AZ5: 2485.83 | BA5: 2456.67 | BB5: 259 | BC5: 1 | BD5: 52 | BE5: 完整覆盖
A6: 2024 | B6: 2414.17 | C6: 2415.83 | D6: 2447.5 | E6: 2615.83 | F6: 2561.67 | G6: 2640 | H6: 2640 | I6: 2635.83 | J6: 2730 | K6: 2711.67 | L6: 2710 | M6: 2685.83 | N6: 2583.33 | O6: 2610 | P6: 2580 | Q6: 2691.67 | R6: 2611.67 | S6: 2651.67 | T6: 2670 | U6: 2864.17 | V6: 2758.33 | W6: 2800 | X6: 2620 | Y6: 2560 | Z6: 2526.67 | AA6: 2530 | AB6: 2540 | AC6: 2550 | AD6: 2525.83 | AE6: 2510 | AF6: 2510 | AG6: 2471.67 | AH6: 2411.67 | AI6: 2481.67 | AJ6: 2495.83 | AK6: 2385.83 | AL6: 2405.83 | AM6: 2440 | AN6: 2440.83 | AO6: 2577.5 | AP6: 2505.83 | AQ6: 2456.67 | AR6: 2440 | AS6: 2485 | AT6: 2499.17 | AU6: 2475 | AV6: 2550 | AW6: 2538.33 | AX6: 2482.5 | AY6: 2595.83 | AZ6: 2625 | BA6: 2750 | BB6: 260 | BC6: 1 | BD6: 52 | BE6: 完整覆盖
A7: 2025 | B7: 2779.17 | C7: 2674.17 | D7: 2710 | E7: 2630 | F7: 2635.83 | G7: 2650 | H7: 2604.17 | I7: 2595 | J7: 2634.17 | K7: 2649.17 | L7: 2628.33 | M7: 2694.17 | N7: 2690 | O7: 2550 | P7: 2537.5 | Q7: 2403.75 | R7: 2420 | S7: 2440 | T7: 2390 | U7: 2426.25 | V7: 2312.5 | W7: 2247 | X7: 2302 | Y7: 2362 | Z7: 2764 | AA7: 2750.83 | AB7: 2474.17 | AC7: 2397.5 | AD7: 2391.67 | AE7: 2459.17 | AF7: 2393.33 | AG7: 2380.83 | AH7: 2346.67 | AI7: 2308.83 | AJ7: 2245.83 | AK7: 2245.83 | AL7: 2290 | AM7: 2261.67 | AN7: 2253.75 | AO7: 2237.5 | AP7: 2232.5 | AQ7: 2324 | AR7: 2256 | AS7: 2176 | AT7: 2096 | AU7: 2078 | AV7: 2002 | AW7: 2103.33 | AX7: 2100 | AY7: 2104.17 | AZ7: 2157.5 | BA7: 2150 | BB7: 259 | BC7: 1 | BD7: 52 | BE7: 完整覆盖
A8: 2026 | B8: 2207.5 | C8: 2240.83 | D8: 2250.83 | E8: 2225.83 | F8: 2284.17 | G8: 2200 | H8: 2225 | I8: 2201.67 | J8: 2185.83 | K8: 2500 | L8: 2750 | M8: 3170 | N8: 3286.67 | O8: 3346.67 | P8: 3386.67 | Q8: 3393.33 | R8: 3256.67 | S8: 3295.83 | T8: 3170 | U8: 3100 | V8: 3215.83 | W8: 3128.33 | X8: 3186.67 | Y8: 3441.67 | Z8: 2916.67 | AA8: 2713.33 | AB8: 2545.83 | AC8: 2650 | AD8: 2656.67 | AE8: 2750 | AF8: 2665 | AG8: 2531.67 | AH8: 2668.33 | AI8: 2875.83 | AJ8: 2850.83 | AK8: 3349.17 | AL8: 3726.67 | AM8: 4030 | AN8: 4110 | AO8: 4493.33 | AP8: 4733.33 | AQ8: 3990 | AR8: 3966.67 | BB8: 212 | BC8: 1 | BD8: 43 | BE8: 部分年份（缺前段/后段）

Sheet 03月度面板
A1: 03 月度面板：年份 × 月
A2: 每格 = 该月最后一个有报价日的价格；空白 = 该月无数据
A3: 年份 | B3: 01月 | C3: 02月 | D3: 03月 | E3: 04月 | F3: 05月 | G3: 06月 | H3: 07月 | I3: 08月 | J3: 09月 | K3: 10月 | L3: 11月 | M3: 12月 | N3: 报价天数 | O3: 首个位置 | P3: 末个位置 | Q3: 覆盖说明
A4: 2022 | I4: 2540 | J4: 3012.5 | K4: 2800 | L4: 2785.83 | M4: 2631.67 | N4: 93 | O4: 8 | P4: 12 | Q4: 部分年份（缺前段/后段）
A5: 2023 | B5: 2768.75 | C5: 2780.83 | D5: 2543.33 | E5: 2488.33 | F5: 2175 | G5: 2161.67 | H5: 2281.67 | I5: 2541.67 | J5: 2478.33 | K5: 2457.5 | L5: 2435.83 | M5: 2456.67 | N5: 259 | O5: 1 | P5: 12 | Q5: 部分年份（缺前段/后段）
A6: 2024 | B6: 2571.67 | C6: 2741.67 | D6: 2583.33 | E6: 2649.17 | F6: 2800 | G6: 2530 | H6: 2465.83 | I6: 2495.83 | J6: 2518.33 | K6: 2440 | L6: 2538.33 | M6: 2745.83 | N6: 262 | O6: 1 | P6: 12 | Q6: 部分年份（缺前段/后段）
A7: 2025 | B7: 2635.83 | C7: 2634.17 | D7: 2654.17 | E7: 2437.5 | F7: 2247 | G7: 2785.83 | H7: 2416.67 | I7: 2245.83 | J7: 2260 | K7: 2176 | L7: 2103.33 | M7: 2200 | N7: 260 | O7: 1 | P7: 12 | Q7: 部分年份（缺前段/后段）
A8: 2026 | B8: 2284.17 | C8: 2185.83 | D8: 3460 | E8: 3292.5 | F8: 3128.33 | G8: 2813.33 | H8: 2665 | I8: 2921.67 | J8: 4585 | K8: 3966.67 | N8: 209 | O8: 1 | P8: 10 | Q8: 部分年份（缺前段/后段）

Sheet 04周次映射规则
A1: 04 周次对齐规则（周次不能跨年直接比，必须按 ISO 周对齐）
A2: 本表说明每个 x 位置是怎么定义的，以及每年实际覆盖到哪一周
A4: 周度 x 轴 | B4: ISO 8601 周次 1..52（周一为首日）。ISO 周 53 折叠入第 52 周，使各年份可同年比较。
A5: 周值定义 | B5: 该 ISO 周内最后一个有报价工作日的价格（周内其余日只用于计算周均值/周高低）。
A6: 为什么不用自然周 | B6: 自然周会跨年错位（如 2024 第 1 周与 2025 第 1 周不是同一时点），跨年比较会产生伪季节性。
A7: 月度 x 轴 | B7: 自然月 1..12；月值 = 该月最后一个有报价日；另存月均值与月内天数。
A8: 春节/长假 | B8: 长假所在周报价日可能仅 1–3 天。本报告不剔除该周，也不补造；如样本量不足会触发样本门槛。如需规避，可在 config 里把该周设为排除位置（excluded_positions）。
A9: 缺报处理 | B9: 工作日无报价：保留为空，不插值、不前值填充；在「11数据缺口」逐条列出。
A10: 窗口 | B10: W1..W52（全年）。若只关心某个季度，把 window_start_iso_week / quarter_end_iso_week 改成 1..13 等。
A11: 归一化 | B11: 每年以该年窗口内第一个有效观测为 100（不是 1 月 1 日插值）。
A13: 逐年实际覆盖（首/末 ISO 周与报价天数）
A14: 年份 | B14: 首个ISO周 | C14: 末个ISO周 | D14: 首日 | E14: 末日 | F14: 有效位置数 | G14: 报价天数 | H14: 内部缺口(周) | I14: 覆盖说明
A15: 2022 | B15: 33 | C15: 52 | D15: 2022-08-17 | E15: 2022-12-30 | F15: 20 | G15: 93 | H15: 0 | I15: 部分年份（缺前段/后段）
A16: 2023 | B16: 1 | C16: 52 | D16: 2023-01-02 | E16: 2023-12-29 | F16: 52 | G16: 259 | H16: 0 | I16: 完整覆盖
A17: 2024 | B17: 1 | C17: 52 | D17: 2024-01-01 | E17: 2024-12-27 | F17: 52 | G17: 260 | H17: 0 | I17: 完整覆盖
A18: 2025 | B18: 1 | C18: 52 | D18: 2024-12-30 | E18: 2025-12-26 | F18: 52 | G18: 259 | H18: 0 | I18: 完整覆盖
A19: 2026 | B19: 1 | C19: 43 | D19: 2025-12-29 | E19: 2026-10-20 | F19: 43 | G19: 212 | H19: 0 | I19: 部分年份（缺前段/后段）

Sheet 05周度统计
A1: 05 周度同期统计（公式直连 02 面板）
A2: 均值/中位数/分位并列：均值易被单一年份拉走，中位数更抗异常；样本 n 一并给出
A3: 位置 | B3: 标签 | C3: n年 | D3: 均值 | E3: 中位数 | F3: 标准差 | G3: 最小 | H3: 最大 | I3: p10 | J3: p25 | K3: p50 | L3: p75 | M3: p90 | N3: IQR | O3: p90-p10 | P3: CV | Q3: 均值-中位 | R3: 均值/中位 | S3: 样本不足? | T3: 缺少年份 | U3: 样本年份
A4: 1 | B4: W01 | C4: =COUNT('02周度面板'!$B$4:$B$8) | D4: =IFERROR(AVERAGE('02周度面板'!$B$4:$B$8),"") | E4: =IFERROR(MEDIAN('02周度面板'!$B$4:$B$8),"") | F4: =IFERROR(STDEV('02周度面板'!$B$4:$B$8),"") | G4: =IFERROR(MIN('02周度面板'!$B$4:$B$8),"") | H4: =IFERROR(MAX('02周度面板'!$B$4:$B$8),"") | I4: =IFERROR(_xlfn.PERCENTILE.INC('02周度面板'!$B$4:$B$8,0.1),PERCENTILE('02周度面板'!$B$4:$B$8,0.1)) | J4: =IFERROR(_xlfn.PERCENTILE.INC('02周度面板'!$B$4:$B$8,0.25),PERCENTILE('02周度面板'!$B$4:$B$8,0.25)) | K4: =IFERROR(_xlfn.PERCENTILE.INC('02周度面板'!$B$4:$B$8,0.5),PERCENTILE('02周度面板'!$B$4:$B$8,0.5)) | L4: =IFERROR(_xlfn.PERCENTILE.INC('02周度面板'!$B$4:$B$8,0.75),PERCENTILE('02周度面板'!$B$4:$B$8,0.75)) | M4: =IFERROR(_xlfn.PERCENTILE.INC('02周度面板'!$B$4:$B$8,0.9),PERCENTILE('02周度面板'!$B$4:$B$8,0.9)) | N4: =IFERROR(J4-I4,"") | O4: =IFERROR(M4-I4,"") | P4: =IFERROR(F4/D4,"") | Q4: =IFERROR(D4-E4,"") | R4: =IFERROR(D4/E4,"") | S4: 否 | T4: 2022 | U4: 2023, 2024, 2025, 2026
A5: 2 | B5: W02 | C5: =COUNT('02周度面板'!$C$4:$C$8) | D5: =IFERROR(AVERAGE('02周度面板'!$C$4:$C$8),"") | E5: =IFERROR(MEDIAN('02周度面板'!$C$4:$C$8),"") | F5: =IFERROR(STDEV('02周度面板'!$C$4:$C$8),"") | G5: =IFERROR(MIN('02周度面板'!$C$4:$C$8),"") | H5: =IFERROR(MAX('02周度面板'!$C$4:$C$8),"") | I5: =IFERROR(_xlfn.PERCENTILE.INC('02周度面板'!$C$4:$C$8,0.1),PERCENTILE('02周度面板'!$C$4:$C$8,0.1)) | J5: =IFERROR(_xlfn.PERCENTILE.INC('02周度面板'!$C$4:$C$8,0.25),PERCENTILE('02周度面板'!$C$4:$C$8,0.25)) | K5: =IFERROR(_xlfn.PERCENTILE.INC('02周度面板'!$C$4:$C$8,0.5),PERCENTILE('02周度面板'!$C$4:$C$8,0.5)) | L5: =IFERROR(_xlfn.PERCENTILE.INC('02周度面板'!$C$4:$C$8,0.75),PERCENTILE('02周度面板'!$C$4:$C$8,0.75)) | M5: =IFERROR(_xlfn.PERCENTILE.INC('02周度面板'!$C$4:$C$8,0.9),PERCENTILE('02周度面板'!$C$4:$C$8,0.9)) | N5: =IFERROR(J5-I5,"") | O5: =IFERROR(M5-I5,"") | P5: =IFERROR(F5/D5,"") | Q5: =IFERROR(D5-E5,"") | R5: =IFERROR(D5/E5,"") | S5: 否 | T5: 2022 | U5: 2023, 2024, 2025, 2026
A6: 3 | B6: W03 | C6: =COUNT('02周度面板'!$D$4:$D$8) | D6: =IFERROR(AVERAGE('02周度面板'!$D$4:$D$8),"") | E6: =IFERROR(MEDIAN('02周度面板'!$D$4:$D$8),"") | F6: =IFERROR(STDEV('02周度面板'!$D$4:$D$8),"") | G6: =IFERROR(MIN('02周度面板'!$D$4:$D$8),"") | H6: =IFERROR(MAX('02周度面板'!$D$4:$D$8),"") | I6: =IFERROR(_xlfn.PERCENTILE.INC('02周度面板'!$D$4:$D$8,0.1),PERCENTILE('02周度面板'!$D$4:$D$8,0.1)) | J6: =IFERROR(_xlfn.PERCENTILE.INC('02周度面板'!$D$4:$D$8,0.25),PERCENTILE('02周度面板'!$D$4:$D$8,0.25)) | K6: =IFERROR(_xlfn.PERCENTILE.INC('02周度面板'!$D$4:$D$8,0.5),PERCENTILE('02周度面板'!$D$4:$D$8,0.5)) | L6: =IFERROR(_xlfn.PERCENTILE.INC('02周度面板'!$D$4:$D$8,0.75),PERCENTILE('02周度面板'!$D$4:$D$8,0.75)) | M6: =IFERROR(_xlfn.PERCENTILE.INC('02周度面板'!$D$4:$D$8,0.9),PERCENTILE('02周度面板'!$D$4:$D$8,0.9)) | N6: =IFERROR(J6-I6,"") | O6: =IFERROR(M6-I6,"") | P6: =IFERROR(F6/D6,"") | Q6: =IFERROR(D6-E6,"") | R6: =IFERROR(D6/E6,"") | S6: 否 | T6: 2022 | U6: 2023, 2024, 2025, 2026
A7: 4 | B7: W04 | C7: =COUNT('02周度面板'!$E$4:$E$8) | D7: =IFERROR(AVERAGE('02周度面板'!$E$4:$E$8),"") | E7: =IFERROR(MEDIAN('02周度面板'!$E$4:$E$8),"") | F7: =IFERROR(STDEV('02周度面板'!$E$4:$E$8),"") | G7: =IFERROR(MIN('02周度面板'!$E$4:$E$8),"") | H7: =IFERROR(MAX('02周度面板'!$E$4:$E$8),"") | I7: =IFERROR(_xlfn.PERCENTILE.INC('02周度面板'!$E$4:$E$8,0.1),PERCENTILE('02周度面板'!$E$4:$E$8,0.1)) | J7: =IFERROR(_xlfn.PERCENTILE.INC('02周度面板'!$E$4:$E$8,0.25),PERCENTILE('02周度面板'!$E$4:$E$8,0.25)) | K7: =IFERROR(_xlfn.PERCENTILE.INC('02周度面板'!$E$4:$E$8,0.5),PERCENTILE('02周度面板'!$E$4:$E$8,0.5)) | L7: =IFERROR(_xlfn.PERCENTILE.INC('02周度面板'!$E$4:$E$8,0.75),PERCENTILE('02周度面板'!$E$4:$E$8,0.75)) | M7: =IFERROR(_xlfn.PERCENTILE.INC('02周度面板'!$E$4:$E$8,0.9),PERCENTILE('02周度面板'!$E$4:$E$8,0.9)) | N7: =IFERROR(J7-I7,"") | O7: =IFERROR(M7-I7,"") | P7: =IFERROR(F7/D7,"") | Q7: =IFERROR(D7-E7,"") | R7: =IFERROR(D7/E7,"") | S7: 否 | T7: 2022 | U7: 2023, 2024, 2025, 2026
A8: 5 | B8: W05 | C8: =COUNT('02周度面板'!$F$4:$F$8) | D8: =IFERROR(AVERAGE('02周度面板'!$F$4:$F$8),"") | E8: =IFERROR(MEDIAN('02周度面板'!$F$4:$F$8),"") | F8: =IFERROR(STDEV('02周度面板'!$F$4:$F$8),"") | G8: =IFERROR(MIN('02周度面板'!$F$4:$F$8),"") | H8: =IFERROR(MAX('02周度面板'!$F$4:$F$8),"") | I8: =IFERROR(_xlfn.PERCENTILE.INC('02周度面板'!$F$4:$F$8,0.1),PERCENTILE('02周度面板'!$F$4:$F$8,0.1)) | J8: =IFERROR(_xlfn.PERCENTILE.INC('02周度面板'!$F$4:$F$8,0.25),PERCENTILE('02周度面板'!$F$4:$F$8,0.25)) | K8: =IFERROR(_xlfn.PERCENTILE.INC('02周度面板'!$F$4:$F$8,0.5),PERCENTILE('02周度面板'!$F$4:$F$8,0.5)) | L8: =IFERROR(_xlfn.PERCENTILE.INC('02周度面板'!$F$4:$F$8,0.75),PERCENTILE('02周度面板'!$F$4:$F$8,0.75)) | M8: =IFERROR(_xlfn.PERCENTILE.INC('02周度面板'!$F$4:$F$8,0.9),PERCENTILE('02周度面板'!$F$4:$F$8,0.9)) | N8: =IFERROR(J8-I8,"") | O8: =IFERROR(M8-I8,"") | P8: =IFERROR(F8/D8,"") | Q8: =IFERROR(D8-E8,"") | R8: =IFERROR(D8/E8,"") | S8: 否 | T8: 2022 | U8: 2023, 2024, 2025, 2026
A9: 6 | B9: W06 | C9: =COUNT('02周度面板'!$G$4:$G$8) | D9: =IFERROR(AVERAGE('02周度面板'!$G$4:$G$8),"") | E9: =IFERROR(MEDIAN('02周度面板'!$G$4:$G$8),"") | F9: =IFERROR(STDEV('02周度面板'!$G$4:$G$8),"") | G9: =IFERROR(MIN('02周度面板'!$G$4:$G$8),"") | H9: =IFERROR(MAX('02周度面板'!$G$4:$G$8),"") | I9: =IFERROR(_xlfn.PERCENTILE.INC('02周度面板'!$G$4:$G$8,0.1),PERCENTILE('02周度面板'!$G$4:$G$8,0.1)) | J9: =IFERROR(_xlfn.PERCENTILE.INC('02周度面板'!$G$4:$G$8,0.25),PERCENTILE('02周度面板'!$G$4:$G$8,0.25)) | K9: =IFERROR(_xlfn.PERCENTILE.INC('02周度面板'!$G$4:$G$8,0.5),PERCENTILE('02周度面板'!$G$4:$G$8,0.5)) | L9: =IFERROR(_xlfn.PERCENTILE.INC('02周度面板'!$G$4:$G$8,0.75),PERCENTILE('02周度面板'!$G$4:$G$8,0.75)) | M9: =IFERROR(_xlfn.PERCENTILE.INC('02周度面板'!$G$4:$G$8,0.9),PERCENTILE('02周度面板'!$G$4:$G$8,0.9)) | N9: =IFERROR(J9-I9,"") | O9: =IFERROR(M9-I9,"") | P9: =IFERROR(F9/D9,"") | Q9: =IFERROR(D9-E9,"") | R9: =IFERROR(D9/E9,"") | S9: 否 | T9: 2022 | U9: 2023, 2024, 2025, 2026
A10: 7 | B10: W07 | C10: =COUNT('02周度面板'!$H$4:$H$8) | D10: =IFERROR(AVERAGE('02周度面板'!$H$4:$H$8),"") | E10: =IFERROR(MEDIAN('02周度面板'!$H$4:$H$8),"") | F10: =IFERROR(STDEV('02周度面板'!$H$4:$H$8),"") | G10: =IFERROR(MIN('02周度面板'!$H$4:$H$8),"") | H10: =IFERROR(MAX('02周度面板'!$H$4:$H$8),"") | I10: =IFERROR(_xlfn.PERCENTILE.INC('02周度面板'!$H$4:$H$8,0.1),PERCENTILE('02周度面板'!$H$4:$H$8,0.1)) | J10: =IFERROR(_xlfn.PERCENTILE.INC('02周度面板'!$H$4:$H$8,0.25),PERCENTILE('02周度面板'!$H$4:$H$8,0.25)) | K10: =IFERROR(_xlfn.PERCENTILE.INC('02周度面板'!$H$4:$H$8,0.5),PERCENTILE('02周度面板'!$H$4:$H$8,0.5)) | L10: =IFERROR(_xlfn.PERCENTILE.INC('02周度面板'!$H$4:$H$8,0.75),PERCENTILE('02周度面板'!$H$4:$H$8,0.75)) | M10: =IFERROR(_xlfn.PERCENTILE.INC('02周度面板'!$H$4:$H$8,0.9),PERCENTILE('02周度面板'!$H$4:$H$8,0.9)) | N10: =IFERROR(J10-I10,"") | O10: =IFERROR(M10-I10,"") | P10: =IFERROR(F10/D10,"") | Q10: =IFERROR(D10-E10,"") | R10: =IFERROR(D10/E10,"") | S10: 否 | T10: 2022 | U10: 2023, 2024, 2025, 2026
A11: 8 | B11: W08 | C11: =COUNT('02周度面板'!$I$4:$I$8) | D11: =IFERROR(AVERAGE('02周度面板'!$I$4:$I$8),"") | E11: =IFERROR(MEDIAN('02周度面板'!$I$4:$I$8),"") | F11: =IFERROR(STDEV('02周度面板'!$I$4:$I$8),"") | G11: =IFERROR(MIN('02周度面板'!$I$4:$I$8),"") | H11: =IFERROR(MAX('02周度面板'!$I$4:$I$8),"") | I11: =IFERROR(_xlfn.PERCENTILE.INC('02周度面板'!$I$4:$I$8,0.1),PERCENTILE('02周度面板'!$I$4:$I$8,0.1)) | J11: =IFERROR(_xlfn.PERCENTILE.INC('02周度面板'!$I$4:$I$8,0.25),PERCENTILE('02周度面板'!$I$4:$I$8,0.25)) | K11: =IFERROR(_xlfn.PERCENTILE.INC('02周度面板'!$I$4:$I$8,0.5),PERCENTILE('02周度面板'!$I$4:$I$8,0.5)) | L11: =IFERROR(_xlfn.PERCENTILE.INC('02周度面板'!$I$4:$I$8,0.75),PERCENTILE('02周度面板'!$I$4:$I$8,0.75)) | M11: =IFERROR(_xlfn.PERCENTILE.INC('02周度面板'!$I$4:$I$8,0.9),PERCENTILE('02周度面板'!$I$4:$I$8,0.9)) | N11: =IFERROR(J11-I11,"") | O11: =IFERROR(M11-I11,"") | P11: =IFERROR(F11/D11,"") | Q11: =IFERROR(D11-E11,"") | R11: =IFERROR(D11/E11,"") | S11: 否 | T11: 2022 | U11: 2023, 2024, 2025, 2026
A12: 9 | B12: W09 | C12: =COUNT('02周度面板'!$J$4:$J$8) | D12: =IFERROR(AVERAGE('02周度面板'!$J$4:$J$8),"") | E12: =IFERROR(MEDIAN('02周度面板'!$J$4:$J$8),"") | F12: =IFERROR(STDEV('02周度面板'!$J$4:$J$8),"") | G12: =IFERROR(MIN('02周度面板'!$J$4:$J$8),"") | H12: =IFERROR(MAX('02周度面板'!$J$4:$J$8),"") | I12: =IFERROR(_xlfn.PERCENTILE.INC('02周度面板'!$J$4:$J$8,0.1),PERCENTILE('02周度面板'!$J$4:$J$8,0.1)) | J12: =IFERROR(_xlfn.PERCENTILE.INC('02周度面板'!$J$4:$J$8,0.25),PERCENTILE('02周度面板'!$J$4:$J$8,0.25)) | K12: =IFERROR(_xlfn.PERCENTILE.INC('02周度面板'!$J$4:$J$8,0.5),PERCENTILE('02周度面板'!$J$4:$J$8,0.5)) | L12: =IFERROR(_xlfn.PERCENTILE.INC('02周度面板'!$J$4:$J$8,0.75),PERCENTILE('02周度面板'!$J$4:$J$8,0.75)) | M12: =IFERROR(_xlfn.PERCENTILE.INC('02周度面板'!$J$4:$J$8,0.9),PERCENTILE('02周度面板'!$J$4:$J$8,0.9)) | N12: =IFERROR(J12-I12,"") | O12: =IFERROR(M12-I12,"") | P12: =IFERROR(F12/D12,"") | Q12: =IFERROR(D12-E12,"") | R12: =IFERROR(D12/E12,"") | S12: 否 | T12: 2022 | U12: 2023, 2024, 2025, 2026
A13: 10 | B13: W10 | C13: =COUNT('02周度面板'!$K$4:$K$8) | D13: =IFERROR(AVERAGE('02周度面板'!$K$4:$K$8),"") | E13: =IFERROR(MEDIAN('02周度面板'!$K$4:$K$8),"") | F13: =IFERROR(STDEV('02周度面板'!$K$4:$K$8),"") | G13: =IFERROR(MIN('02周度面板'!$K$4:$K$8),"") | H13: =IFERROR(MAX('02周度面板'!$K$4:$K$8),"") | I13: =IFERROR(_xlfn.PERCENTILE.INC('02周度面板'!$K$4:$K$8,0.1),PERCENTILE('02周度面板'!$K$4:$K$8,0.1)) | J13: =IFERROR(_xlfn.PERCENTILE.INC('02周度面板'!$K$4:$K$8,0.25),PERCENTILE('02周度面板'!$K$4:$K$8,0.25)) | K13: =IFERROR(_xlfn.PERCENTILE.INC('02周度面板'!$K$4:$K$8,0.5),PERCENTILE('02周度面板'!$K$4:$K$8,0.5)) | L13: =IFERROR(_xlfn.PERCENTILE.INC('02周度面板'!$K$4:$K$8,0.75),PERCENTILE('02周度面板'!$K$4:$K$8,0.75)) | M13: =IFERROR(_xlfn.PERCENTILE.INC('02周度面板'!$K$4:$K$8,0.9),PERCENTILE('02周度面板'!$K$4:$K$8,0.9)) | N13: =IFERROR(J13-I13,"") | O13: =IFERROR(M13-I13,"") | P13: =IFERROR(F13/D13,"") | Q13: =IFERROR(D13-E13,"") | R13: =IFERROR(D13/E13,"") | S13: 否 | T13: 2022 | U13: 2023, 2024, 2025, 2026
A14: 11 | B14: W11 | C14: =COUNT('02周度面板'!$L$4:$L$8) | D14: =IFERROR(AVERAGE('02周度面板'!$L$4:$L$8),"") | E14: =IFERROR(MEDIAN('02周度面板'!$L$4:$L$8),"") | F14: =IFERROR(STDEV('02周度面板'!$L$4:$L$8),"") | G14: =IFERROR(MIN('02周度面板'!$L$4:$L$8),"") | H14: =IFERROR(MAX('02周度面板'!$L$4:$L$8),"") | I14: =IFERROR(_xlfn.PERCENTILE.INC('02周度面板'!$L$4:$L$8,0.1),PERCENTILE('02周度面板'!$L$4:$L$8,0.1)) | J14: =IFERROR(_xlfn.PERCENTILE.INC('02周度面板'!$L$4:$L$8,0.25),PERCENTILE('02周度面板'!$L$4:$L$8,0.25)) | K14: =IFERROR(_xlfn.PERCENTILE.INC('02周度面板'!$L$4:$L$8,0.5),PERCENTILE('02周度面板'!$L$4:$L$8,0.5)) | L14: =IFERROR(_xlfn.PERCENTILE.INC('02周度面板'!$L$4:$L$8,0.75),PERCENTILE('02周度面板'!$L$4:$L$8,0.75)) | M14: =IFERROR(_xlfn.PERCENTILE.INC('02周度面板'!$L$4:$L$8,0.9),PERCENTILE('02周度面板'!$L$4:$L$8,0.9)) | N14: =IFERROR(J14-I14,"") | O14: =IFERROR(M14-I14,"") | P14: =IFERROR(F14/D14,"") | Q14: =IFERROR(D14-E14,"") | R14: =IFERROR(D14/E14,"") | S14: 否 | T14: 2022 | U14: 2023, 2024, 2025, 2026
A15: 12 | B15: W12 | C15: =COUNT('02周度面板'!$M$4:$M$8) | D15: =IFERROR(AVERAGE('02周度面板'!$M$4:$M$8),"") | E15: =IFERROR(MEDIAN('02周度面板'!$M$4:$M$8),"") | F15: =IFERROR(STDEV('02周度面板'!$M$4:$M$8),"") | G15: =IFERROR(MIN('02周度面板'!$M$4:$M$8),"") | H15: =IFERROR(MAX('02周度面板'!$M$4:$M$8),"") | I15: =IFERROR(_xlfn.PERCENTILE.INC('02周度面板'!$M$4:$M$8,0.1),PERCENTILE('02周度面板'!$M$4:$M$8,0.1)) | J15: =IFERROR(_xlfn.PERCENTILE.INC('02周度面板'!$M$4:$M$8,0.25),PERCENTILE('02周度面板'!$M$4:$M$8,0.25)) | K15: =IFERROR(_xlfn.PERCENTILE.INC('02周度面板'!$M$4:$M$8,0.5),PERCENTILE('02周度面板'!$M$4:$M$8,0.5)) | L15: =IFERROR(_xlfn.PERCENTILE.INC('02周度面板'!$M$4:$M$8,0.75),PERCENTILE('02周度面板'!$M$4:$M$8,0.75)) | M15: =IFERROR(_xlfn.PERCENTILE.INC('02周度面板'!$M$4:$M$8,0.9),PERCENTILE('02周度面板'!$M$4:$M$8,0.9)) | N15: =IFERROR(J15-I15,"") | O15: =IFERROR(M15-I15,"") | P15: =IFERROR(F15/D15,"") | Q15: =IFERROR(D15-E15,"") | R15: =IFERROR(D15/E15,"") | S15: 否 | T15: 2022 | U15: 2023, 2024, 2025, 2026
A16: 13 | B16: W13 | C16: =COUNT('02周度面板'!$N$4:$N$8) | D16: =IFERROR(AVERAGE('02周度面板'!$N$4:$N$8),"") | E16: =IFERROR(MEDIAN('02周度面板'!$N$4:$N$8),"") | F16: =IFERROR(STDEV('02周度面板'!$N$4:$N$8),"") | G16: =IFERROR(MIN('02周度面板'!$N$4:$N$8),"") | H16: =IFERROR(MAX('02周度面板'!$N$4:$N$8),"") | I16: =IFERROR(_xlfn.PERCENTILE.INC('02周度面板'!$N$4:$N$8,0.1),PERCENTILE('02周度面板'!$N$4:$N$8,0.1)) | J16: =IFERROR(_xlfn.PERCENTILE.INC('02周度面板'!$N$4:$N$8,0.25),PERCENTILE('02周度面板'!$N$4:$N$8,0.25)) | K16: =IFERROR(_xlfn.PERCENTILE.INC('02周度面板'!$N$4:$N$8,0.5),PERCENTILE('02周度面板'!$N$4:$N$8,0.5)) | L16: =IFERROR(_xlfn.PERCENTILE.INC('02周度面板'!$N$4:$N$8,0.75),PERCENTILE('02周度面板'!$N$4:$N$8,0.75)) | M16: =IFERROR(_xlfn.PERCENTILE.INC('02周度面板'!$N$4:$N$8,0.9),PERCENTILE('02周度面板'!$N$4:$N$8,0.9)) | N16: =IFERROR(J16-I16,"") | O16: =IFERROR(M16-I16,"") | P16: =IFERROR(F16/D16,"") | Q16: =IFERROR(D16-E16,"") | R16: =IFERROR(D16/E16,"") | S16: 否 | T16: 2022 | U16: 2023, 2024, 2025, 2026
A17: 14 | B17: W14 | C17: =COUNT('02周度面板'!$O$4:$O$8) | D17: =IFERROR(AVERAGE('02周度面板'!$O$4:$O$8),"") | E17: =IFERROR(MEDIAN('02周度面板'!$O$4:$O$8),"") | F17: =IFERROR(STDEV('02周度面板'!$O$4:$O$8),"") | G17: =IFERROR(MIN('02周度面板'!$O$4:$O$8),"") | H17: =IFERROR(MAX('02周度面板'!$O$4:$O$8),"") | I17: =IFERROR(_xlfn.PERCENTILE.INC('02周度面板'!$O$4:$O$8,0.1),PERCENTILE('02周度面板'!$O$4:$O$8,0.1)) | J17: =IFERROR(_xlfn.PERCENTILE.INC('02周度面板'!$O$4:$O$8,0.25),PERCENTILE('02周度面板'!$O$4:$O$8,0.25)) | K17: =IFERROR(_xlfn.PERCENTILE.INC('02周度面板'!$O$4:$O$8,0.5),PERCENTILE('02周度面板'!$O$4:$O$8,0.5)) | L17: =IFERROR(_xlfn.PERCENTILE.INC('02周度面板'!$O$4:$O$8,0.75),PERCENTILE('02周度面板'!$O$4:$O$8,0.75)) | M17: =IFERROR(_xlfn.PERCENTILE.INC('02周度面板'!$O$4:$O$8,0.9),PERCENTILE('02周度面板'!$O$4:$O$8,0.9)) | N17: =IFERROR(J17-I17,"") | O17: =IFERROR(M17-I17,"") | P17: =IFERROR(F17/D17,"") | Q17: =IFERROR(D17-E17,"") | R17: =IFERROR(D17/E17,"") | S17: 否 | T17: 2022 | U17: 2023, 2024, 2025, 2026
A18: 15 | B18: W15 | C18: =COUNT('02周度面板'!$P$4:$P$8) | D18: =IFERROR(AVERAGE('02周度面板'!$P$4:$P$8),"") | E18: =IFERROR(MEDIAN('02周度面板'!$P$4:$P$8),"") | F18: =IFERROR(STDEV('02周度面板'!$P$4:$P$8),"") | G18: =IFERROR(MIN('02周度面板'!$P$4:$P$8),"") | H18: =IFERROR(MAX('02周度面板'!$P$4:$P$8),"") | I18: =IFERROR(_xlfn.PERCENTILE.INC('02周度面板'!$P$4:$P$8,0.1),PERCENTILE('02周度面板'!$P$4:$P$8,0.1)) | J18: =IFERROR(_xlfn.PERCENTILE.INC('02周度面板'!$P$4:$P$8,0.25),PERCENTILE('02周度面板'!$P$4:$P$8,0.25)) | K18: =IFERROR(_xlfn.PERCENTILE.INC('02周度面板'!$P$4:$P$8,0.5),PERCENTILE('02周度面板'!$P$4:$P$8,0.5)) | L18: =IFERROR(_xlfn.PERCENTILE.INC('02周度面板'!$P$4:$P$8,0.75),PERCENTILE('02周度面板'!$P$4:$P$8,0.75)) | M18: =IFERROR(_xlfn.PERCENTILE.INC('02周度面板'!$P$4:$P$8,0.9),PERCENTILE('02周度面板'!$P$4:$P$8,0.9)) | N18: =IFERROR(J18-I18,"") | O18: =IFERROR(M18-I18,"") | P18: =IFERROR(F18/D18,"") | Q18: =IFERROR(D18-E18,"") | R18: =IFERROR(D18/E18,"") | S18: 否 | T18: 2022 | U18: 2023, 2024, 2025, 2026
A19: 16 | B19: W16 | C19: =COUNT('02周度面板'!$Q$4:$Q$8) | D19: =IFERROR(AVERAGE('02周度面板'!$Q$4:$Q$8),"") | E19: =IFERROR(MEDIAN('02周度面板'!$Q$4:$Q$8),"") | F19: =IFERROR(STDEV('02周度面板'!$Q$4:$Q$8),"") | G19: =IFERROR(MIN('02周度面板'!$Q$4:$Q$8),"") | H19: =IFERROR(MAX('02周度面板'!$Q$4:$Q$8),"") | I19: =IFERROR(_xlfn.PERCENTILE.INC('02周度面板'!$Q$4:$Q$8,0.1),PERCENTILE('02周度面板'!$Q$4:$Q$8,0.1)) | J19: =IFERROR(_xlfn.PERCENTILE.INC('02周度面板'!$Q$4:$Q$8,0.25),PERCENTILE('02周度面板'!$Q$4:$Q$8,0.25)) | K19: =IFERROR(_xlfn.PERCENTILE.INC('02周度面板'!$Q$4:$Q$8,0.5),PERCENTILE('02周度面板'!$Q$4:$Q$8,0.5)) | L19: =IFERROR(_xlfn.PERCENTILE.INC('02周度面板'!$Q$4:$Q$8,0.75),PERCENTILE('02周度面板'!$Q$4:$Q$8,0.75)) | M19: =IFERROR(_xlfn.PERCENTILE.INC('02周度面板'!$Q$4:$Q$8,0.9),PERCENTILE('02周度面板'!$Q$4:$Q$8,0.9)) | N19: =IFERROR(J19-I19,"") | O19: =IFERROR(M19-I19,"") | P19: =IFERROR(F19/D19,"") | Q19: =IFERROR(D19-E19,"") | R19: =IFERROR(D19/E19,"") | S19: 否 | T19: 2022 | U19: 2023, 2024, 2025, 2026
A20: 17 | B20: W17 | C20: =COUNT('02周度面板'!$R$4:$R$8) | D20: =IFERROR(AVERAGE('02周度面板'!$R$4:$R$8),"") | E20: =IFERROR(MEDIAN('02周度面板'!$R$4:$R$8),"") | F20: =IFERROR(STDEV('02周度面板'!$R$4:$R$8),"") | G20: =IFERROR(MIN('02周度面板'!$R$4:$R$8),"") | H20: =IFERROR(MAX('02周度面板'!$R$4:$R$8),"") | I20: =IFERROR(_xlfn.PERCENTILE.INC('02周度面板'!$R$4:$R$8,0.1),PERCENTILE('02周度面板'!$R$4:$R$8,0.1)) | J20: =IFERROR(_xlfn.PERCENTILE.INC('02周度面板'!$R$4:$R$8,0.25),PERCENTILE('02周度面板'!$R$4:$R$8,0.25)) | K20: =IFERROR(_xlfn.PERCENTILE.INC('02周度面板'!$R$4:$R$8,0.5),PERCENTILE('02周度面板'!$R$4:$R$8,0.5)) | L20: =IFERROR(_xlfn.PERCENTILE.INC('02周度面板'!$R$4:$R$8,0.75),PERCENTILE('02周度面板'!$R$4:$R$8,0.75)) | M20: =IFERROR(_xlfn.PERCENTILE.INC('02周度面板'!$R$4:$R$8,0.9),PERCENTILE('02周度面板'!$R$4:$R$8,0.9)) | N20: =IFERROR(J20-I20,"") | O20: =IFERROR(M20-I20,"") | P20: =IFERROR(F20/D20,"") | Q20: =IFERROR(D20-E20,"") | R20: =IFERROR(D20/E20,"") | S20: 否 | T20: 2022 | U20: 2023, 2024, 2025, 2026
A21: 18 | B21: W18 | C21: =COUNT('02周度面板'!$S$4:$S$8) | D21: =IFERROR(AVERAGE('02周度面板'!$S$4:$S$8),"") | E21: =IFERROR(MEDIAN('02周度面板'!$S$4:$S$8),"") | F21: =IFERROR(STDEV('02周度面板'!$S$4:$S$8),"") | G21: =IFERROR(MIN('02周度面板'!$S$4:$S$8),"") | H21: =IFERROR(MAX('02周度面板'!$S$4:$S$8),"") | I21: =IFERROR(_xlfn.PERCENTILE.INC('02周度面板'!$S$4:$S$8,0.1),PERCENTILE('02周度面板'!$S$4:$S$8,0.1)) | J21: =IFERROR(_xlfn.PERCENTILE.INC('02周度面板'!$S$4:$S$8,0.25),PERCENTILE('02周度面板'!$S$4:$S$8,0.25)) | K21: =IFERROR(_xlfn.PERCENTILE.INC('02周度面板'!$S$4:$S$8,0.5),PERCENTILE('02周度面板'!$S$4:$S$8,0.5)) | L21: =IFERROR(_xlfn.PERCENTILE.INC('02周度面板'!$S$4:$S$8,0.75),PERCENTILE('02周度面板'!$S$4:$S$8,0.75)) | M21: =IFERROR(_xlfn.PERCENTILE.INC('02周度面板'!$S$4:$S$8,0.9),PERCENTILE('02周度面板'!$S$4:$S$8,0.9)) | N21: =IFERROR(J21-I21,"") | O21: =IFERROR(M21-I21,"") | P21: =IFERROR(F21/D21,"") | Q21: =IFERROR(D21-E21,"") | R21: =IFERROR(D21/E21,"") | S21: 否 | T21: 2022 | U21: 2023, 2024, 2025, 2026
A22: 19 | B22: W19 | C22: =COUNT('02周度面板'!$T$4:$T$8) | D22: =IFERROR(AVERAGE('02周度面板'!$T$4:$T$8),"") | E22: =IFERROR(MEDIAN('02周度面板'!$T$4:$T$8),"") | F22: =IFERROR(STDEV('02周度面板'!$T$4:$T$8),"") | G22: =IFERROR(MIN('02周度面板'!$T$4:$T$8),"") | H22: =IFERROR(MAX('02周度面板'!$T$4:$T$8),"") | I22: =IFERROR(_xlfn.PERCENTILE.INC('02周度面板'!$T$4:$T$8,0.1),PERCENTILE('02周度面板'!$T$4:$T$8,0.1)) | J22: =IFERROR(_xlfn.PERCENTILE.INC('02周度面板'!$T$4:$T$8,0.25),PERCENTILE('02周度面板'!$T$4:$T$8,0.25)) | K22: =IFERROR(_xlfn.PERCENTILE.INC('02周度面板'!$T$4:$T$8,0.5),PERCENTILE('02周度面板'!$T$4:$T$8,0.5)) | L22: =IFERROR(_xlfn.PERCENTILE.INC('02周度面板'!$T$4:$T$8,0.75),PERCENTILE('02周度面板'!$T$4:$T$8,0.75)) | M22: =IFERROR(_xlfn.PERCENTILE.INC('02周度面板'!$T$4:$T$8,0.9),PERCENTILE('02周度面板'!$T$4:$T$8,0.9)) | N22: =IFERROR(J22-I22,"") | O22: =IFERROR(M22-I22,"") | P22: =IFERROR(F22/D22,"") | Q22: =IFERROR(D22-E22,"") | R22: =IFERROR(D22/E22,"") | S22: 否 | T22: 2022 | U22: 2023, 2024, 2025, 2026
A23: 20 | B23: W20 | C23: =COUNT('02周度面板'!$U$4:$U$8) | D23: =IFERROR(AVERAGE('02周度面板'!$U$4:$U$8),"") | E23: =IFERROR(MEDIAN('02周度面板'!$U$4:$U$8),"") | F23: =IFERROR(STDEV('02周度面板'!$U$4:$U$8),"") | G23: =IFERROR(MIN('02周度面板'!$U$4:$U$8),"") | H23: =IFERROR(MAX('02周度面板'!$U$4:$U$8),"") | I23: =IFERROR(_xlfn.PERCENTILE.INC('02周度面板'!$U$4:$U$8,0.1),PERCENTILE('02周度面板'!$U$4:$U$8,0.1)) | J23: =IFERROR(_xlfn.PERCENTILE.INC('02周度面板'!$U$4:$U$8,0.25),PERCENTILE('02周度面板'!$U$4:$U$8,0.25)) | K23: =IFERROR(_xlfn.PERCENTILE.INC('02周度面板'!$U$4:$U$8,0.5),PERCENTILE('02周度面板'!$U$4:$U$8,0.5)) | L23: =IFERROR(_xlfn.PERCENTILE.INC('02周度面板'!$U$4:$U$8,0.75),PERCENTILE('02周度面板'!$U$4:$U$8,0.75)) | M23: =IFERROR(_xlfn.PERCENTILE.INC('02周度面板'!$U$4:$U$8,0.9),PERCENTILE('02周度面板'!$U$4:$U$8,0.9)) | N23: =IFERROR(J23-I23,"") | O23: =IFERROR(M23-I23,"") | P23: =IFERROR(F23/D23,"") | Q23: =IFERROR(D23-E23,"") | R23: =IFERROR(D23/E23,"") | S23: 否 | T23: 2022 | U23: 2023, 2024, 2025, 2026
A24: 21 | B24: W21 | C24: =COUNT('02周度面板'!$V$4:$V$8) | D24: =IFERROR(AVERAGE('02周度面板'!$V$4:$V$8),"") | E24: =IFERROR(MEDIAN('02周度面板'!$V$4:$V$8),"") | F24: =IFERROR(STDEV('02周度面板'!$V$4:$V$8),"") | G24: =IFERROR(MIN('02周度面板'!$V$4:$V$8),"") | H24: =IFERROR(MAX('02周度面板'!$V$4:$V$8),"") | I24: =IFERROR(_xlfn.PERCENTILE.INC('02周度面板'!$V$4:$V$8,0.1),PERCENTILE('02周度面板'!$V$4:$V$8,0.1)) | J24: =IFERROR(_xlfn.PERCENTILE.INC('02周度面板'!$V$4:$V$8,0.25),PERCENTILE('02周度面板'!$V$4:$V$8,0.25)) | K24: =IFERROR(_xlfn.PERCENTILE.INC('02周度面板'!$V$4:$V$8,0.5),PERCENTILE('02周度面板'!$V$4:$V$8,0.5)) | L24: =IFERROR(_xlfn.PERCENTILE.INC('02周度面板'!$V$4:$V$8,0.75),PERCENTILE('02周度面板'!$V$4:$V$8,0.75)) | M24: =IFERROR(_xlfn.PERCENTILE.INC('02周度面板'!$V$4:$V$8,0.9),PERCENTILE('02周度面板'!$V$4:$V$8,0.9)) | N24: =IFERROR(J24-I24,"") | O24: =IFERROR(M24-I24,"") | P24: =IFERROR(F24/D24,"") | Q24: =IFERROR(D24-E24,"") | R24: =IFERROR(D24/E24,"") | S24: 否 | T24: 2022 | U24: 2023, 2024, 2025, 2026
A25: 22 | B25: W22 | C25: =COUNT('02周度面板'!$W$4:$W$8) | D25: =IFERROR(AVERAGE('02周度面板'!$W$4:$W$8),"") | E25: =IFERROR(MEDIAN('02周度面板'!$W$4:$W$8),"") | F25: =IFERROR(STDEV('02周度面板'!$W$4:$W$8),"") | G25: =IFERROR(MIN('02周度面板'!$W$4:$W$8),"") | H25: =IFERROR(MAX('02周度面板'!$W$4:$W$8),"") | I25: =IFERROR(_xlfn.PERCENTILE.INC('02周度面板'!$W$4:$W$8,0.1),PERCENTILE('02周度面板'!$W$4:$W$8,0.1)) | J25: =IFERROR(_xlfn.PERCENTILE.INC('02周度面板'!$W$4:$W$8,0.25),PERCENTILE('02周度面板'!$W$4:$W$8,0.25)) | K25: =IFERROR(_xlfn.PERCENTILE.INC('02周度面板'!$W$4:$W$8,0.5),PERCENTILE('02周度面板'!$W$4:$W$8,0.5)) | L25: =IFERROR(_xlfn.PERCENTILE.INC('02周度面板'!$W$4:$W$8,0.75),PERCENTILE('02周度面板'!$W$4:$W$8,0.75)) | M25: =IFERROR(_xlfn.PERCENTILE.INC('02周度面板'!$W$4:$W$8,0.9),PERCENTILE('02周度面板'!$W$4:$W$8,0.9)) | N25: =IFERROR(J25-I25,"") | O25: =IFERROR(M25-I25,"") | P25: =IFERROR(F25/D25,"") | Q25: =IFERROR(D25-E25,"") | R25: =IFERROR(D25/E25,"") | S25: 否 | T25: 2022 | U25: 2023, 2024, 2025, 2026
A26: 23 | B26: W23 | C26: =COUNT('02周度面板'!$X$4:$X$8) | D26: =IFERROR(AVERAGE('02周度面板'!$X$4:$X$8),"") | E26: =IFERROR(MEDIAN('02周度面板'!$X$4:$X$8),"") | F26: =IFERROR(STDEV('02周度面板'!$X$4:$X$8),"") | G26: =IFERROR(MIN('02周度面板'!$X$4:$X$8),"") | H26: =IFERROR(MAX('02周度面板'!$X$4:$X$8),"") | I26: =IFERROR(_xlfn.PERCENTILE.INC('02周度面板'!$X$4:$X$8,0.1),PERCENTILE('02周度面板'!$X$4:$X$8,0.1)) | J26: =IFERROR(_xlfn.PERCENTILE.INC('02周度面板'!$X$4:$X$8,0.25),PERCENTILE('02周度面板'!$X$4:$X$8,0.25)) | K26: =IFERROR(_xlfn.PERCENTILE.INC('02周度面板'!$X$4:$X$8,0.5),PERCENTILE('02周度面板'!$X$4:$X$8,0.5)) | L26: =IFERROR(_xlfn.PERCENTILE.INC('02周度面板'!$X$4:$X$8,0.75),PERCENTILE('02周度面板'!$X$4:$X$8,0.75)) | M26: =IFERROR(_xlfn.PERCENTILE.INC('02周度面板'!$X$4:$X$8,0.9),PERCENTILE('02周度面板'!$X$4:$X$8,0.9)) | N26: =IFERROR(J26-I26,"") | O26: =IFERROR(M26-I26,"") | P26: =IFERROR(F26/D26,"") | Q26: =IFERROR(D26-E26,"") | R26: =IFERROR(D26/E26,"") | S26: 否 | T26: 2022 | U26: 2023, 2024, 2025, 2026
A27: 24 | B27: W24 | C27: =COUNT('02周度面板'!$Y$4:$Y$8) | D27: =IFERROR(AVERAGE('02周度面板'!$Y$4:$Y$8),"") | E27: =IFERROR(MEDIAN('02周度面板'!$Y$4:$Y$8),"") | F27: =IFERROR(STDEV('02周度面板'!$Y$4:$Y$8),"") | G27: =IFERROR(MIN('02周度面板'!$Y$4:$Y$8),"") | H27: =IFERROR(MAX('02周度面板'!$Y$4:$Y$8),"") | I27: =IFERROR(_xlfn.PERCENTILE.INC('02周度面板'!$Y$4:$Y$8,0.1),PERCENTILE('02周度面板'!$Y$4:$Y$8,0.1)) | J27: =IFERROR(_xlfn.PERCENTILE.INC('02周度面板'!$Y$4:$Y$8,0.25),PERCENTILE('02周度面板'!$Y$4:$Y$8,0.25)) | K27: =IFERROR(_xlfn.PERCENTILE.INC('02周度面板'!$Y$4:$Y$8,0.5),PERCENTILE('02周度面板'!$Y$4:$Y$8,0.5)) | L27: =IFERROR(_xlfn.PERCENTILE.INC('02周度面板'!$Y$4:$Y$8,0.75),PERCENTILE('02周度面板'!$Y$4:$Y$8,0.75)) | M27: =IFERROR(_xlfn.PERCENTILE.INC('02周度面板'!$Y$4:$Y$8,0.9),PERCENTILE('02周度面板'!$Y$4:$Y$8,0.9)) | N27: =IFERROR(J27-I27,"") | O27: =IFERROR(M27-I27,"") | P27: =IFERROR(F27/D27,"") | Q27: =IFERROR(D27-E27,"") | R27: =IFERROR(D27/E27,"") | S27: 否 | T27: 2022 | U27: 2023, 2024, 2025, 2026
A28: 25 | B28: W25 | C28: =COUNT('02周度面板'!$Z$4:$Z$8) | D28: =IFERROR(AVERAGE('02周度面板'!$Z$4:$Z$8),"") | E28: =IFERROR(MEDIAN('02周度面板'!$Z$4:$Z$8),"") | F28: =IFERROR(STDEV('02周度面板'!$Z$4:$Z$8),"") | G28: =IFERROR(MIN('02周度面板'!$Z$4:$Z$8),"") | H28: =IFERROR(MAX('02周度面板'!$Z$4:$Z$8),"") | I28: =IFERROR(_xlfn.PERCENTILE.INC('02周度面板'!$Z$4:$Z$8,0.1),PERCENTILE('02周度面板'!$Z$4:$Z$8,0.1)) | J28: =IFERROR(_xlfn.PERCENTILE.INC('02周度面板'!$Z$4:$Z$8,0.25),PERCENTILE('02周度面板'!$Z$4:$Z$8,0.25)) | K28: =IFERROR(_xlfn.PERCENTILE.INC('02周度面板'!$Z$4:$Z$8,0.5),PERCENTILE('02周度面板'!$Z$4:$Z$8,0.5)) | L28: =IFERROR(_xlfn.PERCENTILE.INC('02周度面板'!$Z$4:$Z$8,0.75),PERCENTILE('02周度面板'!$Z$4:$Z$8,0.75)) | M28: =IFERROR(_xlfn.PERCENTILE.INC('02周度面板'!$Z$4:$Z$8,0.9),PERCENTILE('02周度面板'!$Z$4:$Z$8,0.9)) | N28: =IFERROR(J28-I28,"") | O28: =IFERROR(M28-I28,"") | P28: =IFERROR(F28/D28,"") | Q28: =IFERROR(D28-E28,"") | R28: =IFERROR(D28/E28,"") | S28: 否 | T28: 2022 | U28: 2023, 2024, 2025, 2026
A29: 26 | B29: W26 | C29: =COUNT('02周度面板'!$AA$4:$AA$8) | D29: =IFERROR(AVERAGE('02周度面板'!$AA$4:$AA$8),"") | E29: =IFERROR(MEDIAN('02周度面板'!$AA$4:$AA$8),"") | F29: =IFERROR(STDEV('02周度面板'!$AA$4:$AA$8),"") | G29: =IFERROR(MIN('02周度面板'!$AA$4:$AA$8),"") | H29: =IFERROR(MAX('02周度面板'!$AA$4:$AA$8),"") | I29: =IFERROR(_xlfn.PERCENTILE.INC('02周度面板'!$AA$4:$AA$8,0.1),PERCENTILE('02周度面板'!$AA$4:$AA$8,0.1)) | J29: =IFERROR(_xlfn.PERCENTILE.INC('02周度面板'!$AA$4:$AA$8,0.25),PERCENTILE('02周度面板'!$AA$4:$AA$8,0.25)) | K29: =IFERROR(_xlfn.PERCENTILE.INC('02周度面板'!$AA$4:$AA$8,0.5),PERCENTILE('02周度面板'!$AA$4:$AA$8,0.5)) | L29: =IFERROR(_xlfn.PERCENTILE.INC('02周度面板'!$AA$4:$AA$8,0.75),PERCENTILE('02周度面板'!$AA$4:$AA$8,0.75)) | M29: =IFERROR(_xlfn.PERCENTILE.INC('02周度面板'!$AA$4:$AA$8,0.9),PERCENTILE('02周度面板'!$AA$4:$AA$8,0.9)) | N29: =IFERROR(J29-I29,"") | O29: =IFERROR(M29-I29,"") | P29: =IFERROR(F29/D29,"") | Q29: =IFERROR(D29-E29,"") | R29: =IFERROR(D29/E29,"") | S29: 否 | T29: 2022 | U29: 2023, 2024, 2025, 2026
A30: 27 | B30: W27 | C30: =COUNT('02周度面板'!$AB$4:$AB$8) | D30: =IFERROR(AVERAGE('02周度面板'!$AB$4:$AB$8),"") | E30: =IFERROR(MEDIAN('02周度面板'!$AB$4:$AB$8),"") | F30: =IFERROR(STDEV('02周度面板'!$AB$4:$AB$8),"") | G30: =IFERROR(MIN('02周度面板'!$AB$4:$AB$8),"") | H30: =IFERROR(MAX('02周度面板'!$AB$4:$AB$8),"") | I30: =IFERROR(_xlfn.PERCENTILE.INC('02周度面板'!$AB$4:$AB$8,0.1),PERCENTILE('02周度面板'!$AB$4:$AB$8,0.1)) | J30: =IFERROR(_xlfn.PERCENTILE.INC('02周度面板'!$AB$4:$AB$8,0.25),PERCENTILE('02周度面板'!$AB$4:$AB$8,0.25)) | K30: =IFERROR(_xlfn.PERCENTILE.INC('02周度面板'!$AB$4:$AB$8,0.5),PERCENTILE('02周度面板'!$AB$4:$AB$8,0.5)) | L30: =IFERROR(_xlfn.PERCENTILE.INC('02周度面板'!$AB$4:$AB$8,0.75),PERCENTILE('02周度面板'!$AB$4:$AB$8,0.75)) | M30: =IFERROR(_xlfn.PERCENTILE.INC('02周度面板'!$AB$4:$AB$8,0.9),PERCENTILE('02周度面板'!$AB$4:$AB$8,0.9)) | N30: =IFERROR(J30-I30,"") | O30: =IFERROR(M30-I30,"") | P30: =IFERROR(F30/D30,"") | Q30: =IFERROR(D30-E30,"") | R30: =IFERROR(D30/E30,"") | S30: 否 | T30: 2022 | U30: 2023, 2024, 2025, 2026
A31: 28 | B31: W28 | C31: =COUNT('02周度面板'!$AC$4:$AC$8) | D31: =IFERROR(AVERAGE('02周度面板'!$AC$4:$AC$8),"") | E31: =IFERROR(MEDIAN('02周度面板'!$AC$4:$AC$8),"") | F31: =IFERROR(STDEV('02周度面板'!$AC$4:$AC$8),"") | G31: =IFERROR(MIN('02周度面板'!$AC$4:$AC$8),"") | H31: =IFERROR(MAX('02周度面板'!$AC$4:$AC$8),"") | I31: =IFERROR(_xlfn.PERCENTILE.INC('02周度面板'!$AC$4:$AC$8,0.1),PERCENTILE('02周度面板'!$AC$4:$AC$8,0.1)) | J31: =IFERROR(_xlfn.PERCENTILE.INC('02周度面板'!$AC$4:$AC$8,0.25),PERCENTILE('02周度面板'!$AC$4:$AC$8,0.25)) | K31: =IFERROR(_xlfn.PERCENTILE.INC('02周度面板'!$AC$4:$AC$8,0.5),PERCENTILE('02周度面板'!$AC$4:$AC$8,0.5)) | L31: =IFERROR(_xlfn.PERCENTILE.INC('02周度面板'!$AC$4:$AC$8,0.75),PERCENTILE('02周度面板'!$AC$4:$AC$8,0.75)) | M31: =IFERROR(_xlfn.PERCENTILE.INC('02周度面板'!$AC$4:$AC$8,0.9),PERCENTILE('02周度面板'!$AC$4:$AC$8,0.9)) | N31: =IFERROR(J31-I31,"") | O31: =IFERROR(M31-I31,"") | P31: =IFERROR(F31/D31,"") | Q31: =IFERROR(D31-E31,"") | R31: =IFERROR(D31/E31,"") | S31: 否 | T31: 2022 | U31: 2023, 2024, 2025, 2026
A32: 29 | B32: W29 | C32: =COUNT('02周度面板'!$AD$4:$AD$8) | D32: =IFERROR(AVERAGE('02周度面板'!$AD$4:$AD$8),"") | E32: =IFERROR(MEDIAN('02周度面板'!$AD$4:$AD$8),"") | F32: =IFERROR(STDEV('02周度面板'!$AD$4:$AD$8),"") | G32: =IFERROR(MIN('02周度面板'!$AD$4:$AD$8),"") | H32: =IFERROR(MAX('02周度面板'!$AD$4:$AD$8),"") | I32: =IFERROR(_xlfn.PERCENTILE.INC('02周度面板'!$AD$4:$AD$8,0.1),PERCENTILE('02周度面板'!$AD$4:$AD$8,0.1)) | J32: =IFERROR(_xlfn.PERCENTILE.INC('02周度面板'!$AD$4:$AD$8,0.25),PERCENTILE('02周度面板'!$AD$4:$AD$8,0.25)) | K32: =IFERROR(_xlfn.PERCENTILE.INC('02周度面板'!$AD$4:$AD$8,0.5),PERCENTILE('02周度面板'!$AD$4:$AD$8,0.5)) | L32: =IFERROR(_xlfn.PERCENTILE.INC('02周度面板'!$AD$4:$AD$8,0.75),PERCENTILE('02周度面板'!$AD$4:$AD$8,0.75)) | M32: =IFERROR(_xlfn.PERCENTILE.INC('02周度面板'!$AD$4:$AD$8,0.9),PERCENTILE('02周度面板'!$AD$4:$AD$8,0.9)) | N32: =IFERROR(J32-I32,"") | O32: =IFERROR(M32-I32,"") | P32: =IFERROR(F32/D32,"") | Q32: =IFERROR(D32-E32,"") | R32: =IFERROR(D32/E32,"") | S32: 否 | T32: 2022 | U32: 2023, 2024, 2025, 2026
A33: 30 | B33: W30 | C33: =COUNT('02周度面板'!$AE$4:$AE$8) | D33: =IFERROR(AVERAGE('02周度面板'!$AE$4:$AE$8),"") | E33: =IFERROR(MEDIAN('02周度面板'!$AE$4:$AE$8),"") | F33: =IFERROR(STDEV('02周度面板'!$AE$4:$AE$8),"") | G33: =IFERROR(MIN('02周度面板'!$AE$4:$AE$8),"") | H33: =IFERROR(MAX('02周度面板'!$AE$4:$AE$8),"") | I33: =IFERROR(_xlfn.PERCENTILE.INC('02周度面板'!$AE$4:$AE$8,0.1),PERCENTILE('02周度面板'!$AE$4:$AE$8,0.1)) | J33: =IFERROR(_xlfn.PERCENTILE.INC('02周度面板'!$AE$4:$AE$8,0.25),PERCENTILE('02周度面板'!$AE$4:$AE$8,0.25)) | K33: =IFERROR(_xlfn.PERCENTILE.INC('02周度面板'!$AE$4:$AE$8,0.5),PERCENTILE('02周度面板'!$AE$4:$AE$8,0.5)) | L33: =IFERROR(_xlfn.PERCENTILE.INC('02周度面板'!$AE$4:$AE$8,0.75),PERCENTILE('02周度面板'!$AE$4:$AE$8,0.75)) | M33: =IFERROR(_xlfn.PERCENTILE.INC('02周度面板'!$AE$4:$AE$8,0.9),PERCENTILE('02周度面板'!$AE$4:$AE$8,0.9)) | N33: =IFERROR(J33-I33,"") | O33: =IFERROR(M33-I33,"") | P33: =IFERROR(F33/D33,"") | Q33: =IFERROR(D33-E33,"") | R33: =IFERROR(D33/E33,"") | S33: 否 | T33: 2022 | U33: 2023, 2024, 2025, 2026
A34: 31 | B34: W31 | C34: =COUNT('02周度面板'!$AF$4:$AF$8) | D34: =IFERROR(AVERAGE('02周度面板'!$AF$4:$AF$8),"") | E34: =IFERROR(MEDIAN('02周度面板'!$AF$4:$AF$8),"") | F34: =IFERROR(STDEV('02周度面板'!$AF$4:$AF$8),"") | G34: =IFERROR(MIN('02周度面板'!$AF$4:$AF$8),"") | H34: =IFERROR(MAX('02周度面板'!$AF$4:$AF$8),"") | I34: =IFERROR(_xlfn.PERCENTILE.INC('02周度面板'!$AF$4:$AF$8,0.1),PERCENTILE('02周度面板'!$AF$4:$AF$8,0.1)) | J34: =IFERROR(_xlfn.PERCENTILE.INC('02周度面板'!$AF$4:$AF$8,0.25),PERCENTILE('02周度面板'!$AF$4:$AF$8,0.25)) | K34: =IFERROR(_xlfn.PERCENTILE.INC('02周度面板'!$AF$4:$AF$8,0.5),PERCENTILE('02周度面板'!$AF$4:$AF$8,0.5)) | L34: =IFERROR(_xlfn.PERCENTILE.INC('02周度面板'!$AF$4:$AF$8,0.75),PERCENTILE('02周度面板'!$AF$4:$AF$8,0.75)) | M34: =IFERROR(_xlfn.PERCENTILE.INC('02周度面板'!$AF$4:$AF$8,0.9),PERCENTILE('02周度面板'!$AF$4:$AF$8,0.9)) | N34: =IFERROR(J34-I34,"") | O34: =IFERROR(M34-I34,"") | P34: =IFERROR(F34/D34,"") | Q34: =IFERROR(D34-E34,"") | R34: =IFERROR(D34/E34,"") | S34: 否 | T34: 2022 | U34: 2023, 2024, 2025, 2026
A35: 32 | B35: W32 | C35: =COUNT('02周度面板'!$AG$4:$AG$8) | D35: =IFERROR(AVERAGE('02周度面板'!$AG$4:$AG$8),"") | E35: =IFERROR(MEDIAN('02周度面板'!$AG$4:$AG$8),"") | F35: =IFERROR(STDEV('02周度面板'!$AG$4:$AG$8),"") | G35: =IFERROR(MIN('02周度面板'!$AG$4:$AG$8),"") | H35: =IFERROR(MAX('02周度面板'!$AG$4:$AG$8),"") | I35: =IFERROR(_xlfn.PERCENTILE.INC('02周度面板'!$AG$4:$AG$8,0.1),PERCENTILE('02周度面板'!$AG$4:$AG$8,0.1)) | J35: =IFERROR(_xlfn.PERCENTILE.INC('02周度面板'!$AG$4:$AG$8,0.25),PERCENTILE('02周度面板'!$AG$4:$AG$8,0.25)) | K35: =IFERROR(_xlfn.PERCENTILE.INC('02周度面板'!$AG$4:$AG$8,0.5),PERCENTILE('02周度面板'!$AG$4:$AG$8,0.5)) | L35: =IFERROR(_xlfn.PERCENTILE.INC('02周度面板'!$AG$4:$AG$8,0.75),PERCENTILE('02周度面板'!$AG$4:$AG$8,0.75)) | M35: =IFERROR(_xlfn.PERCENTILE.INC('02周度面板'!$AG$4:$AG$8,0.9),PERCENTILE('02周度面板'!$AG$4:$AG$8,0.9)) | N35: =IFERROR(J35-I35,"") | O35: =IFERROR(M35-I35,"") | P35: =IFERROR(F35/D35,"") | Q35: =IFERROR(D35-E35,"") | R35: =IFERROR(D35/E35,"") | S35: 否 | T35: 2022 | U35: 2023, 2024, 2025, 2026
A36: 33 | B36: W33 | C36: =COUNT('02周度面板'!$AH$4:$AH$8) | D36: =IFERROR(AVERAGE('02周度面板'!$AH$4:$AH$8),"") | E36: =IFERROR(MEDIAN('02周度面板'!$AH$4:$AH$8),"") | F36: =IFERROR(STDEV('02周度面板'!$AH$4:$AH$8),"") | G36: =IFERROR(MIN('02周度面板'!$AH$4:$AH$8),"") | H36: =IFERROR(MAX('02周度面板'!$AH$4:$AH$8),"") | I36: =IFERROR(_xlfn.PERCENTILE.INC('02周度面板'!$AH$4:$AH$8,0.1),PERCENTILE('02周度面板'!$AH$4:$AH$8,0.1)) | J36: =IFERROR(_xlfn.PERCENTILE.INC('02周度面板'!$AH$4:$AH$8,0.25),PERCENTILE('02周度面板'!$AH$4:$AH$8,0.25)) | K36: =IFERROR(_xlfn.PERCENTILE.INC('02周度面板'!$AH$4:$AH$8,0.5),PERCENTILE('02周度面板'!$AH$4:$AH$8,0.5)) | L36: =IFERROR(_xlfn.PERCENTILE.INC('02周度面板'!$AH$4:$AH$8,0.75),PERCENTILE('02周度面板'!$AH$4:$AH$8,0.75)) | M36: =IFERROR(_xlfn.PERCENTILE.INC('02周度面板'!$AH$4:$AH$8,0.9),PERCENTILE('02周度面板'!$AH$4:$AH$8,0.9)) | N36: =IFERROR(J36-I36,"") | O36: =IFERROR(M36-I36,"") | P36: =IFERROR(F36/D36,"") | Q36: =IFERROR(D36-E36,"") | R36: =IFERROR(D36/E36,"") | S36: 否 | T36: — | U36: 2022, 2023, 2024, 2025, 2026
A37: 34 | B37: W34 | C37: =COUNT('02周度面板'!$AI$4:$AI$8) | D37: =IFERROR(AVERAGE('02周度面板'!$AI$4:$AI$8),"") | E37: =IFERROR(MEDIAN('02周度面板'!$AI$4:$AI$8),"") | F37: =IFERROR(STDEV('02周度面板'!$AI$4:$AI$8),"") | G37: =IFERROR(MIN('02周度面板'!$AI$4:$AI$8),"") | H37: =IFERROR(MAX('02周度面板'!$AI$4:$AI$8),"") | I37: =IFERROR(_xlfn.PERCENTILE.INC('02周度面板'!$AI$4:$AI$8,0.1),PERCENTILE('02周度面板'!$AI$4:$AI$8,0.1)) | J37: =IFERROR(_xlfn.PERCENTILE.INC('02周度面板'!$AI$4:$AI$8,0.25),PERCENTILE('02周度面板'!$AI$4:$AI$8,0.25)) | K37: =IFERROR(_xlfn.PERCENTILE.INC('02周度面板'!$AI$4:$AI$8,0.5),PERCENTILE('02周度面板'!$AI$4:$AI$8,0.5)) | L37: =IFERROR(_xlfn.PERCENTILE.INC('02周度面板'!$AI$4:$AI$8,0.75),PERCENTILE('02周度面板'!$AI$4:$AI$8,0.75)) | M37: =IFERROR(_xlfn.PERCENTILE.INC('02周度面板'!$AI$4:$AI$8,0.9),PERCENTILE('02周度面板'!$AI$4:$AI$8,0.9)) | N37: =IFERROR(J37-I37,"") | O37: =IFERROR(M37-I37,"") | P37: =IFERROR(F37/D37,"") | Q37: =IFERROR(D37-E37,"") | R37: =IFERROR(D37/E37,"") | S37: 否 | T37: — | U37: 2022, 2023, 2024, 2025, 2026
A38: 35 | B38: W35 | C38: =COUNT('02周度面板'!$AJ$4:$AJ$8) | D38: =IFERROR(AVERAGE('02周度面板'!$AJ$4:$AJ$8),"") | E38: =IFERROR(MEDIAN('02周度面板'!$AJ$4:$AJ$8),"") | F38: =IFERROR(STDEV('02周度面板'!$AJ$4:$AJ$8),"") | G38: =IFERROR(MIN('02周度面板'!$AJ$4:$AJ$8),"") | H38: =IFERROR(MAX('02周度面板'!$AJ$4:$AJ$8),"") | I38: =IFERROR(_xlfn.PERCENTILE.INC('02周度面板'!$AJ$4:$AJ$8,0.1),PERCENTILE('02周度面板'!$AJ$4:$AJ$8,0.1)) | J38: =IFERROR(_xlfn.PERCENTILE.INC('02周度面板'!$AJ$4:$AJ$8,0.25),PERCENTILE('02周度面板'!$AJ$4:$AJ$8,0.25)) | K38: =IFERROR(_xlfn.PERCENTILE.INC('02周度面板'!$AJ$4:$AJ$8,0.5),PERCENTILE('02周度面板'!$AJ$4:$AJ$8,0.5)) | L38: =IFERROR(_xlfn.PERCENTILE.INC('02周度面板'!$AJ$4:$AJ$8,0.75),PERCENTILE('02周度面板'!$AJ$4:$AJ$8,0.75)) | M38: =IFERROR(_xlfn.PERCENTILE.INC('02周度面板'!$AJ$4:$AJ$8,0.9),PERCENTILE('02周度面板'!$AJ$4:$AJ$8,0.9)) | N38: =IFERROR(J38-I38,"") | O38: =IFERROR(M38-I38,"") | P38: =IFERROR(F38/D38,"") | Q38: =IFERROR(D38-E38,"") | R38: =IFERROR(D38/E38,"") | S38: 否 | T38: — | U38: 2022, 2023, 2024, 2025, 2026
A39: 36 | B39: W36 | C39: =COUNT('02周度面板'!$AK$4:$AK$8) | D39: =IFERROR(AVERAGE('02周度面板'!$AK$4:$AK$8),"") | E39: =IFERROR(MEDIAN('02周度面板'!$AK$4:$AK$8),"") | F39: =IFERROR(STDEV('02周度面板'!$AK$4:$AK$8),"") | G39: =IFERROR(MIN('02周度面板'!$AK$4:$AK$8),"") | H39: =IFERROR(MAX('02周度面板'!$AK$4:$AK$8),"") | I39: =IFERROR(_xlfn.PERCENTILE.INC('02周度面板'!$AK$4:$AK$8,0.1),PERCENTILE('02周度面板'!$AK$4:$AK$8,0.1)) | J39: =IFERROR(_xlfn.PERCENTILE.INC('02周度面板'!$AK$4:$AK$8,0.25),PERCENTILE('02周度面板'!$AK$4:$AK$8,0.25)) | K39: =IFERROR(_xlfn.PERCENTILE.INC('02周度面板'!$AK$4:$AK$8,0.5),PERCENTILE('02周度面板'!$AK$4:$AK$8,0.5)) | L39: =IFERROR(_xlfn.PERCENTILE.INC('02周度面板'!$AK$4:$AK$8,0.75),PERCENTILE('02周度面板'!$AK$4:$AK$8,0.75)) | M39: =IFERROR(_xlfn.PERCENTILE.INC('02周度面板'!$AK$4:$AK$8,0.9),PERCENTILE('02周度面板'!$AK$4:$AK$8,0.9)) | N39: =IFERROR(J39-I39,"") | O39: =IFERROR(M39-I39,"") | P39: =IFERROR(F39/D39,"") | Q39: =IFERROR(D39-E39,"") | R39: =IFERROR(D39/E39,"") | S39: 否 | T39: — | U39: 2022, 2023, 2024, 2025, 2026
A40: 37 | B40: W37 | C40: =COUNT('02周度面板'!$AL$4:$AL$8) | D40: =IFERROR(AVERAGE('02周度面板'!$AL$4:$AL$8),"") | E40: =IFERROR(MEDIAN('02周度面板'!$AL$4:$AL$8),"") | F40: =IFERROR(STDEV('02周度面板'!$AL$4:$AL$8),"") | G40: =IFERROR(MIN('02周度面板'!$AL$4:$AL$8),"") | H40: =IFERROR(MAX('02周度面板'!$AL$4:$AL$8),"") | I40: =IFERROR(_xlfn.PERCENTILE.INC('02周度面板'!$AL$4:$AL$8,0.1),PERCENTILE('02周度面板'!$AL$4:$AL$8,0.1)) | J40: =IFERROR(_xlfn.PERCENTILE.INC('02周度面板'!$AL$4:$AL$8,0.25),PERCENTILE('02周度面板'!$AL$4:$AL$8,0.25)) | K40: =IFERROR(_xlfn.PERCENTILE.INC('02周度面板'!$AL$4:$AL$8,0.5),PERCENTILE('02周度面板'!$AL$4:$AL$8,0.5)) | L40: =IFERROR(_xlfn.PERCENTILE.INC('02周度面板'!$AL$4:$AL$8,0.75),PERCENTILE('02周度面板'!$AL$4:$AL$8,0.75)) | M40: =IFERROR(_xlfn.PERCENTILE.INC('02周度面板'!$AL$4:$AL$8,0.9),PERCENTILE('02周度面板'!$AL$4:$AL$8,0.9)) | N40: =IFERROR(J40-I40,"") | O40: =IFERROR(M40-I40,"") | P40: =IFERROR(F40/D40,"") | Q40: =IFERROR(D40-E40,"") | R40: =IFERROR(D40/E40,"") | S40: 否 | T40: — | U40: 2022, 2023, 2024, 2025, 2026
...

Sheet 06月度统计
A1: 06 月度同期统计（公式直连 03 面板）
A2: 同上；月度 n 通常 4–5 年，分位不确定性大
A3: 位置 | B3: 标签 | C3: n年 | D3: 均值 | E3: 中位数 | F3: 标准差 | G3: 最小 | H3: 最大 | I3: p10 | J3: p25 | K3: p50 | L3: p75 | M3: p90 | N3: IQR | O3: p90-p10 | P3: CV | Q3: 均值-中位 | R3: 均值/中位 | S3: 样本不足? | T3: 缺少年份 | U3: 样本年份
A4: 1 | B4: 01月 | C4: =COUNT('03月度面板'!$B$4:$B$8) | D4: =IFERROR(AVERAGE('03月度面板'!$B$4:$B$8),"") | E4: =IFERROR(MEDIAN('03月度面板'!$B$4:$B$8),"") | F4: =IFERROR(STDEV('03月度面板'!$B$4:$B$8),"") | G4: =IFERROR(MIN('03月度面板'!$B$4:$B$8),"") | H4: =IFERROR(MAX('03月度面板'!$B$4:$B$8),"") | I4: =IFERROR(_xlfn.PERCENTILE.INC('03月度面板'!$B$4:$B$8,0.1),PERCENTILE('03月度面板'!$B$4:$B$8,0.1)) | J4: =IFERROR(_xlfn.PERCENTILE.INC('03月度面板'!$B$4:$B$8,0.25),PERCENTILE('03月度面板'!$B$4:$B$8,0.25)) | K4: =IFERROR(_xlfn.PERCENTILE.INC('03月度面板'!$B$4:$B$8,0.5),PERCENTILE('03月度面板'!$B$4:$B$8,0.5)) | L4: =IFERROR(_xlfn.PERCENTILE.INC('03月度面板'!$B$4:$B$8,0.75),PERCENTILE('03月度面板'!$B$4:$B$8,0.75)) | M4: =IFERROR(_xlfn.PERCENTILE.INC('03月度面板'!$B$4:$B$8,0.9),PERCENTILE('03月度面板'!$B$4:$B$8,0.9)) | N4: =IFERROR(J4-I4,"") | O4: =IFERROR(M4-I4,"") | P4: =IFERROR(F4/D4,"") | Q4: =IFERROR(D4-E4,"") | R4: =IFERROR(D4/E4,"") | S4: 否 | T4: 2022 | U4: 2023, 2024, 2025, 2026
A5: 2 | B5: 02月 | C5: =COUNT('03月度面板'!$C$4:$C$8) | D5: =IFERROR(AVERAGE('03月度面板'!$C$4:$C$8),"") | E5: =IFERROR(MEDIAN('03月度面板'!$C$4:$C$8),"") | F5: =IFERROR(STDEV('03月度面板'!$C$4:$C$8),"") | G5: =IFERROR(MIN('03月度面板'!$C$4:$C$8),"") | H5: =IFERROR(MAX('03月度面板'!$C$4:$C$8),"") | I5: =IFERROR(_xlfn.PERCENTILE.INC('03月度面板'!$C$4:$C$8,0.1),PERCENTILE('03月度面板'!$C$4:$C$8,0.1)) | J5: =IFERROR(_xlfn.PERCENTILE.INC('03月度面板'!$C$4:$C$8,0.25),PERCENTILE('03月度面板'!$C$4:$C$8,0.25)) | K5: =IFERROR(_xlfn.PERCENTILE.INC('03月度面板'!$C$4:$C$8,0.5),PERCENTILE('03月度面板'!$C$4:$C$8,0.5)) | L5: =IFERROR(_xlfn.PERCENTILE.INC('03月度面板'!$C$4:$C$8,0.75),PERCENTILE('03月度面板'!$C$4:$C$8,0.75)) | M5: =IFERROR(_xlfn.PERCENTILE.INC('03月度面板'!$C$4:$C$8,0.9),PERCENTILE('03月度面板'!$C$4:$C$8,0.9)) | N5: =IFERROR(J5-I5,"") | O5: =IFERROR(M5-I5,"") | P5: =IFERROR(F5/D5,"") | Q5: =IFERROR(D5-E5,"") | R5: =IFERROR(D5/E5,"") | S5: 否 | T5: 2022 | U5: 2023, 2024, 2025, 2026
A6: 3 | B6: 03月 | C6: =COUNT('03月度面板'!$D$4:$D$8) | D6: =IFERROR(AVERAGE('03月度面板'!$D$4:$D$8),"") | E6: =IFERROR(MEDIAN('03月度面板'!$D$4:$D$8),"") | F6: =IFERROR(STDEV('03月度面板'!$D$4:$D$8),"") | G6: =IFERROR(MIN('03月度面板'!$D$4:$D$8),"") | H6: =IFERROR(MAX('03月度面板'!$D$4:$D$8),"") | I6: =IFERROR(_xlfn.PERCENTILE.INC('03月度面板'!$D$4:$D$8,0.1),PERCENTILE('03月度面板'!$D$4:$D$8,0.1)) | J6: =IFERROR(_xlfn.PERCENTILE.INC('03月度面板'!$D$4:$D$8,0.25),PERCENTILE('03月度面板'!$D$4:$D$8,0.25)) | K6: =IFERROR(_xlfn.PERCENTILE.INC('03月度面板'!$D$4:$D$8,0.5),PERCENTILE('03月度面板'!$D$4:$D$8,0.5)) | L6: =IFERROR(_xlfn.PERCENTILE.INC('03月度面板'!$D$4:$D$8,0.75),PERCENTILE('03月度面板'!$D$4:$D$8,0.75)) | M6: =IFERROR(_xlfn.PERCENTILE.INC('03月度面板'!$D$4:$D$8,0.9),PERCENTILE('03月度面板'!$D$4:$D$8,0.9)) | N6: =IFERROR(J6-I6,"") | O6: =IFERROR(M6-I6,"") | P6: =IFERROR(F6/D6,"") | Q6: =IFERROR(D6-E6,"") | R6: =IFERROR(D6/E6,"") | S6: 否 | T6: 2022 | U6: 2023, 2024, 2025, 2026
A7: 4 | B7: 04月 | C7: =COUNT('03月度面板'!$E$4:$E$8) | D7: =IFERROR(AVERAGE('03月度面板'!$E$4:$E$8),"") | E7: =IFERROR(MEDIAN('03月度面板'!$E$4:$E$8),"") | F7: =IFERROR(STDEV('03月度面板'!$E$4:$E$8),"") | G7: =IFERROR(MIN('03月度面板'!$E$4:$E$8),"") | H7: =IFERROR(MAX('03月度面板'!$E$4:$E$8),"") | I7: =IFERROR(_xlfn.PERCENTILE.INC('03月度面板'!$E$4:$E$8,0.1),PERCENTILE('03月度面板'!$E$4:$E$8,0.1)) | J7: =IFERROR(_xlfn.PERCENTILE.INC('03月度面板'!$E$4:$E$8,0.25),PERCENTILE('03月度面板'!$E$4:$E$8,0.25)) | K7: =IFERROR(_xlfn.PERCENTILE.INC('03月度面板'!$E$4:$E$8,0.5),PERCENTILE('03月度面板'!$E$4:$E$8,0.5)) | L7: =IFERROR(_xlfn.PERCENTILE.INC('03月度面板'!$E$4:$E$8,0.75),PERCENTILE('03月度面板'!$E$4:$E$8,0.75)) | M7: =IFERROR(_xlfn.PERCENTILE.INC('03月度面板'!$E$4:$E$8,0.9),PERCENTILE('03月度面板'!$E$4:$E$8,0.9)) | N7: =IFERROR(J7-I7,"") | O7: =IFERROR(M7-I7,"") | P7: =IFERROR(F7/D7,"") | Q7: =IFERROR(D7-E7,"") | R7: =IFERROR(D7/E7,"") | S7: 否 | T7: 2022 | U7: 2023, 2024, 2025, 2026
A8: 5 | B8: 05月 | C8: =COUNT('03月度面板'!$F$4:$F$8) | D8: =IFERROR(AVERAGE('03月度面板'!$F$4:$F$8),"") | E8: =IFERROR(MEDIAN('03月度面板'!$F$4:$F$8),"") | F8: =IFERROR(STDEV('03月度面板'!$F$4:$F$8),"") | G8: =IFERROR(MIN('03月度面板'!$F$4:$F$8),"") | H8: =IFERROR(MAX('03月度面板'!$F$4:$F$8),"") | I8: =IFERROR(_xlfn.PERCENTILE.INC('03月度面板'!$F$4:$F$8,0.1),PERCENTILE('03月度面板'!$F$4:$F$8,0.1)) | J8: =IFERROR(_xlfn.PERCENTILE.INC('03月度面板'!$F$4:$F$8,0.25),PERCENTILE('03月度面板'!$F$4:$F$8,0.25)) | K8: =IFERROR(_xlfn.PERCENTILE.INC('03月度面板'!$F$4:$F$8,0.5),PERCENTILE('03月度面板'!$F$4:$F$8,0.5)) | L8: =IFERROR(_xlfn.PERCENTILE.INC('03月度面板'!$F$4:$F$8,0.75),PERCENTILE('03月度面板'!$F$4:$F$8,0.75)) | M8: =IFERROR(_xlfn.PERCENTILE.INC('03月度面板'!$F$4:$F$8,0.9),PERCENTILE('03月度面板'!$F$4:$F$8,0.9)) | N8: =IFERROR(J8-I8,"") | O8: =IFERROR(M8-I8,"") | P8: =IFERROR(F8/D8,"") | Q8: =IFERROR(D8-E8,"") | R8: =IFERROR(D8/E8,"") | S8: 否 | T8: 2022 | U8: 2023, 2024, 2025, 2026
A9: 6 | B9: 06月 | C9: =COUNT('03月度面板'!$G$4:$G$8) | D9: =IFERROR(AVERAGE('03月度面板'!$G$4:$G$8),"") | E9: =IFERROR(MEDIAN('03月度面板'!$G$4:$G$8),"") | F9: =IFERROR(STDEV('03月度面板'!$G$4:$G$8),"") | G9: =IFERROR(MIN('03月度面板'!$G$4:$G$8),"") | H9: =IFERROR(MAX('03月度面板'!$G$4:$G$8),"") | I9: =IFERROR(_xlfn.PERCENTILE.INC('03月度面板'!$G$4:$G$8,0.1),PERCENTILE('03月度面板'!$G$4:$G$8,0.1)) | J9: =IFERROR(_xlfn.PERCENTILE.INC('03月度面板'!$G$4:$G$8,0.25),PERCENTILE('03月度面板'!$G$4:$G$8,0.25)) | K9: =IFERROR(_xlfn.PERCENTILE.INC('03月度面板'!$G$4:$G$8,0.5),PERCENTILE('03月度面板'!$G$4:$G$8,0.5)) | L9: =IFERROR(_xlfn.PERCENTILE.INC('03月度面板'!$G$4:$G$8,0.75),PERCENTILE('03月度面板'!$G$4:$G$8,0.75)) | M9: =IFERROR(_xlfn.PERCENTILE.INC('03月度面板'!$G$4:$G$8,0.9),PERCENTILE('03月度面板'!$G$4:$G$8,0.9)) | N9: =IFERROR(J9-I9,"") | O9: =IFERROR(M9-I9,"") | P9: =IFERROR(F9/D9,"") | Q9: =IFERROR(D9-E9,"") | R9: =IFERROR(D9/E9,"") | S9: 否 | T9: 2022 | U9: 2023, 2024, 2025, 2026
A10: 7 | B10: 07月 | C10: =COUNT('03月度面板'!$H$4:$H$8) | D10: =IFERROR(AVERAGE('03月度面板'!$H$4:$H$8),"") | E10: =IFERROR(MEDIAN('03月度面板'!$H$4:$H$8),"") | F10: =IFERROR(STDEV('03月度面板'!$H$4:$H$8),"") | G10: =IFERROR(MIN('03月度面板'!$H$4:$H$8),"") | H10: =IFERROR(MAX('03月度面板'!$H$4:$H$8),"") | I10: =IFERROR(_xlfn.PERCENTILE.INC('03月度面板'!$H$4:$H$8,0.1),PERCENTILE('03月度面板'!$H$4:$H$8,0.1)) | J10: =IFERROR(_xlfn.PERCENTILE.INC('03月度面板'!$H$4:$H$8,0.25),PERCENTILE('03月度面板'!$H$4:$H$8,0.25)) | K10: =IFERROR(_xlfn.PERCENTILE.INC('03月度面板'!$H$4:$H$8,0.5),PERCENTILE('03月度面板'!$H$4:$H$8,0.5)) | L10: =IFERROR(_xlfn.PERCENTILE.INC('03月度面板'!$H$4:$H$8,0.75),PERCENTILE('03月度面板'!$H$4:$H$8,0.75)) | M10: =IFERROR(_xlfn.PERCENTILE.INC('03月度面板'!$H$4:$H$8,0.9),PERCENTILE('03月度面板'!$H$4:$H$8,0.9)) | N10: =IFERROR(J10-I10,"") | O10: =IFERROR(M10-I10,"") | P10: =IFERROR(F10/D10,"") | Q10: =IFERROR(D10-E10,"") | R10: =IFERROR(D10/E10,"") | S10: 否 | T10: 2022 | U10: 2023, 2024, 2025, 2026
A11: 8 | B11: 08月 | C11: =COUNT('03月度面板'!$I$4:$I$8) | D11: =IFERROR(AVERAGE('03月度面板'!$I$4:$I$8),"") | E11: =IFERROR(MEDIAN('03月度面板'!$I$4:$I$8),"") | F11: =IFERROR(STDEV('03月度面板'!$I$4:$I$8),"") | G11: =IFERROR(MIN('03月度面板'!$I$4:$I$8),"") | H11: =IFERROR(MAX('03月度面板'!$I$4:$I$8),"") | I11: =IFERROR(_xlfn.PERCENTILE.INC('03月度面板'!$I$4:$I$8,0.1),PERCENTILE('03月度面板'!$I$4:$I$8,0.1)) | J11: =IFERROR(_xlfn.PERCENTILE.INC('03月度面板'!$I$4:$I$8,0.25),PERCENTILE('03月度面板'!$I$4:$I$8,0.25)) | K11: =IFERROR(_xlfn.PERCENTILE.INC('03月度面板'!$I$4:$I$8,0.5),PERCENTILE('03月度面板'!$I$4:$I$8,0.5)) | L11: =IFERROR(_xlfn.PERCENTILE.INC('03月度面板'!$I$4:$I$8,0.75),PERCENTILE('03月度面板'!$I$4:$I$8,0.75)) | M11: =IFERROR(_xlfn.PERCENTILE.INC('03月度面板'!$I$4:$I$8,0.9),PERCENTILE('03月度面板'!$I$4:$I$8,0.9)) | N11: =IFERROR(J11-I11,"") | O11: =IFERROR(M11-I11,"") | P11: =IFERROR(F11/D11,"") | Q11: =IFERROR(D11-E11,"") | R11: =IFERROR(D11/E11,"") | S11: 否 | T11: — | U11: 2022, 2023, 2024, 2025, 2026
A12: 9 | B12: 09月 | C12: =COUNT('03月度面板'!$J$4:$J$8) | D12: =IFERROR(AVERAGE('03月度面板'!$J$4:$J$8),"") | E12: =IFERROR(MEDIAN('03月度面板'!$J$4:$J$8),"") | F12: =IFERROR(STDEV('03月度面板'!$J$4:$J$8),"") | G12: =IFERROR(MIN('03月度面板'!$J$4:$J$8),"") | H12: =IFERROR(MAX('03月度面板'!$J$4:$J$8),"") | I12: =IFERROR(_xlfn.PERCENTILE.INC('03月度面板'!$J$4:$J$8,0.1),PERCENTILE('03月度面板'!$J$4:$J$8,0.1)) | J12: =IFERROR(_xlfn.PERCENTILE.INC('03月度面板'!$J$4:$J$8,0.25),PERCENTILE('03月度面板'!$J$4:$J$8,0.25)) | K12: =IFERROR(_xlfn.PERCENTILE.INC('03月度面板'!$J$4:$J$8,0.5),PERCENTILE('03月度面板'!$J$4:$J$8,0.5)) | L12: =IFERROR(_xlfn.PERCENTILE.INC('03月度面板'!$J$4:$J$8,0.75),PERCENTILE('03月度面板'!$J$4:$J$8,0.75)) | M12: =IFERROR(_xlfn.PERCENTILE.INC('03月度面板'!$J$4:$J$8,0.9),PERCENTILE('03月度面板'!$J$4:$J$8,0.9)) | N12: =IFERROR(J12-I12,"") | O12: =IFERROR(M12-I12,"") | P12: =IFERROR(F12/D12,"") | Q12: =IFERROR(D12-E12,"") | R12: =IFERROR(D12/E12,"") | S12: 否 | T12: — | U12: 2022, 2023, 2024, 2025, 2026
A13: 10 | B13: 10月 | C13: =COUNT('03月度面板'!$K$4:$K$8) | D13: =IFERROR(AVERAGE('03月度面板'!$K$4:$K$8),"") | E13: =IFERROR(MEDIAN('03月度面板'!$K$4:$K$8),"") | F13: =IFERROR(STDEV('03月度面板'!$K$4:$K$8),"") | G13: =IFERROR(MIN('03月度面板'!$K$4:$K$8),"") | H13: =IFERROR(MAX('03月度面板'!$K$4:$K$8),"") | I13: =IFERROR(_xlfn.PERCENTILE.INC('03月度面板'!$K$4:$K$8,0.1),PERCENTILE('03月度面板'!$K$4:$K$8,0.1)) | J13: =IFERROR(_xlfn.PERCENTILE.INC('03月度面板'!$K$4:$K$8,0.25),PERCENTILE('03月度面板'!$K$4:$K$8,0.25)) | K13: =IFERROR(_xlfn.PERCENTILE.INC('03月度面板'!$K$4:$K$8,0.5),PERCENTILE('03月度面板'!$K$4:$K$8,0.5)) | L13: =IFERROR(_xlfn.PERCENTILE.INC('03月度面板'!$K$4:$K$8,0.75),PERCENTILE('03月度面板'!$K$4:$K$8,0.75)) | M13: =IFERROR(_xlfn.PERCENTILE.INC('03月度面板'!$K$4:$K$8,0.9),PERCENTILE('03月度面板'!$K$4:$K$8,0.9)) | N13: =IFERROR(J13-I13,"") | O13: =IFERROR(M13-I13,"") | P13: =IFERROR(F13/D13,"") | Q13: =IFERROR(D13-E13,"") | R13: =IFERROR(D13/E13,"") | S13: 否 | T13: — | U13: 2022, 2023, 2024, 2025, 2026
A14: 11 | B14: 11月 | C14: =COUNT('03月度面板'!$L$4:$L$8) | D14: =IFERROR(AVERAGE('03月度面板'!$L$4:$L$8),"") | E14: =IFERROR(MEDIAN('03月度面板'!$L$4:$L$8),"") | F14: =IFERROR(STDEV('03月度面板'!$L$4:$L$8),"") | G14: =IFERROR(MIN('03月度面板'!$L$4:$L$8),"") | H14: =IFERROR(MAX('03月度面板'!$L$4:$L$8),"") | I14: =IFERROR(_xlfn.PERCENTILE.INC('03月度面板'!$L$4:$L$8,0.1),PERCENTILE('03月度面板'!$L$4:$L$8,0.1)) | J14: =IFERROR(_xlfn.PERCENTILE.INC('03月度面板'!$L$4:$L$8,0.25),PERCENTILE('03月度面板'!$L$4:$L$8,0.25)) | K14: =IFERROR(_xlfn.PERCENTILE.INC('03月度面板'!$L$4:$L$8,0.5),PERCENTILE('03月度面板'!$L$4:$L$8,0.5)) | L14: =IFERROR(_xlfn.PERCENTILE.INC('03月度面板'!$L$4:$L$8,0.75),PERCENTILE('03月度面板'!$L$4:$L$8,0.75)) | M14: =IFERROR(_xlfn.PERCENTILE.INC('03月度面板'!$L$4:$L$8,0.9),PERCENTILE('03月度面板'!$L$4:$L$8,0.9)) | N14: =IFERROR(J14-I14,"") | O14: =IFERROR(M14-I14,"") | P14: =IFERROR(F14/D14,"") | Q14: =IFERROR(D14-E14,"") | R14: =IFERROR(D14/E14,"") | S14: 否 | T14: 2026 | U14: 2022, 2023, 2024, 2025
A15: 12 | B15: 12月 | C15: =COUNT('03月度面板'!$M$4:$M$8) | D15: =IFERROR(AVERAGE('03月度面板'!$M$4:$M$8),"") | E15: =IFERROR(MEDIAN('03月度面板'!$M$4:$M$8),"") | F15: =IFERROR(STDEV('03月度面板'!$M$4:$M$8),"") | G15: =IFERROR(MIN('03月度面板'!$M$4:$M$8),"") | H15: =IFERROR(MAX('03月度面板'!$M$4:$M$8),"") | I15: =IFERROR(_xlfn.PERCENTILE.INC('03月度面板'!$M$4:$M$8,0.1),PERCENTILE('03月度面板'!$M$4:$M$8,0.1)) | J15: =IFERROR(_xlfn.PERCENTILE.INC('03月度面板'!$M$4:$M$8,0.25),PERCENTILE('03月度面板'!$M$4:$M$8,0.25)) | K15: =IFERROR(_xlfn.PERCENTILE.INC('03月度面板'!$M$4:$M$8,0.5),PERCENTILE('03月度面板'!$M$4:$M$8,0.5)) | L15: =IFERROR(_xlfn.PERCENTILE.INC('03月度面板'!$M$4:$M$8,0.75),PERCENTILE('03月度面板'!$M$4:$M$8,0.75)) | M15: =IFERROR(_xlfn.PERCENTILE.INC('03月度面板'!$M$4:$M$8,0.9),PERCENTILE('03月度面板'!$M$4:$M$8,0.9)) | N15: =IFERROR(J15-I15,"") | O15: =IFERROR(M15-I15,"") | P15: =IFERROR(F15/D15,"") | Q15: =IFERROR(D15-E15,"") | R15: =IFERROR(D15/E15,"") | S15: 否 | T15: 2026 | U15: 2022, 2023, 2024, 2025
A17: 说明：本表统计列为活公式，直接引用「03月度面板」面板；修改面板后按 F9 即复算。PERCENTILE.INC 与 numpy 默认 linear 插值、R type 7 完全等价。

Sheet 07归一化面板
A1: 07 年初归一化面板（该年窗口首个有效观测 = 100）
A2: 把"年份价格水平不同"从形态里剥离，只看年内节奏；百分比口径
A3: 年份 | B3: 基期位置 | C3: 基期日期 | D3: 基期价格 | E3: W01 | F3: W02 | G3: W03 | H3: W04 | I3: W05 | J3: W06 | K3: W07 | L3: W08 | M3: W09 | N3: W10 | O3: W11 | P3: W12 | Q3: W13 | R3: W14 | S3: W15 | T3: W16 | U3: W17 | V3: W18 | W3: W19 | X3: W20 | Y3: W21 | Z3: W22 | AA3: W23 | AB3: W24 | AC3: W25 | AD3: W26 | AE3: W27 | AF3: W28 | AG3: W29 | AH3: W30 | AI3: W31 | AJ3: W32 | AK3: W33 | AL3: W34 | AM3: W35 | AN3: W36 | AO3: W37 | AP3: W38 | AQ3: W39 | AR3: W40 | AS3: W41 | AT3: W42 | AU3: W43 | AV3: W44 | AW3: W45 | AX3: W46 | AY3: W47 | AZ3: W48 | BA3: W49 | BB3: W50 | BC3: W51 | BD3: W52
A4: 2022 | B4: 33 | C4: 2022-08-17 | D4: 2438.75 | AK4: 100 | AL4: 105.3306 | AM4: 104.7155 | AN4: 111.225 | AO4: 113.5828 | AP4: 113.4188 | AQ4: 123.5264 | AR4: 127.3193 | AS4: 117.3757 | AT4: 118.6674 | AU4: 114.8129 | AV4: 116.9042 | AW4: 110.3709 | AX4: 114.8129 | AY4: 114.2319 | AZ4: 109.9608 | BA4: 107.9106 | BB4: 109.8239 | BC4: 106.612 | BD4: 107.9106
A5: 2023 | B5: 1 | C5: 2023-01-02 | D5: 2671.67 | E5: 100 | F5: 98.6585 | G5: 100.6861 | H5: 100.6861 | I5: 101.9336 | J5: 101.4882 | K5: 101.4882 | L5: 103.3997 | M5: 101.1229 | N5: 98.7521 | O5: 96.4127 | P5: 97.6917 | Q5: 95.1963 | R5: 92.5762 | S5: 92.514 | T5: 95.4459 | U5: 93.1376 | V5: 90.2683 | W5: 88.3343 | X5: 87.7103 | Y5: 79.9436 | Z5: 80.9108 | AA5: 78.0721 | AB5: 77.1053 | AC5: 78.2907 | AD5: 80.9108 | AE5: 80.6922 | AF5: 84.217 | AG5: 84.0609 | AH5: 84.2481 | AI5: 87.2424 | AJ5: 88.5839 | AK5: 88.1782 | AL5: 91.9212 | AM5: 94.5102 | AN5: 93.5434 | AO5: 94.6037 | AP5: 95.0406 | AQ5: 92.7633 | AR5: 92.7633 | AS5: 92.8258 | AT5: 91.7029 | AU5: 90.9543 | AV5: 90.2058 | AW5: 93.7926 | AX5: 93.4183 | AY5: 88.5525 | AZ5: 93.9798 | BA5: 91.8901 | BB5: 90.6111 | BC5: 93.0441 | BD5: 91.9526
