Workbook

Sheet 11 进度看板
B2: 进口资料进度看板
B3: ID-H2O2-KR-20261020 · 基准日 2026-10-20 · 过氧化氢溶液（双氧水） 30.0%（质量分数，H₂O₂） · 韩国（大韩民国） → 中国
B5: 一、关键指标
B6: 总体评级 | C6: D · 不可放行（存在硬缺口）
B7: 单证完备度（齐备/必须） | C7: =COUNTIF('04 单证要求'!$F$6:$F$31,"齐备")&" / "&COUNTIF('04 单证要求'!$E$6:$E$31,"必须")
B8: P0 缺口 | C8: =COUNTIF('06 缺失资料'!$B$6:$B$20,"P0")
B9: P0 已完成 | C9: =COUNTIFS('06 缺失资料'!$B$6:$B$20,"P0",'06 缺失资料'!$I$6:$I$20,"☑")
B10: 缺口完成率 | C10: =TEXT(IFERROR(COUNTIF('06 缺失资料'!$I$6:$I$20,"☑")/COUNTA('06 缺失资料'!$A$6:$A$20),0),"0.0%")
B11: 待确认事项 | C11: ='08 待确认事项'!D18
B12: 高优先级未闭环 | C12: ='08 待确认事项'!F18
B13: 监管事项总数 | C13: =COUNTA('03 法规依据'!$A$6:$A$20)
B15: 二、单证状态分布
B16: 齐备 | C16: =COUNTIF('04 单证要求'!$F$6:$F$31,"齐备")
B17: 有但不完整 | C17: =COUNTIF('04 单证要求'!$F$6:$F$31,"有但不完整")
B18: 缺失 | C18: =COUNTIF('04 单证要求'!$F$6:$F$31,"缺失")
B19: 待定（需外部确认） | C19: =COUNTIF('04 单证要求'!$F$6:$F$31,"待定（需外部确认）")
B20: 过期/版本失效 | C20: =COUNTIF('04 单证要求'!$F$6:$F$31,"过期/版本失效")
B21: 不适用 | C21: =COUNTIF('04 单证要求'!$F$6:$F$31,"不适用")
B23: 三、放行闸门
B24: GATE-1 身份闸门 | C24: 待确认 | D24: CAS/浓度/组成/稳定剂/用途/包装/运输方式全部有证据支撑，且与 PI、SDS、合同一致
B25: GATE-2 归类闸门 | C25: 通过 | D25: HS 首选编码可回溯到税则条文与归类决定要素；不确定点已书面移交（报关行/预归类/预裁定）
B26: GATE-3 监管闸门 | C26: 待确认 | D26: 《危险化学品目录》、易制爆/易制毒、两用物项、用途专项（食品/消毒/药品）逐项比对，无 pending
B27: GATE-4 运输闸门 | C27: 通过 | D27: UN 编号/类项/包装类别/正确运输名称与 IMDG（或 IATA）一致，包装与积载满足要求
B28: GATE-5 文件闸门 | C28: 未通过 | D28: 中文化学品安全技术说明书、中文危险公示标签、符合性声明、UN 包装标记信息齐备
B29: GATE-6 税费与原产地闸门 | C29: 待确认 | D29: 适用税率（最惠国/协定/暂定）与优惠资格已确认；原产地证书与直接运输条件满足
B31: 四、缺口按责任方分布
B32: 承运人 | C32: =COUNTIF('06 缺失资料'!$G$6:$G$20,"承运人")
B33: 报关代理 | C33: =COUNTIF('06 缺失资料'!$G$6:$G$20,"报关代理")
B34: 海外供应商 | C34: =COUNTIF('06 缺失资料'!$G$6:$G$20,"海外供应商")
B35: 进口商 | C35: =COUNTIF('06 缺失资料'!$G$6:$G$20,"进口商")
B36: 进口商/海外供应商 | C36: =COUNTIF('06 缺失资料'!$G$6:$G$20,"进口商/海外供应商")

Sheet 00 封面与结论
B2: 进口资料准备与合规核验底稿
B3: 韩国 · 工业级 30% 过氧化氢溶液（UN2014）→ 中国上海 · 进口资料准备与合规核验底稿
B5: 总体结论：D · 不可放行（存在硬缺口）
B6: 产品身份、HS 归类与危险货物运输分类三条主线已可锁定（2847.00.0000 / UN2014 / 危化品目录第903项高度可能适用）；阻断点集中在**中文合规文件（SDS、标签）、稳定剂披露、符合性声明与包装UN标记**四项，补齐后可进入报关准备。
B8: 一、底稿信息
B9: 记录编号 | C9: ID-H2O2-KR-20261020
B10: 基准日（as_of） | C10: 2026-10-20
B11: 场景 | C11: 外贸采购 / 查进口资料要求
B12: 整理 / 复核 | C12: 外贸采购 / 关务合规（演示）
B13: 数据密级 | C13: 内部（含模拟件）
B14: 方法论版本 | C14: 1.0
B15: 生成日期 | C15: 2026-10-20
B17: 二、输入要素（任一变化须重跑）
B18: 要素 | C18: 取值
B19: 来源国家 | C19: 韩国（大韩民国）
B20: 产品名称（中） | C20: 过氧化氢溶液（双氧水）
B21: 产品名称（英） | C21: HYDROGEN PEROXIDE AQUEOUS SOLUTION 30%
B22: CAS | C22: 7722-84-1
B23: 浓度/含量 | C23: 30.0%（质量分数，H₂O₂）
B24: 物理形态 | C24: 液体（均相水溶液）
B25: 等级 | C25: 工业级
B26: 用途 | C26: 用于电子行业 PCB 蚀刻后微蚀工序的单槽漂洗，浓度按工艺稀释至 3%~5% 使用
B27: 包装 | C27: 30 kg UN 认证高密度聚乙烯（HDPE）桶装，每托 20 桶（含托盘与缠绕膜），共约 34 托
B28: 包装容器 | C28: HDPE 开顶桶（中型包装物/桶类，带排气盖）
B29: 数量 | C29: 20 000 kg（20 吨）
... B34: 进口企业 | C34: 华东某精细化工有限公司（脱敏示例）
B36: 三、结论分项
B37: 产品身份 | C37: 30% 过氧化氢水溶液 + 少量稳定剂；定级『部分确认』，差稳定剂明细与『无功能性添加剂』声明
B38: HS归类 | C38: 2847.00.0000（高置信）；CIQ 落 20%≤含量≤60% 段
B39: 监管属性 | C39: 危化品目录第903项（视条件适用）、易制爆名录6.1（适用）、监管条件 A/G 待逐项确认
B40: 税费 | C40: 最惠国 5.5% + 增值税 13%；协定税率存在数据冲突，须以单一窗口核实
B41: 运输与包装 | C41: UN2014 / 5.1 + 8 / PG II；须取得 UN 包装证书与标记照片
B42: 单证完备度 | C42: 关键缺失 6 项（中文SDS、中文标签、稳定剂声明、符合性声明、包装证书、PI术语更正）
B44: 四、结论口径（可以写 / 不能写）
B45: 可以写 | C45: 不能写
B46: 可以写：产品高度可能适用《危险化学品目录（2015版）》第903项，需按危险化学品办理中文SDS、中文标签与登记 | C46: 不能写：产品一定属于危险化学品（未取得稳定剂声明前）
B47: 可以写：2847.00.0000 归类置信度高，依据第28章章注一（二）（四） | C47: 不能写：归类已获海关认可
B48: 可以写：危险货物按 UN2014 / 5.1 / PG II 运输 | C48: 不能写：包装类别 II 等同于 GHS 氧化性液体类别2
B49: 可以写：最惠国税率 5.5%，增值税 13% | C49: 不能写：协定税率已确定为 1.1%
B50: 可以写：如需转售，进口主体须持危化品经营许可证 | C50: 不能写：进口自用无需任何危化品资质
...

Sheet 01 产品属性
A1: 01 · 产品属性
A2: 产品身份要素、组成与风险点。组成必须写到稳定剂——这是『过氧化氢的水溶液』能否成立的判断前提。
A5: 身份判断
A6: 身份结论 | B6: partial
A7: 一句话判断 | B7: 产品身份已基本锁定为『H₂O₂ 约 30% 的水溶液 + 少量磷/锡酸盐类稳定剂』，但稳定剂具体品种与限量、以及是否构成『过氧化氢的水溶液』这一监管前提，仍缺供应商书面确认，因此危化品与易制爆的适用性只能做到『高度可能适用』而非『已证实适用』。
A9: 组成（成分表）
A10: 组分 | B10: 英文名 | C10: CAS | D10: 含量下限% | E10: 含量上限% | F10: 角色
A11: 过氧化氢 | B11: Hydrogen peroxide | C11: 7722-84-1 | D11: 30 | E11: 31 | F11: 主成分（氧化剂）
A12: 稳定剂（磷酸盐类） | B12: Stabiliser (phosphate based) | C12: — | D12: 0.02 | E12: 0.08 | F12: 稳定剂（运输安全所必需）
A13: 硝酸盐稳定剂 | B13: Nitrate stabiliser | C13: 13377-33-8 | D13: 0.01 | E13: 0.05 | F13: 稳定剂
A14: 锡酸盐稳定剂 | B14: Sodium stannate | C14: 12058-66-1 | D14: 0.005 | E14: 0.02 | F14: 稳定剂
A15: 水 | B15: Water | C15: 7732-18-5 | D15: 68.85 | E15: 69.965 | F15: 溶剂
A16: 合计 | D16: =SUM(D11:D15) | E16: =SUM(E11:E15)
A18: 已确认要素
A19: ✓ CAS 7722-84-1（过氧化氢）——SDS（模拟件 U01）第1、3节与 PI（U03）一致
A20: ✓ 主成分浓度 30%~31%（质量分数）——SDS 第3节、COA（U02）实测 30.4%、PI（U03）三处一致
A21: ✓ 物态：均相水溶液，不含有机溶剂
A22: ✓ 原产国：韩国；出口港：Busan
A23: ✓ 包装：30 kg HDPE 桶，非散装
A24: ✓ 运输方式：海运整柜 FCL
A26: 仍未确认的要素
A27: ? 稳定剂的确切化学名称与加入量（SDS 第3节仅写『磷酸盐类稳定剂』，未给 CAS 与精确百分比）
A28: ? 是否含《危险化学品目录》实施指南所称『稳定剂、惰性化学品以外』的其他功能性添加剂
A29: ? 是否同一批次对应同一 SDS 版本号（SDS 未印版本号与修订日期）
A30: ? 工业级是否满足国内下游对铁/总有机碳（TOC）的限值（TDS 未提供）
... A33: 身份风险点与处置
A34: 风险点 | B34: 为什么是风险 | C34: 处置动作
A35: 稳定剂未披露到品种与用量 | B35: 《危险化学品目录》第903项只覆盖『过氧化氢的水溶液』；应急管理部答复（S03）明确『添加其他化学品（稳定剂、惰性化学品除外）』即不再自动落入该条。稳定剂本身在豁免范围内，但若含功能性添加剂（如缓蚀剂、润湿剂）则可能需重新鉴定危化品属性。 | C35: 要求供应商出具稳定剂清单（名称+CAS+精确%) 与『仅含稳定剂、无其他功能性添加剂』的书面声明（见 R-D03 / G03）
A36: 浓度口径只写在 SDS 正文，未写入标签 | B36: 浓度跨越 8%/20%/60% 三个阈值时会同时改变危化品目录适用、易制爆分类（氧化性液体类别1/2/3）与 UN 编号（2984/2014/2015）。若实际交货为 27.5% 或 50%，监管口径完全不同。 | C36: 合同、PI、COA、标签四处浓度必须锁死为『30.0%（质量分数）』并附加允许偏差（±0.5 个百分点以内且不得跨阈值）
A37: SDS 无版本号与修订日期 | B37: GB/T 16483（S10）要求 SDS 载明修订日期；海关 129 号公告（S05）要对中文 SDS 样本做内容审核，无版本号无法证明其为当前版本。 | C37: 索取带版本号与修订日期的 SDS（中英对照），并要求供应商承诺变更时主动更新
A38: 用途如切换为食品添加剂或消毒产品，监管路径完全不同 | B38: 海关 129 号公告第八条（S05）：用作食品、食品添加剂的进出口危险化学品还须符合食品安全相关规定；消毒产品另有卫生许可与备案路径。 | C38: 用途变更前必须重跑 P1–P3；本底稿仅对『PCB 微蚀用工业级』成立

Sheet 02 HS候选
A1: 02 · HS 编码候选与归类依据
A2: 归类是一条推理链：章注/子目注释 → 品目条文 → 成立条件 → 不确定性。候选必须写出排名、置信度与推翻条件。
A5: 排名 | B5: 税则号列 | C5: 品目描述 | D5: 置信度 | E5: 归类依据 | F5: 成立条件 | G5: 不成立时去向 | H5: 来源
A6: 1 | B6: 2847.00.0000 | C6: 过氧化氢（不论是否用尿素固化） | D6: 高 | E6: 第28章章注一（二）：本章税目适用于『上述（一）款产品的水溶液』；章注一（四）：为保存或运输需要加入稳定剂的仍归本章；品目 28.47 条文『过氧化氢，无论是否用尿素固化』。本产品为 H₂O₂ 水溶液 + 运输所必需的稳定剂，未改变一般用途。 | F6: 成立条件：①主成分为过氧化氢；②溶剂仅为水；③添加剂限于稳定剂/防尘剂/着色剂且不改变一般用途；④未与其他有效成分构成具有专门功能的制剂。 | G6: 若加入改变用途的功能性添加剂（如作为杀菌制剂配方出售、含表面活性剂的复配消毒液），可能落入 3808；若按重量计浓度极低且用于特定行业配方，需按具体商品判别。 | H6: S06,S18
A7: 2 | B7: 2850.00.0090 / 2853 | C7: 其他无机化合物（兜底品目） | D7: 低 | E7: 仅在无法满足 28 章章注一时作为兜底讨论；本产品明显满足章注一，兜底品目不应优先。 | F7: 不成立：本章有明确列名品目 28.47 时不使用兜底品目。 | G7: — | H7: S06
A8: 3 | B8: 3808.94 / 3808.99 | C8: 消毒剂、杀虫剂等零售或制剂形态产品 | D8: 低 | E8: 仅当产品以『消毒剂成药』形态申报、具备专门配方与标签宣称时讨论。本单为工业级原料，标签不宣称消毒，故不适用。 | F8: 不成立：工业级 30% 过氧化氢为基本化工原料，非零售消毒制剂。 | G8: 若用途改为医疗消毒并取得相应注册，则需重判。 | H8: S06
A10: 归类结论
A11: 推荐编码 | B11: 2847.00.0000
A12: 不确定性 | B12: 本单归类置信度高（唯一列名品目 + 章注明确涵盖水溶液与稳定剂），但仍有两处不确定：①若供应商稳定剂清单中出现改变用途的功能性添加剂，需复核是否仍在 28 章；②同名商品在实务中存在按『含量』申报差异（海关 CIQ 扩展码对 ≥60%、20%~60%、8%~20% 分列），申报时应与 HS 一并准确填报含量水平。
A13: 是否需要预裁定 | B13: 否（高置信，建议报关行复核后申报）
A14: 规范申报要素（顺序） | B14: 品牌类型 / 出口享惠情况 / 成分含量 / 包装规格 / GTIN（非必填） / CAS
A15: 填报示例 | B15: 0|2|过氧化氢30%，水约69.9%，稳定剂<0.1%|30公斤/桶(HDPE桶)，每托20桶||7722-84-1
A16: CIQ 扩展码 | B16: 2847000000.101 过氧化氢（含量＞60%，特许的） 2847000000.102 过氧化氢（20%≤含量≤60%）← 本单应落在此段 2847000000.103 过氧化氢（8%≤含量＜20%） 2847000000.104 过氧化氢尿素 2847000000.105 非工业用无检疫要求食品添加剂
A17: CIQ 说明 | B17: CIQ 扩展码由报关代理按海关现行参数选取；本单含量 30% 对应 20%~60% 段，与 UN2014 分级一致，可互相印证。

Sheet 03 法规依据
A1: 03 · 监管事项与法规依据
A2: 每条结论都带：判定四态 / 条文依据 / 适用条件 / 对本单影响 / 责任方 / 可回溯来源编号。『待核验』不等于『不适用』。
A5: 编号 | B5: 管理层 | C5: 监管事项 | D5: 判定 | E5: 结论 | F5: 依据（条文） | G5: 来源编号 | H5: 适用条件 | I5: 对本单的影响 | J5: 责任方 | K5: 置信
A6: R01 | B6: 危险化学品管理 | C6: 是否列入《危险化学品目录》 | D6: 视条件适用 | E6: 高度可能适用第 903 项『过氧化氢溶液[含量＞8%]』；因稳定剂品种未完全披露，结论定级为『视条件适用』。 | F6: 《危险化学品目录（2015版）》第903项（S02）；目录说明第四条（无含量说明条目指工业产品或纯度高于工业产品的化学品）；应急管理部答复（S03）。 | G6: S02,S03 | H6: ①含量 > 8%（本单 30% 满足）；②为过氧化氢水溶液；③除稳定剂、惰性化学品外不得含其他功能性添加剂。 | I6: 决定是否触发海关检验（129号公告）、中文SDS与标签、危化品登记、境内储存与经营许可等一整条链路。 | J6: 进口商 / 报关代理 | K6: medium
A7: R02 | B7: 危险化学品管理 | C7: 进口企业危险化学品登记 | D7: 适用 | E7: 适用。进口企业须向应急管理部门危化品登记机构办理登记（同一品种不重复登记，信息变更须及时变更）。 | F7: 《危险化学品安全法》第85–86条（S01）；原《危险化学品安全管理条例》第67条（S16）。 | G7: S01,S16 | H7: 企业实际进口该危化品即触发；登记内容包括分类标签、理化性质、用途、危险特性、储运安全要求与应急处置。 | I7: 首次进口前完成登记；后续信息变更（如换供、改标）须变更登记。 | J7: 进口商 | K7: high
A8: R03 | B8: 危险化学品管理 | C8: 中文化学品安全技术说明书（SDS） | D8: 适用 | E8: 适用。生产企业、进口企业应提供与其进口危险化学品相符的中文化学品安全技术说明书。 | F8: 《危险化学品安全法》第31条（S01）；海关总署2020年第129号公告第二条第（三）项（S05）；GB/T 16483（S10）。 | G8: S01,S05,S10 | H8: 进口危险化学品必须随附中文SDS；内容须符合国家标准要求；与货物不符或不符合国标属违法行为（第31条、法律责任章）。 | I8: 上传件 U01 为韩文/英文 SDS，需整册翻译并核对第14节运输信息与 UN2014 一致。 | J8: 进口商（可委托翻译/合规机构） | K8: high
A9: R04 | B9: 危险化学品管理 | C9: 中文危险公示标签 | D9: 适用 | E9: 适用。进口化学品包装上须粘贴、印刷或拴挂与包装内化学品相符的中文化学品安全标签。 | F9: 《危险化学品安全法》第31条（S01）；海关129号公告第二条第（三）项、第五条（S05）；GB 15258（S12）。 | G9: S01,S05,S12 | H9: 散装产品除外；本单为桶装，不免除。标签须含中文品名、成分及含量、象形图、信号词、危险性说明、防范说明、供应商与应急电话。 | I9: 上传件 U04 标签仅为英文（且缺少中文应急电话），不能直接使用。 | J9: 进口商 / 海外供应商 | K9: high
A10: R05 | B10: 危险化学品管理 | C10: 危险化学品经营许可 | D10: 不适用 | E10: 本单不适用：进口企业为自用（自有工厂 PCB 工序使用），非对外销售危化品。 | F10: 《危险化学品安全法》第53条：国家对危险化学品经营实行许可制度；未取得许可任何单位和个人不得经营（S01）。 | G10: S01 | H10: 以转售为目的的进口（贸易商进口后销售）必须持危化品经营许可证；生产企业厂区内销售自产产品、港口经营人在港区内仓储经营属例外。 | I10: 如本批货物最终转售给第三方，进口主体必须先取得经营许可，否则属无证经营。 | J10: 进口商 | K10: high
A11: R06 | B11: 易制爆管理 | C11: 是否列入《易制爆危险化学品名录》 | D11: 适用 | E11: 适用。第6.1项『过氧化氢溶液（含量＞8%）』；30% 对应『20%≤含量＜60%：氧化性液体，类别2』。 | F11: 《易制爆危险化学品名录（2017年版）》第6.1项（S04）；《危险化学品安全法》第58条、第60–62条（S01）。 | G11: S04,S01 | H11: 门槛同样是含量 > 8%。注意名录对含量的三档划分与运输 UN 编号的分档并不完全一致（见危险属性对照）。 | I11: 购买、销售、储存须纳入治安管理：销售方须查验购买方凭证、如实记录、三日内报送流向信息。 | J11: 进口商 / 境内销售方 | K11: high
A12: R07 | B12: 易制爆管理 | C12: 易制爆购买凭证与流向报备 | D12: 视条件适用 | E12: 进口环节本身不直接对应『购买』行为；但货物入境后若由境内单位购入并转储/使用，则按境内规则办理。 | F12: 《危险化学品安全法》第58条（凭危化品安全生产/使用/经营许可证购买易制爆；其他单位购买须持单位出具的合法用途说明）、第60–62条（查验、记录、3日内报公安机关）。 | G12: S01 | H12: 取决于进口后的处置路径：直接投料生产（自有危化品使用/生产许可）、还是进入仓储再销售。 | I12: 实务中多数属地要求进口易制爆品在入境后 3 个工作日内完成流向报备，须在首批到港前落实属地口径。 | J12: 进口商 / 属地公安机关 | K12: medium
A13: R08 | B13: 运输 | C13: 是否属危险货物（运输分类） | D13: 适用 | E13: 适用。UN 2014，第 5.1 类（氧化性物质），次要危险 8（腐蚀性），包装类别 II。 | F13: UN Model Regulations / IMDG Code（S14）；GB 6944-2025（S08）；GB 12268-2025（S09）；GB 6944/12268 自 2025-10-01 起为现行版本。 | G13: S08,S09,S14 | H13: 按 H₂O₂ 含量分档：8%–<20% → UN2984/PG III；20%–60% → UN2014/PG II；>60% → UN2015/PG I；<8% 通常不作为危险货物。 | I13: 决定包装规格、标志、申报、积载隔离与运费附加。 | J13: 承运人 / 报关代理 / 进口商 | K13: high
A14: R09 | B14: 检验检疫 | C14: 海关进出口危险化学品检验 | D14: 适用 | E14: 适用。海关对列入《危险化学品目录》的进出口危险化学品及其包装实施检验；报关须填报危险类别、包装类别、UN编号、包装UN标记。 | F14: 《危险化学品安全法》第7条(九)（S01）；海关总署公告2020年第129号第一条、第二条、第六条（S05）。 | G14: S01,S05 | H14: 以『是否列入目录』为门槛；本单因属目录第903项而纳入检验范围。不属于危险化学品的危险货物不在此公告检验范围内（但仍受运输规则约束）。 | I14: 报关时须提交《进口危险化学品企业符合性声明》、稳定剂说明、中文危险公示标签与中文SDS样本；包装须检验型式、标记、类别、规格、单件重量与使用状况。 | J14: 进口商 / 报关代理 | K14: high
A15: R10 | B15: 检验检疫 | C15: 海关监管条件代码适用 | D15: 适用 | E15: 2847000000 监管条件为 A（入境货物通关单）、B（出境货物通关单）、G（两用物项和技术出口许可证·定向）。进口环节相关的是 A 与 G 的判定。 | F15: 中国国际贸易单一窗口 2026 申报参数（S07）；365外贸网整理（S18）。 | G15: S07,S18 | H15: A：进口属法检商品，须取得入境货物通关单；B：出口方向；G：出口管制许可（定向），不针对进口。 | I15: 报关代理须按参数填选；若产品同时被列入当年《两用物项和技术进出口许可证管理目录》，则按目录要求另行办证（见 R11）。 | J15: 报关代理 | K15: medium
A16: R11 | B16: 两用物项 | C16: 是否需两用物项和技术进口许可证 | D16: 待核验 | E16: 未见进口方向办证证据；但必须以 2026 年度目录逐条核对，不能仅凭监管条件 G（定向出口许可）推断。 | F16: 《两用物项出口管制条例》（S20）；商务部、海关总署 2026 年度《两用物项和技术进出口许可证管理目录》（S21）。 | G16: S20,S21 | H16: 需核对：产品浓度/形态是否落入目录中『过氧化氢』条目的限定条件（例如浓度区间）；目录条目可能对进口方向另有要求。 | I16: 如落入目录，未办证将导致无法通关；此项须由报关代理书面查询结论或合规顾问出具意见。 | J16: 报关代理 / 合规顾问 | K16: low
... A20: R15 | B20: 储存安全 | C20: 重大危险源辨识（GB 18218） | D20: 视条件适用 | E20: 视进口后的储存方式：20 吨单批次通常未达过氧化氢临界量，但须与现有库存合并计算单元总量。 | F20: 《危险化学品安全法》第13条（重大危险源登记建档、备案）（S01）；GB 18218-2018。 | G20: S01 | H20: 按『单元』合并计算，不能只看单批次。 | I20: 若构成重大危险源，须登记建档、定期检测评估、制定应急预案并报县级应急管理部门备案。 | J20: 进口商 EHS | K20: medium
C22: 判定分布（公式统计）
C23: 适用 | D23: =COUNTIF($D$6:$D$20,"适用")
C24: 视条件适用 | D24: =COUNTIF($D$6:$D$20,"视条件适用")
C25: 待核验 | D25: =COUNTIF($D$6:$D$20,"待核验")
C26: 不适用 | D26: =COUNTIF($D$6:$D$20,"不适用")

Sheet 04 单证要求
A1: 04 · 单证要求
A2: 共 26 项，加权完备度 18.8%（必须=3 / 视情形=1 / 建议=0.5）。『状态』列可下拉修改，进度看板自动汇总。
A5: 编号 | B5: 分组 | C5: 文件名称（中） | D5: 文件名称（英） | E5: 要求 | F5: 状态 | G5: 依据 | H5: 必备关键字段 | I5: 当前问题 | J5: 责任主体 | K5: 关联上传件
A6: D01 | B6: 海外供应商资料 | C6: 英文安全技术说明书（SDS） | D6: Safety Data Sheet (English, 16 sections per GHS) | E6: 必须 | F6: 有但不完整 | G6: GB/T 16483（S10）；海关129号公告（S05） | H6: 16 节齐全；第14节载 UN编号/类项/包装类别/海洋污染物 | I6: 已提供但无版本号与修订日期，第3节稳定剂未给 CAS 与精确百分比，第14节信息需与 UN2014 复核 | J6: 海外供应商 | K6: U01
A7: D02 | B7: 中文合规文件 | C7: 中文化学品安全技术说明书（中文SDS） | D7: Safety Data Sheet (Chinese) | E7: 必须 | F7: 缺失 | G7: 《危险化学品安全法》第31条（S01）；129号公告第二条（S05） | H7: 整册中文；与英文 SDS 逐节对应；符合 GB/T 16483 | I7: 尚未制作。进口危化品未随附中文 SDS 属违法，且无法通过海关检验 | J7: 进口商（可委托翻译）
A8: D03 | B8: 中文合规文件 | C8: 稳定剂/抑制剂添加情况说明 | D8: Statement of stabilisers/inhibitors added (name, quantity) | E8: 必须 | F8: 有但不完整 | G8: 129号公告第二条第（二）项（S05） | H8: 稳定剂名称、CAS、精确添加量；声明仅为稳定剂/惰性化学品 | I8: SDS 仅写『磷酸盐类稳定剂』；PI 与 COA 无稳定剂明细 | J8: 海外供应商 | K8: U01
A9: D04 | B9: 中文合规文件 | C9: 进口危险化学品企业符合性声明 | D9: Importer's Declaration of Conformity (Attachment 1 of GACC Announcement 129) | E9: 必须 | F9: 缺失 | G9: 129号公告第二条第（一）项及附件1（S05） | H9: 按附件1格式；企业盖章；声明符合我国强制性技术规范 | I9: 进口商尚未签署 | J9: 进口商
A10: D05 | B10: 中文合规文件 | C10: 中文危险公示标签（样张） | D10: Chinese GHS Hazard Label (artwork) | E10: 必须 | F10: 有但不完整 | G10: 《危险化学品安全法》第31条（S01）；GB 15258（S12）；129号公告第五条（S05） | H10: 品名、成分含量、象形图、信号词、H/P 说明、供应商信息、24h 中文应急电话 | I10: 上传件为英文标签，缺中文要素与应急电话；须重制 | J10: 进口商 / 海外供应商 | K10: U04
A11: D06 | B11: 海外供应商资料 | C11: 质量分析证书（COA） | D11: Certificate of Analysis (COA) | E11: 必须 | F11: 齐备 | G11: 合同约定 + 报关查验；GB/T 1616 对标 | H11: 批号、检测项目（浓度、稳定剂、色度、铁等）、方法、结论、签发人、日期 | I11: 已提供，实测 30.4%；建议补充铁/TOC 等下游关键项 | J11: 海外供应商 | K11: U02
A12: D07 | B12: 海外供应商资料 | C12: 产品技术数据表（TDS/规格书） | D12: Technical Data Sheet (TDS/Specification) | E12: 建议 | F12: 缺失 | G12: 采购合同约定 | H12: 规格指标表、储存建议、安全操作、包装说明 | I12: 未提供；下游需据此确认工业级指标是否满足 PCB 微蚀要求 | J12: 海外供应商
A13: D08 | B13: 海外供应商资料 | C13: 形式发票（PI） | D13: Proforma Invoice (PI) | E13: 必须 | F13: 有但不完整 | G13: 贸易与结算 | H13: 品名、规格、数量、单价、总价、贸易术语、装运港、付款方式、HS 编码 | I13: 已提供；未列 HS 编码与目的地；FOB 条件需明确装运港附加费承担 | J13: 海外供应商 | K13: U03
A14: D09 | B14: 海外供应商资料 | C14: 原产地证书（中韩FTA CO / RCEP CO） | D14: Certificate of Origin (China-Korea FTA / RCEP) | E14: 视情形 | F14: 缺失 | G14: 中韩 FTA 原产地规则；海关总署公告（S19） | H14: 与发票一致；HS 6 位一致；直接运输证明 | I14: 若要享受协定税率必须取得；且须与报关时的 HS、发票一致 | J14: 海外供应商 / 出口商
A15: D10 | B15: 海外供应商资料 | C15: 非危声明/包装声明（如适用） | D15: Non-regulated / packaging statement (if applicable) | E15: 建议 | F15: 不适用 | G15: 运输规则 | H15: 若可适用限量豁免，需载明豁免依据与单件限量 | I15: 本单 30 kg 桶装，按 IMDG 常规申报，不依赖豁免声明 | J15: 海外供应商
A16: D11 | B16: 海外供应商资料 | C16: UN 包装性能检验证书与包装标记照片 | D16: UN packaging performance certificate & UN mark photo | E16: 必须 | F16: 缺失 | G16: 《危险化学品安全法》第32–33条；129号公告第六条（S05） | H16: 包装代号、包装类别、生产年份、制造厂、性能试验报告 | I16: 报关需填报包装UN标记；无证书无法核实包装是否经认证 | J16: 海外供应商
A17: D12 | B17: 海外供应商资料 | C17: 生产商声明（制造商与供货主体关系） | D17: Manufacturer's letter / producer attestation | E17: 视情形 | F17: 缺失 | G17: 主体一致性核验 | H17: 声明确认生产厂名称地址与 PI 抬头关系 | I17: PI 抬头为贸易公司，需确认生产厂与批次来源 | J17: 海外供应商
A18: D13 | B18: 海外供应商资料 | C18: 危险货物运输申报单（DGD 或海运申报资料） | D18: Dangerous Goods Declaration (IMDG) / shipping documents | E18: 必须 | F18: 缺失 | G18: IMDG Code（S14）；《危险化学品安全法》第82条（S01） | H18: UN、类项、包装组、件数、毛净重、应急联系 | I18: 订舱时提交；须与 SDS 第14节一致 | J18: 承运人 / 海外供应商
A19: D14 | B19: 进口报关资料 | C19: 商业发票（Commercial Invoice） | D19: Commercial Invoice | E19: 必须 | F19: 缺失 | G19: 海关申报基本单证 | H19: 品名、规格、数量、单价、总价、贸易术语、收发货人、原产国 | I19: 需与 PI 一致并补充 HS 编码、原产国、用途 | J19: 海外供应商
A20: D15 | B20: 进口报关资料 | C20: 装箱单（Packing List） | D20: Packing List | E20: 必须 | F20: 缺失 | G20: 海关申报基本单证 | H20: 件数、毛净重、体积、包装规格、唛头 | I20: 需与 600 桶 / 20 吨口径一致 | J20: 海外供应商
A21: D16 | B21: 进口报关资料 | C21: 采购合同（Sales Contract） | D21: Sales Contract | E21: 必须 | F21: 缺失 | G21: 贸易与合规 | H21: 品名规格、浓度公差（不得跨阈值）、包装、SDS 版本、标签责任、检验条款、责任划分 | I21: 建议把『浓度不得跨 20%/60% 阈值』『中文标签与SDS由供应商配合』写入合同 | J21: 进口商
A22: D17 | B22: 进口报关资料 | C22: 提单/海运单（B/L） | D22: Bill of Lading (B/L) | E22: 必须 | F22: 缺失 | G22: 海关申报基本单证 | H22: 发货人、收货人、通知方、品名（须含危险货物信息）、唛头、件数、毛重 | I22: 危险货物提单须载明 UN 编号与正确运输名称 | J22: 承运人
A23: D18 | B23: 进口报关资料 | C23: 报关委托书与报关单 | D23: Customs Declaration & Power of Attorney | E23: 必须 | F23: 缺失 | G23: 海关申报 | H23: 委托关系、申报要素（品牌类型|出口享惠情况|成分含量|包装规格|GTIN|CAS）、危险类别/包装类别/UN编号/包装标记 | I23: 由报关代理制作；要素须按 S07 顺序填报 | J23: 报关代理
A24: D19 | B24: 进口报关资料 | C24: 入境货物通关单（监管条件 A） | D24: Inspection Certificate for Import Goods | E24: 必须 | F24: 缺失 | G24: 监管条件 A（S07,S18） | H24: 由海关出具；对应法检商品 | I24: 进口法检商品须先报检，与报关联动 | J24: 报关代理 / 进口商
A25: D20 | B25: 进口报关资料 | C25: 危险特性分类鉴别报告（如需） | D25: Hazard classification report (if required) | E25: 视情形 | F25: 有但不完整 | G25: 海关检验要求；进口通常以 SDS 分类为准 | H25: CNAS 资质机构出具；用于混合物或分类存疑时 | I25: 本单为单一水溶液，通常可依据 SDS；若稳定剂含功能性添加剂则可能需要 | J25: 第三方检测机构
... A28: D23 | B28: 海关/税费 | C28: 税则归类意见（可选） | D28: Tariff classification opinion (optional) | E28: 建议 | F28: 不适用 | G28: 海关预裁定（海关总署令第236号） | H28: 如归类存疑可申请预裁定 | I28: 本单置信度高，可不申请；如报关行提出不同意见则建议申请 | J28: 进口商 / 报关代理
A29: D24 | B29: 运输资料 | C29: 订舱单与危险货物订舱确认 | D29: Booking & DG booking confirmation | E29: 必须 | F29: 缺失 | G29: IMDG Code | H29: 船公司 DG 订舱；注明 UN/类项/PG/包装 | J29: 承运人 / 进口商
A30: D25 | B30: 运输资料 | C30: 危险货物申报（船代/海事） | D30: DG manifest / to carrier declaration | E30: 必须 | F30: 缺失 | G30: IMDG Code；海事管理机构要求 | H30: 装船前申报；危险货物舱单 | J30: 海外供应商 / 承运人
A31: D26 | B31: 运输资料 | C31: 国内段危货运输资质与运输单据 | D31: Domestic DG road transport permits & documents | E31: 必须 | F31: 缺失 | G31: 《危险化学品安全法》第65–66条；道路危货运输规则 | H31: 承运企业许可、车辆营运证、驾驶员/押运员资格 | I31: 到港后由仓库/工厂联系有资质危货车队 | J31: 进口商 / 承运人
B33: 状态汇总
B34: 齐备 | C34: =COUNTIF($F$6:$F$31,"齐备")
B35: 有但不完整 | C35: =COUNTIF($F$6:$F$31,"有但不完整")
B36: 缺失 | C36: =COUNTIF($F$6:$F$31,"缺失")
B37: 待定（需外部确认） | C37: =COUNTIF($F$6:$F$31,"待定（需外部确认）")
B38: 过期/版本失效 | C38: =COUNTIF($F$6:$F$31,"过期/版本失效")
B39: 不适用 | C39: =COUNTIF($F$6:$F$31,"不适用")
B40: 合计 | C40: =SUM(C34:C39)

Sheet 05 已上传文件
A1: 05 · 已上传文件检查
A2: 每份上传件做三件事：字段提取 → 要件核对 → 交叉一致性。标『模拟』的文件仅用于演示，供应商名称/批号/金额均为虚构。
A5: 一、文件清单与结论
A6: 编号 | B6: 文件名 | C6: 类型 | D6: 语言 | E6: 是否模拟 | F6: 接收日期 | G6: 结论 | H6: 结论说明 | I6: 模拟声明
A7: U01 | B7: SDS_HANWOO_H2O2_30_EN.pdf（模拟） | C7: SDS | D7: en | E7: 是 | F7: 2026-10-12 | G7: 需修订后使用 | H7: 作为技术底稿可用，但必须补齐版本号、稳定剂明细，并制作中文版后方可随货使用。 | I7: 本文件为演示用模拟件，供应商名称、电话、批号均为虚构，不构成任何真实供应商的资料。
A8: U02 | B8: COA_HANWOO_H2O2_30_L2609A.pdf（模拟） | C8: COA | D8: en | E8: 是 | F8: 2026-10-12 | G8: 可直接使用 | H8: 可作为批次质量证明使用；建议补充铁与 TOC 检测项以匹配下游要求。 | I8: 演示用模拟件：批号 L2609A 与检测数据为虚构。
A9: U03 | B9: PI_HANWOO_2026-0918.pdf（模拟） | C9: PI | D9: en | E9: 是 | F9: 2026-10-12 | G9: 需修订后使用 | H9: 金额与规格可用；贸易术语冲突必须更正后重出 PI。 | I9: 演示用模拟件：发票号、金额为虚构。
A10: U04 | B10: Label_HANWOO_H2O2_30_EN.jpg（模拟） | C10: 标签 | D10: en | E10: 是 | F10: 2026-10-12 | G10: 不可用 | H10: 不可直接用于中国进口；须按 GB 15258 重制中文标签。 | I10: 演示用模拟标签：按常见英文出口标签样式构造，非任何真实供应商标签。
A12: 二、字段提取
A13: 文件编号 | B13: 字段 | C13: 提取值 | D13: 位置
A14: U01 | B14: 产品名称（英） | C14: HYDROGEN PEROXIDE AQUEOUS SOLUTION 30% | D14: 第1节
A15: U01 | B15: CAS | C15: 7722-84-1 | D15: 第1、3节
A16: U01 | B16: 浓度/含量 | C16: 30.0 % (w/w) | D16: 第3节
A17: U01 | B17: 稳定剂 | C17: phosphate based stabiliser（未给 CAS 与精确%） | D17: 第3节
A18: U01 | B18: 物理形态 | C18: Liquid, colourless, clear | D18: 第9节
A19: U01 | B19: GHS 分类 | C19: Oxid. Liq. 2; Acute Tox. 4; Skin Irrit. 2; Eye Dam. 1; STOT SE 3 | D19: 第2节
A20: U01 | B20: UN 编号 | C20: UN 2014 | D20: 第14节
A21: U01 | B21: 运输类别/包装组 | C21: Class 5.1 (subsidiary 8), PG II | D21: 第14节
A22: U01 | B22: 海洋污染物 | C22: No | D22: 第14节
A23: U01 | B23: 版本号/修订日期 | C23: （未标注） | D23: 全册
A24: U01 | B24: 语言 | C24: English only | D24: 全册
... A48: U04 | B48: 语言 | C48: English only | D48: 全册
A50: 三、检查项
A51: 检查项编号 | B51: 文件编号 | C51: 检查内容 | D51: 结果 | E51: 说明
A52: C-U01-1 | B52: U01 | C52: 是否 16 节齐全 | D52: 通过 | E52: 第1–16节齐全
A53: C-U01-2 | B53: U01 | C53: 是否载有版本号与修订日期 | D53: 不通过 | E53: 全册未见版本号/修订日期，无法证明为现行版本（GB/T 16483 要求）
A54: C-U01-3 | B54: U01 | C54: 第3节是否给出各组分 CAS 与精确浓度 | D54: 存疑 | E54: 主成分完整；稳定剂仅有类别表述，未给 CAS 与精确%
A55: C-U01-4 | B55: U01 | C55: 第14节是否载 UN 编号、类项、包装类别、海洋污染物 | D55: 通过 | E55: UN2014 / 5.1(8) / PG II / 海洋污染物 No，齐全
A56: C-U01-5 | B56: U01 | C56: 第14节与产品浓度是否匹配 | D56: 通过 | E56: 30% 落在 20%–60% 区间，对应 UN2014，逻辑一致
A57: C-U01-6 | B57: U01 | C57: 是否为中文版本 | D57: 不通过 | E57: 仅英文，不满足中文SDS要求
A58: C-U01-7 | B58: U01 | C58: 是否与上传标签、COA 一致 | D58: 存疑 | E58: 与 COA 浓度一致；与标签（英文、无含量）不一致
A59: C-U01-8 | B59: U01 | C59: 是否声明仅为稳定剂（无功能性添加剂） | D59: 不通过 | E59: 未见声明，无法据此锁定危化品目录第903项适用性
A60: C-U02-1 | B60: U02 | C60: 批号可追溯 | D60: 通过 | E60: 批号 L2609A，可与装箱单核对
A61: C-U02-2 | B61: U02 | C61: 浓度是否在规格范围内 | D61: 通过 | E61: 30.4% 在 30.0–31.0 内，且不跨阈值
A62: C-U02-3 | B62: U02 | C62: 是否载明检测方法与依据标准 | D62: 存疑 | E62: 未列检测方法编号；企标对国内下游参考价值有限
... A77: C-U04-6 | B77: U04 | C77: 是否含进口商/境内联系人 | D77: 不通过 | E77: 进口产品标签通常需可追溯的境内联系人
A79: 四、交叉一致性冲突
A80: 等级 | B80: 问题 | C80: 明细 | D80: 处置
A81: 中 | B81: SDS 无中文版本 | C81: SDS_HANWOO_H2O2_30_EN.pdf（模拟） 为 en 版本 | D81: 进口危化品须随货提供中文化学品安全技术说明书与中文危险公示标签
A82: 中 | B82: 标签 无中文版本 | C82: Label_HANWOO_H2O2_30_EN.jpg（模拟） 为 en 版本 | D82: 进口危化品须随货提供中文化学品安全技术说明书与中文危险公示标签

Sheet 06 缺失资料
A1: 06 · 缺失资料清单
A2: P0 = 不取得不得报关/不得使用；P1 = 影响税费、时效或质量；P2 = 档案完善。『已完成』列可勾选，进度看板实时汇总。
A5: 编号 | B5: 优先级 | C5: 缺失资料 | D5: 为什么必须 | E5: 怎么要（动作） | F5: 关联单证 | G5: 责任主体 | H5: 是否阻断 | I5: 已完成
A6: G01 | B6: P0 | C6: 中文化学品安全技术说明书（中文SDS） | D6: 《危险化学品安全法》第31条与海关129号公告第二条要求进口危化品随附中文SDS；无中文版无法通过海关检验，且不能合法交付使用。 | E6: 进口商按英文SDS整册翻译，逐节与GB/T 16483对照；第14节须与UN2014一致；完成后请报关行预审。 | F6: D02 | G6: 进口商 | H6: 是 | I6: ☐
A7: G02 | B7: P0 | C7: 中文危险公示标签（含24小时中文应急电话） | D7: 现行标签仅英文，缺中文品名、成分含量、中文H/P说明与中文应急电话，不符合GB 15258。 | E7: 按GB 15258重制样张；确认应急电话为国内可接通号码；标签稿经供应商与进口商双签确认后印刷。 | F7: D05 | G7: 进口商/海外供应商 | H7: 是 | I7: ☐
A8: G03 | B8: P0 | C8: 稳定剂的名称、CAS 与精确添加量，及『无其他功能性添加剂』声明 | D8: 这是判定是否落入《危险化学品目录》第903项『过氧化氢的水溶液』的关键前提；缺此声明只能给出『视条件适用』。 | E8: 要求供应商出具组分清单与书面声明；如含功能性添加剂，需委托第三方做危险特性鉴定后再申报。 | F8: D03 | G8: 海外供应商 | H8: 是 | I8: ☐
A9: G04 | B9: P0 | C9: 《进口危险化学品企业符合性声明》 | D9: 129号公告第二条第（一）项的强制材料，缺失无法报关。 | E9: 进口商用海关附件1格式签署盖章。 | F9: D04 | G9: 进口商 | H9: 是 | I9: ☐
A10: G05 | B10: P0 | C10: UN 包装性能检验证书与包装标记照片 | D10: 报关需填报包装UN标记；且须核实包装是否经认证并适配PG II。 | E10: 索取桶体UN标记清晰照片（含包装代码、类别字母、生产年份）与性能检验证书。 | F10: D11 | G10: 海外供应商 | H10: 是 | I10: ☐
A11: G06 | B11: P0 | C11: PI 贸易术语更正（CIF/FOB 冲突） | D11: 同一份PI出现三种术语表述，将直接影响完税价格、运费承担与保险责任。 | E11: 要求重出PI，统一为 FOB Busan（或改为 CIF Shanghai 并给出运保费拆分）。 | F11: D08 | G11: 海外供应商 | H11: 是 | I11: ☐
A12: G07 | B12: P1 | C12: SDS 版本号与修订日期 | D12: 无版本号无法证明为现行版本，海关审核中文SDS时可能要求补正。 | E12: 要求供应商补印版本号/修订日期并签字确认，承诺变更时主动更新。 | F12: D01 | G12: 海外供应商 | H12: 否 | I12: ☐
A13: G08 | B13: P1 | C13: TDS / 产品规格书 | D13: 下游PCB工序需确认工业级的铁、氯化物、TOC 限值是否满足微蚀工艺。 | E13: 索取TDS；若供方无TDS，要求提供关键指标清单并写入合同附件。 | F13: D07 | G13: 海外供应商 | H13: 否 | I13: ☐
A14: G09 | B14: P1 | C14: 商业发票、装箱单、采购合同 | D14: 尚无发票与装箱单，报关单证链未闭环；合同尚未签订，责任划分未落纸。 | E14: 签约时同步确认浓度公差（不得跨阈值）、SDS版本、中文标签责任、检验与索赔条款。 | F14: D14,D15,D16 | G14: 进口商/海外供应商 | H14: 否 | I14: ☐
A15: G10 | B15: P1 | C15: 原产地证书（中韩FTA / RCEP）与直接运输证明 | D15: 若不能用协定税率，税负相差数个百分点；若无法出证则只能按最惠国税率。 | E15: 确认供应商能否出中韩FTA原产地证书（或RCEP），并核对是否直航/满足转运规则。 | F15: D09 | G15: 海外供应商 | H15: 否 | I15: ☐
A16: G11 | B16: P1 | C16: 危险货物订舱确认与海运申报 | D16: 危险货物须提前向船公司申请DG舱位，时限通常早于普通货物；未申报将导致拒载。 | E16: 由货代/供应商提交DGD并取得DG booking confirmation；核对UN2014与积载要求。 | F16: D24,D25 | G16: 承运人 | H16: 否 | I16: ☐
... A20: G15 | B20: P2 | C20: 国内段危货运输资质与车辆 | D20: 到港后须使用有资质的危货车辆与押运人员。 | E20: 与危货运输公司签约，留存许可与人员资格复印件。 | F20: D26 | G20: 进口商 | H20: 否 | I20: ☐
C22: 进度统计（公式）
C23: P0 总数 | D23: =COUNTIF($B$6:$B$20,"P0")
C24: P0 已完成 | D24: =COUNTIFS($B$6:$B$20,"P0",$I$6:$I$20,"☑")
C25: 全部总数 | D25: =COUNTA($A$6:$A$20)
C26: 全部已完成 | D26: =COUNTIF($I$6:$I$20,"☑")
C27: 完成率 | D27: =TEXT(IFERROR(COUNTIF($I$6:$I$20,"☑")/COUNTA($A$6:$A$20),0),"0.0%")

Sheet 07 责任主体
A1: 07 · 责任主体与资料义务
A2: 同一份资料由谁出、谁核对、谁留存，必须在签约前落纸，否则查验时互相推诿。
A5: 责任主体 | B5: 序号 | C5: 资料/动作义务 | D5: 说明 | E5: 关联单证
A6: 海外供应商 | B6: 1 | C6: 提供现行版英文 SDS（含版本号、稳定剂明细）与 TDS | D6: 供应商的核心义务是『把危险货物的技术事实说清楚』；中文合规文件的翻译与制作可由进口商完成，但技术信息必须由供应商确认。 | E6: D01, D03, D05, D06, D07, D08, D09, D10, D11, D12, D13, D14, D15, D22, D25
B7: 2 | C7: 提供 COA（按批）、PI、商业发票、装箱单
B8: 3 | C8: 出具稳定剂/抑制剂添加情况说明与『无功能性添加剂』声明
B9: 4 | C9: 提供 UN 包装性能检验证书与包装标记照片
B10: 5 | C10: 按 GB 15258 配合提供中文标签所需信息（成分含量、H/P 码、应急电话）
B11: 6 | C11: 办理危险货物订舱与海运申报，提供 DGD
B12: 7 | C12: 如可出证，办理中韩FTA / RCEP 原产地证书并保证直接运输
A13: 进口商（收货人） | B13: 1 | C13: 审核并采用中文 SDS，确保与货物一致（法律第31条） | D13: 进口企业是危险化学品合规的第一责任人；海关检验的对象是『货物 + 包装 + 中文SDS + 中文标签』。 | E13: D02, D04, D16, D19, D23, D24, D26
B14: 2 | C14: 在包装上粘贴/印刷中文危险公示标签（法律第31条）
B15: 3 | C15: 签署《进口危险化学品企业符合性声明》
B16: 4 | C16: 办理危险化学品登记（法律第86条）
B17: 5 | C17: 确认是否有权储存/使用该危化品（储存条件、安全使用许可适用性）
B18: 6 | C18: 如转售，须持危险化学品经营许可证（法律第53条）
B19: 7 | C19: 落实易制爆流入后的流向报备与购买凭证管理
B20: 8 | C20: 核算重大危险源单元总量（GB 18218）
B21: 9 | C21: 支付进口关税与进口环节增值税，申报时选择享惠并保存原产地证书
A22: 承运人 / 船公司 | B22: 1 | C22: 审核 DG 订舱与危险货物申报单（UN2014 / 5.1 / PG II） | D22: 海运与陆运均属危险货物运输，承运人负有审核与拒载权。 | E22: D17
B23: 2 | C23: 按 IMDG 积载与隔离要求安排舱位
B24: 3 | C24: 出具危险货物提单（载明UN编号与正确运输名称）
B25: 4 | C25: 国内段安排有资质的危货道路运输企业与车辆
A26: 报关代理 | B26: 1 | C26: 按 2847000000 规范申报要素填报（品牌类型|出口享惠情况|成分含量|包装规格|GTIN|CAS） | D26: 报关代理不替代进口商的实体责任；建议以书面形式确认关键口径（归类、监管、税率）并留档。 | E26: D18, D21
B27: 2 | C27: 填报危险类别、包装类别、UN编号、包装UN标记
B28: 3 | C28: 校核监管条件 A（法检）与 G（定向出口）适用性
B29: 4 | C29: 书面确认 2026 年度两用物项目录比对结论
B30: 5 | C30: 核查原产地证书与享惠资格，选用正确税率
B31: 6 | C31: 如归类存在分歧，建议申请预裁定
A32: 第三方检测机构 / 合规顾问 | B32: 1 | C32: 如需，开展危险特性分类鉴别（混合物或添加剂存疑时） | D32: 仅在前述场景触发；本单在稳定剂声明闭环前不必然需要。 | E32: D20
B33: 2 | C33: 如海关对 SDS 分类提出异议，出具鉴定报告
B34: 3 | C34: 协助核对两用物项目录与用途管控
A35: 监管机构 | B35: 1 | C35: 海关：对进出口危险化学品及包装实施检验；出具入境货物通关单；征收关税与增值税 | D35: 各部门职责见《危险化学品安全法》第7条。
B36: 2 | C36: 应急管理部门：危化品登记、经营许可、使用许可、重大危险源备案
B37: 3 | C37: 公安机关：易制爆流向报备
B38: 4 | C38: 海事管理机构：危险货物船舶运输安全条件

Sheet 08 待确认事项
A1: 08 · 待确认事项
A2: 这些问题不能由公开资料可靠回答。必须取得书面答复并归档；口头沟通不构成依据。
A5: 编号 | B5: 优先级 | C5: 事项 | D5: 为什么不能自判 | E5: 谁确认 | F5: 怎么核实 | G5: 判断错的代价 | H5: 已确认 | I5: 答复要点
A6: Q01 | B6: 高 | C6: 第903项『过氧化氢的水溶液』是否成立（稳定剂是否仅为稳定剂） | D6: 应急管理部答复（S03）明确：添加稳定剂/惰性化学品之外的其他化学品即不属该水溶液。供应商未披露稳定剂明细。 | E6: 合规顾问 / 第三方检测机构 | F6: 取得稳定剂清单与声明；如含功能性添加剂，委托做危险特性鉴定并出具结论。 | G6: 若最终不落入第903项，则海关129号公告检验、中文SDS/标签、危化品登记等义务的判定基础会改变，需重新评估。 | H6: ☐
A7: Q02 | B7: 高 | C7: 2026 年度《两用物项和技术进出口许可证管理目录》中是否含本产品（进口方向） | D7: 监管条件含 G（两用物项和技术出口许可证·定向），但该代码为出口管制；进口方向是否需证必须查当年目录。 | E7: 报关行 / 合规顾问 | F7: 请报关行以单一窗口或商务部公告原文核对并书面答复；必要时请省商务厅确认。 | G7: 如应办证未办，货物无法清关，可能被退运并处罚。 | H7: ☐
A8: Q03 | B8: 高 | C8: 中韩 FTA 与 RCEP 项下 2847000000 的 2026 年度协定税率 | D8: 两处第三方数据分别给出 1.1% 与 2.8%，且另一处称该类产品已零关税，口径冲突且缺年度。 | E8: 报关行 | F8: 在单一窗口『关税优惠税率查询』按 2847000000 + 韩国 + 2026 年度实查；或请货代出具书面截图。 | G8: 税率用错会导致少缴/多缴税款，少缴将被追征并加收滞纳金。 | H8: ☐
A9: Q04 | B9: 中 | C9: 能否取得原产地证书及是否满足直接运输 | D9: 协定税率以原产地证书 + 原产地规则 + 直接运输为条件。Busan→Shanghai 通常直航，但需确认。 | E9: 海外供应商 / 货代 | F9: 要求供应商确认出证能力；核对提单是否直航。 | G9: 无法享惠则按 5.5% 最惠国税率计税，到厂成本上升。 | H9: ☐
A10: Q05 | B10: 中 | C10: 易制爆流入后的属地报备口径（时限、系统、购买凭证） | D10: 法律第58–62条规定查验与三日内报备，但地方执行口径与系统（如易制爆流向管理系统）不同。 | E10: 进口商 EHS + 属地公安机关 | F10: 首批到港前与属地派出所/县级公安机关书面确认报送方式与时限。 | G10: 逾期未报可能被处罚，并影响后续购买。 | H10: ☐
A11: Q06 | B11: 中 | C11: 进口企业是否已有该品种危险化学品登记 | D11: 法律第86条要求进口企业办理登记，同一品种不重复登记；企业实际登记状态只有企业自己掌握。 | E11: 进口商 EHS | F11: 查企业危化品登记证书/系统记录；无则办理新增登记。 | G11: 未登记属合规缺口，检查中会被要求整改。 | H11: ☐
A12: Q07 | B12: 中 | C12: 本批到货的储存与使用条件是否满足危化品要求 | D12: 20 吨过氧化氢需阴凉通风、避光、与还原剂/酸碱隔离；是否与现有库存合并构成重大危险源需计算。 | E12: 进口商 EHS | F12: 按 GB 18218 计算单元总量；核查仓库通风、温控、泄漏收集设施。 | G12: 若构成重大危险源而未备案，属重大合规风险。 | H12: ☐
A13: Q08 | B13: 低 | C13: 30 kg 桶装是否可适用 IMDG 限量/例外或其他豁免 | D13: 若适用豁免可简化部分运输要求，但不得免除危险货物申报与标志；豁免条件须按 IMDG 具体条款核对。 | E13: 货代 / 船公司 DG 部门 | F13: 由船公司 DG 部门按 IMDG 现行版本确认并书面答复。 | G13: 误用豁免会导致拒载或事故责任。 | H13: ☐
A14: Q09 | B14: 低 | C14: 是否需要向海关申请归类预裁定 | D14: 本单归类置信度高，但若报关行对包装规格/成分含量表述有异议，预裁定可锁定口径。 | E14: 进口商 / 报关代理 | F14: 评估是否存在争议点；存在则按海关总署令第236号申请预裁定。 | G14: 不申请则存在被质疑后改归并补税的风险。 | H14: ☐
A15: Q10 | B15: 中 | C15: SDS 第2节的 GHS 分类是否与 GB 30000 分项标准一致 | D15: SDS 给出 Oxid. Liq. 2 / Eye Dam. 1 等，需与 GB 30000.14（氧化性液体）等分项对应并确认中国大陆口径。 | E15: 合规顾问 / SDS 编制机构 | F15: 按 GB 30000.1-2024 与分项标准复核分类，必要时修订 H 码。 | G15: 标签与 SDS 分类不一致会被海关退单。 | H15: ☐
A17: 闭环统计
C18: 已闭环 / 总数 | D18: =COUNTIF($H$6:$H$15,"☑")&" / "&COUNTA($A$6:$A$15) | E18: 高优先级未闭环 | F18: =COUNTIFS($B$6:$B$15,"高",$H$6:$H$15,"☐")

Sheet 09 危险属性对照
A1: 09 · 危险化学品 vs 危险货物（两套体系分开判）
A2: 危险化学品（中国安全生产监管，依《危险化学品目录（2015版）》）与危险货物（运输环节，依 UN Model Regulations / GB 6944-2025 / GB 12268-2025）是两套独立的分类体系：一套成立不必然推出另一套成立，阈值与分档也不相同。
A5: 一、两套分类对照
A6: 维度 | B6: 危险化学品（中国安全生产监管） | C6: 危险货物（运输）
A7: 监管体系 | B7: 危险化学品（生产/经营/储存/使用/登记监管） | C7: 危险货物（运输）
A8: 本单适用性 | B8: 视条件适用 | C8: 适用
A9: 条目 / 编号 | B9: 《危险化学品目录（2015版）》第 903 项『过氧化氢溶液[含量＞8%]』 | C9: UN 2014 · 5.1（氧化性物质） · 次要危险 8（腐蚀性） · PG II（包装类别 II）
A10: 正确运输名称 | B10: — | C10: HYDROGEN PEROXIDE, AQUEOUS SOLUTION, with not less than 20% but not more than 60% hydrogen peroxide (stabilized as necessary)
A11: 阈值 | B11: 含量 > 8%（质量分数）；本单 30%，远超阈值。且须为『过氧化氢的水溶液』，添加剂仅限稳定剂/惰性化学品。 | C11: H₂O₂ 含量 20%~60% 对应 UN2014 / 5.1 / PG II；本单 30% 正落在该区间。
A12: 后果 | B12: 进口企业须办理危险化学品登记（法律第86条）、提供中文 SDS 与中文危险公示标签（第31条）、包装符合要求（第32条）；境内储存/使用/经营另受相应许可与安全条件约束。 | C12: 须按 IMDG Code 使用 UN 规格包装、张贴 5.1 与 8 类危险标志、提交危险货物申报、按积载与隔离要求装船；报关需填报危险类别、包装类别、UN 编号、包装UN标记（S05 第二条）。
A14: 二、浓度/形态 → 双轨结论矩阵
A15: 浓度 / 形态 | B15: 危险化学品（目录） | C15: 危险货物（运输） | D15: 要点
A16: H₂O₂ < 8%（如 3%~5% 医用稀释液） | B16: 通常不落入第903项（含量阈值） | C16: 通常不作为危险货物（<8% 一般非危险货物） | D16: 两套体系同时『不适用』，但仍属化学品，需提供一般 SDS。
A17: 8% < H₂O₂ < 20% | B17: 适用第903项；易制爆列为『8%＜含量＜20%：氧化性液体类别3』 | C17: UN 2984 / 5.1 / 包装类别 III | D17: 危化品与危险货物同时成立，但运输分档与 GHS 类别不同，容易把『类别3』误写成 UN2014。
A18: 20% ≤ H₂O₂ ≤ 60%（本单 30%） | B18: 适用第903项；易制爆列为『20%≤含量＜60%：氧化性液体类别2』 | C18: UN 2014 / 5.1（次要 8）/ 包装类别 II | D18: 本单所处区间。注意易制爆名录写『＜60%』而 IMDG 写『≤60%』，60% 边界处两套文件口径不同，需以原文核对。
A19: H₂O₂ > 60% | B19: 适用第903项；易制爆列为『含量≥60%：氧化性液体类别1』 | C19: UN 2015 / 5.1（次要 8）/ 包装类别 I | D19: 高浓度受更多运输与储存限制。
A20: 含功能性添加剂的过氧化氢复配液（如清洗剂、消毒液） | B20: 不再自动落入第903项，须按危险特性鉴定后判定（S03） | C20: 仍按实际危险特性判定 UN 编号，可能改变类别与包装类别 | D20: 这是最容易出错的一类：『溶液』二字不等于豁免。
A22: 三、常见混淆（务必避免）
A23: ✕ 把 GHS 的『氧化性液体类别2』直接当作运输的『包装类别 II』——两者分档依据不同，只是本单恰好都是 2 级。
A24: ✕ 认为『八类危险货物』等俗语能替代分类编号——运输必须落到 UN 编号、类项、包装类别、正确运输名称四项。
A25: ✕ 只凭商品名『双氧水』判断——必须看浓度与组成；同一商品名在不同浓度下监管结论完全不同。
A26: ✕ 把『危化品目录未列入』理解为『不危险』——目录以分类为基础筛选，未列入不等于无危险特性。
A28: 四、运输参数
A29: 运输方式 | B29: 海运（整柜 FCL，非散装）
A30: 国际规则 | B30: IMDG Code（国际海运危险货物规则）
A31: 国内国标 | B31: GB 6944-2025 + GB 12268-2025（自 2025-10-01 实施）
A32: UN 编号 | B32: UN 2014
A33: 正确运输名称 | B33: HYDROGEN PEROXIDE, AQUEOUS SOLUTION, with not less than 20% but not more than 60% hydrogen peroxide (stabilized as necessary)
A34: 类别 | B34: 5.1（氧化性物质）
A35: 次要危险 | B35: 8（腐蚀性）
A36: 包装类别 | B36: II
A37: 类项标志 | B37: 5.1 氧化性物质（橙底黑火焰圆）、8 腐蚀性（黑白双斜线）
A38: 包装指令 | B38: 按 IMDG 对应包装指令执行；本单采用 HDPE 桶（包装类别 II 适用的中型/桶类包装）
A39: EmS | B39: F-H（火灾：使用大量水雾冷却/稀释，避免直接射流冲击液面）、S-Q（泄漏：穿戴防护，使用惰性吸收材料收集，用水大量稀释）
A40: 隔离要求 | B40: • 与易燃液体、易燃固体、还原剂、有机过氧化物、酸类、粉末金属、食品等严禁同柜混装 • 不得与爆炸品、气体同舱积载 • 与腐蚀性物质分立积载，避免泄漏叠加
... A42: 补充说明 | B42: • 本单为 30 kg 桶装，需确认是否满足 IMDG 的限量/例外数量豁免——即便可豁免运输包装，仍不能豁免危险货物申报与标志。 • 空运（IATA DGR）对应 UN2014 有额外的客/货机限制；若改空运须重新核对，不得沿用海运结论。 • 国内段（上海港→工厂）按道路危险货物运输规则，须具备资质的危货运输车辆与押运人员。
A44: 五、中文危险公示标签（GB 15258 / GB 30000）
A45: 是否强制 | B45: 是（强制，且须为简体中文）
A46: 语言 | B46: 简体中文（可中英双语并列）
A47: 依据标准 | B47: GB 15258-2009 + GB 30000.1-2024 及分项标准（S12、S13）
...

Sheet 10 税费测算
A1: 10 · 进口税费测算（2026 年税则）
A2: 黄色底为可修改输入项，税额与合计为实时公式。汇率须替换为海关计征日实际汇率。
A5: 一、税率
A6: 项目 | B6: 税率 | C6: 说明
A7: 税则号列 | B7: 2847000000 | C7: 按归类结论
A8: 最惠国税率 | B8: 5.5% | C8: 原产于最惠国待遇地区货物适用；韩国为 WTO 成员，适用最惠国税率。来源 S06/S18，以海关现场核定为准。
A9: 暂定税率 | B9: 无（未见暂定税率） | C9: 暂定税率如设置则优先于最惠国税率适用；需在报关前以单一窗口/税则原文复核。
A10: 普通税率 | B10: 30% | C10: 仅适用于原产地不适用最惠国待遇或原产地不明的货物。
A11: 进口环节增值税 | B11: 13% | C11: 进口环节增值税由海关代征，计税价格=关税完税价格+关税+消费税。
A12: 消费税 | B12: 0 | C12: 过氧化氢不属消费税应税消费品。
A14: 二、优惠税率（状态须核实）
A15: 优惠安排 | B15: 页面显示税率 | C15: 状态 | D15: 适用条件
A16: 中国—韩国自由贸易协定（中韩 FTA） | B16: 页面显示 1.1%，但年度与降税阶段未标注 | C16: 数据冲突·待核实 | D16: 需①产品在韩方生产并符合原产地规则；②符合直接运输（Busan→Shanghai 直航或满足转运规则）；③取得中韩 FTA 原产地证书（CO）。
A17: RCEP（区域全面经济伙伴关系协定，韩国为成员） | B17: 页面显示 RCEP·韩国 2.8% | C17: 数据冲突·待核实 | D17: 需①满足 RCEP 原产地规则；②取得 RCEP 原产地证书或经核准出口商的原产地声明；③注意 RCEP 与中韩 FTA 择低适用。
A18: 最惠国税率（不申请优惠） | B18: 5.5% | C18: 已核实 | D18: 无条件适用，但税负最高；可作为原产地证书办理延迟时的兜底方案。
A19: ⚠ 同一页面另提示『部分化工产品 2016 年起零关税（含过氧化氢）』，与 1.1%/2.8% 的栏位相互矛盾，且均未给出协定年度与降税阶段编号，因此**两个第三方税率都不能直接用于成本测算**。必须由报关行在『中国国际贸易单一窗口—关税优惠税率查询』按 2847000000 + 韩国 + 2026 年度实查，或由供应商/货代书面确认出证能力后再锁定。
A21: 三、税额试算（黄色为输入）
A22: 项目 | B22: 数值 | C22: 单位 | D22: 公式说明
A23: CIF 金额（USD） | B23: 24200 | C23: USD | D23: 货值 + 运费 + 保险费
A24: 汇率（USD/CNY） | B24: 7.118 | C24: CNY | D24: 以海关计征日汇率为准
A25: CIF 金额（CNY） | B25: =B23*B24 | C25: CNY | D25: =USD × 汇率
A26: 关税税率 | B26: 0.055 | C26: % | D26: 默认取最惠国；若有证书改协定税率
A27: 关税额（CNY） | B27: =B25*B26 | C27: CNY | D27: =CIF(CNY) × 关税税率
A28: 消费税（CNY） | B28: 0 | C28: CNY | D28: 本商品不属应税消费品
A29: 增值税计税价格（CNY） | B29: =B25+B27+B28 | C29: CNY | D29: =CIF + 关税 + 消费税
A30: 增值税率 | B30: 0.13 | C30: % | D30: 标准税率
A31: 增值税额（CNY） | B31: =B29*B30 | C31: CNY | D31: =计税价格 × 增值税率
A32: 税费合计（CNY） | B32: =B27+B28+B31 | C32: CNY | D32: =关税 + 消费税 + 增值税
A35: 四、情景对比（改 CIF 或税率即自动更新）
A36: 情景 | B36: 关税率 | C36: 关税（CNY） | D36: 增值税（CNY） | E36: 税费合计（CNY）
A37: 最惠国 5.5%（无证书） | B37: 0.055 | C37: =$B$25*B37 | D37: =($B$25+C37)*$B$30 | E37: =C37+D37
A38: 中韩FTA 1.1%（待核实） | B38: 0.011 | C38: =$B$25*B38 | D38: =($B$25+C38)*$B$30 | E38: =C38+D38
A39: 零关税（若成立） | B39: 0 | C39: =$B$25*B39 | D39: =($B$25+C39)*$B$30 | E39: =C39+D39
A40: 普通税率 30%（最坏情形） | B40: 0.3 | C40: =$B$25*B40 | D40: =($B$25+C40)*$B$30 | E40: =C40+D40
A42: 说明：按 20 吨 × USD 1.18/kg + 运保费 USD 600 估算 CIF；汇率取示例值 7.1180，实际以海关计征日汇率为准。增值税进项可抵扣，此处仅计现金流。 关税 = CIF × 适用税率；进口环节增值税 = (CIF + 关税 + 消费税) × 13%。优惠税率须以原产地证书与直接运输为条件，否则按最惠国税率补税并可能加收滞纳金。

Sheet 12 法规来源
A1: 12 · 法规来源与查询日期
A2: 每条结论都可回溯。A 级=官方一手；B 级=官方转载/政务数据库；C 级=行业平台，仅供交叉参考，不可作唯一依据。
A5: 编号 | B5: 级别 | C5: 类型 | D5: 标题 | E5: 发布机关 | F5: 日期 | G5: 效力状态 | H5: 查询日期
A6: S01 | B6: A | C6: 法律 | D6: 中华人民共和国危险化学品安全法（主席令第六十四号） | E6: 全国人民代表大会常务委员会 | F6: 2025-12-27 通过 / 2026-05-01 施行 | G6: 现行有效 | H6: 2026-10-20
A7: S02 | B7: A | C7: 公告 | D7: 危险化学品目录（2015版）——十部门公告 2015年第5号（含应急管理部 2022年第8号柴油调整、2026年第3号新增5种） | E7: 应急管理部等十部门 | F7: 2015-05-01 施行 / 2022、2026 两次调整 | G7: 现行有效 | H7: 2026-10-20
A8: S03 | B8: A | C8: 官方答复 | D8: 应急管理部互动留言答复：关于《危险化学品名录》中溶液的定义（第903项） | E8: 应急管理部 危险化学品安全监督管理二司 | F8: 2021-07-26 | G8: 现行有效 | H8: 2026-10-20
A9: S04 | B9: A | C9: 部门公告 | D9: 易制爆危险化学品名录（2017年版）（公安部，2017年5月11日） | E9: 公安部 | F9: 2017-05-11 | G9: 现行有效 | H9: 2026-10-20
A10: S05 | B10: A | C10: 部门公告 | D10: 海关总署公告2020年第129号《关于进出口危险化学品及其包装检验监管有关问题的公告》 | E10: 海关总署 | F10: 2020-12-18 发布 / 2021-01-10 实施 | G10: 现行有效 | H10: 2026-10-20
A11: S06 | B11: A | C11: 公告 | D11: 国务院关税税则委员会公告2025年第12号《中华人民共和国进出口税则（2026）》 | E11: 国务院关税税则委员会 | F11: 2025-12-31 发布 / 2026-01-01 施行 | G11: 现行有效 | H11: 2026-10-20
A12: S07 | B12: B | C12: 政务数据库 | D12: 中国国际贸易单一窗口·商品编号 2847000000 申报参数（监管条件 ABG、法定第一单位 千克、规范申报要素、CIQ扩展码） | E12: 中国电子口岸数据中心 / 海关总署业务参数 | F12: 2026 税则参数 | G12: 现行有效 | H12: 2026-10-20
A13: S08 | B13: A | C13: 国家标准 | D13: GB 6944-2025《危险货物分类和品名编号》 | E13: 国家市场监督管理总局、国家标准化管理委员会 | F13: 2025-03-28 发布 / 2025-10-01 实施 | G13: 现行有效 | H13: 2026-10-20
A14: S09 | B14: A | C14: 国家标准 | D14: GB 12268-2025《危险货物品名表》 | E14: 国家市场监督管理总局、国家标准化管理委员会 | F14: 2025-03-28 发布 / 2025-10-01 实施 | G14: 现行有效 | H14: 2026-10-20
A15: S10 | B15: A | C15: 国家标准 | D15: GB/T 16483—2008《化学品安全技术说明书 内容和项目顺序》（现行有效，2009-02-01 实施） | E15: 国家质量监督检验检疫总局、国家标准委 | F15: 2008-06-18 发布 / 2009-02-01 实施 | G15: 现行有效 | H15: 2026-10-20
A16: S11 | B16: A | C16: 国家标准 | D16: GB/T 17519—2013《化学品安全技术说明书编写指南》 | E16: 国家质量监督检验检疫总局、国家标准委 | F16: 2013-09-06 发布 / 2014-01-31 实施 | G16: 现行有效 | H16: 2026-10-20
... A26: S21 | B26: A | C26: 部门规章 | D26: 商务部、海关总署公布 2026 年度《两用物项和技术进出口许可证管理目录》 | E26: 商务部、海关总署 | F26: 2025-12-31 | G26: 现行有效 | H26: 2026-10-20
D28: 链接与支撑结论
A29: 编号 | D29: 原文链接 | E29: 支撑了哪条结论
A30: S01 | D30: http://paper.people.com.cn/rmrb/pc/content/202602/25/content_30141885.html | E30: 第7条(九)海关检验；第31条中文SDS与标签；第32条包装；第53条经营许可；第58条易制爆购买凭证；第82条托运；第86条进口企业危化品登记；第122条进出口管理
A31: S02 | D31: https://www.ehscity.com/law/201505/ehslaw671.html | E31: 说明第四条：无含量说明条目指工业产品或纯度高于工业产品；序号2828为类属条目；第903项过氧化氢溶液（含量＞8%）
A32: S03 | D32: https://www.mem.gov.cn/hd/gzly/lyhf/202108/t20210812_395783.shtml | E32: 目录中如无特殊说明，溶液指水溶液；>8% 过氧化氢水溶液适用第903项；添加化学品（稳定剂、惰性化学品除外）即不再属于该水溶液条目，需另行鉴定
A33: S04 | D33: https://csrcare.com/master%20law/ | E33: 第6.1项 过氧化氢溶液（含量＞8%）：含量≥60% 氧化性液体类别1；20%≤含量＜60% 氧化性液体类别2；8%＜含量＜20% 氧化性液体类别3
A34: S05 | D34: https://www.anywayshipping.com/zh/shuangqingDetail/1c53f202-187f-4618-cfe8-a160a888f8b1 | E34: 第一条检验范围；第二条报关填报（危险类别、包装类别、UN编号、包装UN标记）与三项材料（符合性声明、抑制剂/稳定剂说明、中文危险公示标签与中文SDS样本）；第六条包装检验内容
A35: S06 | D35: https://gss.mof.gov.cn/gzdt/zhengcefabu/202512/t20251231_3981044.htm | E35: 税目 28.47『过氧化氢，不论是否用尿素固化』及税率、备注列口径
A36: S07 | D36: https://www.singlewindow.cn/access/ui/1654414908097/Param002 | E36: 监管条件 A（入境货物通关单）、B（出境货物通关单）、G（两用物项和技术出口许可证·定向）；申报要素 品牌类型|出口享惠情况|成分含量|包装规格|GTIN|CAS
A37: S08 | D37: https://chinesestandard.net/PDF-EN/GB6944-2025EN-P13P-H10896H-658331.pdf | E37: 危险货物九类分类与类项划分（第5类氧化性物质含5.1项）
A38: S09 | D38: https://codeofchina.com/standard/GB12268-2025.html | E38: UN编号对应的类项、包装类别、正确运输名称
A39: S10 | D39: https://openstd.samr.gov.cn/bzgk/std/newGbInfo?hcno=67992CA972A4CF9222095CA06064724A | E39: SDS 16 节的顺序与必备要素；第14节应载运输分类、UN编号、包装类别、海洋污染物
A40: S11 | D40: https://codeofchina.com/standard/GBT17519-2013.html | E40: SDS 各节的编写方法、数据来源与标注要求
... A50: S21 | D50: https://www.mofcom.gov.cn/zfxxgk/gkml/art/2025/art_14af6ed6ec0f43c8800f391a97b3f324.html | E50: 需按当年目录逐条核对产品是否列入；列入则进出口均需许可证
