Workbook

Sheet 01 参数与汇率
A1: 01 参数与汇率（唯一录入区）
A2: 所有黄色底色单元格可直接修改；其余表全部由公式联动计算。绿色=真实数据，紫色=模拟值，黄色=演示值。
A4: A. 交易基本信息
A5: 项目 | B5: 数值 | C5: 单位 | D5: 说明 / 来源 | E5: 性质
A6: 采购金额（外币） | B6: 1000000 | C6: USD | D6: 合同外币金额，必填 | E6: 真实
A7: 外币币种 | B7: USD | D7: 任意币种（USD/EUR/JPY/SAR…） | E7: 真实
A8: 交易方向 | B8: IMPORT_PAYMENT | D8: 进口付汇：人民币贬值 → 人民币成本上升 | E8: 真实
A9: 产品 / 规格 | B9: 工业级乙二醇（MEG, Monoethylene Glycol），聚酯级 ≥99.9% | E9: 真实
A10: HS 编码 | B10: 2905310000 | D10: 以《中华人民共和国进出口税则》为准 | E10: 真实
A11: 原产国 | B11: 沙特阿拉伯（Jubail / Al Jubail） | E11: 真实
A12: 贸易术语 | B12: CFR 中国华东主港 | E12: 真实
A13: 合同数量 | B13: 1136.4 | C13: 吨 | D13: 按 100 万美元 ÷ 880 美元/吨（MEGlobal 2026年11月 ACP，CFR 亚洲主港）= 1136.4 吨推算，用于单位成本换算；实际提单数量以合同为准。 | E13: 模拟
A14: 汇率标价方向 | B14: 1 外币 = x 人民币 | D14: CNY per FC（x 上升=人民币贬值） | E14: 真实
A15: 公司预算汇率 | B15: 6.8 | C15: CNY/FC | D15: 内部预算/成本核算用 | E15: 模拟
A17: B. 四类汇率口径（务必区分，不可混用）
A18: 口径 | B18: 汇率（CNY / 1 USD） | C18: 日期 | D18: 来源 / 定义 | E18: 性质
A19: 市场汇率 | B19: 6.6807 | C19: 2026-10-19 | D19: ECB 欧元参考汇率经 EUR/USD 交叉折算（Frankfurter API），2026-10-19 | E19: 真实
A20: 人民币汇率中间价（PBOC/CFETS） | B20: 6.72 | C20: 2026-10-20 09:15 | D20: 中国外汇交易中心 CFETS 人民币汇率中间价 ccpr.json（人民银行授权），2026-10-20 09:15 | E20: 真实
A21: 银行实际购汇价（现汇卖出价） | B21: 6.7435 | C21: 2026-10-20 | D21: DEMO：以 CFETS 中间价 6.7200 为基准 +35bp 模拟的银行现汇卖出价（银行实盘须由用户提供） | E21: 演示
A22: 海关计征汇率 | B22: 6.72 | C22: 2026-09-16 | D22: DEMO：按海关总署令第272号第十三条，取 2026 年 9 月第三个星期三（9/16）CFETS 中间价；实际值须查海关每月公布数据 | E22: 演示
A23: 基准汇率取值口径 | B23: 银行实际购汇价 | D23: 下拉选择。进口付汇的实际付款以「银行实际购汇价」为准。 | E23: 设置
A24: 基准汇率（CNY per FC） | B24: =IF(B23="银行实际购汇价",$B$21,IF(B23="人民币汇率中间价",$B$20,IF(B23="市场汇率",$B$19,$B$22))) -> 6.7435 | C24: CNY/FC | D24: =INDEX(四口径汇率, MATCH(所选口径, 口径名, 0)) -> 0 | E24: 计算
A25: 银行购汇价相对中间价升水 | B25: =IF(B20=0,0,B21/B20-1) -> 0 | C25: bp | D25: =银行购汇价 ÷ 中间价 − 1 -> 0 | E25: 计算
A27: C. 到厂成本参数
A28: 项目 | B28: 数值 | C28: 单位 | D28: 说明 | E28: 性质
A29: 国际运费（外币） | B29: 0 | C29: USD | D29: CFR/CIF 已含则填 0 | E29: 模拟
A30: 保险费（外币） | B30: 0 | C30: USD | E30: 模拟
A31: 其他外币费用 | B31: 0 | C31: USD | E31: 模拟
A32: 港杂费 | B32: 38000 | C32: CNY | D32: 与汇率无关 | E32: 模拟
A33: 报关代理费 | B33: 12000 | C33: CNY | D33: 与汇率无关 | E33: 模拟
A34: 内陆运输费 | B34: 26000 | C34: CNY | D34: 与汇率无关 | E34: 模拟
A35: 仓储及其他人民币费用 | B35: 9000 | C35: CNY | D35: 与汇率无关 | E35: 模拟
A36: 银行手续费及汇兑费用 | B36: 6800 | C36: CNY | D36: 与汇率无关 | E36: 模拟
A37: 进口关税率 | B37: 0.055 | C37: % | D37: 乙二醇 2905310000 最惠国 5.5%（无暂定税率） | E37: 真实
A38: 消费税税率 | B38: 0 | C38: % | D38: MEG 为 0 | E38: 真实
A39: 增值税率 | B39: 0.13 | C39: % | D39: 标准税率 13% | E39: 真实
A40: 增值税口径 | B40: deductible | D40: deductible=可抵扣（不计入成本）；cost=不可抵扣（计入成本） | E40: 设置
A42: D. 国内销售与毛利参数（可选）
A43: 项目 | B43: 数值 | C43: 单位 | D43: 说明 | E43: 性质
A44: 国内销售价 | B44: 7600 | C44: 元/吨 | D44: 【模拟教学值】设定为 7,600 元/吨（含税）。同期华东主流现货为 5,722 元/吨（同花顺 iFinD，2026-10-14），本值显著高于市场价，仅用于演示“毛利随汇率变动 + 零毛利/5%毛利盈亏平衡汇率落在历史区间内”的机理；真实测算须替换为企业实际销售合同价。 | E44: 模拟
...

Sheet 02 付款额与敏感性
A1: 02 人民币付款额与汇率敏感性
A2: 方向关系：汇率 x 上升 = 外币升值/人民币贬值 → 付汇人民币增加（红色）；x 下降 = 人民币升值 → 减少（绿色）。
A4: 核心结果
A5: 项目 | B5: 数值 | I5: 公式 / 说明
A6: 采购金额（外币） | B6: ='01 参数与汇率'!B6 -> 0 | I6: =01!B4 录入值 -> 0
A7: 基准汇率（CNY/FC） | B7: ='01 参数与汇率'!B24 -> 0 | I7: =01 表按所选口径取值（中英文标签 IF 分支） -> 0
A8: 人民币付款额（基准） | B8: =B6*B7 -> 0 | I8: =外币金额 × 汇率 -> 0
A10: 汇率敏感性（±1% / ±3% / ±5%，可自行增删行）
A11: 汇率变动 | B11: 新汇率 | C11: 人民币付款额 | D11: 变动额 | E11: 变动幅度 | F11: 方向判定 | I11: 公式
A12: -0.05 | B12: =B7*(1+A12) -> 0 | C12: =B6*B12 -> 0 | D12: =C12-C$15 -> 0 | E12: =IF(C$15=0,0,C12/C$15-1) -> 0 | F12: =IF(A12>0,"人民币贬值·成本↑",IF(A12<0,"人民币升值·成本↓","基准情景")) -> 0 | I12: =金额 × 汇率 ×(1+变动率)；行内变动额相对 0% 行 -> 0
A13: -0.03 | B13: =B7*(1+A13) -> 0 | C13: =B6*B13 -> 0 | D13: =C13-C$15 -> 0 | E13: =IF(C$15=0,0,C13/C$15-1) -> 0 | F13: =IF(A13>0,"人民币贬值·成本↑",IF(A13<0,"人民币升值·成本↓","基准情景")) -> 0 | I13: =金额 × 汇率 ×(1+变动率)；行内变动额相对 0% 行 -> 0
A14: -0.01 | B14: =B7*(1+A14) -> 0 | C14: =B6*B14 -> 0 | D14: =C14-C$15 -> 0 | E14: =IF(C$15=0,0,C14/C$15-1) -> 0 | F14: =IF(A14>0,"人民币贬值·成本↑",IF(A14<0,"人民币升值·成本↓","基准情景")) -> 0 | I14: =金额 × 汇率 ×(1+变动率)；行内变动额相对 0% 行 -> 0
A15: 0 | B15: =B7*(1+A15) -> 0 | C15: =B6*B15 -> 0 | D15: =C15-C$15 -> 0 | E15: =IF(C$15=0,0,C15/C$15-1) -> 0 | F15: =IF(A15>0,"人民币贬值·成本↑",IF(A15<0,"人民币升值·成本↓","基准情景")) -> 0 | I15: =金额 × 汇率 ×(1+变动率)；行内变动额相对 0% 行 -> 0
A16: 0.01 | B16: =B7*(1+A16) -> 0 | C16: =B6*B16 -> 0 | D16: =C16-C$15 -> 0 | E16: =IF(C$15=0,0,C16/C$15-1) -> 0 | F16: =IF(A16>0,"人民币贬值·成本↑",IF(A16<0,"人民币升值·成本↓","基准情景")) -> 0 | I16: =金额 × 汇率 ×(1+变动率)；行内变动额相对 0% 行 -> 0
A17: 0.03 | B17: =B7*(1+A17) -> 0 | C17: =B6*B17 -> 0 | D17: =C17-C$15 -> 0 | E17: =IF(C$15=0,0,C17/C$15-1) -> 0 | F17: =IF(A17>0,"人民币贬值·成本↑",IF(A17<0,"人民币升值·成本↓","基准情景")) -> 0 | I17: =金额 × 汇率 ×(1+变动率)；行内变动额相对 0% 行 -> 0
A18: 0.05 | B18: =B7*(1+A18) -> 0 | C18: =B6*B18 -> 0 | D18: =C18-C$15 -> 0 | E18: =IF(C$15=0,0,C18/C$15-1) -> 0 | F18: =IF(A18>0,"人民币贬值·成本↑",IF(A18<0,"人民币升值·成本↓","基准情景")) -> 0 | I18: =金额 × 汇率 ×(1+变动率)；行内变动额相对 0% 行 -> 0
A20: 四类汇率口径对照（同一笔付款）
A21: 口径 | B21: 汇率 | C21: 日期 | D21: 人民币付款 | E21: 相对基准差额 | F21: 相对基准% | I21: 说明
A22: 市场汇率 | B22: ='01 参数与汇率'!B19 -> 0 | C22: 2026-10-19 | D22: =B6*B22 -> 0 | E22: =D22-$'02 付款额与敏感性'!B8 -> 0 | F22: =IF($'02 付款额与敏感性'!B8=0,0,D22/$'02 付款额与敏感性'!B8-1) -> 0 | I22: 海关计征汇率仅用于计税，不代表实际付款价
A23: 人民币汇率中间价 | B23: ='01 参数与汇率'!B20 -> 0 | C23: 2026-10-20 09:15 | D23: =B6*B23 -> 0 | E23: =D23-$'02 付款额与敏感性'!B8 -> 0 | F23: =IF($'02 付款额与敏感性'!B8=0,0,D23/$'02 付款额与敏感性'!B8-1) -> 0 | I23: 海关计征汇率仅用于计税，不代表实际付款价
A24: 银行实际购汇价 | B24: ='01 参数与汇率'!B21 -> 0 | C24: 2026-10-20 | D24: =B6*B24 -> 0 | E24: =D24-$'02 付款额与敏感性'!B8 -> 0 | F24: =IF($'02 付款额与敏感性'!B8=0,0,D24/$'02 付款额与敏感性'!B8-1) -> 0 | I24: 海关计征汇率仅用于计税，不代表实际付款价
A25: 海关计征汇率 | B25: ='01 参数与汇率'!B22 -> 0 | C25: 2026-09-16 | D25: =B6*B25 -> 0 | E25: =D25-$'02 付款额与敏感性'!B8 -> 0 | F25: =IF($'02 付款额与敏感性'!B8=0,0,D25/$'02 付款额与敏感性'!B8-1) -> 0 | I25: 海关计征汇率仅用于计税，不代表实际付款价
A27: 提醒：中间价、市场汇率、银行购汇价、海关计征汇率是四个不同概念。进口付汇的真实人民币支出由银行购汇价决定；海关计征汇率为上月第三个星期三中间价（海关总署令第272号第十三条），只用于完税价格折算。

Sheet 03 到厂成本
A1: 03 人民币到厂成本构成
A2: 完税价格按海关计征汇率折算；增值税按 01 表所选口径决定是否计入成本。
A4: 成本构成（基准汇率情景）
A5: 成本项 | B5: 金额（元） | C5: 计算依据 | D5: 占合计 | H5: 公式
A6: 货值（外币×汇率） | B6: ='02 付款额与敏感性'!B6*'02 付款额与敏感性'!B7 -> 0 | C6: 外币金额 × 基准汇率 | D6: =IF($B$16=0,0,B6/$B$16) -> 0 | H6: ='02 付款额与敏感性'!B6*'02 付款额与敏感性'!B7 -> 0
A7: 国际运费（外币×汇率） | B7: ='01 参数与汇率'!B29*'02 付款额与敏感性'!B7 -> 0 | C7: 外币运费 × 基准汇率 | D7: =IF($B$16=0,0,B7/$B$16) -> 0 | H7: ='01 参数与汇率'!B29*'02 付款额与敏感性'!B7 -> 0
A8: 保险费（外币×汇率） | B8: ='01 参数与汇率'!B30*'02 付款额与敏感性'!B7 -> 0 | C8: 外币保费 × 基准汇率 | D8: =IF($B$16=0,0,B8/$B$16) -> 0 | H8: ='01 参数与汇率'!B30*'02 付款额与敏感性'!B7 -> 0
A9: 其他外币费用（×汇率） | B9: ='01 参数与汇率'!B31*'02 付款额与敏感性'!B7 -> 0 | C9: 外币费用 × 基准汇率 | D9: =IF($B$16=0,0,B9/$B$16) -> 0 | H9: ='01 参数与汇率'!B31*'02 付款额与敏感性'!B7 -> 0
A10: 海关完税价格（CIF×计征汇率） | B10: =SUM(B6:B9)/'02 付款额与敏感性'!B7*'01 参数与汇率'!B22 -> 0 | C10: (货值+运+保+其他外币费用)×计征汇率 | D10: =IF($B$16=0,0,B10/$B$16) -> 0 | H10: =(CIF 外币合计) ÷ 基准汇率 × 计征汇率 -> 0
A11: 进口关税 | B11: =B10*'01 参数与汇率'!B37 -> 0 | C11: 完税价格 × 关税率 | D11: =IF($B$16=0,0,B11/$B$16) -> 0 | H11: =完税价格 × 关税率 -> 0
A12: 消费税 | B12: =B10*'01 参数与汇率'!B38 -> 0 | C12: 完税价格 × 消费税率 | D12: =IF($B$16=0,0,B12/$B$16) -> 0 | H12: =完税价格 × 消费税率 -> 0
A13: 进口增值税（计税用） | B13: =(B10+B11+B12)*'01 参数与汇率'!B39 -> 0 | C13: (完税价格+关税+消费税)×增值税率 | D13: =IF($B$16=0,0,B13/$B$16) -> 0 | H13: =(完税价格+关税+消费税) × 增值税率 -> 0
A14: 增值税计入成本金额 | B14: =IF('01 参数与汇率'!B40="cost",B13,0) -> 0 | C14: 可抵扣 → 0；不可抵扣 → 全额计入 | D14: =IF($B$16=0,0,B14/$B$16) -> 0 | H14: =IF(增值税口径="cost", 增值税, 0) -> 0
A15: 人民币固定费用合计 | B15: ='01 参数与汇率'!B32+'01 参数与汇率'!B33+'01 参数与汇率'!B34+'01 参数与汇率'!B35+'01 参数与汇率'!B36 -> 0 | C15: 港杂+代理+内陆+仓储+银行手续费 | D15: =IF($B$16=0,0,B15/$B$16) -> 0 | H15: =各项人民币费用之和（与汇率无关） -> 0
A16: 人民币到厂成本合计 | B16: =B6+B7+B8+B9+B11+B12+B14+B15 -> 0 | C16: 各项之和 | D16: =1 -> 0 | H16: =货值+运费+保费+其他+关税+消费税+增值税(入成本)+人民币费用 -> 0
A17: 折合单位到厂成本（元/吨） | B17: =IF('01 参数与汇率'!B13=0,0,B16/'01 参数与汇率'!B13) -> 0 | C17: 合计 ÷ 数量 | H17: =到厂成本合计 ÷ 合同数量 -> 0
A18: 汇率相关成本占比 | B18: =IF(B16=0,0,(B6+B7+B8+B9+B11+B12+B14)/B16) -> 0 | C18: 汇率相关 ÷ 合计 | H18: =(汇率相关成本) ÷ 合计；其余为人民币固定费用，稀释了敏感性 -> 0
A20: 到厂成本汇率敏感性
A21: 汇率变动 | B21: 新汇率 | C21: 货值（人民币） | D21: 关税 | E21: 到厂成本 | F21: 变动额 | G21: 变动幅度 | H21: 公式
A22: -0.05 | B22: ='02 付款额与敏感性'!B7*(1+A22) -> 0 | C22: ='02 付款额与敏感性'!B6*B22 -> 0 | D22: =B11*B22/'02 付款额与敏感性'!B7 -> 0 | E22: =B16*B18*B22/'02 付款额与敏感性'!B7+B16*(1-B18) -> 0 | F22: =E22-E$25 -> 0 | G22: =IF(E$25=0,0,E22/E$25-1) -> 0 | H22: 成本=汇率相关部分×(1+Δ%)+固定费用
A23: -0.03 | B23: ='02 付款额与敏感性'!B7*(1+A23) -> 0 | C23: ='02 付款额与敏感性'!B6*B23 -> 0 | D23: =B11*B23/'02 付款额与敏感性'!B7 -> 0 | E23: =B16*B18*B23/'02 付款额与敏感性'!B7+B16*(1-B18) -> 0 | F23: =E23-E$25 -> 0 | G23: =IF(E$25=0,0,E23/E$25-1) -> 0
A24: -0.01 | B24: ='02 付款额与敏感性'!B7*(1+A24) -> 0 | C24: ='02 付款额与敏感性'!B6*B24 -> 0 | D24: =B11*B24/'02 付款额与敏感性'!B7 -> 0 | E24: =B16*B18*B24/'02 付款额与敏感性'!B7+B16*(1-B18) -> 0 | F24: =E24-E$25 -> 0 | G24: =IF(E$25=0,0,E24/E$25-1) -> 0
A25: 0 | B25: ='02 付款额与敏感性'!B7*(1+A25) -> 0 | C25: ='02 付款额与敏感性'!B6*B25 -> 0 | D25: =B11*B25/'02 付款额与敏感性'!B7 -> 0 | E25: =B16*B18*B25/'02 付款额与敏感性'!B7+B16*(1-B18) -> 0 | F25: =E25-E$25 -> 0 | G25: =IF(E$25=0,0,E25/E$25-1) -> 0
A26: 0.01 | B26: ='02 付款额与敏感性'!B7*(1+A26) -> 0 | C26: ='02 付款额与敏感性'!B6*B26 -> 0 | D26: =B11*B26/'02 付款额与敏感性'!B7 -> 0 | E26: =B16*B18*B26/'02 付款额与敏感性'!B7+B16*(1-B18) -> 0 | F26: =E26-E$25 -> 0 | G26: =IF(E$25=0,0,E26/E$25-1) -> 0
A27: 0.03 | B27: ='02 付款额与敏感性'!B7*(1+A27) -> 0 | C27: ='02 付款额与敏感性'!B6*B27 -> 0 | D27: =B11*B27/'02 付款额与敏感性'!B7 -> 0 | E27: =B16*B18*B27/'02 付款额与敏感性'!B7+B16*(1-B18) -> 0 | F27: =E27-E$25 -> 0 | G27: =IF(E$25=0,0,E27/E$25-1) -> 0
A28: 0.05 | B28: ='02 付款额与敏感性'!B7*(1+A28) -> 0 | C28: ='02 付款额与敏感性'!B6*B28 -> 0 | D28: =B11*B28/'02 付款额与敏感性'!B7 -> 0 | E28: =B16*B18*B28/'02 付款额与敏感性'!B7+B16*(1-B18) -> 0 | F28: =E28-E$25 -> 0 | G28: =IF(E$25=0,0,E28/E$25-1) -> 0
A30: 说明：到厂成本的敏感性小于纯付汇金额的敏感性，因为港杂、内陆运费、代理费等人民币费用不随汇率变动。本表假设海关计征汇率与市场同步按比例变动；若申报月份计征汇率已锁定，应以实际计征汇率重算。

Sheet 04 毛利与盈亏平衡
A1: 04 毛利测算与盈亏平衡汇率
A2: 仅在销售价、数量、非汇率成本齐备时有效；缺少任一，本表结果将显示为无效值而非臆造利润。
A4: 毛利构成（基准汇率）
A5: 项目 | B5: 数值 | C5: 单位 | I5: 公式
A6: 合同数量（吨） | B6: ='01 参数与汇率'!B13 -> 0 | C6: 吨 | I6: 来自 01 表
A7: 国内销售价 | B7: ='01 参数与汇率'!B44 -> 0 | C7: 元/吨 | I7: 模拟值，须替换为实际售价
A8: 不含税售价 | B8: =IF('01 参数与汇率'!B49="tax_included",B7/(1+'01 参数与汇率'!B39),B7) -> 0 | C8: 元/吨 | I8: 含税价 ÷(1+增值税率)
A9: 不含税销售收入 | B9: =B8*B6 -> 0 | C9: 元 | I9: 不含税售价 × 数量
A10: 到厂成本 | B10: ='03 到厂成本'!B16 -> 0 | C10: 元 | I10: 来自 03 表
A11: 非汇率相关成本 | B11: ='01 参数与汇率'!B45*B6 -> 0 | C11: 元 | I11: 单位成本 × 数量
A12: 总成本 | B12: =B10+B11 -> 0 | C12: 元 | I12: 到厂成本 + 非汇率成本
A13: 毛利额 | B13: =B9-B12 -> 0 | C13: 元 | I13: 不含税收入 − 总成本
A14: 毛利率 | B14: =IF(B9=0,0,B13/B9) -> 0 | C14: % | I14: 毛利额 ÷ 不含税收入
A16: 不同汇率下的毛利
A17: 汇率变动 | B17: 新汇率 | C17: 到厂成本 | D17: 总成本 | E17: 毛利额 | F17: 毛利率 | I17: 公式
A18: -0.05 | B18: ='02 付款额与敏感性'!B7*(1+A18) -> 0 | C18: =B10*B18*B18/'02 付款额与敏感性'!B7+B10*(1-B18) -> 0 | D18: =C18+B11 -> 0 | E18: =B9-D18 -> 0 | F18: =IF(B9=0,0,E18/B9) -> 0 | I18: 成本 = 到厂汇率相关部分×(1+Δ%) + 固定部分 + 非汇率成本
A19: -0.03 | B19: ='02 付款额与敏感性'!B7*(1+A19) -> 0 | C19: =B10*B18*B19/'02 付款额与敏感性'!B7+B10*(1-B18) -> 0 | D19: =C19+B11 -> 0 | E19: =B9-D19 -> 0 | F19: =IF(B9=0,0,E19/B9) -> 0
A20: -0.01 | B20: ='02 付款额与敏感性'!B7*(1+A20) -> 0 | C20: =B10*B18*B20/'02 付款额与敏感性'!B7+B10*(1-B18) -> 0 | D20: =C20+B11 -> 0 | E20: =B9-D20 -> 0 | F20: =IF(B9=0,0,E20/B9) -> 0
A21: 0 | B21: ='02 付款额与敏感性'!B7*(1+A21) -> 0 | C21: =B10*B18*B21/'02 付款额与敏感性'!B7+B10*(1-B18) -> 0 | D21: =C21+B11 -> 0 | E21: =B9-D21 -> 0 | F21: =IF(B9=0,0,E21/B9) -> 0
A22: 0.01 | B22: ='02 付款额与敏感性'!B7*(1+A22) -> 0 | C22: =B10*B18*B22/'02 付款额与敏感性'!B7+B10*(1-B18) -> 0 | D22: =C22+B11 -> 0 | E22: =B9-D22 -> 0 | F22: =IF(B9=0,0,E22/B9) -> 0
A23: 0.03 | B23: ='02 付款额与敏感性'!B7*(1+A23) -> 0 | C23: =B10*B18*B23/'02 付款额与敏感性'!B7+B10*(1-B18) -> 0 | D23: =C23+B11 -> 0 | E23: =B9-D23 -> 0 | F23: =IF(B9=0,0,E23/B9) -> 0
A24: 0.05 | B24: ='02 付款额与敏感性'!B7*(1+A24) -> 0 | C24: =B10*B18*B24/'02 付款额与敏感性'!B7+B10*(1-B18) -> 0 | D24: =C24+B11 -> 0 | E24: =B9-D24 -> 0 | F24: =IF(B9=0,0,E24/B9) -> 0
A26: 盈亏平衡汇率（毛利降至目标水平时的汇率）
A27: 目标毛利率 | B27: λ* | C27: 平衡汇率 | D27: 相对当前变动 | E27: 汇率缓冲空间（元） | F27: 适用性 | I27: 公式
A28: ='01 参数与汇率'!B46 -> 0 | B28: =IF(OR(('03 到厂成本'!B6+'03 到厂成本'!B7+'03 到厂成本'!B8+'03 到厂成本'!B9+'03 到厂成本'!B11+'03 到厂成本'!B12+'03 到厂成本'!B14)<=0,B14<A28,(B9*(1-A28)-((B10-('03 到厂成本'!B6+'03 到厂成本'!B7+'03 到厂成本'!B8+'03 到厂成本'!B9+'03 到厂成本'!B11+'03 到厂成本'!B12+'03 到厂成本'!B14))+B11))<=0),"",(B9*(1-A28)-((B10-('03 到厂成本'!B6+'03 到厂成本'!B7+'03 到厂成本'!B8+'03 到厂成本'!B9+'03 到厂成本'!B11+'03 到厂成本'!B12+'03 到厂成本'!B14))+B11))/('03 到厂成本'!B6+'03 到厂成本'!B7+'03 到厂成本'!B8+'03 到厂成本'!B9+'03 到厂成本'!B11+'03 到厂成本'!B12+'03 到厂成本'!B14)) -> 0 | C28: =IF(ISNUMBER(B28),'02 付款额与敏感性'!B7*B28,"") -> 0 | D28: =IF(ISNUMBER(B28),B28-1,"") -> 0 | E28: =IF(ISNUMBER(B28),(B28-1)*('03 到厂成本'!B6+'03 到厂成本'!B7+'03 到厂成本'!B8+'03 到厂成本'!B9+'03 到厂成本'!B11+'03 到厂成本'!B12+'03 到厂成本'!B14),"") -> 0 | F28: =IF(B14<A28,"不适用：基准毛利率已低于目标","适用") -> 0 | I28: λ*=[R0(1−m)−NF]÷FX0；平衡汇率=基准汇率×λ*
A29: ='01 参数与汇率'!B47 -> 0 | B29: =IF(OR(('03 到厂成本'!B6+'03 到厂成本'!B7+'03 到厂成本'!B8+'03 到厂成本'!B9+'03 到厂成本'!B11+'03 到厂成本'!B12+'03 到厂成本'!B14)<=0,B14<A29,(B9*(1-A29)-((B10-('03 到厂成本'!B6+'03 到厂成本'!B7+'03 到厂成本'!B8+'03 到厂成本'!B9+'03 到厂成本'!B11+'03 到厂成本'!B12+'03 到厂成本'!B14))+B11))<=0),"",(B9*(1-A29)-((B10-('03 到厂成本'!B6+'03 到厂成本'!B7+'03 到厂成本'!B8+'03 到厂成本'!B9+'03 到厂成本'!B11+'03 到厂成本'!B12+'03 到厂成本'!B14))+B11))/('03 到厂成本'!B6+'03 到厂成本'!B7+'03 到厂成本'!B8+'03 到厂成本'!B9+'03 到厂成本'!B11+'03 到厂成本'!B12+'03 到厂成本'!B14)) -> 0 | C29: =IF(ISNUMBER(B29),'02 付款额与敏感性'!B7*B29,"") -> 0 | D29: =IF(ISNUMBER(B29),B29-1,"") -> 0 | E29: =IF(ISNUMBER(B29),(B29-1)*('03 到厂成本'!B6+'03 到厂成本'!B7+'03 到厂成本'!B8+'03 到厂成本'!B9+'03 到厂成本'!B11+'03 到厂成本'!B12+'03 到厂成本'!B14),"") -> 0 | F29: =IF(B14<A29,"不适用：基准毛利率已低于目标","适用") -> 0 | I29: λ*=[R0(1−m)−NF]÷FX0；平衡汇率=基准汇率×λ*
A30: ='01 参数与汇率'!B48 -> 0 | B30: =IF(OR(('03 到厂成本'!B6+'03 到厂成本'!B7+'03 到厂成本'!B8+'03 到厂成本'!B9+'03 到厂成本'!B11+'03 到厂成本'!B12+'03 到厂成本'!B14)<=0,B14<A30,(B9*(1-A30)-((B10-('03 到厂成本'!B6+'03 到厂成本'!B7+'03 到厂成本'!B8+'03 到厂成本'!B9+'03 到厂成本'!B11+'03 到厂成本'!B12+'03 到厂成本'!B14))+B11))<=0),"",(B9*(1-A30)-((B10-('03 到厂成本'!B6+'03 到厂成本'!B7+'03 到厂成本'!B8+'03 到厂成本'!B9+'03 到厂成本'!B11+'03 到厂成本'!B12+'03 到厂成本'!B14))+B11))/('03 到厂成本'!B6+'03 到厂成本'!B7+'03 到厂成本'!B8+'03 到厂成本'!B9+'03 到厂成本'!B11+'03 到厂成本'!B12+'03 到厂成本'!B14)) -> 0 | C30: =IF(ISNUMBER(B30),'02 付款额与敏感性'!B7*B30,"") -> 0 | D30: =IF(ISNUMBER(B30),B30-1,"") -> 0 | E30: =IF(ISNUMBER(B30),(B30-1)*('03 到厂成本'!B6+'03 到厂成本'!B7+'03 到厂成本'!B8+'03 到厂成本'!B9+'03 到厂成本'!B11+'03 到厂成本'!B12+'03 到厂成本'!B14),"") -> 0 | F30: =IF(B14<A30,"不适用：基准毛利率已低于目标","适用") -> 0 | I30: λ*=[R0(1−m)−NF]÷FX0；平衡汇率=基准汇率×λ*
A32: 解读：平衡汇率表示“在当前销售价与成本结构下，汇率升到多少会把毛利压到目标水平”，用于评估风险敞口大小。 它不是汇率预测，也不代表汇率会走到该位置。λ*<1 表示当前已不达标；‘不适用’表示基准毛利率已低于目标。

Sheet 05 分批付款
A1: 05 分批付款汇率敏感性
A2: 各批次按 01 表比例与锁定情况分别计价；锁定批次不随情景变动。
A4: 分批明细（基准情景）
A5: 批次 | B5: 比例 | C5: 外币金额 | D5: 已锁汇率 | E5: 基准人民币 | F5: 结算日 | L5: 公式
A6: ='01 参数与汇率'!A53 -> 0 | B6: ='01 参数与汇率'!B53 -> 0 | C6: ='02 付款额与敏感性'!B6*B6 -> 0 | D6: =IF('01 参数与汇率'!D53="",'02 付款额与敏感性'!B7,'01 参数与汇率'!D53) -> 0 | E6: =C6*D6 -> 0 | F6: =IF('01 参数与汇率'!B56="","",TEXT('01 参数与汇率'!B56+'01 参数与汇率'!C53,"yyyy-mm-dd")) -> 0 | L6: 外币金额=总额×比例；人民币=外币金额×该批汇率(锁定值或基准)
A7: ='01 参数与汇率'!A54 -> 0 | B7: ='01 参数与汇率'!B54 -> 0 | C7: ='02 付款额与敏感性'!B6*B7 -> 0 | D7: =IF('01 参数与汇率'!D54="",'02 付款额与敏感性'!B7,'01 参数与汇率'!D54) -> 0 | E7: =C7*D7 -> 0 | F7: =IF('01 参数与汇率'!B56="","",TEXT('01 参数与汇率'!B56+'01 参数与汇率'!C54,"yyyy-mm-dd")) -> 0 | L7: 外币金额=总额×比例；人民币=外币金额×该批汇率(锁定值或基准)
A8: 合计 | B8: =SUM(B6:B7) -> 0 | C8: =SUM(C6:C7) -> 0 | E8: =SUM(E6:E7) -> 0 | L8: =SUM(各批次) -> 0
A10: 情景矩阵（汇率整体变动 Δ% 下的各批人民币金额）
A11: 汇率变动 | B11: 新汇率 | C11: 预付款人民币 | D11: 尾款人民币 | E11: 合计 | F11: 相对基准变动 | G11: 变动幅度 | L11: 公式
A12: -0.05 | B12: ='02 付款额与敏感性'!B7*(1+A12) -> 0 | C12: =C6*IF('01 参数与汇率'!D53="",B12,'01 参数与汇率'!D53) -> 0 | D12: =C7*IF('01 参数与汇率'!D54="",B12,'01 参数与汇率'!D54) -> 0 | E12: =C12+D12 -> 0 | F12: =E12-$E8 -> 0 | G12: =IF($E8=0,0,E12/$E8-1) -> 0 | L12: 锁定批次取锁定价，其余取情景价
A13: -0.03 | B13: ='02 付款额与敏感性'!B7*(1+A13) -> 0 | C13: =C6*IF('01 参数与汇率'!D53="",B13,'01 参数与汇率'!D53) -> 0 | D13: =C7*IF('01 参数与汇率'!D54="",B13,'01 参数与汇率'!D54) -> 0 | E13: =C13+D13 -> 0 | F13: =E13-$E8 -> 0 | G13: =IF($E8=0,0,E13/$E8-1) -> 0
A14: -0.01 | B14: ='02 付款额与敏感性'!B7*(1+A14) -> 0 | C14: =C6*IF('01 参数与汇率'!D53="",B14,'01 参数与汇率'!D53) -> 0 | D14: =C7*IF('01 参数与汇率'!D54="",B14,'01 参数与汇率'!D54) -> 0 | E14: =C14+D14 -> 0 | F14: =E14-$E8 -> 0 | G14: =IF($E8=0,0,E14/$E8-1) -> 0
A15: 0 | B15: ='02 付款额与敏感性'!B7*(1+A15) -> 0 | C15: =C6*IF('01 参数与汇率'!D53="",B15,'01 参数与汇率'!D53) -> 0 | D15: =C7*IF('01 参数与汇率'!D54="",B15,'01 参数与汇率'!D54) -> 0 | E15: =C15+D15 -> 0 | F15: =E15-$E8 -> 0 | G15: =IF($E8=0,0,E15/$E8-1) -> 0
A16: 0.01 | B16: ='02 付款额与敏感性'!B7*(1+A16) -> 0 | C16: =C6*IF('01 参数与汇率'!D53="",B16,'01 参数与汇率'!D53) -> 0 | D16: =C7*IF('01 参数与汇率'!D54="",B16,'01 参数与汇率'!D54) -> 0 | E16: =C16+D16 -> 0 | F16: =E16-$E8 -> 0 | G16: =IF($E8=0,0,E16/$E8-1) -> 0
A17: 0.03 | B17: ='02 付款额与敏感性'!B7*(1+A17) -> 0 | C17: =C6*IF('01 参数与汇率'!D53="",B17,'01 参数与汇率'!D53) -> 0 | D17: =C7*IF('01 参数与汇率'!D54="",B17,'01 参数与汇率'!D54) -> 0 | E17: =C17+D17 -> 0 | F17: =E17-$E8 -> 0 | G17: =IF($E8=0,0,E17/$E8-1) -> 0
A18: 0.05 | B18: ='02 付款额与敏感性'!B7*(1+A18) -> 0 | C18: =C6*IF('01 参数与汇率'!D53="",B18,'01 参数与汇率'!D53) -> 0 | D18: =C7*IF('01 参数与汇率'!D54="",B18,'01 参数与汇率'!D54) -> 0 | E18: =C18+D18 -> 0 | F18: =E18-$E8 -> 0 | G18: =IF($E8=0,0,E18/$E8-1) -> 0
A20: 提示：把某批“已锁汇率”填入 01 表 D 列后，该批在情景矩阵中不再变化，可直观看到部分锁定如何降低整体敏感度。本表仅测算不同结算时点的汇率敞口大小，不涉及任何外汇衍生品选择或交易建议。

Sheet 06 历史汇率与分位
A1: 06 USD/CNY 历史汇率与当前分位
A2: 数据来源：ECB 欧元参考汇率（经交叉折算）/ Frankfurter 公开接口；已与 ER-API 交叉核对。真实数据，未做任何平滑或伪造。 | L2: 日期 | M2: 汇率
L3: 43830 | M3: 6.9615
A4: 统计摘要（公式基于本表右侧日度数据区间计算） | L4: 43832 | M4: 6.9638
A5: 区间 | B5: 起始日 | C5: 观测数 | D5: 最低 | E5: 最高 | F5: 均值 | G5: 当前中间价分位 | H5: 当前市场汇率分位 | I5: 说明 | L5: 43833 | M5: 6.9716
A6: 近 1 年 | B6: 45949 | C6: =COUNTIFS($L$3:$L$1745,">="&B6) -> 0 | D6: =MINIFS($M$3:$M$1745,$L$3:$L$1745,">="&B6) -> 0 | E6: =MAXIFS($M$3:$M$1745,$L$3:$L$1745,">="&B6) -> 0 | F6: =AVERAGEIFS($M$3:$M$1745,$L$3:$L$1745,">="&B6) -> 0 | G6: =IF(C6=0,0,COUNTIFS($M$3:$M$1745,"<="&'01 参数与汇率'!B20,$L$3:$L$1745,">="&B6)/C6) -> 0 | H6: =IF(C6=0,0,COUNTIFS($M$3:$M$1745,"<="&'01 参数与汇率'!B19,$L$3:$L$1745,">="&B6)/C6) -> 0 | I6: 分位=区间内≤当前汇率的观测占比；越低说明当前外币越便宜 | L6: 43836 | M6: 6.9724
A7: 近 3 年 | B7: 45218 | C7: =COUNTIFS($L$3:$L$1745,">="&B7) -> 0 | D7: =MINIFS($M$3:$M$1745,$L$3:$L$1745,">="&B7) -> 0 | E7: =MAXIFS($M$3:$M$1745,$L$3:$L$1745,">="&B7) -> 0 | F7: =AVERAGEIFS($M$3:$M$1745,$L$3:$L$1745,">="&B7) -> 0 | G7: =IF(C7=0,0,COUNTIFS($M$3:$M$1745,"<="&'01 参数与汇率'!B20,$L$3:$L$1745,">="&B7)/C7) -> 0 | H7: =IF(C7=0,0,COUNTIFS($M$3:$M$1745,"<="&'01 参数与汇率'!B19,$L$3:$L$1745,">="&B7)/C7) -> 0 | I7: 分位=区间内≤当前汇率的观测占比；越低说明当前外币越便宜 | L7: 43837 | M7: 6.9425
A8: 近 5 年 | B8: 44488 | C8: =COUNTIFS($L$3:$L$1745,">="&B8) -> 0 | D8: =MINIFS($M$3:$M$1745,$L$3:$L$1745,">="&B8) -> 0 | E8: =MAXIFS($M$3:$M$1745,$L$3:$L$1745,">="&B8) -> 0 | F8: =AVERAGEIFS($M$3:$M$1745,$L$3:$L$1745,">="&B8) -> 0 | G8: =IF(C8=0,0,COUNTIFS($M$3:$M$1745,"<="&'01 参数与汇率'!B20,$L$3:$L$1745,">="&B8)/C8) -> 0 | H8: =IF(C8=0,0,COUNTIFS($M$3:$M$1745,"<="&'01 参数与汇率'!B19,$L$3:$L$1745,">="&B8)/C8) -> 0 | I8: 分位=区间内≤当前汇率的观测占比；越低说明当前外币越便宜 | L8: 43838 | M8: 6.9441
A9: 全部样本 | B9: 2019-12-31 | C9: =COUNT($M$3:$M$1745) -> 0 | D9: =MIN($M$3:$M$1745) -> 0 | E9: =MAX($M$3:$M$1745) -> 0 | F9: =AVERAGE($M$3:$M$1745) -> 0 | G9: =COUNTIFS($M$3:$M$1745,"<="&'01 参数与汇率'!B20)/C9 -> 0 | H9: =COUNTIFS($M$3:$M$1745,"<="&'01 参数与汇率'!B19)/C9 -> 0 | L9: 43839 | M9: 6.9317
L10: 43840 | M10: 6.9221
A11: 说明：历史分位只描述“当前汇率在这段历史中的相对位置”，不代表未来走势。汇率可能长期停留在历史区间之外，分位低不等于汇率必然回升，分位高也不等于必然回落。 | L11: 43843 | M11: 6.8935
L12: 43844 | M12: 6.8858
L13: 43845 | M13: 6.888
L14: 43846 | M14: 6.8795
L15: 43847 | M15: 6.8587
L16: 43850 | M16: 6.8662
L17: 43851 | M17: 6.9035
L18: 43852 | M18: 6.9021
L19: 43853 | M19: 6.9333
L20: 43854 | M20: 6.9333
L21: 43857 | M21: 6.9367
L22: 43858 | M22: 6.9367
L23: 43859 | M23: 6.9366
... L1745: 46314 | M1745: 6.6807

Sheet 07 汇率口径与法规
A1: 07 四类汇率口径区分与法规依据
A3: 口径 | B3: 用途 | C3: 定义与特征 | D3: 法规 / 权威依据
A4: 市场汇率 | B4: 观察、比价、参考 | C4: 境外市场即时成交价（如 ECB 每日参考汇率、离岸价）。反映市场供需，但不等于企业结售汇成交价。 | D4: 欧洲央行 Euro foreign exchange reference rates
A5: 人民币汇率中间价 | B5: 观察、定价基准 | C5: 人民银行授权中国外汇交易中心每日 9:15 公布，由做市商报价去极值加权平均形成；当日中间价适用于发布后至下一中间价发布前。 | D5: 《中国人民银行关于银行间外汇市场交易汇价和银行挂牌汇价管理有关事项的通知》（2014）；《银行间外汇市场管理规定》（2025年第13号令，2026-02-01 施行）
A6: 银行实际购汇价 | B6: 决定企业真实付款 | C6: 企业进口付汇按银行「现汇卖出价」成交（银行视角的卖出）。银行间即期 CNY/USD 可在中间价上下 2% 内浮动；银行为客户提供的当日美元最高现汇卖出价与最低现汇买入价之差不得超过中间价的 3%。 | D6: 中国人民银行公告〔2014〕第5号；银行挂牌汇价管理规定
A7: 海关计征汇率 | B7: 折算完税价格与计税 | C7: 每月使用的计征汇率为「上一个月第三个星期三」人民银行授权外汇交易中心公布的人民币汇率中间价；该日非交易日的，顺延下一交易日。与计征税额相关的汇率发生重大波动时海关总署可另行规定。 | D7: 《中华人民共和国海关进出口货物征税管理办法》（海关总署令第272号，2024-12-01 施行）第十三条
A9: 计征汇率基准日速查（上月第三个星期三）
A10: 申报月份 | B10: 适用计征汇率基准日 | C10: 说明
A11: 2026-10 | B11: 2026-09-16 | C11: 取 2026-09 第三个星期三中间价
A12: 2026-11 | B12: 2026-10-21 | C12: 取 2026-10 第三个星期三中间价
A13: 2026-12 | B13: 2026-11-18 | C13: 取 2026-11 第三个星期三中间价
A14: 2027-01 | B14: 2026-12-16 | C14: 取 2026-12 第三个星期三中间价
A15: 2027-02 | B15: 2027-01-20 | C15: 取 2027-01 第三个星期三中间价
A16: 2027-03 | B16: 2027-02-17 | C16: 取 2027-02 第三个星期三中间价
A18: 常见错误： ✗ 用市场汇率（ECB/离岸价）直接估算关税与增值税 —— 计税必须用海关计征汇率； ✗ 用中间价估算实际付款 —— 实际付款按银行现汇卖出价，通常高于中间价； ✗ 用当日中间价估算本月进口计税 —— 计征汇率取决于上月第三个星期三。
