Workbook

Sheet 00 封面说明
A1: 重质纯碱 区域价差研究工作簿
A2: 覆盖：山东 / 河北 / 江苏 ｜ 单位：元/吨 ｜ 频率：weekly ｜ 样本：2023-01-06 ~ 2025-12-26（152 期）
A4: 数据状态 | B4: DEMO ← DEMO 拟真数据，非真实报价，不得用于交易或对外引用
A5: 产品 / 规格 | B5: 重质纯碱 ｜ GB/T 210-2022《工业碳酸钠》Ⅱ类优等品，Na₂CO₃ ≥ 99.2%（干基）
A6: 主口径 | B6: 送到价（到厂/到库）：国内纯碱统计规范：轻碱统一采用出厂价，【重碱除西北以外地区采用送到价】。山东、河北、江苏的重碱报价默认即送到价，三地同口径，可直接相减。
A7: 对照口径 | B7: 出厂价（厂提）：对照口径。用于展示『同一批货离开工厂时的价差』，并把运费显性化。山东海化、山东海天、唐山三友、苏盐井神等均为郑商所纯碱交割厂库，厂提价可核。
A8: 减法方向 | B8: 价差 = 价(甲) − 价(乙)；正数表示甲比乙贵。矩阵为「行 − 列」。
A9: 对齐规则 | B9: ISO 周对齐（周五锚）；三地同周均有报价才进入价差样本，缺口剔除、不插值。
A10: 分位算法 | B10: 经验分布 ECDF：(#{x<v} + 0.5·#{x=v}) / N × 100%，不假设正态。
A11: 运费口径 | B11: 综合运费 = 主运费 + 装货费 + 卸货费 + 短驳费 + 其他；任一项未知则总额为空，不按 0 计。
A12: 生成日期 | B12: 2026-10-20
A14: 工作表导览
A15: 01 口径与来源 | B15: 五要素核对：规格/税率/计量/交付/付款 + 来源与口径风险
A16: 02 价格(主口径) | B16: 三地区周度价格（用户输入区，改这里→全表重算）+ 走势图
A17: 03 价格(对照口径) | B17: 出厂价口径价格序列，用于口径对照
A18: 04 价差明细 | B18: 全部有序对价差，原生公式 =B-A
A19: 05 价差矩阵 | B19: 行−列矩阵，含等价校验与颜色刻度
A20: 06 历史分位 | B20: 当前价差在 1 年 / 3 年 / 全样本中的分位（公式实现）
A21: 07 滚动分位 | B21: 滚动 1 年分位曲线数据
A22: 08 运输距离 | B22: 三地公路里程 + 已核实参考点（阿拉善—石家庄 1500km 等）
A23: 09 运费参数 | B23: ★ 运费输入区：真实报价优先；默认参考值可直接改
A24: 10 运费调整 | B24: 按方向计算 综合运费 / 到货成本 / 扣费后参考差异
A25: 11 企业产能 | B25: 企业级可核实产能（省级合计未查到者不给假数）
A26: 12 下游结构 | B26: 全国工艺结构与下游；省级拆分为示意并标注
... A30: 16 计算公式 | B30: 每个单元格公式的含义、Excel 写法、与 Python 的对应关系

Sheet 01 口径与来源
A1: 口径与来源（多地区可比性的第一道关）
A2: 同一张表回答：三地区卖的是不是同一个东西、同一个税基、同一个交货方式、同一个时点。
A3: 地区 | B3: 代表市场 | C3: 报价口径 | D3: 交付方式 | E3: 付款方式 | F3: 税基 | G3: 来源与样本 | H3: 口径风险 | I3: 供需角色
A4: 山东 | B4: 潍坊 | C4: 重碱送到价（含13%增值税、现汇） | D4: DELIVERED | E4: 现汇 | F4: 含13%增值税 | G4: 卓创资讯 / 隆众资讯 华东纯碱日报（潍坊），厂库核对：山东海化、山东海天生物化工 | H4: 潍坊主产区出厂与『送到淄博/潍坊下游』之间存在短途差价；山东口径在部分机构按『潍坊出厂』、部分按『潍坊送到』，切换机构即视为口径断点。山东海化产能存在 280 万吨（上市公司口径）/300 万吨（资讯口径）两个流通值。 | I4: 净调出
A5: 河北 | B5: 沙河 | C5: 重碱送到价（含13%增值税、现汇），以沙河及周边为交割地 | D5: DELIVERED | E5: 现汇 | F5: 含13%增值税 | G5: 隆众资讯《沙河及周边贸易价格行情》（我的钢铁网转载）；厂库核对：唐山三友化工（郑商所指定厂库）、沙玻玻璃物流沙河（指定厂库） | H5: 河北同时存在三种报价：①期现交割库出库价、②送到价、③厂提价（按 SA 合约升贴水报）。2025-06-04 同日实测：交割库出库 1220 元/吨 vs 送到 1270—1320 元/吨，短途物流+装卸溢价 50—100 元/吨。河北的产业角色更偏消费与集散（沙河），而非生产。 | I5: 生产+集散
A6: 江苏 | B6: 连云港 | C6: 重碱送到价（含13%增值税、现汇） | D6: DELIVERED | E6: 现汇 | F6: 含13%增值税 | G6: 卓创资讯 / 隆众资讯 华东纯碱日报（连云港、徐州）；厂库核对：苏盐井神（2024-11 增设纯碱交割厂库）、江苏华昌化工、中盐昆山 | H6: 连云港碱业老厂已于 2021—2022 年间关停（协会 2022-12 分企业产量为 0），新厂 110 万吨联碱于 2025-05-18 投产——江苏供给格局在样本期内发生过置换，必须分段解释。江苏无海港直达山东的水路优势，京杭运河船期受水位影响。 | I6: 净调入
A8: 口径核对清单
A9: 项 | B9: 检查问题 | C9: 状态 | D9: 处理动作
A11: 数据来源
A12: 编号 | B12: 来源 | C12: 日期 | D12: 覆盖内容 | E12: 链接 | F12: 状态
A13: S1 | B13: 期货日报《纯碱的物流仓储与价格政策介绍》 | C13: 43800 | D13: 统计口径（重碱除西北外为送到价）、运费分界线（300 km 汽运/铁运）、水运 30—120 元/吨 | F13: https://finance.sina.cn/futuremarket/qszx/2019-12-01/detail-iihnzahi4623500.d.html?vt=4 | I13: 已核实
A14: S2 | B14: 隆众资讯《沙河及周边贸易价格行情》（我的钢铁网转载） | C14: 45812 | D14: 河北沙河交割库出库价 1220 vs 送到价 1270—1320；各厂提基差 | F14: https://nenghua.m.mysteel.com/a/25060416/98BCA1C064AACE9D_abc.html | I14: 已核实
A15: S3 | B15: 生意社（100ppi）纯碱产业网 / 重质纯碱基准价 | C15: 46022 | D15: 重质纯碱基准价 1225.71 元/吨；华东/华北/华中大区区间价 | F15: https://soda.100ppi.com | I15: 已核实（量级校对）
A16: S4 | B16: 卓创资讯《纯碱：2024年数据盘点及2025年展望》（新浪财经转载） | C16: 45660 | D16: 2024 重碱终端均价 1953（-29.6%）；全国产能 3838 万吨；工艺结构 | F16: https://finance.sina.com.cn/money/future/roll/2025-01-03/doc-inecsvux6433846.shtml | I16: 已核实
A17: S5 | B17: 证券时报《远兴能源：启动阿拉善塔木素天然碱二期》 | C17: 45288 | D17: 一期 500 万吨 2023-06 投产；二期 280 万吨规划 | F17: https://www.stcn.com/article/detail/1077670.html | I17: 已核实
A18: S6 | B18: 连云港市政府《碱业公司搬迁升级改造项目建成投产》 | C18: 45803 | D18: 连云港碱业 110 万吨联碱 2025-05-18 一次开车成功 | F18: http://www.lyg.gov.cn/zglygzfmhwz/gcyw/content/3ad7d8d1-8a2a-4683-82b5-4766ac84985e.html | I18: 已核实
A19: S7 | B19: 中国纯碱工业协会 2022年12月全国纯碱产量（分企业） | C19: 2023 | D19: 连云港当月与累计产量均为 0（老厂关停硬证据） | F19: https://www.chinasoda.com.cn/cn/datainfo.aspx?faid=578&rid=12963 | I19: 已核实
A20: S8 | B20: 七禾网《河北、山东玻璃纯碱调研报告完整版》 | C20: 2024-05 | D20: 沙河月用量约 9 万吨、玻璃厂纯碱库存 15—25 天、阿拉善→石家庄 300 元/1500 km、海运 140—150 元/吨、基差套利阈值约 100 元/吨 | F20: https://www.7hcn.com/article/458274-1.html | I20: 已核实
A21: S9 | B21: 郑商所《纯碱期货业务细则》/ 交割手册 | C21: 45253 | D21: 交割品规格、吨包 1 吨、入库费 25 元/吨（汽车）/30（火车）、仓储 0.5 元/吨·天 | F21: https://np-newsimg.dfcfw.com/download/A2_cms_f_20231123161555494870?direct=1&abc7363.pdf | I21: 已核实
A22: S10 | B22: 东方财富研报《纯碱行业分析框架》 | C22: 2022-05 | D22: 三友化工纯碱 340 万吨（唐山三友 230 + 五彩碱业 110） | F22: https://pdf.dfcfw.com/pdf/H3_AP202205101564746575_1.pdf | I22: 已核实
A23: S11 | B23: 山东海化集团·纯碱厂简介 / 上市公司回应 | C23: 2023-07 | D23: 山东海化 280 万吨（老线 120 + 新线 160） | F23: https://www.haihua.com.cn/About_11/1664471386467147776.html | I23: 已核实
A24: S12 | B24: 国家发改委等《关于深化新能源上网电价市场化改革》（发改价格〔2025〕136号） | C24: 45697 | D24: 2025-06-01 存量/增量分界，Q1 抢装 5971 万千瓦 | F24: https://www.stcn.com/article/detail/1580785.html | I24: 已核实

Sheet 02 价格(主口径)
A1: 三地区周度价格（送到价（到厂/到库））
A2: 送到价（到厂/到库）｜国内纯碱统计规范：轻碱统一采用出厂价，【重碱除西北以外地区采用送到价】。山东、河北、江苏的重碱报价默认即送到价，三地同口径，可直接相减。
A4: 日期 | B4: 山东 | C4: 河北 | D4: 江苏 | E4: 有效地区数 | F4: 备注
A5: 44932 | B5: 2805 | C5: 2740 | D5: 2805 | E5: =COUNT(B5,C5,D5)
A6: 44939 | B6: 2825 | C6: 2765 | D6: 2825 | E6: =COUNT(B6,C6,D6)
A7: 44946 | B7: 2825 | C7: 2770 | D7: 2825 | E7: =COUNT(B7,C7,D7)
A8: 44953 | B8: 2810 | C8: 2755 | D8: 2815 | E8: =COUNT(B8,C8,D8)
A9: 44960 | B9: 2790 | C9: 2735 | D9: 2800 | E9: =COUNT(B9,C9,D9)
A10: 44967 | B10: 2785 | C10: 2720 | D10: 2790 | E10: =COUNT(B10,C10,D10)
A11: 44974 | B11: 2785 | C11: 2720 | D11: 2790 | E11: =COUNT(B11,C11,D11)
A12: 44981 | B12: 2785 | C12: 2715 | D12: 2790 | E12: =COUNT(B12,C12,D12)
A13: 44988 | B13: 2785 | C13: 2725 | D13: 2790 | E13: =COUNT(B13,C13,D13)
A14: 44995 | B14: 2805 | C14: 2740 | D14: 2810 | E14: =COUNT(B14,C14,D14)
A15: 45002 | B15: 2800 | C15: 2740 | D15: 2795 | E15: =COUNT(B15,C15,D15)
A16: 45009 | B16: 2790 | C16: 2730 | D16: 2790 | E16: =COUNT(B16,C16,D16)
... A156: 46017 | B156: 1370 | C156: 1275 | D156: 1385 | E156: =COUNT(B156,C156,D156)
A158: ★ 输入区：直接把真实数据粘贴到 B:E 列即可，全表（价差/分位/图）自动重算。缺失请留空——不要把缺失填 0 或重复上一期值；留空会在价差表里显示为空，这是正确行为。

Sheet 03 价格(对照口径)
A1: 三地区周度价格（出厂价（厂提））
A2: 出厂价（厂提）｜对照口径。用于展示『同一批货离开工厂时的价差』，并把运费显性化。山东海化、山东海天、唐山三友、苏盐井神等均为郑商所纯碱交割厂库，厂提价可核。
A4: 日期 | B4: 山东 | C4: 河北 | D4: 江苏 | E4: 有效地区数 | F4: 备注
A5: 44932 | B5: 2760 | C5: 2670 | D5: 2750 | E5: =COUNT(B5,C5,D5)
A6: 44939 | B6: 2780 | C6: 2695 | D6: 2770 | E6: =COUNT(B6,C6,D6)
A7: 44946 | B7: 2780 | C7: 2700 | D7: 2770 | E7: =COUNT(B7,C7,D7)
A8: 44953 | B8: 2765 | C8: 2685 | D8: 2760 | E8: =COUNT(B8,C8,D8)
A9: 44960 | B9: 2745 | C9: 2665 | D9: 2745 | E9: =COUNT(B9,C9,D9)
A10: 44967 | B10: 2740 | C10: 2650 | D10: 2735 | E10: =COUNT(B10,C10,D10)
A11: 44974 | B11: 2740 | C11: 2650 | D11: 2735 | E11: =COUNT(B11,C11,D11)
A12: 44981 | B12: 2740 | C12: 2645 | D12: 2735 | E12: =COUNT(B12,C12,D12)
A13: 44988 | B13: 2740 | C13: 2655 | D13: 2735 | E13: =COUNT(B13,C13,D13)
A14: 44995 | B14: 2760 | C14: 2670 | D14: 2755 | E14: =COUNT(B14,C14,D14)
A15: 45002 | B15: 2755 | C15: 2665 | D15: 2740 | E15: =COUNT(B15,C15,D15)
A16: 45009 | B16: 2745 | C16: 2655 | D16: 2735 | E16: =COUNT(B16,C16,D16)
... A158: 46017 | B158: 1325 | C158: 1205 | D158: 1330 | E158: =COUNT(B158,C158,D158)
A160: ★ 输入区：直接把真实数据粘贴到 B:E 列即可，全表（价差/分位/图）自动重算。缺失请留空——不要把缺失填 0 或重复上一期值；留空会在价差表里显示为空，这是正确行为。

Sheet 04 价差明细
A1: 两两价差明细（全部有序对，方向明确）
A2: 价差 = 价(甲) − 价(乙)。甲列在前。公式直接引用「02 价格(主口径)」，改价格即重算。
A3: 日期 | B3: 价差(甲−乙) | C3: 甲 | D3: 乙 | E3: 甲价 | F3: 乙价 | G3: 价差 | H3: 方向说明
A4: 山东 − 河北
A5: 日期 | B5: 价差(甲−乙) | C5: 甲 | D5: 乙 | E5: 甲价 | F5: 乙价 | G5: 价差 | H5: 方向说明
A6: ='02 价格(主口径)'!A5 | C6: SD | D6: HB | E6: ='02 价格(主口径)'!B5 | F6: ='02 价格(主口径)'!C5 | G6: =IF(OR(E6="",F6=""),"",E6-F6)
A7: ='02 价格(主口径)'!A6 | C7: SD | D7: HB | E7: ='02 价格(主口径)'!B6 | F7: ='02 价格(主口径)'!C6 | G7: =IF(OR(E7="",F7=""),"",E7-F7)
A8: ='02 价格(主口径)'!A7 | C8: SD | D8: HB | E8: ='02 价格(主口径)'!B7 | F8: ='02 价格(主口径)'!C7 | G8: =IF(OR(E8="",F8=""),"",E8-F8)
A9: ='02 价格(主口径)'!A8 | C9: SD | D9: HB | E9: ='02 价格(主口径)'!B8 | F9: ='02 价格(主口径)'!C8 | G9: =IF(OR(E9="",F9=""),"",E9-F9)
A10: ='02 价格(主口径)'!A9 | C10: SD | D10: HB | E10: ='02 价格(主口径)'!B9 | F10: ='02 价格(主口径)'!C9 | G10: =IF(OR(E10="",F10=""),"",E10-F10)
A11: ='02 价格(主口径)'!A10 | C11: SD | D11: HB | E11: ='02 价格(主口径)'!B10 | F11: ='02 价格(主口径)'!C10 | G11: =IF(OR(E11="",F11=""),"",E11-F11)
A12: ='02 价格(主口径)'!A11 | C12: SD | D12: HB | E12: ='02 价格(主口径)'!B11 | F12: ='02 价格(主口径)'!C11 | G12: =IF(OR(E12="",F12=""),"",E12-F12)
A13: ='02 价格(主口径)'!A12 | C13: SD | D13: HB | E13: ='02 价格(主口径)'!B12 | F13: ='02 价格(主口径)'!C12 | G13: =IF(OR(E13="",F13=""),"",E13-F13)
A14: ='02 价格(主口径)'!A13 | C14: SD | D14: HB | E14: ='02 价格(主口径)'!B13 | F14: ='02 价格(主口径)'!C13 | G14: =IF(OR(E14="",F14=""),"",E14-F14)
A15: ='02 价格(主口径)'!A14 | C15: SD | D15: HB | E15: ='02 价格(主口径)'!B14 | F15: ='02 价格(主口径)'!C14 | G15: =IF(OR(E15="",F15=""),"",E15-F15)
A16: ='02 价格(主口径)'!A15 | C16: SD | D16: HB | E16: ='02 价格(主口径)'!B15 | F16: ='02 价格(主口径)'!C15 | G16: =IF(OR(E16="",F16=""),"",E16-F16)
A17: ='02 价格(主口径)'!A16 | C17: SD | D17: HB | E17: ='02 价格(主口径)'!B16 | F17: ='02 价格(主口径)'!C16 | G17: =IF(OR(E17="",F17=""),"",E17-F17)
... A157: ='02 价格(主口径)'!A156 | C157: SD | D157: HB | E157: ='02 价格(主口径)'!B156 | F157: ='02 价格(主口径)'!C156 | G157: =IF(OR(E157="",F157=""),"",E157-F157)
A158: 统计 | B158: N（有效配对） | E158: =COUNT(G6:G157) | F158: 均值 | G158: =IFERROR(AVERAGE(G6:G157),"") | H158: 价差方向：正值=山东更贵
A159: 校验 | B159: 标准差 | C159: =IFERROR(STDEV(G6:G157),"") | D159: 最小 | E159: =IFERROR(MIN(G6:G157),"") | F159: 最大 | G159: =IFERROR(MAX(G6:G157),"")
A162: 山东 − 江苏
A163: 日期 | B163: 价差(甲−乙) | C163: 甲 | D163: 乙 | E163: 甲价 | F163: 乙价 | G163: 价差 | H163: 方向说明
A164: ='02 价格(主口径)'!A5 | C164: SD | D164: JS | E164: ='02 价格(主口径)'!B5 | F164: ='02 价格(主口径)'!D5 | G164: =IF(OR(E164="",F164=""),"",E164-F164)
A165: ='02 价格(主口径)'!A6 | C165: SD | D165: JS | E165: ='02 价格(主口径)'!B6 | F165: ='02 价格(主口径)'!D6 | G165: =IF(OR(E165="",F165=""),"",E165-F165)
A166: ='02 价格(主口径)'!A7 | C166: SD | D166: JS | E166: ='02 价格(主口径)'!B7 | F166: ='02 价格(主口径)'!D7 | G166: =IF(OR(E166="",F166=""),"",E166-F166)
A167: ='02 价格(主口径)'!A8 | C167: SD | D167: JS | E167: ='02 价格(主口径)'!B8 | F167: ='02 价格(主口径)'!D8 | G167: =IF(OR(E167="",F167=""),"",E167-F167)
A168: ='02 价格(主口径)'!A9 | C168: SD | D168: JS | E168: ='02 价格(主口径)'!B9 | F168: ='02 价格(主口径)'!D9 | G168: =IF(OR(E168="",F168=""),"",E168-F168)
A169: ='02 价格(主口径)'!A10 | C169: SD | D169: JS | E169: ='02 价格(主口径)'!B10 | F169: ='02 价格(主口径)'!D10 | G169: =IF(OR(E169="",F169=""),"",E169-F169)
A170: ='02 价格(主口径)'!A11 | C170: SD | D170: JS | E170: ='02 价格(主口径)'!B11 | F170: ='02 价格(主口径)'!D11 | G170: =IF(OR(E170="",F170=""),"",E170-F170)
A171: ='02 价格(主口径)'!A12 | C171: SD | D171: JS | E171: ='02 价格(主口径)'!B12 | F171: ='02 价格(主口径)'!D12 | G171: =IF(OR(E171="",F171=""),"",E171-F171)
A172: ='02 价格(主口径)'!A13 | C172: SD | D172: JS | E172: ='02 价格(主口径)'!B13 | F172: ='02 价格(主口径)'!D13 | G172: =IF(OR(E172="",F172=""),"",E172-F172)
A173: ='02 价格(主口径)'!A14 | C173: SD | D173: JS | E173: ='02 价格(主口径)'!B14 | F173: ='02 价格(主口径)'!D14 | G173: =IF(OR(E173="",F173=""),"",E173-F173)
A174: ='02 价格(主口径)'!A15 | C174: SD | D174: JS | E174: ='02 价格(主口径)'!B15 | F174: ='02 价格(主口径)'!D15 | G174: =IF(OR(E174="",F174=""),"",E174-F174)
A175: ='02 价格(主口径)'!A16 | C175: SD | D175: JS | E175: ='02 价格(主口径)'!B16 | F175: ='02 价格(主口径)'!D16 | G175: =IF(OR(E175="",F175=""),"",E175-F175)
... A315: ='02 价格(主口径)'!A156 | C315: SD | D315: JS | E315: ='02 价格(主口径)'!B156 | F315: ='02 价格(主口径)'!D156 | G315: =IF(OR(E315="",F315=""),"",E315-F315)
A316: 统计 | B316: N（有效配对） | E316: =COUNT(G164:G315) | F316: 均值 | G316: =IFERROR(AVERAGE(G164:G315),"") | H316: 价差方向：正值=山东更贵
A317: 校验 | B317: 标准差 | C317: =IFERROR(STDEV(G164:G315),"") | D317: 最小 | E317: =IFERROR(MIN(G164:G315),"") | F317: 最大 | G317: =IFERROR(MAX(G164:G315),"")
A320: 河北 − 山东
A321: 日期 | B321: 价差(甲−乙) | C321: 甲 | D321: 乙 | E321: 甲价 | F321: 乙价 | G321: 价差 | H321: 方向说明
A322: ='02 价格(主口径)'!A5 | C322: HB | D322: SD | E322: ='02 价格(主口径)'!C5 | F322: ='02 价格(主口径)'!B5 | G322: =IF(OR(E322="",F322=""),"",E322-F322)
...

Sheet 05 价差矩阵
A1: 价差矩阵（当前，元/吨）
A2: 行 − 列。B4 起为矩阵主体；下方为等价校验（M[i][j] = −M[j][i]）。
A3: 行 − 列 ↓ / 列 → | B3: 山东 | C3: 河北 | D3: 江苏
A4: 山东 | B4: 0 | C4: =IFERROR('02 价格(主口径)'!B156-'02 价格(主口径)'!C156,"") | D4: =IFERROR('02 价格(主口径)'!B156-'02 价格(主口径)'!D156,"")
A5: 河北 | B5: =IFERROR('02 价格(主口径)'!C156-'02 价格(主口径)'!B156,"") | C5: 0 | D5: =IFERROR('02 价格(主口径)'!C156-'02 价格(主口径)'!D156,"")
A6: 江苏 | B6: =IFERROR('02 价格(主口径)'!D156-'02 价格(主口径)'!B156,"") | C6: =IFERROR('02 价格(主口径)'!D156-'02 价格(主口径)'!C156,"") | D6: 0
A8: 等价校验
A9: SD−HB | B9: =C4 | C9: HB−SD | D9: =B5 | E9: =IF(ABS(B9+D9)<0.001,"✓ 互为相反数","✗ 异常")
A10: SD−JS | B10: =D4 | C10: JS−SD | D10: =B6 | E10: =IF(ABS(B10+D10)<0.001,"✓ 互为相反数","✗ 异常")
A11: HB−JS | B11: =D5 | C11: JS−HB | D11: =C6 | E11: =IF(ABS(B11+D11)<0.001,"✓ 互为相反数","✗ 异常")

Sheet 06 历史分位
A1: 当前价差的历史分位（公式实现，与 Python 同口径）
A2: 分位 = (COUNTIF(<当前值) + 0.5×COUNTIF(=当前值)) / COUNT × 100%。窗口按自然日回溯 365 / 1095 天。
A3: 价差(甲−乙) | B3: 甲 | C3: 乙 | D3: 当前值 | E3: 1y 分位 | F3: 1y N | G3: 3y 分位 | H3: 3y N | I3: 全样本分位 | J3: 位置判断
A4: 山东 − 河北 | B4: SD | C4: HB | D4: =LOOKUP(2,1/('04 价差明细'!$G$6:$G$157<>""),'04 价差明细'!$G$6:$G$157) | E4: =IF(SUMPRODUCT(('04 价差明细'!$A$6:$A$157>'02 价格(主口径)'!$A$156-365)*ISNUMBER('04 价差明细'!$G$6:$G$157))=0,"",(SUMPRODUCT(('04 价差明细'!$A$6:$A$157>'02 价格(主口径)'!$A$156-365)*ISNUMBER('04 价差明细'!$G$6:$G$157)*('04 价差明细'!$G$6:$G$157<D4))+0.5*SUMPRODUCT(('04 价差明细'!$A$6:$A$157>'02 价格(主口径)'!$A$156-365)*ISNUMBER('04 价差明细'!$G$6:$G$157)*('04 价差明细'!$G$6:$G$157=D4)))/SUMPRODUCT(('04 价差明细'!$A$6:$A$157>'02 价格(主口径)'!$A$156-365)*ISNUMBER('04 价差明细'!$G$6:$G$157))*100) | F4: =SUMPRODUCT(('04 价差明细'!$A$6:$A$157>'02 价格(主口径)'!$A$156-365)*ISNUMBER('04 价差明细'!$G$6:$G$157)) | G4: =IF(SUMPRODUCT(('04 价差明细'!$A$6:$A$157>'02 价格(主口径)'!$A$156-1095)*ISNUMBER('04 价差明细'!$G$6:$G$157))=0,"",(SUMPRODUCT(('04 价差明细'!$A$6:$A$157>'02 价格(主口径)'!$A$156-1095)*ISNUMBER('04 价差明细'!$G$6:$G$157)*('04 价差明细'!$G$6:$G$157<D4))+0.5*SUMPRODUCT(('04 价差明细'!$A$6:$A$157>'02 价格(主口径)'!$A$156-1095)*ISNUMBER('04 价差明细'!$G$6:$G$157)*('04 价差明细'!$G$6:$G$157=D4)))/SUMPRODUCT(('04 价差明细'!$A$6:$A$157>'02 价格(主口径)'!$A$156-1095)*ISNUMBER('04 价差明细'!$G$6:$G$157))*100) | H4: =SUMPRODUCT(('04 价差明细'!$A$6:$A$157>'02 价格(主口径)'!$A$156-1095)*ISNUMBER('04 价差明细'!$G$6:$G$157)) | I4: =IF(COUNT('04 价差明细'!$G$6:$G$157)=0,"",(COUNTIF('04 价差明细'!$G$6:$G$157,"<"&D4)+0.5*COUNTIF('04 价差明细'!$G$6:$G$157,D4))/COUNT('04 价差明细'!$G$6:$G$157)*100) | J4: =IF(E4="","样本不足",IF(E4>=90,"历史高位(≥P90)",IF(E4>=75,"偏高(P75-P90)",IF(E4>25,"中枢区间(P25-P75)",IF(E4>10,"偏低(P10-P25)","历史低位(≤P10)")))))
A5: 山东 − 江苏 | B5: SD | C5: JS | D5: =LOOKUP(2,1/('04 价差明细'!$G$164:$G$315<>""),'04 价差明细'!$G$164:$G$315) | E5: =IF(SUMPRODUCT(('04 价差明细'!$A$164:$A$315>'02 价格(主口径)'!$A$156-365)*ISNUMBER('04 价差明细'!$G$164:$G$315))=0,"",(SUMPRODUCT(('04 价差明细'!$A$164:$A$315>'02 价格(主口径)'!$A$156-365)*ISNUMBER('04 价差明细'!$G$164:$G$315)*('04 价差明细'!$G$164:$G$315<D5))+0.5*SUMPRODUCT(('04 价差明细'!$A$164:$A$315>'02 价格(主口径)'!$A$156-365)*ISNUMBER('04 价差明细'!$G$164:$G$315)*('04 价差明细'!$G$164:$G$315=D5)))/SUMPRODUCT(('04 价差明细'!$A$164:$A$315>'02 价格(主口径)'!$A$156-365)*ISNUMBER('04 价差明细'!$G$164:$G$315))*100) | F5: =SUMPRODUCT(('04 价差明细'!$A$164:$A$315>'02 价格(主口径)'!$A$156-365)*ISNUMBER('04 价差明细'!$G$164:$G$315)) | G5: =IF(SUMPRODUCT(('04 价差明细'!$A$164:$A$315>'02 价格(主口径)'!$A$156-1095)*ISNUMBER('04 价差明细'!$G$164:$G$315))=0,"",(SUMPRODUCT(('04 价差明细'!$A$164:$A$315>'02 价格(主口径)'!$A$156-1095)*ISNUMBER('04 价差明细'!$G$164:$G$315)*('04 价差明细'!$G$164:$G$315<D5))+0.5*SUMPRODUCT(('04 价差明细'!$A$164:$A$315>'02 价格(主口径)'!$A$156-1095)*ISNUMBER('04 价差明细'!$G$164:$G$315)*('04 价差明细'!$G$164:$G$315=D5)))/SUMPRODUCT(('04 价差明细'!$A$164:$A$315>'02 价格(主口径)'!$A$156-1095)*ISNUMBER('04 价差明细'!$G$164:$G$315))*100) | H5: =SUMPRODUCT(('04 价差明细'!$A$164:$A$315>'02 价格(主口径)'!$A$156-1095)*ISNUMBER('04 价差明细'!$G$164:$G$315)) | I5: =IF(COUNT('04 价差明细'!$G$164:$G$315)=0,"",(COUNTIF('04 价差明细'!$G$164:$G$315,"<"&D5)+0.5*COUNTIF('04 价差明细'!$G$164:$G$315,D5))/COUNT('04 价差明细'!$G$164:$G$315)*100) | J5: =IF(E5="","样本不足",IF(E5>=90,"历史高位(≥P90)",IF(E5>=75,"偏高(P75-P90)",IF(E5>25,"中枢区间(P25-P75)",IF(E5>10,"偏低(P10-P25)","历史低位(≤P10)")))))
A6: 河北 − 山东 | B6: HB | C6: SD | D6: =LOOKUP(2,1/('04 价差明细'!$G$322:$G$473<>""),'04 价差明细'!$G$322:$G$473) | E6: =IF(SUMPRODUCT(('04 价差明细'!$A$322:$A$473>'02 价格(主口径)'!$A$156-365)*ISNUMBER('04 价差明细'!$G$322:$G$473))=0,"",(SUMPRODUCT(('04 价差明细'!$A$322:$A$473>'02 价格(主口径)'!$A$156-365)*ISNUMBER('04 价差明细'!$G$322:$G$473)*('04 价差明细'!$G$322:$G$473<D6))+0.5*SUMPRODUCT(('04 价差明细'!$A$322:$A$473>'02 价格(主口径)'!$A$156-365)*ISNUMBER('04 价差明细'!$G$322:$G$473)*('04 价差明细'!$G$322:$G$473=D6)))/SUMPRODUCT(('04 价差明细'!$A$322:$A$473>'02 价格(主口径)'!$A$156-365)*ISNUMBER('04 价差明细'!$G$322:$G$473))*100) | F6: =SUMPRODUCT(('04 价差明细'!$A$322:$A$473>'02 价格(主口径)'!$A$156-365)*ISNUMBER('04 价差明细'!$G$322:$G$473)) | G6: =IF(SUMPRODUCT(('04 价差明细'!$A$322:$A$473>'02 价格(主口径)'!$A$156-1095)*ISNUMBER('04 价差明细'!$G$322:$G$473))=0,"",(SUMPRODUCT(('04 价差明细'!$A$322:$A$473>'02 价格(主口径)'!$A$156-1095)*ISNUMBER('04 价差明细'!$G$322:$G$473)*('04 价差明细'!$G$322:$G$473<D6))+0.5*SUMPRODUCT(('04 价差明细'!$A$322:$A$473>'02 价格(主口径)'!$A$156-1095)*ISNUMBER('04 价差明细'!$G$322:$G$473)*('04 价差明细'!$G$322:$G$473=D6)))/SUMPRODUCT(('04 价差明细'!$A$322:$A$473>'02 价格(主口径)'!$A$156-1095)*ISNUMBER('04 价差明细'!$G$322:$G$473))*100) | H6: =SUMPRODUCT(('04 价差明细'!$A$322:$A$473>'02 价格(主口径)'!$A$156-1095)*ISNUMBER('04 价差明细'!$G$322:$G$473)) | I6: =IF(COUNT('04 价差明细'!$G$322:$G$473)=0,"",(COUNTIF('04 价差明细'!$G$322:$G$473,"<"&D6)+0.5*COUNTIF('04 价差明细'!$G$322:$G$473,D6))/COUNT('04 价差明细'!$G$322:$G$473)*100) | J6: =IF(E6="","样本不足",IF(E6>=90,"历史高位(≥P90)",IF(E6>=75,"偏高(P75-P90)",IF(E6>25,"中枢区间(P25-P75)",IF(E6>10,"偏低(P10-P25)","历史低位(≤P10)")))))
A7: 河北 − 江苏 | B7: HB | C7: JS | D7: =LOOKUP(2,1/('04 价差明细'!$G$480:$G$631<>""),'04 价差明细'!$G$480:$G$631) | E7: =IF(SUMPRODUCT(('04 价差明细'!$A$480:$A$631>'02 价格(主口径)'!$A$156-365)*ISNUMBER('04 价差明细'!$G$480:$G$631))=0,"",(SUMPRODUCT(('04 价差明细'!$A$480:$A$631>'02 价格(主口径)'!$A$156-365)*ISNUMBER('04 价差明细'!$G$480:$G$631)*('04 价差明细'!$G$480:$G$631<D7))+0.5*SUMPRODUCT(('04 价差明细'!$A$480:$A$631>'02 价格(主口径)'!$A$156-365)*ISNUMBER('04 价差明细'!$G$480:$G$631)*('04 价差明细'!$G$480:$G$631=D7)))/SUMPRODUCT(('04 价差明细'!$A$480:$A$631>'02 价格(主口径)'!$A$156-365)*ISNUMBER('04 价差明细'!$G$480:$G$631))*100) | F7: =SUMPRODUCT(('04 价差明细'!$A$480:$A$631>'02 价格(主口径)'!$A$156-365)*ISNUMBER('04 价差明细'!$G$480:$G$631)) | G7: =IF(SUMPRODUCT(('04 价差明细'!$A$480:$A$631>'02 价格(主口径)'!$A$156-1095)*ISNUMBER('04 价差明细'!$G$480:$G$631))=0,"",(SUMPRODUCT(('04 价差明细'!$A$480:$A$631>'02 价格(主口径)'!$A$156-1095)*ISNUMBER('04 价差明细'!$G$480:$G$631)*('04 价差明细'!$G$480:$G$631<D7))+0.5*SUMPRODUCT(('04 价差明细'!$A$480:$A$631>'02 价格(主口径)'!$A$156-1095)*ISNUMBER('04 价差明细'!$G$480:$G$631)*('04 价差明细'!$G$480:$G$631=D7)))/SUMPRODUCT(('04 价差明细'!$A$480:$A$631>'02 价格(主口径)'!$A$156-1095)*ISNUMBER('04 价差明细'!$G$480:$G$631))*100) | H7: =SUMPRODUCT(('04 价差明细'!$A$480:$A$631>'02 价格(主口径)'!$A$156-1095)*ISNUMBER('04 价差明细'!$G$480:$G$631)) | I7: =IF(COUNT('04 价差明细'!$G$480:$G$631)=0,"",(COUNTIF('04 价差明细'!$G$480:$G$631,"<"&D7)+0.5*COUNTIF('04 价差明细'!$G$480:$G$631,D7))/COUNT('04 价差明细'!$G$480:$G$631)*100) | J7: =IF(E7="","样本不足",IF(E7>=90,"历史高位(≥P90)",IF(E7>=75,"偏高(P75-P90)",IF(E7>25,"中枢区间(P25-P75)",IF(E7>10,"偏低(P10-P25)","历史低位(≤P10)")))))
A8: 江苏 − 山东 | B8: JS | C8: SD | D8: =LOOKUP(2,1/('04 价差明细'!$G$638:$G$789<>""),'04 价差明细'!$G$638:$G$789) | E8: =IF(SUMPRODUCT(('04 价差明细'!$A$638:$A$789>'02 价格(主口径)'!$A$156-365)*ISNUMBER('04 价差明细'!$G$638:$G$789))=0,"",(SUMPRODUCT(('04 价差明细'!$A$638:$A$789>'02 价格(主口径)'!$A$156-365)*ISNUMBER('04 价差明细'!$G$638:$G$789)*('04 价差明细'!$G$638:$G$789<D8))+0.5*SUMPRODUCT(('04 价差明细'!$A$638:$A$789>'02 价格(主口径)'!$A$156-365)*ISNUMBER('04 价差明细'!$G$638:$G$789)*('04 价差明细'!$G$638:$G$789=D8)))/SUMPRODUCT(('04 价差明细'!$A$638:$A$789>'02 价格(主口径)'!$A$156-365)*ISNUMBER('04 价差明细'!$G$638:$G$789))*100) | F8: =SUMPRODUCT(('04 价差明细'!$A$638:$A$789>'02 价格(主口径)'!$A$156-365)*ISNUMBER('04 价差明细'!$G$638:$G$789)) | G8: =IF(SUMPRODUCT(('04 价差明细'!$A$638:$A$789>'02 价格(主口径)'!$A$156-1095)*ISNUMBER('04 价差明细'!$G$638:$G$789))=0,"",(SUMPRODUCT(('04 价差明细'!$A$638:$A$789>'02 价格(主口径)'!$A$156-1095)*ISNUMBER('04 价差明细'!$G$638:$G$789)*('04 价差明细'!$G$638:$G$789<D8))+0.5*SUMPRODUCT(('04 价差明细'!$A$638:$A$789>'02 价格(主口径)'!$A$156-1095)*ISNUMBER('04 价差明细'!$G$638:$G$789)*('04 价差明细'!$G$638:$G$789=D8)))/SUMPRODUCT(('04 价差明细'!$A$638:$A$789>'02 价格(主口径)'!$A$156-1095)*ISNUMBER('04 价差明细'!$G$638:$G$789))*100) | H8: =SUMPRODUCT(('04 价差明细'!$A$638:$A$789>'02 价格(主口径)'!$A$156-1095)*ISNUMBER('04 价差明细'!$G$638:$G$789)) | I8: =IF(COUNT('04 价差明细'!$G$638:$G$789)=0,"",(COUNTIF('04 价差明细'!$G$638:$G$789,"<"&D8)+0.5*COUNTIF('04 价差明细'!$G$638:$G$789,D8))/COUNT('04 价差明细'!$G$638:$G$789)*100) | J8: =IF(E8="","样本不足",IF(E8>=90,"历史高位(≥P90)",IF(E8>=75,"偏高(P75-P90)",IF(E8>25,"中枢区间(P25-P75)",IF(E8>10,"偏低(P10-P25)","历史低位(≤P10)")))))
A9: 江苏 − 河北 | B9: JS | C9: HB | D9: =LOOKUP(2,1/('04 价差明细'!$G$796:$G$947<>""),'04 价差明细'!$G$796:$G$947) | E9: =IF(SUMPRODUCT(('04 价差明细'!$A$796:$A$947>'02 价格(主口径)'!$A$156-365)*ISNUMBER('04 价差明细'!$G$796:$G$947))=0,"",(SUMPRODUCT(('04 价差明细'!$A$796:$A$947>'02 价格(主口径)'!$A$156-365)*ISNUMBER('04 价差明细'!$G$796:$G$947)*('04 价差明细'!$G$796:$G$947<D9))+0.5*SUMPRODUCT(('04 价差明细'!$A$796:$A$947>'02 价格(主口径)'!$A$156-365)*ISNUMBER('04 价差明细'!$G$796:$G$947)*('04 价差明细'!$G$796:$G$947=D9)))/SUMPRODUCT(('04 价差明细'!$A$796:$A$947>'02 价格(主口径)'!$A$156-365)*ISNUMBER('04 价差明细'!$G$796:$G$947))*100) | F9: =SUMPRODUCT(('04 价差明细'!$A$796:$A$947>'02 价格(主口径)'!$A$156-365)*ISNUMBER('04 价差明细'!$G$796:$G$947)) | G9: =IF(SUMPRODUCT(('04 价差明细'!$A$796:$A$947>'02 价格(主口径)'!$A$156-1095)*ISNUMBER('04 价差明细'!$G$796:$G$947))=0,"",(SUMPRODUCT(('04 价差明细'!$A$796:$A$947>'02 价格(主口径)'!$A$156-1095)*ISNUMBER('04 价差明细'!$G$796:$G$947)*('04 价差明细'!$G$796:$G$947<D9))+0.5*SUMPRODUCT(('04 价差明细'!$A$796:$A$947>'02 价格(主口径)'!$A$156-1095)*ISNUMBER('04 价差明细'!$G$796:$G$947)*('04 价差明细'!$G$796:$G$947=D9)))/SUMPRODUCT(('04 价差明细'!$A$796:$A$947>'02 价格(主口径)'!$A$156-1095)*ISNUMBER('04 价差明细'!$G$796:$G$947))*100) | H9: =SUMPRODUCT(('04 价差明细'!$A$796:$A$947>'02 价格(主口径)'!$A$156-1095)*ISNUMBER('04 价差明细'!$G$796:$G$947)) | I9: =IF(COUNT('04 价差明细'!$G$796:$G$947)=0,"",(COUNTIF('04 价差明细'!$G$796:$G$947,"<"&D9)+0.5*COUNTIF('04 价差明细'!$G$796:$G$947,D9))/COUNT('04 价差明细'!$G$796:$G$947)*100) | J9: =IF(E9="","样本不足",IF(E9>=90,"历史高位(≥P90)",IF(E9>=75,"偏高(P75-P90)",IF(E9>25,"中枢区间(P25-P75)",IF(E9>10,"偏低(P10-P25)","历史低位(≤P10)")))))
A11: 为什么用 COUNTIF 而不是 PERCENTRANK：PERCENTRANK 对并列值取最小秩，会把「重复报价」系统性地算偏；本表采用中秩（并列各算 0.5），与 Python percentile_of() 完全一致。

Sheet 07 滚动分位
A1: 滚动 1 年分位（每个时点用「过去 1 年」样本计算）
A2: 样本 <30 时不计算（留空），避免用 10 个点算出一个「看起来很确定」的分位。
A3: 日期 | B3: 山东−河北 分位 | C3: 山东−江苏 分位 | D3: 河北−山东 分位
A4: ='02 价格(主口径)'!A5
A5: ='02 价格(主口径)'!A6
A6: ='02 价格(主口径)'!A7
A7: ='02 价格(主口径)'!A8
A8: ='02 价格(主口径)'!A9
A9: ='02 价格(主口径)'!A10
A10: ='02 价格(主口径)'!A11
A11: ='02 价格(主口径)'!A12
A12: ='02 价格(主口径)'!A13
A13: ='02 价格(主口径)'!A14
A14: ='02 价格(主口径)'!A15
A15: ='02 价格(主口径)'!A16
... A32: ='02 价格(主口径)'!A33
A33: ='02 价格(主口径)'!A34 | B33: 1.7 | C33: 65 | D33: 98.3
A34: ='02 价格(主口径)'!A35 | B34: 8.1 | C34: 87.1 | D34: 91.9
A35: ='02 价格(主口径)'!A36 | B35: 3.1 | C35: 96.9 | D35: 96.9
A36: ='02 价格(主口径)'!A37 | B36: 1.5 | C36: 83.3 | D36: 98.5
A37: ='02 价格(主口径)'!A38 | B37: 2.9 | C37: 98.5 | D37: 97.1
A38: ='02 价格(主口径)'!A39 | B38: 4.3 | C38: 98.6 | D38: 95.7
A39: ='02 价格(主口径)'!A40 | B39: 12.5 | C39: 98.6 | D39: 87.5
A40: ='02 价格(主口径)'!A41 | B40: 9.5 | C40: 97.3 | D40: 90.5
A41: ='02 价格(主口径)'!A42 | B41: 10.5 | C41: 89.5 | D41: 89.5
A42: ='02 价格(主口径)'!A43 | B42: 11.5 | C42: 83.3 | D42: 88.5
A43: ='02 价格(主口径)'!A44 | B43: 27.5 | C43: 82.5 | D43: 72.5
A44: ='02 价格(主口径)'!A45 | B44: 53.7 | C44: 81.7 | D44: 46.3
... A155: ='02 价格(主口径)'!A156 | B155: 91.3 | C155: 33.7 | D155: 8.7
A157: 本表为 Python 预计算值写入（滚动窗口公式在 Excel 中会非常重，故不逐格展开公式）；如需在 Excel 内重算，请用 06 表的分位公式 + 自建日期窗口。

Sheet 08 运输距离
A1: 地区间运输距离与可用方式
A2: 距离直接影响运费；标「估算」的必须用高德/百度地图 API 实测后替换。
A3: 方向 | B3: 起点 | C3: 终点 | D3: 典型里程 km | E3: 里程区间 | F3: 可信度 | G3: 主路线 | H3: 运费(默认,元/吨) | I3: 可用方式
A4: 山东 → 河北 | B4: SD | C4: HB | D4: 620 | E4: 600–650 | F4: 估算 | G4: 潍坊—淄博—沧州—唐山（G18/G25） | H4: 96 | I4: 公路汽运(620km,1天)；公路汽运（至沙河）(620km,1天)；铁路（集装箱/敞车）(720km,2天)；海运（潍坊港—天津/唐山）(380km,3天)
A5: 河北 → 山东 | B5: HB | C5: SD | D5: 620 | E5: 600–650 | F5: 估算 | G5: 唐山—沧州—淄博—潍坊（G25/G18） | H5: 100 | I5: 公路汽运(620km,1天)；铁路(720km,2天)
A6: 山东 → 江苏 | B6: SD | C6: JS | D6: 325 | E6: 300–350 | F6: 估算 | G6: 潍坊—日照—连云港（G15 沈海高速） | H6: 65 | I6: 公路汽运(325km,1天)；内河（京杭运河）(400km,3天)；海运(300km,3天)
A7: 江苏 → 山东 | B7: JS | C7: SD | D7: 325 | E7: 300–350 | F7: 估算 | G7: 连云港—日照—潍坊（G15） | H7: 68 | I7: 公路汽运(325km,1天)；内河(420km,3天)
A8: 河北 → 江苏 | B8: HB | C8: JS | D8: 825 | E8: 800–850 | F8: 估算 | G8: 唐山—天津—德州—徐州—连云港（G25/G3/G15） | H8: 150 | I8: 公路汽运(825km,2天)；铁路 + 公路短驳(840km,3天)；海运(700km,3天)
A9: 江苏 → 河北 | B9: JS | C9: HB | D9: 825 | E9: 800–850 | F9: 估算 | G9: 连云港—徐州—德州—天津—唐山 | H9: 158 | I9: 公路汽运(825km,2天)；铁路 + 公路短驳(840km,3天)
A11: 已核实参考点
A12: 起点 | B12: 终点 | C12: 里程 km | D12: 可信度 | E12: 运价说明
A13: 阿拉善 | B13: 石家庄 | C13: 1500 | D13: 已核实 | E13: 汽运 300 元/吨（34 吨/车，约 10200 元/车）；火车约 270 元/吨
A14: 沙河 | B14: 石家庄 | C14: 130 | D14: 已核实 | E14: —
A15: 潍坊港 | B15: 广东/广西 | D15: 已核实（运价） | E15: 海运 140—150 元/吨，最贵 200 元/吨
A17: 纯碱运输一般以 300 公里为界：300 公里以内以汽运为主，300 公里以外以铁运为主；水运成本最低（30—120 元/吨），铁路次之，汽运最高。来源：期货日报 2019-12-01。 已核实反推：阿拉善→石家庄汽运 300 元 / 1500 km ≈ 0.20 元/吨·公里。行业经验区间 0.2—0.4 元/吨·公里（经验值，非纯碱专属权威报价）。

Sheet 09 运费参数
A1: 运费参数与主运费（★ 输入区）
A2: 蓝色字=可编辑输入。未提供真实运费时保持默认参考值，且所有结论只作敏感性参考。
A3: A. 承运构成参数（元/吨）
A4: 装货费 loading_fee | B4: 8 | C4: 装车/装车设备费；可由卖方或买方承担，按合同
A5: 卸货费 unloading_fee | B5: 10 | C5: 卸车费；由收货方承担时置 0
A6: 短驳费 short_haul | B6: 0 | C6: 厂区/站台到码头或仓库的短倒运费（元/吨）
A7: 其他/代理 handler | B7: 2 | C7: 过磅、代理、单证等杂费
A8: 综合运费（公式）
A10: B. 各路线的运费（真实报价优先）
A11: 路线 | B11: 方向 | C11: 主运费 元/吨 | D11: 来源类型 | E11: 依据 | F11: 备选:公路 | G11: 备选:铁路 | H11: 备选:内河/海运 | I11: 备注
A12: SD-HB | B12: 山东 → 河北 | C12: 96 | D12: 默认参考 | E12: 0.20 元/吨·公里（已核实反推值）× 620 km − 整车批量折让 | F12: 96 | G12: 88 | I12: 铁路:88.0
A13: HB-SD | B13: 河北 → 山东 | C13: 100 | D13: 默认参考 | E13: 0.20 元/吨·公里 × 620 km，回程车偏少无显著折让 | F13: 100 | G13: 90 | I13: 铁路:90.0
A14: SD-JS | B14: 山东 → 江苏 | C14: 65 | D14: 默认参考 | E14: 0.20 元/吨·公里 × 325 km | F14: 65 | H14: 40 | I14: 内河:40.0；海运:45.0
A15: JS-SD | B15: 江苏 → 山东 | C15: 68 | D15: 默认参考 | E15: 0.20 元/吨·公里 × 325 km，回程车折让有限 | F15: 68 | H15: 42 | I15: 内河:42.0
A16: HB-JS | B16: 河北 → 江苏 | C16: 150 | D16: 默认参考 | E16: 0.20 元/吨·公里 × 825 km − 整车批量折让 | F16: 150 | G16: 112 | H16: 95 | I16: 铁路+短驳:112.0；海运:95.0
A17: JS-HB | B17: 江苏 → 河北 | C17: 158 | D17: 默认参考 | E17: 0.20 元/吨·公里 × 825 km，回程车少 | F17: 158 | G17: 118 | I17: 铁路+短驳:118.0
A19: 运价字段分三类：real_quote（用户/委托方提供的真实报价）、default_ref（默认展示用的行业参考值，非真实报价）、not_available（未获得，不得计算）。未提供真实运费时，任何『覆盖运费』的结论只能作为敏感性参考，不得写成套利机会。
A21: 已核实锚点（装卸与仓储）
A22: 郑商所交割库入库费（汽车） | B22: 25 | C22: 元/吨，含卸车+库内运输+倒垛+装车（纯碱）
A23: 郑商所交割库入库费（火车） | B23: 30 | C23: 元/吨
A24: 沙河 交割库出库价 vs 送到价 价差 | B24: 50 | C24: 元/吨（2025-06-04 同日，区间 50–100），可作短途综合溢价锚
A25: 仓储费 | B25: 0.5 | C25: 元/吨·天（交割库）

Sheet 10 运费调整
A1: 按运输方向的运费调整（裸价差 / 运输成本 / 扣费后差异 分列）
A2: 参考差异 = 目的地区价 − (产地区价 + 综合运费)。引用「09 运费参数」，改运费即全表重算。
A3: ⚠ 主口径为「送到价」，运费已内含在报价中。本表的「到货成本」仅用于出厂价口径核对与物流可行性，不得再当作可套利空间；不要用整段运费从送到价里重复扣减。
A5: 路线 | B5: 方向 | C5: 里程km | D5: 产地价 | E5: 目的地价 | F5: 裸价差(目的−产地) | G5: 主运费 | H5: 装货费 | I5: 卸货费 | J5: 短驳+其他 | K5: 综合运费 | L5: 到货成本 | M5: 扣费后参考差异 | N5: 判定
A6: SD-HB | B6: 山东 → 河北 | C6: 620 | D6: ='02 价格(主口径)'!B156 | E6: ='02 价格(主口径)'!C156 | F6: =IF(OR(D6="",E6=""),"",E6-D6) | G6: ='09 运费参数'!C12 | H6: ='09 运费参数'!$B$4 | I6: ='09 运费参数'!$B$5 | J6: ='09 运费参数'!$B$6+'09 运费参数'!$B$7 | K6: =IF(G6="","",SUM(G6:J6)) | L6: =IF(K6="","",D6+K6) | M6: =IF(OR(K6="",E6=""),"",E6-L6) | N6: =IF(M6="","运费未知→不计算",IF(M6>0,"价差覆盖运费","未覆盖运费"))
A7: HB-SD | B7: 河北 → 山东 | C7: 620 | D7: ='02 价格(主口径)'!C156 | E7: ='02 价格(主口径)'!B156 | F7: =IF(OR(D7="",E7=""),"",E7-D7) | G7: ='09 运费参数'!C13 | H7: ='09 运费参数'!$B$4 | I7: ='09 运费参数'!$B$5 | J7: ='09 运费参数'!$B$6+'09 运费参数'!$B$7 | K7: =IF(G7="","",SUM(G7:J7)) | L7: =IF(K7="","",D7+K7) | M7: =IF(OR(K7="",E7=""),"",E7-L7) | N7: =IF(M7="","运费未知→不计算",IF(M7>0,"价差覆盖运费","未覆盖运费"))
A8: SD-JS | B8: 山东 → 江苏 | C8: 325 | D8: ='02 价格(主口径)'!B156 | E8: ='02 价格(主口径)'!D156 | F8: =IF(OR(D8="",E8=""),"",E8-D8) | G8: ='09 运费参数'!C14 | H8: ='09 运费参数'!$B$4 | I8: ='09 运费参数'!$B$5 | J8: ='09 运费参数'!$B$6+'09 运费参数'!$B$7 | K8: =IF(G8="","",SUM(G8:J8)) | L8: =IF(K8="","",D8+K8) | M8: =IF(OR(K8="",E8=""),"",E8-L8) | N8: =IF(M8="","运费未知→不计算",IF(M8>0,"价差覆盖运费","未覆盖运费"))
A9: JS-SD | B9: 江苏 → 山东 | C9: 325 | D9: ='02 价格(主口径)'!D156 | E9: ='02 价格(主口径)'!B156 | F9: =IF(OR(D9="",E9=""),"",E9-D9) | G9: ='09 运费参数'!C15 | H9: ='09 运费参数'!$B$4 | I9: ='09 运费参数'!$B$5 | J9: ='09 运费参数'!$B$6+'09 运费参数'!$B$7 | K9: =IF(G9="","",SUM(G9:J9)) | L9: =IF(K9="","",D9+K9) | M9: =IF(OR(K9="",E9=""),"",E9-L9) | N9: =IF(M9="","运费未知→不计算",IF(M9>0,"价差覆盖运费","未覆盖运费"))
A10: HB-JS | B10: 河北 → 江苏 | C10: 825 | D10: ='02 价格(主口径)'!C156 | E10: ='02 价格(主口径)'!D156 | F10: =IF(OR(D10="",E10=""),"",E10-D10) | G10: ='09 运费参数'!C16 | H10: ='09 运费参数'!$B$4 | I10: ='09 运费参数'!$B$5 | J10: ='09 运费参数'!$B$6+'09 运费参数'!$B$7 | K10: =IF(G10="","",SUM(G10:J10)) | L10: =IF(K10="","",D10+K10) | M10: =IF(OR(K10="",E10=""),"",E10-L10) | N10: =IF(M10="","运费未知→不计算",IF(M10>0,"价差覆盖运费","未覆盖运费"))
A11: JS-HB | B11: 江苏 → 河北 | C11: 825 | D11: ='02 价格(主口径)'!D156 | E11: ='02 价格(主口径)'!C156 | F11: =IF(OR(D11="",E11=""),"",E11-D11) | G11: ='09 运费参数'!C17 | H11: ='09 运费参数'!$B$4 | I11: ='09 运费参数'!$B$5 | J11: ='09 运费参数'!$B$6+'09 运费参数'!$B$7 | K11: =IF(G11="","",SUM(G11:J11)) | L11: =IF(K11="","",D11+K11) | M11: =IF(OR(K11="",E11=""),"",E11-L11) | N11: =IF(M11="","运费未知→不计算",IF(M11>0,"价差覆盖运费","未覆盖运费"))
A13: 「价差覆盖运费」只表示目的地区价格高于产地价+承运成本；未计入资金占用与利息、运输损耗、账期与承兑贴息、卸货地短驳、仓储、开票与结算风险、可成交批量。不能据此认定套利机会。
A16: 情形对照（把「价差覆盖运费」之外的隐性成本也列出来）
A17: 项目 | B17: 方向 A | C17: 方向 B | D17: 说明
A18: 裸价差（目的−产地） | B18: =F6 | C18: =F7 | D18: 与价差矩阵同向；尚未扣任何费用
A19: − 综合运费 | B19: =-K6 | C19: =-K7 | D19: 主运费+装货+卸货+短驳+其他
A20: '= 扣费后参考差异 | B20: =M6 | C20: =M7 | D20: 仅代表价差是否覆盖承运成本
A21: − 资金占用（未计入） | B21: 未计入 | C21: 未计入 | D21: 吨价×账期天数×资金成本率/365；需用户给账期与利率
A22: − 运输损耗（未计入） | B22: 未计入 | C22: 未计入 | D22: 纯碱吨包/散装公路损耗通常极低，但需以实测为准
A23: − 承兑贴息（未计入） | B23: 未计入 | C23: 未计入 | D23: 现汇−承兑价差属于公开源【未查到】项，不给假设值
A24: − 卸货地短驳（未计入） | B24: 未计入 | C24: 未计入 | D24: 目的地到厂/到库的最后一段
A25: '= 全部成本后净差 | B25: 需用户补参数 | C25: 需用户补参数 | D25: 本 Skill 只做到「扣运费」，不替代完整经济性核算

Sheet 11 企业产能
A1: 生产企业与产能（企业级可核实）
A2: 省级产能合计若未查到权威发布，则不给估算数——宁缺不假。
A3: 地区 | B3: 企业 | C3: 代码 | D3: 所在地 | E3: 产能(万吨/年) | F3: 工艺 | G3: 说明 | H3: 核实
A4: 山东 | B4: 山东海化 | C4: 000822 | D4: 潍坊（滨海/寿光） | E4: 280 | F4: 氨碱法 | G4: 郑商所纯碱指定交割厂库；正推进氨碱改联碱技改（投资 48.37 亿元） | H4: ✓
A5: 山东 | B5: 山东海天生物化工 | D5: 潍坊（昌邑） | E5: 150 | F5: 氨碱法 | G5: 金晶集团旗下；重质占比约 80%（低盐重碱 40 + 普通重碱 40 + 轻碱 20 起步）；郑商所指定交割厂库 | H5: ✓
A6: 山东 | B6: 山东 可核实产能小计 | E6: =SUM(E4:E5) | G6: 省级合计【未查到】权威发布数。企业级可核实：山东海化 280 万吨（氨碱，潍坊滨海/寿光，老线 120 + 新线 160；资讯另有 300 万吨口径）+ 山东海天生物化工 150 万吨（氨碱，潍坊昌邑，重质占比约 80%）= 至少 430 万吨可核实。
A7: 河北 | B7: 唐山三友化工 | C7: 600409 | D7: 唐山南堡 | E7: 230 | F7: 氨碱法 | G7: 郑商所纯碱指定交割厂库；轻重碱比例约 3:7（重碱约 70%） | H7: ✓
A8: 河北 | B8: 五彩碱业（三友系） | D8: 河北 | E8: 110 | F8: 氨碱法 | G8: 纳入三友集团 340 万吨口径；单独统计时不计入唐山三友 230 万吨 | H8: ✓
A9: 河北 | B9: 沙玻玻璃物流沙河 | D9: 邢台沙河 | F9: — | G9: 郑商所纯碱指定交割厂库（无生产产能，属物流/交割设施） | H9: ✓
A10: 河北 | B10: 河北 可核实产能小计 | E10: =SUM(E7:E9) | G10: 省级合计【未查到】。可核实：唐山三友化工系 340 万吨（= 唐山三友 230 + 五彩碱业 110，氨碱）；资讯另按『唐山三友 230 万吨装置』单独表述。河北更偏消费与集散（沙河），而非生产。
A11: 江苏 | B11: 连云港碱业（新厂） | D11: 连云港灌云燕尾港 | E11: 110 | F11: 联碱法（新）／氨碱法（老厂已停） | G11: 投资 58.28 亿元，2025-05-18 一次开车成功；80 万吨重碱 + 30 万吨轻灰 | H11: ✓
A12: 江苏 | B12: 江苏华昌化工 | C12: 002274 | D12: 张家港 | E12: 70 | F12: 联碱法 | G12: 2025 年 5 月有检修计划 | H12: ✓
A13: 江苏 | B13: 实联化工 | D13: 江苏 | E13: 120 | F13: 联碱法 | G13: 2022 年产量 93.44 万吨 | H13: ✓
A14: 江苏 | B14: 中盐昆山 | D14: 苏州昆山 | E14: 80 | F14: 联碱法 | G14: ⚠️ 位于江苏昆山，不属山东 | H14: ✓
A15: 江苏 | B15: 苏盐井神（江苏井神） | D15: 淮安 | E15: 70 | F15: 联碱法 | G15: 2024-11 被郑商所增设为首批新一批纯碱交割厂库 | H15: ✓
A16: 江苏 | B16: 江苏德邦 | D16: 江苏 | E16: 60 | F16: 联碱法 | G16: 搬迁项目 2025-02 出货 | H16: ✓
A17: 江苏 | B17: 徐州丰成 | D17: 徐州 | E17: 60 | F17: 联碱法 | G17: 2025 年有检修记录 | H17: ✓
A18: 江苏 | B18: 江苏 可核实产能小计 | E18: =SUM(E11:E17) | G18: 省级合计【未查到】权威发布。可核实企业级：实联化工 120、中盐昆山 60—80、江苏华昌 70、江苏井神（苏盐井神）70、江苏德邦 60、徐州丰成 60、连云港碱业 110（2025-05 新厂联碱；老厂氨碱约 130 已于 2021—2022 关停）。
A20: 全国
A21: 2024 年底产能 | B21: 3838 | C21: 2024 年底全国纯碱产能 3838 万吨（较 2023 年 +4.9%，近五年峰值）；另一口径『有效运行产能 3970 万吨（氨碱 1440 / 联碱 1840 / 天然碱 690）』
A22: 2025 年末产能 | B22: 4475 | C22: 2025 年末总产能 4450—4500 万吨（取中值 4475），2025 年新增 550—590 万吨；全年产量 3981 万吨（+3.08%）
A23: 2024 年产量 | B23: 3735 | C23: 同比 +16.2%
A24: CR4 集中度 | B24: 60 | C24: 四家龙头合计份额
A26: 工艺结构与成本梯次
A27: 工艺 | B27: 占比 | C27: 成本区间 | D27: 说明
A28: 联碱法 | B28: 0.452 | C28: 1050—1200 元/吨 | D28: 与氯化铵联动（双吨成本），华北华东集中
A29: 氨碱法 | B29: 0.369 | C29: >1300 元/吨 | D29: 成本对原盐、石灰石、煤/焦敏感；山东、江苏主力
A30: 天然碱法 | B30: 0.169 | C30: <1000 元/吨 | D30: 内蒙为主，外运半径远，压全国边际价
A32: 成本梯次（2025）：天然碱 <1000 < 联碱 1050—1200 < 氨碱 >1300 元/吨。这是区域价差的结构底座：山东以氨碱为主、河北以氨碱（三友）为主、江苏联碱占比高且 2025 年新增联碱。

Sheet 12 下游结构
A1: 下游需求结构
A2: 全国口径为已核实数据；省级拆分为结构性示意，逐行标注——不要把示意当统计。
A3: 地区 | B3: 行业 | C3: 占比 | D3: 数据性质 | E3: 说明
A4: 山东 | B4: 玻璃（浮法/深加工） | C4: 0.43 | D4: 示意 | E4: 全国口径参考
A5: 山东 | B5: 光伏玻璃 | C5: 0.17 | D5: 示意 | E5: 全国口径参考
A6: 山东 | B6: 日用玻璃 | C6: 0.13 | D6: 示意 | E6: 全国口径参考
A7: 山东 | B7: 小苏打 / 泡花碱 | C7: 0.12 | D7: 示意
A8: 山东 | B8: 其他（洗涤剂、无机盐、出口） | C8: 0.15 | D8: 示意
A9: 山东 | B9: 合计 | C9: =SUM(C4:C8) | E9: 以上为全国结构口径（2023：玻璃合计 73%，其中平板 43%、光伏 17%、日用 13%）。山东省级下游拆分【未查到】独立量化数据——不出省级假数。
A11: 河北 | B11: 浮法玻璃（沙河集群） | C11: 0.45 | D11: 示意 | E11: 沙河月用纯碱约 9 万吨（年约 108 万吨，推算）
A12: 河北 | B12: 深加工/日用玻璃 | C12: 0.2 | D12: 示意
A13: 河北 | B13: 其他（轻工、医药） | C13: 0.35 | D13: 示意
A14: 河北 | B14: 合计 | C14: =SUM(C11:C13) | E14: 河北份额为本 Skill 依据『沙河产能占全国约 10%、月用量 9 万吨』构造的结构性拆分，非统计口径。
A16: 江苏 | B16: 光伏玻璃 | C16: 0.22 | D16: 示意 | E16: 江苏光伏玻璃集聚度较高
A17: 江苏 | B17: 浮法/深加工玻璃 | C17: 0.2 | D17: 示意
A18: 江苏 | B18: 无机盐/精细化工 | C18: 0.28 | D18: 示意
A19: 江苏 | B19: 洗涤剂 | C19: 0.12 | D19: 示意
A20: 江苏 | B20: 其他（出口、医药） | C20: 0.18 | D20: 示意
A21: 江苏 | B21: 合计 | C21: =SUM(C16:C20) | E21: 江苏省级下游拆分【未查到】独立量化数据；此处为结构性拆分示意，非统计口径。已核实的部分是：江苏属玻璃原片库存压力较大省区（2025-06 卓创口径），且光伏玻璃是其重碱需求的关键变量。

Sheet 13 国标与规格
A1: 规格、包装与税基（口径切换的锚点）
A2: 任何跨地区比较先确认这五项；不一致就显式换算，缺参数就不让算。
A3: 项目 | B3: 取值 | C3: 依据/说明
A4: 产品 | B4: 重质纯碱 | C4: 重质纯碱（dense soda ash）
A5: 国标 | B5: GB/T 210-2022《工业碳酸钠》 | C5: Ⅱ 类优等品为期货交割基准
A6: 主成分要求 | B6: GB/T 210-2022《工业碳酸钠》Ⅱ类优等品，Na₂CO₃ ≥ 99.2%（干基） | C6: Na₂CO₃（干基）≥ 99.2%
A7: 期货交割基准品 | B7: 郑商所纯碱期货交割基准品：Ⅱ类优等品重质纯碱，NaCl（干基）≤ 0.6% | C7: 郑商所纯碱期货；交割品须满足 NaCl（干基）≤ 0.6%
A8: 堆积密度 | B8: 重质 ≥ 1.0 g/cm³；轻质约 0.5–0.6 g/cm³ | C8: 轻/重碱不能混算价差，必须分列
A9: 包装 | B9: 吨包（单包净重 1 吨）或散装，重碱通常同价执行 | C9: 吨包单包 1 吨；散装罐车亦有，通常同价
A10: 计量单位 | B10: 元/吨 | C10: 郑商所期货交易单位 20 吨/手，报价单位 元/吨
A11: 增值税率 | B11: 13% | C11: 2019-04-01 起由 16% 调整为 13%
A12: 不含税换算 | B12: 不含税 = 含税 ÷ 1.13 | C12: 例：含税 1225.71 → 不含税约 1084.7
A13: 区域税率差异 | B13: 无 | C13: 调研确认：沙河增值税 13%，与全国一致，不构成区域价差来源
A14: 重碱报价口径 | B14: 轻碱统一出厂价；重碱除西北以外地区采用送到价，西北采用出厂价 | C14: 期货日报《纯碱的物流仓储与价格政策介绍》2019-12-01
... A18: 水运成本 | B18: 30–120 元/吨 | C18: 期货日报；山东沿海→华南 140–150 元/吨

Sheet 14 区域事件
A1: 区域产业事件日历（只写可核对的事件）
A2: events 只用于解释「可能为什么变化」，不用于把相关升级为因果。
A3: 编号 | B3: 起始 | C3: 结束 | D3: 类型 | E3: 影响地区 | F3: 事件 | G3: 价格方向 | H3: 经济链条（传导路径） | I3: 核实
A4: E01 | B4: 45078 | C4: 至今 | D4: 产能 | E4: 全国、HB、SD | F4: 远兴阿拉善天然碱一期 500 万吨投产 | G4: 宽松 | H4: 内蒙古阿拉善塔木素天然碱一期 500 万吨纯碱 + 40 万吨小苏打投产，首批一线 2023-08 日产 4000 多吨。天然碱完全成本 <1000 元/吨，显著低于联碱（1050—1200）与氨碱（>1300）。 天然碱外运至沙河/华北约 300 元/吨（1500 km 汽运，已核实），折算到货成本仍低于华东本地氨碱/联碱出厂——它压的是『全国边际成本』与『华北到货价』，不是单压某一省。 | I4: ✓
A5: E02 | B5: 45131 | C5: 45184 | D5: 需求 | E5: 全国、HB、SD、JS | F5: 2023 年旺季急涨：重碱 2175 → 华北 3200 / 华东 3150 | G5: 收紧 | H5: 夏季检修超预期 + 厂家库存 8—9 月最低约 13 万吨（历史最低）+ 光伏玻璃需求，重碱从 7-24 低点 2175 涨至 9-01 华北 3200、华东 3150。 全区域同向急涨时，区域价差通常被压缩（缺货时贸易流被『就近取货』替代，跨区流向减少）；这是『价差收敛型事件』的典型样本。 | I5: ✓
A6: E03 | B6: 45139 | C6: 45230 | D6: 物流 | E6: SD、HB、JS | F6: 2023 年极端缺货期：现货『封单不报价』 | G6: 不确定 | H6: 8 月部分碱厂停止接新单，贸易商库存耗尽，市场传闻 SA2309 大量空单被逼仓；现货报价一度中断。 缺货期『报价停更』本身会造成序列缺口——本 Skill 的处理是留空、标缺口，绝不插值，否则会在最关键的区间造出一条假曲线。 | I6: ✓
A7: E04 | B7: 45288 | C7: 至今 | D7: 产能 | E7: 全国、HB、SD | F7: 阿拉善二期 280 万吨启动建设（计划 2025-12 建成） | G7: 宽松 | H7: 二期纯碱 280 万吨 + 小苏打 40 万吨，投资约 55 亿元。 二期投产预期自 2024 年起持续压制华北/华东远月与现货中枢。 | I7: ✓
A8: E05 | B8: 45292 | C8: 45657 | D8: 产能 | E8: 全国 | F8: 2024 年供给过剩：全年跌 45%，重碱终端均价 1953（-29.6%） | G8: 宽松 | H8: 2024 年底全国产能 3838 万吨（+4.9%），产量 3735 万吨（+16.2%）；生意社口径年初 2790 → 年末 1528（-45.23%）；卓创重碱主流终端均价 1953 元/吨（-29.6%）。 过剩期价格由『边际成本最高的氨碱装置』定价，区域价差主要由各区域『本地装置成本 + 到货成本』决定，而非需求强弱。 | I8: ✓
A9: E06 | B9: 45352 | C9: 45473 | D9: 装置 | E9: JS、全国 | F9: 2024 上半年江苏装置检修：徐州丰成、江苏实联、江苏井神等 | G9: 收紧 | H9: 2024 年 3 月开工负荷 91.5%（年内最高）、9 月 82.6%（年内最低）；检修期内江苏本地供给收缩，需外省调入补缺。 江苏为净调入省，本地检修会抬升『外省到货依赖度』，在运费不变的条件下把江苏送到价相对山东/河北推高——这是江苏相对升水扩张的典型成因。 | I9: ✓
A10: E07 | B10: 45536 | C10: 45626 | D10: 需求 | E10: HB | F10: 2024 下半年浮法玻璃冷修增加，沙河需求走弱 | G10: 宽松 | H10: 浮法玻璃上半年产能高于上年同期、下半年收缩；光伏玻璃同样上冲高、下半年回落。沙河为北方建筑玻璃基地（产能占全国约 10%），纯碱月用量约 9 万吨。 沙河需求走弱 → 沙河到货价承压 → 河北相对山东/江苏走弱，形成『河北贴水扩张』阶段。 | I10: ✓
A11: E08 | B11: 45597 | C11: 45657 | D11: 需求 | E11: 全国 | F11: 2024 年末库存创高：厂家库存 143.9 万吨（同比 +318%） | G11: 宽松 | H11: 11 月上旬库存高点 158.8 万吨；全年周均库存 103.3 万吨（+223.8%）。 高库存 + 高开工时，卖方为去库会接受区域贴价，价差更多由『谁先卖得掉』决定。 | I11: ✓
A12: E09 | B12: 45689 | C12: 45747 | D12: 产能 | E12: JS | F12: 江苏德邦 60 万吨联碱搬迁投产 | G12: 宽松 | H12: 搬迁项目 2025-02 出货（生意社年度表列 2025-03）。 新增本地产能替代部分外省调入，短期压制江苏相对升水。 | I12: ✓
A13: E10 | B13: 45717 | C13: 45808 | D13: 装置 | E13: 全国、JS | F13: 2025 上半年检修损失量同比 +22.82%（1—6 月 328.66 万吨） | G13: 收紧 | H13: 3 月损失 68.18 万吨、5 月 70.73 万吨；涉及徐州丰成、江苏实联、江苏井神、河南骏化、博源银根等。 检修集中在江苏、河南装置时，江苏本地供给收缩最明显。 | I13: ✓
A14: E11 | B14: 45795 | C14: 至今 | D14: 产能 | E14: JS | F14: 连云港碱业 110 万吨联碱一次开车成功（搬迁+换工艺） | G14: 宽松 | H14: 老厂（氨碱，原约 130 万吨）于 2021—2022 年间关停（协会 2022-12 分企业产量为 0）；新厂在灌云燕尾港，投资 58.28 亿元，110 万吨联碱（80 重碱 + 30 轻灰）。 这是『同一家企业内部置换』：旧产能退出（氨碱，高成本）→ 新产能投产（联碱，低成本）。对区域价格的影响是净供给回升 + 成本下移，需分段观察江苏相对升水是否收敛。 | I14: ✓
A15: E12 | B15: 45809 | C15: 45930 | D15: 需求 | E15: 全国、JS | F15: 光伏 136 号文『531』节点：Q1 抢装 5971 万千瓦后需求后置 | G15: 宽松 | H15: 发改价格〔2025〕136 号以 2025-06-01 为存量/增量分界，Q1 全国新增光伏装机 5971 万千瓦（占新增装机近八成）；抢装透支后光伏玻璃需求走弱，间接压制重碱需求。新疆 6 月出台的 21 条是 136 号文的落地，不是独立新增利空。 光伏玻璃日熔量在抢装后回落 → 重碱刚需下降。江苏光伏玻璃集聚度高于山东河北，因此对江苏相对价格影响更大。 | I15: ✓
A16: E13 | B16: 45839 | C16: 45900 | D16: 政策 | E16: 全国 | F16: 『反内卷』政策预期推动纯碱阶段性大涨（随后急跌） | G16: 不确定 | H16: 7 月反内卷预期 + 成本支撑推动行情上涨，7-18 夜盘纯碱、玻璃盘中一度涨超 5%；情绪利多后急跌。 预期驱动型上涨通常是『全区域同向、同幅度』，区域价差变化不大——若价差同步走阔，说明是区域物流或供给事件，而非政策。 | I16: ✓
A17: E14 | B17: 45962 | C17: 46022 | D17: 需求 | E17: HB | F17: 沙河 4 条燃煤玻璃线集中停产冷修（合计日熔约 2400—2650 吨） | G17: 宽松 | H17: 煤改气推进下沙河燃煤产线集中冷修；11 月沙河在产 17 条产线、日熔 1.45 万吨，燃料结构天然气 58%。 沙河日熔下降 → 河北纯碱刚需下降 → 河北相对贴水扩张。 | I17: ✓
A18: E15 | B18: 46000 | C18: 至今 | D18: 产能 | E18: 全国、HB、SD | F18: 阿拉善二期首条 100 万吨线投料试车 | G18: 宽松 | H18: 2025-12-09 投料试车当日产出合格品；完全达产后基地纯碱总产能 780 万吨/年。 二期首线在样本期末投产，影响主要体现在 2026 年及以后，2025 年内对价差的影响有限（预期定价除外）。 | I18: ✓
A19: E16 | B19: 46022 | C19: 至今 | D19: 需求 | E19: 全国 | F19: 2025 年出口 219.38 万吨创近十年新高（+79.73%） | G19: 收紧 | H19: 1—11 月出口 196.12 万吨（+88.83%）、进口仅 2.17 万吨（-97.76%）。 出口放量主要消化沿海（山东海化、江苏港口）货源，内陆天然碱出口不经济——这会使沿海省份相对内陆的反应更快。 | I19: ✓
A20: E17 | B20: 45962 | C20: 46022 | D20: 成本 | E20: 全国 | F20: 轻重碱价倒挂 + 煤价走强的成本支撑 | G20: 收紧 | H20: 2025 年四季度出现轻重碱价格倒挂；2025 年煤价走强被视为四季度反弹原因之一。 成品结构倒挂时，重碱供给会被生产商主动调减（改产轻碱更划算），对重碱区域价差是向上的偏置。 | I20: ✓
A21: E18 | B21: 45425 | C21: 45428 | D21: 口径 | E21: HB、SD、JS | F21: 行业调研确认三地增值税一致（13%），税基不构成区域价差来源 | G21: 中性 | H21: 玻璃行业调研原文：沙河增值税 13%，与全国其他地区一致，不存在税收优惠。 既然税基一致，区域价差就不应被『税率』解释；真正的解释应在物流成本、装置结构与需求强弱上。 | I21: ✓

Sheet 15 数据质检
A1: 数据质检（提交前逐项打勾）
A2: ERROR 未清零不得对外交付。
A3: 检查项 | B3: 结果 | C3: 判定 | D3: 说明
A4: 观测期长度 | B4: 152 期 | C4: PASS | D4: ≥52 期（约 1 年）才足以谈分位
A5: 对齐后剔除周数 | B5: 4 周 | C5: PASS | D5: 缺口剔除、不插值；剔除日期见下表
A6: 口径换算缺失参数 | B6: 0 项 | C6: PASS | D6: 缺失即「不让算」，不会用 0 顶替
A7: 三地区税基一致 | B7: 是（均 13% 含税） | C7: PASS | D7: 税基不一致会系统性扭曲价差
A8: 三地区交付方式一致 | B8: 是（主口径均为送到价） | C8: PASS | D8: 送到 vs 出厂混算会高估 50–100 元/吨
A9: 运费来源 | B9: default_ref | C9: WARN | D9: 无真实报价时，扣费后差异只能作敏感性参考
A10: 运费已内含于报价 | B10: 是（送到价） | C10: WARN | D10: 送到价口径下不可重复扣减整段运费
A11: 数据状态 | B11: DEMO | C11: WARN | D11: DEMO 数据不得用于报价、交易或对外引用
A12: 省级产能合计 | B12: 未查到（仅企业级） | C12: WARN | D12: 宁缺不假；不要用估算数冒充统计
A13: 承兑贴息 | B13: 未查到 | C13: WARN | D13: 不给假设值；遇到承兑报价时标记而非填 0
A15: 缺口明细（被剔除的观测周）
A16: 日期 | B16: 缺失地区 | C16: 滞后（天） | D16: 口径
A17: 45219 | B17: 山东 | D17: 送到价（到厂/到库）
A18: 45331 | B18: 江苏 | D18: 送到价（到厂/到库）
A19: 45646 | B19: 河北 | D19: 送到价（到厂/到库）
A20: 45779 | B20: 江苏 | D20: 送到价（到厂/到库）

Sheet 16 计算公式
A1: 计算公式对照表（Excel 写法 ↔ Python 实现 ↔ 含义）
A2: 每一个数字都能被复算——这是可交付的前提。
A3: # | B3: 指标 | C3: 数学定义 / 规则 | D3: Excel 写法 | E3: Python 函数 | F3: 说明与陷阱
A4: F1 | B4: 价差 | C4: spread(a,b) = P(a) − P(b) | D4: '=甲价单元格−乙价单元格 | E4: spreadlib.spread_series | F4: 永远写清「谁减谁」；矩阵是「行−列」
A5: F2 | B5: 含税→不含税 | C5: P_ex = P_inc / (1 + 13%) | D5: '=P/(1+0.13) | E5: normalize_price | F5: 增值税是价外税；不要「再扣一次」增值税
A6: F3 | B6: 承兑→现汇 | C6: P_cash = P_acc − 贴息 | D6: '=P_cell-贴息(元/吨) | E6: normalize_price(payment_discount) | F6: 贴息数值公开源【未查到】——缺失时不让算，绝不填 0
A7: F4 | B7: 送到→出厂 | C7: P_exw = P_delivered − 内含运费 | D7: '=P-内含运费 | E7: normalize_price(freight_included) | F7: 内含运费未知则不让算；不要用整段外部运费替代
A8: F5 | B8: 两两价差（矩阵） | C8: M[i][j] = P_i − P_j，M[i][i]=0 | D8: '=IFERROR(价格表!{Ci}-价格表!{Cj},"") | E8: spread_matrix | F8: 等价校验：M[i][j] = −M[j][i]
A9: F6 | B9: 有效样本数 N | C9: 同时有两侧报价的观测数 | D9: '=COUNT(价差列) | E9: describe().n | F9: 价差为空=该日两侧未同时有报价
A10: F7 | B10: 经验分位（ECDF） | C10: (#{x<v} + 0.5·#{x=v}) / N × 100% | D10: '=(COUNTIF(r,"<"&v)+0.5*COUNTIF(r,v))/COUNT(r)*100 | E10: percentile_of | F10: 并列取中秩；PERCENTRANK 取最小秩会系统性偏低
A11: F8 | B11: 窗口分位 | C11: 只用 end−365 / end−1095 天内的样本 | D11: '=SUMPRODUCT((日期>=截止-365)*(价差列<>"")) | E11: window_sample + percentile_of | F11: 窗口内样本 <30 时应标注低置信
A12: F9 | B12: 滚动分位 | C12: 每点用 [t−365, t] 的样本计算当前值分位 | D12: SUMPRODUCT 逐行窗口 | E12: rolling_percentile | F12: 窗口重叠是正常的；不要对滚动分位再算显著性
A13: F10 | B13: 标准分 z | C13: z = (x − mean(window)) / sd(window) | D13: '=(x-AVERAGE(r))/STDEV.S(r) | E13: zscore | F13: 用于识别异常阶段；|z|≥1 且连续≥3 周
A14: F11 | B14: 综合运费 | C14: F = 主运费 + 装货 + 卸货 + 短驳 + 其他 | D14: '=SUM(主运费:其他) | E14: freight_total | F14: 任一项未知则总额为空，不按 0 计
... A23: F20 | B23: 距离×运价 | C23: 运费 ≈ 里程(km) × 吨公里运价(元/吨·km) − 整车折让 | D23: '=km*rate-discount | E23: — | F23: 吨公里 0.2–0.4 为经验值；已核实反推 0.20（阿拉善→石家庄 300元/1500km）
A25: Excel 与 Python 的一致性由 scripts/verify_excel.py 对账：读取本工作簿公式重算值，与 result.json 中的价差 / 分位逐项比较，差异须 < 0.01。
