Workbook

Sheet 00 说明与使用指南
A1: 两指标相关性研究工作簿｜甲醇港口库存 × 太仓现货价
A2: 示例数据为按真实行业口径拟真的 DEMO 数据（见“01 口径与来源”）。把真实历史数据贴进“02 原始数据”，本工作簿所有公式自动重算。
B4: 这份工作簿解决什么 | C4: 回答“两个指标到底相不相关、在什么条件下相关、这个相关是否可信”。不回答“买还是卖”，也不给因果结论。
B5: 第 1 步 输入数据 | C5: 在“02 原始数据”替换 B/C/D/G 列（观测日、价格锚日、库存、价格）。缺失就留空或用 =NA()，绝不插值补数。
B6: 第 2 步 核对口径 | C6: “01 口径与来源”逐项填全：单位、频率、区域、样本口径、发布时点、来源。任一项缺失，结论不可对外引用。
B7: 第 3 步 频率对齐 | C7: “03 频率对齐”标出每期配对状态（成功/缺失-剔除），并给出有效配对 N 与缺失期数。
B8: 第 4 步 变换 | C8: “04 变换后数据”把库存/价格分别做成 水平、差分、环比%。库存常看变化，价格常看变化率。
B9: 第 5 步 读结果 | C9: “05 总体相关”给 5 种形态组合的 r/N/R²/t/p/判定；“06 滚动相关”看强度随时间变化；“07 分阶段”按业务阶段重算。
B10: 第 6 步 查伪相关 | C10: “09 稳健性与伪相关诊断”+“09b 辅助计算(残差)”：去趋势、差分、剔极值、分段、偏相关；自相关强时用有效样本量修正。
B11: 第 7 步 写结论 | C11: 结论必须带口径、形态、时间段、N、显著性、稳健性；禁止把相关性写成因果，禁止输出交易建议。
B12: 公式透明 | C12: “12 公式说明”逐条给出公式定义与 Excel 写法，全部可在表内复核（无宏、无加载项）。
B14: ⚠ 重要声明 | C14: 相关性不等于因果关系；滚动相关只描述历史窗口内的共变强度，不外推未来；本工作簿不提供任何交易建议或价格预测。

Sheet 01 口径与来源
A1: 口径与来源（数据可否引用的前提）
A2: 每列都要有值。任一项写“待确认”，对应结论只能当探索性提示。
B4: 指标 | C4: 指标全称 | D4: 单位 | E4: 频率 | F4: 统计区域/样本 | G4: 发布时点（口径） | H4: 来源与链接 | I4: 备注（口径风险）
B5: 指标 X（库存） | C5: 中国甲醇样本港口库存（总） | D5: 万吨 | E5: 周度 | F5: 华东（江苏/浙江各港口）+ 华南 | G5: 调查日=每周三，机构当日或次日发布 | H5: DEMO：按隆众资讯周度口径拟真，非真实市场数据 | I5: 示例为拟真数据；真实使用请替换为可获得的历史序列
B6: 指标 Y（价格） | C6: 江苏太仓甲醇出罐现货价（现汇） | D6: 元/吨 | E6: 周度（由日报汇总） | F6: 江苏太仓 | G6: 日报午评口径（如 12:00），取当周锚日 | H6: DEMO：按隆众/我的钢铁日报口径拟真，非真实市场数据 | I6: 现货报价的税基/现汇/库提口径需与成交口径核对
B7: 控制变量（可选） | C7: 动力煤 5500 现货价 | D7: 元/吨 | E7: 周度 | F7: 环渤海/秦皇岛 | G7: 周度发布 | H7: DEMO：成本参照 | I7: 仅用于偏相关诊断“共同外部因素”
B8: 分析频率 | C8: 周度（周三对齐） | D8: — | E8: 周度 | F8: — | G8: — | H8: 对齐规则见“03 频率对齐” | I8: 若原始为日度，须按同一时点汇总，禁止使用未来信息
B10: 数据状态 | C10: 本文件所有数值为教学/演示用拟真数据（机制见 scripts/make_data.py），不得作为真实行情或研究结论引用。

Sheet 02 原始数据
A1: 原始数据（唯一数据入口，其余表全部由本表驱动）
A2: 橙底两列为需替换的核心输入列（库存、价格）。留空=缺失，全表按缺失处理，不插补。
A4: 序号 | B4: 观测日(库存调查日) | C4: 价格锚日 | D4: 港口库存-总计 | E4: 港口库存-华东 | F4: 港口库存-华南 | G4: 太仓现货价 | H4: 动力煤5500 | I4: 下游开工率% | J4: 周度到港 | K4: 周度提货
A5: 1 | B5: 2023-10-11 | C5: 2023-10-11 | D5: 57.54 | E5: 38.52 | F5: 19.02 | G5: 2640 | H5: 799 | I5: 70 | J5: 7.03 | K5: 13.19
A6: 2 | B6: 2023-10-18 | C6: 2023-10-18 | D6: 60.29 | E6: 37.3 | F6: 22.99 | G6: 2444 | H6: 815 | I6: 70.3 | J6: 10.42 | K6: 11.88
A7: 3 | B7: 2023-10-25 | C7: 2023-10-25 | D7: 55.24 | E7: 37.12 | F7: 18.12 | G7: 2938 | H7: 811 | I7: 68.7 | J7: 8.14 | K7: 11.28
A8: 4 | B8: 2023-11-01 | C8: 2023-11-01 | D8: 57.64 | E8: 38.53 | F8: 19.11 | G8: 2726 | H8: 808 | I8: 71.4 | J8: 13.42 | K8: 11.99
A9: 5 | B9: 2023-11-08 | C9: 2023-11-08 | D9: 67.02 | E9: 43.43 | F9: 23.59 | G9: 2069 | H9: 808 | I9: 71.4 | J9: 16.04 | K9: 11.28
A10: 6 | B10: 2023-11-15 | C10: 2023-11-15 | D10: 67.23 | E10: 45.81 | F10: 21.42 | G10: 2050 | H10: 818 | I10: 72.8 | J10: 12.18 | K10: 12.52
A11: 7 | B11: 2023-11-22 | C11: 2023-11-22 | D11: 64.21 | E11: 42.73 | F11: 21.48 | G11: 2155 | H11: 821 | I11: 70.8 | J11: 9.36 | K11: 13.79
A12: 8 | B12: 2023-11-29 | C12: 2023-11-29 | D12: 67.39 | E12: 43.85 | F12: 23.54 | G12: 2087 | H12: 812 | I12: 71.7 | J12: 15.03 | K12: 11.68
A13: 9 | B13: 2023-12-06 | C13: 2023-12-06 | D13: 65.95 | E13: 43.43 | F13: 22.52 | G13: 2181 | H13: 814 | I13: 72.4 | J13: 11.34 | K13: 12.44
A14: 10 | B14: 2023-12-13 | C14: 2023-12-13 | D14: 58.84 | E14: 38.1 | F14: 20.74 | G14: 2675 | H14: 822 | I14: 72.7 | J14: 8.49 | K14: 12.2
A15: 11 | B15: 2023-12-20 | C15: 2023-12-20 | D15: 54.79 | E15: 35.39 | F15: 19.4 | G15: 2940 | H15: 818 | I15: 73.6 | J15: 9.22 | K15: 13.38
A16: 12 | B16: 2023-12-27 | C16: 2023-12-27 | D16: 52.11 | E16: 33.63 | F16: 18.48 | G16: 3228 | H16: 810 | I16: 74.9 | J16: 9.71 | K16: 11.82
... A160: 156 | B160: 2026-09-30 | C160: 2026-09-30 | D160: 78.39 | E160: 49.73 | F160: 28.66 | G160: 1668 | H160: 777 | I160: 74.9 | J160: 22.5 | K160: 11.52

Sheet 03 频率对齐
A1: 频率对齐与配对规则
A2: 库存为周三调查值，价格为同一交易日午评报价；两序列均按周度处理，直接按观测日一一配对。任一期缺失则不参与配对，也不补数。
A4: 序号 | B4: 观测日 | C4: 价格锚日 | D4: 配对状态 | E4: 库存 | F4: 价格 | G4: 库存形态 | H4: 价格形态 | I4: 时点一致性
A5: 1 | B5: ='02 原始数据'!B5 | C5: ='02 原始数据'!C5 | D5: =IF(OR(E5="",F5=""),"缺失-剔除","配对成功") | E5: ='02 原始数据'!D5 | F5: ='02 原始数据'!G5 | G5: =IF(D5="配对成功","水平可用","") | H5: ="" | I5: =IF(B5=C5,"同日","不同日，需注明时点差")
A6: 2 | B6: ='02 原始数据'!B6 | C6: ='02 原始数据'!C6 | D6: =IF(OR(E6="",F6=""),"缺失-剔除","配对成功") | E6: ='02 原始数据'!D6 | F6: ='02 原始数据'!G6 | G6: =IF(D6="配对成功","水平可用","") | H6: =IF(AND(D6="配对成功",A6>1,E5<>""),"变化可用","") | I6: =IF(B6=C6,"同日","不同日，需注明时点差")
A7: 3 | B7: ='02 原始数据'!B7 | C7: ='02 原始数据'!C7 | D7: =IF(OR(E7="",F7=""),"缺失-剔除","配对成功") | E7: ='02 原始数据'!D7 | F7: ='02 原始数据'!G7 | G7: =IF(D7="配对成功","水平可用","") | H7: =IF(AND(D7="配对成功",A7>1,E6<>""),"变化可用","") | I7: =IF(B7=C7,"同日","不同日，需注明时点差")
A8: 4 | B8: ='02 原始数据'!B8 | C8: ='02 原始数据'!C8 | D8: =IF(OR(E8="",F8=""),"缺失-剔除","配对成功") | E8: ='02 原始数据'!D8 | F8: ='02 原始数据'!G8 | G8: =IF(D8="配对成功","水平可用","") | H8: =IF(AND(D8="配对成功",A8>1,E7<>""),"变化可用","") | I8: =IF(B8=C8,"同日","不同日，需注明时点差")
A9: 5 | B9: ='02 原始数据'!B9 | C9: ='02 原始数据'!C9 | D9: =IF(OR(E9="",F9=""),"缺失-剔除","配对成功") | E9: ='02 原始数据'!D9 | F9: ='02 原始数据'!G9 | G9: =IF(D9="配对成功","水平可用","") | H9: =IF(AND(D9="配对成功",A9>1,E8<>""),"变化可用","") | I9: =IF(B9=C9,"同日","不同日，需注明时点差")
A10: 6 | B10: ='02 原始数据'!B10 | C10: ='02 原始数据'!C10 | D10: =IF(OR(E10="",F10=""),"缺失-剔除","配对成功") | E10: ='02 原始数据'!D10 | F10: ='02 原始数据'!G10 | G10: =IF(D10="配对成功","水平可用","") | H10: =IF(AND(D10="配对成功",A10>1,E9<>""),"变化可用","") | I10: =IF(B10=C10,"同日","不同日，需注明时点差")
A11: 7 | B11: ='02 原始数据'!B11 | C11: ='02 原始数据'!C11 | D11: =IF(OR(E11="",F11=""),"缺失-剔除","配对成功") | E11: ='02 原始数据'!D11 | F11: ='02 原始数据'!G11 | G11: =IF(D11="配对成功","水平可用","") | H11: =IF(AND(D11="配对成功",A11>1,E10<>""),"变化可用","") | I11: =IF(B11=C11,"同日","不同日，需注明时点差")
A12: 8 | B12: ='02 原始数据'!B12 | C12: ='02 原始数据'!C12 | D12: =IF(OR(E12="",F12=""),"缺失-剔除","配对成功") | E12: ='02 原始数据'!D12 | F12: ='02 原始数据'!G12 | G12: =IF(D12="配对成功","水平可用","") | H12: =IF(AND(D12="配对成功",A12>1,E11<>""),"变化可用","") | I12: =IF(B12=C12,"同日","不同日，需注明时点差")
A13: 9 | B13: ='02 原始数据'!B13 | C13: ='02 原始数据'!C13 | D13: =IF(OR(E13="",F13=""),"缺失-剔除","配对成功") | E13: ='02 原始数据'!D13 | F13: ='02 原始数据'!G13 | G13: =IF(D13="配对成功","水平可用","") | H13: =IF(AND(D13="配对成功",A13>1,E12<>""),"变化可用","") | I13: =IF(B13=C13,"同日","不同日，需注明时点差")
A14: 10 | B14: ='02 原始数据'!B14 | C14: ='02 原始数据'!C14 | D14: =IF(OR(E14="",F14=""),"缺失-剔除","配对成功") | E14: ='02 原始数据'!D14 | F14: ='02 原始数据'!G14 | G14: =IF(D14="配对成功","水平可用","") | H14: =IF(AND(D14="配对成功",A14>1,E13<>""),"变化可用","") | I14: =IF(B14=C14,"同日","不同日，需注明时点差")
A15: 11 | B15: ='02 原始数据'!B15 | C15: ='02 原始数据'!C15 | D15: =IF(OR(E15="",F15=""),"缺失-剔除","配对成功") | E15: ='02 原始数据'!D15 | F15: ='02 原始数据'!G15 | G15: =IF(D15="配对成功","水平可用","") | H15: =IF(AND(D15="配对成功",A15>1,E14<>""),"变化可用","") | I15: =IF(B15=C15,"同日","不同日，需注明时点差")
A16: 12 | B16: ='02 原始数据'!B16 | C16: ='02 原始数据'!C16 | D16: =IF(OR(E16="",F16=""),"缺失-剔除","配对成功") | E16: ='02 原始数据'!D16 | F16: ='02 原始数据'!G16 | G16: =IF(D16="配对成功","水平可用","") | H16: =IF(AND(D16="配对成功",A16>1,E15<>""),"变化可用","") | I16: =IF(B16=C16,"同日","不同日，需注明时点差")
A17: 13 | B17: ='02 原始数据'!B17 | C17: ='02 原始数据'!C17 | D17: =IF(OR(E17="",F17=""),"缺失-剔除","配对成功") | E17: ='02 原始数据'!D17 | F17: ='02 原始数据'!G17 | G17: =IF(D17="配对成功","水平可用","") | H17: =IF(AND(D17="配对成功",A17>1,E16<>""),"变化可用","") | I17: =IF(B17=C17,"同日","不同日，需注明时点差")
... A160: 156 | B160: ='02 原始数据'!B160 | C160: ='02 原始数据'!C160 | D160: =IF(OR(E160="",F160=""),"缺失-剔除","配对成功") | E160: ='02 原始数据'!D160 | F160: ='02 原始数据'!G160 | G160: =IF(D160="配对成功","水平可用","") | H160: =IF(AND(D160="配对成功",A160>1,E159<>""),"变化可用","") | I160: =IF(B160=C160,"同日","不同日，需注明时点差")
B162: 有效配对数 N = | E162: =COUNTIF(D5:D160,"配对成功")
B163: 缺失期数 = | E163: =COUNTIF(D5:D160,"缺失-剔除")

Sheet 04 变换后数据
A1: 变换：水平 / 一阶差分 / 环比%
A2: 差分与环比的首期必为空（没有上一期），这是设计而非缺数。库存变化单位是万吨，价格变化单位是%，相关系数本身与单位无关，但经济含义不同。
A4: 序号 | B4: 观测日 | C4: 库存-水平 | D4: 库存-差分 | E4: 库存-环比% | F4: 价格-水平 | G4: 价格-差分 | H4: 价格-环比% | I4: 煤价-水平 | J4: 开工率-水平 | K4: 库存/提货比
A5: 1 | B5: ='02 原始数据'!B5 | C5: ='02 原始数据'!D5 | D5: ="" | E5: ="" | F5: ='02 原始数据'!G5 | G5: ="" | H5: ="" | I5: ='02 原始数据'!H5 | J5: ='02 原始数据'!I5 | K5: =IFERROR(IF(C5="","",C5/'02 原始数据'!K5),"")
A6: 2 | B6: ='02 原始数据'!B6 | C6: ='02 原始数据'!D6 | D6: =IF(OR(C6="",C5=""),"",C6-C5) | E6: =IF(OR(C6="",C5=""),"",(C6-C5)/ABS(C5)) | F6: ='02 原始数据'!G6 | G6: =IF(OR(F6="",F5=""),"",F6-F5) | H6: =IF(OR(F6="",F5=""),"",(F6-F5)/ABS(F5)) | I6: ='02 原始数据'!H6 | J6: ='02 原始数据'!I6 | K6: =IFERROR(IF(C6="","",C6/'02 原始数据'!K6),"")
A7: 3 | B7: ='02 原始数据'!B7 | C7: ='02 原始数据'!D7 | D7: =IF(OR(C7="",C6=""),"",C7-C6) | E7: =IF(OR(C7="",C6=""),"",(C7-C6)/ABS(C6)) | F7: ='02 原始数据'!G7 | G7: =IF(OR(F7="",F6=""),"",F7-F6) | H7: =IF(OR(F7="",F6=""),"",(F7-F6)/ABS(F6)) | I7: ='02 原始数据'!H7 | J7: ='02 原始数据'!I7 | K7: =IFERROR(IF(C7="","",C7/'02 原始数据'!K7),"")
A8: 4 | B8: ='02 原始数据'!B8 | C8: ='02 原始数据'!D8 | D8: =IF(OR(C8="",C7=""),"",C8-C7) | E8: =IF(OR(C8="",C7=""),"",(C8-C7)/ABS(C7)) | F8: ='02 原始数据'!G8 | G8: =IF(OR(F8="",F7=""),"",F8-F7) | H8: =IF(OR(F8="",F7=""),"",(F8-F7)/ABS(F7)) | I8: ='02 原始数据'!H8 | J8: ='02 原始数据'!I8 | K8: =IFERROR(IF(C8="","",C8/'02 原始数据'!K8),"")
A9: 5 | B9: ='02 原始数据'!B9 | C9: ='02 原始数据'!D9 | D9: =IF(OR(C9="",C8=""),"",C9-C8) | E9: =IF(OR(C9="",C8=""),"",(C9-C8)/ABS(C8)) | F9: ='02 原始数据'!G9 | G9: =IF(OR(F9="",F8=""),"",F9-F8) | H9: =IF(OR(F9="",F8=""),"",(F9-F8)/ABS(F8)) | I9: ='02 原始数据'!H9 | J9: ='02 原始数据'!I9 | K9: =IFERROR(IF(C9="","",C9/'02 原始数据'!K9),"")
A10: 6 | B10: ='02 原始数据'!B10 | C10: ='02 原始数据'!D10 | D10: =IF(OR(C10="",C9=""),"",C10-C9) | E10: =IF(OR(C10="",C9=""),"",(C10-C9)/ABS(C9)) | F10: ='02 原始数据'!G10 | G10: =IF(OR(F10="",F9=""),"",F10-F9) | H10: =IF(OR(F10="",F9=""),"",(F10-F9)/ABS(F9)) | I10: ='02 原始数据'!H10 | J10: ='02 原始数据'!I10 | K10: =IFERROR(IF(C10="","",C10/'02 原始数据'!K10),"")
A11: 7 | B11: ='02 原始数据'!B11 | C11: ='02 原始数据'!D11 | D11: =IF(OR(C11="",C10=""),"",C11-C10) | E11: =IF(OR(C11="",C10=""),"",(C11-C10)/ABS(C10)) | F11: ='02 原始数据'!G11 | G11: =IF(OR(F11="",F10=""),"",F11-F10) | H11: =IF(OR(F11="",F10=""),"",(F11-F10)/ABS(F10)) | I11: ='02 原始数据'!H11 | J11: ='02 原始数据'!I11 | K11: =IFERROR(IF(C11="","",C11/'02 原始数据'!K11),"")
A12: 8 | B12: ='02 原始数据'!B12 | C12: ='02 原始数据'!D12 | D12: =IF(OR(C12="",C11=""),"",C12-C11) | E12: =IF(OR(C12="",C11=""),"",(C12-C11)/ABS(C11)) | F12: ='02 原始数据'!G12 | G12: =IF(OR(F12="",F11=""),"",F12-F11) | H12: =IF(OR(F12="",F11=""),"",(F12-F11)/ABS(F11)) | I12: ='02 原始数据'!H12 | J12: ='02 原始数据'!I12 | K12: =IFERROR(IF(C12="","",C12/'02 原始数据'!K12),"")
A13: 9 | B13: ='02 原始数据'!B13 | C13: ='02 原始数据'!D13 | D13: =IF(OR(C13="",C12=""),"",C13-C12) | E13: =IF(OR(C13="",C12=""),"",(C13-C12)/ABS(C12)) | F13: ='02 原始数据'!G13 | G13: =IF(OR(F13="",F12=""),"",F13-F12) | H13: =IF(OR(F13="",F12=""),"",(F13-F12)/ABS(F12)) | I13: ='02 原始数据'!H13 | J13: ='02 原始数据'!I13 | K13: =IFERROR(IF(C13="","",C13/'02 原始数据'!K13),"")
A14: 10 | B14: ='02 原始数据'!B14 | C14: ='02 原始数据'!D14 | D14: =IF(OR(C14="",C13=""),"",C14-C13) | E14: =IF(OR(C14="",C13=""),"",(C14-C13)/ABS(C13)) | F14: ='02 原始数据'!G14 | G14: =IF(OR(F14="",F13=""),"",F14-F13) | H14: =IF(OR(F14="",F13=""),"",(F14-F13)/ABS(F13)) | I14: ='02 原始数据'!H14 | J14: ='02 原始数据'!I14 | K14: =IFERROR(IF(C14="","",C14/'02 原始数据'!K14),"")
A15: 11 | B15: ='02 原始数据'!B15 | C15: ='02 原始数据'!D15 | D15: =IF(OR(C15="",C14=""),"",C15-C14) | E15: =IF(OR(C15="",C14=""),"",(C15-C14)/ABS(C14)) | F15: ='02 原始数据'!G15 | G15: =IF(OR(F15="",F14=""),"",F15-F14) | H15: =IF(OR(F15="",F14=""),"",(F15-F14)/ABS(F14)) | I15: ='02 原始数据'!H15 | J15: ='02 原始数据'!I15 | K15: =IFERROR(IF(C15="","",C15/'02 原始数据'!K15),"")
A16: 12 | B16: ='02 原始数据'!B16 | C16: ='02 原始数据'!D16 | D16: =IF(OR(C16="",C15=""),"",C16-C15) | E16: =IF(OR(C16="",C15=""),"",(C16-C15)/ABS(C15)) | F16: ='02 原始数据'!G16 | G16: =IF(OR(F16="",F15=""),"",F16-F15) | H16: =IF(OR(F16="",F15=""),"",(F16-F15)/ABS(F15)) | I16: ='02 原始数据'!H16 | J16: ='02 原始数据'!I16 | K16: =IFERROR(IF(C16="","",C16/'02 原始数据'!K16),"")
A17: 13 | B17: ='02 原始数据'!B17 | C17: ='02 原始数据'!D17 | D17: =IF(OR(C17="",C16=""),"",C17-C16) | E17: =IF(OR(C17="",C16=""),"",(C17-C16)/ABS(C16)) | F17: ='02 原始数据'!G17 | G17: =IF(OR(F17="",F16=""),"",F17-F16) | H17: =IF(OR(F17="",F16=""),"",(F17-F16)/ABS(F16)) | I17: ='02 原始数据'!H17 | J17: ='02 原始数据'!I17 | K17: =IFERROR(IF(C17="","",C17/'02 原始数据'!K17),"")
... A160: 156 | B160: ='02 原始数据'!B160 | C160: ='02 原始数据'!D160 | D160: =IF(OR(C160="",C159=""),"",C160-C159) | E160: =IF(OR(C160="",C159=""),"",(C160-C159)/ABS(C159)) | F160: ='02 原始数据'!G160 | G160: =IF(OR(F160="",F159=""),"",F160-F159) | H160: =IF(OR(F160="",F159=""),"",(F160-F159)/ABS(F159)) | I160: ='02 原始数据'!H160 | J160: ='02 原始数据'!I160 | K160: =IFERROR(IF(C160="","",C160/'02 原始数据'!K160),"")

Sheet 05 总体相关
A1: 总体相关系数（Excel 原生公式，可在表内直接重算）
A2: 五种形态组合齐列，避免“只用一种口径下结论”。p 用 T.DIST.2T，R² 用 RSQ，N 用 COUNT 系列函数统计有效数。
B4: 组合 | C4: Pearson r | D4: N | E4: R² | F4: t 统计量 | G4: p 值（双侧） | H4: 判定
B5: ① 库存水平 × 价格水平 | C5: =IFERROR(CORREL('04 变换后数据'!$C$5:$C$160,'04 变换后数据'!$F$5:$F$160),"样本不足") | D5: =SUMPRODUCT(--ISNUMBER('04 变换后数据'!$C$5:$C$160),--ISNUMBER('04 变换后数据'!$F$5:$F$160)) | E5: =IFERROR(C5^2,"") | F5: =IFERROR(C5*SQRT((D5-2)/(1-C5^2)),"") | G5: =IFERROR(_XLFN.T.DIST.2T(ABS(F5),D5-2),"") | H5: =IF(G5="","",IF(G5<0.01,"显著(1%)",IF(G5<0.05,"显著(5%)",IF(G5<0.1,"边际(10%)","不显著"))))
B6: ② 库存水平 × 价格环比% | C6: =IFERROR(CORREL('04 变换后数据'!$C$5:$C$160,'04 变换后数据'!$H$5:$H$160),"样本不足") | D6: =SUMPRODUCT(--ISNUMBER('04 变换后数据'!$C$5:$C$160),--ISNUMBER('04 变换后数据'!$H$5:$H$160)) | E6: =IFERROR(C6^2,"") | F6: =IFERROR(C6*SQRT((D6-2)/(1-C6^2)),"") | G6: =IFERROR(_XLFN.T.DIST.2T(ABS(F6),D6-2),"") | H6: =IF(G6="","",IF(G6<0.01,"显著(1%)",IF(G6<0.05,"显著(5%)",IF(G6<0.1,"边际(10%)","不显著"))))
B7: ③ 库存差分 × 价格环比% | C7: =IFERROR(CORREL('04 变换后数据'!$D$5:$D$160,'04 变换后数据'!$H$5:$H$160),"样本不足") | D7: =SUMPRODUCT(--ISNUMBER('04 变换后数据'!$D$5:$D$160),--ISNUMBER('04 变换后数据'!$H$5:$H$160)) | E7: =IFERROR(C7^2,"") | F7: =IFERROR(C7*SQRT((D7-2)/(1-C7^2)),"") | G7: =IFERROR(_XLFN.T.DIST.2T(ABS(F7),D7-2),"") | H7: =IF(G7="","",IF(G7<0.01,"显著(1%)",IF(G7<0.05,"显著(5%)",IF(G7<0.1,"边际(10%)","不显著"))))
B8: ④ 库存差分 × 价格差分 | C8: =IFERROR(CORREL('04 变换后数据'!$D$5:$D$160,'04 变换后数据'!$G$5:$G$160),"样本不足") | D8: =SUMPRODUCT(--ISNUMBER('04 变换后数据'!$D$5:$D$160),--ISNUMBER('04 变换后数据'!$G$5:$G$160)) | E8: =IFERROR(C8^2,"") | F8: =IFERROR(C8*SQRT((D8-2)/(1-C8^2)),"") | G8: =IFERROR(_XLFN.T.DIST.2T(ABS(F8),D8-2),"") | H8: =IF(G8="","",IF(G8<0.01,"显著(1%)",IF(G8<0.05,"显著(5%)",IF(G8<0.1,"边际(10%)","不显著"))))
B9: ⑤ 库存环比% × 价格环比% | C9: =IFERROR(CORREL('04 变换后数据'!$E$5:$E$160,'04 变换后数据'!$H$5:$H$160),"样本不足") | D9: =SUMPRODUCT(--ISNUMBER('04 变换后数据'!$E$5:$E$160),--ISNUMBER('04 变换后数据'!$H$5:$H$160)) | E9: =IFERROR(C9^2,"") | F9: =IFERROR(C9*SQRT((D9-2)/(1-C9^2)),"") | G9: =IFERROR(_XLFN.T.DIST.2T(ABS(F9),D9-2),"") | H9: =IF(G9="","",IF(G9<0.01,"显著(1%)",IF(G9<0.05,"显著(5%)",IF(G9<0.1,"边际(10%)","不显著"))))
B11: N 的算法 | C11: SUMPRODUCT(--ISNUMBER(x),--ISNUMBER(y)) 统计“两列同时有数”的期数；缺失用 NA() 表示，CORREL 会自动跳过缺配对，不会把缺失当 0。
B12: p 值的含义 | C12: “若总体真实相关为 0，出现这么极端样本的概率”。p 小只说明不像偶然；相关强不强看 |r|，是不是因果与 p 无关。
B13: 为什么列五种组合 | C13: 同一对指标换个形态，r 可能完全不同。只报一种口径的相关系数，无法被复核。

Sheet 06 滚动相关
A1: 滚动相关系数（12 / 26 / 52 周；主口径：库存差分 × 价格环比%）
A2: 每行对应窗口末端日期。窗口内有效配对数低于“最小样本数”时输出空白，不外推、不插值。改第 3 行窗口参数后整表自动重算。
B3: 12周窗口 | C3: 12 | D3: 26周窗口 | E3: 26 | F3: 52周窗口 | G3: 52
A4: 序号 | B4: 窗口末端日期 | C4: 12周 r | D4: 12周 N | E4: 26周 r | F4: 26周 N | G4: 52周 r | H4: 52周 N | I4: 主口径强度
A5: 1 | B5: ='04 变换后数据'!B5 | C5: =IF(1<$C$3,"",IF(45=0,"",IF(45<MAX(5,ROUND($C$3*0.8,0)),"样本不足",CORREL(OFFSET('04 变换后数据'!$D$5:$D$160,ROW()-5-$C$3+1,0,$C$3,1),OFFSET('04 变换后数据'!$H$5:$H$160,ROW()-5-$C$3+1,0,$C$3,1)))) | D5: =IF(1<$C$3,0,SUMPRODUCT(--(ROW('04 变换后数据'!$D$5:$D$160)<=ROW()),--ISNUMBER(OFFSET('04 变换后数据'!$D$5:$D$160,ROW()-5-$C$3+1,0,MIN($C$3,ROW()-4),1)),--ISNUMBER(OFFSET('04 变换后数据'!$H$5:$H$160,ROW()-5-$C$3+1,0,MIN($C$3,ROW()-4),1)))) | E5: =IF(1<$E$3,"",IF(65=0,"",IF(65<MAX(5,ROUND($E$3*0.8,0)),"样本不足",CORREL(OFFSET('04 变换后数据'!$D$5:$D$160,ROW()-5-$E$3+1,0,$E$3,1),OFFSET('04 变换后数据'!$H$5:$H$160,ROW()-5-$E$3+1,0,$E$3,1)))) | F5: =IF(1<$E$3,0,SUMPRODUCT(--(ROW('04 变换后数据'!$D$5:$D$160)<=ROW()),--ISNUMBER(OFFSET('04 变换后数据'!$D$5:$D$160,ROW()-5-$E$3+1,0,MIN($E$3,ROW()-4),1)),--ISNUMBER(OFFSET('04 变换后数据'!$H$5:$H$160,ROW()-5-$E$3+1,0,MIN($E$3,ROW()-4),1)))) | G5: =IF(1<$G$3,"",IF(85=0,"",IF(85<MAX(5,ROUND($G$3*0.8,0)),"样本不足",CORREL(OFFSET('04 变换后数据'!$D$5:$D$160,ROW()-5-$G$3+1,0,$G$3,1),OFFSET('04 变换后数据'!$H$5:$H$160,ROW()-5-$G$3+1,0,$G$3,1)))) | H5: =IF(1<$G$3,0,SUMPRODUCT(--(ROW('04 变换后数据'!$D$5:$D$160)<=ROW()),--ISNUMBER(OFFSET('04 变换后数据'!$D$5:$D$160,ROW()-5-$G$3+1,0,MIN($G$3,ROW()-4),1)),--ISNUMBER(OFFSET('04 变换后数据'!$H$5:$H$160,ROW()-5-$G$3+1,0,MIN($G$3,ROW()-4),1)))) | I5: =IF(ISNUMBER(E5),IF(ABS(E5)>=0.7,"强",IF(ABS(E5)>=0.4,"中","弱")),"-")
A6: 2 | B6: ='04 变换后数据'!B6 | C6: =IF(2<$C$3,"",IF(46=0,"",IF(46<MAX(5,ROUND($C$3*0.8,0)),"样本不足",CORREL(OFFSET('04 变换后数据'!$D$5:$D$160,ROW()-5-$C$3+1,0,$C$3,1),OFFSET('04 变换后数据'!$H$5:$H$160,ROW()-5-$C$3+1,0,$C$3,1)))) | D6: =IF(2<$C$3,0,SUMPRODUCT(--(ROW('04 变换后数据'!$D$5:$D$160)<=ROW()),--ISNUMBER(OFFSET('04 变换后数据'!$D$5:$D$160,ROW()-5-$C$3+1,0,MIN($C$3,ROW()-4),1)),--ISNUMBER(OFFSET('04 变换后数据'!$H$5:$H$160,ROW()-5-$C$3+1,0,MIN($C$3,ROW()-4),1)))) | E6: =IF(2<$E$3,"",IF(66=0,"",IF(66<MAX(5,ROUND($E$3*0.8,0)),"样本不足",CORREL(OFFSET('04 变换后数据'!$D$5:$D$160,ROW()-5-$E$3+1,0,$E$3,1),OFFSET('04 变换后数据'!$H$5:$H$160,ROW()-5-$E$3+1,0,$E$3,1)))) | F6: =IF(2<$E$3,0,SUMPRODUCT(--(ROW('04 变换后数据'!$D$5:$D$160)<=ROW()),--ISNUMBER(OFFSET('04 变换后数据'!$D$5:$D$160,ROW()-5-$E$3+1,0,MIN($E$3,ROW()-4),1)),--ISNUMBER(OFFSET('04 变换后数据'!$H$5:$H$160,ROW()-5-$E$3+1,0,MIN($E$3,ROW()-4),1)))) | G6: =IF(2<$G$3,"",IF(86=0,"",IF(86<MAX(5,ROUND($G$3*0.8,0)),"样本不足",CORREL(OFFSET('04 变换后数据'!$D$5:$D$160,ROW()-5-$G$3+1,0,$G$3,1),OFFSET('04 变换后数据'!$H$5:$H$160,ROW()-5-$G$3+1,0,$G$3,1)))) | H6: =IF(2<$G$3,0,SUMPRODUCT(--(ROW('04 变换后数据'!$D$5:$D$160)<=ROW()),--ISNUMBER(OFFSET('04 变换后数据'!$D$5:$D$160,ROW()-5-$G$3+1,0,MIN($G$3,ROW()-4),1)),--ISNUMBER(OFFSET('04 变换后数据'!$H$5:$H$160,ROW()-5-$G$3+1,0,MIN($G$3,ROW()-4),1)))) | I6: =IF(ISNUMBER(E6),IF(ABS(E6)>=0.7,"强",IF(ABS(E6)>=0.4,"中","弱")),"-")
A7: 3 | B7: ='04 变换后数据'!B7 | C7: =IF(3<$C$3,"",IF(47=0,"",IF(47<MAX(5,ROUND($C$3*0.8,0)),"样本不足",CORREL(OFFSET('04 变换后数据'!$D$5:$D$160,ROW()-5-$C$3+1,0,$C$3,1),OFFSET('04 变换后数据'!$H$5:$H$160,ROW()-5-$C$3+1,0,$C$3,1)))) | D7: =IF(3<$C$3,0,SUMPRODUCT(--(ROW('04 变换后数据'!$D$5:$D$160)<=ROW()),--ISNUMBER(OFFSET('04 变换后数据'!$D$5:$D$160,ROW()-5-$C$3+1,0,MIN($C$3,ROW()-4),1)),--ISNUMBER(OFFSET('04 变换后数据'!$H$5:$H$160,ROW()-5-$C$3+1,0,MIN($C$3,ROW()-4),1)))) | E7: =IF(3<$E$3,"",IF(67=0,"",IF(67<MAX(5,ROUND($E$3*0.8,0)),"样本不足",CORREL(OFFSET('04 变换后数据'!$D$5:$D$160,ROW()-5-$E$3+1,0,$E$3,1),OFFSET('04 变换后数据'!$H$5:$H$160,ROW()-5-$E$3+1,0,$E$3,1)))) | F7: =IF(3<$E$3,0,SUMPRODUCT(--(ROW('04 变换后数据'!$D$5:$D$160)<=ROW()),--ISNUMBER(OFFSET('04 变换后数据'!$D$5:$D$160,ROW()-5-$E$3+1,0,MIN($E$3,ROW()-4),1)),--ISNUMBER(OFFSET('04 变换后数据'!$H$5:$H$160,ROW()-5-$E$3+1,0,MIN($E$3,ROW()-4),1)))) | G7: =IF(3<$G$3,"",IF(87=0,"",IF(87<MAX(5,ROUND($G$3*0.8,0)),"样本不足",CORREL(OFFSET('04 变换后数据'!$D$5:$D$160,ROW()-5-$G$3+1,0,$G$3,1),OFFSET('04 变换后数据'!$H$5:$H$160,ROW()-5-$G$3+1,0,$G$3,1)))) | H7: =IF(3<$G$3,0,SUMPRODUCT(--(ROW('04 变换后数据'!$D$5:$D$160)<=ROW()),--ISNUMBER(OFFSET('04 变换后数据'!$D$5:$D$160,ROW()-5-$G$3+1,0,MIN($G$3,ROW()-4),1)),--ISNUMBER(OFFSET('04 变换后数据'!$H$5:$H$160,ROW()-5-$G$3+1,0,MIN($G$3,ROW()-4),1)))) | I7: =IF(ISNUMBER(E7),IF(ABS(E7)>=0.7,"强",IF(ABS(E7)>=0.4,"中","弱")),"-")
A8: 4 | B8: ='04 变换后数据'!B8 | C8: =IF(4<$C$3,"",IF(48=0,"",IF(48<MAX(5,ROUND($C$3*0.8,0)),"样本不足",CORREL(OFFSET('04 变换后数据'!$D$5:$D$160,ROW()-5-$C$3+1,0,$C$3,1),OFFSET('04 变换后数据'!$H$5:$H$160,ROW()-5-$C$3+1,0,$C$3,1)))) | D8: =IF(4<$C$3,0,SUMPRODUCT(--(ROW('04 变换后数据'!$D$5:$D$160)<=ROW()),--ISNUMBER(OFFSET('04 变换后数据'!$D$5:$D$160,ROW()-5-$C$3+1,0,MIN($C$3,ROW()-4),1)),--ISNUMBER(OFFSET('04 变换后数据'!$H$5:$H$160,ROW()-5-$C$3+1,0,MIN($C$3,ROW()-4),1)))) | E8: =IF(4<$E$3,"",IF(68=0,"",IF(68<MAX(5,ROUND($E$3*0.8,0)),"样本不足",CORREL(OFFSET('04 变换后数据'!$D$5:$D$160,ROW()-5-$E$3+1,0,$E$3,1),OFFSET('04 变换后数据'!$H$5:$H$160,ROW()-5-$E$3+1,0,$E$3,1)))) | F8: =IF(4<$E$3,0,SUMPRODUCT(--(ROW('04 变换后数据'!$D$5:$D$160)<=ROW()),--ISNUMBER(OFFSET('04 变换后数据'!$D$5:$D$160,ROW()-5-$E$3+1,0,MIN($E$3,ROW()-4),1)),--ISNUMBER(OFFSET('04 变换后数据'!$H$5:$H$160,ROW()-5-$E$3+1,0,MIN($E$3,ROW()-4),1)))) | G8: =IF(4<$G$3,"",IF(88=0,"",IF(88<MAX(5,ROUND($G$3*0.8,0)),"样本不足",CORREL(OFFSET('04 变换后数据'!$D$5:$D$160,ROW()-5-$G$3+1,0,$G$3,1),OFFSET('04 变换后数据'!$H$5:$H$160,ROW()-5-$G$3+1,0,$G$3,1)))) | H8: =IF(4<$G$3,0,SUMPRODUCT(--(ROW('04 变换后数据'!$D$5:$D$160)<=ROW()),--ISNUMBER(OFFSET('04 变换后数据'!$D$5:$D$160,ROW()-5-$G$3+1,0,MIN($G$3,ROW()-4),1)),--ISNUMBER(OFFSET('04 变换后数据'!$H$5:$H$160,ROW()-5-$G$3+1,0,MIN($G$3,ROW()-4),1)))) | I8: =IF(ISNUMBER(E8),IF(ABS(E8)>=0.7,"强",IF(ABS(E8)>=0.4,"中","弱")),"-")
A9: 5 | B9: ='04 变换后数据'!B9 | C9: =IF(5<$C$3,"",IF(49=0,"",IF(49<MAX(5,ROUND($C$3*0.8,0)),"样本不足",CORREL(OFFSET('04 变换后数据'!$D$5:$D$160,ROW()-5-$C$3+1,0,$C$3,1),OFFSET('04 变换后数据'!$H$5:$H$160,ROW()-5-$C$3+1,0,$C$3,1)))) | D9: =IF(5<$C$3,0,SUMPRODUCT(--(ROW('04 变换后数据'!$D$5:$D$160)<=ROW()),--ISNUMBER(OFFSET('04 变换后数据'!$D$5:$D$160,ROW()-5-$C$3+1,0,MIN($C$3,ROW()-4),1)),--ISNUMBER(OFFSET('04 变换后数据'!$H$5:$H$160,ROW()-5-$C$3+1,0,MIN($C$3,ROW()-4),1)))) | E9: =IF(5<$E$3,"",IF(69=0,"",IF(69<MAX(5,ROUND($E$3*0.8,0)),"样本不足",CORREL(OFFSET('04 变换后数据'!$D$5:$D$160,ROW()-5-$E$3+1,0,$E$3,1),OFFSET('04 变换后数据'!$H$5:$H$160,ROW()-5-$E$3+1,0,$E$3,1)))) | F9: =IF(5<$E$3,0,SUMPRODUCT(--(ROW('04 变换后数据'!$D$5:$D$160)<=ROW()),--ISNUMBER(OFFSET('04 变换后数据'!$D$5:$D$160,ROW()-5-$E$3+1,0,MIN($E$3,ROW()-4),1)),--ISNUMBER(OFFSET('04 变换后数据'!$H$5:$H$160,ROW()-5-$E$3+1,0,MIN($E$3,ROW()-4),1)))) | G9: =IF(5<$G$3,"",IF(89=0,"",IF(89<MAX(5,ROUND($G$3*0.8,0)),"样本不足",CORREL(OFFSET('04 变换后数据'!$D$5:$D$160,ROW()-5-$G$3+1,0,$G$3,1),OFFSET('04 变换后数据'!$H$5:$H$160,ROW()-5-$G$3+1,0,$G$3,1)))) | H9: =IF(5<$G$3,0,SUMPRODUCT(--(ROW('04 变换后数据'!$D$5:$D$160)<=ROW()),--ISNUMBER(OFFSET('04 变换后数据'!$D$5:$D$160,ROW()-5-$G$3+1,0,MIN($G$3,ROW()-4),1)),--ISNUMBER(OFFSET('04 变换后数据'!$H$5:$H$160,ROW()-5-$G$3+1,0,MIN($G$3,ROW()-4),1)))) | I9: =IF(ISNUMBER(E9),IF(ABS(E9)>=0.7,"强",IF(ABS(E9)>=0.4,"中","弱")),"-")
A10: 6 | B10: ='04 变换后数据'!B10 | C10: =IF(6<$C$3,"",IF(410=0,"",IF(410<MAX(5,ROUND($C$3*0.8,0)),"样本不足",CORREL(OFFSET('04 变换后数据'!$D$5:$D$160,ROW()-5-$C$3+1,0,$C$3,1),OFFSET('04 变换后数据'!$H$5:$H$160,ROW()-5-$C$3+1,0,$C$3,1)))) | D10: =IF(6<$C$3,0,SUMPRODUCT(--(ROW('04 变换后数据'!$D$5:$D$160)<=ROW()),--ISNUMBER(OFFSET('04 变换后数据'!$D$5:$D$160,ROW()-5-$C$3+1,0,MIN($C$3,ROW()-4),1)),--ISNUMBER(OFFSET('04 变换后数据'!$H$5:$H$160,ROW()-5-$C$3+1,0,MIN($C$3,ROW()-4),1)))) | E10: =IF(6<$E$3,"",IF(610=0,"",IF(610<MAX(5,ROUND($E$3*0.8,0)),"样本不足",CORREL(OFFSET('04 变换后数据'!$D$5:$D$160,ROW()-5-$E$3+1,0,$E$3,1),OFFSET('04 变换后数据'!$H$5:$H$160,ROW()-5-$E$3+1,0,$E$3,1)))) | F10: =IF(6<$E$3,0,SUMPRODUCT(--(ROW('04 变换后数据'!$D$5:$D$160)<=ROW()),--ISNUMBER(OFFSET('04 变换后数据'!$D$5:$D$160,ROW()-5-$E$3+1,0,MIN($E$3,ROW()-4),1)),--ISNUMBER(OFFSET('04 变换后数据'!$H$5:$H$160,ROW()-5-$E$3+1,0,MIN($E$3,ROW()-4),1)))) | G10: =IF(6<$G$3,"",IF(810=0,"",IF(810<MAX(5,ROUND($G$3*0.8,0)),"样本不足",CORREL(OFFSET('04 变换后数据'!$D$5:$D$160,ROW()-5-$G$3+1,0,$G$3,1),OFFSET('04 变换后数据'!$H$5:$H$160,ROW()-5-$G$3+1,0,$G$3,1)))) | H10: =IF(6<$G$3,0,SUMPRODUCT(--(ROW('04 变换后数据'!$D$5:$D$160)<=ROW()),--ISNUMBER(OFFSET('04 变换后数据'!$D$5:$D$160,ROW()-5-$G$3+1,0,MIN($G$3,ROW()-4),1)),--ISNUMBER(OFFSET('04 变换后数据'!$H$5:$H$160,ROW()-5-$G$3+1,0,MIN($G$3,ROW()-4),1)))) | I10: =IF(ISNUMBER(E10),IF(ABS(E10)>=0.7,"强",IF(ABS(E10)>=0.4,"中","弱")),"-")
A11: 7 | B11: ='04 变换后数据'!B11 | C11: =IF(7<$C$3,"",IF(411=0,"",IF(411<MAX(5,ROUND($C$3*0.8,0)),"样本不足",CORREL(OFFSET('04 变换后数据'!$D$5:$D$160,ROW()-5-$C$3+1,0,$C$3,1),OFFSET('04 变换后数据'!$H$5:$H$160,ROW()-5-$C$3+1,0,$C$3,1)))) | D11: =IF(7<$C$3,0,SUMPRODUCT(--(ROW('04 变换后数据'!$D$5:$D$160)<=ROW()),--ISNUMBER(OFFSET('04 变换后数据'!$D$5:$D$160,ROW()-5-$C$3+1,0,MIN($C$3,ROW()-4),1)),--ISNUMBER(OFFSET('04 变换后数据'!$H$5:$H$160,ROW()-5-$C$3+1,0,MIN($C$3,ROW()-4),1)))) | E11: =IF(7<$E$3,"",IF(611=0,"",IF(611<MAX(5,ROUND($E$3*0.8,0)),"样本不足",CORREL(OFFSET('04 变换后数据'!$D$5:$D$160,ROW()-5-$E$3+1,0,$E$3,1),OFFSET('04 变换后数据'!$H$5:$H$160,ROW()-5-$E$3+1,0,$E$3,1)))) | F11: =IF(7<$E$3,0,SUMPRODUCT(--(ROW('04 变换后数据'!$D$5:$D$160)<=ROW()),--ISNUMBER(OFFSET('04 变换后数据'!$D$5:$D$160,ROW()-5-$E$3+1,0,MIN($E$3,ROW()-4),1)),--ISNUMBER(OFFSET('04 变换后数据'!$H$5:$H$160,ROW()-5-$E$3+1,0,MIN($E$3,ROW()-4),1)))) | G11: =IF(7<$G$3,"",IF(811=0,"",IF(811<MAX(5,ROUND($G$3*0.8,0)),"样本不足",CORREL(OFFSET('04 变换后数据'!$D$5:$D$160,ROW()-5-$G$3+1,0,$G$3,1),OFFSET('04 变换后数据'!$H$5:$H$160,ROW()-5-$G$3+1,0,$G$3,1)))) | H11: =IF(7<$G$3,0,SUMPRODUCT(--(ROW('04 变换后数据'!$D$5:$D$160)<=ROW()),--ISNUMBER(OFFSET('04 变换后数据'!$D$5:$D$160,ROW()-5-$G$3+1,0,MIN($G$3,ROW()-4),1)),--ISNUMBER(OFFSET('04 变换后数据'!$H$5:$H$160,ROW()-5-$G$3+1,0,MIN($G$3,ROW()-4),1)))) | I11: =IF(ISNUMBER(E11),IF(ABS(E11)>=0.7,"强",IF(ABS(E11)>=0.4,"中","弱")),"-")
A12: 8 | B12: ='04 变换后数据'!B12 | C12: =IF(8<$C$3,"",IF(412=0,"",IF(412<MAX(5,ROUND($C$3*0.8,0)),"样本不足",CORREL(OFFSET('04 变换后数据'!$D$5:$D$160,ROW()-5-$C$3+1,0,$C$3,1),OFFSET('04 变换后数据'!$H$5:$H$160,ROW()-5-$C$3+1,0,$C$3,1)))) | D12: =IF(8<$C$3,0,SUMPRODUCT(--(ROW('04 变换后数据'!$D$5:$D$160)<=ROW()),--ISNUMBER(OFFSET('04 变换后数据'!$D$5:$D$160,ROW()-5-$C$3+1,0,MIN($C$3,ROW()-4),1)),--ISNUMBER(OFFSET('04 变换后数据'!$H$5:$H$160,ROW()-5-$C$3+1,0,MIN($C$3,ROW()-4),1)))) | E12: =IF(8<$E$3,"",IF(612=0,"",IF(612<MAX(5,ROUND($E$3*0.8,0)),"样本不足",CORREL(OFFSET('04 变换后数据'!$D$5:$D$160,ROW()-5-$E$3+1,0,$E$3,1),OFFSET('04 变换后数据'!$H$5:$H$160,ROW()-5-$E$3+1,0,$E$3,1)))) | F12: =IF(8<$E$3,0,SUMPRODUCT(--(ROW('04 变换后数据'!$D$5:$D$160)<=ROW()),--ISNUMBER(OFFSET('04 变换后数据'!$D$5:$D$160,ROW()-5-$E$3+1,0,MIN($E$3,ROW()-4),1)),--ISNUMBER(OFFSET('04 变换后数据'!$H$5:$H$160,ROW()-5-$E$3+1,0,MIN($E$3,ROW()-4),1)))) | G12: =IF(8<$G$3,"",IF(812=0,"",IF(812<MAX(5,ROUND($G$3*0.8,0)),"样本不足",CORREL(OFFSET('04 变换后数据'!$D$5:$D$160,ROW()-5-$G$3+1,0,$G$3,1),OFFSET('04 变换后数据'!$H$5:$H$160,ROW()-5-$G$3+1,0,$G$3,1)))) | H12: =IF(8<$G$3,0,SUMPRODUCT(--(ROW('04 变换后数据'!$D$5:$D$160)<=ROW()),--ISNUMBER(OFFSET('04 变换后数据'!$D$5:$D$160,ROW()-5-$G$3+1,0,MIN($G$3,ROW()-4),1)),--ISNUMBER(OFFSET('04 变换后数据'!$H$5:$H$160,ROW()-5-$G$3+1,0,MIN($G$3,ROW()-4),1)))) | I12: =IF(ISNUMBER(E12),IF(ABS(E12)>=0.7,"强",IF(ABS(E12)>=0.4,"中","弱")),"-")
A13: 9 | B13: ='04 变换后数据'!B13 | C13: =IF(9<$C$3,"",IF(413=0,"",IF(413<MAX(5,ROUND($C$3*0.8,0)),"样本不足",CORREL(OFFSET('04 变换后数据'!$D$5:$D$160,ROW()-5-$C$3+1,0,$C$3,1),OFFSET('04 变换后数据'!$H$5:$H$160,ROW()-5-$C$3+1,0,$C$3,1)))) | D13: =IF(9<$C$3,0,SUMPRODUCT(--(ROW('04 变换后数据'!$D$5:$D$160)<=ROW()),--ISNUMBER(OFFSET('04 变换后数据'!$D$5:$D$160,ROW()-5-$C$3+1,0,MIN($C$3,ROW()-4),1)),--ISNUMBER(OFFSET('04 变换后数据'!$H$5:$H$160,ROW()-5-$C$3+1,0,MIN($C$3,ROW()-4),1)))) | E13: =IF(9<$E$3,"",IF(613=0,"",IF(613<MAX(5,ROUND($E$3*0.8,0)),"样本不足",CORREL(OFFSET('04 变换后数据'!$D$5:$D$160,ROW()-5-$E$3+1,0,$E$3,1),OFFSET('04 变换后数据'!$H$5:$H$160,ROW()-5-$E$3+1,0,$E$3,1)))) | F13: =IF(9<$E$3,0,SUMPRODUCT(--(ROW('04 变换后数据'!$D$5:$D$160)<=ROW()),--ISNUMBER(OFFSET('04 变换后数据'!$D$5:$D$160,ROW()-5-$E$3+1,0,MIN($E$3,ROW()-4),1)),--ISNUMBER(OFFSET('04 变换后数据'!$H$5:$H$160,ROW()-5-$E$3+1,0,MIN($E$3,ROW()-4),1)))) | G13: =IF(9<$G$3,"",IF(813=0,"",IF(813<MAX(5,ROUND($G$3*0.8,0)),"样本不足",CORREL(OFFSET('04 变换后数据'!$D$5:$D$160,ROW()-5-$G$3+1,0,$G$3,1),OFFSET('04 变换后数据'!$H$5:$H$160,ROW()-5-$G$3+1,0,$G$3,1)))) | H13: =IF(9<$G$3,0,SUMPRODUCT(--(ROW('04 变换后数据'!$D$5:$D$160)<=ROW()),--ISNUMBER(OFFSET('04 变换后数据'!$D$5:$D$160,ROW()-5-$G$3+1,0,MIN($G$3,ROW()-4),1)),--ISNUMBER(OFFSET('04 变换后数据'!$H$5:$H$160,ROW()-5-$G$3+1,0,MIN($G$3,ROW()-4),1)))) | I13: =IF(ISNUMBER(E13),IF(ABS(E13)>=0.7,"强",IF(ABS(E13)>=0.4,"中","弱")),"-")
A14: 10 | B14: ='04 变换后数据'!B14 | C14: =IF(10<$C$3,"",IF(414=0,"",IF(414<MAX(5,ROUND($C$3*0.8,0)),"样本不足",CORREL(OFFSET('04 变换后数据'!$D$5:$D$160,ROW()-5-$C$3+1,0,$C$3,1),OFFSET('04 变换后数据'!$H$5:$H$160,ROW()-5-$C$3+1,0,$C$3,1)))) | D14: =IF(10<$C$3,0,SUMPRODUCT(--(ROW('04 变换后数据'!$D$5:$D$160)<=ROW()),--ISNUMBER(OFFSET('04 变换后数据'!$D$5:$D$160,ROW()-5-$C$3+1,0,MIN($C$3,ROW()-4),1)),--ISNUMBER(OFFSET('04 变换后数据'!$H$5:$H$160,ROW()-5-$C$3+1,0,MIN($C$3,ROW()-4),1)))) | E14: =IF(10<$E$3,"",IF(614=0,"",IF(614<MAX(5,ROUND($E$3*0.8,0)),"样本不足",CORREL(OFFSET('04 变换后数据'!$D$5:$D$160,ROW()-5-$E$3+1,0,$E$3,1),OFFSET('04 变换后数据'!$H$5:$H$160,ROW()-5-$E$3+1,0,$E$3,1)))) | F14: =IF(10<$E$3,0,SUMPRODUCT(--(ROW('04 变换后数据'!$D$5:$D$160)<=ROW()),--ISNUMBER(OFFSET('04 变换后数据'!$D$5:$D$160,ROW()-5-$E$3+1,0,MIN($E$3,ROW()-4),1)),--ISNUMBER(OFFSET('04 变换后数据'!$H$5:$H$160,ROW()-5-$E$3+1,0,MIN($E$3,ROW()-4),1)))) | G14: =IF(10<$G$3,"",IF(814=0,"",IF(814<MAX(5,ROUND($G$3*0.8,0)),"样本不足",CORREL(OFFSET('04 变换后数据'!$D$5:$D$160,ROW()-5-$G$3+1,0,$G$3,1),OFFSET('04 变换后数据'!$H$5:$H$160,ROW()-5-$G$3+1,0,$G$3,1)))) | H14: =IF(10<$G$3,0,SUMPRODUCT(--(ROW('04 变换后数据'!$D$5:$D$160)<=ROW()),--ISNUMBER(OFFSET('04 变换后数据'!$D$5:$D$160,ROW()-5-$G$3+1,0,MIN($G$3,ROW()-4),1)),--ISNUMBER(OFFSET('04 变换后数据'!$H$5:$H$160,ROW()-5-$G$3+1,0,MIN($G$3,ROW()-4),1)))) | I14: =IF(ISNUMBER(E14),IF(ABS(E14)>=0.7,"强",IF(ABS(E14)>=0.4,"中","弱")),"-")
A15: 11 | B15: ='04 变换后数据'!B15 | C15: =IF(11<$C$3,"",IF(415=0,"",IF(415<MAX(5,ROUND($C$3*0.8,0)),"样本不足",CORREL(OFFSET('04 变换后数据'!$D$5:$D$160,ROW()-5-$C$3+1,0,$C$3,1),OFFSET('04 变换后数据'!$H$5:$H$160,ROW()-5-$C$3+1,0,$C$3,1)))) | D15: =IF(11<$C$3,0,SUMPRODUCT(--(ROW('04 变换后数据'!$D$5:$D$160)<=ROW()),--ISNUMBER(OFFSET('04 变换后数据'!$D$5:$D$160,ROW()-5-$C$3+1,0,MIN($C$3,ROW()-4),1)),--ISNUMBER(OFFSET('04 变换后数据'!$H$5:$H$160,ROW()-5-$C$3+1,0,MIN($C$3,ROW()-4),1)))) | E15: =IF(11<$E$3,"",IF(615=0,"",IF(615<MAX(5,ROUND($E$3*0.8,0)),"样本不足",CORREL(OFFSET('04 变换后数据'!$D$5:$D$160,ROW()-5-$E$3+1,0,$E$3,1),OFFSET('04 变换后数据'!$H$5:$H$160,ROW()-5-$E$3+1,0,$E$3,1)))) | F15: =IF(11<$E$3,0,SUMPRODUCT(--(ROW('04 变换后数据'!$D$5:$D$160)<=ROW()),--ISNUMBER(OFFSET('04 变换后数据'!$D$5:$D$160,ROW()-5-$E$3+1,0,MIN($E$3,ROW()-4),1)),--ISNUMBER(OFFSET('04 变换后数据'!$H$5:$H$160,ROW()-5-$E$3+1,0,MIN($E$3,ROW()-4),1)))) | G15: =IF(11<$G$3,"",IF(815=0,"",IF(815<MAX(5,ROUND($G$3*0.8,0)),"样本不足",CORREL(OFFSET('04 变换后数据'!$D$5:$D$160,ROW()-5-$G$3+1,0,$G$3,1),OFFSET('04 变换后数据'!$H$5:$H$160,ROW()-5-$G$3+1,0,$G$3,1)))) | H15: =IF(11<$G$3,0,SUMPRODUCT(--(ROW('04 变换后数据'!$D$5:$D$160)<=ROW()),--ISNUMBER(OFFSET('04 变换后数据'!$D$5:$D$160,ROW()-5-$G$3+1,0,MIN($G$3,ROW()-4),1)),--ISNUMBER(OFFSET('04 变换后数据'!$H$5:$H$160,ROW()-5-$G$3+1,0,MIN($G$3,ROW()-4),1)))) | I15: =IF(ISNUMBER(E15),IF(ABS(E15)>=0.7,"强",IF(ABS(E15)>=0.4,"中","弱")),"-")
A16: 12 | B16: ='04 变换后数据'!B16 | C16: =IF(12<$C$3,"",IF(416=0,"",IF(416<MAX(5,ROUND($C$3*0.8,0)),"样本不足",CORREL(OFFSET('04 变换后数据'!$D$5:$D$160,ROW()-5-$C$3+1,0,$C$3,1),OFFSET('04 变换后数据'!$H$5:$H$160,ROW()-5-$C$3+1,0,$C$3,1)))) | D16: =IF(12<$C$3,0,SUMPRODUCT(--(ROW('04 变换后数据'!$D$5:$D$160)<=ROW()),--ISNUMBER(OFFSET('04 变换后数据'!$D$5:$D$160,ROW()-5-$C$3+1,0,MIN($C$3,ROW()-4),1)),--ISNUMBER(OFFSET('04 变换后数据'!$H$5:$H$160,ROW()-5-$C$3+1,0,MIN($C$3,ROW()-4),1)))) | E16: =IF(12<$E$3,"",IF(616=0,"",IF(616<MAX(5,ROUND($E$3*0.8,0)),"样本不足",CORREL(OFFSET('04 变换后数据'!$D$5:$D$160,ROW()-5-$E$3+1,0,$E$3,1),OFFSET('04 变换后数据'!$H$5:$H$160,ROW()-5-$E$3+1,0,$E$3,1)))) | F16: =IF(12<$E$3,0,SUMPRODUCT(--(ROW('04 变换后数据'!$D$5:$D$160)<=ROW()),--ISNUMBER(OFFSET('04 变换后数据'!$D$5:$D$160,ROW()-5-$E$3+1,0,MIN($E$3,ROW()-4),1)),--ISNUMBER(OFFSET('04 变换后数据'!$H$5:$H$160,ROW()-5-$E$3+1,0,MIN($E$3,ROW()-4),1)))) | G16: =IF(12<$G$3,"",IF(816=0,"",IF(816<MAX(5,ROUND($G$3*0.8,0)),"样本不足",CORREL(OFFSET('04 变换后数据'!$D$5:$D$160,ROW()-5-$G$3+1,0,$G$3,1),OFFSET('04 变换后数据'!$H$5:$H$160,ROW()-5-$G$3+1,0,$G$3,1)))) | H16: =IF(12<$G$3,0,SUMPRODUCT(--(ROW('04 变换后数据'!$D$5:$D$160)<=ROW()),--ISNUMBER(OFFSET('04 变换后数据'!$D$5:$D$160,ROW()-5-$G$3+1,0,MIN($G$3,ROW()-4),1)),--ISNUMBER(OFFSET('04 变换后数据'!$H$5:$H$160,ROW()-5-$G$3+1,0,MIN($G$3,ROW()-4),1)))) | I16: =IF(ISNUMBER(E16),IF(ABS(E16)>=0.7,"强",IF(ABS(E16)>=0.4,"中","弱")),"-")
A17: 13 | B17: ='04 变换后数据'!B17 | C17: =IF(13<$C$3,"",IF(417=0,"",IF(417<MAX(5,ROUND($C$3*0.8,0)),"样本不足",CORREL(OFFSET('04 变换后数据'!$D$5:$D$160,ROW()-5-$C$3+1,0,$C$3,1),OFFSET('04 变换后数据'!$H$5:$H$160,ROW()-5-$C$3+1,0,$C$3,1)))) | D17: =IF(13<$C$3,0,SUMPRODUCT(--(ROW('04 变换后数据'!$D$5:$D$160)<=ROW()),--ISNUMBER(OFFSET('04 变换后数据'!$D$5:$D$160,ROW()-5-$C$3+1,0,MIN($C$3,ROW()-4),1)),--ISNUMBER(OFFSET('04 变换后数据'!$H$5:$H$160,ROW()-5-$C$3+1,0,MIN($C$3,ROW()-4),1)))) | E17: =IF(13<$E$3,"",IF(617=0,"",IF(617<MAX(5,ROUND($E$3*0.8,0)),"样本不足",CORREL(OFFSET('04 变换后数据'!$D$5:$D$160,ROW()-5-$E$3+1,0,$E$3,1),OFFSET('04 变换后数据'!$H$5:$H$160,ROW()-5-$E$3+1,0,$E$3,1)))) | F17: =IF(13<$E$3,0,SUMPRODUCT(--(ROW('04 变换后数据'!$D$5:$D$160)<=ROW()),--ISNUMBER(OFFSET('04 变换后数据'!$D$5:$D$160,ROW()-5-$E$3+1,0,MIN($E$3,ROW()-4),1)),--ISNUMBER(OFFSET('04 变换后数据'!$H$5:$H$160,ROW()-5-$E$3+1,0,MIN($E$3,ROW()-4),1)))) | G17: =IF(13<$G$3,"",IF(817=0,"",IF(817<MAX(5,ROUND($G$3*0.8,0)),"样本不足",CORREL(OFFSET('04 变换后数据'!$D$5:$D$160,ROW()-5-$G$3+1,0,$G$3,1),OFFSET('04 变换后数据'!$H$5:$H$160,ROW()-5-$G$3+1,0,$G$3,1)))) | H17: =IF(13<$G$3,0,SUMPRODUCT(--(ROW('04 变换后数据'!$D$5:$D$160)<=ROW()),--ISNUMBER(OFFSET('04 变换后数据'!$D$5:$D$160,ROW()-5-$G$3+1,0,MIN($G$3,ROW()-4),1)),--ISNUMBER(OFFSET('04 变换后数据'!$H$5:$H$160,ROW()-5-$G$3+1,0,MIN($G$3,ROW()-4),1)))) | I17: =IF(ISNUMBER(E17),IF(ABS(E17)>=0.7,"强",IF(ABS(E17)>=0.4,"中","弱")),"-")
A18: 14 | B18: ='04 变换后数据'!B18 | C18: =IF(14<$C$3,"",IF(418=0,"",IF(418<MAX(5,ROUND($C$3*0.8,0)),"样本不足",CORREL(OFFSET('04 变换后数据'!$D$5:$D$160,ROW()-5-$C$3+1,0,$C$3,1),OFFSET('04 变换后数据'!$H$5:$H$160,ROW()-5-$C$3+1,0,$C$3,1)))) | D18: =IF(14<$C$3,0,SUMPRODUCT(--(ROW('04 变换后数据'!$D$5:$D$160)<=ROW()),--ISNUMBER(OFFSET('04 变换后数据'!$D$5:$D$160,ROW()-5-$C$3+1,0,MIN($C$3,ROW()-4),1)),--ISNUMBER(OFFSET('04 变换后数据'!$H$5:$H$160,ROW()-5-$C$3+1,0,MIN($C$3,ROW()-4),1)))) | E18: =IF(14<$E$3,"",IF(618=0,"",IF(618<MAX(5,ROUND($E$3*0.8,0)),"样本不足",CORREL(OFFSET('04 变换后数据'!$D$5:$D$160,ROW()-5-$E$3+1,0,$E$3,1),OFFSET('04 变换后数据'!$H$5:$H$160,ROW()-5-$E$3+1,0,$E$3,1)))) | F18: =IF(14<$E$3,0,SUMPRODUCT(--(ROW('04 变换后数据'!$D$5:$D$160)<=ROW()),--ISNUMBER(OFFSET('04 变换后数据'!$D$5:$D$160,ROW()-5-$E$3+1,0,MIN($E$3,ROW()-4),1)),--ISNUMBER(OFFSET('04 变换后数据'!$H$5:$H$160,ROW()-5-$E$3+1,0,MIN($E$3,ROW()-4),1)))) | G18: =IF(14<$G$3,"",IF(818=0,"",IF(818<MAX(5,ROUND($G$3*0.8,0)),"样本不足",CORREL(OFFSET('04 变换后数据'!$D$5:$D$160,ROW()-5-$G$3+1,0,$G$3,1),OFFSET('04 变换后数据'!$H$5:$H$160,ROW()-5-$G$3+1,0,$G$3,1)))) | H18: =IF(14<$G$3,0,SUMPRODUCT(--(ROW('04 变换后数据'!$D$5:$D$160)<=ROW()),--ISNUMBER(OFFSET('04 变换后数据'!$D$5:$D$160,ROW()-5-$G$3+1,0,MIN($G$3,ROW()-4),1)),--ISNUMBER(OFFSET('04 变换后数据'!$H$5:$H$160,ROW()-5-$G$3+1,0,MIN($G$3,ROW()-4),1)))) | I18: =IF(ISNUMBER(E18),IF(ABS(E18)>=0.7,"强",IF(ABS(E18)>=0.4,"中","弱")),"-")
A19: 15 | B19: ='04 变换后数据'!B19 | C19: =IF(15<$C$3,"",IF(419=0,"",IF(419<MAX(5,ROUND($C$3*0.8,0)),"样本不足",CORREL(OFFSET('04 变换后数据'!$D$5:$D$160,ROW()-5-$C$3+1,0,$C$3,1),OFFSET('04 变换后数据'!$H$5:$H$160,ROW()-5-$C$3+1,0,$C$3,1)))) | D19: =IF(15<$C$3,0,SUMPRODUCT(--(ROW('04 变换后数据'!$D$5:$D$160)<=ROW()),--ISNUMBER(OFFSET('04 变换后数据'!$D$5:$D$160,ROW()-5-$C$3+1,0,MIN($C$3,ROW()-4),1)),--ISNUMBER(OFFSET('04 变换后数据'!$H$5:$H$160,ROW()-5-$C$3+1,0,MIN($C$3,ROW()-4),1)))) | E19: =IF(15<$E$3,"",IF(619=0,"",IF(619<MAX(5,ROUND($E$3*0.8,0)),"样本不足",CORREL(OFFSET('04 变换后数据'!$D$5:$D$160,ROW()-5-$E$3+1,0,$E$3,1),OFFSET('04 变换后数据'!$H$5:$H$160,ROW()-5-$E$3+1,0,$E$3,1)))) | F19: =IF(15<$E$3,0,SUMPRODUCT(--(ROW('04 变换后数据'!$D$5:$D$160)<=ROW()),--ISNUMBER(OFFSET('04 变换后数据'!$D$5:$D$160,ROW()-5-$E$3+1,0,MIN($E$3,ROW()-4),1)),--ISNUMBER(OFFSET('04 变换后数据'!$H$5:$H$160,ROW()-5-$E$3+1,0,MIN($E$3,ROW()-4),1)))) | G19: =IF(15<$G$3,"",IF(819=0,"",IF(819<MAX(5,ROUND($G$3*0.8,0)),"样本不足",CORREL(OFFSET('04 变换后数据'!$D$5:$D$160,ROW()-5-$G$3+1,0,$G$3,1),OFFSET('04 变换后数据'!$H$5:$H$160,ROW()-5-$G$3+1,0,$G$3,1)))) | H19: =IF(15<$G$3,0,SUMPRODUCT(--(ROW('04 变换后数据'!$D$5:$D$160)<=ROW()),--ISNUMBER(OFFSET('04 变换后数据'!$D$5:$D$160,ROW()-5-$G$3+1,0,MIN($G$3,ROW()-4),1)),--ISNUMBER(OFFSET('04 变换后数据'!$H$5:$H$160,ROW()-5-$G$3+1,0,MIN($G$3,ROW()-4),1)))) | I19: =IF(ISNUMBER(E19),IF(ABS(E19)>=0.7,"强",IF(ABS(E19)>=0.4,"中","弱")),"-")
A20: 16 | B20: ='04 变换后数据'!B20 | C20: =IF(16<$C$3,"",IF(420=0,"",IF(420<MAX(5,ROUND($C$3*0.8,0)),"样本不足",CORREL(OFFSET('04 变换后数据'!$D$5:$D$160,ROW()-5-$C$3+1,0,$C$3,1),OFFSET('04 变换后数据'!$H$5:$H$160,ROW()-5-$C$3+1,0,$C$3,1)))) | D20: =IF(16<$C$3,0,SUMPRODUCT(--(ROW('04 变换后数据'!$D$5:$D$160)<=ROW()),--ISNUMBER(OFFSET('04 变换后数据'!$D$5:$D$160,ROW()-5-$C$3+1,0,MIN($C$3,ROW()-4),1)),--ISNUMBER(OFFSET('04 变换后数据'!$H$5:$H$160,ROW()-5-$C$3+1,0,MIN($C$3,ROW()-4),1)))) | E20: =IF(16<$E$3,"",IF(620=0,"",IF(620<MAX(5,ROUND($E$3*0.8,0)),"样本不足",CORREL(OFFSET('04 变换后数据'!$D$5:$D$160,ROW()-5-$E$3+1,0,$E$3,1),OFFSET('04 变换后数据'!$H$5:$H$160,ROW()-5-$E$3+1,0,$E$3,1)))) | F20: =IF(16<$E$3,0,SUMPRODUCT(--(ROW('04 变换后数据'!$D$5:$D$160)<=ROW()),--ISNUMBER(OFFSET('04 变换后数据'!$D$5:$D$160,ROW()-5-$E$3+1,0,MIN($E$3,ROW()-4),1)),--ISNUMBER(OFFSET('04 变换后数据'!$H$5:$H$160,ROW()-5-$E$3+1,0,MIN($E$3,ROW()-4),1)))) | G20: =IF(16<$G$3,"",IF(820=0,"",IF(820<MAX(5,ROUND($G$3*0.8,0)),"样本不足",CORREL(OFFSET('04 变换后数据'!$D$5:$D$160,ROW()-5-$G$3+1,0,$G$3,1),OFFSET('04 变换后数据'!$H$5:$H$160,ROW()-5-$G$3+1,0,$G$3,1)))) | H20: =IF(16<$G$3,0,SUMPRODUCT(--(ROW('04 变换后数据'!$D$5:$D$160)<=ROW()),--ISNUMBER(OFFSET('04 变换后数据'!$D$5:$D$160,ROW()-5-$G$3+1,0,MIN($G$3,ROW()-4),1)),--ISNUMBER(OFFSET('04 变换后数据'!$H$5:$H$160,ROW()-5-$G$3+1,0,MIN($G$3,ROW()-4),1)))) | I20: =IF(ISNUMBER(E20),IF(ABS(E20)>=0.7,"强",IF(ABS(E20)>=0.4,"中","弱")),"-")
A21: 17 | B21: ='04 变换后数据'!B21 | C21: =IF(17<$C$3,"",IF(421=0,"",IF(421<MAX(5,ROUND($C$3*0.8,0)),"样本不足",CORREL(OFFSET('04 变换后数据'!$D$5:$D$160,ROW()-5-$C$3+1,0,$C$3,1),OFFSET('04 变换后数据'!$H$5:$H$160,ROW()-5-$C$3+1,0,$C$3,1)))) | D21: =IF(17<$C$3,0,SUMPRODUCT(--(ROW('04 变换后数据'!$D$5:$D$160)<=ROW()),--ISNUMBER(OFFSET('04 变换后数据'!$D$5:$D$160,ROW()-5-$C$3+1,0,MIN($C$3,ROW()-4),1)),--ISNUMBER(OFFSET('04 变换后数据'!$H$5:$H$160,ROW()-5-$C$3+1,0,MIN($C$3,ROW()-4),1)))) | E21: =IF(17<$E$3,"",IF(621=0,"",IF(621<MAX(5,ROUND($E$3*0.8,0)),"样本不足",CORREL(OFFSET('04 变换后数据'!$D$5:$D$160,ROW()-5-$E$3+1,0,$E$3,1),OFFSET('04 变换后数据'!$H$5:$H$160,ROW()-5-$E$3+1,0,$E$3,1)))) | F21: =IF(17<$E$3,0,SUMPRODUCT(--(ROW('04 变换后数据'!$D$5:$D$160)<=ROW()),--ISNUMBER(OFFSET('04 变换后数据'!$D$5:$D$160,ROW()-5-$E$3+1,0,MIN($E$3,ROW()-4),1)),--ISNUMBER(OFFSET('04 变换后数据'!$H$5:$H$160,ROW()-5-$E$3+1,0,MIN($E$3,ROW()-4),1)))) | G21: =IF(17<$G$3,"",IF(821=0,"",IF(821<MAX(5,ROUND($G$3*0.8,0)),"样本不足",CORREL(OFFSET('04 变换后数据'!$D$5:$D$160,ROW()-5-$G$3+1,0,$G$3,1),OFFSET('04 变换后数据'!$H$5:$H$160,ROW()-5-$G$3+1,0,$G$3,1)))) | H21: =IF(17<$G$3,0,SUMPRODUCT(--(ROW('04 变换后数据'!$D$5:$D$160)<=ROW()),--ISNUMBER(OFFSET('04 变换后数据'!$D$5:$D$160,ROW()-5-$G$3+1,0,MIN($G$3,ROW()-4),1)),--ISNUMBER(OFFSET('04 变换后数据'!$H$5:$H$160,ROW()-5-$G$3+1,0,MIN($G$3,ROW()-4),1)))) | I21: =IF(ISNUMBER(E21),IF(ABS(E21)>=0.7,"强",IF(ABS(E21)>=0.4,"中","弱")),"-")
A22: 18 | B22: ='04 变换后数据'!B22 | C22: =IF(18<$C$3,"",IF(422=0,"",IF(422<MAX(5,ROUND($C$3*0.8,0)),"样本不足",CORREL(OFFSET('04 变换后数据'!$D$5:$D$160,ROW()-5-$C$3+1,0,$C$3,1),OFFSET('04 变换后数据'!$H$5:$H$160,ROW()-5-$C$3+1,0,$C$3,1)))) | D22: =IF(18<$C$3,0,SUMPRODUCT(--(ROW('04 变换后数据'!$D$5:$D$160)<=ROW()),--ISNUMBER(OFFSET('04 变换后数据'!$D$5:$D$160,ROW()-5-$C$3+1,0,MIN($C$3,ROW()-4),1)),--ISNUMBER(OFFSET('04 变换后数据'!$H$5:$H$160,ROW()-5-$C$3+1,0,MIN($C$3,ROW()-4),1)))) | E22: =IF(18<$E$3,"",IF(622=0,"",IF(622<MAX(5,ROUND($E$3*0.8,0)),"样本不足",CORREL(OFFSET('04 变换后数据'!$D$5:$D$160,ROW()-5-$E$3+1,0,$E$3,1),OFFSET('04 变换后数据'!$H$5:$H$160,ROW()-5-$E$3+1,0,$E$3,1)))) | F22: =IF(18<$E$3,0,SUMPRODUCT(--(ROW('04 变换后数据'!$D$5:$D$160)<=ROW()),--ISNUMBER(OFFSET('04 变换后数据'!$D$5:$D$160,ROW()-5-$E$3+1,0,MIN($E$3,ROW()-4),1)),--ISNUMBER(OFFSET('04 变换后数据'!$H$5:$H$160,ROW()-5-$E$3+1,0,MIN($E$3,ROW()-4),1)))) | G22: =IF(18<$G$3,"",IF(822=0,"",IF(822<MAX(5,ROUND($G$3*0.8,0)),"样本不足",CORREL(OFFSET('04 变换后数据'!$D$5:$D$160,ROW()-5-$G$3+1,0,$G$3,1),OFFSET('04 变换后数据'!$H$5:$H$160,ROW()-5-$G$3+1,0,$G$3,1)))) | H22: =IF(18<$G$3,0,SUMPRODUCT(--(ROW('04 变换后数据'!$D$5:$D$160)<=ROW()),--ISNUMBER(OFFSET('04 变换后数据'!$D$5:$D$160,ROW()-5-$G$3+1,0,MIN($G$3,ROW()-4),1)),--ISNUMBER(OFFSET('04 变换后数据'!$H$5:$H$160,ROW()-5-$G$3+1,0,MIN($G$3,ROW()-4),1)))) | I22: =IF(ISNUMBER(E22),IF(ABS(E22)>=0.7,"强",IF(ABS(E22)>=0.4,"中","弱")),"-")
A23: 19 | B23: ='04 变换后数据'!B23 | C23: =IF(19<$C$3,"",IF(423=0,"",IF(423<MAX(5,ROUND($C$3*0.8,0)),"样本不足",CORREL(OFFSET('04 变换后数据'!$D$5:$D$160,ROW()-5-$C$3+1,0,$C$3,1),OFFSET('04 变换后数据'!$H$5:$H$160,ROW()-5-$C$3+1,0,$C$3,1)))) | D23: =IF(19<$C$3,0,SUMPRODUCT(--(ROW('04 变换后数据'!$D$5:$D$160)<=ROW()),--ISNUMBER(OFFSET('04 变换后数据'!$D$5:$D$160,ROW()-5-$C$3+1,0,MIN($C$3,ROW()-4),1)),--ISNUMBER(OFFSET('04 变换后数据'!$H$5:$H$160,ROW()-5-$C$3+1,0,MIN($C$3,ROW()-4),1)))) | E23: =IF(19<$E$3,"",IF(623=0,"",IF(623<MAX(5,ROUND($E$3*0.8,0)),"样本不足",CORREL(OFFSET('04 变换后数据'!$D$5:$D$160,ROW()-5-$E$3+1,0,$E$3,1),OFFSET('04 变换后数据'!$H$5:$H$160,ROW()-5-$E$3+1,0,$E$3,1)))) | F23: =IF(19<$E$3,0,SUMPRODUCT(--(ROW('04 变换后数据'!$D$5:$D$160)<=ROW()),--ISNUMBER(OFFSET('04 变换后数据'!$D$5:$D$160,ROW()-5-$E$3+1,0,MIN($E$3,ROW()-4),1)),--ISNUMBER(OFFSET('04 变换后数据'!$H$5:$H$160,ROW()-5-$E$3+1,0,MIN($E$3,ROW()-4),1)))) | G23: =IF(19<$G$3,"",IF(823=0,"",IF(823<MAX(5,ROUND($G$3*0.8,0)),"样本不足",CORREL(OFFSET('04 变换后数据'!$D$5:$D$160,ROW()-5-$G$3+1,0,$G$3,1),OFFSET('04 变换后数据'!$H$5:$H$160,ROW()-5-$G$3+1,0,$G$3,1)))) | H23: =IF(19<$G$3,0,SUMPRODUCT(--(ROW('04 变换后数据'!$D$5:$D$160)<=ROW()),--ISNUMBER(OFFSET('04 变换后数据'!$D$5:$D$160,ROW()-5-$G$3+1,0,MIN($G$3,ROW()-4),1)),--ISNUMBER(OFFSET('04 变换后数据'!$H$5:$H$160,ROW()-5-$G$3+1,0,MIN($G$3,ROW()-4),1)))) | I23: =IF(ISNUMBER(E23),IF(ABS(E23)>=0.7,"强",IF(ABS(E23)>=0.4,"中","弱")),"-")
A24: 20 | B24: ='04 变换后数据'!B24 | C24: =IF(20<$C$3,"",IF(424=0,"",IF(424<MAX(5,ROUND($C$3*0.8,0)),"样本不足",CORREL(OFFSET('04 变换后数据'!$D$5:$D$160,ROW()-5-$C$3+1,0,$C$3,1),OFFSET('04 变换后数据'!$H$5:$H$160,ROW()-5-$C$3+1,0,$C$3,1)))) | D24: =IF(20<$C$3,0,SUMPRODUCT(--(ROW('04 变换后数据'!$D$5:$D$160)<=ROW()),--ISNUMBER(OFFSET('04 变换后数据'!$D$5:$D$160,ROW()-5-$C$3+1,0,MIN($C$3,ROW()-4),1)),--ISNUMBER(OFFSET('04 变换后数据'!$H$5:$H$160,ROW()-5-$C$3+1,0,MIN($C$3,ROW()-4),1)))) | E24: =IF(20<$E$3,"",IF(624=0,"",IF(624<MAX(5,ROUND($E$3*0.8,0)),"样本不足",CORREL(OFFSET('04 变换后数据'!$D$5:$D$160,ROW()-5-$E$3+1,0,$E$3,1),OFFSET('04 变换后数据'!$H$5:$H$160,ROW()-5-$E$3+1,0,$E$3,1)))) | F24: =IF(20<$E$3,0,SUMPRODUCT(--(ROW('04 变换后数据'!$D$5:$D$160)<=ROW()),--ISNUMBER(OFFSET('04 变换后数据'!$D$5:$D$160,ROW()-5-$E$3+1,0,MIN($E$3,ROW()-4),1)),--ISNUMBER(OFFSET('04 变换后数据'!$H$5:$H$160,ROW()-5-$E$3+1,0,MIN($E$3,ROW()-4),1)))) | G24: =IF(20<$G$3,"",IF(824=0,"",IF(824<MAX(5,ROUND($G$3*0.8,0)),"样本不足",CORREL(OFFSET('04 变换后数据'!$D$5:$D$160,ROW()-5-$G$3+1,0,$G$3,1),OFFSET('04 变换后数据'!$H$5:$H$160,ROW()-5-$G$3+1,0,$G$3,1)))) | H24: =IF(20<$G$3,0,SUMPRODUCT(--(ROW('04 变换后数据'!$D$5:$D$160)<=ROW()),--ISNUMBER(OFFSET('04 变换后数据'!$D$5:$D$160,ROW()-5-$G$3+1,0,MIN($G$3,ROW()-4),1)),--ISNUMBER(OFFSET('04 变换后数据'!$H$5:$H$160,ROW()-5-$G$3+1,0,MIN($G$3,ROW()-4),1)))) | I24: =IF(ISNUMBER(E24),IF(ABS(E24)>=0.7,"强",IF(ABS(E24)>=0.4,"中","弱")),"-")
A25: 21 | B25: ='04 变换后数据'!B25 | C25: =IF(21<$C$3,"",IF(425=0,"",IF(425<MAX(5,ROUND($C$3*0.8,0)),"样本不足",CORREL(OFFSET('04 变换后数据'!$D$5:$D$160,ROW()-5-$C$3+1,0,$C$3,1),OFFSET('04 变换后数据'!$H$5:$H$160,ROW()-5-$C$3+1,0,$C$3,1)))) | D25: =IF(21<$C$3,0,SUMPRODUCT(--(ROW('04 变换后数据'!$D$5:$D$160)<=ROW()),--ISNUMBER(OFFSET('04 变换后数据'!$D$5:$D$160,ROW()-5-$C$3+1,0,MIN($C$3,ROW()-4),1)),--ISNUMBER(OFFSET('04 变换后数据'!$H$5:$H$160,ROW()-5-$C$3+1,0,MIN($C$3,ROW()-4),1)))) | E25: =IF(21<$E$3,"",IF(625=0,"",IF(625<MAX(5,ROUND($E$3*0.8,0)),"样本不足",CORREL(OFFSET('04 变换后数据'!$D$5:$D$160,ROW()-5-$E$3+1,0,$E$3,1),OFFSET('04 变换后数据'!$H$5:$H$160,ROW()-5-$E$3+1,0,$E$3,1)))) | F25: =IF(21<$E$3,0,SUMPRODUCT(--(ROW('04 变换后数据'!$D$5:$D$160)<=ROW()),--ISNUMBER(OFFSET('04 变换后数据'!$D$5:$D$160,ROW()-5-$E$3+1,0,MIN($E$3,ROW()-4),1)),--ISNUMBER(OFFSET('04 变换后数据'!$H$5:$H$160,ROW()-5-$E$3+1,0,MIN($E$3,ROW()-4),1)))) | G25: =IF(21<$G$3,"",IF(825=0,"",IF(825<MAX(5,ROUND($G$3*0.8,0)),"样本不足",CORREL(OFFSET('04 变换后数据'!$D$5:$D$160,ROW()-5-$G$3+1,0,$G$3,1),OFFSET('04 变换后数据'!$H$5:$H$160,ROW()-5-$G$3+1,0,$G$3,1)))) | H25: =IF(21<$G$3,0,SUMPRODUCT(--(ROW('04 变换后数据'!$D$5:$D$160)<=ROW()),--ISNUMBER(OFFSET('04 变换后数据'!$D$5:$D$160,ROW()-5-$G$3+1,0,MIN($G$3,ROW()-4),1)),--ISNUMBER(OFFSET('04 变换后数据'!$H$5:$H$160,ROW()-5-$G$3+1,0,MIN($G$3,ROW()-4),1)))) | I25: =IF(ISNUMBER(E25),IF(ABS(E25)>=0.7,"强",IF(ABS(E25)>=0.4,"中","弱")),"-")
A26: 22 | B26: ='04 变换后数据'!B26 | C26: =IF(22<$C$3,"",IF(426=0,"",IF(426<MAX(5,ROUND($C$3*0.8,0)),"样本不足",CORREL(OFFSET('04 变换后数据'!$D$5:$D$160,ROW()-5-$C$3+1,0,$C$3,1),OFFSET('04 变换后数据'!$H$5:$H$160,ROW()-5-$C$3+1,0,$C$3,1)))) | D26: =IF(22<$C$3,0,SUMPRODUCT(--(ROW('04 变换后数据'!$D$5:$D$160)<=ROW()),--ISNUMBER(OFFSET('04 变换后数据'!$D$5:$D$160,ROW()-5-$C$3+1,0,MIN($C$3,ROW()-4),1)),--ISNUMBER(OFFSET('04 变换后数据'!$H$5:$H$160,ROW()-5-$C$3+1,0,MIN($C$3,ROW()-4),1)))) | E26: =IF(22<$E$3,"",IF(626=0,"",IF(626<MAX(5,ROUND($E$3*0.8,0)),"样本不足",CORREL(OFFSET('04 变换后数据'!$D$5:$D$160,ROW()-5-$E$3+1,0,$E$3,1),OFFSET('04 变换后数据'!$H$5:$H$160,ROW()-5-$E$3+1,0,$E$3,1)))) | F26: =IF(22<$E$3,0,SUMPRODUCT(--(ROW('04 变换后数据'!$D$5:$D$160)<=ROW()),--ISNUMBER(OFFSET('04 变换后数据'!$D$5:$D$160,ROW()-5-$E$3+1,0,MIN($E$3,ROW()-4),1)),--ISNUMBER(OFFSET('04 变换后数据'!$H$5:$H$160,ROW()-5-$E$3+1,0,MIN($E$3,ROW()-4),1)))) | G26: =IF(22<$G$3,"",IF(826=0,"",IF(826<MAX(5,ROUND($G$3*0.8,0)),"样本不足",CORREL(OFFSET('04 变换后数据'!$D$5:$D$160,ROW()-5-$G$3+1,0,$G$3,1),OFFSET('04 变换后数据'!$H$5:$H$160,ROW()-5-$G$3+1,0,$G$3,1)))) | H26: =IF(22<$G$3,0,SUMPRODUCT(--(ROW('04 变换后数据'!$D$5:$D$160)<=ROW()),--ISNUMBER(OFFSET('04 变换后数据'!$D$5:$D$160,ROW()-5-$G$3+1,0,MIN($G$3,ROW()-4),1)),--ISNUMBER(OFFSET('04 变换后数据'!$H$5:$H$160,ROW()-5-$G$3+1,0,MIN($G$3,ROW()-4),1)))) | I26: =IF(ISNUMBER(E26),IF(ABS(E26)>=0.7,"强",IF(ABS(E26)>=0.4,"中","弱")),"-")
A27: 23 | B27: ='04 变换后数据'!B27 | C27: =IF(23<$C$3,"",IF(427=0,"",IF(427<MAX(5,ROUND($C$3*0.8,0)),"样本不足",CORREL(OFFSET('04 变换后数据'!$D$5:$D$160,ROW()-5-$C$3+1,0,$C$3,1),OFFSET('04 变换后数据'!$H$5:$H$160,ROW()-5-$C$3+1,0,$C$3,1)))) | D27: =IF(23<$C$3,0,SUMPRODUCT(--(ROW('04 变换后数据'!$D$5:$D$160)<=ROW()),--ISNUMBER(OFFSET('04 变换后数据'!$D$5:$D$160,ROW()-5-$C$3+1,0,MIN($C$3,ROW()-4),1)),--ISNUMBER(OFFSET('04 变换后数据'!$H$5:$H$160,ROW()-5-$C$3+1,0,MIN($C$3,ROW()-4),1)))) | E27: =IF(23<$E$3,"",IF(627=0,"",IF(627<MAX(5,ROUND($E$3*0.8,0)),"样本不足",CORREL(OFFSET('04 变换后数据'!$D$5:$D$160,ROW()-5-$E$3+1,0,$E$3,1),OFFSET('04 变换后数据'!$H$5:$H$160,ROW()-5-$E$3+1,0,$E$3,1)))) | F27: =IF(23<$E$3,0,SUMPRODUCT(--(ROW('04 变换后数据'!$D$5:$D$160)<=ROW()),--ISNUMBER(OFFSET('04 变换后数据'!$D$5:$D$160,ROW()-5-$E$3+1,0,MIN($E$3,ROW()-4),1)),--ISNUMBER(OFFSET('04 变换后数据'!$H$5:$H$160,ROW()-5-$E$3+1,0,MIN($E$3,ROW()-4),1)))) | G27: =IF(23<$G$3,"",IF(827=0,"",IF(827<MAX(5,ROUND($G$3*0.8,0)),"样本不足",CORREL(OFFSET('04 变换后数据'!$D$5:$D$160,ROW()-5-$G$3+1,0,$G$3,1),OFFSET('04 变换后数据'!$H$5:$H$160,ROW()-5-$G$3+1,0,$G$3,1)))) | H27: =IF(23<$G$3,0,SUMPRODUCT(--(ROW('04 变换后数据'!$D$5:$D$160)<=ROW()),--ISNUMBER(OFFSET('04 变换后数据'!$D$5:$D$160,ROW()-5-$G$3+1,0,MIN($G$3,ROW()-4),1)),--ISNUMBER(OFFSET('04 变换后数据'!$H$5:$H$160,ROW()-5-$G$3+1,0,MIN($G$3,ROW()-4),1)))) | I27: =IF(ISNUMBER(E27),IF(ABS(E27)>=0.7,"强",IF(ABS(E27)>=0.4,"中","弱")),"-")
A28: 24 | B28: ='04 变换后数据'!B28 | C28: =IF(24<$C$3,"",IF(428=0,"",IF(428<MAX(5,ROUND($C$3*0.8,0)),"样本不足",CORREL(OFFSET('04 变换后数据'!$D$5:$D$160,ROW()-5-$C$3+1,0,$C$3,1),OFFSET('04 变换后数据'!$H$5:$H$160,ROW()-5-$C$3+1,0,$C$3,1)))) | D28: =IF(24<$C$3,0,SUMPRODUCT(--(ROW('04 变换后数据'!$D$5:$D$160)<=ROW()),--ISNUMBER(OFFSET('04 变换后数据'!$D$5:$D$160,ROW()-5-$C$3+1,0,MIN($C$3,ROW()-4),1)),--ISNUMBER(OFFSET('04 变换后数据'!$H$5:$H$160,ROW()-5-$C$3+1,0,MIN($C$3,ROW()-4),1)))) | E28: =IF(24<$E$3,"",IF(628=0,"",IF(628<MAX(5,ROUND($E$3*0.8,0)),"样本不足",CORREL(OFFSET('04 变换后数据'!$D$5:$D$160,ROW()-5-$E$3+1,0,$E$3,1),OFFSET('04 变换后数据'!$H$5:$H$160,ROW()-5-$E$3+1,0,$E$3,1)))) | F28: =IF(24<$E$3,0,SUMPRODUCT(--(ROW('04 变换后数据'!$D$5:$D$160)<=ROW()),--ISNUMBER(OFFSET('04 变换后数据'!$D$5:$D$160,ROW()-5-$E$3+1,0,MIN($E$3,ROW()-4),1)),--ISNUMBER(OFFSET('04 变换后数据'!$H$5:$H$160,ROW()-5-$E$3+1,0,MIN($E$3,ROW()-4),1)))) | G28: =IF(24<$G$3,"",IF(828=0,"",IF(828<MAX(5,ROUND($G$3*0.8,0)),"样本不足",CORREL(OFFSET('04 变换后数据'!$D$5:$D$160,ROW()-5-$G$3+1,0,$G$3,1),OFFSET('04 变换后数据'!$H$5:$H$160,ROW()-5-$G$3+1,0,$G$3,1)))) | H28: =IF(24<$G$3,0,SUMPRODUCT(--(ROW('04 变换后数据'!$D$5:$D$160)<=ROW()),--ISNUMBER(OFFSET('04 变换后数据'!$D$5:$D$160,ROW()-5-$G$3+1,0,MIN($G$3,ROW()-4),1)),--ISNUMBER(OFFSET('04 变换后数据'!$H$5:$H$160,ROW()-5-$G$3+1,0,MIN($G$3,ROW()-4),1)))) | I28: =IF(ISNUMBER(E28),IF(ABS(E28)>=0.7,"强",IF(ABS(E28)>=0.4,"中","弱")),"-")
A29: 25 | B29: ='04 变换后数据'!B29 | C29: =IF(25<$C$3,"",IF(429=0,"",IF(429<MAX(5,ROUND($C$3*0.8,0)),"样本不足",CORREL(OFFSET('04 变换后数据'!$D$5:$D$160,ROW()-5-$C$3+1,0,$C$3,1),OFFSET('04 变换后数据'!$H$5:$H$160,ROW()-5-$C$3+1,0,$C$3,1)))) | D29: =IF(25<$C$3,0,SUMPRODUCT(--(ROW('04 变换后数据'!$D$5:$D$160)<=ROW()),--ISNUMBER(OFFSET('04 变换后数据'!$D$5:$D$160,ROW()-5-$C$3+1,0,MIN($C$3,ROW()-4),1)),--ISNUMBER(OFFSET('04 变换后数据'!$H$5:$H$160,ROW()-5-$C$3+1,0,MIN($C$3,ROW()-4),1)))) | E29: =IF(25<$E$3,"",IF(629=0,"",IF(629<MAX(5,ROUND($E$3*0.8,0)),"样本不足",CORREL(OFFSET('04 变换后数据'!$D$5:$D$160,ROW()-5-$E$3+1,0,$E$3,1),OFFSET('04 变换后数据'!$H$5:$H$160,ROW()-5-$E$3+1,0,$E$3,1)))) | F29: =IF(25<$E$3,0,SUMPRODUCT(--(ROW('04 变换后数据'!$D$5:$D$160)<=ROW()),--ISNUMBER(OFFSET('04 变换后数据'!$D$5:$D$160,ROW()-5-$E$3+1,0,MIN($E$3,ROW()-4),1)),--ISNUMBER(OFFSET('04 变换后数据'!$H$5:$H$160,ROW()-5-$E$3+1,0,MIN($E$3,ROW()-4),1)))) | G29: =IF(25<$G$3,"",IF(829=0,"",IF(829<MAX(5,ROUND($G$3*0.8,0)),"样本不足",CORREL(OFFSET('04 变换后数据'!$D$5:$D$160,ROW()-5-$G$3+1,0,$G$3,1),OFFSET('04 变换后数据'!$H$5:$H$160,ROW()-5-$G$3+1,0,$G$3,1)))) | H29: =IF(25<$G$3,0,SUMPRODUCT(--(ROW('04 变换后数据'!$D$5:$D$160)<=ROW()),--ISNUMBER(OFFSET('04 变换后数据'!$D$5:$D$160,ROW()-5-$G$3+1,0,MIN($G$3,ROW()-4),1)),--ISNUMBER(OFFSET('04 变换后数据'!$H$5:$H$160,ROW()-5-$G$3+1,0,MIN($G$3,ROW()-4),1)))) | I29: =IF(ISNUMBER(E29),IF(ABS(E29)>=0.7,"强",IF(ABS(E29)>=0.4,"中","弱")),"-")
A30: 26 | B30: ='04 变换后数据'!B30 | C30: =IF(26<$C$3,"",IF(430=0,"",IF(430<MAX(5,ROUND($C$3*0.8,0)),"样本不足",CORREL(OFFSET('04 变换后数据'!$D$5:$D$160,ROW()-5-$C$3+1,0,$C$3,1),OFFSET('04 变换后数据'!$H$5:$H$160,ROW()-5-$C$3+1,0,$C$3,1)))) | D30: =IF(26<$C$3,0,SUMPRODUCT(--(ROW('04 变换后数据'!$D$5:$D$160)<=ROW()),--ISNUMBER(OFFSET('04 变换后数据'!$D$5:$D$160,ROW()-5-$C$3+1,0,MIN($C$3,ROW()-4),1)),--ISNUMBER(OFFSET('04 变换后数据'!$H$5:$H$160,ROW()-5-$C$3+1,0,MIN($C$3,ROW()-4),1)))) | E30: =IF(26<$E$3,"",IF(630=0,"",IF(630<MAX(5,ROUND($E$3*0.8,0)),"样本不足",CORREL(OFFSET('04 变换后数据'!$D$5:$D$160,ROW()-5-$E$3+1,0,$E$3,1),OFFSET('04 变换后数据'!$H$5:$H$160,ROW()-5-$E$3+1,0,$E$3,1)))) | F30: =IF(26<$E$3,0,SUMPRODUCT(--(ROW('04 变换后数据'!$D$5:$D$160)<=ROW()),--ISNUMBER(OFFSET('04 变换后数据'!$D$5:$D$160,ROW()-5-$E$3+1,0,MIN($E$3,ROW()-4),1)),--ISNUMBER(OFFSET('04 变换后数据'!$H$5:$H$160,ROW()-5-$E$3+1,0,MIN($E$3,ROW()-4),1)))) | G30: =IF(26<$G$3,"",IF(830=0,"",IF(830<MAX(5,ROUND($G$3*0.8,0)),"样本不足",CORREL(OFFSET('04 变换后数据'!$D$5:$D$160,ROW()-5-$G$3+1,0,$G$3,1),OFFSET('04 变换后数据'!$H$5:$H$160,ROW()-5-$G$3+1,0,$G$3,1)))) | H30: =IF(26<$G$3,0,SUMPRODUCT(--(ROW('04 变换后数据'!$D$5:$D$160)<=ROW()),--ISNUMBER(OFFSET('04 变换后数据'!$D$5:$D$160,ROW()-5-$G$3+1,0,MIN($G$3,ROW()-4),1)),--ISNUMBER(OFFSET('04 变换后数据'!$H$5:$H$160,ROW()-5-$G$3+1,0,MIN($G$3,ROW()-4),1)))) | I30: =IF(ISNUMBER(E30),IF(ABS(E30)>=0.7,"强",IF(ABS(E30)>=0.4,"中","弱")),"-")
A31: 27 | B31: ='04 变换后数据'!B31 | C31: =IF(27<$C$3,"",IF(431=0,"",IF(431<MAX(5,ROUND($C$3*0.8,0)),"样本不足",CORREL(OFFSET('04 变换后数据'!$D$5:$D$160,ROW()-5-$C$3+1,0,$C$3,1),OFFSET('04 变换后数据'!$H$5:$H$160,ROW()-5-$C$3+1,0,$C$3,1)))) | D31: =IF(27<$C$3,0,SUMPRODUCT(--(ROW('04 变换后数据'!$D$5:$D$160)<=ROW()),--ISNUMBER(OFFSET('04 变换后数据'!$D$5:$D$160,ROW()-5-$C$3+1,0,MIN($C$3,ROW()-4),1)),--ISNUMBER(OFFSET('04 变换后数据'!$H$5:$H$160,ROW()-5-$C$3+1,0,MIN($C$3,ROW()-4),1)))) | E31: =IF(27<$E$3,"",IF(631=0,"",IF(631<MAX(5,ROUND($E$3*0.8,0)),"样本不足",CORREL(OFFSET('04 变换后数据'!$D$5:$D$160,ROW()-5-$E$3+1,0,$E$3,1),OFFSET('04 变换后数据'!$H$5:$H$160,ROW()-5-$E$3+1,0,$E$3,1)))) | F31: =IF(27<$E$3,0,SUMPRODUCT(--(ROW('04 变换后数据'!$D$5:$D$160)<=ROW()),--ISNUMBER(OFFSET('04 变换后数据'!$D$5:$D$160,ROW()-5-$E$3+1,0,MIN($E$3,ROW()-4),1)),--ISNUMBER(OFFSET('04 变换后数据'!$H$5:$H$160,ROW()-5-$E$3+1,0,MIN($E$3,ROW()-4),1)))) | G31: =IF(27<$G$3,"",IF(831=0,"",IF(831<MAX(5,ROUND($G$3*0.8,0)),"样本不足",CORREL(OFFSET('04 变换后数据'!$D$5:$D$160,ROW()-5-$G$3+1,0,$G$3,1),OFFSET('04 变换后数据'!$H$5:$H$160,ROW()-5-$G$3+1,0,$G$3,1)))) | H31: =IF(27<$G$3,0,SUMPRODUCT(--(ROW('04 变换后数据'!$D$5:$D$160)<=ROW()),--ISNUMBER(OFFSET('04 变换后数据'!$D$5:$D$160,ROW()-5-$G$3+1,0,MIN($G$3,ROW()-4),1)),--ISNUMBER(OFFSET('04 变换后数据'!$H$5:$H$160,ROW()-5-$G$3+1,0,MIN($G$3,ROW()-4),1)))) | I31: =IF(ISNUMBER(E31),IF(ABS(E31)>=0.7,"强",IF(ABS(E31)>=0.4,"中","弱")),"-")
A32: 28 | B32: ='04 变换后数据'!B32 | C32: =IF(28<$C$3,"",IF(432=0,"",IF(432<MAX(5,ROUND($C$3*0.8,0)),"样本不足",CORREL(OFFSET('04 变换后数据'!$D$5:$D$160,ROW()-5-$C$3+1,0,$C$3,1),OFFSET('04 变换后数据'!$H$5:$H$160,ROW()-5-$C$3+1,0,$C$3,1)))) | D32: =IF(28<$C$3,0,SUMPRODUCT(--(ROW('04 变换后数据'!$D$5:$D$160)<=ROW()),--ISNUMBER(OFFSET('04 变换后数据'!$D$5:$D$160,ROW()-5-$C$3+1,0,MIN($C$3,ROW()-4),1)),--ISNUMBER(OFFSET('04 变换后数据'!$H$5:$H$160,ROW()-5-$C$3+1,0,MIN($C$3,ROW()-4),1)))) | E32: =IF(28<$E$3,"",IF(632=0,"",IF(632<MAX(5,ROUND($E$3*0.8,0)),"样本不足",CORREL(OFFSET('04 变换后数据'!$D$5:$D$160,ROW()-5-$E$3+1,0,$E$3,1),OFFSET('04 变换后数据'!$H$5:$H$160,ROW()-5-$E$3+1,0,$E$3,1)))) | F32: =IF(28<$E$3,0,SUMPRODUCT(--(ROW('04 变换后数据'!$D$5:$D$160)<=ROW()),--ISNUMBER(OFFSET('04 变换后数据'!$D$5:$D$160,ROW()-5-$E$3+1,0,MIN($E$3,ROW()-4),1)),--ISNUMBER(OFFSET('04 变换后数据'!$H$5:$H$160,ROW()-5-$E$3+1,0,MIN($E$3,ROW()-4),1)))) | G32: =IF(28<$G$3,"",IF(832=0,"",IF(832<MAX(5,ROUND($G$3*0.8,0)),"样本不足",CORREL(OFFSET('04 变换后数据'!$D$5:$D$160,ROW()-5-$G$3+1,0,$G$3,1),OFFSET('04 变换后数据'!$H$5:$H$160,ROW()-5-$G$3+1,0,$G$3,1)))) | H32: =IF(28<$G$3,0,SUMPRODUCT(--(ROW('04 变换后数据'!$D$5:$D$160)<=ROW()),--ISNUMBER(OFFSET('04 变换后数据'!$D$5:$D$160,ROW()-5-$G$3+1,0,MIN($G$3,ROW()-4),1)),--ISNUMBER(OFFSET('04 变换后数据'!$H$5:$H$160,ROW()-5-$G$3+1,0,MIN($G$3,ROW()-4),1)))) | I32: =IF(ISNUMBER(E32),IF(ABS(E32)>=0.7,"强",IF(ABS(E32)>=0.4,"中","弱")),"-")
A33: 29 | B33: ='04 变换后数据'!B33 | C33: =IF(29<$C$3,"",IF(433=0,"",IF(433<MAX(5,ROUND($C$3*0.8,0)),"样本不足",CORREL(OFFSET('04 变换后数据'!$D$5:$D$160,ROW()-5-$C$3+1,0,$C$3,1),OFFSET('04 变换后数据'!$H$5:$H$160,ROW()-5-$C$3+1,0,$C$3,1)))) | D33: =IF(29<$C$3,0,SUMPRODUCT(--(ROW('04 变换后数据'!$D$5:$D$160)<=ROW()),--ISNUMBER(OFFSET('04 变换后数据'!$D$5:$D$160,ROW()-5-$C$3+1,0,MIN($C$3,ROW()-4),1)),--ISNUMBER(OFFSET('04 变换后数据'!$H$5:$H$160,ROW()-5-$C$3+1,0,MIN($C$3,ROW()-4),1)))) | E33: =IF(29<$E$3,"",IF(633=0,"",IF(633<MAX(5,ROUND($E$3*0.8,0)),"样本不足",CORREL(OFFSET('04 变换后数据'!$D$5:$D$160,ROW()-5-$E$3+1,0,$E$3,1),OFFSET('04 变换后数据'!$H$5:$H$160,ROW()-5-$E$3+1,0,$E$3,1)))) | F33: =IF(29<$E$3,0,SUMPRODUCT(--(ROW('04 变换后数据'!$D$5:$D$160)<=ROW()),--ISNUMBER(OFFSET('04 变换后数据'!$D$5:$D$160,ROW()-5-$E$3+1,0,MIN($E$3,ROW()-4),1)),--ISNUMBER(OFFSET('04 变换后数据'!$H$5:$H$160,ROW()-5-$E$3+1,0,MIN($E$3,ROW()-4),1)))) | G33: =IF(29<$G$3,"",IF(833=0,"",IF(833<MAX(5,ROUND($G$3*0.8,0)),"样本不足",CORREL(OFFSET('04 变换后数据'!$D$5:$D$160,ROW()-5-$G$3+1,0,$G$3,1),OFFSET('04 变换后数据'!$H$5:$H$160,ROW()-5-$G$3+1,0,$G$3,1)))) | H33: =IF(29<$G$3,0,SUMPRODUCT(--(ROW('04 变换后数据'!$D$5:$D$160)<=ROW()),--ISNUMBER(OFFSET('04 变换后数据'!$D$5:$D$160,ROW()-5-$G$3+1,0,MIN($G$3,ROW()-4),1)),--ISNUMBER(OFFSET('04 变换后数据'!$H$5:$H$160,ROW()-5-$G$3+1,0,MIN($G$3,ROW()-4),1)))) | I33: =IF(ISNUMBER(E33),IF(ABS(E33)>=0.7,"强",IF(ABS(E33)>=0.4,"中","弱")),"-")
A34: 30 | B34: ='04 变换后数据'!B34 | C34: =IF(30<$C$3,"",IF(434=0,"",IF(434<MAX(5,ROUND($C$3*0.8,0)),"样本不足",CORREL(OFFSET('04 变换后数据'!$D$5:$D$160,ROW()-5-$C$3+1,0,$C$3,1),OFFSET('04 变换后数据'!$H$5:$H$160,ROW()-5-$C$3+1,0,$C$3,1)))) | D34: =IF(30<$C$3,0,SUMPRODUCT(--(ROW('04 变换后数据'!$D$5:$D$160)<=ROW()),--ISNUMBER(OFFSET('04 变换后数据'!$D$5:$D$160,ROW()-5-$C$3+1,0,MIN($C$3,ROW()-4),1)),--ISNUMBER(OFFSET('04 变换后数据'!$H$5:$H$160,ROW()-5-$C$3+1,0,MIN($C$3,ROW()-4),1)))) | E34: =IF(30<$E$3,"",IF(634=0,"",IF(634<MAX(5,ROUND($E$3*0.8,0)),"样本不足",CORREL(OFFSET('04 变换后数据'!$D$5:$D$160,ROW()-5-$E$3+1,0,$E$3,1),OFFSET('04 变换后数据'!$H$5:$H$160,ROW()-5-$E$3+1,0,$E$3,1)))) | F34: =IF(30<$E$3,0,SUMPRODUCT(--(ROW('04 变换后数据'!$D$5:$D$160)<=ROW()),--ISNUMBER(OFFSET('04 变换后数据'!$D$5:$D$160,ROW()-5-$E$3+1,0,MIN($E$3,ROW()-4),1)),--ISNUMBER(OFFSET('04 变换后数据'!$H$5:$H$160,ROW()-5-$E$3+1,0,MIN($E$3,ROW()-4),1)))) | G34: =IF(30<$G$3,"",IF(834=0,"",IF(834<MAX(5,ROUND($G$3*0.8,0)),"样本不足",CORREL(OFFSET('04 变换后数据'!$D$5:$D$160,ROW()-5-$G$3+1,0,$G$3,1),OFFSET('04 变换后数据'!$H$5:$H$160,ROW()-5-$G$3+1,0,$G$3,1)))) | H34: =IF(30<$G$3,0,SUMPRODUCT(--(ROW('04 变换后数据'!$D$5:$D$160)<=ROW()),--ISNUMBER(OFFSET('04 变换后数据'!$D$5:$D$160,ROW()-5-$G$3+1,0,MIN($G$3,ROW()-4),1)),--ISNUMBER(OFFSET('04 变换后数据'!$H$5:$H$160,ROW()-5-$G$3+1,0,MIN($G$3,ROW()-4),1)))) | I34: =IF(ISNUMBER(E34),IF(ABS(E34)>=0.7,"强",IF(ABS(E34)>=0.4,"中","弱")),"-")
A35: 31 | B35: ='04 变换后数据'!B35 | C35: =IF(31<$C$3,"",IF(435=0,"",IF(435<MAX(5,ROUND($C$3*0.8,0)),"样本不足",CORREL(OFFSET('04 变换后数据'!$D$5:$D$160,ROW()-5-$C$3+1,0,$C$3,1),OFFSET('04 变换后数据'!$H$5:$H$160,ROW()-5-$C$3+1,0,$C$3,1)))) | D35: =IF(31<$C$3,0,SUMPRODUCT(--(ROW('04 变换后数据'!$D$5:$D$160)<=ROW()),--ISNUMBER(OFFSET('04 变换后数据'!$D$5:$D$160,ROW()-5-$C$3+1,0,MIN($C$3,ROW()-4),1)),--ISNUMBER(OFFSET('04 变换后数据'!$H$5:$H$160,ROW()-5-$C$3+1,0,MIN($C$3,ROW()-4),1)))) | E35: =IF(31<$E$3,"",IF(635=0,"",IF(635<MAX(5,ROUND($E$3*0.8,0)),"样本不足",CORREL(OFFSET('04 变换后数据'!$D$5:$D$160,ROW()-5-$E$3+1,0,$E$3,1),OFFSET('04 变换后数据'!$H$5:$H$160,ROW()-5-$E$3+1,0,$E$3,1)))) | F35: =IF(31<$E$3,0,SUMPRODUCT(--(ROW('04 变换后数据'!$D$5:$D$160)<=ROW()),--ISNUMBER(OFFSET('04 变换后数据'!$D$5:$D$160,ROW()-5-$E$3+1,0,MIN($E$3,ROW()-4),1)),--ISNUMBER(OFFSET('04 变换后数据'!$H$5:$H$160,ROW()-5-$E$3+1,0,MIN($E$3,ROW()-4),1)))) | G35: =IF(31<$G$3,"",IF(835=0,"",IF(835<MAX(5,ROUND($G$3*0.8,0)),"样本不足",CORREL(OFFSET('04 变换后数据'!$D$5:$D$160,ROW()-5-$G$3+1,0,$G$3,1),OFFSET('04 变换后数据'!$H$5:$H$160,ROW()-5-$G$3+1,0,$G$3,1)))) | H35: =IF(31<$G$3,0,SUMPRODUCT(--(ROW('04 变换后数据'!$D$5:$D$160)<=ROW()),--ISNUMBER(OFFSET('04 变换后数据'!$D$5:$D$160,ROW()-5-$G$3+1,0,MIN($G$3,ROW()-4),1)),--ISNUMBER(OFFSET('04 变换后数据'!$H$5:$H$160,ROW()-5-$G$3+1,0,MIN($G$3,ROW()-4),1)))) | I35: =IF(ISNUMBER(E35),IF(ABS(E35)>=0.7,"强",IF(ABS(E35)>=0.4,"中","弱")),"-")
A36: 32 | B36: ='04 变换后数据'!B36 | C36: =IF(32<$C$3,"",IF(436=0,"",IF(436<MAX(5,ROUND($C$3*0.8,0)),"样本不足",CORREL(OFFSET('04 变换后数据'!$D$5:$D$160,ROW()-5-$C$3+1,0,$C$3,1),OFFSET('04 变换后数据'!$H$5:$H$160,ROW()-5-$C$3+1,0,$C$3,1)))) | D36: =IF(32<$C$3,0,SUMPRODUCT(--(ROW('04 变换后数据'!$D$5:$D$160)<=ROW()),--ISNUMBER(OFFSET('04 变换后数据'!$D$5:$D$160,ROW()-5-$C$3+1,0,MIN($C$3,ROW()-4),1)),--ISNUMBER(OFFSET('04 变换后数据'!$H$5:$H$160,ROW()-5-$C$3+1,0,MIN($C$3,ROW()-4),1)))) | E36: =IF(32<$E$3,"",IF(636=0,"",IF(636<MAX(5,ROUND($E$3*0.8,0)),"样本不足",CORREL(OFFSET('04 变换后数据'!$D$5:$D$160,ROW()-5-$E$3+1,0,$E$3,1),OFFSET('04 变换后数据'!$H$5:$H$160,ROW()-5-$E$3+1,0,$E$3,1)))) | F36: =IF(32<$E$3,0,SUMPRODUCT(--(ROW('04 变换后数据'!$D$5:$D$160)<=ROW()),--ISNUMBER(OFFSET('04 变换后数据'!$D$5:$D$160,ROW()-5-$E$3+1,0,MIN($E$3,ROW()-4),1)),--ISNUMBER(OFFSET('04 变换后数据'!$H$5:$H$160,ROW()-5-$E$3+1,0,MIN($E$3,ROW()-4),1)))) | G36: =IF(32<$G$3,"",IF(836=0,"",IF(836<MAX(5,ROUND($G$3*0.8,0)),"样本不足",CORREL(OFFSET('04 变换后数据'!$D$5:$D$160,ROW()-5-$G$3+1,0,$G$3,1),OFFSET('04 变换后数据'!$H$5:$H$160,ROW()-5-$G$3+1,0,$G$3,1)))) | H36: =IF(32<$G$3,0,SUMPRODUCT(--(ROW('04 变换后数据'!$D$5:$D$160)<=ROW()),--ISNUMBER(OFFSET('04 变换后数据'!$D$5:$D$160,ROW()-5-$G$3+1,0,MIN($G$3,ROW()-4),1)),--ISNUMBER(OFFSET('04 变换后数据'!$H$5:$H$160,ROW()-5-$G$3+1,0,MIN($G$3,ROW()-4),1)))) | I36: =IF(ISNUMBER(E36),IF(ABS(E36)>=0.7,"强",IF(ABS(E36)>=0.4,"中","弱")),"-")
