Workbook

Sheet 00_封面与说明
A1: PX → PTA 成本传导研究
A2: 观测窗口 20251001 ~ 20261020，275 个交易日。本工作簿所有数字与 HTML 报告同源（同一份 analysis.json）。
A5: 【必读】加工价差不是利润 | B5: 价差 = 下游价 − 单耗×上游价。不含能源、辅料、人工、折旧、财务费用、检维修、运费、库存损益。不得作为利润对外使用。
A6: 【必读】同涨同跌不等于因果 | B6: 上游与下游可能被原油、宏观、政策等共同因素驱动。本工作簿不做因果推断，相关系数仅为观察值。
A7: 上游 | B7: PX ｜ 生意社PX基准价（国内对二甲苯现货评估价） ｜ 中国（华东主港/国产基准） ｜ 含增值税
A8: 下游 | B8: PTA ｜ 生意社PTA基准价（华东现货评估价） ｜ 华东（张家港/主港） ｜ 含增值税
A9: 单耗（主模型） | B9: 0.655 吨 PX / 吨 PTA（区间 0.648 ~ 0.665）
A10: 价差定义 | B10: 加工价差 = PTA价格 − 0.655×PX价格
A12: 表目录 | B12: 01原料价格 · 02下游价格 · 03工艺单耗 · 04理论成本 · 05加工价差 · 06分阶段对比 · 07背离区间 · 08计算公式 · 09数据缺口与来源

Sheet 01_原料价格
A1: PX 日度价格（上游）
A2: 生意社PX基准价（国内对二甲苯现货评估价） ｜ 中国（华东主港/国产基准） ｜ 含增值税 ｜ 来源：生意社 100ppi 基准价日评（每日 08:30 发布）
A4: 日期 | B4: PX 价格（元/吨） | C4: 日变动 | D4: 是否变动 | E4: 备注
A5: 20251001 | B5: 6800
A6: 20251002 | B6: 6800 | C6: 0 | D6: 否 | E6: 台阶（连续不变）
A7: 20251003 | B7: 6800 | C7: 0 | D7: 否 | E7: 台阶（连续不变）
A8: 20251006 | B8: 6800 | C8: 0 | D8: 否 | E8: 台阶（连续不变）
A9: 20251007 | B9: 6800 | C9: 0 | D9: 否 | E9: 台阶（连续不变）
A10: 20251008 | B10: 6800 | C10: 0 | D10: 否 | E10: 台阶（连续不变）
A11: 20251009 | B11: 6800 | C11: 0 | D11: 否 | E11: 台阶（连续不变）
A12: 20251010 | B12: 6800 | C12: 0 | D12: 否 | E12: 台阶（连续不变）
A13: 20251011 | B13: 6800 | C13: 0 | D13: 否 | E13: 台阶（连续不变）
A14: 20251013 | B14: 6800 | C14: 0 | D14: 否 | E14: 台阶（连续不变）
A15: 20251014 | B15: 6800 | C15: 0 | D15: 否 | E15: 台阶（连续不变）
A16: 20251015 | B16: 6800 | C16: 0 | D16: 否 | E16: 台阶（连续不变）
A17: 20251016 | B17: 6800 | C17: 0 | D17: 否 | E17: 台阶（连续不变）
... A19: 20251020 | B19: 6800 | C19: 0 | D19: 否 | E19: 台阶（连续不变）
A20: 20251021 | B20: 6650 | C20: -150 | D20: 是
A21: 20251022 | B21: 6650 | C21: 0 | D21: 否 | E21: 台阶（连续不变）
A22: 20251023 | B22: 6650 | C22: 0 | D22: 否 | E22: 台阶（连续不变）
A23: 20251024 | B23: 6650 | C23: 0 | D23: 否 | E23: 台阶（连续不变）
A24: 20251027 | B24: 6650 | C24: 0 | D24: 否 | E24: 台阶（连续不变）
A25: 20251028 | B25: 6650 | C25: 0 | D25: 否 | E25: 台阶（连续不变）
A26: 20251029 | B26: 6650 | C26: 0 | D26: 否 | E26: 台阶（连续不变）
A27: 20251030 | B27: 6650 | C27: 0 | D27: 否 | E27: 台阶（连续不变）
A28: 20251031 | B28: 6650 | C28: 0 | D28: 否 | E28: 台阶（连续不变）
A29: 20251103 | B29: 6700 | C29: 50 | D29: 是
A30: 20251104 | B30: 6700 | C30: 0 | D30: 否 | E30: 台阶（连续不变）
A31: 20251105 | B31: 6700 | C31: 0 | D31: 否 | E31: 台阶（连续不变）
A32: 20251106 | B32: 6700 | C32: 0 | D32: 否 | E32: 台阶（连续不变）
A33: 20251107 | B33: 6700 | C33: 0 | D33: 否 | E33: 台阶（连续不变）
A34: 20251110 | B34: 6700 | C34: 0 | D34: 否 | E34: 台阶（连续不变）
A35: 20251111 | B35: 6700 | C35: 0 | D35: 否 | E35: 台阶（连续不变）
A36: 20251112 | B36: 6800 | C36: 100 | D36: 是
A37: 20251113 | B37: 6800 | C37: 0 | D37: 否 | E37: 台阶（连续不变）
A38: 20251114 | B38: 6800 | C38: 0 | D38: 否 | E38: 台阶（连续不变）
A39: 20251117 | B39: 6800 | C39: 0 | D39: 否 | E39: 台阶（连续不变）
A40: 20251118 | B40: 6800 | C40: 0 | D40: 否 | E40: 台阶（连续不变）
A41: 20251119 | B41: 6800 | C41: 0 | D41: 否 | E41: 台阶（连续不变）
A42: 20251120 | B42: 6800 | C42: 0 | D42: 否 | E42: 台阶（连续不变）
...

Sheet 02_下游价格
A1: PTA 日度价格（下游）
A2: 生意社PTA基准价（华东现货评估价） ｜ 华东（张家港/主港） ｜ 含增值税 ｜ 来源：生意社 100ppi 基准价日评（每日 08:30 发布）
A4: 日期 | B4: PTA 价格（元/吨） | C4: 日变动 | D4: 日涨跌%
A5: 20251001 | B5: 4595
A6: 20251002 | B6: 4595 | C6: 0 | D6: 0
A7: 20251003 | B7: 4595 | C7: 0 | D7: 0
A8: 20251006 | B8: 4595 | C8: 0 | D8: 0
A9: 20251007 | B9: 4595 | C9: 0 | D9: 0
A10: 20251008 | B10: 4595 | C10: 0 | D10: 0
A11: 20251009 | B11: 4595 | C11: 0 | D11: 0
A12: 20251010 | B12: 4564.5 | C12: -30.5 | D12: -0.66376496
A13: 20251011 | B13: 4521.08 | C13: -43.42 | D13: -0.95125424
A14: 20251013 | B14: 4521.08 | C14: 0 | D14: 0
A15: 20251014 | B15: 4492.17 | C15: -28.91 | D15: -0.63944898
A16: 20251015 | B16: 4460.09 | C16: -32.08 | D16: -0.71413148
A17: 20251016 | B17: 4397.16 | C17: -62.93 | D17: -1.4109581
... A279: 20261020 | B279: 7054.5 | C279: -176.5 | D279: -2.4408795

Sheet 03_工艺单耗
A1: 工艺与单耗参数（可修改，04/05 表会联动重算）
A2: 浅蓝底色为可修改输入项。改单耗后，04 表的吨成本与 05 表的价差会按公式自动重算。
A4: 工艺路线 | B4: PX 液相空气氧化（ Amoco/BP 系）→ 粗对苯二甲酸 → 加氢精制 → PTA
A5: 反应式 | B5: PX + 3O2 → PTA + 2H2O
A6: 核实状态 | B6: 已核实
A7: 原料 | B7: 单耗（主模型） | C7: 区间下界 | D7: 区间上界 | E7: 单位口径 | F7: 来源
A8: PX | B8: 0.655 | C8: 0.648 | D8: 0.665 | E8: 吨 PX / 吨 PTA | F8: 行业通用加工费口径 0.655；技术迭代区间 0.648（新装置）~0.665（早期装置）
A10: 主模型单耗所在单元格： | B10: =B8
A12: 未纳入主模型的辅料
A13: 项目 | B13: 单耗 | C13: 下界 | D13: 上界 | E13: 状态说明
A14: 醋酸 | B14: 0.03 | C14: 0.029 | D14: 0.04 | E14: 未纳入主模型：缺少同期间序列的醋酸日度基准价，纳入需另接数据

Sheet 04_理论成本
A1: 理论原料成本（Excel 真公式，可复核）
A2: 公式：成本 = 单耗 × 上游价。单耗引用 03 表 B 列主模型单元格，改那里即可全表重算。
A4: 日期 | B4: PX 价格（元/吨） | C4: 单耗 | D4: 理论原料成本（元/吨） | E4: PTA 价格（元/吨） | F4: 原料成本占下游价%
A5: 20251001 | B5: 6800 | C5: =03_工艺单耗!B8 | D5: =B5*C5 | E5: 4595 | F5: =IF(E5,D5/E5*100,"")
A6: 20251002 | B6: 6800 | C6: =03_工艺单耗!B8 | D6: =B6*C6 | E6: 4595 | F6: =IF(E6,D6/E6*100,"")
A7: 20251003 | B7: 6800 | C7: =03_工艺单耗!B8 | D7: =B7*C7 | E7: 4595 | F7: =IF(E7,D7/E7*100,"")
A8: 20251006 | B8: 6800 | C8: =03_工艺单耗!B8 | D8: =B8*C8 | E8: 4595 | F8: =IF(E8,D8/E8*100,"")
A9: 20251007 | B9: 6800 | C9: =03_工艺单耗!B8 | D9: =B9*C9 | E9: 4595 | F9: =IF(E9,D9/E9*100,"")
A10: 20251008 | B10: 6800 | C10: =03_工艺单耗!B8 | D10: =B10*C10 | E10: 4595 | F10: =IF(E10,D10/E10*100,"")
A11: 20251009 | B11: 6800 | C11: =03_工艺单耗!B8 | D11: =B11*C11 | E11: 4595 | F11: =IF(E11,D11/E11*100,"")
A12: 20251010 | B12: 6800 | C12: =03_工艺单耗!B8 | D12: =B12*C12 | E12: 4564.5 | F12: =IF(E12,D12/E12*100,"")
A13: 20251011 | B13: 6800 | C13: =03_工艺单耗!B8 | D13: =B13*C13 | E13: 4521.08 | F13: =IF(E13,D13/E13*100,"")
A14: 20251013 | B14: 6800 | C14: =03_工艺单耗!B8 | D14: =B14*C14 | E14: 4521.08 | F14: =IF(E14,D14/E14*100,"")
A15: 20251014 | B15: 6800 | C15: =03_工艺单耗!B8 | D15: =B15*C15 | E15: 4492.17 | F15: =IF(E15,D15/E15*100,"")
A16: 20251015 | B16: 6800 | C16: =03_工艺单耗!B8 | D16: =B16*C16 | E16: 4460.09 | F16: =IF(E16,D16/E16*100,"")
A17: 20251016 | B17: 6800 | C17: =03_工艺单耗!B8 | D17: =B17*C17 | E17: 4397.16 | F17: =IF(E17,D17/E17*100,"")
A18: 20251017 | B18: 6800 | C18: =03_工艺单耗!B8 | D18: =B18*C18 | E18: 4404.16 | F18: =IF(E18,D18/E18*100,"")
A19: 20251020 | B19: 6800 | C19: =03_工艺单耗!B8 | D19: =B19*C19 | E19: 4381.5 | F19: =IF(E19,D19/E19*100,"")
A20: 20251021 | B20: 6650 | C20: =03_工艺单耗!B8 | D20: =B20*C20 | E20: 4363.25 | F20: =IF(E20,D20/E20*100,"")
A21: 20251022 | B21: 6650 | C21: =03_工艺单耗!B8 | D21: =B21*C21 | E21: 4369.84 | F21: =IF(E21,D21/E21*100,"")
A22: 20251023 | B22: 6650 | C22: =03_工艺单耗!B8 | D22: =B22*C22 | E22: 4415.83 | F22: =IF(E22,D22/E22*100,"")
A23: 20251024 | B23: 6650 | C23: =03_工艺单耗!B8 | D23: =B23*C23 | E23: 4467.08 | F23: =IF(E23,D23/E23*100,"")
A24: 20251027 | B24: 6650 | C24: =03_工艺单耗!B8 | D24: =B24*C24 | E24: 4468.34 | F24: =IF(E24,D24/E24*100,"")
A25: 20251028 | B25: 6650 | C25: =03_工艺单耗!B8 | D25: =B25*C25 | E25: 4535.67 | F25: =IF(E25,D25/E25*100,"")
A26: 20251029 | B26: 6650 | C26: =03_工艺单耗!B8 | D26: =B26*C26 | E26: 4558.09 | F26: =IF(E26,D26/E26*100,"")
A27: 20251030 | B27: 6650 | C27: =03_工艺单耗!B8 | D27: =B27*C27 | E27: 4554.75 | F27: =IF(E27,D27/E27*100,"")
A28: 20251031 | B28: 6650 | C28: =03_工艺单耗!B8 | D28: =B28*C28 | E28: 4552.34 | F28: =IF(E28,D28/E28*100,"")
A29: 20251103 | B29: 6700 | C29: =03_工艺单耗!B8 | D29: =B29*C29 | E29: 4543.91 | F29: =IF(E29,D29/E29*100,"")
A30: 20251104 | B30: 6700 | C30: =03_工艺单耗!B8 | D30: =B30*C30 | E30: 4558.75 | F30: =IF(E30,D30/E30*100,"")
A31: 20251105 | B31: 6700 | C31: =03_工艺单耗!B8 | D31: =B31*C31 | E31: 4569.75 | F31: =IF(E31,D31/E31*100,"")
A32: 20251106 | B32: 6700 | C32: =03_工艺单耗!B8 | D32: =B32*C32 | E32: 4555.41 | F32: =IF(E32,D32/E32*100,"")
A33: 20251107 | B33: 6700 | C33: =03_工艺单耗!B8 | D33: =B33*C33 | E33: 4561.09 | F33: =IF(E33,D33/E33*100,"")
A34: 20251110 | B34: 6700 | C34: =03_工艺单耗!B8 | D34: =B34*C34 | E34: 4598.84 | F34: =IF(E34,D34/E34*100,"")
A35: 20251111 | B35: 6700 | C35: =03_工艺单耗!B8 | D35: =B35*C35 | E35: 4645.66 | F35: =IF(E35,D35/E35*100,"")
A36: 20251112 | B36: 6800 | C36: =03_工艺单耗!B8 | D36: =B36*C36 | E36: 4637.17 | F36: =IF(E36,D36/E36*100,"")
A37: 20251113 | B37: 6800 | C37: =03_工艺单耗!B8 | D37: =B37*C37 | E37: 4635.5 | F37: =IF(E37,D37/E37*100,"")
A38: 20251114 | B38: 6800 | C38: =03_工艺单耗!B8 | D38: =B38*C38 | E38: 4591.58 | F38: =IF(E38,D38/E38*100,"")
A39: 20251117 | B39: 6800 | C39: =03_工艺单耗!B8 | D39: =B39*C39 | E39: 4671.09 | F39: =IF(E39,D39/E39*100,"")
A40: 20251118 | B40: 6800 | C40: =03_工艺单耗!B8 | D40: =B40*C40 | E40: 4647 | F40: =IF(E40,D40/E40*100,"")
A41: 20251119 | B41: 6800 | C41: =03_工艺单耗!B8 | D41: =B41*C41 | E41: 4628.75 | F41: =IF(E41,D41/E41*100,"")
...

Sheet 05_加工价差
A1: 加工价差（价差口径，不是利润）
A2: 价差 = 下游价 − 理论原料成本。低/高单耗两列用于敏感性。
A4: 日期 | B4: PTA 价（元/吨） | C4: 理论原料成本 | D4: 加工价差 | E4: 价差-低单耗情形 | F4: 价差-高单耗情形 | G4: z分数(20日)
A5: 20251001 | B5: 4595 | C5: =04_理论成本!D5 | D5: =B5-C5 | E5: 188.6 | F5: 73
A6: 20251002 | B6: 4595 | C6: =04_理论成本!D6 | D6: =B6-C6 | E6: 188.6 | F6: 73
A7: 20251003 | B7: 4595 | C7: =04_理论成本!D7 | D7: =B7-C7 | E7: 188.6 | F7: 73
A8: 20251006 | B8: 4595 | C8: =04_理论成本!D8 | D8: =B8-C8 | E8: 188.6 | F8: 73
A9: 20251007 | B9: 4595 | C9: =04_理论成本!D9 | D9: =B9-C9 | E9: 188.6 | F9: 73
A10: 20251008 | B10: 4595 | C10: =04_理论成本!D10 | D10: =B10-C10 | E10: 188.6 | F10: 73
A11: 20251009 | B11: 4595 | C11: =04_理论成本!D11 | D11: =B11-C11 | E11: 188.6 | F11: 73
A12: 20251010 | B12: 4564.5 | C12: =04_理论成本!D12 | D12: =B12-C12 | E12: 158.1 | F12: 42.5 | G12: -2.4748737
A13: 20251011 | B13: 4521.08 | C13: =04_理论成本!D13 | D13: =B13-C13 | E13: 114.68 | F13: -0.92 | G13: -2.4483304
A14: 20251013 | B14: 4521.08 | C14: =04_理论成本!D14 | D14: =B14-C14 | E14: 114.68 | F14: -0.92 | G14: -1.8061933
A15: 20251014 | B15: 4492.17 | C15: =04_理论成本!D15 | D15: =B15-C15 | E15: 85.77 | F15: -29.83 | G15: -1.9789422
A16: 20251015 | B16: 4460.09 | C16: =04_理论成本!D16 | D16: =B16-C16 | E16: 53.69 | F16: -61.91 | G16: -2.0536154
A17: 20251016 | B17: 4397.16 | C17: =04_理论成本!D17 | D17: =B17-C17 | E17: -9.24 | F17: -124.84 | G17: -2.3152921
A18: 20251017 | B18: 4404.16 | C18: =04_理论成本!D18 | D18: =B18-C18 | E18: -2.24 | F18: -117.84 | G18: -1.8182093
A19: 20251020 | B19: 4381.5 | C19: =04_理论成本!D19 | D19: =B19-C19 | E19: -24.9 | F19: -140.5 | G19: -1.7899644
A20: 20251021 | B20: 4363.25 | C20: =04_理论成本!D20 | D20: =B20-C20 | E20: 54.05 | F20: -59 | G20: -0.76619319
A21: 20251022 | B21: 4369.84 | C21: =04_理论成本!D21 | D21: =B21-C21 | E21: 60.64 | F21: -52.41 | G21: -0.65543252
A22: 20251023 | B22: 4415.83 | C22: =04_理论成本!D22 | D22: =B22-C22 | E22: 106.63 | F22: -6.42 | G22: -0.070396195
A23: 20251024 | B23: 4467.08 | C23: =04_理论成本!D23 | D23: =B23-C23 | E23: 157.88 | F23: 44.83 | G23: 0.57845826
... A279: 20261020 | B279: 7054.5 | C279: =04_理论成本!D279 | D279: =B279-C279 | E279: 250.5 | F279: 72 | G279: -2.0548585
A281: 统计 | B281: 加工价差 | D281: 与 analysis.json 对照（非公式）
A282: 均值 | B282: =AVERAGE(D5:D279) | D282: 均值 | E282: 339.57156
A283: 中位数 | B283: =MEDIAN(D5:D279) | D283: 中位数 | E283: 257.16
A284: 最小 | B284: =MIN(D5:D279) | D284: 最小 | E284: -1153.07
A285: 最大 | B285: =MAX(D5:D279) | D285: 最大 | E285: 1371.75

Sheet 06_分阶段对比
A1: 分阶段成本传导分解
A2: 恒等式：Δ下游价 = Δ原料成本 + Δ加工价差（残差应为 0）。传导率 = Δ下游价 / Δ原料成本；分母过小（<成本1%）时标记为不稳定。
A4: 阶段起 | B4: 阶段止 | C4: 天数 | D4: 期初原料成本 | E4: 期末原料成本 | F4: Δ原料成本 | G4: 期初下游价 | H4: 期末下游价 | I4: Δ下游价 | J4: Δ加工价差 | K4: 传导率
A5: 20251001 | B5: 20251231 | C5: 66 | D5: 4454 | E5: 4585 | F5: 131 | G5: 4595 | H5: 5082.66 | I5: 487.66 | J5: 356.66 | K5: 3.7225954
A6: 20251231 | B6: 20260331 | C6: 64 | D6: 4585 | E6: 6681 | F6: 2096 | G6: 5082.66 | H6: 6867.64 | I6: 1784.98 | J6: -311.02 | K6: 0.8516126
A7: 20260331 | B7: 20260630 | C7: 64 | D7: 6681 | E7: 5174.5 | F7: -1506.5 | G7: 6867.64 | H7: 5785.66 | I7: -1081.98 | J7: 424.52 | K7: 0.71820777
A8: 20260630 | B8: 20260826 | C8: 41 | D8: 5174.5 | E8: 5567.5 | F8: 393 | G8: 5785.66 | H8: 6453 | I8: 667.34 | J8: 274.34 | K8: 1.6980662
A9: 20260826 | B9: 20261020 | C9: 39 | D9: 5567.5 | E9: 6877.5 | F9: 1310 | G9: 6453 | H9: 7054.5 | I9: 601.5 | J9: -708.5 | K9: 0.45916031
A11: ⚠ 传导率说明
A12: 传导率 ≈1：成本基本全额传导；<1：下游未跟满、价差被压缩；>1：下游涨幅超过成本、价差走阔；<0：反向。
A13: 传导率 >1 时必须先检查上游是否为台阶式评估价（见 01 表"是否变动"列），分母过小会把比值放大成几倍，这是计算假象。
A14: 本表只做算术分解，不证明"上游导致下游"。

Sheet 07_背离区间
A1: 价差背离区间与异常跳变
A2: 背离：价差相对 20 日滚动均值的 z 分数，连续越阈 ≥5 日。异常跳变：单日变动 ≥400 元/吨。
A4: 类型 | B4: 起 | C4: 止 | D4: 天数 | E4: 期初价差 | F4: 期末价差 | G4: 区间均值 | H4: 极端z | I4: 原因核查
A5: 压缩 | B5: 20251010 | C5: 20251020 | D5: 8 | E5: 110.5 | F5: -72.5 | G5: 13.7175 | H5: -2.47 | I5: PriceSeek重点提醒：逸盛宁波PTA装置降负影；生意社：逸盛宁波PTA装置动态；PriceSeek提醒：逸盛PTA装置恢复生产影响
A6: 压缩 | B6: 20251205 | C6: 20251215 | D6: 7 | E6: 117.25 | F6: 54.4 | G6: 85.77 | H6: -2.42 | I6: PriceSeek重点提醒：PTA装置停车供应趋紧；生意社：逸盛宁波PTA装置动态
A7: 走阔 | B7: 20251223 | C7: 20251231 | D7: 7 | E7: 294.34 | F7: 497.66 | G7: 429.66857 | H7: 2.46 | I7: PriceSeek重点提醒：独山能源PTA装置重启市；生意社：珠海BPPTA装置动态；生意社：独山能源PTA装置动态
A8: 走阔 | B8: 20260127 | C8: 20260202 | D8: 5 | E8: 559.75 | F8: 517.33 | G8: 522.334 | H8: 2.9 | I8: 未检索到可核查事件，原因未确认
A9: 走阔 | B9: 20260818 | C9: 20260826 | D9: 7 | E9: 725.36 | F9: 885.5 | G9: 813.95571 | H9: 2.53 | I9: PriceSeek提醒：虹港石化250万吨PTA装置；PriceSeek提醒：福海创450万吨PTA装置重；PriceSeek提醒：逸盛PTA装置提负 聚酯产业
A11: 单日异常跳变（未剔除）
A12: 日期 | B12: 前一日价差 | C12: 当日价差 | D12: 跳变
A13: 20260311 | B13: 224.34 | C13: -1153.07 | D13: -1377.41
A14: 20260312 | B14: -1153.07 | C14: 101.47 | D14: 1254.54
A15: 20260316 | B15: 381.26 | C15: -80.4 | D15: -461.66
A16: 20260409 | B16: 579.4 | C16: 150.97 | D16: -428.43
A17: 20260601 | B17: -139.17 | C17: 363.75 | D17: 502.92
A18: 20260630 | B18: -30 | C18: 611.16 | D18: 641.16
A19: 20261009 | B19: 842.75 | C19: 1371.75 | D19: 529
A20: 20261012 | B20: 1371.75 | C20: 859.25 | D20: -512.5

Sheet 08_计算公式
A1: 全部计算公式与参数
A3: 序号 | B3: 项目 | C3: 公式 | D3: 说明
A4: 1 | B4: 理论原料成本 | C4: 成本 = Σ(单耗ᵢ × 原料价ᵢ) | D4: 单耗单位：吨原料/吨产品；价格单位：元/吨（已含税、同地区）
A5: 2 | B5: 单耗敏感性 | C5: 价差_低 = 下游价 − 下界单耗 × 上游价 | D5: 下界单耗 → 成本偏低 → 价差偏高
A6: 3 | B6: 加工价差 | C6: 价差 = 下游价 − 理论原料成本 | D6: ★ 价差口径，不是利润。不含能源/辅料/人工/折旧/财务/运费
A7: 4 | B7: 阶段分解 | C7: Δ下游 = Δ原料成本 + Δ价差 | D7: 恒等式，残差应恒为 0
A8: 5 | B8: 传导率 | C8: 传导率 = Δ下游价 / Δ原料成本 | D8: 分母 < 成本1% 时不稳定，标记为无效
A9: 6 | B9: 原料成本占比 | C9: 占比 = 原料成本 / 下游价 × 100% | D9: 正常区间 60%~98%，超出提示单位或单耗有误
A10: 7 | B10: 价差 z 分数 | C10: z = (价差 − 20日滚动均值) / 20日滚动标准差 | D10: |z|≥1.5 且连续 ≥5 日 → 背离区间
A11: 8 | B11: 滞后相关 | C11: r(k) = corr(Δ上游[t], Δ下游[t+k]), k=0..20 | D11: ★ 仅观察，不作因果推断
A12: 9 | B12: 美元→人民币 | C12: 上游价(元/吨) = CFR × 汇率 × (1+关税) × (1+增值税) | D12: 常漏关税项；换完必须检查数量级（化工品通常 6000~11000 元/吨）
A13: 本期实际参数
A14: 上游 | B14: PX（生意社PX基准价（国内对二甲苯现货评估价） / 中国（华东主港/国产基准） / 含增值税）
A15: 下游 | B15: PTA（生意社PTA基准价（华东现货评估价） / 华东（张家港/主港） / 含增值税）
A16: 单耗 | B16: 0.655（0.648~0.665）
A17: 观测数 | B17: 275 个交易日
A18: 上游变动天数 | B18: 28 / 275 天
A19: 下游变动天数 | B19: 249 / 275 天

Sheet 09_数据缺口与来源
A1: 数据缺口、口径校验与来源
A3: 类型 | B3: 项目 | C3: 说明 | D3: 影响/偏差 | E3: 来源
A4: 锚点校验 | B4: 2025-10 | C4: 模型 90.84083333333335 vs 公开 154.0 | D4: -63.159167 | E4: 界面新闻《PTA反内卷还有多大空间？》引用 10月平均加工费 154 元/吨
A5: 锚点校验 | B5: 2026-08-20~2026-08-26 | C5: 模型 837.9519999999999 vs 公开 712.73 | D5: 125.222 | E5: 隆众资讯 中国PTA加工费周数据统计（20260820-0826）
A6: 锚点校验 | B6: 2026-09-24 | C6: 模型 530.5 vs 公开 662.63 | D6: -132.13 | E6: 期货日报/建信期货《PTA加工费修复能否持续？》
A7: 缺口 | B7: 辅料（醋酸等） | C7: 缺同期间日度基准价，未纳入价差计算 | D7: 价差少扣约 75~160 元/吨 | E7: 见 references/data-sources.md
A8: 缺口 | B8: 装置级成本 | C8: 无企业级能耗、折旧、财务费用数据 | D8: 只能做行业价差，不能判断单个装置盈亏 | E8: —
A9: 口径 | B9: 评估价 vs 成交价 | C9: 本表用的是资讯机构日度评估价，非成交价 | D9: 实际成交受品牌/账期/地区影响，可能差百元级 | E9: —
A10: 口径 | B10: 上游台阶式更新 | C10: 上游 PX 在 275 天中仅 28 天变动 | D10: 阶段传导率在分母极小时失真 | E10: 01 表"是否变动"列
