Workbook
Name Lambda: '02_参数'!$C$5
Name LambdaLo: '02_参数'!$C$6
Name LambdaHi: '02_参数'!$C$7
Name OtherCost: '02_参数'!$C$8
Name AceticCoef: '02_参数'!$C$9
Name WinA: '02_参数'!$C$10
Name WinB: '02_参数'!$C$11
Name WinC: '02_参数'!$C$12
Name MinObs: '02_参数'!$C$13
Name Alpha: '02_参数'!$C$14

Sheet 00_说明
A1: PX × PTA 上下游价格联动研究 · 数据与计算工作簿
A2: 所有结果均为活公式；改动「02_参数」的 λ 或「03_原始数据」的价格，其余各表自动重算。
B4: 研究问题 | C4: PX（上游）与 PTA（下游）之间价格传导是否明显？哪些阶段出现背离？理论加工价差处于历史什么位置？是否存在可识别的领先/滞后？
B5: 产业关系 | C5: PTA 由 PX 液相空气氧化制得（醋酸为溶剂、Co-Mn-Br 催化），PX 是唯一主要原料，不存在第二条主要原料路线 → 允许做单耗折算加工价差。
B6: 数据源 | C6: 100ppi 生意社 PX/PTA 基准价（中文，2025-05-22 起）；SunSirs 日度现货价（英文站，可回溯 2023-01）。两源在重叠期逐日一致（差异 0 元/吨）。
B7: 价格口径 | C7: 元/吨，含增值税，华东现货基准价；同一机构同一口径，避免跨源拼接。
B8: 频率与样本 | C8: 日频；成对有效样本 N=869；区间 2023-10-08 ~ 2026-10-20。缺失日不插值，统计一律用成对有效样本。
B9: 发布时点 | C9: 生意社基准价于当日 08:30 发布，反映当日市场水平（发布滞后 0 天）；SunSirs 英文站页面日期为报道日，价格对应链接日期（滞后 1 天），已校正。
B10: 单耗来源 | C10: 0.655 t PX/t PTA：长江期货 2023-12-18；0.653：SCI99 2026-08-20；0.647~0.657：天风证券 2019-12-14 表 4 逐套装置。见「04_单耗台账」。
B11: 加工价差定义 | C11: Δ = PTA − λ×PX − 其他成本。λ 默认 0.655；「其他成本」= 醋酸贡献(≈0.032 t/t×醋酸价) + 动力 + 折旧的简化项，默认为 0，含义为「不含折旧与能源的收入型加工费」。
B12: 禁止事项 | C12: ① 不得把相关性表述为成本传导的因果证据；② 加工价差不等同企业利润；③ 不得给出交易建议/目标价；④ 单耗无出处时不得自造系数；⑤ 缺失不插值。
B13: 待补缺口 | C13: 醋酸价格序列未纳入（未取得可靠日频公开序列），故「其他成本」以参数形式暴露，默认 0 并在敏感性中说明；一体化装置的内部结算价与物流成本未剔除。

Sheet 01_口径与来源
A1: 口径与来源台账
A2: 每一条价格数据都必须能回答：什么品种/规格、哪个地区、含不含税、哪天发布、来自哪里。
A4: 序号 | B4: 口径项 | C4: 上游 PX | D4: 下游 PTA | E4: 是否一致 | F4: 处理方式 | G4: 数据来源 | H4: 发布时点 | I4: 备注
A5: 1 | B5: 品种/规格 | C5: 对二甲苯 PX，优等品 | D5: 精对苯二甲酸 PTA，优等品 | E5: 是 | F5: 按品种标准品取值 | G5: 生意社/ SunSirs | H5: 每日
A6: 2 | B6: 地区 | C6: 华东综合现货 | D6: 华东现货 | E6: 近似一致 | F6: 统一用华东口径，不做跨区拼价 | G6: 生意社/ SunSirs | H6: 每日 | I6: 跨区升贴水未剔除
A7: 3 | B7: 计量单位 | C7: 元/吨 | D7: 元/吨 | E7: 是 | F7: 无需换算 | G7: — | H7: —
A8: 4 | B8: 税费 | C8: 含增值税 | D8: 含增值税 | E8: 是 | F8: 税基相同，无需价税分离 | G8: — | H8: — | I8: 若一含税一不含税须先×1.13/1.09
A9: 5 | B9: 价格性质 | C9: 现货基准价 | D9: 现货基准价 | E9: 是 | F9: 不使用期货价格，避免基差混入 | G9: 生意社/ SunSirs | H9: 每日 08:30 | I9: 期货仅用于交叉验证
A10: 6 | B10: 频率 | C10: 日度 | D10: 日度 | E10: 是 | F10: 成对有效样本 | G10: — | H10: — | I10: 缺失不插值
A11: 7 | B11: 日期对齐 | C11: 价格口径日 | D11: 价格口径日 | E11: 是 | F11: 英文站滞后一天已校正 | G11: — | H11: — | I11: 错位会导致价差约 80 元/吨的系统偏差
A12: 8 | B12: 交叉校验 | C12: 两源重叠期逐日一致 | D12: 两源重叠期逐日一致 | E12: 是 | F12: 差异 0 元/吨，误差 0.00% | G12: 100ppi vs SunSirs | H12: — | I12: 见 12_公式说明 的校验方法

Sheet 02_参数
A1: 参数与命名区域
A2: 改这里，全表重算。λ 只有一个出处，禁止在各表重复写死。
A4: 参数 | B4: 名称 | C4: 取值 | D4: 单位 | E4: 来源/说明
A5: 单耗系数 λ | B5: Lambda | C5: 0.655 | D5: t PX/t PTA | E5: 长江期货 2023-12-18（行业通用 0.655）
A6: 单耗下限 | B6: LambdaLo | C6: 0.647 | D6: t PX/t PTA | E6: 天风证券 2019-12-14 表4：新凤鸣独山
A7: 单耗上限 | B7: LambdaHi | C7: 0.657 | D7: t PX/t PTA | E7: 天风证券 2019-12-14 表4：汉邦一期/桐昆嘉兴一期
A8: 其他成本 | B8: OtherCost | C8: 0 | D8: 元/吨 | E8: 醋酸+动力+折旧简化项；默认 0 = 仅收入型加工费
A9: 醋酸单耗 | B9: AceticCoef | C9: 0.032 | D9: t/t | E9: 天风证券表4（0.029~0.040）；SCI99 0.030~0.039
A10: 滚动窗口A | B10: WinA | C10: 20 | D10: 观测 | E10: 短期
A11: 滚动窗口B | B11: WinB | C11: 60 | D11: 观测 | E11: 主口径（报告 §5 默认）
A12: 滚动窗口C | B12: WinC | C12: 120 | D12: 观测 | E12: 中期
A13: 最小有效样本比 | B13: MinObs | C13: 0.8 | D13: 比例 | E13: 窗口内有效样本 < 80% 时不出数
A14: 显著水平 | B14: Alpha | C14: 0.05 | D14: — | E14: 双尾
A17: 阶段定义
A18: 阶段 | B18: 起始日 | C18: 结束日 | D18: 名称
A19: S1 | B19: 2023-10-07 | C19: 2024-12-31 | D19: PX扩能兑现+PTA过剩，加工费中枢下移
A20: S2 | B20: 2025-01-01 | C20: 2025-12-31 | D20: PX供给趋紧、PTA加工费走阔
A21: S3 | B21: 2026-01-01 | C21: 2026-10-20 | D21: PTA集中检修+地缘油价扰动

Sheet 03_原始数据
A1: 原始价格数据与派生列
A2: E/F/G/H 列为公式，改 PX/PTA 两列即全表联动。
N3: 阶段起点行 | O3: 阶段终点行
A4: 日期 | B4: PX 元/吨 | C4: PTA 元/吨 | D4: 区间涨跌 PX% | E4: 理论价差 | F4: PTA/PX | G4: PX 日收益 | H4: PTA 日收益
A5: 2023-10-08 | B5: 9500 | C5: 6013.64 | E5: =C5-Lambda*B5-OtherCost | F5: =C5/B5 | N5: 5 | O5: 328
A6: 2023-10-09 | B6: 9500 | C6: 5962.73 | E6: =C6-Lambda*B6-OtherCost | F6: =C6/B6 | G6: =B6/B5-1 | H6: =C6/C5-1 | N6: 329 | O6: 622
A7: 2023-10-10 | B7: 9100 | C7: 5961.82 | E7: =C7-Lambda*B7-OtherCost | F7: =C7/B7 | G7: =B7/B6-1 | H7: =C7/C6-1 | N7: 623 | O7: 873
A8: 2023-10-11 | B8: 9100 | C8: 5898 | E8: =C8-Lambda*B8-OtherCost | F8: =C8/B8 | G8: =B8/B7-1 | H8: =C8/C7-1
A9: 2023-10-12 | B9: 9100 | C9: 5854.5 | E9: =C9-Lambda*B9-OtherCost | F9: =C9/B9 | G9: =B9/B8-1 | H9: =C9/C8-1
A10: 2023-10-15 | B10: 9100 | C10: 5871 | E10: =C10-Lambda*B10-OtherCost | F10: =C10/B10 | G10: =B10/B9-1 | H10: =C10/C9-1
A11: 2023-10-16 | B11: 9100 | C11: 5870 | E11: =C11-Lambda*B11-OtherCost | F11: =C11/B11 | G11: =B11/B10-1 | H11: =C11/C10-1
A12: 2023-10-17 | B12: 9100 | C12: 5867.5 | E12: =C12-Lambda*B12-OtherCost | F12: =C12/B12 | G12: =B12/B11-1 | H12: =C12/C11-1
A13: 2023-10-18 | B13: 9100 | C13: 5856 | E13: =C13-Lambda*B13-OtherCost | F13: =C13/B13 | G13: =B13/B12-1 | H13: =C13/C12-1
A14: 2023-10-19 | B14: 9100 | C14: 5851 | E14: =C14-Lambda*B14-OtherCost | F14: =C14/B14 | G14: =B14/B13-1 | H14: =C14/C13-1
A15: 2023-10-22 | B15: 9100 | C15: 5851 | E15: =C15-Lambda*B15-OtherCost | F15: =C15/B15 | G15: =B15/B14-1 | H15: =C15/C14-1
A16: 2023-10-23 | B16: 9100 | C16: 5851 | E16: =C16-Lambda*B16-OtherCost | F16: =C16/B16 | G16: =B16/B15-1 | H16: =C16/C15-1
A17: 2023-10-24 | B17: 9100 | C17: 5851.5 | E17: =C17-Lambda*B17-OtherCost | F17: =C17/B17 | G17: =B17/B16-1 | H17: =C17/C16-1
A18: 2023-10-25 | B18: 9100 | C18: 5873 | E18: =C18-Lambda*B18-OtherCost | F18: =C18/B18 | G18: =B18/B17-1 | H18: =C18/C17-1
A19: 2023-10-26 | B19: 9100 | C19: 5875.5 | E19: =C19-Lambda*B19-OtherCost | F19: =C19/B19 | G19: =B19/B18-1 | H19: =C19/C18-1
... A873: 2026-10-20 | B873: 10500 | C873: 7054.5 | E873: =C873-Lambda*B873-OtherCost | F873: =C873/B873 | G873: =B873/B872-1 | H873: =C873/C872-1

Sheet 04_单耗台账
A1: 单耗台账：0.647~0.657 的出处
A2: 单耗是加工价差的唯一乘数，必须逐条可追溯；无出处不得使用。
A4: 序号 | B4: 装置/口径 | C4: PX 单耗 t/t | D4: 醋酸 t/t | E4: 高压蒸汽 t/t | F4: 电力 kWh/t | G4: 来源
A5: 1 | B5: 汉邦石化一期 | C5: 0.657 | D5: 0.036 | E5: 1.15 | F5: 26.4 | G5: 天风证券 2019-12-14 表4
A6: 2 | B6: 华彬石化 | C6: 0.654 | D6: 0.04 | E6: 1.04 | F6: 68.6 | G6: 同上
A7: 3 | B7: 恒力石化 1-3# | C7: 0.655 | D7: 0.036 | E7: 0.67 | F7: -17.8 | G7: 同上（电力为负＝副产外送）
A8: 4 | B8: 桐昆嘉兴一期 | C8: 0.657 | D8: 0.038 | E8: 0.76 | F8: 0 | G8: 同上
A9: 5 | B9: 汉邦石化二期 | C9: 0.654 | D9: 0.035 | E9: 0.6 | F9: 92.4 | G9: 同上
A10: 6 | B10: 桐昆嘉兴二期 | C10: 0.651 | D10: 0.033 | E10: 0.52 | F10: 0 | G10: 同上
A11: 7 | B11: 新凤鸣独山 | C11: 0.647 | D11: 0.032 | E11: 0.65 | F11: -25.1 | G11: 同上
A12: 8 | B12: 恒力石化 4-5#（P8+） | C12: 0.649 | D12: 0.029 | E12: 0.48 | F12: -100 | G12: 同上
A13: 9 | B13: 行业通用（估值口径） | C13: 0.655 | D13: 0.032 | G13: 长江期货 2023-12-18
A14: 10 | B14: SCI99 调研口径 | C14: 0.653 | D14: 0.035 | G14: SCI99 2026-08-20（醋酸 0.030~0.039）
A15: 11 | B15: 均值（1-8 行） | C15: =AVERAGE(C5:C12) | D15: =AVERAGE(D5:D12) | E15: =AVERAGE(E5:E12) | F15: =AVERAGE(F5:F12) | G15: 逐套装置算术平均
A16: 12 | B16: 极差（1-8 行） | C16: =MAX(C5:C12)-MIN(C5:C12) | D16: =MAX(D5:D12)-MIN(D5:D12) | E16: =MAX(E5:E12)-MIN(E5:E12) | G16: 单耗离散度：PX 仅 ±0.8%，说明单耗稳定

Sheet 05_单耗敏感性
A1: 单耗敏感性
A2: λ 每变动 0.001 t/t，价差水平整体平移约 PX 价格×0.001（元/吨）。
M3: 辅助：各 λ 下的价差序列（列＝λ，行＝日期观测）
A4: λ | B4: 价差均值 | C4: 价差中位 | D4: P10 | E4: P50 | F4: P90 | G4: 价差标准差 | H4: 与 λ=0.655 之差 | M4: 0.6 | N4: 0.605 | O4: 0.61 | P4: 0.615 | Q4: 0.62 | R4: 0.625 | S4: 0.63 | T4: 0.635 | U4: 0.64 | V4: 0.645 | W4: 0.65 | X4: 0.655 | Y4: 0.66 | Z4: 0.665 | AA4: 0.67 | AB4: 0.675 | AC4: 0.68 | AD4: 0.685 | AE4: 0.69 | AF4: 0.695 | AG4: 0.7
A5: 0.6 | B5: =AVERAGE($M$5:$M$873) | C5: =MEDIAN($M$5:$M$873) | D5: =_xlfn.PERCENTILE.INC($M$5:$M$873,0.1) | E5: =_xlfn.PERCENTILE.INC($M$5:$M$873,0.5) | F5: =_xlfn.PERCENTILE.INC($M$5:$M$873,0.9) | G5: =STDEV($M$5:$M$873) | H5: =B5-$B$16 | M5: ='03_原始数据'!C5-0.6*'03_原始数据'!B5-OtherCost | N5: ='03_原始数据'!C5-0.605*'03_原始数据'!B5-OtherCost | O5: ='03_原始数据'!C5-0.61*'03_原始数据'!B5-OtherCost | P5: ='03_原始数据'!C5-0.615*'03_原始数据'!B5-OtherCost | Q5: ='03_原始数据'!C5-0.62*'03_原始数据'!B5-OtherCost | R5: ='03_原始数据'!C5-0.625*'03_原始数据'!B5-OtherCost | S5: ='03_原始数据'!C5-0.63*'03_原始数据'!B5-OtherCost | T5: ='03_原始数据'!C5-0.635*'03_原始数据'!B5-OtherCost | U5: ='03_原始数据'!C5-0.64*'03_原始数据'!B5-OtherCost | V5: ='03_原始数据'!C5-0.645*'03_原始数据'!B5-OtherCost | W5: ='03_原始数据'!C5-0.65*'03_原始数据'!B5-OtherCost | X5: ='03_原始数据'!C5-0.655*'03_原始数据'!B5-OtherCost | Y5: ='03_原始数据'!C5-0.66*'03_原始数据'!B5-OtherCost | Z5: ='03_原始数据'!C5-0.665*'03_原始数据'!B5-OtherCost | AA5: ='03_原始数据'!C5-0.67*'03_原始数据'!B5-OtherCost | AB5: ='03_原始数据'!C5-0.675*'03_原始数据'!B5-OtherCost | AC5: ='03_原始数据'!C5-0.68*'03_原始数据'!B5-OtherCost | AD5: ='03_原始数据'!C5-0.685*'03_原始数据'!B5-OtherCost | AE5: ='03_原始数据'!C5-0.69*'03_原始数据'!B5-OtherCost | AF5: ='03_原始数据'!C5-0.695*'03_原始数据'!B5-OtherCost | AG5: ='03_原始数据'!C5-0.7*'03_原始数据'!B5-OtherCost
A6: 0.605 | B6: =AVERAGE($N$5:$N$873) | C6: =MEDIAN($N$5:$N$873) | D6: =_xlfn.PERCENTILE.INC($N$5:$N$873,0.1) | E6: =_xlfn.PERCENTILE.INC($N$5:$N$873,0.5) | F6: =_xlfn.PERCENTILE.INC($N$5:$N$873,0.9) | G6: =STDEV($N$5:$N$873) | H6: =B6-$B$16 | M6: ='03_原始数据'!C6-0.6*'03_原始数据'!B6-OtherCost | N6: ='03_原始数据'!C6-0.605*'03_原始数据'!B6-OtherCost | O6: ='03_原始数据'!C6-0.61*'03_原始数据'!B6-OtherCost | P6: ='03_原始数据'!C6-0.615*'03_原始数据'!B6-OtherCost | Q6: ='03_原始数据'!C6-0.62*'03_原始数据'!B6-OtherCost | R6: ='03_原始数据'!C6-0.625*'03_原始数据'!B6-OtherCost | S6: ='03_原始数据'!C6-0.63*'03_原始数据'!B6-OtherCost | T6: ='03_原始数据'!C6-0.635*'03_原始数据'!B6-OtherCost | U6: ='03_原始数据'!C6-0.64*'03_原始数据'!B6-OtherCost | V6: ='03_原始数据'!C6-0.645*'03_原始数据'!B6-OtherCost | W6: ='03_原始数据'!C6-0.65*'03_原始数据'!B6-OtherCost | X6: ='03_原始数据'!C6-0.655*'03_原始数据'!B6-OtherCost | Y6: ='03_原始数据'!C6-0.66*'03_原始数据'!B6-OtherCost | Z6: ='03_原始数据'!C6-0.665*'03_原始数据'!B6-OtherCost | AA6: ='03_原始数据'!C6-0.67*'03_原始数据'!B6-OtherCost | AB6: ='03_原始数据'!C6-0.675*'03_原始数据'!B6-OtherCost | AC6: ='03_原始数据'!C6-0.68*'03_原始数据'!B6-OtherCost | AD6: ='03_原始数据'!C6-0.685*'03_原始数据'!B6-OtherCost | AE6: ='03_原始数据'!C6-0.69*'03_原始数据'!B6-OtherCost | AF6: ='03_原始数据'!C6-0.695*'03_原始数据'!B6-OtherCost | AG6: ='03_原始数据'!C6-0.7*'03_原始数据'!B6-OtherCost
A7: 0.61 | B7: =AVERAGE($O$5:$O$873) | C7: =MEDIAN($O$5:$O$873) | D7: =_xlfn.PERCENTILE.INC($O$5:$O$873,0.1) | E7: =_xlfn.PERCENTILE.INC($O$5:$O$873,0.5) | F7: =_xlfn.PERCENTILE.INC($O$5:$O$873,0.9) | G7: =STDEV($O$5:$O$873) | H7: =B7-$B$16 | M7: ='03_原始数据'!C7-0.6*'03_原始数据'!B7-OtherCost | N7: ='03_原始数据'!C7-0.605*'03_原始数据'!B7-OtherCost | O7: ='03_原始数据'!C7-0.61*'03_原始数据'!B7-OtherCost | P7: ='03_原始数据'!C7-0.615*'03_原始数据'!B7-OtherCost | Q7: ='03_原始数据'!C7-0.62*'03_原始数据'!B7-OtherCost | R7: ='03_原始数据'!C7-0.625*'03_原始数据'!B7-OtherCost | S7: ='03_原始数据'!C7-0.63*'03_原始数据'!B7-OtherCost | T7: ='03_原始数据'!C7-0.635*'03_原始数据'!B7-OtherCost | U7: ='03_原始数据'!C7-0.64*'03_原始数据'!B7-OtherCost | V7: ='03_原始数据'!C7-0.645*'03_原始数据'!B7-OtherCost | W7: ='03_原始数据'!C7-0.65*'03_原始数据'!B7-OtherCost | X7: ='03_原始数据'!C7-0.655*'03_原始数据'!B7-OtherCost | Y7: ='03_原始数据'!C7-0.66*'03_原始数据'!B7-OtherCost | Z7: ='03_原始数据'!C7-0.665*'03_原始数据'!B7-OtherCost | AA7: ='03_原始数据'!C7-0.67*'03_原始数据'!B7-OtherCost | AB7: ='03_原始数据'!C7-0.675*'03_原始数据'!B7-OtherCost | AC7: ='03_原始数据'!C7-0.68*'03_原始数据'!B7-OtherCost | AD7: ='03_原始数据'!C7-0.685*'03_原始数据'!B7-OtherCost | AE7: ='03_原始数据'!C7-0.69*'03_原始数据'!B7-OtherCost | AF7: ='03_原始数据'!C7-0.695*'03_原始数据'!B7-OtherCost | AG7: ='03_原始数据'!C7-0.7*'03_原始数据'!B7-OtherCost
A8: 0.615 | B8: =AVERAGE($P$5:$P$873) | C8: =MEDIAN($P$5:$P$873) | D8: =_xlfn.PERCENTILE.INC($P$5:$P$873,0.1) | E8: =_xlfn.PERCENTILE.INC($P$5:$P$873,0.5) | F8: =_xlfn.PERCENTILE.INC($P$5:$P$873,0.9) | G8: =STDEV($P$5:$P$873) | H8: =B8-$B$16 | J8: 注：PERCENTILE.INC 与报告和 Python 的线性插值分位一致；PERCENTILE.EXC 会给出不同结果，勿混用。 | M8: ='03_原始数据'!C8-0.6*'03_原始数据'!B8-OtherCost | N8: ='03_原始数据'!C8-0.605*'03_原始数据'!B8-OtherCost | O8: ='03_原始数据'!C8-0.61*'03_原始数据'!B8-OtherCost | P8: ='03_原始数据'!C8-0.615*'03_原始数据'!B8-OtherCost | Q8: ='03_原始数据'!C8-0.62*'03_原始数据'!B8-OtherCost | R8: ='03_原始数据'!C8-0.625*'03_原始数据'!B8-OtherCost | S8: ='03_原始数据'!C8-0.63*'03_原始数据'!B8-OtherCost | T8: ='03_原始数据'!C8-0.635*'03_原始数据'!B8-OtherCost | U8: ='03_原始数据'!C8-0.64*'03_原始数据'!B8-OtherCost | V8: ='03_原始数据'!C8-0.645*'03_原始数据'!B8-OtherCost | W8: ='03_原始数据'!C8-0.65*'03_原始数据'!B8-OtherCost | X8: ='03_原始数据'!C8-0.655*'03_原始数据'!B8-OtherCost | Y8: ='03_原始数据'!C8-0.66*'03_原始数据'!B8-OtherCost | Z8: ='03_原始数据'!C8-0.665*'03_原始数据'!B8-OtherCost | AA8: ='03_原始数据'!C8-0.67*'03_原始数据'!B8-OtherCost | AB8: ='03_原始数据'!C8-0.675*'03_原始数据'!B8-OtherCost | AC8: ='03_原始数据'!C8-0.68*'03_原始数据'!B8-OtherCost | AD8: ='03_原始数据'!C8-0.685*'03_原始数据'!B8-OtherCost | AE8: ='03_原始数据'!C8-0.69*'03_原始数据'!B8-OtherCost | AF8: ='03_原始数据'!C8-0.695*'03_原始数据'!B8-OtherCost | AG8: ='03_原始数据'!C8-0.7*'03_原始数据'!B8-OtherCost
A9: 0.62 | B9: =AVERAGE($Q$5:$Q$873) | C9: =MEDIAN($Q$5:$Q$873) | D9: =_xlfn.PERCENTILE.INC($Q$5:$Q$873,0.1) | E9: =_xlfn.PERCENTILE.INC($Q$5:$Q$873,0.5) | F9: =_xlfn.PERCENTILE.INC($Q$5:$Q$873,0.9) | G9: =STDEV($Q$5:$Q$873) | H9: =B9-$B$16 | M9: ='03_原始数据'!C9-0.6*'03_原始数据'!B9-OtherCost | N9: ='03_原始数据'!C9-0.605*'03_原始数据'!B9-OtherCost | O9: ='03_原始数据'!C9-0.61*'03_原始数据'!B9-OtherCost | P9: ='03_原始数据'!C9-0.615*'03_原始数据'!B9-OtherCost | Q9: ='03_原始数据'!C9-0.62*'03_原始数据'!B9-OtherCost | R9: ='03_原始数据'!C9-0.625*'03_原始数据'!B9-OtherCost | S9: ='03_原始数据'!C9-0.63*'03_原始数据'!B9-OtherCost | T9: ='03_原始数据'!C9-0.635*'03_原始数据'!B9-OtherCost | U9: ='03_原始数据'!C9-0.64*'03_原始数据'!B9-OtherCost | V9: ='03_原始数据'!C9-0.645*'03_原始数据'!B9-OtherCost | W9: ='03_原始数据'!C9-0.65*'03_原始数据'!B9-OtherCost | X9: ='03_原始数据'!C9-0.655*'03_原始数据'!B9-OtherCost | Y9: ='03_原始数据'!C9-0.66*'03_原始数据'!B9-OtherCost | Z9: ='03_原始数据'!C9-0.665*'03_原始数据'!B9-OtherCost | AA9: ='03_原始数据'!C9-0.67*'03_原始数据'!B9-OtherCost | AB9: ='03_原始数据'!C9-0.675*'03_原始数据'!B9-OtherCost | AC9: ='03_原始数据'!C9-0.68*'03_原始数据'!B9-OtherCost | AD9: ='03_原始数据'!C9-0.685*'03_原始数据'!B9-OtherCost | AE9: ='03_原始数据'!C9-0.69*'03_原始数据'!B9-OtherCost | AF9: ='03_原始数据'!C9-0.695*'03_原始数据'!B9-OtherCost | AG9: ='03_原始数据'!C9-0.7*'03_原始数据'!B9-OtherCost
A10: 0.625 | B10: =AVERAGE($R$5:$R$873) | C10: =MEDIAN($R$5:$R$873) | D10: =_xlfn.PERCENTILE.INC($R$5:$R$873,0.1) | E10: =_xlfn.PERCENTILE.INC($R$5:$R$873,0.5) | F10: =_xlfn.PERCENTILE.INC($R$5:$R$873,0.9) | G10: =STDEV($R$5:$R$873) | H10: =B10-$B$16 | M10: ='03_原始数据'!C10-0.6*'03_原始数据'!B10-OtherCost | N10: ='03_原始数据'!C10-0.605*'03_原始数据'!B10-OtherCost | O10: ='03_原始数据'!C10-0.61*'03_原始数据'!B10-OtherCost | P10: ='03_原始数据'!C10-0.615*'03_原始数据'!B10-OtherCost | Q10: ='03_原始数据'!C10-0.62*'03_原始数据'!B10-OtherCost | R10: ='03_原始数据'!C10-0.625*'03_原始数据'!B10-OtherCost | S10: ='03_原始数据'!C10-0.63*'03_原始数据'!B10-OtherCost | T10: ='03_原始数据'!C10-0.635*'03_原始数据'!B10-OtherCost | U10: ='03_原始数据'!C10-0.64*'03_原始数据'!B10-OtherCost | V10: ='03_原始数据'!C10-0.645*'03_原始数据'!B10-OtherCost | W10: ='03_原始数据'!C10-0.65*'03_原始数据'!B10-OtherCost | X10: ='03_原始数据'!C10-0.655*'03_原始数据'!B10-OtherCost | Y10: ='03_原始数据'!C10-0.66*'03_原始数据'!B10-OtherCost | Z10: ='03_原始数据'!C10-0.665*'03_原始数据'!B10-OtherCost | AA10: ='03_原始数据'!C10-0.67*'03_原始数据'!B10-OtherCost | AB10: ='03_原始数据'!C10-0.675*'03_原始数据'!B10-OtherCost | AC10: ='03_原始数据'!C10-0.68*'03_原始数据'!B10-OtherCost | AD10: ='03_原始数据'!C10-0.685*'03_原始数据'!B10-OtherCost | AE10: ='03_原始数据'!C10-0.69*'03_原始数据'!B10-OtherCost | AF10: ='03_原始数据'!C10-0.695*'03_原始数据'!B10-OtherCost | AG10: ='03_原始数据'!C10-0.7*'03_原始数据'!B10-OtherCost
A11: 0.63 | B11: =AVERAGE($S$5:$S$873) | C11: =MEDIAN($S$5:$S$873) | D11: =_xlfn.PERCENTILE.INC($S$5:$S$873,0.1) | E11: =_xlfn.PERCENTILE.INC($S$5:$S$873,0.5) | F11: =_xlfn.PERCENTILE.INC($S$5:$S$873,0.9) | G11: =STDEV($S$5:$S$873) | H11: =B11-$B$16 | M11: ='03_原始数据'!C11-0.6*'03_原始数据'!B11-OtherCost | N11: ='03_原始数据'!C11-0.605*'03_原始数据'!B11-OtherCost | O11: ='03_原始数据'!C11-0.61*'03_原始数据'!B11-OtherCost | P11: ='03_原始数据'!C11-0.615*'03_原始数据'!B11-OtherCost | Q11: ='03_原始数据'!C11-0.62*'03_原始数据'!B11-OtherCost | R11: ='03_原始数据'!C11-0.625*'03_原始数据'!B11-OtherCost | S11: ='03_原始数据'!C11-0.63*'03_原始数据'!B11-OtherCost | T11: ='03_原始数据'!C11-0.635*'03_原始数据'!B11-OtherCost | U11: ='03_原始数据'!C11-0.64*'03_原始数据'!B11-OtherCost | V11: ='03_原始数据'!C11-0.645*'03_原始数据'!B11-OtherCost | W11: ='03_原始数据'!C11-0.65*'03_原始数据'!B11-OtherCost | X11: ='03_原始数据'!C11-0.655*'03_原始数据'!B11-OtherCost | Y11: ='03_原始数据'!C11-0.66*'03_原始数据'!B11-OtherCost | Z11: ='03_原始数据'!C11-0.665*'03_原始数据'!B11-OtherCost | AA11: ='03_原始数据'!C11-0.67*'03_原始数据'!B11-OtherCost | AB11: ='03_原始数据'!C11-0.675*'03_原始数据'!B11-OtherCost | AC11: ='03_原始数据'!C11-0.68*'03_原始数据'!B11-OtherCost | AD11: ='03_原始数据'!C11-0.685*'03_原始数据'!B11-OtherCost | AE11: ='03_原始数据'!C11-0.69*'03_原始数据'!B11-OtherCost | AF11: ='03_原始数据'!C11-0.695*'03_原始数据'!B11-OtherCost | AG11: ='03_原始数据'!C11-0.7*'03_原始数据'!B11-OtherCost
A12: 0.635 | B12: =AVERAGE($T$5:$T$873) | C12: =MEDIAN($T$5:$T$873) | D12: =_xlfn.PERCENTILE.INC($T$5:$T$873,0.1) | E12: =_xlfn.PERCENTILE.INC($T$5:$T$873,0.5) | F12: =_xlfn.PERCENTILE.INC($T$5:$T$873,0.9) | G12: =STDEV($T$5:$T$873) | H12: =B12-$B$16 | M12: ='03_原始数据'!C12-0.6*'03_原始数据'!B12-OtherCost | N12: ='03_原始数据'!C12-0.605*'03_原始数据'!B12-OtherCost | O12: ='03_原始数据'!C12-0.61*'03_原始数据'!B12-OtherCost | P12: ='03_原始数据'!C12-0.615*'03_原始数据'!B12-OtherCost | Q12: ='03_原始数据'!C12-0.62*'03_原始数据'!B12-OtherCost | R12: ='03_原始数据'!C12-0.625*'03_原始数据'!B12-OtherCost | S12: ='03_原始数据'!C12-0.63*'03_原始数据'!B12-OtherCost | T12: ='03_原始数据'!C12-0.635*'03_原始数据'!B12-OtherCost | U12: ='03_原始数据'!C12-0.64*'03_原始数据'!B12-OtherCost | V12: ='03_原始数据'!C12-0.645*'03_原始数据'!B12-OtherCost | W12: ='03_原始数据'!C12-0.65*'03_原始数据'!B12-OtherCost | X12: ='03_原始数据'!C12-0.655*'03_原始数据'!B12-OtherCost | Y12: ='03_原始数据'!C12-0.66*'03_原始数据'!B12-OtherCost | Z12: ='03_原始数据'!C12-0.665*'03_原始数据'!B12-OtherCost | AA12: ='03_原始数据'!C12-0.67*'03_原始数据'!B12-OtherCost | AB12: ='03_原始数据'!C12-0.675*'03_原始数据'!B12-OtherCost | AC12: ='03_原始数据'!C12-0.68*'03_原始数据'!B12-OtherCost | AD12: ='03_原始数据'!C12-0.685*'03_原始数据'!B12-OtherCost | AE12: ='03_原始数据'!C12-0.69*'03_原始数据'!B12-OtherCost | AF12: ='03_原始数据'!C12-0.695*'03_原始数据'!B12-OtherCost | AG12: ='03_原始数据'!C12-0.7*'03_原始数据'!B12-OtherCost
A13: 0.64 | B13: =AVERAGE($U$5:$U$873) | C13: =MEDIAN($U$5:$U$873) | D13: =_xlfn.PERCENTILE.INC($U$5:$U$873,0.1) | E13: =_xlfn.PERCENTILE.INC($U$5:$U$873,0.5) | F13: =_xlfn.PERCENTILE.INC($U$5:$U$873,0.9) | G13: =STDEV($U$5:$U$873) | H13: =B13-$B$16 | M13: ='03_原始数据'!C13-0.6*'03_原始数据'!B13-OtherCost | N13: ='03_原始数据'!C13-0.605*'03_原始数据'!B13-OtherCost | O13: ='03_原始数据'!C13-0.61*'03_原始数据'!B13-OtherCost | P13: ='03_原始数据'!C13-0.615*'03_原始数据'!B13-OtherCost | Q13: ='03_原始数据'!C13-0.62*'03_原始数据'!B13-OtherCost | R13: ='03_原始数据'!C13-0.625*'03_原始数据'!B13-OtherCost | S13: ='03_原始数据'!C13-0.63*'03_原始数据'!B13-OtherCost | T13: ='03_原始数据'!C13-0.635*'03_原始数据'!B13-OtherCost | U13: ='03_原始数据'!C13-0.64*'03_原始数据'!B13-OtherCost | V13: ='03_原始数据'!C13-0.645*'03_原始数据'!B13-OtherCost | W13: ='03_原始数据'!C13-0.65*'03_原始数据'!B13-OtherCost | X13: ='03_原始数据'!C13-0.655*'03_原始数据'!B13-OtherCost | Y13: ='03_原始数据'!C13-0.66*'03_原始数据'!B13-OtherCost | Z13: ='03_原始数据'!C13-0.665*'03_原始数据'!B13-OtherCost | AA13: ='03_原始数据'!C13-0.67*'03_原始数据'!B13-OtherCost | AB13: ='03_原始数据'!C13-0.675*'03_原始数据'!B13-OtherCost | AC13: ='03_原始数据'!C13-0.68*'03_原始数据'!B13-OtherCost | AD13: ='03_原始数据'!C13-0.685*'03_原始数据'!B13-OtherCost | AE13: ='03_原始数据'!C13-0.69*'03_原始数据'!B13-OtherCost | AF13: ='03_原始数据'!C13-0.695*'03_原始数据'!B13-OtherCost | AG13: ='03_原始数据'!C13-0.7*'03_原始数据'!B13-OtherCost
A14: 0.645 | B14: =AVERAGE($V$5:$V$873) | C14: =MEDIAN($V$5:$V$873) | D14: =_xlfn.PERCENTILE.INC($V$5:$V$873,0.1) | E14: =_xlfn.PERCENTILE.INC($V$5:$V$873,0.5) | F14: =_xlfn.PERCENTILE.INC($V$5:$V$873,0.9) | G14: =STDEV($V$5:$V$873) | H14: =B14-$B$16 | M14: ='03_原始数据'!C14-0.6*'03_原始数据'!B14-OtherCost | N14: ='03_原始数据'!C14-0.605*'03_原始数据'!B14-OtherCost | O14: ='03_原始数据'!C14-0.61*'03_原始数据'!B14-OtherCost | P14: ='03_原始数据'!C14-0.615*'03_原始数据'!B14-OtherCost | Q14: ='03_原始数据'!C14-0.62*'03_原始数据'!B14-OtherCost | R14: ='03_原始数据'!C14-0.625*'03_原始数据'!B14-OtherCost | S14: ='03_原始数据'!C14-0.63*'03_原始数据'!B14-OtherCost | T14: ='03_原始数据'!C14-0.635*'03_原始数据'!B14-OtherCost | U14: ='03_原始数据'!C14-0.64*'03_原始数据'!B14-OtherCost | V14: ='03_原始数据'!C14-0.645*'03_原始数据'!B14-OtherCost | W14: ='03_原始数据'!C14-0.65*'03_原始数据'!B14-OtherCost | X14: ='03_原始数据'!C14-0.655*'03_原始数据'!B14-OtherCost | Y14: ='03_原始数据'!C14-0.66*'03_原始数据'!B14-OtherCost | Z14: ='03_原始数据'!C14-0.665*'03_原始数据'!B14-OtherCost | AA14: ='03_原始数据'!C14-0.67*'03_原始数据'!B14-OtherCost | AB14: ='03_原始数据'!C14-0.675*'03_原始数据'!B14-OtherCost | AC14: ='03_原始数据'!C14-0.68*'03_原始数据'!B14-OtherCost | AD14: ='03_原始数据'!C14-0.685*'03_原始数据'!B14-OtherCost | AE14: ='03_原始数据'!C14-0.69*'03_原始数据'!B14-OtherCost | AF14: ='03_原始数据'!C14-0.695*'03_原始数据'!B14-OtherCost | AG14: ='03_原始数据'!C14-0.7*'03_原始数据'!B14-OtherCost
A15: 0.65 | B15: =AVERAGE($W$5:$W$873) | C15: =MEDIAN($W$5:$W$873) | D15: =_xlfn.PERCENTILE.INC($W$5:$W$873,0.1) | E15: =_xlfn.PERCENTILE.INC($W$5:$W$873,0.5) | F15: =_xlfn.PERCENTILE.INC($W$5:$W$873,0.9) | G15: =STDEV($W$5:$W$873) | H15: =B15-$B$16 | M15: ='03_原始数据'!C15-0.6*'03_原始数据'!B15-OtherCost | N15: ='03_原始数据'!C15-0.605*'03_原始数据'!B15-OtherCost | O15: ='03_原始数据'!C15-0.61*'03_原始数据'!B15-OtherCost | P15: ='03_原始数据'!C15-0.615*'03_原始数据'!B15-OtherCost | Q15: ='03_原始数据'!C15-0.62*'03_原始数据'!B15-OtherCost | R15: ='03_原始数据'!C15-0.625*'03_原始数据'!B15-OtherCost | S15: ='03_原始数据'!C15-0.63*'03_原始数据'!B15-OtherCost | T15: ='03_原始数据'!C15-0.635*'03_原始数据'!B15-OtherCost | U15: ='03_原始数据'!C15-0.64*'03_原始数据'!B15-OtherCost | V15: ='03_原始数据'!C15-0.645*'03_原始数据'!B15-OtherCost | W15: ='03_原始数据'!C15-0.65*'03_原始数据'!B15-OtherCost | X15: ='03_原始数据'!C15-0.655*'03_原始数据'!B15-OtherCost | Y15: ='03_原始数据'!C15-0.66*'03_原始数据'!B15-OtherCost | Z15: ='03_原始数据'!C15-0.665*'03_原始数据'!B15-OtherCost | AA15: ='03_原始数据'!C15-0.67*'03_原始数据'!B15-OtherCost | AB15: ='03_原始数据'!C15-0.675*'03_原始数据'!B15-OtherCost | AC15: ='03_原始数据'!C15-0.68*'03_原始数据'!B15-OtherCost | AD15: ='03_原始数据'!C15-0.685*'03_原始数据'!B15-OtherCost | AE15: ='03_原始数据'!C15-0.69*'03_原始数据'!B15-OtherCost | AF15: ='03_原始数据'!C15-0.695*'03_原始数据'!B15-OtherCost | AG15: ='03_原始数据'!C15-0.7*'03_原始数据'!B15-OtherCost
A16: 0.655 | B16: =AVERAGE($X$5:$X$873) | C16: =MEDIAN($X$5:$X$873) | D16: =_xlfn.PERCENTILE.INC($X$5:$X$873,0.1) | E16: =_xlfn.PERCENTILE.INC($X$5:$X$873,0.5) | F16: =_xlfn.PERCENTILE.INC($X$5:$X$873,0.9) | G16: =STDEV($X$5:$X$873) | H16: =B16-$B$16 | M16: ='03_原始数据'!C16-0.6*'03_原始数据'!B16-OtherCost | N16: ='03_原始数据'!C16-0.605*'03_原始数据'!B16-OtherCost | O16: ='03_原始数据'!C16-0.61*'03_原始数据'!B16-OtherCost | P16: ='03_原始数据'!C16-0.615*'03_原始数据'!B16-OtherCost | Q16: ='03_原始数据'!C16-0.62*'03_原始数据'!B16-OtherCost | R16: ='03_原始数据'!C16-0.625*'03_原始数据'!B16-OtherCost | S16: ='03_原始数据'!C16-0.63*'03_原始数据'!B16-OtherCost | T16: ='03_原始数据'!C16-0.635*'03_原始数据'!B16-OtherCost | U16: ='03_原始数据'!C16-0.64*'03_原始数据'!B16-OtherCost | V16: ='03_原始数据'!C16-0.645*'03_原始数据'!B16-OtherCost | W16: ='03_原始数据'!C16-0.65*'03_原始数据'!B16-OtherCost | X16: ='03_原始数据'!C16-0.655*'03_原始数据'!B16-OtherCost | Y16: ='03_原始数据'!C16-0.66*'03_原始数据'!B16-OtherCost | Z16: ='03_原始数据'!C16-0.665*'03_原始数据'!B16-OtherCost | AA16: ='03_原始数据'!C16-0.67*'03_原始数据'!B16-OtherCost | AB16: ='03_原始数据'!C16-0.675*'03_原始数据'!B16-OtherCost | AC16: ='03_原始数据'!C16-0.68*'03_原始数据'!B16-OtherCost | AD16: ='03_原始数据'!C16-0.685*'03_原始数据'!B16-OtherCost | AE16: ='03_原始数据'!C16-0.69*'03_原始数据'!B16-OtherCost | AF16: ='03_原始数据'!C16-0.695*'03_原始数据'!B16-OtherCost | AG16: ='03_原始数据'!C16-0.7*'03_原始数据'!B16-OtherCost
A17: 0.66 | B17: =AVERAGE($Y$5:$Y$873) | C17: =MEDIAN($Y$5:$Y$873) | D17: =_xlfn.PERCENTILE.INC($Y$5:$Y$873,0.1) | E17: =_xlfn.PERCENTILE.INC($Y$5:$Y$873,0.5) | F17: =_xlfn.PERCENTILE.INC($Y$5:$Y$873,0.9) | G17: =STDEV($Y$5:$Y$873) | H17: =B17-$B$16 | M17: ='03_原始数据'!C17-0.6*'03_原始数据'!B17-OtherCost | N17: ='03_原始数据'!C17-0.605*'03_原始数据'!B17-OtherCost | O17: ='03_原始数据'!C17-0.61*'03_原始数据'!B17-OtherCost | P17: ='03_原始数据'!C17-0.615*'03_原始数据'!B17-OtherCost | Q17: ='03_原始数据'!C17-0.62*'03_原始数据'!B17-OtherCost | R17: ='03_原始数据'!C17-0.625*'03_原始数据'!B17-OtherCost | S17: ='03_原始数据'!C17-0.63*'03_原始数据'!B17-OtherCost | T17: ='03_原始数据'!C17-0.635*'03_原始数据'!B17-OtherCost | U17: ='03_原始数据'!C17-0.64*'03_原始数据'!B17-OtherCost | V17: ='03_原始数据'!C17-0.645*'03_原始数据'!B17-OtherCost | W17: ='03_原始数据'!C17-0.65*'03_原始数据'!B17-OtherCost | X17: ='03_原始数据'!C17-0.655*'03_原始数据'!B17-OtherCost | Y17: ='03_原始数据'!C17-0.66*'03_原始数据'!B17-OtherCost | Z17: ='03_原始数据'!C17-0.665*'03_原始数据'!B17-OtherCost | AA17: ='03_原始数据'!C17-0.67*'03_原始数据'!B17-OtherCost | AB17: ='03_原始数据'!C17-0.675*'03_原始数据'!B17-OtherCost | AC17: ='03_原始数据'!C17-0.68*'03_原始数据'!B17-OtherCost | AD17: ='03_原始数据'!C17-0.685*'03_原始数据'!B17-OtherCost | AE17: ='03_原始数据'!C17-0.69*'03_原始数据'!B17-OtherCost | AF17: ='03_原始数据'!C17-0.695*'03_原始数据'!B17-OtherCost | AG17: ='03_原始数据'!C17-0.7*'03_原始数据'!B17-OtherCost
A18: 0.665 | B18: =AVERAGE($Z$5:$Z$873) | C18: =MEDIAN($Z$5:$Z$873) | D18: =_xlfn.PERCENTILE.INC($Z$5:$Z$873,0.1) | E18: =_xlfn.PERCENTILE.INC($Z$5:$Z$873,0.5) | F18: =_xlfn.PERCENTILE.INC($Z$5:$Z$873,0.9) | G18: =STDEV($Z$5:$Z$873) | H18: =B18-$B$16 | M18: ='03_原始数据'!C18-0.6*'03_原始数据'!B18-OtherCost | N18: ='03_原始数据'!C18-0.605*'03_原始数据'!B18-OtherCost | O18: ='03_原始数据'!C18-0.61*'03_原始数据'!B18-OtherCost | P18: ='03_原始数据'!C18-0.615*'03_原始数据'!B18-OtherCost | Q18: ='03_原始数据'!C18-0.62*'03_原始数据'!B18-OtherCost | R18: ='03_原始数据'!C18-0.625*'03_原始数据'!B18-OtherCost | S18: ='03_原始数据'!C18-0.63*'03_原始数据'!B18-OtherCost | T18: ='03_原始数据'!C18-0.635*'03_原始数据'!B18-OtherCost | U18: ='03_原始数据'!C18-0.64*'03_原始数据'!B18-OtherCost | V18: ='03_原始数据'!C18-0.645*'03_原始数据'!B18-OtherCost | W18: ='03_原始数据'!C18-0.65*'03_原始数据'!B18-OtherCost | X18: ='03_原始数据'!C18-0.655*'03_原始数据'!B18-OtherCost | Y18: ='03_原始数据'!C18-0.66*'03_原始数据'!B18-OtherCost | Z18: ='03_原始数据'!C18-0.665*'03_原始数据'!B18-OtherCost | AA18: ='03_原始数据'!C18-0.67*'03_原始数据'!B18-OtherCost | AB18: ='03_原始数据'!C18-0.675*'03_原始数据'!B18-OtherCost | AC18: ='03_原始数据'!C18-0.68*'03_原始数据'!B18-OtherCost | AD18: ='03_原始数据'!C18-0.685*'03_原始数据'!B18-OtherCost | AE18: ='03_原始数据'!C18-0.69*'03_原始数据'!B18-OtherCost | AF18: ='03_原始数据'!C18-0.695*'03_原始数据'!B18-OtherCost | AG18: ='03_原始数据'!C18-0.7*'03_原始数据'!B18-OtherCost
A19: 0.67 | B19: =AVERAGE($AA$5:$AA$873) | C19: =MEDIAN($AA$5:$AA$873) | D19: =_xlfn.PERCENTILE.INC($AA$5:$AA$873,0.1) | E19: =_xlfn.PERCENTILE.INC($AA$5:$AA$873,0.5) | F19: =_xlfn.PERCENTILE.INC($AA$5:$AA$873,0.9) | G19: =STDEV($AA$5:$AA$873) | H19: =B19-$B$16 | M19: ='03_原始数据'!C19-0.6*'03_原始数据'!B19-OtherCost | N19: ='03_原始数据'!C19-0.605*'03_原始数据'!B19-OtherCost | O19: ='03_原始数据'!C19-0.61*'03_原始数据'!B19-OtherCost | P19: ='03_原始数据'!C19-0.615*'03_原始数据'!B19-OtherCost | Q19: ='03_原始数据'!C19-0.62*'03_原始数据'!B19-OtherCost | R19: ='03_原始数据'!C19-0.625*'03_原始数据'!B19-OtherCost | S19: ='03_原始数据'!C19-0.63*'03_原始数据'!B19-OtherCost | T19: ='03_原始数据'!C19-0.635*'03_原始数据'!B19-OtherCost | U19: ='03_原始数据'!C19-0.64*'03_原始数据'!B19-OtherCost | V19: ='03_原始数据'!C19-0.645*'03_原始数据'!B19-OtherCost | W19: ='03_原始数据'!C19-0.65*'03_原始数据'!B19-OtherCost | X19: ='03_原始数据'!C19-0.655*'03_原始数据'!B19-OtherCost | Y19: ='03_原始数据'!C19-0.66*'03_原始数据'!B19-OtherCost | Z19: ='03_原始数据'!C19-0.665*'03_原始数据'!B19-OtherCost | AA19: ='03_原始数据'!C19-0.67*'03_原始数据'!B19-OtherCost | AB19: ='03_原始数据'!C19-0.675*'03_原始数据'!B19-OtherCost | AC19: ='03_原始数据'!C19-0.68*'03_原始数据'!B19-OtherCost | AD19: ='03_原始数据'!C19-0.685*'03_原始数据'!B19-OtherCost | AE19: ='03_原始数据'!C19-0.69*'03_原始数据'!B19-OtherCost | AF19: ='03_原始数据'!C19-0.695*'03_原始数据'!B19-OtherCost | AG19: ='03_原始数据'!C19-0.7*'03_原始数据'!B19-OtherCost
A20: 0.675 | B20: =AVERAGE($AB$5:$AB$873) | C20: =MEDIAN($AB$5:$AB$873) | D20: =_xlfn.PERCENTILE.INC($AB$5:$AB$873,0.1) | E20: =_xlfn.PERCENTILE.INC($AB$5:$AB$873,0.5) | F20: =_xlfn.PERCENTILE.INC($AB$5:$AB$873,0.9) | G20: =STDEV($AB$5:$AB$873) | H20: =B20-$B$16 | M20: ='03_原始数据'!C20-0.6*'03_原始数据'!B20-OtherCost | N20: ='03_原始数据'!C20-0.605*'03_原始数据'!B20-OtherCost | O20: ='03_原始数据'!C20-0.61*'03_原始数据'!B20-OtherCost | P20: ='03_原始数据'!C20-0.615*'03_原始数据'!B20-OtherCost | Q20: ='03_原始数据'!C20-0.62*'03_原始数据'!B20-OtherCost | R20: ='03_原始数据'!C20-0.625*'03_原始数据'!B20-OtherCost | S20: ='03_原始数据'!C20-0.63*'03_原始数据'!B20-OtherCost | T20: ='03_原始数据'!C20-0.635*'03_原始数据'!B20-OtherCost | U20: ='03_原始数据'!C20-0.64*'03_原始数据'!B20-OtherCost | V20: ='03_原始数据'!C20-0.645*'03_原始数据'!B20-OtherCost | W20: ='03_原始数据'!C20-0.65*'03_原始数据'!B20-OtherCost | X20: ='03_原始数据'!C20-0.655*'03_原始数据'!B20-OtherCost | Y20: ='03_原始数据'!C20-0.66*'03_原始数据'!B20-OtherCost | Z20: ='03_原始数据'!C20-0.665*'03_原始数据'!B20-OtherCost | AA20: ='03_原始数据'!C20-0.67*'03_原始数据'!B20-OtherCost | AB20: ='03_原始数据'!C20-0.675*'03_原始数据'!B20-OtherCost | AC20: ='03_原始数据'!C20-0.68*'03_原始数据'!B20-OtherCost | AD20: ='03_原始数据'!C20-0.685*'03_原始数据'!B20-OtherCost | AE20: ='03_原始数据'!C20-0.69*'03_原始数据'!B20-OtherCost | AF20: ='03_原始数据'!C20-0.695*'03_原始数据'!B20-OtherCost | AG20: ='03_原始数据'!C20-0.7*'03_原始数据'!B20-OtherCost
A21: 0.68 | B21: =AVERAGE($AC$5:$AC$873) | C21: =MEDIAN($AC$5:$AC$873) | D21: =_xlfn.PERCENTILE.INC($AC$5:$AC$873,0.1) | E21: =_xlfn.PERCENTILE.INC($AC$5:$AC$873,0.5) | F21: =_xlfn.PERCENTILE.INC($AC$5:$AC$873,0.9) | G21: =STDEV($AC$5:$AC$873) | H21: =B21-$B$16 | M21: ='03_原始数据'!C21-0.6*'03_原始数据'!B21-OtherCost | N21: ='03_原始数据'!C21-0.605*'03_原始数据'!B21-OtherCost | O21: ='03_原始数据'!C21-0.61*'03_原始数据'!B21-OtherCost | P21: ='03_原始数据'!C21-0.615*'03_原始数据'!B21-OtherCost | Q21: ='03_原始数据'!C21-0.62*'03_原始数据'!B21-OtherCost | R21: ='03_原始数据'!C21-0.625*'03_原始数据'!B21-OtherCost | S21: ='03_原始数据'!C21-0.63*'03_原始数据'!B21-OtherCost | T21: ='03_原始数据'!C21-0.635*'03_原始数据'!B21-OtherCost | U21: ='03_原始数据'!C21-0.64*'03_原始数据'!B21-OtherCost | V21: ='03_原始数据'!C21-0.645*'03_原始数据'!B21-OtherCost | W21: ='03_原始数据'!C21-0.65*'03_原始数据'!B21-OtherCost | X21: ='03_原始数据'!C21-0.655*'03_原始数据'!B21-OtherCost | Y21: ='03_原始数据'!C21-0.66*'03_原始数据'!B21-OtherCost | Z21: ='03_原始数据'!C21-0.665*'03_原始数据'!B21-OtherCost | AA21: ='03_原始数据'!C21-0.67*'03_原始数据'!B21-OtherCost | AB21: ='03_原始数据'!C21-0.675*'03_原始数据'!B21-OtherCost | AC21: ='03_原始数据'!C21-0.68*'03_原始数据'!B21-OtherCost | AD21: ='03_原始数据'!C21-0.685*'03_原始数据'!B21-OtherCost | AE21: ='03_原始数据'!C21-0.69*'03_原始数据'!B21-OtherCost | AF21: ='03_原始数据'!C21-0.695*'03_原始数据'!B21-OtherCost | AG21: ='03_原始数据'!C21-0.7*'03_原始数据'!B21-OtherCost
A22: 0.685 | B22: =AVERAGE($AD$5:$AD$873) | C22: =MEDIAN($AD$5:$AD$873) | D22: =_xlfn.PERCENTILE.INC($AD$5:$AD$873,0.1) | E22: =_xlfn.PERCENTILE.INC($AD$5:$AD$873,0.5) | F22: =_xlfn.PERCENTILE.INC($AD$5:$AD$873,0.9) | G22: =STDEV($AD$5:$AD$873) | H22: =B22-$B$16 | M22: ='03_原始数据'!C22-0.6*'03_原始数据'!B22-OtherCost | N22: ='03_原始数据'!C22-0.605*'03_原始数据'!B22-OtherCost | O22: ='03_原始数据'!C22-0.61*'03_原始数据'!B22-OtherCost | P22: ='03_原始数据'!C22-0.615*'03_原始数据'!B22-OtherCost | Q22: ='03_原始数据'!C22-0.62*'03_原始数据'!B22-OtherCost | R22: ='03_原始数据'!C22-0.625*'03_原始数据'!B22-OtherCost | S22: ='03_原始数据'!C22-0.63*'03_原始数据'!B22-OtherCost | T22: ='03_原始数据'!C22-0.635*'03_原始数据'!B22-OtherCost | U22: ='03_原始数据'!C22-0.64*'03_原始数据'!B22-OtherCost | V22: ='03_原始数据'!C22-0.645*'03_原始数据'!B22-OtherCost | W22: ='03_原始数据'!C22-0.65*'03_原始数据'!B22-OtherCost | X22: ='03_原始数据'!C22-0.655*'03_原始数据'!B22-OtherCost | Y22: ='03_原始数据'!C22-0.66*'03_原始数据'!B22-OtherCost | Z22: ='03_原始数据'!C22-0.665*'03_原始数据'!B22-OtherCost | AA22: ='03_原始数据'!C22-0.67*'03_原始数据'!B22-OtherCost | AB22: ='03_原始数据'!C22-0.675*'03_原始数据'!B22-OtherCost | AC22: ='03_原始数据'!C22-0.68*'03_原始数据'!B22-OtherCost | AD22: ='03_原始数据'!C22-0.685*'03_原始数据'!B22-OtherCost | AE22: ='03_原始数据'!C22-0.69*'03_原始数据'!B22-OtherCost | AF22: ='03_原始数据'!C22-0.695*'03_原始数据'!B22-OtherCost | AG22: ='03_原始数据'!C22-0.7*'03_原始数据'!B22-OtherCost
A23: 0.69 | B23: =AVERAGE($AE$5:$AE$873) | C23: =MEDIAN($AE$5:$AE$873) | D23: =_xlfn.PERCENTILE.INC($AE$5:$AE$873,0.1) | E23: =_xlfn.PERCENTILE.INC($AE$5:$AE$873,0.5) | F23: =_xlfn.PERCENTILE.INC($AE$5:$AE$873,0.9) | G23: =STDEV($AE$5:$AE$873) | H23: =B23-$B$16 | M23: ='03_原始数据'!C23-0.6*'03_原始数据'!B23-OtherCost | N23: ='03_原始数据'!C23-0.605*'03_原始数据'!B23-OtherCost | O23: ='03_原始数据'!C23-0.61*'03_原始数据'!B23-OtherCost | P23: ='03_原始数据'!C23-0.615*'03_原始数据'!B23-OtherCost | Q23: ='03_原始数据'!C23-0.62*'03_原始数据'!B23-OtherCost | R23: ='03_原始数据'!C23-0.625*'03_原始数据'!B23-OtherCost | S23: ='03_原始数据'!C23-0.63*'03_原始数据'!B23-OtherCost | T23: ='03_原始数据'!C23-0.635*'03_原始数据'!B23-OtherCost | U23: ='03_原始数据'!C23-0.64*'03_原始数据'!B23-OtherCost | V23: ='03_原始数据'!C23-0.645*'03_原始数据'!B23-OtherCost | W23: ='03_原始数据'!C23-0.65*'03_原始数据'!B23-OtherCost | X23: ='03_原始数据'!C23-0.655*'03_原始数据'!B23-OtherCost | Y23: ='03_原始数据'!C23-0.66*'03_原始数据'!B23-OtherCost | Z23: ='03_原始数据'!C23-0.665*'03_原始数据'!B23-OtherCost | AA23: ='03_原始数据'!C23-0.67*'03_原始数据'!B23-OtherCost | AB23: ='03_原始数据'!C23-0.675*'03_原始数据'!B23-OtherCost | AC23: ='03_原始数据'!C23-0.68*'03_原始数据'!B23-OtherCost | AD23: ='03_原始数据'!C23-0.685*'03_原始数据'!B23-OtherCost | AE23: ='03_原始数据'!C23-0.69*'03_原始数据'!B23-OtherCost | AF23: ='03_原始数据'!C23-0.695*'03_原始数据'!B23-OtherCost | AG23: ='03_原始数据'!C23-0.7*'03_原始数据'!B23-OtherCost
A24: 0.695 | B24: =AVERAGE($AF$5:$AF$873) | C24: =MEDIAN($AF$5:$AF$873) | D24: =_xlfn.PERCENTILE.INC($AF$5:$AF$873,0.1) | E24: =_xlfn.PERCENTILE.INC($AF$5:$AF$873,0.5) | F24: =_xlfn.PERCENTILE.INC($AF$5:$AF$873,0.9) | G24: =STDEV($AF$5:$AF$873) | H24: =B24-$B$16 | M24: ='03_原始数据'!C24-0.6*'03_原始数据'!B24-OtherCost | N24: ='03_原始数据'!C24-0.605*'03_原始数据'!B24-OtherCost | O24: ='03_原始数据'!C24-0.61*'03_原始数据'!B24-OtherCost | P24: ='03_原始数据'!C24-0.615*'03_原始数据'!B24-OtherCost | Q24: ='03_原始数据'!C24-0.62*'03_原始数据'!B24-OtherCost | R24: ='03_原始数据'!C24-0.625*'03_原始数据'!B24-OtherCost | S24: ='03_原始数据'!C24-0.63*'03_原始数据'!B24-OtherCost | T24: ='03_原始数据'!C24-0.635*'03_原始数据'!B24-OtherCost | U24: ='03_原始数据'!C24-0.64*'03_原始数据'!B24-OtherCost | V24: ='03_原始数据'!C24-0.645*'03_原始数据'!B24-OtherCost | W24: ='03_原始数据'!C24-0.65*'03_原始数据'!B24-OtherCost | X24: ='03_原始数据'!C24-0.655*'03_原始数据'!B24-OtherCost | Y24: ='03_原始数据'!C24-0.66*'03_原始数据'!B24-OtherCost | Z24: ='03_原始数据'!C24-0.665*'03_原始数据'!B24-OtherCost | AA24: ='03_原始数据'!C24-0.67*'03_原始数据'!B24-OtherCost | AB24: ='03_原始数据'!C24-0.675*'03_原始数据'!B24-OtherCost | AC24: ='03_原始数据'!C24-0.68*'03_原始数据'!B24-OtherCost | AD24: ='03_原始数据'!C24-0.685*'03_原始数据'!B24-OtherCost | AE24: ='03_原始数据'!C24-0.69*'03_原始数据'!B24-OtherCost | AF24: ='03_原始数据'!C24-0.695*'03_原始数据'!B24-OtherCost | AG24: ='03_原始数据'!C24-0.7*'03_原始数据'!B24-OtherCost
A25: 0.7 | B25: =AVERAGE($AG$5:$AG$873) | C25: =MEDIAN($AG$5:$AG$873) | D25: =_xlfn.PERCENTILE.INC($AG$5:$AG$873,0.1) | E25: =_xlfn.PERCENTILE.INC($AG$5:$AG$873,0.5) | F25: =_xlfn.PERCENTILE.INC($AG$5:$AG$873,0.9) | G25: =STDEV($AG$5:$AG$873) | H25: =B25-$B$16 | M25: ='03_原始数据'!C25-0.6*'03_原始数据'!B25-OtherCost | N25: ='03_原始数据'!C25-0.605*'03_原始数据'!B25-OtherCost | O25: ='03_原始数据'!C25-0.61*'03_原始数据'!B25-OtherCost | P25: ='03_原始数据'!C25-0.615*'03_原始数据'!B25-OtherCost | Q25: ='03_原始数据'!C25-0.62*'03_原始数据'!B25-OtherCost | R25: ='03_原始数据'!C25-0.625*'03_原始数据'!B25-OtherCost | S25: ='03_原始数据'!C25-0.63*'03_原始数据'!B25-OtherCost | T25: ='03_原始数据'!C25-0.635*'03_原始数据'!B25-OtherCost | U25: ='03_原始数据'!C25-0.64*'03_原始数据'!B25-OtherCost | V25: ='03_原始数据'!C25-0.645*'03_原始数据'!B25-OtherCost | W25: ='03_原始数据'!C25-0.65*'03_原始数据'!B25-OtherCost | X25: ='03_原始数据'!C25-0.655*'03_原始数据'!B25-OtherCost | Y25: ='03_原始数据'!C25-0.66*'03_原始数据'!B25-OtherCost | Z25: ='03_原始数据'!C25-0.665*'03_原始数据'!B25-OtherCost | AA25: ='03_原始数据'!C25-0.67*'03_原始数据'!B25-OtherCost | AB25: ='03_原始数据'!C25-0.675*'03_原始数据'!B25-OtherCost | AC25: ='03_原始数据'!C25-0.68*'03_原始数据'!B25-OtherCost | AD25: ='03_原始数据'!C25-0.685*'03_原始数据'!B25-OtherCost | AE25: ='03_原始数据'!C25-0.69*'03_原始数据'!B25-OtherCost | AF25: ='03_原始数据'!C25-0.695*'03_原始数据'!B25-OtherCost | AG25: ='03_原始数据'!C25-0.7*'03_原始数据'!B25-OtherCost
M26: ='03_原始数据'!C26-0.6*'03_原始数据'!B26-OtherCost | N26: ='03_原始数据'!C26-0.605*'03_原始数据'!B26-OtherCost | O26: ='03_原始数据'!C26-0.61*'03_原始数据'!B26-OtherCost | P26: ='03_原始数据'!C26-0.615*'03_原始数据'!B26-OtherCost | Q26: ='03_原始数据'!C26-0.62*'03_原始数据'!B26-OtherCost | R26: ='03_原始数据'!C26-0.625*'03_原始数据'!B26-OtherCost | S26: ='03_原始数据'!C26-0.63*'03_原始数据'!B26-OtherCost | T26: ='03_原始数据'!C26-0.635*'03_原始数据'!B26-OtherCost | U26: ='03_原始数据'!C26-0.64*'03_原始数据'!B26-OtherCost | V26: ='03_原始数据'!C26-0.645*'03_原始数据'!B26-OtherCost | W26: ='03_原始数据'!C26-0.65*'03_原始数据'!B26-OtherCost | X26: ='03_原始数据'!C26-0.655*'03_原始数据'!B26-OtherCost | Y26: ='03_原始数据'!C26-0.66*'03_原始数据'!B26-OtherCost | Z26: ='03_原始数据'!C26-0.665*'03_原始数据'!B26-OtherCost | AA26: ='03_原始数据'!C26-0.67*'03_原始数据'!B26-OtherCost | AB26: ='03_原始数据'!C26-0.675*'03_原始数据'!B26-OtherCost | AC26: ='03_原始数据'!C26-0.68*'03_原始数据'!B26-OtherCost | AD26: ='03_原始数据'!C26-0.685*'03_原始数据'!B26-OtherCost | AE26: ='03_原始数据'!C26-0.69*'03_原始数据'!B26-OtherCost | AF26: ='03_原始数据'!C26-0.695*'03_原始数据'!B26-OtherCost | AG26: ='03_原始数据'!C26-0.7*'03_原始数据'!B26-OtherCost
M27: ='03_原始数据'!C27-0.6*'03_原始数据'!B27-OtherCost | N27: ='03_原始数据'!C27-0.605*'03_原始数据'!B27-OtherCost | O27: ='03_原始数据'!C27-0.61*'03_原始数据'!B27-OtherCost | P27: ='03_原始数据'!C27-0.615*'03_原始数据'!B27-OtherCost | Q27: ='03_原始数据'!C27-0.62*'03_原始数据'!B27-OtherCost | R27: ='03_原始数据'!C27-0.625*'03_原始数据'!B27-OtherCost | S27: ='03_原始数据'!C27-0.63*'03_原始数据'!B27-OtherCost | T27: ='03_原始数据'!C27-0.635*'03_原始数据'!B27-OtherCost | U27: ='03_原始数据'!C27-0.64*'03_原始数据'!B27-OtherCost | V27: ='03_原始数据'!C27-0.645*'03_原始数据'!B27-OtherCost | W27: ='03_原始数据'!C27-0.65*'03_原始数据'!B27-OtherCost | X27: ='03_原始数据'!C27-0.655*'03_原始数据'!B27-OtherCost | Y27: ='03_原始数据'!C27-0.66*'03_原始数据'!B27-OtherCost | Z27: ='03_原始数据'!C27-0.665*'03_原始数据'!B27-OtherCost | AA27: ='03_原始数据'!C27-0.67*'03_原始数据'!B27-OtherCost | AB27: ='03_原始数据'!C27-0.675*'03_原始数据'!B27-OtherCost | AC27: ='03_原始数据'!C27-0.68*'03_原始数据'!B27-OtherCost | AD27: ='03_原始数据'!C27-0.685*'03_原始数据'!B27-OtherCost | AE27: ='03_原始数据'!C27-0.69*'03_原始数据'!B27-OtherCost | AF27: ='03_原始数据'!C27-0.695*'03_原始数据'!B27-OtherCost | AG27: ='03_原始数据'!C27-0.7*'03_原始数据'!B27-OtherCost
M28: ='03_原始数据'!C28-0.6*'03_原始数据'!B28-OtherCost | N28: ='03_原始数据'!C28-0.605*'03_原始数据'!B28-OtherCost | O28: ='03_原始数据'!C28-0.61*'03_原始数据'!B28-OtherCost | P28: ='03_原始数据'!C28-0.615*'03_原始数据'!B28-OtherCost | Q28: ='03_原始数据'!C28-0.62*'03_原始数据'!B28-OtherCost | R28: ='03_原始数据'!C28-0.625*'03_原始数据'!B28-OtherCost | S28: ='03_原始数据'!C28-0.63*'03_原始数据'!B28-OtherCost | T28: ='03_原始数据'!C28-0.635*'03_原始数据'!B28-OtherCost | U28: ='03_原始数据'!C28-0.64*'03_原始数据'!B28-OtherCost | V28: ='03_原始数据'!C28-0.645*'03_原始数据'!B28-OtherCost | W28: ='03_原始数据'!C28-0.65*'03_原始数据'!B28-OtherCost | X28: ='03_原始数据'!C28-0.655*'03_原始数据'!B28-OtherCost | Y28: ='03_原始数据'!C28-0.66*'03_原始数据'!B28-OtherCost | Z28: ='03_原始数据'!C28-0.665*'03_原始数据'!B28-OtherCost | AA28: ='03_原始数据'!C28-0.67*'03_原始数据'!B28-OtherCost | AB28: ='03_原始数据'!C28-0.675*'03_原始数据'!B28-OtherCost | AC28: ='03_原始数据'!C28-0.68*'03_原始数据'!B28-OtherCost | AD28: ='03_原始数据'!C28-0.685*'03_原始数据'!B28-OtherCost | AE28: ='03_原始数据'!C28-0.69*'03_原始数据'!B28-OtherCost | AF28: ='03_原始数据'!C28-0.695*'03_原始数据'!B28-OtherCost | AG28: ='03_原始数据'!C28-0.7*'03_原始数据'!B28-OtherCost
M29: ='03_原始数据'!C29-0.6*'03_原始数据'!B29-OtherCost | N29: ='03_原始数据'!C29-0.605*'03_原始数据'!B29-OtherCost | O29: ='03_原始数据'!C29-0.61*'03_原始数据'!B29-OtherCost | P29: ='03_原始数据'!C29-0.615*'03_原始数据'!B29-OtherCost | Q29: ='03_原始数据'!C29-0.62*'03_原始数据'!B29-OtherCost | R29: ='03_原始数据'!C29-0.625*'03_原始数据'!B29-OtherCost | S29: ='03_原始数据'!C29-0.63*'03_原始数据'!B29-OtherCost | T29: ='03_原始数据'!C29-0.635*'03_原始数据'!B29-OtherCost | U29: ='03_原始数据'!C29-0.64*'03_原始数据'!B29-OtherCost | V29: ='03_原始数据'!C29-0.645*'03_原始数据'!B29-OtherCost | W29: ='03_原始数据'!C29-0.65*'03_原始数据'!B29-OtherCost | X29: ='03_原始数据'!C29-0.655*'03_原始数据'!B29-OtherCost | Y29: ='03_原始数据'!C29-0.66*'03_原始数据'!B29-OtherCost | Z29: ='03_原始数据'!C29-0.665*'03_原始数据'!B29-OtherCost | AA29: ='03_原始数据'!C29-0.67*'03_原始数据'!B29-OtherCost | AB29: ='03_原始数据'!C29-0.675*'03_原始数据'!B29-OtherCost | AC29: ='03_原始数据'!C29-0.68*'03_原始数据'!B29-OtherCost | AD29: ='03_原始数据'!C29-0.685*'03_原始数据'!B29-OtherCost | AE29: ='03_原始数据'!C29-0.69*'03_原始数据'!B29-OtherCost | AF29: ='03_原始数据'!C29-0.695*'03_原始数据'!B29-OtherCost | AG29: ='03_原始数据'!C29-0.7*'03_原始数据'!B29-OtherCost
M30: ='03_原始数据'!C30-0.6*'03_原始数据'!B30-OtherCost | N30: ='03_原始数据'!C30-0.605*'03_原始数据'!B30-OtherCost | O30: ='03_原始数据'!C30-0.61*'03_原始数据'!B30-OtherCost | P30: ='03_原始数据'!C30-0.615*'03_原始数据'!B30-OtherCost | Q30: ='03_原始数据'!C30-0.62*'03_原始数据'!B30-OtherCost | R30: ='03_原始数据'!C30-0.625*'03_原始数据'!B30-OtherCost | S30: ='03_原始数据'!C30-0.63*'03_原始数据'!B30-OtherCost | T30: ='03_原始数据'!C30-0.635*'03_原始数据'!B30-OtherCost | U30: ='03_原始数据'!C30-0.64*'03_原始数据'!B30-OtherCost | V30: ='03_原始数据'!C30-0.645*'03_原始数据'!B30-OtherCost | W30: ='03_原始数据'!C30-0.65*'03_原始数据'!B30-OtherCost | X30: ='03_原始数据'!C30-0.655*'03_原始数据'!B30-OtherCost | Y30: ='03_原始数据'!C30-0.66*'03_原始数据'!B30-OtherCost | Z30: ='03_原始数据'!C30-0.665*'03_原始数据'!B30-OtherCost | AA30: ='03_原始数据'!C30-0.67*'03_原始数据'!B30-OtherCost | AB30: ='03_原始数据'!C30-0.675*'03_原始数据'!B30-OtherCost | AC30: ='03_原始数据'!C30-0.68*'03_原始数据'!B30-OtherCost | AD30: ='03_原始数据'!C30-0.685*'03_原始数据'!B30-OtherCost | AE30: ='03_原始数据'!C30-0.69*'03_原始数据'!B30-OtherCost | AF30: ='03_原始数据'!C30-0.695*'03_原始数据'!B30-OtherCost | AG30: ='03_原始数据'!C30-0.7*'03_原始数据'!B30-OtherCost
M31: ='03_原始数据'!C31-0.6*'03_原始数据'!B31-OtherCost | N31: ='03_原始数据'!C31-0.605*'03_原始数据'!B31-OtherCost | O31: ='03_原始数据'!C31-0.61*'03_原始数据'!B31-OtherCost | P31: ='03_原始数据'!C31-0.615*'03_原始数据'!B31-OtherCost | Q31: ='03_原始数据'!C31-0.62*'03_原始数据'!B31-OtherCost | R31: ='03_原始数据'!C31-0.625*'03_原始数据'!B31-OtherCost | S31: ='03_原始数据'!C31-0.63*'03_原始数据'!B31-OtherCost | T31: ='03_原始数据'!C31-0.635*'03_原始数据'!B31-OtherCost | U31: ='03_原始数据'!C31-0.64*'03_原始数据'!B31-OtherCost | V31: ='03_原始数据'!C31-0.645*'03_原始数据'!B31-OtherCost | W31: ='03_原始数据'!C31-0.65*'03_原始数据'!B31-OtherCost | X31: ='03_原始数据'!C31-0.655*'03_原始数据'!B31-OtherCost | Y31: ='03_原始数据'!C31-0.66*'03_原始数据'!B31-OtherCost | Z31: ='03_原始数据'!C31-0.665*'03_原始数据'!B31-OtherCost | AA31: ='03_原始数据'!C31-0.67*'03_原始数据'!B31-OtherCost | AB31: ='03_原始数据'!C31-0.675*'03_原始数据'!B31-OtherCost | AC31: ='03_原始数据'!C31-0.68*'03_原始数据'!B31-OtherCost | AD31: ='03_原始数据'!C31-0.685*'03_原始数据'!B31-OtherCost | AE31: ='03_原始数据'!C31-0.69*'03_原始数据'!B31-OtherCost | AF31: ='03_原始数据'!C31-0.695*'03_原始数据'!B31-OtherCost | AG31: ='03_原始数据'!C31-0.7*'03_原始数据'!B31-OtherCost
M32: ='03_原始数据'!C32-0.6*'03_原始数据'!B32-OtherCost | N32: ='03_原始数据'!C32-0.605*'03_原始数据'!B32-OtherCost | O32: ='03_原始数据'!C32-0.61*'03_原始数据'!B32-OtherCost | P32: ='03_原始数据'!C32-0.615*'03_原始数据'!B32-OtherCost | Q32: ='03_原始数据'!C32-0.62*'03_原始数据'!B32-OtherCost | R32: ='03_原始数据'!C32-0.625*'03_原始数据'!B32-OtherCost | S32: ='03_原始数据'!C32-0.63*'03_原始数据'!B32-OtherCost | T32: ='03_原始数据'!C32-0.635*'03_原始数据'!B32-OtherCost | U32: ='03_原始数据'!C32-0.64*'03_原始数据'!B32-OtherCost | V32: ='03_原始数据'!C32-0.645*'03_原始数据'!B32-OtherCost | W32: ='03_原始数据'!C32-0.65*'03_原始数据'!B32-OtherCost | X32: ='03_原始数据'!C32-0.655*'03_原始数据'!B32-OtherCost | Y32: ='03_原始数据'!C32-0.66*'03_原始数据'!B32-OtherCost | Z32: ='03_原始数据'!C32-0.665*'03_原始数据'!B32-OtherCost | AA32: ='03_原始数据'!C32-0.67*'03_原始数据'!B32-OtherCost | AB32: ='03_原始数据'!C32-0.675*'03_原始数据'!B32-OtherCost | AC32: ='03_原始数据'!C32-0.68*'03_原始数据'!B32-OtherCost | AD32: ='03_原始数据'!C32-0.685*'03_原始数据'!B32-OtherCost | AE32: ='03_原始数据'!C32-0.69*'03_原始数据'!B32-OtherCost | AF32: ='03_原始数据'!C32-0.695*'03_原始数据'!B32-OtherCost | AG32: ='03_原始数据'!C32-0.7*'03_原始数据'!B32-OtherCost
M33: ='03_原始数据'!C33-0.6*'03_原始数据'!B33-OtherCost | N33: ='03_原始数据'!C33-0.605*'03_原始数据'!B33-OtherCost | O33: ='03_原始数据'!C33-0.61*'03_原始数据'!B33-OtherCost | P33: ='03_原始数据'!C33-0.615*'03_原始数据'!B33-OtherCost | Q33: ='03_原始数据'!C33-0.62*'03_原始数据'!B33-OtherCost | R33: ='03_原始数据'!C33-0.625*'03_原始数据'!B33-OtherCost | S33: ='03_原始数据'!C33-0.63*'03_原始数据'!B33-OtherCost | T33: ='03_原始数据'!C33-0.635*'03_原始数据'!B33-OtherCost | U33: ='03_原始数据'!C33-0.64*'03_原始数据'!B33-OtherCost | V33: ='03_原始数据'!C33-0.645*'03_原始数据'!B33-OtherCost | W33: ='03_原始数据'!C33-0.65*'03_原始数据'!B33-OtherCost | X33: ='03_原始数据'!C33-0.655*'03_原始数据'!B33-OtherCost | Y33: ='03_原始数据'!C33-0.66*'03_原始数据'!B33-OtherCost | Z33: ='03_原始数据'!C33-0.665*'03_原始数据'!B33-OtherCost | AA33: ='03_原始数据'!C33-0.67*'03_原始数据'!B33-OtherCost | AB33: ='03_原始数据'!C33-0.675*'03_原始数据'!B33-OtherCost | AC33: ='03_原始数据'!C33-0.68*'03_原始数据'!B33-OtherCost | AD33: ='03_原始数据'!C33-0.685*'03_原始数据'!B33-OtherCost | AE33: ='03_原始数据'!C33-0.69*'03_原始数据'!B33-OtherCost | AF33: ='03_原始数据'!C33-0.695*'03_原始数据'!B33-OtherCost | AG33: ='03_原始数据'!C33-0.7*'03_原始数据'!B33-OtherCost
M34: ='03_原始数据'!C34-0.6*'03_原始数据'!B34-OtherCost | N34: ='03_原始数据'!C34-0.605*'03_原始数据'!B34-OtherCost | O34: ='03_原始数据'!C34-0.61*'03_原始数据'!B34-OtherCost | P34: ='03_原始数据'!C34-0.615*'03_原始数据'!B34-OtherCost | Q34: ='03_原始数据'!C34-0.62*'03_原始数据'!B34-OtherCost | R34: ='03_原始数据'!C34-0.625*'03_原始数据'!B34-OtherCost | S34: ='03_原始数据'!C34-0.63*'03_原始数据'!B34-OtherCost | T34: ='03_原始数据'!C34-0.635*'03_原始数据'!B34-OtherCost | U34: ='03_原始数据'!C34-0.64*'03_原始数据'!B34-OtherCost | V34: ='03_原始数据'!C34-0.645*'03_原始数据'!B34-OtherCost | W34: ='03_原始数据'!C34-0.65*'03_原始数据'!B34-OtherCost | X34: ='03_原始数据'!C34-0.655*'03_原始数据'!B34-OtherCost | Y34: ='03_原始数据'!C34-0.66*'03_原始数据'!B34-OtherCost | Z34: ='03_原始数据'!C34-0.665*'03_原始数据'!B34-OtherCost | AA34: ='03_原始数据'!C34-0.67*'03_原始数据'!B34-OtherCost | AB34: ='03_原始数据'!C34-0.675*'03_原始数据'!B34-OtherCost | AC34: ='03_原始数据'!C34-0.68*'03_原始数据'!B34-OtherCost | AD34: ='03_原始数据'!C34-0.685*'03_原始数据'!B34-OtherCost | AE34: ='03_原始数据'!C34-0.69*'03_原始数据'!B34-OtherCost | AF34: ='03_原始数据'!C34-0.695*'03_原始数据'!B34-OtherCost | AG34: ='03_原始数据'!C34-0.7*'03_原始数据'!B34-OtherCost
M35: ='03_原始数据'!C35-0.6*'03_原始数据'!B35-OtherCost | N35: ='03_原始数据'!C35-0.605*'03_原始数据'!B35-OtherCost | O35: ='03_原始数据'!C35-0.61*'03_原始数据'!B35-OtherCost | P35: ='03_原始数据'!C35-0.615*'03_原始数据'!B35-OtherCost | Q35: ='03_原始数据'!C35-0.62*'03_原始数据'!B35-OtherCost | R35: ='03_原始数据'!C35-0.625*'03_原始数据'!B35-OtherCost | S35: ='03_原始数据'!C35-0.63*'03_原始数据'!B35-OtherCost | T35: ='03_原始数据'!C35-0.635*'03_原始数据'!B35-OtherCost | U35: ='03_原始数据'!C35-0.64*'03_原始数据'!B35-OtherCost | V35: ='03_原始数据'!C35-0.645*'03_原始数据'!B35-OtherCost | W35: ='03_原始数据'!C35-0.65*'03_原始数据'!B35-OtherCost | X35: ='03_原始数据'!C35-0.655*'03_原始数据'!B35-OtherCost | Y35: ='03_原始数据'!C35-0.66*'03_原始数据'!B35-OtherCost | Z35: ='03_原始数据'!C35-0.665*'03_原始数据'!B35-OtherCost | AA35: ='03_原始数据'!C35-0.67*'03_原始数据'!B35-OtherCost | AB35: ='03_原始数据'!C35-0.675*'03_原始数据'!B35-OtherCost | AC35: ='03_原始数据'!C35-0.68*'03_原始数据'!B35-OtherCost | AD35: ='03_原始数据'!C35-0.685*'03_原始数据'!B35-OtherCost | AE35: ='03_原始数据'!C35-0.69*'03_原始数据'!B35-OtherCost | AF35: ='03_原始数据'!C35-0.695*'03_原始数据'!B35-OtherCost | AG35: ='03_原始数据'!C35-0.7*'03_原始数据'!B35-OtherCost
M36: ='03_原始数据'!C36-0.6*'03_原始数据'!B36-OtherCost | N36: ='03_原始数据'!C36-0.605*'03_原始数据'!B36-OtherCost | O36: ='03_原始数据'!C36-0.61*'03_原始数据'!B36-OtherCost | P36: ='03_原始数据'!C36-0.615*'03_原始数据'!B36-OtherCost | Q36: ='03_原始数据'!C36-0.62*'03_原始数据'!B36-OtherCost | R36: ='03_原始数据'!C36-0.625*'03_原始数据'!B36-OtherCost | S36: ='03_原始数据'!C36-0.63*'03_原始数据'!B36-OtherCost | T36: ='03_原始数据'!C36-0.635*'03_原始数据'!B36-OtherCost | U36: ='03_原始数据'!C36-0.64*'03_原始数据'!B36-OtherCost | V36: ='03_原始数据'!C36-0.645*'03_原始数据'!B36-OtherCost | W36: ='03_原始数据'!C36-0.65*'03_原始数据'!B36-OtherCost | X36: ='03_原始数据'!C36-0.655*'03_原始数据'!B36-OtherCost | Y36: ='03_原始数据'!C36-0.66*'03_原始数据'!B36-OtherCost | Z36: ='03_原始数据'!C36-0.665*'03_原始数据'!B36-OtherCost | AA36: ='03_原始数据'!C36-0.67*'03_原始数据'!B36-OtherCost | AB36: ='03_原始数据'!C36-0.675*'03_原始数据'!B36-OtherCost | AC36: ='03_原始数据'!C36-0.68*'03_原始数据'!B36-OtherCost | AD36: ='03_原始数据'!C36-0.685*'03_原始数据'!B36-OtherCost | AE36: ='03_原始数据'!C36-0.69*'03_原始数据'!B36-OtherCost | AF36: ='03_原始数据'!C36-0.695*'03_原始数据'!B36-OtherCost | AG36: ='03_原始数据'!C36-0.7*'03_原始数据'!B36-OtherCost
M37: ='03_原始数据'!C37-0.6*'03_原始数据'!B37-OtherCost | N37: ='03_原始数据'!C37-0.605*'03_原始数据'!B37-OtherCost | O37: ='03_原始数据'!C37-0.61*'03_原始数据'!B37-OtherCost | P37: ='03_原始数据'!C37-0.615*'03_原始数据'!B37-OtherCost | Q37: ='03_原始数据'!C37-0.62*'03_原始数据'!B37-OtherCost | R37: ='03_原始数据'!C37-0.625*'03_原始数据'!B37-OtherCost | S37: ='03_原始数据'!C37-0.63*'03_原始数据'!B37-OtherCost | T37: ='03_原始数据'!C37-0.635*'03_原始数据'!B37-OtherCost | U37: ='03_原始数据'!C37-0.64*'03_原始数据'!B37-OtherCost | V37: ='03_原始数据'!C37-0.645*'03_原始数据'!B37-OtherCost | W37: ='03_原始数据'!C37-0.65*'03_原始数据'!B37-OtherCost | X37: ='03_原始数据'!C37-0.655*'03_原始数据'!B37-OtherCost | Y37: ='03_原始数据'!C37-0.66*'03_原始数据'!B37-OtherCost | Z37: ='03_原始数据'!C37-0.665*'03_原始数据'!B37-OtherCost | AA37: ='03_原始数据'!C37-0.67*'03_原始数据'!B37-OtherCost | AB37: ='03_原始数据'!C37-0.675*'03_原始数据'!B37-OtherCost | AC37: ='03_原始数据'!C37-0.68*'03_原始数据'!B37-OtherCost | AD37: ='03_原始数据'!C37-0.685*'03_原始数据'!B37-OtherCost | AE37: ='03_原始数据'!C37-0.69*'03_原始数据'!B37-OtherCost | AF37: ='03_原始数据'!C37-0.695*'03_原始数据'!B37-OtherCost | AG37: ='03_原始数据'!C37-0.7*'03_原始数据'!B37-OtherCost
... M873: ='03_原始数据'!C873-0.6*'03_原始数据'!B873-OtherCost | N873: ='03_原始数据'!C873-0.605*'03_原始数据'!B873-OtherCost | O873: ='03_原始数据'!C873-0.61*'03_原始数据'!B873-OtherCost | P873: ='03_原始数据'!C873-0.615*'03_原始数据'!B873-OtherCost | Q873: ='03_原始数据'!C873-0.62*'03_原始数据'!B873-OtherCost | R873: ='03_原始数据'!C873-0.625*'03_原始数据'!B873-OtherCost | S873: ='03_原始数据'!C873-0.63*'03_原始数据'!B873-OtherCost | T873: ='03_原始数据'!C873-0.635*'03_原始数据'!B873-OtherCost | U873: ='03_原始数据'!C873-0.64*'03_原始数据'!B873-OtherCost | V873: ='03_原始数据'!C873-0.645*'03_原始数据'!B873-OtherCost | W873: ='03_原始数据'!C873-0.65*'03_原始数据'!B873-OtherCost | X873: ='03_原始数据'!C873-0.655*'03_原始数据'!B873-OtherCost | Y873: ='03_原始数据'!C873-0.66*'03_原始数据'!B873-OtherCost | Z873: ='03_原始数据'!C873-0.665*'03_原始数据'!B873-OtherCost | AA873: ='03_原始数据'!C873-0.67*'03_原始数据'!B873-OtherCost | AB873: ='03_原始数据'!C873-0.675*'03_原始数据'!B873-OtherCost | AC873: ='03_原始数据'!C873-0.68*'03_原始数据'!B873-OtherCost | AD873: ='03_原始数据'!C873-0.685*'03_原始数据'!B873-OtherCost | AE873: ='03_原始数据'!C873-0.69*'03_原始数据'!B873-OtherCost | AF873: ='03_原始数据'!C873-0.695*'03_原始数据'!B873-OtherCost | AG873: ='03_原始数据'!C873-0.7*'03_原始数据'!B873-OtherCost

Sheet 06_加工价差
A1: 理论加工价差与分位
A2: 价差 = PTA − λ×PX − 其他成本。分位用 PERCENTRANK.INC（与报告一致）。
A4: 日期 | B4: PX | C4: PTA | D4: 加工价差 | E4: 历史分位（全样本） | F4: 滚动60日均值 | G4: 滚动60日标准差
A5: ='03_原始数据'!A5 | B5: ='03_原始数据'!B5 | C5: ='03_原始数据'!C5 | D5: ='03_原始数据'!E5 | E5: =_xlfn.PERCENTRANK.INC('03_原始数据'!$E$5:$E$873,'03_原始数据'!E5) | F5: =IF(False,AVERAGE('03_原始数据'!$E$5:$E$5),"") | G5: =IF(False,STDEV('03_原始数据'!$E$5:$E$5),"")
A6: ='03_原始数据'!A6 | B6: ='03_原始数据'!B6 | C6: ='03_原始数据'!C6 | D6: ='03_原始数据'!E6 | E6: =_xlfn.PERCENTRANK.INC('03_原始数据'!$E$5:$E$873,'03_原始数据'!E6) | F6: =IF(False,AVERAGE('03_原始数据'!$E$5:$E$6),"") | G6: =IF(False,STDEV('03_原始数据'!$E$5:$E$6),"")
A7: ='03_原始数据'!A7 | B7: ='03_原始数据'!B7 | C7: ='03_原始数据'!C7 | D7: ='03_原始数据'!E7 | E7: =_xlfn.PERCENTRANK.INC('03_原始数据'!$E$5:$E$873,'03_原始数据'!E7) | F7: =IF(False,AVERAGE('03_原始数据'!$E$5:$E$7),"") | G7: =IF(False,STDEV('03_原始数据'!$E$5:$E$7),"")
A8: ='03_原始数据'!A8 | B8: ='03_原始数据'!B8 | C8: ='03_原始数据'!C8 | D8: ='03_原始数据'!E8 | E8: =_xlfn.PERCENTRANK.INC('03_原始数据'!$E$5:$E$873,'03_原始数据'!E8) | F8: =IF(False,AVERAGE('03_原始数据'!$E$5:$E$8),"") | G8: =IF(False,STDEV('03_原始数据'!$E$5:$E$8),"")
A9: ='03_原始数据'!A9 | B9: ='03_原始数据'!B9 | C9: ='03_原始数据'!C9 | D9: ='03_原始数据'!E9 | E9: =_xlfn.PERCENTRANK.INC('03_原始数据'!$E$5:$E$873,'03_原始数据'!E9) | F9: =IF(False,AVERAGE('03_原始数据'!$E$5:$E$9),"") | G9: =IF(False,STDEV('03_原始数据'!$E$5:$E$9),"")
A10: ='03_原始数据'!A10 | B10: ='03_原始数据'!B10 | C10: ='03_原始数据'!C10 | D10: ='03_原始数据'!E10 | E10: =_xlfn.PERCENTRANK.INC('03_原始数据'!$E$5:$E$873,'03_原始数据'!E10) | F10: =IF(False,AVERAGE('03_原始数据'!$E$5:$E$10),"") | G10: =IF(False,STDEV('03_原始数据'!$E$5:$E$10),"")
A11: ='03_原始数据'!A11 | B11: ='03_原始数据'!B11 | C11: ='03_原始数据'!C11 | D11: ='03_原始数据'!E11 | E11: =_xlfn.PERCENTRANK.INC('03_原始数据'!$E$5:$E$873,'03_原始数据'!E11) | F11: =IF(False,AVERAGE('03_原始数据'!$E$5:$E$11),"") | G11: =IF(False,STDEV('03_原始数据'!$E$5:$E$11),"")
A12: ='03_原始数据'!A12 | B12: ='03_原始数据'!B12 | C12: ='03_原始数据'!C12 | D12: ='03_原始数据'!E12 | E12: =_xlfn.PERCENTRANK.INC('03_原始数据'!$E$5:$E$873,'03_原始数据'!E12) | F12: =IF(False,AVERAGE('03_原始数据'!$E$5:$E$12),"") | G12: =IF(False,STDEV('03_原始数据'!$E$5:$E$12),"")
A13: ='03_原始数据'!A13 | B13: ='03_原始数据'!B13 | C13: ='03_原始数据'!C13 | D13: ='03_原始数据'!E13 | E13: =_xlfn.PERCENTRANK.INC('03_原始数据'!$E$5:$E$873,'03_原始数据'!E13) | F13: =IF(False,AVERAGE('03_原始数据'!$E$5:$E$13),"") | G13: =IF(False,STDEV('03_原始数据'!$E$5:$E$13),"")
A14: ='03_原始数据'!A14 | B14: ='03_原始数据'!B14 | C14: ='03_原始数据'!C14 | D14: ='03_原始数据'!E14 | E14: =_xlfn.PERCENTRANK.INC('03_原始数据'!$E$5:$E$873,'03_原始数据'!E14) | F14: =IF(False,AVERAGE('03_原始数据'!$E$5:$E$14),"") | G14: =IF(False,STDEV('03_原始数据'!$E$5:$E$14),"")
A15: ='03_原始数据'!A15 | B15: ='03_原始数据'!B15 | C15: ='03_原始数据'!C15 | D15: ='03_原始数据'!E15 | E15: =_xlfn.PERCENTRANK.INC('03_原始数据'!$E$5:$E$873,'03_原始数据'!E15) | F15: =IF(False,AVERAGE('03_原始数据'!$E$5:$E$15),"") | G15: =IF(False,STDEV('03_原始数据'!$E$5:$E$15),"")
A16: ='03_原始数据'!A16 | B16: ='03_原始数据'!B16 | C16: ='03_原始数据'!C16 | D16: ='03_原始数据'!E16 | E16: =_xlfn.PERCENTRANK.INC('03_原始数据'!$E$5:$E$873,'03_原始数据'!E16) | F16: =IF(False,AVERAGE('03_原始数据'!$E$5:$E$16),"") | G16: =IF(False,STDEV('03_原始数据'!$E$5:$E$16),"")
A17: ='03_原始数据'!A17 | B17: ='03_原始数据'!B17 | C17: ='03_原始数据'!C17 | D17: ='03_原始数据'!E17 | E17: =_xlfn.PERCENTRANK.INC('03_原始数据'!$E$5:$E$873,'03_原始数据'!E17) | F17: =IF(False,AVERAGE('03_原始数据'!$E$5:$E$17),"") | G17: =IF(False,STDEV('03_原始数据'!$E$5:$E$17),"")
A18: ='03_原始数据'!A18 | B18: ='03_原始数据'!B18 | C18: ='03_原始数据'!C18 | D18: ='03_原始数据'!E18 | E18: =_xlfn.PERCENTRANK.INC('03_原始数据'!$E$5:$E$873,'03_原始数据'!E18) | F18: =IF(False,AVERAGE('03_原始数据'!$E$5:$E$18),"") | G18: =IF(False,STDEV('03_原始数据'!$E$5:$E$18),"")
A19: ='03_原始数据'!A19 | B19: ='03_原始数据'!B19 | C19: ='03_原始数据'!C19 | D19: ='03_原始数据'!E19 | E19: =_xlfn.PERCENTRANK.INC('03_原始数据'!$E$5:$E$873,'03_原始数据'!E19) | F19: =IF(False,AVERAGE('03_原始数据'!$E$5:$E$19),"") | G19: =IF(False,STDEV('03_原始数据'!$E$5:$E$19),"")
A20: ='03_原始数据'!A20 | B20: ='03_原始数据'!B20 | C20: ='03_原始数据'!C20 | D20: ='03_原始数据'!E20 | E20: =_xlfn.PERCENTRANK.INC('03_原始数据'!$E$5:$E$873,'03_原始数据'!E20) | F20: =IF(False,AVERAGE('03_原始数据'!$E$5:$E$20),"") | G20: =IF(False,STDEV('03_原始数据'!$E$5:$E$20),"")
A21: ='03_原始数据'!A21 | B21: ='03_原始数据'!B21 | C21: ='03_原始数据'!C21 | D21: ='03_原始数据'!E21 | E21: =_xlfn.PERCENTRANK.INC('03_原始数据'!$E$5:$E$873,'03_原始数据'!E21) | F21: =IF(False,AVERAGE('03_原始数据'!$E$5:$E$21),"") | G21: =IF(False,STDEV('03_原始数据'!$E$5:$E$21),"")
A22: ='03_原始数据'!A22 | B22: ='03_原始数据'!B22 | C22: ='03_原始数据'!C22 | D22: ='03_原始数据'!E22 | E22: =_xlfn.PERCENTRANK.INC('03_原始数据'!$E$5:$E$873,'03_原始数据'!E22) | F22: =IF(False,AVERAGE('03_原始数据'!$E$5:$E$22),"") | G22: =IF(False,STDEV('03_原始数据'!$E$5:$E$22),"")
A23: ='03_原始数据'!A23 | B23: ='03_原始数据'!B23 | C23: ='03_原始数据'!C23 | D23: ='03_原始数据'!E23 | E23: =_xlfn.PERCENTRANK.INC('03_原始数据'!$E$5:$E$873,'03_原始数据'!E23) | F23: =IF(False,AVERAGE('03_原始数据'!$E$5:$E$23),"") | G23: =IF(False,STDEV('03_原始数据'!$E$5:$E$23),"")
A24: ='03_原始数据'!A24 | B24: ='03_原始数据'!B24 | C24: ='03_原始数据'!C24 | D24: ='03_原始数据'!E24 | E24: =_xlfn.PERCENTRANK.INC('03_原始数据'!$E$5:$E$873,'03_原始数据'!E24) | F24: =IF(False,AVERAGE('03_原始数据'!$E$5:$E$24),"") | G24: =IF(False,STDEV('03_原始数据'!$E$5:$E$24),"")
A25: ='03_原始数据'!A25 | B25: ='03_原始数据'!B25 | C25: ='03_原始数据'!C25 | D25: ='03_原始数据'!E25 | E25: =_xlfn.PERCENTRANK.INC('03_原始数据'!$E$5:$E$873,'03_原始数据'!E25) | F25: =IF(False,AVERAGE('03_原始数据'!$E$5:$E$25),"") | G25: =IF(False,STDEV('03_原始数据'!$E$5:$E$25),"")
A26: ='03_原始数据'!A26 | B26: ='03_原始数据'!B26 | C26: ='03_原始数据'!C26 | D26: ='03_原始数据'!E26 | E26: =_xlfn.PERCENTRANK.INC('03_原始数据'!$E$5:$E$873,'03_原始数据'!E26) | F26: =IF(False,AVERAGE('03_原始数据'!$E$5:$E$26),"") | G26: =IF(False,STDEV('03_原始数据'!$E$5:$E$26),"")
A27: ='03_原始数据'!A27 | B27: ='03_原始数据'!B27 | C27: ='03_原始数据'!C27 | D27: ='03_原始数据'!E27 | E27: =_xlfn.PERCENTRANK.INC('03_原始数据'!$E$5:$E$873,'03_原始数据'!E27) | F27: =IF(False,AVERAGE('03_原始数据'!$E$5:$E$27),"") | G27: =IF(False,STDEV('03_原始数据'!$E$5:$E$27),"")
A28: ='03_原始数据'!A28 | B28: ='03_原始数据'!B28 | C28: ='03_原始数据'!C28 | D28: ='03_原始数据'!E28 | E28: =_xlfn.PERCENTRANK.INC('03_原始数据'!$E$5:$E$873,'03_原始数据'!E28) | F28: =IF(False,AVERAGE('03_原始数据'!$E$5:$E$28),"") | G28: =IF(False,STDEV('03_原始数据'!$E$5:$E$28),"")
A29: ='03_原始数据'!A29 | B29: ='03_原始数据'!B29 | C29: ='03_原始数据'!C29 | D29: ='03_原始数据'!E29 | E29: =_xlfn.PERCENTRANK.INC('03_原始数据'!$E$5:$E$873,'03_原始数据'!E29) | F29: =IF(False,AVERAGE('03_原始数据'!$E$5:$E$29),"") | G29: =IF(False,STDEV('03_原始数据'!$E$5:$E$29),"")
A30: ='03_原始数据'!A30 | B30: ='03_原始数据'!B30 | C30: ='03_原始数据'!C30 | D30: ='03_原始数据'!E30 | E30: =_xlfn.PERCENTRANK.INC('03_原始数据'!$E$5:$E$873,'03_原始数据'!E30) | F30: =IF(False,AVERAGE('03_原始数据'!$E$5:$E$30),"") | G30: =IF(False,STDEV('03_原始数据'!$E$5:$E$30),"")
A31: ='03_原始数据'!A31 | B31: ='03_原始数据'!B31 | C31: ='03_原始数据'!C31 | D31: ='03_原始数据'!E31 | E31: =_xlfn.PERCENTRANK.INC('03_原始数据'!$E$5:$E$873,'03_原始数据'!E31) | F31: =IF(False,AVERAGE('03_原始数据'!$E$5:$E$31),"") | G31: =IF(False,STDEV('03_原始数据'!$E$5:$E$31),"")
A32: ='03_原始数据'!A32 | B32: ='03_原始数据'!B32 | C32: ='03_原始数据'!C32 | D32: ='03_原始数据'!E32 | E32: =_xlfn.PERCENTRANK.INC('03_原始数据'!$E$5:$E$873,'03_原始数据'!E32) | F32: =IF(False,AVERAGE('03_原始数据'!$E$5:$E$32),"") | G32: =IF(False,STDEV('03_原始数据'!$E$5:$E$32),"")
A33: ='03_原始数据'!A33 | B33: ='03_原始数据'!B33 | C33: ='03_原始数据'!C33 | D33: ='03_原始数据'!E33 | E33: =_xlfn.PERCENTRANK.INC('03_原始数据'!$E$5:$E$873,'03_原始数据'!E33) | F33: =IF(False,AVERAGE('03_原始数据'!$E$5:$E$33),"") | G33: =IF(False,STDEV('03_原始数据'!$E$5:$E$33),"")
A34: ='03_原始数据'!A34 | B34: ='03_原始数据'!B34 | C34: ='03_原始数据'!C34 | D34: ='03_原始数据'!E34 | E34: =_xlfn.PERCENTRANK.INC('03_原始数据'!$E$5:$E$873,'03_原始数据'!E34) | F34: =IF(False,AVERAGE('03_原始数据'!$E$5:$E$34),"") | G34: =IF(False,STDEV('03_原始数据'!$E$5:$E$34),"")
A35: ='03_原始数据'!A35 | B35: ='03_原始数据'!B35 | C35: ='03_原始数据'!C35 | D35: ='03_原始数据'!E35 | E35: =_xlfn.PERCENTRANK.INC('03_原始数据'!$E$5:$E$873,'03_原始数据'!E35) | F35: =IF(False,AVERAGE('03_原始数据'!$E$5:$E$35),"") | G35: =IF(False,STDEV('03_原始数据'!$E$5:$E$35),"")
A36: ='03_原始数据'!A36 | B36: ='03_原始数据'!B36 | C36: ='03_原始数据'!C36 | D36: ='03_原始数据'!E36 | E36: =_xlfn.PERCENTRANK.INC('03_原始数据'!$E$5:$E$873,'03_原始数据'!E36) | F36: =IF(False,AVERAGE('03_原始数据'!$E$5:$E$36),"") | G36: =IF(False,STDEV('03_原始数据'!$E$5:$E$36),"")
A37: ='03_原始数据'!A37 | B37: ='03_原始数据'!B37 | C37: ='03_原始数据'!C37 | D37: ='03_原始数据'!E37 | E37: =_xlfn.PERCENTRANK.INC('03_原始数据'!$E$5:$E$873,'03_原始数据'!E37) | F37: =IF(False,AVERAGE('03_原始数据'!$E$5:$E$37),"") | G37: =IF(False,STDEV('03_原始数据'!$E$5:$E$37),"")
A38: ='03_原始数据'!A38 | B38: ='03_原始数据'!B38 | C38: ='03_原始数据'!C38 | D38: ='03_原始数据'!E38 | E38: =_xlfn.PERCENTRANK.INC('03_原始数据'!$E$5:$E$873,'03_原始数据'!E38) | F38: =IF(False,AVERAGE('03_原始数据'!$E$5:$E$38),"") | G38: =IF(False,STDEV('03_原始数据'!$E$5:$E$38),"")
A39: ='03_原始数据'!A39 | B39: ='03_原始数据'!B39 | C39: ='03_原始数据'!C39 | D39: ='03_原始数据'!E39 | E39: =_xlfn.PERCENTRANK.INC('03_原始数据'!$E$5:$E$873,'03_原始数据'!E39) | F39: =IF(False,AVERAGE('03_原始数据'!$E$5:$E$39),"") | G39: =IF(False,STDEV('03_原始数据'!$E$5:$E$39),"")
A40: ='03_原始数据'!A40 | B40: ='03_原始数据'!B40 | C40: ='03_原始数据'!C40 | D40: ='03_原始数据'!E40 | E40: =_xlfn.PERCENTRANK.INC('03_原始数据'!$E$5:$E$873,'03_原始数据'!E40) | F40: =IF(False,AVERAGE('03_原始数据'!$E$5:$E$40),"") | G40: =IF(False,STDEV('03_原始数据'!$E$5:$E$40),"")
A41: ='03_原始数据'!A41 | B41: ='03_原始数据'!B41 | C41: ='03_原始数据'!C41 | D41: ='03_原始数据'!E41 | E41: =_xlfn.PERCENTRANK.INC('03_原始数据'!$E$5:$E$873,'03_原始数据'!E41) | F41: =IF(False,AVERAGE('03_原始数据'!$E$5:$E$41),"") | G41: =IF(False,STDEV('03_原始数据'!$E$5:$E$41),"")
...

Sheet 07_历史分位
A1: 历史分位表
A2: 同一张表同时给出「价差处于什么位置」和「对应多少钱」，便于业务直接引用。
A4: 分位 | B4: 加工价差 元/吨 | C4: 含义 | D4: 分位 | E4: 加工价差 元/吨 | F4: 含义
A5: 0% | B5: =_xlfn.PERCENTILE.INC('03_原始数据'!$E$5:$E$873,0) | C5: 历史最低 | D5: 50% | E5: =_xlfn.PERCENTILE.INC('03_原始数据'!$E$5:$E$873,0.5) | F5: 中位
A6: 1% | B6: =_xlfn.PERCENTILE.INC('03_原始数据'!$E$5:$E$873,0.01) | C6: 极低 | D6: 75% | E6: =_xlfn.PERCENTILE.INC('03_原始数据'!$E$5:$E$873,0.75) | F6: 上四分位
A7: 5% | B7: =_xlfn.PERCENTILE.INC('03_原始数据'!$E$5:$E$873,0.05) | C7: 极低（历史 5% 以下） | D7: 90% | E7: =_xlfn.PERCENTILE.INC('03_原始数据'!$E$5:$E$873,0.9) | F7: 偏高
A8: 10% | B8: =_xlfn.PERCENTILE.INC('03_原始数据'!$E$5:$E$873,0.1) | C8: 偏低 | D8: 95% | E8: =_xlfn.PERCENTILE.INC('03_原始数据'!$E$5:$E$873,0.95) | F8: 极高
A9: 25% | B9: =_xlfn.PERCENTILE.INC('03_原始数据'!$E$5:$E$873,0.25) | C9: 下四分位 | D9: 100% | E9: =_xlfn.PERCENTILE.INC('03_原始数据'!$E$5:$E$873,1) | F9: 历史最高
A11: 定位
A12: 指标 | B12: 数值 | C12: 公式说明
A13: 最新价差 | B13: ='03_原始数据'!E873 | C13: 直接引用最后一行
A14: 最新分位 | B14: =_xlfn.PERCENTRANK.INC('03_原始数据'!$E$5:$E$873,'03_原始数据'!E873) | C14: PERCENTRANK.INC：与 Python 的 pct_rank 定义一致
A15: 均值 | B15: =AVERAGE('03_原始数据'!E5:E873) | C15: 全样本算术均值
