Workbook

Sheet 00 封面与结论
A1: 纯碱（华东 · 重质）· 现货价格历史位置分析
A2: 本工作簿与同名 HTML 报告同源同数；所有统计量均为<b>可复核的 Excel 公式</b>，改动「02 原始序列」里任一价格，04/05/06/07/08 表会随公式自动重算。
A5: 最新可靠报价（元/吨） | B5: 1215 | C5: 数据日期 | D5: 2026-07-28 | E5: 3 年经验分位 | F5: 0.28
A7: 1 年经验分位 | B7: 0.72 | C7: 3 年最高 | D7: 2100 | E7: 3 年最低 | F7: 1215
A10: 一句话结论：华东重质纯碱当前 1215 元/吨，落在 2024-07-17 以来真实观测的 0.28% 分位——即历史上 99.72% 的报价日比今天更贵。但请注意：该口径的公开日度记录起点是 2024-07-17，「3 年」与「5 年」窗口的样本完全相同，这不是五年数据齐全。
A12: 表 | B12: 内容 | C12: 关键说明
A13: 01 口径与基准日 | B13: 六项口径：规格/地区/含税/交付/单位/来源 | C13: 价格能不能用，先看这张表
A14: 02 原始序列(主) | B14: 华东重质纯碱逐日 lo/hi/mid + 原文链接 | C14: 358 条真实观测，每条可点开核对
A15: 03 原始序列(辅助) | B15: 华东轻质 + 全国基准价 | C15: 辅助口径，不作替换
A16: 04 历史分位(公式) | B16: PERCENTRANK / COUNTIF 双口径分位 | C16: 公式可改、可复核
A17: 05 统计指标(公式) | B17: max/min/均值/中位数/标准差/IQR/年化波动 | C17: 全部为 Excel 公式
A18: 06 分窗口统计(公式) | B18: 5 个窗口 × 12 项指标 | C18: 样本不足的窗口明确写「不计算」
A19: 07 同期对比(公式) | B19: 逐年同月均价 + 同比 + 季节性指数 | C19: 只呈现有真实观测的格子
A20: 08 季节性(公式) | B20: 月 × 年矩阵 | C20: 空格＝无观测，非 0
A21: 09 异常点 | B21: 三条独立判据（水平/跳变/IQR） | C21: 分别标注，不合并
A22: 10 事件时间线 | B22: 可核验事件 + 来源链接 | C22: 只写已发生事实
A23: 11 数据缺口 | B23: 连续缺失段 + 单日缺失 | C23: 不插值、不模拟
... A25: 13 来源清单 | B25: 文号/链接 | C25: 复核用

Sheet 01 口径与基准日
A1: 01 口径与基准日
A2: 缺任何一项，这个价格都不能拿去报价。
A4: 要素 | B4: 取值 | C4: 为什么重要 | D4: 来源/备注
A5: 品种 | B5: 纯碱 | C5: 只说「纯碱」不能报价，纯度是前提 | D5: 生意社商品库
A6: 规格 | B6: 重质纯碱（≥99.2%，GB/T 210-2022 优等品口径） | C6: 重质与轻质价差常见 100–300 元/吨，混用即失真 | D6: 生意社 华东日评原文
A7: 地区 | B7: 华东 | C7: 华东与华北/华中价差显著，且基准价是全国口径 | D7: 生意社 华东日评
A8: 含税 | B8: 含税（增值税13%） | C8: 含税与不含税差约 13%，必锝标明 | D8: 生意社报价说明
A9: 交付方式 | B9: 主流市场报价 / 实单商谈（非严格出厂或送到） | C9: 出厂价 ≠ 送到价，运费与风险归属不同 | D9: 原文「实单以商谈为主」
A10: 单位 | B10: 元/吨 | C10: 与期货盘面 20 吨/手、元/吨保持同单位才可对比 | D10: —
A11: 数据日期 | B11: 2026-07-28 | C11: 现货逐日报价，日期不同不可比 | D11: —
A12: 来源 | B12: 生意社（100ppi.com）华东地区纯碱市场日评 + 生意社基准价 | C12: 每条价格都要能回溯到原文 | D12: https://www.100ppi.com/news/list--12-1.html
A13: 最小样本门槛 | B13: 20 条有效观测 | C13: 低于此不做分位，避免拿 3 个点编出分位数 | D13: 本方法设定
A14: 分位口径 | B14: 经验分位（含并列 / 中位秩），另列区间位置 | C14: 三者含义不同，不可混用 | D14: 见「12 方法与公式」
A16: ⚠ 区域口径提醒：生意社「重质纯碱基准价」是全国样本，不是华东价。本报告把它作为辅助序列 S3 单列，用于判断「华东这个价是全国同步还是华东独有」，绝不用它替代华东区域报价。

Sheet 02 原始序列(主)
A1: 02 原始序列 · 华东重质纯碱（主口径 S1）
A2: 每行一条真实观测。D/E/F 列是原始报价区间与中值；H 列可点开当日原文。改动 F 列任一数值，其余各表的公式会联动重算。
A4: 序号 | B4: 日期 | C4: 区间低端(元/吨) | D4: 区间高端(元/吨) | E4: 区间中值(元/吨) | F4: 区间宽度 | G4: 口径 | H4: 原文链接
A5: 1 | B5: 45490 | C5: 2000 | D5: 2200 | E5: =(C5+D5)/2 | F5: =D5-C5 | G5: 主流市场报价 | H5: 打开原文
A6: 2 | B6: 45491 | C6: 2000 | D6: 2200 | E6: =(C6+D6)/2 | F6: =D6-C6 | G6: 主流市场报价 | H6: 打开原文
A7: 3 | B7: 45492 | C7: 2000 | D7: 2200 | E7: =(C7+D7)/2 | F7: =D7-C7 | G7: 主流市场报价 | H7: 打开原文
A8: 4 | B8: 45495 | C8: 2000 | D8: 2200 | E8: =(C8+D8)/2 | F8: =D8-C8 | G8: 主流市场报价 | H8: 打开原文
A9: 5 | B9: 45496 | C9: 2000 | D9: 2200 | E9: =(C9+D9)/2 | F9: =D9-C9 | G9: 主流市场报价 | H9: 打开原文
A10: 6 | B10: 45497 | C10: 2000 | D10: 2200 | E10: =(C10+D10)/2 | F10: =D10-C10 | G10: 主流市场报价 | H10: 打开原文
A11: 7 | B11: 45498 | C11: 2000 | D11: 2200 | E11: =(C11+D11)/2 | F11: =D11-C11 | G11: 主流市场报价 | H11: 打开原文
A12: 8 | B12: 45499 | C12: 2000 | D12: 2200 | E12: =(C12+D12)/2 | F12: =D12-C12 | G12: 主流市场报价 | H12: 打开原文
A13: 9 | B13: 45502 | C13: 1950 | D13: 2100 | E13: =(C13+D13)/2 | F13: =D13-C13 | G13: 主流市场报价 | H13: 打开原文
A14: 10 | B14: 45503 | C14: 1950 | D14: 2100 | E14: =(C14+D14)/2 | F14: =D14-C14 | G14: 主流市场报价 | H14: 打开原文
A15: 11 | B15: 45504 | C15: 1900 | D15: 2100 | E15: =(C15+D15)/2 | F15: =D15-C15 | G15: 主流市场报价 | H15: 打开原文
A16: 12 | B16: 45505 | C16: 1900 | D16: 2100 | E16: =(C16+D16)/2 | F16: =D16-C16 | G16: 主流市场报价 | H16: 打开原文
... A362: 358 | B362: 46231 | C362: 1180 | D362: 1250 | E362: =(C362+D362)/2 | F362: =D362-C362 | G362: 主流市场报价（实单商谈） | H362: 打开原文
A364: 共 358 条观测，2024-07-17 至 2026-07-28。E/F 列为公式（=(C+D)/2、=D-C），不做四舍五入存储，显示层保留两位。

Sheet 03 原始序列(辅助)
A1: 03 原始序列 · 辅助口径（S2 华东轻质 / S3 全国基准）
A2: 两条辅助序列各自独立，不与主序列拼接、不互换。
A5: S2 华东·轻质纯碱·主流市场区间中值
A6: 序号 | B6: 日期 | C6: 区间低端 | D6: 区间高端 | E6: 中值 | F6: 宽度 | G6: 口径 | H6: 原文链接
A7: 1 | B7: 44970 | C7: 2700 | D7: 2900 | E7: =(C7+D7)/2 | F7: =D7-C7 | G7: 主流市场报价 | H7: 打开原文
A8: 2 | B8: 44974 | C8: 2700 | D8: 2900 | E8: =(C8+D8)/2 | F8: =D8-C8 | G8: 主流市场报价 | H8: 打开原文
A9: 3 | B9: 44978 | C9: 2700 | D9: 2900 | E9: =(C9+D9)/2 | F9: =D9-C9 | G9: 主流市场报价 | H9: 打开原文
A10: 4 | B10: 44979 | C10: 2700 | D10: 2900 | E10: =(C10+D10)/2 | F10: =D10-C10 | G10: 主流市场报价 | H10: 打开原文
A11: 5 | B11: 44981 | C11: 2700 | D11: 2900 | E11: =(C11+D11)/2 | F11: =D11-C11 | G11: 主流市场报价 | H11: 打开原文
A12: 6 | B12: 44985 | C12: 2700 | D12: 2900 | E12: =(C12+D12)/2 | F12: =D12-C12 | G12: 主流市场报价 | H12: 打开原文
A13: 7 | B13: 44991 | C13: 2700 | D13: 2900 | E13: =(C13+D13)/2 | F13: =D13-C13 | G13: 主流市场报价 | H13: 打开原文
A14: 8 | B14: 45013 | C14: 2650 | D14: 2850 | E14: =(C14+D14)/2 | F14: =D14-C14 | G14: 主流市场报价 | H14: 打开原文
A15: 9 | B15: 45014 | C15: 2650 | D15: 2850 | E15: =(C15+D15)/2 | F15: =D15-C15 | G15: 主流市场报价 | H15: 打开原文
A16: 10 | B16: 45015 | C16: 2650 | D16: 2850 | E16: =(C16+D16)/2 | F16: =D16-C16 | G16: 主流市场报价 | H16: 打开原文
A17: 11 | B17: 45029 | C17: 2600 | D17: 2800 | E17: =(C17+D17)/2 | F17: =D17-C17 | G17: 主流市场报价 | H17: 打开原文
A18: 12 | B18: 45030 | C18: 2600 | D18: 2800 | E18: =(C18+D18)/2 | F18: =D18-C18 | G18: 主流市场报价 | H18: 打开原文
... A534: 528 | B534: 46231 | C534: 980 | D534: 1560 | E534: =(C534+D534)/2 | F534: =D534-C534 | G534: 主流市场报价（实单商谈） | H534: 打开原文
A535: S2 华东 共 528 条观测（2023-02-13 至 2026-07-28）。
A537: S3 全国·重质纯碱·生意社基准价（单点）
A538: 序号 | B538: 日期 | C538: 基准价 | G538: 口径 | H538: 原文链接
A539: 1 | B539: 45239 | C539: 2360 | G539: 全国基准价 | H539: 打开原文
A540: 2 | B540: 45240 | C540: 2340 | G540: 全国基准价 | H540: 打开原文
A541: 3 | B541: 45243 | C541: 2340 | G541: 全国基准价 | H541: 打开原文
A542: 4 | B542: 45244 | C542: 2340 | G542: 全国基准价 | H542: 打开原文
A543: 5 | B543: 45245 | C543: 2360 | G543: 全国基准价 | H543: 打开原文
A544: 6 | B544: 45246 | C544: 2370 | G544: 全国基准价 | H544: 打开原文
A545: 7 | B545: 45247 | C545: 2370 | G545: 全国基准价 | H545: 打开原文
A546: 8 | B546: 45250 | C546: 2370 | G546: 全国基准价 | H546: 打开原文
A547: 9 | B547: 45251 | C547: 2410 | G547: 全国基准价 | H547: 打开原文
A548: 10 | B548: 45252 | C548: 2450 | G548: 全国基准价 | H548: 打开原文
A549: 11 | B549: 45253 | C549: 2490 | G549: 全国基准价 | H549: 打开原文
A550: 12 | B550: 45254 | C550: 2490 | G550: 全国基准价 | H550: 打开原文
... A1308: 770 | B1308: 46315 | C1308: 1062.86 | G1308: 全国基准价 | H1308: 打开原文
A1309: S3 全国 共 770 条观测（2023-11-09 至 2026-10-20）。

Sheet 04 历史分位(公式)
A1: 04 历史分位 · 经验分位（Excel 公式实算）
A2: ★ 分位不是「当前价在最高最低之间的位置」，而是「历史上多少比例的观测日 ≤ 当前价」。下表每一条都是 COUNTIF 计数公式，可自行展开核对。
A4: 窗口 | B4: 窗口起 | C4: 窗口止 | D4: 样本 n | E4: 最低 | F4: 最高 | G4: 中位数 | H4: 经验分位(含并列) | I4: 经验分位(中位秩) | J4: 区间位置(非分位)
A5: 近 30 天 | B5: =C5-30 | C5: =DATE(2026,7,28) | D5: =COUNTIFS('02 原始序列(主)'!$B$5:$B$362,">"&$B5,'02 原始序列(主)'!$B$5:$B$362,"<="&$C5) | E5: =IF($D5<1,"",MIN(N9:N366)) | F5: =IF($D5<1,"",MAX(N9:N366)) | G5: =IF($D5<1,"",MEDIAN(N9:N366)) | H5: =IF($D5<20,"样本不足，不计算",(COUNTIFS('02 原始序列(主)'!$E$5:$E$362,"<="&'02 原始序列(主)'!$E$362,'02 原始序列(主)'!$B$5:$B$362,">"&$B5,'02 原始序列(主)'!$B$5:$B$362,"<="&$C5))/D5) | I5: =IF($D5<20,"样本不足，不计算",(COUNTIFS('02 原始序列(主)'!$E$5:$E$362,"<"&'02 原始序列(主)'!$E$362,'02 原始序列(主)'!$B$5:$B$362,">"&$B5,'02 原始序列(主)'!$B$5:$B$362,"<="&$C5)+0.5*COUNTIFS('02 原始序列(主)'!$E$5:$E$362,"="&'02 原始序列(主)'!$E$362,'02 原始序列(主)'!$B$5:$B$362,">"&$B5,'02 原始序列(主)'!$B$5:$B$362,"<="&$C5))/D5) | J5: =IF($D5<2,"",('02 原始序列(主)'!$E$362-E5)/(F5-E5))
A6: 近 3 个月 | B6: =C6-90 | C6: =DATE(2026,7,28) | D6: =COUNTIFS('02 原始序列(主)'!$B$5:$B$362,">"&$B6,'02 原始序列(主)'!$B$5:$B$362,"<="&$C6) | E6: =IF($D6<1,"",MIN(O9:O366)) | F6: =IF($D6<1,"",MAX(O9:O366)) | G6: =IF($D6<1,"",MEDIAN(O9:O366)) | H6: =IF($D6<20,"样本不足，不计算",(COUNTIFS('02 原始序列(主)'!$E$5:$E$362,"<="&'02 原始序列(主)'!$E$362,'02 原始序列(主)'!$B$5:$B$362,">"&$B6,'02 原始序列(主)'!$B$5:$B$362,"<="&$C6))/D6) | I6: =IF($D6<20,"样本不足，不计算",(COUNTIFS('02 原始序列(主)'!$E$5:$E$362,"<"&'02 原始序列(主)'!$E$362,'02 原始序列(主)'!$B$5:$B$362,">"&$B6,'02 原始序列(主)'!$B$5:$B$362,"<="&$C6)+0.5*COUNTIFS('02 原始序列(主)'!$E$5:$E$362,"="&'02 原始序列(主)'!$E$362,'02 原始序列(主)'!$B$5:$B$362,">"&$B6,'02 原始序列(主)'!$B$5:$B$362,"<="&$C6))/D6) | J6: =IF($D6<2,"",('02 原始序列(主)'!$E$362-E6)/(F6-E6))
A7: 近 1 年 | B7: =C7-365 | C7: =DATE(2026,7,28) | D7: =COUNTIFS('02 原始序列(主)'!$B$5:$B$362,">"&$B7,'02 原始序列(主)'!$B$5:$B$362,"<="&$C7) | E7: =IF($D7<1,"",MIN(P9:P366)) | F7: =IF($D7<1,"",MAX(P9:P366)) | G7: =IF($D7<1,"",MEDIAN(P9:P366)) | H7: =IF($D7<20,"样本不足，不计算",(COUNTIFS('02 原始序列(主)'!$E$5:$E$362,"<="&'02 原始序列(主)'!$E$362,'02 原始序列(主)'!$B$5:$B$362,">"&$B7,'02 原始序列(主)'!$B$5:$B$362,"<="&$C7))/D7) | I7: =IF($D7<20,"样本不足，不计算",(COUNTIFS('02 原始序列(主)'!$E$5:$E$362,"<"&'02 原始序列(主)'!$E$362,'02 原始序列(主)'!$B$5:$B$362,">"&$B7,'02 原始序列(主)'!$B$5:$B$362,"<="&$C7)+0.5*COUNTIFS('02 原始序列(主)'!$E$5:$E$362,"="&'02 原始序列(主)'!$E$362,'02 原始序列(主)'!$B$5:$B$362,">"&$B7,'02 原始序列(主)'!$B$5:$B$362,"<="&$C7))/D7) | J7: =IF($D7<2,"",('02 原始序列(主)'!$E$362-E7)/(F7-E7)) | L7: 辅助矩阵 · 各窗口内的真实现测取值（空白＝该日不在该窗口内，不参与计算）
A8: 近 3 年 | B8: =C8-1095 | C8: =DATE(2026,7,28) | D8: =COUNTIFS('02 原始序列(主)'!$B$5:$B$362,">"&$B8,'02 原始序列(主)'!$B$5:$B$362,"<="&$C8) | E8: =IF($D8<1,"",MIN(Q9:Q366)) | F8: =IF($D8<1,"",MAX(Q9:Q366)) | G8: =IF($D8<1,"",MEDIAN(Q9:Q366)) | H8: =IF($D8<20,"样本不足，不计算",(COUNTIFS('02 原始序列(主)'!$E$5:$E$362,"<="&'02 原始序列(主)'!$E$362,'02 原始序列(主)'!$B$5:$B$362,">"&$B8,'02 原始序列(主)'!$B$5:$B$362,"<="&$C8))/D8) | I8: =IF($D8<20,"样本不足，不计算",(COUNTIFS('02 原始序列(主)'!$E$5:$E$362,"<"&'02 原始序列(主)'!$E$362,'02 原始序列(主)'!$B$5:$B$362,">"&$B8,'02 原始序列(主)'!$B$5:$B$362,"<="&$C8)+0.5*COUNTIFS('02 原始序列(主)'!$E$5:$E$362,"="&'02 原始序列(主)'!$E$362,'02 原始序列(主)'!$B$5:$B$362,">"&$B8,'02 原始序列(主)'!$B$5:$B$362,"<="&$C8))/D8) | J8: =IF($D8<2,"",('02 原始序列(主)'!$E$362-E8)/(F8-E8)) | L8: 日期 | M8: 主序列价格 | N8: 近 30 天 | O8: 近 3 个月 | P8: 近 1 年 | Q8: 近 3 年 | R8: 近 5 年
A9: 近 5 年 | B9: =C9-1826 | C9: =DATE(2026,7,28) | D9: =COUNTIFS('02 原始序列(主)'!$B$5:$B$362,">"&$B9,'02 原始序列(主)'!$B$5:$B$362,"<="&$C9) | E9: =IF($D9<1,"",MIN(R9:R366)) | F9: =IF($D9<1,"",MAX(R9:R366)) | G9: =IF($D9<1,"",MEDIAN(R9:R366)) | H9: =IF($D9<20,"样本不足，不计算",(COUNTIFS('02 原始序列(主)'!$E$5:$E$362,"<="&'02 原始序列(主)'!$E$362,'02 原始序列(主)'!$B$5:$B$362,">"&$B9,'02 原始序列(主)'!$B$5:$B$362,"<="&$C9))/D9) | I9: =IF($D9<20,"样本不足，不计算",(COUNTIFS('02 原始序列(主)'!$E$5:$E$362,"<"&'02 原始序列(主)'!$E$362,'02 原始序列(主)'!$B$5:$B$362,">"&$B9,'02 原始序列(主)'!$B$5:$B$362,"<="&$C9)+0.5*COUNTIFS('02 原始序列(主)'!$E$5:$E$362,"="&'02 原始序列(主)'!$E$362,'02 原始序列(主)'!$B$5:$B$362,">"&$B9,'02 原始序列(主)'!$B$5:$B$362,"<="&$C9))/D9) | J9: =IF($D9<2,"",('02 原始序列(主)'!$E$362-E9)/(F9-E9)) | L9: 45490 | M9: 2100 | N9: =IF(($L9>$B$5)*($L9<=$C$5),$M9,"") | O9: =IF(($L9>$B$6)*($L9<=$C$6),$M9,"") | P9: =IF(($L9>$B$7)*($L9<=$C$7),$M9,"") | Q9: =IF(($L9>$B$8)*($L9<=$C$8),$M9,"") | R9: =IF(($L9>$B$9)*($L9<=$C$9),$M9,"")
L10: 45491 | M10: 2100 | N10: =IF(($L10>$B$5)*($L10<=$C$5),$M10,"") | O10: =IF(($L10>$B$6)*($L10<=$C$6),$M10,"") | P10: =IF(($L10>$B$7)*($L10<=$C$7),$M10,"") | Q10: =IF(($L10>$B$8)*($L10<=$C$8),$M10,"") | R10: =IF(($L10>$B$9)*($L10<=$C$9),$M10,"")
A11: 公式说明：D 列 =COUNT(条件区间) 得窗口内真实观测数；H 列 =(COUNTIF(≤当前价 且 在窗口内)) / n —— 这就是经验分位；I 列 把与当前价相等的观测按 0.5 计入（中位秩），用于抵消现货锯齿状并列值；J 列 =(当前价−最低)/(最高−最低)，<b>只是区间位置，不是分位</b>。 | L11: 45492 | M11: 2100 | N11: =IF(($L11>$B$5)*($L11<=$C$5),$M11,"") | O11: =IF(($L11>$B$6)*($L11<=$C$6),$M11,"") | P11: =IF(($L11>$B$7)*($L11<=$C$7),$M11,"") | Q11: =IF(($L11>$B$8)*($L11<=$C$8),$M11,"") | R11: =IF(($L11>$B$9)*($L11<=$C$9),$M11,"")
L12: 45495 | M12: 2100 | N12: =IF(($L12>$B$5)*($L12<=$C$5),$M12,"") | O12: =IF(($L12>$B$6)*($L12<=$C$6),$M12,"") | P12: =IF(($L12>$B$7)*($L12<=$C$7),$M12,"") | Q12: =IF(($L12>$B$8)*($L12<=$C$8),$M12,"") | R12: =IF(($L12>$B$9)*($L12<=$C$9),$M12,"")
A13: 为什么必须区分这三个数：现货逐日报价大量取相同值，当当前价恰为窗口最低点时，含并列分位可能 0.7%、中位秩 0.4%、区间位置 0.0%——三个都对，含义完全不同。对外只说「经验分位」，并把算法写清楚。 | L13: 45496 | M13: 2100 | N13: =IF(($L13>$B$5)*($L13<=$C$5),$M13,"") | O13: =IF(($L13>$B$6)*($L13<=$C$6),$M13,"") | P13: =IF(($L13>$B$7)*($L13<=$C$7),$M13,"") | Q13: =IF(($L13>$B$8)*($L13<=$C$8),$M13,"") | R13: =IF(($L13>$B$9)*($L13<=$C$9),$M13,"")
L14: 45497 | M14: 2100 | N14: =IF(($L14>$B$5)*($L14<=$C$5),$M14,"") | O14: =IF(($L14>$B$6)*($L14<=$C$6),$M14,"") | P14: =IF(($L14>$B$7)*($L14<=$C$7),$M14,"") | Q14: =IF(($L14>$B$8)*($L14<=$C$8),$M14,"") | R14: =IF(($L14>$B$9)*($L14<=$C$9),$M14,"")
L15: 45498 | M15: 2100 | N15: =IF(($L15>$B$5)*($L15<=$C$5),$M15,"") | O15: =IF(($L15>$B$6)*($L15<=$C$6),$M15,"") | P15: =IF(($L15>$B$7)*($L15<=$C$7),$M15,"") | Q15: =IF(($L15>$B$8)*($L15<=$C$8),$M15,"") | R15: =IF(($L15>$B$9)*($L15<=$C$9),$M15,"")
L16: 45499 | M16: 2100 | N16: =IF(($L16>$B$5)*($L16<=$C$5),$M16,"") | O16: =IF(($L16>$B$6)*($L16<=$C$6),$M16,"") | P16: =IF(($L16>$B$7)*($L16<=$C$7),$M16,"") | Q16: =IF(($L16>$B$8)*($L16<=$C$8),$M16,"") | R16: =IF(($L16>$B$9)*($L16<=$C$9),$M16,"")
L17: 45502 | M17: 2025 | N17: =IF(($L17>$B$5)*($L17<=$C$5),$M17,"") | O17: =IF(($L17>$B$6)*($L17<=$C$6),$M17,"") | P17: =IF(($L17>$B$7)*($L17<=$C$7),$M17,"") | Q17: =IF(($L17>$B$8)*($L17<=$C$8),$M17,"") | R17: =IF(($L17>$B$9)*($L17<=$C$9),$M17,"")
L18: 45503 | M18: 2025 | N18: =IF(($L18>$B$5)*($L18<=$C$5),$M18,"") | O18: =IF(($L18>$B$6)*($L18<=$C$6),$M18,"") | P18: =IF(($L18>$B$7)*($L18<=$C$7),$M18,"") | Q18: =IF(($L18>$B$8)*($L18<=$C$8),$M18,"") | R18: =IF(($L18>$B$9)*($L18<=$C$9),$M18,"")
L19: 45504 | M19: 2000 | N19: =IF(($L19>$B$5)*($L19<=$C$5),$M19,"") | O19: =IF(($L19>$B$6)*($L19<=$C$6),$M19,"") | P19: =IF(($L19>$B$7)*($L19<=$C$7),$M19,"") | Q19: =IF(($L19>$B$8)*($L19<=$C$8),$M19,"") | R19: =IF(($L19>$B$9)*($L19<=$C$9),$M19,"")
L20: 45505 | M20: 2000 | N20: =IF(($L20>$B$5)*($L20<=$C$5),$M20,"") | O20: =IF(($L20>$B$6)*($L20<=$C$6),$M20,"") | P20: =IF(($L20>$B$7)*($L20<=$C$7),$M20,"") | Q20: =IF(($L20>$B$8)*($L20<=$C$8),$M20,"") | R20: =IF(($L20>$B$9)*($L20<=$C$9),$M20,"")
L21: 45506 | M21: 2000 | N21: =IF(($L21>$B$5)*($L21<=$C$5),$M21,"") | O21: =IF(($L21>$B$6)*($L21<=$C$6),$M21,"") | P21: =IF(($L21>$B$7)*($L21<=$C$7),$M21,"") | Q21: =IF(($L21>$B$8)*($L21<=$C$8),$M21,"") | R21: =IF(($L21>$B$9)*($L21<=$C$9),$M21,"")
L22: 45509 | M22: 2000 | N22: =IF(($L22>$B$5)*($L22<=$C$5),$M22,"") | O22: =IF(($L22>$B$6)*($L22<=$C$6),$M22,"") | P22: =IF(($L22>$B$7)*($L22<=$C$7),$M22,"") | Q22: =IF(($L22>$B$8)*($L22<=$C$8),$M22,"") | R22: =IF(($L22>$B$9)*($L22<=$C$9),$M22,"")
L23: 45510 | M23: 2000 | N23: =IF(($L23>$B$5)*($L23<=$C$5),$M23,"") | O23: =IF(($L23>$B$6)*($L23<=$C$6),$M23,"") | P23: =IF(($L23>$B$7)*($L23<=$C$7),$M23,"") | Q23: =IF(($L23>$B$8)*($L23<=$C$8),$M23,"") | R23: =IF(($L23>$B$9)*($L23<=$C$9),$M23,"")
L24: 45511 | M24: 2000 | N24: =IF(($L24>$B$5)*($L24<=$C$5),$M24,"") | O24: =IF(($L24>$B$6)*($L24<=$C$6),$M24,"") | P24: =IF(($L24>$B$7)*($L24<=$C$7),$M24,"") | Q24: =IF(($L24>$B$8)*($L24<=$C$8),$M24,"") | R24: =IF(($L24>$B$9)*($L24<=$C$9),$M24,"")
L25: 45512 | M25: 2000 | N25: =IF(($L25>$B$5)*($L25<=$C$5),$M25,"") | O25: =IF(($L25>$B$6)*($L25<=$C$6),$M25,"") | P25: =IF(($L25>$B$7)*($L25<=$C$7),$M25,"") | Q25: =IF(($L25>$B$8)*($L25<=$C$8),$M25,"") | R25: =IF(($L25>$B$9)*($L25<=$C$9),$M25,"")
... L366: 46231 | M366: 1215 | N366: =IF(($L366>$B$5)*($L366<=$C$5),$M366,"") | O366: =IF(($L366>$B$6)*($L366<=$C$6),$M366,"") | P366: =IF(($L366>$B$7)*($L366<=$C$7),$M366,"") | Q366: =IF(($L366>$B$8)*($L366<=$C$8),$M366,"") | R366: =IF(($L366>$B$9)*($L366<=$C$9),$M366,"")

Sheet 05 统计指标(公式)
A1: 05 统计指标 · 全样本与分窗口（Excel 公式实算）
A2: MAX/MIN/AVERAGE/MEDIAN/STDEV.S/QUARTILE.STDEV 全部为公式；年化波动率按真实自然日间隔折算（现货报价不等距，不能用 sqrt(252)）。
A4: 指标 | B4: 全样本 | C4: 近30天 | D4: 近3个月 | E4: 近1年 | F4: 近3年 | G4: 近5年
A5: 样本数 n | B5: =COUNT('02 原始序列(主)'!$E$5:$E$362) | C5: =COUNT(N33:N390) | D5: =COUNT(O33:O390) | E5: =COUNT(P33:P390) | F5: =COUNT(Q33:Q390) | G5: =COUNT(R33:R390)
A6: 最低 | B6: =IF(COUNT('02 原始序列(主)'!$E$5:$E$362)<1,"",MIN('02 原始序列(主)'!$E$5:$E$362)) | C6: =IF(COUNT(N33:N390)<1,"",MIN(N33:N390)) | D6: =IF(COUNT(O33:O390)<1,"",MIN(O33:O390)) | E6: =IF(COUNT(P33:P390)<1,"",MIN(P33:P390)) | F6: =IF(COUNT(Q33:Q390)<1,"",MIN(Q33:Q390)) | G6: =IF(COUNT(R33:R390)<1,"",MIN(R33:R390))
A7: 最高 | B7: =IF(COUNT('02 原始序列(主)'!$E$5:$E$362)<1,"",MAX('02 原始序列(主)'!$E$5:$E$362)) | C7: =IF(COUNT(N33:N390)<1,"",MAX(N33:N390)) | D7: =IF(COUNT(O33:O390)<1,"",MAX(O33:O390)) | E7: =IF(COUNT(P33:P390)<1,"",MAX(P33:P390)) | F7: =IF(COUNT(Q33:Q390)<1,"",MAX(Q33:Q390)) | G7: =IF(COUNT(R33:R390)<1,"",MAX(R33:R390))
A8: 均值 | B8: =IF(COUNT('02 原始序列(主)'!$E$5:$E$362)<1,"",AVERAGE('02 原始序列(主)'!$E$5:$E$362)) | C8: =IF(COUNT(N33:N390)<1,"",AVERAGE(N33:N390)) | D8: =IF(COUNT(O33:O390)<1,"",AVERAGE(O33:O390)) | E8: =IF(COUNT(P33:P390)<1,"",AVERAGE(P33:P390)) | F8: =IF(COUNT(Q33:Q390)<1,"",AVERAGE(Q33:Q390)) | G8: =IF(COUNT(R33:R390)<1,"",AVERAGE(R33:R390))
A9: 中位数 | B9: =IF(COUNT('02 原始序列(主)'!$E$5:$E$362)<1,"",MEDIAN('02 原始序列(主)'!$E$5:$E$362)) | C9: =IF(COUNT(N33:N390)<1,"",MEDIAN(N33:N390)) | D9: =IF(COUNT(O33:O390)<1,"",MEDIAN(O33:O390)) | E9: =IF(COUNT(P33:P390)<1,"",MEDIAN(P33:P390)) | F9: =IF(COUNT(Q33:Q390)<1,"",MEDIAN(Q33:Q390)) | G9: =IF(COUNT(R33:R390)<1,"",MEDIAN(R33:R390))
A10: 标准差(样本) | B10: =IF(COUNT('02 原始序列(主)'!$E$5:$E$362)<2,"",STDEV('02 原始序列(主)'!$E$5:$E$362)) | C10: =IF(COUNT(N33:N390)<2,"",STDEV(N33:N390)) | D10: =IF(COUNT(O33:O390)<2,"",STDEV(O33:O390)) | E10: =IF(COUNT(P33:P390)<2,"",STDEV(P33:P390)) | F10: =IF(COUNT(Q33:Q390)<2,"",STDEV(Q33:Q390)) | G10: =IF(COUNT(R33:R390)<2,"",STDEV(R33:R390))
A11: 变异系数 CV | B11: =IF(COUNT('02 原始序列(主)'!$E$5:$E$362)<2,"",STDEV('02 原始序列(主)'!$E$5:$E$362)/AVERAGE('02 原始序列(主)'!$E$5:$E$362)) | C11: =IF(COUNT(N33:N390)<2,"",STDEV(N33:N390)/AVERAGE(N33:N390)) | D11: =IF(COUNT(O33:O390)<2,"",STDEV(O33:O390)/AVERAGE(O33:O390)) | E11: =IF(COUNT(P33:P390)<2,"",STDEV(P33:P390)/AVERAGE(P33:P390)) | F11: =IF(COUNT(Q33:Q390)<2,"",STDEV(Q33:Q390)/AVERAGE(Q33:Q390)) | G11: =IF(COUNT(R33:R390)<2,"",STDEV(R33:R390)/AVERAGE(R33:R390))
A12: 当前价相对中位 | B12: =IF(COUNT('02 原始序列(主)'!$E$5:$E$362)<1,"",('02 原始序列(主)'!$E$362)/MEDIAN('02 原始序列(主)'!$E$5:$E$362)-1) | C12: =IF(COUNT(N33:N390)<1,"",('02 原始序列(主)'!$E$362)/MEDIAN(N33:N390)-1) | D12: =IF(COUNT(O33:O390)<1,"",('02 原始序列(主)'!$E$362)/MEDIAN(O33:O390)-1) | E12: =IF(COUNT(P33:P390)<1,"",('02 原始序列(主)'!$E$362)/MEDIAN(P33:P390)-1) | F12: =IF(COUNT(Q33:Q390)<1,"",('02 原始序列(主)'!$E$362)/MEDIAN(Q33:Q390)-1) | G12: =IF(COUNT(R33:R390)<1,"",('02 原始序列(主)'!$E$362)/MEDIAN(R33:R390)-1)
A14: 波动率与回撤不写进公式列，因为现货报价不等距，「每自然日对数收益的标准差 × √365」必须在脚本里按真实日差计算；结果见下表（与 HTML 报告同源）。
A16: 波动指标 | B16: 窗口 | C16: 年化波动率 | D16: 日均绝对变动 | E16: 最大单日变动 | F16: ≥1% 天数占比
A17: 年化波动率 | B17: 近 30 天 | C17: 2.78 | D17: 0.504 | E17: 2.02 | F17: 25
A18: 年化波动率 | B18: 近 3 个月 | C18: 1.51 | D18: 0.201 | E18: 2.02 | F18: 7.14
A19: 年化波动率 | B19: 近 1 年 | C19: 6.69 | D19: 0.106 | E19: 3.77 | F19: 5.07
A20: 最大回撤 | B20: 全样本 | C20: -42.14 | D20: 2024-07-17 | E20: 2026-07-28
A22: 年化波动率算法：对相邻两条真实报价计算 ln(P_t/P_{t-1}) / 相隔自然日数，取其样本标准差 × √365。未做前值填充，未假设每日都有报价。
L31: 辅助矩阵 · 各窗口内的真实现测（空白＝该日不在该窗口内，不参与计算）
L32: 日期 | M32: 主序列价格 | N32: 近 30 天 | O32: 近 3 个月 | P32: 近 1 年 | Q32: 近 3 年 | R32: 近 5 年
L33: 45490 | M33: 2100 | N33: =IF((L33>$B$4)*(L33<=$C$4),$M33,"") | O33: =IF((L33>$B$5)*(L33<=$C$5),$M33,"") | P33: =IF((L33>$B$6)*(L33<=$C$6),$M33,"") | Q33: =IF((L33>$B$7)*(L33<=$C$7),$M33,"") | R33: =IF((L33>$B$8)*(L33<=$C$8),$M33,"")
L34: 45491 | M34: 2100 | N34: =IF((L34>$B$4)*(L34<=$C$4),$M34,"") | O34: =IF((L34>$B$5)*(L34<=$C$5),$M34,"") | P34: =IF((L34>$B$6)*(L34<=$C$6),$M34,"") | Q34: =IF((L34>$B$7)*(L34<=$C$7),$M34,"") | R34: =IF((L34>$B$8)*(L34<=$C$8),$M34,"")
L35: 45492 | M35: 2100 | N35: =IF((L35>$B$4)*(L35<=$C$4),$M35,"") | O35: =IF((L35>$B$5)*(L35<=$C$5),$M35,"") | P35: =IF((L35>$B$6)*(L35<=$C$6),$M35,"") | Q35: =IF((L35>$B$7)*(L35<=$C$7),$M35,"") | R35: =IF((L35>$B$8)*(L35<=$C$8),$M35,"")
L36: 45495 | M36: 2100 | N36: =IF((L36>$B$4)*(L36<=$C$4),$M36,"") | O36: =IF((L36>$B$5)*(L36<=$C$5),$M36,"") | P36: =IF((L36>$B$6)*(L36<=$C$6),$M36,"") | Q36: =IF((L36>$B$7)*(L36<=$C$7),$M36,"") | R36: =IF((L36>$B$8)*(L36<=$C$8),$M36,"")
L37: 45496 | M37: 2100 | N37: =IF((L37>$B$4)*(L37<=$C$4),$M37,"") | O37: =IF((L37>$B$5)*(L37<=$C$5),$M37,"") | P37: =IF((L37>$B$6)*(L37<=$C$6),$M37,"") | Q37: =IF((L37>$B$7)*(L37<=$C$7),$M37,"") | R37: =IF((L37>$B$8)*(L37<=$C$8),$M37,"")
L38: 45497 | M38: 2100 | N38: =IF((L38>$B$4)*(L38<=$C$4),$M38,"") | O38: =IF((L38>$B$5)*(L38<=$C$5),$M38,"") | P38: =IF((L38>$B$6)*(L38<=$C$6),$M38,"") | Q38: =IF((L38>$B$7)*(L38<=$C$7),$M38,"") | R38: =IF((L38>$B$8)*(L38<=$C$8),$M38,"")
L39: 45498 | M39: 2100 | N39: =IF((L39>$B$4)*(L39<=$C$4),$M39,"") | O39: =IF((L39>$B$5)*(L39<=$C$5),$M39,"") | P39: =IF((L39>$B$6)*(L39<=$C$6),$M39,"") | Q39: =IF((L39>$B$7)*(L39<=$C$7),$M39,"") | R39: =IF((L39>$B$8)*(L39<=$C$8),$M39,"")
L40: 45499 | M40: 2100 | N40: =IF((L40>$B$4)*(L40<=$C$4),$M40,"") | O40: =IF((L40>$B$5)*(L40<=$C$5),$M40,"") | P40: =IF((L40>$B$6)*(L40<=$C$6),$M40,"") | Q40: =IF((L40>$B$7)*(L40<=$C$7),$M40,"") | R40: =IF((L40>$B$8)*(L40<=$C$8),$M40,"")
L41: 45502 | M41: 2025 | N41: =IF((L41>$B$4)*(L41<=$C$4),$M41,"") | O41: =IF((L41>$B$5)*(L41<=$C$5),$M41,"") | P41: =IF((L41>$B$6)*(L41<=$C$6),$M41,"") | Q41: =IF((L41>$B$7)*(L41<=$C$7),$M41,"") | R41: =IF((L41>$B$8)*(L41<=$C$8),$M41,"")
L42: 45503 | M42: 2025 | N42: =IF((L42>$B$4)*(L42<=$C$4),$M42,"") | O42: =IF((L42>$B$5)*(L42<=$C$5),$M42,"") | P42: =IF((L42>$B$6)*(L42<=$C$6),$M42,"") | Q42: =IF((L42>$B$7)*(L42<=$C$7),$M42,"") | R42: =IF((L42>$B$8)*(L42<=$C$8),$M42,"")
L43: 45504 | M43: 2000 | N43: =IF((L43>$B$4)*(L43<=$C$4),$M43,"") | O43: =IF((L43>$B$5)*(L43<=$C$5),$M43,"") | P43: =IF((L43>$B$6)*(L43<=$C$6),$M43,"") | Q43: =IF((L43>$B$7)*(L43<=$C$7),$M43,"") | R43: =IF((L43>$B$8)*(L43<=$C$8),$M43,"")
L44: 45505 | M44: 2000 | N44: =IF((L44>$B$4)*(L44<=$C$4),$M44,"") | O44: =IF((L44>$B$5)*(L44<=$C$5),$M44,"") | P44: =IF((L44>$B$6)*(L44<=$C$6),$M44,"") | Q44: =IF((L44>$B$7)*(L44<=$C$7),$M44,"") | R44: =IF((L44>$B$8)*(L44<=$C$8),$M44,"")
... L390: 46231 | M390: 1215 | N390: =IF((L390>$B$4)*(L390<=$C$4),$M390,"") | O390: =IF((L390>$B$5)*(L390<=$C$5),$M390,"") | P390: =IF((L390>$B$6)*(L390<=$C$6),$M390,"") | Q390: =IF((L390>$B$7)*(L390<=$C$7),$M390,"") | R390: =IF((L390>$B$8)*(L390<=$C$8),$M390,"")

Sheet 06 分窗口统计(公式)
A1: 06 分窗口统计 · 三条序列对照
A2: 本表直接引用 04/05 表的结果，用于横向比较「华东重质 / 华东轻质 / 全国基准」在同一窗口下的位置差异。
A4: 序列 | B4: 窗口 | C4: 样本 n | D4: 最低 | E4: 最高 | F4: 中位数 | G4: 经验分位 | H4: 区间涨跌幅 | I4: 结论标注
A5: S1 华东·重质（主口径） | B5: 近 30 天 | C5: 5 | I5: 有效观测不足 5 条，不计算（不外推、不插值）
A6: S1 华东·重质（主口径） | B6: 近 3 个月 | C6: 15 | I6: 有效观测不足 15 条，不计算（不外推、不插值）
A7: S1 华东·重质（主口径） | B7: 近 1 年 | C7: 139 | D7: 1215 | E7: 1375 | F7: 1250 | G7: 0.72 | H7: -11.64 | I7: 极低
A8: S1 华东·重质（主口径） | B8: 近 3 年 | C8: 358 | D8: 1215 | E8: 2100 | F8: 1450 | G8: 0.28 | H8: -42.14 | I8: 极低
A9: S1 华东·重质（主口径） | B9: 近 5 年 | C9: 358 | D9: 1215 | E9: 2100 | F9: 1450 | G9: 0.28 | H9: -42.14 | I9: 极低
A10: S2 华东·轻质（辅助） | B10: 近 30 天 | C10: 5 | I10: 有效观测不足 5 条，不计算（不外推、不插值）
A11: S2 华东·轻质（辅助） | B11: 近 3 个月 | C11: 15 | I11: 有效观测不足 15 条，不计算（不外推、不插值）
A12: S2 华东·轻质（辅助） | B12: 近 1 年 | C12: 139 | D12: 1250 | E12: 1400 | F12: 1325 | G12: 37.41 | H12: -5.22 | I12: 中位
A13: S2 华东·轻质（辅助） | B13: 近 3 年 | C13: 491 | D13: 1125 | E13: 3100 | F13: 1510 | G13: 13.85 | H13: -39.52 | I13: 偏低
A14: S2 华东·轻质（辅助） | B14: 近 5 年 | C14: 528 | D14: 1125 | E14: 3100 | F14: 1510 | G14: 12.88 | H14: -54.64 | I14: 偏低
A15: S3 全国·重质基准（辅助） | B15: 近 30 天 | C15: 22 | D15: 1144.29 | E15: 1195.71 | F15: 1158.57 | G15: 4.55 | H15: -4.3 | I15: 极低
A16: S3 全国·重质基准（辅助） | B16: 近 3 个月 | C16: 64 | D16: 1144.29 | E16: 1241.43 | F16: 1215.71 | G16: 1.56 | H16: -7.67 | I16: 极低
A17: S3 全国·重质基准（辅助） | B17: 近 1 年 | C17: 262 | D17: 1144.29 | E17: 1315 | F17: 1222.86 | G17: 0.38 | H17: -12.98 | I17: 极低
A18: S3 全国·重质基准（辅助） | B18: 近 3 年 | C18: 710 | D18: 1144.29 | E18: 2910 | F18: 1530 | G18: 0.14 | H18: -51.51 | I18: 极低
A19: S3 全国·重质基准（辅助） | B19: 近 5 年 | C19: 710 | D19: 1144.29 | E19: 2910 | F19: 1530 | G19: 0.14 | H19: -51.51 | I19: 极低
A21: 三条序列的分位各自独立计算。S2 与 S3 的作用是回答「华东这个价是不是全国同步」——如果三条序列分位都很低，说明是行业性的，不是华东独有的区域问题。

Sheet 07 同期对比(公式)
A1: 07 同期对比 · 逐年同月（Excel 公式实算）
A2: 用 AVERAGEIFS 对「02 原始序列」按年月聚合真实观测；没有任何观测的格子留空并注明，不是 0。
A4: 年份 | B4: 1月 | C4: 2月 | D4: 3月 | E4: 4月 | F4: 5月 | G4: 6月 | H4: 7月 | I4: 8月 | J4: 9月 | K4: 10月 | L4: 11月 | M4: 12月 | N4: 全年均值 | O4: 观测数合计
A5: 2024 | B5: =IFERROR(AVERAGEIFS('02 原始序列(主)'!$E$5:$E$362,'02 原始序列(主)'!$B$5:$B$362,">="&DATE(2024,1,1),'02 原始序列(主)'!$B$5:$B$362,"<"&DATE(2024,2,1)),"无观测") | C5: =IFERROR(AVERAGEIFS('02 原始序列(主)'!$E$5:$E$362,'02 原始序列(主)'!$B$5:$B$362,">="&DATE(2024,2,1),'02 原始序列(主)'!$B$5:$B$362,"<"&DATE(2024,3,1)),"无观测") | D5: =IFERROR(AVERAGEIFS('02 原始序列(主)'!$E$5:$E$362,'02 原始序列(主)'!$B$5:$B$362,">="&DATE(2024,3,1),'02 原始序列(主)'!$B$5:$B$362,"<"&DATE(2024,4,1)),"无观测") | E5: =IFERROR(AVERAGEIFS('02 原始序列(主)'!$E$5:$E$362,'02 原始序列(主)'!$B$5:$B$362,">="&DATE(2024,4,1),'02 原始序列(主)'!$B$5:$B$362,"<"&DATE(2024,5,1)),"无观测") | F5: =IFERROR(AVERAGEIFS('02 原始序列(主)'!$E$5:$E$362,'02 原始序列(主)'!$B$5:$B$362,">="&DATE(2024,5,1),'02 原始序列(主)'!$B$5:$B$362,"<"&DATE(2024,6,1)),"无观测") | G5: =IFERROR(AVERAGEIFS('02 原始序列(主)'!$E$5:$E$362,'02 原始序列(主)'!$B$5:$B$362,">="&DATE(2024,6,1),'02 原始序列(主)'!$B$5:$B$362,"<"&DATE(2024,7,1)),"无观测") | H5: =IFERROR(AVERAGEIFS('02 原始序列(主)'!$E$5:$E$362,'02 原始序列(主)'!$B$5:$B$362,">="&DATE(2024,7,1),'02 原始序列(主)'!$B$5:$B$362,"<"&DATE(2024,8,1)),"无观测") | I5: =IFERROR(AVERAGEIFS('02 原始序列(主)'!$E$5:$E$362,'02 原始序列(主)'!$B$5:$B$362,">="&DATE(2024,8,1),'02 原始序列(主)'!$B$5:$B$362,"<"&DATE(2024,9,1)),"无观测") | J5: =IFERROR(AVERAGEIFS('02 原始序列(主)'!$E$5:$E$362,'02 原始序列(主)'!$B$5:$B$362,">="&DATE(2024,9,1),'02 原始序列(主)'!$B$5:$B$362,"<"&DATE(2024,10,1)),"无观测") | K5: =IFERROR(AVERAGEIFS('02 原始序列(主)'!$E$5:$E$362,'02 原始序列(主)'!$B$5:$B$362,">="&DATE(2024,10,1),'02 原始序列(主)'!$B$5:$B$362,"<"&DATE(2024,11,1)),"无观测") | L5: =IFERROR(AVERAGEIFS('02 原始序列(主)'!$E$5:$E$362,'02 原始序列(主)'!$B$5:$B$362,">="&DATE(2024,11,1),'02 原始序列(主)'!$B$5:$B$362,"<"&DATE(2024,12,1)),"无观测") | M5: =IFERROR(AVERAGEIFS('02 原始序列(主)'!$E$5:$E$362,'02 原始序列(主)'!$B$5:$B$362,">="&DATE(2024,12,1),'02 原始序列(主)'!$B$5:$B$362,"<="&DATE(2024,12,31)),"无观测") | N5: =IFERROR(AVERAGEIFS('02 原始序列(主)'!$E$5:$E$362,'02 原始序列(主)'!$B$5:$B$362,">="&DATE(2024,1,1),'02 原始序列(主)'!$B$5:$B$362,"<="&DATE(2024,12,31)),"无观测") | O5: =COUNTIFS('02 原始序列(主)'!$B$5:$B$362,">="&DATE(2024,1,1),'02 原始序列(主)'!$B$5:$B$362,"<="&DATE(2024,12,31))
A6: 2025 | B6: =IFERROR(AVERAGEIFS('02 原始序列(主)'!$E$5:$E$362,'02 原始序列(主)'!$B$5:$B$362,">="&DATE(2025,1,1),'02 原始序列(主)'!$B$5:$B$362,"<"&DATE(2025,2,1)),"无观测") | C6: =IFERROR(AVERAGEIFS('02 原始序列(主)'!$E$5:$E$362,'02 原始序列(主)'!$B$5:$B$362,">="&DATE(2025,2,1),'02 原始序列(主)'!$B$5:$B$362,"<"&DATE(2025,3,1)),"无观测") | D6: =IFERROR(AVERAGEIFS('02 原始序列(主)'!$E$5:$E$362,'02 原始序列(主)'!$B$5:$B$362,">="&DATE(2025,3,1),'02 原始序列(主)'!$B$5:$B$362,"<"&DATE(2025,4,1)),"无观测") | E6: =IFERROR(AVERAGEIFS('02 原始序列(主)'!$E$5:$E$362,'02 原始序列(主)'!$B$5:$B$362,">="&DATE(2025,4,1),'02 原始序列(主)'!$B$5:$B$362,"<"&DATE(2025,5,1)),"无观测") | F6: =IFERROR(AVERAGEIFS('02 原始序列(主)'!$E$5:$E$362,'02 原始序列(主)'!$B$5:$B$362,">="&DATE(2025,5,1),'02 原始序列(主)'!$B$5:$B$362,"<"&DATE(2025,6,1)),"无观测") | G6: =IFERROR(AVERAGEIFS('02 原始序列(主)'!$E$5:$E$362,'02 原始序列(主)'!$B$5:$B$362,">="&DATE(2025,6,1),'02 原始序列(主)'!$B$5:$B$362,"<"&DATE(2025,7,1)),"无观测") | H6: =IFERROR(AVERAGEIFS('02 原始序列(主)'!$E$5:$E$362,'02 原始序列(主)'!$B$5:$B$362,">="&DATE(2025,7,1),'02 原始序列(主)'!$B$5:$B$362,"<"&DATE(2025,8,1)),"无观测") | I6: =IFERROR(AVERAGEIFS('02 原始序列(主)'!$E$5:$E$362,'02 原始序列(主)'!$B$5:$B$362,">="&DATE(2025,8,1),'02 原始序列(主)'!$B$5:$B$362,"<"&DATE(2025,9,1)),"无观测") | J6: =IFERROR(AVERAGEIFS('02 原始序列(主)'!$E$5:$E$362,'02 原始序列(主)'!$B$5:$B$362,">="&DATE(2025,9,1),'02 原始序列(主)'!$B$5:$B$362,"<"&DATE(2025,10,1)),"无观测") | K6: =IFERROR(AVERAGEIFS('02 原始序列(主)'!$E$5:$E$362,'02 原始序列(主)'!$B$5:$B$362,">="&DATE(2025,10,1),'02 原始序列(主)'!$B$5:$B$362,"<"&DATE(2025,11,1)),"无观测") | L6: =IFERROR(AVERAGEIFS('02 原始序列(主)'!$E$5:$E$362,'02 原始序列(主)'!$B$5:$B$362,">="&DATE(2025,11,1),'02 原始序列(主)'!$B$5:$B$362,"<"&DATE(2025,12,1)),"无观测") | M6: =IFERROR(AVERAGEIFS('02 原始序列(主)'!$E$5:$E$362,'02 原始序列(主)'!$B$5:$B$362,">="&DATE(2025,12,1),'02 原始序列(主)'!$B$5:$B$362,"<="&DATE(2025,12,31)),"无观测") | N6: =IFERROR(AVERAGEIFS('02 原始序列(主)'!$E$5:$E$362,'02 原始序列(主)'!$B$5:$B$362,">="&DATE(2025,1,1),'02 原始序列(主)'!$B$5:$B$362,"<="&DATE(2025,12,31)),"无观测") | O6: =COUNTIFS('02 原始序列(主)'!$B$5:$B$362,">="&DATE(2025,1,1),'02 原始序列(主)'!$B$5:$B$362,"<="&DATE(2025,12,31))
A7: 2026 | B7: =IFERROR(AVERAGEIFS('02 原始序列(主)'!$E$5:$E$362,'02 原始序列(主)'!$B$5:$B$362,">="&DATE(2026,1,1),'02 原始序列(主)'!$B$5:$B$362,"<"&DATE(2026,2,1)),"无观测") | C7: =IFERROR(AVERAGEIFS('02 原始序列(主)'!$E$5:$E$362,'02 原始序列(主)'!$B$5:$B$362,">="&DATE(2026,2,1),'02 原始序列(主)'!$B$5:$B$362,"<"&DATE(2026,3,1)),"无观测") | D7: =IFERROR(AVERAGEIFS('02 原始序列(主)'!$E$5:$E$362,'02 原始序列(主)'!$B$5:$B$362,">="&DATE(2026,3,1),'02 原始序列(主)'!$B$5:$B$362,"<"&DATE(2026,4,1)),"无观测") | E7: =IFERROR(AVERAGEIFS('02 原始序列(主)'!$E$5:$E$362,'02 原始序列(主)'!$B$5:$B$362,">="&DATE(2026,4,1),'02 原始序列(主)'!$B$5:$B$362,"<"&DATE(2026,5,1)),"无观测") | F7: =IFERROR(AVERAGEIFS('02 原始序列(主)'!$E$5:$E$362,'02 原始序列(主)'!$B$5:$B$362,">="&DATE(2026,5,1),'02 原始序列(主)'!$B$5:$B$362,"<"&DATE(2026,6,1)),"无观测") | G7: =IFERROR(AVERAGEIFS('02 原始序列(主)'!$E$5:$E$362,'02 原始序列(主)'!$B$5:$B$362,">="&DATE(2026,6,1),'02 原始序列(主)'!$B$5:$B$362,"<"&DATE(2026,7,1)),"无观测") | H7: =IFERROR(AVERAGEIFS('02 原始序列(主)'!$E$5:$E$362,'02 原始序列(主)'!$B$5:$B$362,">="&DATE(2026,7,1),'02 原始序列(主)'!$B$5:$B$362,"<"&DATE(2026,8,1)),"无观测") | I7: =IFERROR(AVERAGEIFS('02 原始序列(主)'!$E$5:$E$362,'02 原始序列(主)'!$B$5:$B$362,">="&DATE(2026,8,1),'02 原始序列(主)'!$B$5:$B$362,"<"&DATE(2026,9,1)),"无观测") | J7: =IFERROR(AVERAGEIFS('02 原始序列(主)'!$E$5:$E$362,'02 原始序列(主)'!$B$5:$B$362,">="&DATE(2026,9,1),'02 原始序列(主)'!$B$5:$B$362,"<"&DATE(2026,10,1)),"无观测") | K7: =IFERROR(AVERAGEIFS('02 原始序列(主)'!$E$5:$E$362,'02 原始序列(主)'!$B$5:$B$362,">="&DATE(2026,10,1),'02 原始序列(主)'!$B$5:$B$362,"<"&DATE(2026,11,1)),"无观测") | L7: =IFERROR(AVERAGEIFS('02 原始序列(主)'!$E$5:$E$362,'02 原始序列(主)'!$B$5:$B$362,">="&DATE(2026,11,1),'02 原始序列(主)'!$B$5:$B$362,"<"&DATE(2026,12,1)),"无观测") | M7: =IFERROR(AVERAGEIFS('02 原始序列(主)'!$E$5:$E$362,'02 原始序列(主)'!$B$5:$B$362,">="&DATE(2026,12,1),'02 原始序列(主)'!$B$5:$B$362,"<="&DATE(2026,12,31)),"无观测") | N7: =IFERROR(AVERAGEIFS('02 原始序列(主)'!$E$5:$E$362,'02 原始序列(主)'!$B$5:$B$362,">="&DATE(2026,1,1),'02 原始序列(主)'!$B$5:$B$362,"<="&DATE(2026,12,31)),"无观测") | O7: =COUNTIFS('02 原始序列(主)'!$B$5:$B$362,">="&DATE(2026,1,1),'02 原始序列(主)'!$B$5:$B$362,"<="&DATE(2026,12,31))
A9: 月份 | B9: 跨年均价 | C9: 季节性指数 | D9: 样本月数 | E9: 说明
A10: 1月 | B10: =IFERROR(AVERAGE(B5:B7),"无观测") | C10: =IFERROR(B10/AVERAGE($B$5:$B$7),"—") | D10: =COUNT(B5:B7) | E10: 100＝全期月均；>100 表示该月历史均价高于全年平均
A11: 2月 | B11: =IFERROR(AVERAGE(C5:C7),"无观测") | C11: =IFERROR(B11/AVERAGE($B$5:$B$7),"—") | D11: =COUNT(C5:C7)
A12: 3月 | B12: =IFERROR(AVERAGE(D5:D7),"无观测") | C12: =IFERROR(B12/AVERAGE($B$5:$B$7),"—") | D12: =COUNT(D5:D7)
A13: 4月 | B13: =IFERROR(AVERAGE(E5:E7),"无观测") | C13: =IFERROR(B13/AVERAGE($B$5:$B$7),"—") | D13: =COUNT(E5:E7)
A14: 5月 | B14: =IFERROR(AVERAGE(F5:F7),"无观测") | C14: =IFERROR(B14/AVERAGE($B$5:$B$7),"—") | D14: =COUNT(F5:F7)
A15: 6月 | B15: =IFERROR(AVERAGE(G5:G7),"无观测") | C15: =IFERROR(B15/AVERAGE($B$5:$B$7),"—") | D15: =COUNT(G5:G7)
A16: 7月 | B16: =IFERROR(AVERAGE(H5:H7),"无观测") | C16: =IFERROR(B16/AVERAGE($B$5:$B$7),"—") | D16: =COUNT(H5:H7)
A17: 8月 | B17: =IFERROR(AVERAGE(I5:I7),"无观测") | C17: =IFERROR(B17/AVERAGE($B$5:$B$7),"—") | D17: =COUNT(I5:I7)
A18: 9月 | B18: =IFERROR(AVERAGE(J5:J7),"无观测") | C18: =IFERROR(B18/AVERAGE($B$5:$B$7),"—") | D18: =COUNT(J5:J7)
A19: 10月 | B19: =IFERROR(AVERAGE(K5:K7),"无观测") | C19: =IFERROR(B19/AVERAGE($B$5:$B$7),"—") | D19: =COUNT(K5:K7)
A20: 11月 | B20: =IFERROR(AVERAGE(L5:L7),"无观测") | C20: =IFERROR(B20/AVERAGE($B$5:$B$7),"—") | D20: =COUNT(L5:L7)
A21: 12月 | B21: =IFERROR(AVERAGE(M5:M7),"无观测") | C21: =IFERROR(B21/AVERAGE($B$5:$B$7),"—") | D21: =COUNT(M5:M7)
A23: 季节性指数只描述「历史上各月相对全期的位置」，不是对今年该月的推演。样本月数少于 2 的月份，指数参考价值有限，已在 D 列标出。

Sheet 08 季节性(公式)
A1: 08 季节性矩阵 · 年 × 月 均价与样本数
A2: 两层：上层为各年各月均价（AVERAGEIFS），下层为对应观测条数（COUNTIFS）。
A4: 【第 1 层】均价
A5: 年 \ 月 | B5: 1月 | C5: 2月 | D5: 3月 | E5: 4月 | F5: 5月 | G5: 6月 | H5: 7月 | I5: 8月 | J5: 9月 | K5: 10月 | L5: 11月 | M5: 12月
A6: 2024 | B6: =IFERROR(AVERAGEIFS('02 原始序列(主)'!$E$5:$E$362,'02 原始序列(主)'!$B$5:$B$362,">="&DATE(2024,1,1),'02 原始序列(主)'!$B$5:$B$362,"<"&DATE(2024,2,1)),"") | C6: =IFERROR(AVERAGEIFS('02 原始序列(主)'!$E$5:$E$362,'02 原始序列(主)'!$B$5:$B$362,">="&DATE(2024,2,1),'02 原始序列(主)'!$B$5:$B$362,"<"&DATE(2024,3,1)),"") | D6: =IFERROR(AVERAGEIFS('02 原始序列(主)'!$E$5:$E$362,'02 原始序列(主)'!$B$5:$B$362,">="&DATE(2024,3,1),'02 原始序列(主)'!$B$5:$B$362,"<"&DATE(2024,4,1)),"") | E6: =IFERROR(AVERAGEIFS('02 原始序列(主)'!$E$5:$E$362,'02 原始序列(主)'!$B$5:$B$362,">="&DATE(2024,4,1),'02 原始序列(主)'!$B$5:$B$362,"<"&DATE(2024,5,1)),"") | F6: =IFERROR(AVERAGEIFS('02 原始序列(主)'!$E$5:$E$362,'02 原始序列(主)'!$B$5:$B$362,">="&DATE(2024,5,1),'02 原始序列(主)'!$B$5:$B$362,"<"&DATE(2024,6,1)),"") | G6: =IFERROR(AVERAGEIFS('02 原始序列(主)'!$E$5:$E$362,'02 原始序列(主)'!$B$5:$B$362,">="&DATE(2024,6,1),'02 原始序列(主)'!$B$5:$B$362,"<"&DATE(2024,7,1)),"") | H6: =IFERROR(AVERAGEIFS('02 原始序列(主)'!$E$5:$E$362,'02 原始序列(主)'!$B$5:$B$362,">="&DATE(2024,7,1),'02 原始序列(主)'!$B$5:$B$362,"<"&DATE(2024,8,1)),"") | I6: =IFERROR(AVERAGEIFS('02 原始序列(主)'!$E$5:$E$362,'02 原始序列(主)'!$B$5:$B$362,">="&DATE(2024,8,1),'02 原始序列(主)'!$B$5:$B$362,"<"&DATE(2024,9,1)),"") | J6: =IFERROR(AVERAGEIFS('02 原始序列(主)'!$E$5:$E$362,'02 原始序列(主)'!$B$5:$B$362,">="&DATE(2024,9,1),'02 原始序列(主)'!$B$5:$B$362,"<"&DATE(2024,10,1)),"") | K6: =IFERROR(AVERAGEIFS('02 原始序列(主)'!$E$5:$E$362,'02 原始序列(主)'!$B$5:$B$362,">="&DATE(2024,10,1),'02 原始序列(主)'!$B$5:$B$362,"<"&DATE(2024,11,1)),"") | L6: =IFERROR(AVERAGEIFS('02 原始序列(主)'!$E$5:$E$362,'02 原始序列(主)'!$B$5:$B$362,">="&DATE(2024,11,1),'02 原始序列(主)'!$B$5:$B$362,"<"&DATE(2024,12,1)),"") | M6: =IFERROR(AVERAGEIFS('02 原始序列(主)'!$E$5:$E$362,'02 原始序列(主)'!$B$5:$B$362,">="&DATE(2024,12,1),'02 原始序列(主)'!$B$5:$B$362,"<"&DATE(2024,12,31)),"")
A7: 2025 | B7: =IFERROR(AVERAGEIFS('02 原始序列(主)'!$E$5:$E$362,'02 原始序列(主)'!$B$5:$B$362,">="&DATE(2025,1,1),'02 原始序列(主)'!$B$5:$B$362,"<"&DATE(2025,2,1)),"") | C7: =IFERROR(AVERAGEIFS('02 原始序列(主)'!$E$5:$E$362,'02 原始序列(主)'!$B$5:$B$362,">="&DATE(2025,2,1),'02 原始序列(主)'!$B$5:$B$362,"<"&DATE(2025,3,1)),"") | D7: =IFERROR(AVERAGEIFS('02 原始序列(主)'!$E$5:$E$362,'02 原始序列(主)'!$B$5:$B$362,">="&DATE(2025,3,1),'02 原始序列(主)'!$B$5:$B$362,"<"&DATE(2025,4,1)),"") | E7: =IFERROR(AVERAGEIFS('02 原始序列(主)'!$E$5:$E$362,'02 原始序列(主)'!$B$5:$B$362,">="&DATE(2025,4,1),'02 原始序列(主)'!$B$5:$B$362,"<"&DATE(2025,5,1)),"") | F7: =IFERROR(AVERAGEIFS('02 原始序列(主)'!$E$5:$E$362,'02 原始序列(主)'!$B$5:$B$362,">="&DATE(2025,5,1),'02 原始序列(主)'!$B$5:$B$362,"<"&DATE(2025,6,1)),"") | G7: =IFERROR(AVERAGEIFS('02 原始序列(主)'!$E$5:$E$362,'02 原始序列(主)'!$B$5:$B$362,">="&DATE(2025,6,1),'02 原始序列(主)'!$B$5:$B$362,"<"&DATE(2025,7,1)),"") | H7: =IFERROR(AVERAGEIFS('02 原始序列(主)'!$E$5:$E$362,'02 原始序列(主)'!$B$5:$B$362,">="&DATE(2025,7,1),'02 原始序列(主)'!$B$5:$B$362,"<"&DATE(2025,8,1)),"") | I7: =IFERROR(AVERAGEIFS('02 原始序列(主)'!$E$5:$E$362,'02 原始序列(主)'!$B$5:$B$362,">="&DATE(2025,8,1),'02 原始序列(主)'!$B$5:$B$362,"<"&DATE(2025,9,1)),"") | J7: =IFERROR(AVERAGEIFS('02 原始序列(主)'!$E$5:$E$362,'02 原始序列(主)'!$B$5:$B$362,">="&DATE(2025,9,1),'02 原始序列(主)'!$B$5:$B$362,"<"&DATE(2025,10,1)),"") | K7: =IFERROR(AVERAGEIFS('02 原始序列(主)'!$E$5:$E$362,'02 原始序列(主)'!$B$5:$B$362,">="&DATE(2025,10,1),'02 原始序列(主)'!$B$5:$B$362,"<"&DATE(2025,11,1)),"") | L7: =IFERROR(AVERAGEIFS('02 原始序列(主)'!$E$5:$E$362,'02 原始序列(主)'!$B$5:$B$362,">="&DATE(2025,11,1),'02 原始序列(主)'!$B$5:$B$362,"<"&DATE(2025,12,1)),"") | M7: =IFERROR(AVERAGEIFS('02 原始序列(主)'!$E$5:$E$362,'02 原始序列(主)'!$B$5:$B$362,">="&DATE(2025,12,1),'02 原始序列(主)'!$B$5:$B$362,"<"&DATE(2025,12,31)),"")
A8: 2026 | B8: =IFERROR(AVERAGEIFS('02 原始序列(主)'!$E$5:$E$362,'02 原始序列(主)'!$B$5:$B$362,">="&DATE(2026,1,1),'02 原始序列(主)'!$B$5:$B$362,"<"&DATE(2026,2,1)),"") | C8: =IFERROR(AVERAGEIFS('02 原始序列(主)'!$E$5:$E$362,'02 原始序列(主)'!$B$5:$B$362,">="&DATE(2026,2,1),'02 原始序列(主)'!$B$5:$B$362,"<"&DATE(2026,3,1)),"") | D8: =IFERROR(AVERAGEIFS('02 原始序列(主)'!$E$5:$E$362,'02 原始序列(主)'!$B$5:$B$362,">="&DATE(2026,3,1),'02 原始序列(主)'!$B$5:$B$362,"<"&DATE(2026,4,1)),"") | E8: =IFERROR(AVERAGEIFS('02 原始序列(主)'!$E$5:$E$362,'02 原始序列(主)'!$B$5:$B$362,">="&DATE(2026,4,1),'02 原始序列(主)'!$B$5:$B$362,"<"&DATE(2026,5,1)),"") | F8: =IFERROR(AVERAGEIFS('02 原始序列(主)'!$E$5:$E$362,'02 原始序列(主)'!$B$5:$B$362,">="&DATE(2026,5,1),'02 原始序列(主)'!$B$5:$B$362,"<"&DATE(2026,6,1)),"") | G8: =IFERROR(AVERAGEIFS('02 原始序列(主)'!$E$5:$E$362,'02 原始序列(主)'!$B$5:$B$362,">="&DATE(2026,6,1),'02 原始序列(主)'!$B$5:$B$362,"<"&DATE(2026,7,1)),"") | H8: =IFERROR(AVERAGEIFS('02 原始序列(主)'!$E$5:$E$362,'02 原始序列(主)'!$B$5:$B$362,">="&DATE(2026,7,1),'02 原始序列(主)'!$B$5:$B$362,"<"&DATE(2026,8,1)),"") | I8: =IFERROR(AVERAGEIFS('02 原始序列(主)'!$E$5:$E$362,'02 原始序列(主)'!$B$5:$B$362,">="&DATE(2026,8,1),'02 原始序列(主)'!$B$5:$B$362,"<"&DATE(2026,9,1)),"") | J8: =IFERROR(AVERAGEIFS('02 原始序列(主)'!$E$5:$E$362,'02 原始序列(主)'!$B$5:$B$362,">="&DATE(2026,9,1),'02 原始序列(主)'!$B$5:$B$362,"<"&DATE(2026,10,1)),"") | K8: =IFERROR(AVERAGEIFS('02 原始序列(主)'!$E$5:$E$362,'02 原始序列(主)'!$B$5:$B$362,">="&DATE(2026,10,1),'02 原始序列(主)'!$B$5:$B$362,"<"&DATE(2026,11,1)),"") | L8: =IFERROR(AVERAGEIFS('02 原始序列(主)'!$E$5:$E$362,'02 原始序列(主)'!$B$5:$B$362,">="&DATE(2026,11,1),'02 原始序列(主)'!$B$5:$B$362,"<"&DATE(2026,12,1)),"") | M8: =IFERROR(AVERAGEIFS('02 原始序列(主)'!$E$5:$E$362,'02 原始序列(主)'!$B$5:$B$362,">="&DATE(2026,12,1),'02 原始序列(主)'!$B$5:$B$362,"<"&DATE(2026,12,31)),"")
A10: 【第 2 层】观测数
A11: 年 \ 月 | B11: 1月 | C11: 2月 | D11: 3月 | E11: 4月 | F11: 5月 | G11: 6月 | H11: 7月 | I11: 8月 | J11: 9月 | K11: 10月 | L11: 11月 | M11: 12月
A12: 2024 | B12: =IFERROR(COUNTIFS('02 原始序列(主)'!$B$5:$B$362,">="&DATE(2024,1,1),'02 原始序列(主)'!$B$5:$B$362,"<"&DATE(2024,2,1)),0) | C12: =IFERROR(COUNTIFS('02 原始序列(主)'!$B$5:$B$362,">="&DATE(2024,2,1),'02 原始序列(主)'!$B$5:$B$362,"<"&DATE(2024,3,1)),0) | D12: =IFERROR(COUNTIFS('02 原始序列(主)'!$B$5:$B$362,">="&DATE(2024,3,1),'02 原始序列(主)'!$B$5:$B$362,"<"&DATE(2024,4,1)),0) | E12: =IFERROR(COUNTIFS('02 原始序列(主)'!$B$5:$B$362,">="&DATE(2024,4,1),'02 原始序列(主)'!$B$5:$B$362,"<"&DATE(2024,5,1)),0) | F12: =IFERROR(COUNTIFS('02 原始序列(主)'!$B$5:$B$362,">="&DATE(2024,5,1),'02 原始序列(主)'!$B$5:$B$362,"<"&DATE(2024,6,1)),0) | G12: =IFERROR(COUNTIFS('02 原始序列(主)'!$B$5:$B$362,">="&DATE(2024,6,1),'02 原始序列(主)'!$B$5:$B$362,"<"&DATE(2024,7,1)),0) | H12: =IFERROR(COUNTIFS('02 原始序列(主)'!$B$5:$B$362,">="&DATE(2024,7,1),'02 原始序列(主)'!$B$5:$B$362,"<"&DATE(2024,8,1)),0) | I12: =IFERROR(COUNTIFS('02 原始序列(主)'!$B$5:$B$362,">="&DATE(2024,8,1),'02 原始序列(主)'!$B$5:$B$362,"<"&DATE(2024,9,1)),0) | J12: =IFERROR(COUNTIFS('02 原始序列(主)'!$B$5:$B$362,">="&DATE(2024,9,1),'02 原始序列(主)'!$B$5:$B$362,"<"&DATE(2024,10,1)),0) | K12: =IFERROR(COUNTIFS('02 原始序列(主)'!$B$5:$B$362,">="&DATE(2024,10,1),'02 原始序列(主)'!$B$5:$B$362,"<"&DATE(2024,11,1)),0) | L12: =IFERROR(COUNTIFS('02 原始序列(主)'!$B$5:$B$362,">="&DATE(2024,11,1),'02 原始序列(主)'!$B$5:$B$362,"<"&DATE(2024,12,1)),0) | M12: =IFERROR(COUNTIFS('02 原始序列(主)'!$B$5:$B$362,">="&DATE(2024,12,1),'02 原始序列(主)'!$B$5:$B$362,"<"&DATE(2024,12,31)),0)
A13: 2025 | B13: =IFERROR(COUNTIFS('02 原始序列(主)'!$B$5:$B$362,">="&DATE(2025,1,1),'02 原始序列(主)'!$B$5:$B$362,"<"&DATE(2025,2,1)),0) | C13: =IFERROR(COUNTIFS('02 原始序列(主)'!$B$5:$B$362,">="&DATE(2025,2,1),'02 原始序列(主)'!$B$5:$B$362,"<"&DATE(2025,3,1)),0) | D13: =IFERROR(COUNTIFS('02 原始序列(主)'!$B$5:$B$362,">="&DATE(2025,3,1),'02 原始序列(主)'!$B$5:$B$362,"<"&DATE(2025,4,1)),0) | E13: =IFERROR(COUNTIFS('02 原始序列(主)'!$B$5:$B$362,">="&DATE(2025,4,1),'02 原始序列(主)'!$B$5:$B$362,"<"&DATE(2025,5,1)),0) | F13: =IFERROR(COUNTIFS('02 原始序列(主)'!$B$5:$B$362,">="&DATE(2025,5,1),'02 原始序列(主)'!$B$5:$B$362,"<"&DATE(2025,6,1)),0) | G13: =IFERROR(COUNTIFS('02 原始序列(主)'!$B$5:$B$362,">="&DATE(2025,6,1),'02 原始序列(主)'!$B$5:$B$362,"<"&DATE(2025,7,1)),0) | H13: =IFERROR(COUNTIFS('02 原始序列(主)'!$B$5:$B$362,">="&DATE(2025,7,1),'02 原始序列(主)'!$B$5:$B$362,"<"&DATE(2025,8,1)),0) | I13: =IFERROR(COUNTIFS('02 原始序列(主)'!$B$5:$B$362,">="&DATE(2025,8,1),'02 原始序列(主)'!$B$5:$B$362,"<"&DATE(2025,9,1)),0) | J13: =IFERROR(COUNTIFS('02 原始序列(主)'!$B$5:$B$362,">="&DATE(2025,9,1),'02 原始序列(主)'!$B$5:$B$362,"<"&DATE(2025,10,1)),0) | K13: =IFERROR(COUNTIFS('02 原始序列(主)'!$B$5:$B$362,">="&DATE(2025,10,1),'02 原始序列(主)'!$B$5:$B$362,"<"&DATE(2025,11,1)),0) | L13: =IFERROR(COUNTIFS('02 原始序列(主)'!$B$5:$B$362,">="&DATE(2025,11,1),'02 原始序列(主)'!$B$5:$B$362,"<"&DATE(2025,12,1)),0) | M13: =IFERROR(COUNTIFS('02 原始序列(主)'!$B$5:$B$362,">="&DATE(2025,12,1),'02 原始序列(主)'!$B$5:$B$362,"<"&DATE(2025,12,31)),0)
A14: 2026 | B14: =IFERROR(COUNTIFS('02 原始序列(主)'!$B$5:$B$362,">="&DATE(2026,1,1),'02 原始序列(主)'!$B$5:$B$362,"<"&DATE(2026,2,1)),0) | C14: =IFERROR(COUNTIFS('02 原始序列(主)'!$B$5:$B$362,">="&DATE(2026,2,1),'02 原始序列(主)'!$B$5:$B$362,"<"&DATE(2026,3,1)),0) | D14: =IFERROR(COUNTIFS('02 原始序列(主)'!$B$5:$B$362,">="&DATE(2026,3,1),'02 原始序列(主)'!$B$5:$B$362,"<"&DATE(2026,4,1)),0) | E14: =IFERROR(COUNTIFS('02 原始序列(主)'!$B$5:$B$362,">="&DATE(2026,4,1),'02 原始序列(主)'!$B$5:$B$362,"<"&DATE(2026,5,1)),0) | F14: =IFERROR(COUNTIFS('02 原始序列(主)'!$B$5:$B$362,">="&DATE(2026,5,1),'02 原始序列(主)'!$B$5:$B$362,"<"&DATE(2026,6,1)),0) | G14: =IFERROR(COUNTIFS('02 原始序列(主)'!$B$5:$B$362,">="&DATE(2026,6,1),'02 原始序列(主)'!$B$5:$B$362,"<"&DATE(2026,7,1)),0) | H14: =IFERROR(COUNTIFS('02 原始序列(主)'!$B$5:$B$362,">="&DATE(2026,7,1),'02 原始序列(主)'!$B$5:$B$362,"<"&DATE(2026,8,1)),0) | I14: =IFERROR(COUNTIFS('02 原始序列(主)'!$B$5:$B$362,">="&DATE(2026,8,1),'02 原始序列(主)'!$B$5:$B$362,"<"&DATE(2026,9,1)),0) | J14: =IFERROR(COUNTIFS('02 原始序列(主)'!$B$5:$B$362,">="&DATE(2026,9,1),'02 原始序列(主)'!$B$5:$B$362,"<"&DATE(2026,10,1)),0) | K14: =IFERROR(COUNTIFS('02 原始序列(主)'!$B$5:$B$362,">="&DATE(2026,10,1),'02 原始序列(主)'!$B$5:$B$362,"<"&DATE(2026,11,1)),0) | L14: =IFERROR(COUNTIFS('02 原始序列(主)'!$B$5:$B$362,">="&DATE(2026,11,1),'02 原始序列(主)'!$B$5:$B$362,"<"&DATE(2026,12,1)),0) | M14: =IFERROR(COUNTIFS('02 原始序列(主)'!$B$5:$B$362,">="&DATE(2026,12,1),'02 原始序列(主)'!$B$5:$B$362,"<"&DATE(2026,12,31)),0)
A16: 「0」或空表示该年该月没有可用观测——本表不做任何填补。重碱序列起点为 2024-07-17，故 2024 年只有 7 月之后有数。

Sheet 09 异常点
A1: 09 异常点 · 三条独立判据
A2: A 水平异常：相对滚动一年中位数偏离 ≥2.5 倍稳健 z（MAD）；B 跳变：相邻报价日变动 ≥3%；C 分布异常：越 1.5×IQR 栅栏。
A4: 日期 | B4: 价格(元/吨) | C4: 判据 | D4: 分值/幅度 | E4: 说明 | F4: 原文链接
A5: 45502 | B5: 2025 | C5: B 单日跳变 | D5: -3.57 | E5: 前值 2100.00（2024-07-26）→ 2025.00 | F5: 打开原文
A6: 45516 | B6: 1925 | C6: B 单日跳变 | D6: -3.75 | E6: 前值 2000.00（2024-08-09）→ 1925.00 | F6: 打开原文
A7: 45537 | B7: 1750 | C7: B 单日跳变 | D7: -6.67 | E7: 前值 1875.00（2024-08-30）→ 1750.00 | F7: 打开原文
A8: 45537 | B8: 1750 | C8: C 分布异常 | D8: 越栅栏 | E8: 落在 Q1-1.5IQR ~ Q3+1.5IQR 之外 | F8: 打开原文
A9: 45538 | B9: 1750 | C9: C 分布异常 | D9: 越栅栏 | E9: 落在 Q1-1.5IQR ~ Q3+1.5IQR 之外 | F9: 打开原文
A10: 45539 | B10: 1700 | C10: A 水平异常 | D10: -3.54 | E10: 相对滚动一年中位数偏 -3.54 倍稳健 z | F10: 打开原文
A11: 45539 | B11: 1700 | C11: C 分布异常 | D11: 越栅栏 | E11: 落在 Q1-1.5IQR ~ Q3+1.5IQR 之外 | F11: 打开原文
A12: 45540 | B12: 1700 | C12: C 分布异常 | D12: 越栅栏 | E12: 落在 Q1-1.5IQR ~ Q3+1.5IQR 之外 | F12: 打开原文
A13: 45545 | B13: 1675 | C13: C 分布异常 | D13: 越栅栏 | E13: 落在 Q1-1.5IQR ~ Q3+1.5IQR 之外 | F13: 打开原文
A14: 45546 | B14: 1625 | C14: A 水平异常 | D14: -2.7 | E14: 相对滚动一年中位数偏 -2.70 倍稳健 z | F14: 打开原文
A15: 45546 | B15: 1625 | C15: C 分布异常 | D15: 越栅栏 | E15: 落在 Q1-1.5IQR ~ Q3+1.5IQR 之外 | F15: 打开原文
A16: 45547 | B16: 1625 | C16: A 水平异常 | D16: -2.7 | E16: 相对滚动一年中位数偏 -2.70 倍稳健 z | F16: 打开原文
A17: 45547 | B17: 1625 | C17: C 分布异常 | D17: 越栅栏 | E17: 落在 Q1-1.5IQR ~ Q3+1.5IQR 之外 | F17: 打开原文
A18: 45548 | B18: 1625 | C18: A 水平异常 | D18: -2.7 | E18: 相对滚动一年中位数偏 -2.70 倍稳健 z | F18: 打开原文
A19: 45548 | B19: 1625 | C19: C 分布异常 | D19: 越栅栏 | E19: 落在 Q1-1.5IQR ~ Q3+1.5IQR 之外 | F19: 打开原文
A20: 45549 | B20: 1625 | C20: A 水平异常 | D20: -2.7 | E20: 相对滚动一年中位数偏 -2.70 倍稳健 z | F20: 打开原文
A21: 45553 | B21: 1575 | C21: A 水平异常 | D21: -3.15 | E21: 相对滚动一年中位数偏 -3.15 倍稳健 z | F21: 打开原文
A22: 45553 | B22: 1575 | C22: B 单日跳变 | D22: -3.08 | E22: 前值 1625.00（2024-09-14）→ 1575.00 | F22: 打开原文
A23: 45554 | B23: 1575 | C23: A 水平异常 | D23: -2.7 | E23: 相对滚动一年中位数偏 -2.70 倍稳健 z | F23: 打开原文
A24: 45586 | B24: 1575 | C24: B 单日跳变 | D24: -3.08 | E24: 前值 1625.00（2024-10-18）→ 1575.00 | F24: 打开原文
A25: 45670 | B25: 1510 | C25: B 单日跳变 | D25: -4.13 | E25: 前值 1575.00（2025-01-10）→ 1510.00 | F25: 打开原文
A26: 45681 | B26: 1510 | C26: A 水平异常 | D26: -3.51 | E26: 相对滚动一年中位数偏 -3.51 倍稳健 z | F26: 打开原文
A27: 45716 | B27: 1525 | C27: B 单日跳变 | D27: 5.17 | E27: 前值 1450.00（2025-02-26）→ 1525.00 | F27: 打开原文
A28: 45719 | B28: 1600 | C28: B 单日跳变 | D28: 4.92 | E28: 前值 1525.00（2025-02-28）→ 1600.00 | F28: 打开原文
A29: 45758 | B29: 1475 | C29: A 水平异常 | D29: -2.7 | E29: 相对滚动一年中位数偏 -2.70 倍稳健 z | F29: 打开原文
A30: 45758 | B30: 1475 | C30: B 单日跳变 | D30: -3.28 | E30: 前值 1525.00（2025-04-08）→ 1475.00 | F30: 打开原文
A31: 45758 | B31: 1475 | C31: C 分布异常 | D31: 越栅栏 | E31: 落在 Q1-1.5IQR ~ Q3+1.5IQR 之外 | F31: 打开原文
A32: 45762 | B32: 1450 | C32: C 分布异常 | D32: 越栅栏 | E32: 落在 Q1-1.5IQR ~ Q3+1.5IQR 之外 | F32: 打开原文
A33: 45763 | B33: 1450 | C33: C 分布异常 | D33: 越栅栏 | E33: 落在 Q1-1.5IQR ~ Q3+1.5IQR 之外 | F33: 打开原文
A34: 45764 | B34: 1450 | C34: C 分布异常 | D34: 越栅栏 | E34: 落在 Q1-1.5IQR ~ Q3+1.5IQR 之外 | F34: 打开原文
A35: 45765 | B35: 1450 | C35: C 分布异常 | D35: 越栅栏 | E35: 落在 Q1-1.5IQR ~ Q3+1.5IQR 之外 | F35: 打开原文
A36: 45769 | B36: 1450 | C36: C 分布异常 | D36: 越栅栏 | E36: 落在 Q1-1.5IQR ~ Q3+1.5IQR 之外 | F36: 打开原文
A37: 45771 | B37: 1450 | C37: C 分布异常 | D37: 越栅栏 | E37: 落在 Q1-1.5IQR ~ Q3+1.5IQR 之外 | F37: 打开原文
A38: 45772 | B38: 1450 | C38: C 分布异常 | D38: 越栅栏 | E38: 落在 Q1-1.5IQR ~ Q3+1.5IQR 之外 | F38: 打开原文
A39: 45774 | B39: 1450 | C39: C 分布异常 | D39: 越栅栏 | E39: 落在 Q1-1.5IQR ~ Q3+1.5IQR 之外 | F39: 打开原文
A40: 45775 | B40: 1450 | C40: C 分布异常 | D40: 越栅栏 | E40: 落在 Q1-1.5IQR ~ Q3+1.5IQR 之外 | F40: 打开原文
A41: 45818 | B41: 1375 | C41: A 水平异常 | D41: -2.7 | E41: 相对滚动一年中位数偏 -2.70 倍稳健 z | F41: 打开原文
...

Sheet 10 事件时间线
A1: 10 事件时间线 · 仅收录可核验事实
A2: 每条事件都必须能点开原始来源。不含任何机构观点、行情预测或归因推测。
A4: 日期 | B4: 事件 | C4: 事实描述 | D4: 来源 | E4: 链接
A5: 2024-08-01 | B5: 华东重碱报价首次成为生意社日评固定口径 | C5: 生意社华东地区纯碱日评自本月起稳定披露「重质纯碱主流市场」区间，此前仅披露轻质或不分规格的「纯碱主流报价」。这是本报告 3 年序列的真实起点，也是最大的一处口径断点。 | D5: 生意社 华东地区纯碱市场日评（频道列表） | E5: 打开原文
A6: 2024-09-20 | B6: 纯碱期货大幅回落，现货报价跟跌 | C6: 2024 年三季度纯碱供需转向宽松，华东重碱区间自 7 月的 2000-2200 元/吨逐级下移。此阶段为本序列下行通道的起点。 | D6: 生意社 纯碱商品动态 | E6: 打开原文
A7: 2025-07-01 | B7: 华东重碱主流报价降至 1180-1300 元/吨区间 | C7: 据生意社 7 月 1 日华东地区纯碱报价，重质纯碱主流市场在 1180-1300 元/吨左右，实单以商谈为主。 | D7: 生意社：7 月 1 日华东地区纯碱市场平稳观望 | E7: 打开原文
A8: 2025-09-05 | B8: 华东重碱主流价 1260-1320 元/吨（第三方同日口径） | C8: 东方汇金期货晨会纪要：9 月 5 日华东地区轻质纯碱 1130-1470 元/吨，重质纯碱 1260-1320 元/吨；同期国内纯碱厂家总库存 182.21 万吨。可作独立信源交叉校验。 | D8: 东方汇金期货 2025.09.08 晨会纪要 | E8: 打开原文
A9: 2025-12-25 | B9: 华东重碱下调至 1200-1300 元/吨 | C9: 生意社 12 月 25 日讯：轻质纯碱主流市场 1140-1600 元/吨，价格下调 20 元/吨；重质纯碱主流市场 1200-1300 元/吨；纯碱开工窄幅波动，下游按需跟进。 | D9: 生意社：12 月 25 日华东地区纯碱市场偏弱运行 | E9: 打开原文
A10: 2026-03-16 | B10: 华东重碱上调至 1200-1300 元/吨（3 月 10 日上调 30 元/吨） | C10: 生意社 3 月 16 日华东地区纯碱报价：轻质纯碱主流市场 1150-1560 元/吨；重质纯碱主流市场 1200-1300 元/吨，3 月 10 日价格上调 30 元/吨，实单以商谈为主。 | D10: 生意社：3 月 16 日华东地区纯碱市场观望运行 | E10: 打开原文
A11: 2026-07-27 | B11: 华东重碱单日下调 50 元/吨至 1180-1250 元/吨 | C11: 生意社 7 月 28 日发布：7 月 27 日重质纯碱价格下调 50 元/吨，主流市场 1180-1250 元/吨；同期轻质下调 70 元/吨。为本次数据窗口内最后一次可核验的价格调整。 | D11: 生意社：7 月 28 日华东地区纯碱市场暂稳运行 | E11: 打开原文

Sheet 11 数据缺口
A1: 11 数据缺口 · 不插值、不模拟
A2: 缺口＝该有报价的工作日却没有公开报价。全部留空，不做前值填充、不做插值补价。
A4: 共识别 40 个连续缺口段（连续 ≥3 个工作日无报价），另有 69 个单日缺失（多为法定假日）。合计缺失 113 个工作日。
A6: 序号 | B6: 缺口起 | C6: 缺口止 | D6: 缺失工作日 | E6: 处理方式
A7: 1 | B7: 2024-09-16 | C7: 2024-09-17 | D7: 2 | E7: 留空，不填补；统计时该期间无观测参与
A8: 2 | B8: 2024-09-30 | C8: 2024-10-04 | D8: 5 | E8: 留空，不填补；统计时该期间无观测参与
A9: 3 | B9: 2025-01-27 | C9: 2025-01-31 | D9: 5 | E9: 留空，不填补；统计时该期间无观测参与
A10: 4 | B10: 2025-02-03 | C10: 2025-02-05 | D10: 3 | E10: 留空，不填补；统计时该期间无观测参与
A11: 5 | B11: 2025-03-31 | C11: 2025-04-01 | D11: 2 | E11: 留空，不填补；统计时该期间无观测参与
A12: 6 | B12: 2025-04-09 | C12: 2025-04-10 | D12: 2 | E12: 留空，不填补；统计时该期间无观测参与
A13: 7 | B13: 2025-05-01 | C13: 2025-05-02 | D13: 2 | E13: 留空，不填补；统计时该期间无观测参与
A14: 8 | B14: 2025-05-05 | C14: 2025-05-06 | D14: 2 | E14: 留空，不填补；统计时该期间无观测参与
A15: 9 | B15: 2025-05-22 | C15: 2025-05-23 | D15: 2 | E15: 留空，不填补；统计时该期间无观测参与
A16: 10 | B16: 2025-06-02 | C16: 2025-06-03 | D16: 2 | E16: 留空，不填补；统计时该期间无观测参与
A17: 11 | B17: 2025-07-24 | C17: 2025-07-25 | D17: 2 | E17: 留空，不填补；统计时该期间无观测参与
A18: 12 | B18: 2025-10-01 | C18: 2025-10-03 | D18: 3 | E18: 留空，不填补；统计时该期间无观测参与
... A46: 40 | B46: 2026-07-22 | C46: 2026-07-24 | D46: 3 | E46: 留空，不填补；统计时该期间无观测参与

Sheet 12 方法与公式说明
A1: 12 方法与公式说明
A2: 这一张表是给审阅者看的：每个统计量到底怎么算、边界在哪里。
A4: 指标 | B4: Excel 公式/算法 | C4: 口径与边界 | D4: 常见误用
A5: 经验分位（含并列） | B5: COUNTIFS(值,"<="&当前价, 日期在窗口内) / n | C5: 回答「历史上有多少比例的报价日 ≤ 今天」 | D5: 用 (P−min)/(max−min) 冒充分位
A6: 经验分位（中位秩） | B6: (COUNTIF(<当前价)+0.5×COUNTIF(=当前价)) / n | C6: 并列值按半数计入，抵消现货锯齿 | D6: 与含并列口径混用而不说明
A7: 区间位置 | B7: (当前价 − 最低) / (最高 − 最低) | C7: 纯几何位置，不是统计分位 | D7: 直接叫成「历史分位」
A8: 最低/最高/均值/中位数 | B8: MIN / MAX / AVERAGE / MEDIAN | C8: 只用窗口内真实观测 | D8: 把全样本极值当成当前窗口极值
A9: 标准差 | B9: STDEV.S（样本标准差） | C9: n<2 不计算 | D9: 用总体标准差 STDEV.P 导致年化波动偏低
A10: 四分位 | B10: QUARTILE.INC（含端点位次） | C10: 用于分位带与 IQR 栅栏 | D10: 与 PERCENTILE.EXC 混用导致边界不一致
A11: 年化波动率 | B11: std(ln(P_t/P_{t−1}) / 相隔自然日数) × √365 | C11: 现货报价不等距，必须按真实日差折算 | D11: 直接对相邻报价算收益再 ×√252
A12: 最大回撤 | B12: min((P_t − 历史峰值)/历史峰值) | C12: 全样本，标注峰/谷日期 | D12: 只报幅度不报日期，无法复核
A13: 水平异常 | B13: 0.6745×(P−滚动一年中位数)/MAD ≥ 2.5 | C13: 稳健 z，抗极端值 | D13: 用均值±kσ，被极端值本身污染
A14: 跳变异常 | B14: 相邻报价日变动绝对值 ≥ 3% | C14: 按报价日，不按自然日 | D14: 跨节假日误判为跳变
A15: 分布异常 | B15: P < Q1−1.5IQR 或 P > Q3+1.5IQR | C15: 箱线图栅栏 | D15: 与稳健 z 重复计数同一现象
... A18: 缺口处理 | B18: 按工作日统计，留空 | C18: 不插值、不前值填充 | D18: 用 fillna(method='ffill') 填平后算波动率
A20: 本工作簿所有统计列都是真实公式（可点开单元格查看），不是预计算结果。若改动「02 原始序列」中的价格，04–08 表会自动重算；若 Excel 提示是否重算，请选「是」。

Sheet 13 来源清单
A1: 13 来源清单
A2: 每条价格都能回溯到这里列出的来源。
A4: 来源 | B4: 用于 | C4: 链接 | D4: 备注
A5: 生意社（100ppi.com）纯碱频道 · 商品动态 | B5: 全部价格观测的原始出处（华东日评 534 篇 + 基准价 770 篇） | C5: https://soda.100ppi.com/news/list--12-1.html
A6: 生意社 华东地区纯碱市场日评（逐篇） | B6: S1 华东重质 / S2 华东轻质 的区间低-高-中值，每行均可点开原文核对 | C6: https://www.100ppi.com/news/detail-20260728-5990717.html
A7: 生意社 重质纯碱基准价（逐日） | B7: S3 全国重质基准价序列 | C7: https://www.100ppi.com/rawmex/detail-737.html
A8: 东方汇金期货晨会纪要（2025-09-08） | B8: 第三方同日口径交叉校验（华东重碱 1260-1320 元/吨，库存 182.21 万吨） | C8: https://www.dfhjqh.com/news/1316.html
A10: 报告生成时间 2026-10-20 16:03；数据基准日 2026-07-28。
